# Converted from schematic
# THIS TEMPLATE USES DEFAULTS!  Please edit for corrections.
# If you need help, consult template_rules.txt

weight=1
embed_into_distance=2
acceptable_target_blocks=1,2,3,12,13
dimensions=36,21,21
allowable_overhang=0
max_cut_in=2
cut_in_buffer=0
max_leveling=2
leveling_buffer=1
preserve_water=0
preserve_lava=0
preserve_plants=0


rule1=0,100,3
rule2=0,100,89
rule3=0,100,80
rule4=0,100,60-7
rule5=0,100,9
rule6=0,100,2
rule7=0,100,60
rule8=0,100,78
rule9=0,100,59-7
rule10=0,100,83
rule11=0,100,31-1
rule12=0,100,37
rule13=0,100,17
rule14=0,100,86-3
rule15=0,100,106-1
rule16=0,100,106-4
rule17=0,100,106-2
rule18=0,100,17-3
rule19=0,100,83-14
rule20=0,100,83-7
rule21=0,100,83-9
rule22=0,100,83-15
rule23=0,100,83-13
rule24=0,100,83-6
rule25=0,100,83-10
rule26=0,100,83-5
rule27=0,100,83-12
rule28=0,100,106
rule29=0,100,65-3
rule30=0,100,79
rule31=0,100,18
rule32=0,100,18-3
rule33=0,100,HardChest


layer
1,1,1,1,1,1,1,1,1,1,1,1,1,1,1,1,1,1,1,1,1
1,1,1,1,1,1,1,1,1,1,1,1,1,1,1,1,1,1,1,1,1
1,1,1,1,1,1,1,1,1,1,1,1,1,1,1,1,1,1,1,1,1
1,1,1,1,1,1,1,1,1,1,1,1,1,1,1,1,1,1,1,1,1
1,1,1,1,1,1,1,1,1,1,1,1,1,1,1,1,1,1,1,1,1
1,1,1,1,1,1,1,1,1,1,1,1,1,2,1,1,1,1,1,1,1
1,1,1,1,1,1,1,1,1,1,1,1,1,1,1,1,1,1,1,1,1
1,1,1,1,1,1,1,1,1,1,1,1,1,1,1,2,1,1,1,1,1
1,1,1,1,1,1,1,1,1,1,1,1,1,1,1,1,1,1,1,1,1
1,1,1,1,1,1,1,1,1,1,1,1,1,1,1,1,1,1,1,1,1
1,1,1,1,1,1,1,1,1,1,1,1,1,1,1,1,1,1,1,1,1
1,1,1,1,1,1,1,1,1,1,1,1,1,1,2,1,2,1,2,1,1
1,1,1,1,1,1,1,1,1,1,1,1,1,1,2,1,2,1,2,1,1
1,1,1,1,1,2,1,1,1,1,1,1,1,1,2,1,2,1,2,1,1
1,1,1,1,1,1,1,1,1,1,1,2,2,2,2,1,2,1,2,1,1
1,1,1,1,1,1,1,2,1,1,1,1,1,1,1,1,1,1,1,1,1
1,1,1,1,1,1,1,1,1,1,1,2,2,2,2,1,1,1,1,1,1
1,1,1,1,1,1,1,1,1,1,1,1,1,1,1,1,1,1,1,1,1
1,1,1,1,1,1,1,1,1,1,1,2,2,2,2,1,1,1,1,1,1
1,1,1,1,1,1,1,1,1,1,1,1,1,1,1,1,1,1,1,1,1
1,1,1,1,1,1,1,1,1,1,1,1,1,1,1,1,1,1,1,1,1
endlayer

layer
3,3,3,3,3,3,3,3,3,3,3,3,3,3,3,3,3,3,3,3,3
3,3,3,3,3,3,6,6,6,6,3,4,4,4,4,3,3,3,3,3,3
3,3,3,3,3,3,6,6,6,6,3,4,4,4,4,3,3,3,3,3,3
3,3,3,3,3,3,6,6,6,6,3,4,4,4,4,3,3,3,3,3,3
3,3,3,3,3,3,6,6,1,6,3,4,4,4,4,3,3,3,3,3,3
3,3,3,3,3,6,6,1,6,6,3,4,4,5,4,4,3,3,3,3,3
3,6,6,6,6,6,6,6,6,6,3,4,4,4,4,4,4,4,4,4,3
3,6,6,6,6,6,6,3,3,3,3,3,3,3,4,5,4,4,4,4,3
3,6,1,6,6,6,6,3,3,3,3,3,3,3,4,4,4,4,4,4,3
3,6,6,6,6,6,6,3,3,3,3,3,3,3,4,4,4,4,4,4,3
3,3,3,3,3,3,3,3,3,3,3,3,3,3,3,3,3,3,3,3,3
3,4,4,4,4,4,4,3,3,3,3,3,3,3,5,1,5,1,5,1,3
3,4,4,4,4,4,4,3,3,3,3,3,3,3,5,1,5,1,5,1,3
3,7,4,4,4,5,4,3,3,3,3,3,3,3,5,1,5,1,5,1,3
3,4,4,4,4,4,4,4,4,4,3,5,5,5,5,1,5,1,5,1,3
3,3,3,3,3,4,4,5,4,4,3,1,1,1,1,5,3,3,3,3,3
3,3,3,3,3,3,4,4,4,4,3,5,5,5,5,3,3,3,3,3,3
3,3,3,3,3,3,4,4,4,4,3,1,1,1,1,3,3,3,3,3,3
3,3,3,3,3,3,4,4,4,4,3,5,5,5,5,3,3,3,3,3,3
3,3,3,3,3,3,4,4,4,4,3,1,1,1,1,3,3,3,3,3,3
3,3,3,3,3,3,3,3,3,3,3,3,3,3,3,3,3,3,3,3,3
endlayer

layer
8,3,3,3,3,3,3,3,3,3,3,3,3,3,3,3,3,3,3,3,8
3,8,8,8,8,3,15,11,11,11,3,9,9,9,9,3,8,8,8,8,3
3,8,8,8,8,3,11,11,11,12,3,9,9,9,9,3,8,8,8,8,3
3,8,8,8,8,3,11,12,11,11,3,9,9,9,9,3,8,8,8,8,3
3,8,8,8,8,3,11,11,13,11,3,9,9,9,9,3,8,8,8,8,3
3,3,3,3,3,0,11,14,11,0,3,9,9,0,9,9,3,3,3,3,3
3,11,11,17,17,11,11,11,11,0,3,9,9,9,9,9,9,9,9,9,3
3,11,0,11,11,11,11,3,3,3,3,3,3,3,9,0,9,9,9,9,3
3,11,18,11,12,11,11,3,3,3,3,3,3,3,9,9,9,9,9,9,3
3,11,0,11,11,11,16,3,3,3,3,3,3,3,9,9,9,9,9,9,3
3,3,3,3,3,3,3,3,3,3,3,3,3,3,3,3,3,3,3,3,3
3,9,9,9,9,9,9,3,3,3,3,3,3,3,0,10,0,10,0,10,3
3,9,9,9,9,9,9,3,3,3,3,3,3,3,0,10,0,10,0,10,3
3,9,9,9,9,0,9,3,3,3,3,3,3,3,0,10,0,10,0,10,3
3,9,9,9,9,9,9,9,9,9,3,0,0,0,0,10,0,10,0,10,3
3,3,3,3,3,9,9,0,9,9,3,10,10,10,10,0,3,3,3,3,3
3,8,8,8,8,3,9,9,9,9,3,0,0,0,0,3,8,8,8,8,3
3,8,8,8,8,3,9,9,9,9,3,10,10,10,10,3,8,8,8,8,3
3,8,8,8,8,3,9,9,9,9,3,0,0,0,0,3,8,8,8,8,3
3,8,8,8,8,3,9,9,9,9,3,10,10,10,10,3,8,8,8,8,3
8,3,3,3,3,3,3,3,3,3,3,3,3,3,3,3,3,3,3,3,8
endlayer

layer
0,3,3,3,3,0,0,0,0,0,0,0,0,0,0,0,3,3,3,3,0
3,0,0,0,0,3,0,0,0,0,0,0,0,0,0,3,0,0,0,0,3
3,0,0,0,0,3,15,0,0,28,0,0,0,0,0,3,0,0,0,0,3
3,0,0,0,0,3,15,0,0,28,0,0,0,0,0,3,0,0,0,0,3
3,0,0,0,0,3,0,0,13,0,0,0,0,0,0,3,0,0,0,0,3
3,3,3,3,3,0,0,0,0,0,0,0,0,0,0,0,3,3,3,3,0
0,0,0,17,17,0,16,0,0,0,0,0,0,0,0,0,0,0,0,0,0
0,0,0,0,0,0,0,0,3,3,0,3,3,0,0,0,0,0,0,0,0
0,0,18,0,0,0,16,3,0,0,0,0,0,3,0,0,0,0,0,0,0
0,0,0,0,0,0,16,3,0,0,0,0,0,3,0,0,0,0,0,0,0
0,0,0,0,0,0,0,0,0,29,3,0,0,0,0,0,0,0,0,0,0
0,0,0,0,0,0,0,3,0,0,0,0,0,3,0,10,0,21,0,19,0
0,0,0,0,0,0,0,3,0,0,0,0,0,3,0,25,0,22,0,19,0
0,0,0,0,0,0,0,0,3,3,0,3,3,0,0,26,0,23,0,20,0
0,0,0,0,0,0,0,0,0,0,0,0,0,0,0,22,0,24,0,10,0
0,3,3,3,3,0,0,0,0,0,0,19,20,24,10,0,3,3,3,3,0
3,0,0,0,0,3,0,0,0,0,0,0,0,0,0,3,0,0,0,0,3
3,0,0,0,0,3,0,0,0,0,0,20,10,10,22,3,0,0,0,0,3
3,0,0,0,0,3,0,0,0,0,0,0,0,0,0,3,0,0,0,0,3
3,0,0,0,0,3,0,0,0,0,0,23,24,27,25,3,0,0,0,0,3
0,3,3,3,3,0,0,0,0,0,0,0,0,0,0,0,3,3,3,3,0
endlayer

layer
0,3,3,3,3,0,0,0,0,0,0,0,0,0,0,0,3,3,3,3,0
3,0,0,0,0,3,0,0,0,0,0,0,0,0,0,3,0,0,0,0,3
3,0,0,0,0,3,0,31,31,31,0,0,0,0,0,3,0,0,0,0,3
3,0,0,0,0,3,31,31,31,31,31,0,0,0,0,3,0,0,0,0,3
3,0,0,0,0,3,31,31,13,31,31,0,0,0,0,3,0,0,0,0,3
0,3,3,3,3,0,31,31,31,31,31,0,0,0,0,0,3,30,3,3,0
0,0,0,17,0,0,16,31,31,31,0,0,0,0,0,0,0,0,0,0,0
0,0,0,0,0,0,0,17,3,3,0,3,3,0,0,0,0,0,0,0,0
0,0,18,0,0,0,0,3,0,0,0,0,0,3,0,0,0,0,0,0,0
0,0,0,0,0,0,0,3,0,0,0,0,0,3,0,0,0,0,0,0,0
0,0,0,0,0,0,0,0,0,29,3,0,0,0,0,0,0,0,0,0,0
0,0,0,0,0,0,0,3,0,0,0,0,0,3,0,10,0,0,0,0,0
0,0,0,0,0,0,0,3,0,0,0,0,0,3,0,0,0,0,0,0,0
0,0,0,0,0,0,0,0,3,3,0,3,3,0,0,0,0,0,0,0,0
0,0,0,0,0,0,0,0,0,0,0,0,0,0,0,0,0,0,0,10,0
0,3,3,3,3,0,0,0,0,0,0,0,0,0,10,0,3,3,30,3,0
3,0,0,0,0,3,0,0,0,0,0,0,0,0,0,3,0,0,0,0,3
3,0,0,0,0,3,0,0,0,0,0,0,10,10,0,3,0,0,0,0,3
3,0,0,0,0,3,0,0,0,0,0,0,0,0,0,30,0,0,0,0,3
3,0,0,0,0,3,0,0,0,0,0,0,0,0,0,3,0,0,0,0,3
0,3,3,3,3,0,0,0,0,0,0,0,0,0,0,0,3,3,30,3,0
endlayer

layer
0,3,30,3,3,0,0,0,0,0,0,0,0,0,0,0,3,3,30,3,0
3,0,0,0,0,3,0,0,0,0,0,0,0,0,0,3,0,0,0,0,3
30,0,0,0,0,3,31,31,31,31,0,0,0,0,0,3,0,0,0,0,30
3,0,0,0,0,3,31,31,31,31,31,0,0,0,0,3,0,0,0,0,3
3,0,0,0,0,3,31,31,13,31,31,0,0,0,0,3,0,0,0,0,3
0,3,3,3,3,0,31,31,31,31,31,0,0,0,0,0,3,3,3,3,0
0,0,0,0,0,0,31,31,31,31,31,0,0,0,0,0,0,0,0,0,0
0,0,0,0,0,0,0,0,3,30,3,3,3,0,0,0,0,0,0,0,0
0,0,18,0,0,0,0,3,0,0,0,0,0,3,0,0,0,0,0,0,0
0,0,0,0,0,0,0,30,0,0,0,0,0,3,0,0,0,0,0,0,0
0,0,0,0,0,0,0,3,0,29,3,0,0,3,0,0,0,0,0,0,0
0,0,0,0,0,0,0,3,0,0,0,0,0,3,0,0,0,0,0,0,0
0,0,0,0,0,0,0,3,0,0,0,0,0,3,0,0,0,0,0,0,0
0,0,0,0,0,0,0,0,3,30,3,3,3,0,0,0,0,0,0,0,0
0,0,0,0,0,0,0,0,0,0,0,0,0,0,0,0,0,0,0,0,0
0,3,3,30,3,0,0,0,0,0,0,0,0,0,0,0,3,3,3,3,0
3,0,0,0,0,3,0,0,0,0,0,0,0,0,0,3,0,0,0,0,3
30,0,0,0,0,3,0,0,0,0,0,0,0,0,0,3,0,0,0,0,30
3,0,0,0,0,30,0,0,0,0,0,0,0,0,0,30,0,0,0,0,3
3,0,0,0,0,3,0,0,0,0,0,0,0,0,0,3,0,0,0,0,3
0,3,30,3,3,0,0,0,0,0,0,0,0,0,0,0,3,3,3,3,0
endlayer

layer
0,3,30,3,0,0,0,0,0,0,0,0,0,0,0,0,0,3,3,3,0
3,0,0,0,0,3,0,0,0,0,0,0,0,0,0,3,0,0,0,0,3
30,0,0,0,0,30,0,0,0,0,0,0,0,0,0,30,0,0,0,0,30
3,0,0,0,0,3,0,0,31,0,0,0,0,0,0,3,0,0,0,0,3
3,0,0,0,0,3,0,31,13,31,0,0,0,0,0,3,0,0,0,0,3
0,0,3,30,3,0,0,31,31,31,0,0,0,0,0,0,3,30,3,0,0
0,0,0,0,0,0,0,0,0,0,0,0,0,0,0,0,0,0,0,0,0
0,0,0,0,0,0,0,0,3,30,3,3,3,0,0,0,0,0,0,0,0
0,0,18,0,0,0,0,3,3,3,3,3,3,3,0,0,0,0,0,0,0
0,0,0,0,0,0,0,30,3,0,0,0,3,30,0,0,0,0,0,0,0
0,0,0,0,0,0,0,3,3,29,3,0,3,3,0,0,0,0,0,0,0
0,0,0,0,0,0,0,3,3,0,0,0,3,3,0,0,0,0,0,0,0
0,0,0,0,0,0,0,3,3,3,3,3,3,3,0,0,0,0,0,0,0
0,0,0,0,0,0,0,0,3,30,3,30,3,0,0,0,0,0,0,0,0
0,0,0,0,0,0,0,0,0,0,0,0,0,0,0,0,0,0,0,0,0
0,0,3,30,3,0,0,0,0,0,0,0,0,0,0,0,3,3,3,0,0
3,0,0,0,0,3,0,0,0,0,0,0,0,0,0,3,0,0,0,0,3
3,0,0,0,0,3,0,0,0,0,0,0,0,0,0,3,0,0,0,0,30
3,0,0,0,0,3,0,0,0,0,0,0,0,0,0,3,0,0,0,0,3
3,0,0,0,0,3,0,0,0,0,0,0,0,0,0,3,0,0,0,0,3
0,3,3,3,0,0,0,0,0,0,0,0,0,0,0,0,0,3,30,3,0
endlayer

layer
0,3,3,3,0,0,0,0,0,0,0,0,0,0,0,0,0,3,3,3,0
3,0,0,0,0,3,0,0,0,0,0,0,0,0,0,3,0,0,0,0,3
3,0,0,0,0,30,0,0,0,0,0,0,0,0,0,3,0,0,0,0,30
3,0,0,0,0,3,0,0,31,0,0,0,0,0,0,3,0,0,0,0,3
3,0,0,0,0,3,0,31,31,31,0,0,0,0,0,3,0,0,0,0,3
0,0,3,3,3,0,0,0,31,0,0,0,0,0,0,0,3,3,3,0,0
0,0,0,0,0,0,0,0,0,0,0,0,0,0,0,0,0,0,0,0,0
0,0,0,0,0,0,0,0,3,30,3,3,3,0,0,0,0,0,0,0,0
0,0,18,0,0,0,0,3,3,3,3,3,3,3,0,0,0,0,0,0,0
0,0,0,0,0,0,0,30,3,3,3,3,3,30,0,0,0,0,0,0,0
0,0,0,0,0,0,0,3,3,29,3,3,3,3,0,0,0,0,0,0,0
0,0,0,0,0,0,0,3,3,3,3,3,3,3,0,0,0,0,0,0,0
0,0,0,0,0,0,0,3,3,3,3,3,3,3,0,0,0,0,0,0,0
0,0,0,0,0,0,0,0,3,30,3,30,3,0,0,0,0,0,0,0,0
0,0,0,0,0,0,0,0,0,0,0,0,0,0,0,0,0,0,0,0,0
0,0,3,3,3,0,0,0,0,0,0,0,0,0,0,0,3,3,3,0,0
3,0,0,0,0,3,0,0,0,0,0,0,0,0,0,3,0,0,0,0,3
3,0,0,0,0,30,0,0,0,0,0,0,0,0,0,3,0,0,0,0,3
30,0,0,0,0,3,0,0,0,0,0,0,0,0,0,30,0,0,0,0,3
3,0,0,0,0,3,0,0,0,0,0,0,0,0,0,3,0,0,0,0,3
0,3,3,3,0,0,0,0,0,0,0,0,0,0,0,0,0,3,3,3,0
endlayer

layer
0,3,3,0,0,0,0,0,0,0,0,0,0,0,0,0,0,0,3,3,0
3,0,0,0,0,3,0,0,0,0,0,0,0,0,0,3,0,0,0,0,3
3,0,0,0,0,3,0,0,0,0,0,0,0,0,0,3,0,0,0,0,3
30,0,0,0,0,3,0,0,0,0,0,0,0,0,0,30,0,0,0,0,3
3,0,0,0,0,3,0,0,0,0,0,0,0,0,0,3,0,0,0,0,3
0,0,0,3,3,0,0,0,0,0,0,0,0,0,0,0,3,3,8,0,0
0,0,0,0,0,0,0,0,0,0,0,0,0,0,0,0,0,0,0,0,0
0,0,0,0,0,0,0,0,3,30,3,30,3,0,0,0,0,0,0,0,0
0,0,18,0,0,0,0,3,3,3,3,3,3,3,0,0,0,0,0,0,0
0,0,0,0,0,0,0,30,3,3,3,3,3,30,0,0,0,0,0,0,0
0,0,0,0,0,0,0,3,3,29,3,3,3,3,0,0,0,0,0,0,0
0,0,0,0,17,0,0,3,3,3,3,3,3,3,0,0,0,0,0,0,0
0,0,0,0,0,0,0,3,3,3,3,3,3,3,0,0,0,0,0,0,0
0,0,0,0,0,0,0,0,3,3,3,30,3,0,0,0,0,0,0,0,0
0,0,0,0,0,0,0,0,0,0,0,0,0,0,0,0,0,0,0,0,0
0,0,0,3,3,0,0,0,0,0,0,0,0,0,0,0,3,3,0,0,0
3,0,0,0,0,3,0,0,0,0,0,0,0,0,0,3,0,0,0,0,3
3,0,0,0,0,3,0,0,0,0,0,0,0,0,0,3,0,0,0,0,3
3,0,0,0,0,3,0,0,0,0,0,0,0,0,0,3,0,0,0,0,30
3,0,0,0,0,3,0,0,0,0,0,0,0,0,0,3,0,0,0,0,3
0,3,3,0,0,0,0,0,0,0,0,0,0,0,0,0,0,0,3,3,0
endlayer

layer
0,3,3,0,0,0,0,0,0,0,0,0,0,0,0,0,0,0,3,3,0
3,0,0,0,0,3,0,0,0,0,0,0,0,0,0,3,0,0,0,0,3
3,0,0,0,0,3,0,0,0,0,0,0,0,0,0,3,0,0,0,0,3
3,0,0,0,0,30,0,0,0,0,0,0,0,0,0,30,0,0,0,0,30
3,0,0,0,0,3,0,0,0,0,0,0,0,0,0,3,0,0,0,0,3
0,0,0,3,3,0,0,0,0,0,0,0,0,0,0,0,3,3,0,0,0
0,0,0,0,0,0,0,0,0,0,0,0,0,0,0,0,0,0,0,0,0
0,0,0,0,0,0,0,0,3,30,3,30,3,0,0,0,0,0,0,0,0
0,0,18,0,0,15,0,3,3,3,3,3,3,3,0,0,0,0,0,0,0
0,0,0,0,0,0,0,30,3,3,3,3,3,30,0,0,0,0,0,0,0
0,0,0,0,0,0,0,3,3,29,3,3,3,3,0,0,0,0,0,0,0
0,17,0,0,17,0,0,3,3,3,3,3,3,3,0,0,0,0,0,0,0
0,0,0,0,0,0,0,3,3,3,3,3,3,3,0,0,0,0,0,0,0
0,0,0,0,0,0,0,0,3,3,3,30,3,0,0,0,0,0,0,0,0
0,0,0,0,0,0,0,0,0,0,0,0,0,0,0,0,0,0,0,0,0
0,0,0,3,3,0,0,0,0,0,0,0,0,0,0,0,3,3,0,0,0
3,0,0,0,0,3,0,0,0,0,0,0,0,0,0,3,0,0,0,0,3
30,0,0,0,0,3,0,0,0,0,0,0,0,0,0,30,0,0,0,0,3
3,0,0,0,0,3,0,0,0,0,0,0,0,0,0,3,0,0,0,0,3
3,0,0,0,0,3,0,0,0,0,0,0,0,0,0,3,0,0,0,0,3
0,3,3,0,0,0,0,0,0,0,0,0,0,0,0,0,0,0,3,3,0
endlayer

layer
0,3,0,0,0,0,0,0,0,0,0,0,0,0,0,0,0,0,0,3,0
3,0,0,0,0,3,0,0,0,0,0,0,0,0,0,3,0,0,0,0,3
3,0,0,0,0,3,0,0,0,0,0,0,0,0,0,3,0,0,0,0,3
30,0,0,0,0,3,0,0,0,0,0,0,0,0,0,3,0,0,0,0,3
3,0,0,0,0,3,0,0,0,0,0,0,0,0,0,3,0,0,0,0,3
0,0,0,0,3,0,0,0,0,0,0,0,0,0,0,0,3,8,0,0,0
0,32,32,32,32,0,0,0,0,0,0,0,0,0,0,0,0,0,0,0,0
32,32,32,32,32,15,0,0,3,3,3,30,3,0,0,0,0,0,0,0,0
32,32,18,32,32,15,0,3,3,3,3,3,3,3,0,0,0,0,0,0,0
32,32,32,32,32,0,0,30,3,3,3,3,3,30,0,0,0,0,0,0,0
0,32,32,32,32,15,0,3,3,29,3,3,3,3,0,0,0,0,0,0,0
0,17,0,17,17,0,0,3,3,3,3,3,3,3,0,0,0,0,0,0,0
0,0,0,0,0,0,0,3,3,3,3,3,3,3,0,0,0,0,0,0,0
0,0,0,0,0,0,0,0,3,30,3,30,3,0,0,0,0,0,0,0,0
0,0,0,0,0,0,0,0,0,0,0,0,0,0,0,0,0,0,0,0,0
0,0,0,0,3,0,0,0,0,0,0,0,0,0,0,0,3,0,0,0,0
3,0,0,0,0,3,0,0,0,0,0,0,0,0,0,3,0,0,0,0,3
30,0,0,0,0,3,0,0,0,0,0,0,0,0,0,3,0,0,0,0,30
3,0,0,0,0,30,0,0,0,0,0,0,0,0,0,3,0,0,0,0,3
3,0,0,0,0,3,0,0,0,0,0,0,0,0,0,3,0,0,0,0,3
0,3,0,0,0,0,0,0,0,0,0,0,0,0,0,0,0,0,0,3,0
endlayer

layer
0,3,0,0,0,0,0,0,0,0,0,0,0,0,0,0,0,0,0,3,0
3,0,0,0,0,3,0,0,0,0,0,0,0,0,0,3,0,0,0,0,3
3,0,0,0,0,30,0,0,0,0,0,0,0,0,0,30,0,0,0,0,3
3,0,0,0,0,3,0,0,0,0,0,0,0,0,0,3,0,0,0,0,30
3,0,0,0,0,3,0,0,0,0,0,0,0,0,0,3,0,0,0,0,3
0,0,0,0,3,0,0,0,0,0,0,0,0,0,0,0,3,0,0,0,0
0,32,32,32,32,0,0,0,0,0,0,0,0,0,0,0,0,0,0,0,0
32,32,32,32,32,0,0,0,3,3,3,3,3,0,0,0,0,0,0,0,0
32,32,18,32,32,0,0,3,3,3,3,3,3,3,0,0,0,0,0,0,0
32,32,32,32,32,0,0,30,3,3,3,3,3,30,0,0,0,0,0,0,0
32,32,32,32,32,0,0,3,2,29,3,3,3,3,0,0,0,0,0,0,0
0,0,0,0,0,0,0,3,3,3,3,3,3,3,0,0,0,0,0,0,0
0,0,0,0,0,0,0,3,3,3,3,3,3,3,0,0,0,0,0,0,0
0,0,0,0,0,0,0,0,3,30,3,3,3,0,0,0,0,0,0,0,0
0,0,0,0,0,0,0,0,0,0,0,0,0,0,0,0,0,0,0,0,0
0,0,0,0,3,0,0,0,0,0,0,0,0,0,0,0,3,0,0,0,0
3,0,0,0,0,3,0,0,0,0,0,0,0,0,0,3,0,0,0,0,3
3,0,0,0,0,3,0,0,0,0,0,0,0,0,0,3,0,0,0,0,30
3,0,0,0,0,30,0,0,0,0,0,0,0,0,0,3,0,0,0,0,3
3,0,0,0,0,3,0,0,0,0,0,0,0,0,0,3,0,0,0,0,3
0,3,0,0,0,0,0,0,0,0,0,0,0,0,0,0,0,0,0,3,0
endlayer

layer
0,0,0,0,0,0,0,0,0,0,0,0,0,0,0,0,0,0,0,0,0
0,0,0,0,0,3,0,0,0,0,0,0,0,0,0,3,0,0,0,0,0
3,0,0,0,0,30,0,0,0,0,0,0,0,0,0,3,0,0,0,0,3
3,0,0,0,0,3,0,0,0,0,0,0,0,0,0,3,0,0,0,0,30
3,0,0,0,0,0,0,0,0,0,0,0,0,0,0,0,0,0,0,0,3
0,0,0,0,0,0,0,0,0,0,0,0,0,0,0,0,0,0,0,0,0
0,0,0,0,0,0,0,0,0,0,0,0,0,0,0,0,0,0,0,0,0
0,32,32,32,0,0,0,0,3,30,3,3,3,0,0,0,0,0,0,0,0
0,32,18,32,0,0,0,3,3,3,3,3,3,3,0,0,0,0,0,0,0
0,32,32,0,0,0,0,3,3,3,3,3,3,30,0,0,0,0,0,0,0
0,0,0,0,0,0,0,3,3,29,3,3,3,3,0,0,0,0,0,0,0
0,0,0,0,0,0,0,3,3,3,3,3,3,30,0,0,0,0,0,0,0
0,0,0,0,0,0,0,3,3,3,3,3,3,3,0,0,0,0,0,0,0
0,0,0,0,0,0,0,0,3,30,3,3,3,0,0,0,0,0,0,0,0
0,0,0,0,0,0,0,0,0,0,0,0,0,0,0,0,0,0,0,0,0
0,0,0,0,8,0,0,0,0,0,0,0,0,0,0,0,0,0,0,0,0
3,0,0,0,0,0,0,0,0,0,0,0,0,0,0,0,0,0,0,0,3
3,0,0,0,0,3,0,0,0,0,0,0,0,0,0,3,0,0,0,0,3
3,0,0,0,0,3,0,0,0,0,0,0,0,0,0,3,0,0,0,0,3
0,0,0,0,0,3,0,0,0,0,0,0,0,0,0,3,0,0,0,0,0
0,0,0,0,0,0,0,0,0,0,0,0,0,0,0,0,0,0,0,0,0
endlayer

layer
0,0,0,0,0,0,0,0,0,0,0,0,0,0,0,0,0,0,0,0,0
0,0,0,0,0,3,0,0,0,0,0,0,0,0,0,3,0,0,0,0,0
3,0,0,0,0,3,0,0,0,0,0,0,0,0,0,3,0,0,0,0,3
3,0,0,0,0,3,0,0,0,0,0,0,0,0,0,3,0,0,0,0,3
3,0,0,0,0,0,0,0,0,0,0,0,0,0,0,0,0,0,0,0,3
0,0,0,0,0,0,0,0,0,0,0,0,0,0,0,0,0,0,0,0,0
0,0,0,0,0,0,0,0,0,0,0,0,0,0,0,0,0,0,0,0,0
0,0,32,0,0,0,0,0,3,30,3,3,3,0,0,0,0,0,0,0,0
0,32,32,32,0,0,0,3,3,3,3,3,3,3,0,0,0,0,0,0,0
0,0,32,0,0,0,0,3,3,3,3,3,3,30,0,0,0,0,0,0,0
0,0,0,0,0,0,0,3,3,29,3,3,3,3,0,0,0,0,0,0,0
0,0,0,0,0,0,0,30,3,3,3,3,3,30,0,0,0,0,0,0,0
0,0,0,0,0,0,0,3,3,3,3,3,3,3,0,0,0,0,0,0,0
0,0,0,0,0,0,0,0,3,30,3,3,3,0,0,0,0,0,0,0,0
0,0,0,0,0,0,0,0,0,0,0,0,0,0,0,0,0,0,0,0,0
0,0,0,0,0,0,0,0,0,0,0,0,0,0,0,0,0,0,0,0,0
3,0,0,0,0,0,0,0,0,0,0,0,0,0,0,0,0,0,0,0,3
3,0,0,0,0,3,0,0,0,0,0,0,0,0,0,3,0,0,0,0,3
3,0,0,0,0,3,0,0,0,0,0,0,0,0,0,3,0,0,0,0,3
0,0,0,0,0,3,0,0,0,0,0,0,0,0,0,3,0,0,0,0,0
0,0,0,0,0,0,0,0,0,0,0,0,0,0,0,0,0,0,0,0,0
endlayer

layer
0,0,0,0,0,0,0,0,0,0,0,0,0,0,0,0,0,0,0,0,0
0,0,0,0,0,3,0,0,0,0,0,0,0,0,0,3,0,0,0,0,0
0,0,0,0,0,3,0,0,0,0,0,0,0,0,0,3,0,0,0,0,0
3,0,0,0,0,0,0,0,0,0,0,0,0,0,0,0,0,0,0,0,3
3,0,0,0,0,0,0,0,0,0,0,0,0,0,0,0,0,0,0,0,3
0,0,0,0,0,0,0,0,0,0,0,0,0,0,0,0,0,0,0,0,0
0,0,0,0,0,0,0,0,0,0,0,0,0,0,0,0,0,0,0,0,0
0,0,0,0,0,0,0,0,3,3,3,3,3,0,0,0,0,0,0,0,0
0,0,0,0,0,0,0,3,3,3,3,3,3,3,0,0,0,0,0,0,0
0,0,0,0,0,0,0,3,3,3,3,3,3,3,0,0,0,0,0,0,0
0,0,0,0,0,0,0,3,3,29,3,3,3,3,0,0,0,0,0,0,0
0,0,0,0,0,0,0,30,3,3,3,3,3,30,0,0,0,0,0,0,0
0,0,0,0,0,0,0,3,3,3,3,3,3,3,0,0,0,0,0,0,0
0,0,0,0,0,0,0,0,3,3,3,3,3,0,0,0,0,0,0,0,0
0,0,0,0,0,0,0,0,0,0,0,0,0,0,0,0,0,0,0,0,0
0,0,0,0,0,0,0,0,0,0,0,0,0,0,0,0,0,0,0,0,0
3,0,0,0,0,0,0,0,0,0,0,0,0,0,0,0,0,0,0,0,3
3,0,0,0,0,0,0,0,0,0,0,0,0,0,0,0,0,0,0,0,3
0,0,0,0,0,3,0,0,0,0,0,0,0,0,0,3,0,0,0,0,0
0,0,0,0,0,3,0,0,0,0,0,0,0,0,0,3,0,0,0,0,0
0,0,0,0,0,0,0,0,0,0,0,0,0,0,0,0,0,0,0,0,0
endlayer

layer
0,0,0,0,0,0,0,0,0,0,0,0,0,0,0,0,0,0,0,0,0
0,0,0,0,0,3,0,0,0,0,0,0,0,0,0,3,0,0,0,0,0
0,0,0,0,0,3,0,0,0,0,0,0,0,0,0,3,0,0,0,0,0
3,0,0,0,0,0,0,0,0,0,0,0,0,0,0,0,0,0,0,0,3
3,0,0,0,0,0,0,0,0,0,0,0,0,0,0,0,0,0,0,0,3
0,0,0,0,0,0,0,0,0,0,0,0,0,0,0,0,0,0,0,0,0
0,0,0,0,0,0,0,0,0,0,0,0,0,0,0,0,0,0,0,0,0
0,0,0,0,0,0,0,0,3,3,3,30,3,0,0,0,0,0,0,0,0
0,0,0,0,0,0,0,3,3,3,3,3,3,3,0,0,0,0,0,0,0
0,0,0,0,0,0,0,3,3,3,3,3,3,3,0,0,0,0,0,0,0
0,0,0,0,0,0,0,3,3,29,3,3,3,3,0,0,0,0,0,0,0
0,0,0,0,0,0,0,30,3,3,3,3,3,30,0,0,0,0,0,0,0
0,0,0,0,0,0,0,3,3,3,3,3,3,3,0,0,0,0,0,0,0
0,0,0,0,0,0,0,0,3,3,30,3,3,0,0,0,0,0,0,0,0
0,0,0,0,0,0,0,0,0,0,0,0,0,0,0,0,0,0,0,0,0
0,0,0,0,0,0,0,0,0,0,0,0,0,0,0,0,0,0,0,0,0
3,0,0,0,0,0,0,0,0,0,0,0,0,0,0,0,0,0,0,0,3
3,0,0,0,0,0,0,0,0,0,0,0,0,0,0,0,0,0,0,0,3
0,0,0,0,0,3,0,0,0,0,0,0,0,0,0,3,0,0,0,0,0
0,0,0,0,0,3,0,0,0,0,0,0,0,0,0,3,0,0,0,0,0
0,0,0,0,0,0,0,0,0,0,0,0,0,0,0,0,0,0,0,0,0
endlayer

layer
0,0,0,0,0,0,0,0,0,0,0,0,0,0,0,0,0,0,0,0,0
0,0,0,0,0,3,0,0,0,0,0,0,0,0,0,3,0,0,0,0,0
0,0,0,0,0,0,0,0,0,0,0,0,0,0,0,0,0,0,0,0,0
0,0,0,0,0,0,0,0,0,0,0,0,0,0,0,0,0,0,0,0,0
3,0,0,0,0,0,0,0,0,0,0,0,0,0,0,0,0,0,0,0,3
0,0,0,0,0,0,0,0,0,0,0,0,0,0,0,0,0,0,0,0,0
0,0,0,0,0,0,0,0,0,0,0,0,0,0,0,0,0,0,0,0,0
0,0,0,0,0,0,0,0,3,3,3,30,3,0,0,0,0,0,0,0,0
0,0,0,0,0,0,0,3,3,3,3,3,3,3,0,0,0,0,0,0,0
0,0,0,0,0,0,0,3,3,3,3,3,3,3,0,0,0,0,0,0,0
0,0,0,0,0,0,0,3,3,29,3,3,3,3,0,0,0,0,0,0,0
0,0,0,0,0,0,0,3,3,3,3,3,3,30,0,0,0,0,0,0,0
0,0,0,0,0,0,0,3,3,3,3,3,3,3,0,0,0,0,0,0,0
0,0,0,0,0,0,0,0,3,3,30,3,3,0,0,0,0,0,0,0,0
0,0,0,0,0,0,0,0,0,0,0,0,0,0,0,0,0,0,0,0,0
0,0,0,0,0,0,0,0,0,0,0,0,0,0,0,0,0,0,0,0,0
3,0,0,0,0,0,0,0,0,0,0,0,0,0,0,0,0,0,0,0,3
0,0,0,0,0,0,0,0,0,0,0,0,0,0,0,0,0,0,0,0,0
0,0,0,0,0,0,0,0,0,0,0,0,0,0,0,0,0,0,0,0,0
0,0,0,0,0,3,0,0,0,0,0,0,0,0,0,3,0,0,0,0,0
0,0,0,0,0,0,0,0,0,0,0,0,0,0,0,0,0,0,0,0,0
endlayer

layer
0,0,0,0,0,0,0,0,0,0,0,0,0,0,0,0,0,0,0,0,0
0,0,0,0,0,3,0,0,0,0,0,0,0,0,0,3,0,0,0,0,0
0,0,0,0,0,0,0,0,0,0,0,0,0,0,0,0,0,0,0,0,0
0,0,0,0,0,0,0,0,0,0,0,0,0,0,0,0,0,0,0,0,0
3,0,0,0,0,0,0,0,0,0,0,0,0,0,0,0,0,0,0,0,3
0,0,0,0,0,0,0,0,0,0,0,0,0,0,0,0,0,0,0,0,0
0,0,0,0,0,0,0,0,0,0,0,0,0,0,0,0,0,0,0,0,0
0,0,0,0,0,0,0,0,3,3,3,30,3,0,0,0,0,0,0,0,0
0,0,0,0,0,0,0,3,3,3,3,3,3,3,0,0,0,0,0,0,0
0,0,0,0,0,0,0,3,3,3,3,3,3,3,0,0,0,0,0,0,0
0,0,0,0,0,0,0,30,3,29,3,3,3,3,0,0,0,0,0,0,0
0,0,0,0,0,0,0,3,3,3,3,3,3,3,0,0,0,0,0,0,0
0,0,0,0,0,0,0,3,3,3,3,3,3,3,0,0,0,0,0,0,0
0,0,0,0,0,0,0,0,3,3,30,3,3,0,0,0,0,0,0,0,0
0,0,0,0,0,0,0,0,0,0,0,0,0,0,0,0,0,0,0,0,0
0,0,0,0,0,0,0,0,0,0,0,0,0,0,0,0,0,0,0,0,0
3,0,0,0,0,0,0,0,0,0,0,0,0,0,0,0,0,0,0,0,3
0,0,0,0,0,0,0,0,0,0,0,0,0,0,0,0,0,0,0,0,0
0,0,0,0,0,0,0,0,0,0,0,0,0,0,0,0,0,0,0,0,0
0,0,0,0,0,3,0,0,0,0,0,0,0,0,0,3,0,0,0,0,0
0,0,0,0,0,0,0,0,0,0,0,0,0,0,0,0,0,0,0,0,0
endlayer

layer
0,0,0,0,0,0,0,0,0,0,0,0,0,0,0,0,0,0,0,0,0
0,0,0,0,0,0,0,0,0,0,0,0,0,0,0,0,0,0,0,0,0
0,0,0,0,0,0,0,0,0,0,0,0,0,0,0,0,0,0,0,0,0
0,0,0,0,0,0,0,0,0,0,0,0,0,0,0,0,0,0,0,0,0
0,0,0,0,0,0,0,0,0,0,0,0,0,0,0,0,0,0,0,0,8
0,0,0,0,0,0,0,0,0,0,0,0,0,0,0,0,0,0,0,0,0
0,0,0,0,0,0,0,0,0,0,0,0,0,0,0,0,0,0,0,0,0
0,0,0,0,0,0,0,0,3,3,3,30,3,0,0,0,0,0,0,0,0
0,0,0,0,0,0,0,3,3,3,3,3,3,3,0,0,0,0,0,0,0
0,0,0,0,0,0,0,3,3,3,3,3,3,3,0,0,0,0,0,0,0
0,0,0,0,0,0,0,30,3,29,3,3,3,3,0,0,0,0,0,0,0
0,0,0,0,0,0,0,3,3,3,3,3,3,30,0,0,0,0,0,0,0
0,0,0,0,0,0,0,3,3,3,3,3,3,3,0,0,0,0,0,0,0
0,0,0,0,0,0,0,0,3,3,3,3,3,0,0,0,0,0,0,0,0
0,0,0,0,0,0,0,0,0,0,0,0,0,0,0,0,0,0,0,0,0
0,0,0,0,0,0,0,0,0,0,0,0,0,0,0,0,0,0,0,0,0
0,0,0,0,0,0,0,0,0,0,0,0,0,0,0,0,0,0,0,0,0
0,0,0,0,0,0,0,0,0,0,0,0,0,0,0,0,0,0,0,0,0
0,0,0,0,0,0,0,0,0,0,0,0,0,0,0,0,0,0,0,0,0
0,0,0,0,0,8,0,0,0,0,0,0,0,0,0,8,0,0,0,0,0
0,0,0,0,0,0,0,0,0,0,0,0,0,0,0,0,0,0,0,0,0
endlayer

layer
0,0,0,0,0,0,0,0,0,0,0,0,0,0,0,0,0,0,0,0,0
0,0,0,0,0,0,0,0,0,0,0,0,0,0,0,0,0,0,0,0,0
0,0,0,0,0,0,0,0,0,0,0,0,0,0,0,0,0,0,0,0,0
0,0,0,0,0,0,0,0,0,0,0,0,0,0,0,0,0,0,0,0,0
0,0,0,0,0,0,0,0,0,0,0,0,0,0,0,0,0,0,0,0,0
0,0,0,0,0,0,0,0,0,0,0,0,0,0,0,0,0,0,0,0,0
0,0,0,0,0,0,0,0,0,0,0,0,0,0,0,0,0,0,0,0,0
0,0,0,0,0,0,0,0,3,30,3,30,3,0,0,0,0,0,0,0,0
0,0,0,0,0,0,0,3,3,3,3,3,3,3,0,0,0,0,0,0,0
0,0,0,0,0,0,0,3,3,3,3,3,3,30,0,0,0,0,0,0,0
0,0,0,0,0,0,0,3,3,29,3,3,3,3,0,0,0,0,0,0,0
0,0,0,0,0,0,0,3,3,3,3,3,3,30,0,0,0,0,0,0,0
0,0,0,0,0,0,0,3,3,3,3,3,3,3,0,0,0,0,0,0,0
0,0,0,0,0,0,0,0,3,3,3,3,3,0,0,0,0,0,0,0,0
0,0,0,0,0,0,0,0,0,0,0,0,0,0,0,0,0,0,0,0,0
0,0,0,0,0,0,0,0,0,0,0,0,0,0,0,0,0,0,0,0,0
0,0,0,0,0,0,0,0,0,0,0,0,0,0,0,0,0,0,0,0,0
0,0,0,0,0,0,0,0,0,0,0,0,0,0,0,0,0,0,0,0,0
0,0,0,0,0,0,0,0,0,0,0,0,0,0,0,0,0,0,0,0,0
0,0,0,0,0,0,0,0,0,0,0,0,0,0,0,0,0,0,0,0,0
0,0,0,0,0,0,0,0,0,0,0,0,0,0,0,0,0,0,0,0,0
endlayer

layer
0,0,0,0,0,0,0,0,0,0,0,0,0,0,0,0,0,0,0,0,0
0,0,0,0,0,0,0,0,0,0,0,0,0,0,0,0,0,0,0,0,0
0,0,0,0,0,0,0,0,0,0,0,0,0,0,0,0,0,0,0,0,0
0,0,0,0,0,0,0,0,0,0,0,0,0,0,0,0,0,0,0,0,0
0,0,0,0,0,0,0,0,0,0,0,0,0,0,0,0,0,0,0,0,0
0,0,0,0,0,0,0,0,0,0,0,0,0,0,0,0,0,0,0,0,0
0,0,0,0,0,0,0,0,0,0,0,0,0,0,0,0,0,0,0,0,0
0,0,0,0,0,0,0,0,3,3,3,30,3,0,0,0,0,0,0,0,0
0,0,0,0,0,0,0,3,3,3,3,3,3,3,0,0,0,0,0,0,0
0,0,0,0,0,0,0,3,3,3,3,3,3,30,0,0,0,0,0,0,0
0,0,0,0,0,0,0,3,3,29,3,3,3,3,0,0,0,0,0,0,0
0,0,0,0,0,0,0,30,3,3,3,3,3,30,0,0,0,0,0,0,0
0,0,0,0,0,0,0,3,3,3,3,3,3,3,0,0,0,0,0,0,0
0,0,0,0,0,0,0,0,3,3,30,3,3,0,0,0,0,0,0,0,0
0,0,0,0,0,0,0,0,0,0,0,0,0,0,0,0,0,0,0,0,0
0,0,0,0,0,0,0,0,0,0,0,0,0,0,0,0,0,0,0,0,0
0,0,0,0,0,0,0,0,0,0,0,0,0,0,0,0,0,0,0,0,0
0,0,0,0,0,0,0,0,0,0,0,0,0,0,0,0,0,0,0,0,0
0,0,0,0,0,0,0,0,0,0,0,0,0,0,0,0,0,0,0,0,0
0,0,0,0,0,0,0,0,0,0,0,0,0,0,0,0,0,0,0,0,0
0,0,0,0,0,0,0,0,0,0,0,0,0,0,0,0,0,0,0,0,0
endlayer

layer
0,0,0,0,0,0,0,0,0,0,0,0,0,0,0,0,0,0,0,0,0
0,0,0,0,0,0,0,0,0,0,0,0,0,0,0,0,0,0,0,0,0
0,0,0,0,0,0,0,0,0,0,0,0,0,0,0,0,0,0,0,0,0
0,0,0,0,0,0,0,0,0,0,0,0,0,0,0,0,0,0,0,0,0
0,0,0,0,0,0,0,0,0,0,0,0,0,0,0,0,0,0,0,0,0
0,0,0,0,0,0,0,0,0,0,0,0,0,0,0,0,0,0,0,0,0
0,0,0,0,0,0,0,0,0,0,0,0,0,0,0,0,0,0,0,0,0
0,0,0,0,0,0,0,0,3,3,3,30,3,0,0,0,0,0,0,0,0
0,0,0,0,0,0,0,3,3,0,3,3,3,3,0,0,0,0,0,0,0
0,0,0,0,0,0,0,30,3,3,3,3,3,30,0,0,0,0,0,0,0
0,0,0,0,0,0,0,3,3,29,3,3,3,3,0,0,0,0,0,0,0
0,0,0,0,0,0,0,30,3,3,3,3,3,30,0,0,0,0,0,0,0
0,0,0,0,0,0,0,3,3,3,3,3,3,3,0,0,0,0,0,0,0
0,0,0,0,0,0,0,0,3,3,30,3,3,0,0,0,0,0,0,0,0
0,0,0,0,0,0,0,0,0,0,0,0,0,0,0,0,0,0,0,0,0
0,0,0,0,0,0,0,0,0,0,0,0,0,0,0,0,0,0,0,0,0
0,0,0,0,0,0,0,0,0,0,0,0,0,0,0,0,0,0,0,0,0
0,0,0,0,0,0,0,0,0,0,0,0,0,0,0,0,0,0,0,0,0
0,0,0,0,0,0,0,0,0,0,0,0,0,0,0,0,0,0,0,0,0
0,0,0,0,0,0,0,0,0,0,0,0,0,0,0,0,0,0,0,0,0
0,0,0,0,0,0,0,0,0,0,0,0,0,0,0,0,0,0,0,0,0
endlayer

layer
0,0,0,0,0,0,0,0,0,0,0,0,0,0,0,0,0,0,0,0,0
0,0,0,0,0,0,0,0,0,0,0,0,0,0,0,0,0,0,0,0,0
0,0,0,0,0,0,0,0,0,0,0,0,0,0,0,0,0,0,0,0,0
0,0,0,0,0,0,0,0,0,0,0,0,0,0,0,0,0,0,0,0,0
0,0,0,0,0,0,0,0,0,0,0,0,0,0,0,0,0,0,0,0,0
0,0,0,0,0,0,0,0,0,0,0,0,0,0,0,0,0,0,0,0,0
0,0,0,0,0,0,0,0,0,0,0,0,0,0,0,0,0,0,0,0,0
0,0,0,0,0,0,0,0,3,3,3,30,3,0,0,0,0,0,0,0,0
0,0,0,0,0,0,0,3,3,3,3,3,3,3,0,0,0,0,0,0,0
0,0,0,0,0,0,0,30,3,3,3,3,3,30,0,0,0,0,0,0,0
0,0,0,0,0,0,0,3,3,29,3,3,3,3,0,0,0,0,0,0,0
0,0,0,0,0,0,0,30,3,3,3,3,3,3,0,0,0,0,0,0,0
0,0,0,0,0,0,0,3,3,3,3,3,3,3,0,0,0,0,0,0,0
0,0,0,0,0,0,0,0,3,3,30,3,3,0,0,0,0,0,0,0,0
0,0,0,0,0,0,0,0,0,0,0,0,0,0,0,0,0,0,0,0,0
0,0,0,0,0,0,0,0,0,0,0,0,0,0,0,0,0,0,0,0,0
0,0,0,0,0,0,0,0,0,0,0,0,0,0,0,0,0,0,0,0,0
0,0,0,0,0,0,0,0,0,0,0,0,0,0,0,0,0,0,0,0,0
0,0,0,0,0,0,0,0,0,0,0,0,0,0,0,0,0,0,0,0,0
0,0,0,0,0,0,0,0,0,0,0,0,0,0,0,0,0,0,0,0,0
0,0,0,0,0,0,0,0,0,0,0,0,0,0,0,0,0,0,0,0,0
endlayer

layer
0,0,0,0,0,0,0,0,0,0,0,0,0,0,0,0,0,0,0,0,0
0,0,0,0,0,0,0,0,0,0,0,0,0,0,0,0,0,0,0,0,0
0,0,0,0,0,0,0,0,0,0,0,0,0,0,0,0,0,0,0,0,0
0,0,0,0,0,0,0,0,0,0,0,0,0,0,0,0,0,0,0,0,0
0,0,0,0,0,0,0,0,0,0,0,0,0,0,0,0,0,0,0,0,0
0,0,0,0,0,0,0,0,0,0,0,0,0,0,0,0,0,0,0,0,0
0,0,0,0,0,0,0,0,0,0,0,0,0,0,0,0,0,0,0,0,0
0,0,0,0,0,0,0,0,3,3,3,30,3,0,0,0,0,0,0,0,0
0,0,0,0,0,0,0,3,3,3,3,3,3,3,0,0,0,0,0,0,0
0,0,0,0,0,0,0,30,3,3,3,3,3,30,0,0,0,0,0,0,0
0,0,0,0,0,0,0,3,3,29,3,3,3,3,0,0,0,0,0,0,0
0,0,0,0,0,0,0,3,3,3,3,3,3,3,0,0,0,0,0,0,0
0,0,0,0,0,0,0,3,3,3,3,3,3,3,0,0,0,0,0,0,0
0,0,0,0,0,0,0,0,3,3,30,3,3,0,0,0,0,0,0,0,0
0,0,0,0,0,0,0,0,0,0,0,0,0,0,0,0,0,0,0,0,0
0,0,0,0,0,0,0,0,0,0,0,0,0,0,0,0,0,0,0,0,0
0,0,0,0,0,0,0,0,0,0,0,0,0,0,0,0,0,0,0,0,0
0,0,0,0,0,0,0,0,0,0,0,0,0,0,0,0,0,0,0,0,0
0,0,0,0,0,0,0,0,0,0,0,0,0,0,0,0,0,0,0,0,0
0,0,0,0,0,0,0,0,0,0,0,0,0,0,0,0,0,0,0,0,0
0,0,0,0,0,0,0,0,0,0,0,0,0,0,0,0,0,0,0,0,0
endlayer

layer
0,0,0,0,0,0,0,0,0,0,0,0,0,0,0,0,0,0,0,0,0
0,0,0,0,0,0,0,0,0,0,0,0,0,0,0,0,0,0,0,0,0
0,0,0,0,0,0,0,0,0,0,0,0,0,0,0,0,0,0,0,0,0
0,0,0,0,0,0,0,0,0,0,0,0,0,0,0,0,0,0,0,0,0
0,0,0,0,0,0,0,0,0,0,0,0,0,0,0,0,0,0,0,0,0
0,0,0,0,0,0,0,0,0,0,0,0,0,0,0,0,0,0,0,0,0
0,0,0,0,0,0,0,0,0,0,0,0,0,0,0,0,0,0,0,0,0
0,0,0,0,0,0,0,0,3,3,3,30,3,0,0,0,0,0,0,0,0
0,0,0,0,0,0,0,3,3,3,3,3,3,3,0,0,0,0,0,0,0
0,0,0,0,0,0,0,30,3,3,3,3,3,30,0,0,0,0,0,0,0
0,0,0,0,0,0,0,3,3,29,3,3,3,3,0,0,0,0,0,0,0
0,0,0,0,0,0,0,3,3,3,3,3,3,3,0,0,0,0,0,0,0
0,0,0,0,0,0,0,3,3,3,3,3,3,3,0,0,0,0,0,0,0
0,0,0,0,0,0,0,0,3,3,30,3,3,0,0,0,0,0,0,0,0
0,0,0,0,0,0,0,0,0,0,0,0,0,0,0,0,0,0,0,0,0
0,0,0,0,0,0,0,0,0,0,0,0,0,0,0,0,0,0,0,0,0
0,0,0,0,0,0,0,0,0,0,0,0,0,0,0,0,0,0,0,0,0
0,0,0,0,0,0,0,0,0,0,0,0,0,0,0,0,0,0,0,0,0
0,0,0,0,0,0,0,0,0,0,0,0,0,0,0,0,0,0,0,0,0
0,0,0,0,0,0,0,0,0,0,0,0,0,0,0,0,0,0,0,0,0
0,0,0,0,0,0,0,0,0,0,0,0,0,0,0,0,0,0,0,0,0
endlayer

layer
0,0,0,0,0,0,0,0,0,0,0,0,0,0,0,0,0,0,0,0,0
0,0,0,0,0,0,0,0,0,0,0,0,0,0,0,0,0,0,0,0,0
0,0,0,0,0,0,0,0,0,0,0,0,0,0,0,0,0,0,0,0,0
0,0,0,0,0,0,0,0,0,0,0,0,0,0,0,0,0,0,0,0,0
0,0,0,0,0,0,0,0,0,0,0,0,0,0,0,0,0,0,0,0,0
0,0,0,0,0,0,0,0,0,0,0,0,0,0,0,0,0,0,0,0,0
0,0,0,0,0,0,0,0,0,0,0,0,0,0,0,0,0,0,0,0,0
0,0,0,0,0,0,0,0,3,3,3,30,3,0,0,0,0,0,0,0,0
0,0,0,0,0,0,0,3,3,3,3,3,3,3,0,0,0,0,0,0,0
0,0,0,0,0,0,0,30,3,3,3,3,3,30,0,0,0,0,0,0,0
0,0,0,0,0,0,0,3,3,29,3,3,3,3,0,0,0,0,0,0,0
0,0,0,0,0,0,0,3,3,3,3,3,3,3,0,0,0,0,0,0,0
0,0,0,0,0,0,0,3,3,3,3,3,3,3,0,0,0,0,0,0,0
0,0,0,0,0,0,0,0,3,3,30,3,3,0,0,0,0,0,0,0,0
0,0,0,0,0,0,0,0,0,0,0,0,0,0,0,0,0,0,0,0,0
0,0,0,0,0,0,0,0,0,0,0,0,0,0,0,0,0,0,0,0,0
0,0,0,0,0,0,0,0,0,0,0,0,0,0,0,0,0,0,0,0,0
0,0,0,0,0,0,0,0,0,0,0,0,0,0,0,0,0,0,0,0,0
0,0,0,0,0,0,0,0,0,0,0,0,0,0,0,0,0,0,0,0,0
0,0,0,0,0,0,0,0,0,0,0,0,0,0,0,0,0,0,0,0,0
0,0,0,0,0,0,0,0,0,0,0,0,0,0,0,0,0,0,0,0,0
endlayer

layer
0,0,0,0,0,0,0,0,0,0,0,0,0,0,0,0,0,0,0,0,0
0,0,0,0,0,0,0,0,0,0,0,0,0,0,0,0,0,0,0,0,0
0,0,0,0,0,0,0,0,0,0,0,0,0,0,0,0,0,0,0,0,0
0,0,0,0,0,0,0,0,0,0,0,0,0,0,0,0,0,0,0,0,0
0,0,0,0,0,0,0,0,0,0,0,0,0,0,0,0,0,0,0,0,0
0,0,0,0,0,0,0,0,0,0,0,0,0,0,0,0,0,0,0,0,0
0,0,0,0,0,0,0,0,0,0,0,0,0,0,0,0,0,0,0,0,0
0,0,0,0,0,0,0,3,3,3,3,3,3,3,0,0,0,0,0,0,0
0,0,0,0,0,0,0,3,3,3,3,3,3,3,0,0,0,0,0,0,0
0,0,0,0,0,0,0,3,3,3,3,3,3,3,0,0,0,0,0,0,0
0,0,0,0,0,0,0,3,3,29,3,3,3,3,0,0,0,0,0,0,0
0,0,0,0,0,0,0,3,3,3,3,3,3,3,0,0,0,0,0,0,0
0,0,0,0,0,0,0,3,3,3,3,3,3,3,0,0,0,0,0,0,0
0,0,0,0,0,0,0,3,3,3,3,3,3,3,0,0,0,0,0,0,0
0,0,0,0,0,0,0,0,0,0,0,0,0,0,0,0,0,0,0,0,0
0,0,0,0,0,0,0,0,0,0,0,0,0,0,0,0,0,0,0,0,0
0,0,0,0,0,0,0,0,0,0,0,0,0,0,0,0,0,0,0,0,0
0,0,0,0,0,0,0,0,0,0,0,0,0,0,0,0,0,0,0,0,0
0,0,0,0,0,0,0,0,0,0,0,0,0,0,0,0,0,0,0,0,0
0,0,0,0,0,0,0,0,0,0,0,0,0,0,0,0,0,0,0,0,0
0,0,0,0,0,0,0,0,0,0,0,0,0,0,0,0,0,0,0,0,0
endlayer

layer
0,0,0,0,0,0,0,0,0,0,0,0,0,0,0,0,0,0,0,0,0
0,0,0,0,0,0,0,0,0,0,0,0,0,0,0,0,0,0,0,0,0
0,0,0,0,0,0,0,0,0,0,0,0,0,0,0,0,0,0,0,0,0
0,0,0,0,0,0,0,0,0,0,0,0,0,0,0,0,0,0,0,0,0
0,0,0,0,0,0,0,0,0,0,0,0,0,0,0,0,0,0,0,0,0
0,0,0,0,0,0,0,0,0,0,0,0,0,0,0,0,0,0,0,0,0
0,0,0,0,0,0,0,0,0,0,0,0,0,0,0,0,0,0,0,0,0
0,0,0,0,0,0,0,3,3,3,3,3,3,3,0,0,0,0,0,0,0
0,0,0,0,0,0,0,3,3,3,3,3,3,3,0,0,0,0,0,0,0
0,0,0,0,0,0,0,3,3,0,0,0,3,3,0,0,0,0,0,0,0
0,0,0,0,0,0,0,3,3,29,3,0,3,3,0,0,0,0,0,0,0
0,0,0,0,0,0,0,3,3,0,0,0,3,3,0,0,0,0,0,0,0
0,0,0,0,0,0,0,3,3,3,3,3,3,3,0,0,0,0,0,0,0
0,0,0,0,0,0,0,3,3,3,3,3,3,3,0,0,0,0,0,0,0
0,0,0,0,0,0,0,0,0,0,0,0,0,0,0,0,0,0,0,0,0
0,0,0,0,0,0,0,0,0,0,0,0,0,0,0,0,0,0,0,0,0
0,0,0,0,0,0,0,0,0,0,0,0,0,0,0,0,0,0,0,0,0
0,0,0,0,0,0,0,0,0,0,0,0,0,0,0,0,0,0,0,0,0
0,0,0,0,0,0,0,0,0,0,0,0,0,0,0,0,0,0,0,0,0
0,0,0,0,0,0,0,0,0,0,0,0,0,0,0,0,0,0,0,0,0
0,0,0,0,0,0,0,0,0,0,0,0,0,0,0,0,0,0,0,0,0
endlayer

layer
0,0,0,0,0,0,0,0,0,0,0,0,0,0,0,0,0,0,0,0,0
0,0,0,0,0,0,0,0,0,0,0,0,0,0,0,0,0,0,0,0,0
0,0,0,0,0,0,0,0,0,0,0,0,0,0,0,0,0,0,0,0,0
0,0,0,0,0,0,0,0,0,0,0,0,0,0,0,0,0,0,0,0,0
0,0,0,0,0,0,0,0,0,0,0,0,0,0,0,0,0,0,0,0,0
0,0,0,0,0,0,0,0,0,0,0,0,0,0,0,0,0,0,0,0,0
0,0,0,0,0,0,0,0,0,0,0,0,0,0,0,0,0,0,0,0,0
0,0,0,0,0,0,0,3,0,0,0,0,0,3,0,0,0,0,0,0,0
0,0,0,0,0,0,0,0,30,30,30,30,30,0,0,0,0,0,0,0,0
0,0,0,0,0,0,0,0,30,0,0,0,30,0,0,0,0,0,0,0,0
0,0,0,0,0,0,0,0,30,29,3,0,30,0,0,0,0,0,0,0,0
0,0,0,0,0,0,0,0,30,0,0,0,30,0,0,0,0,0,0,0,0
0,0,0,0,0,0,0,0,30,30,30,30,30,0,0,0,0,0,0,0,0
0,0,0,0,0,0,0,3,0,0,0,0,0,3,0,0,0,0,0,0,0
0,0,0,0,0,0,0,0,0,0,0,0,0,0,0,0,0,0,0,0,0
0,0,0,0,0,0,0,0,0,0,0,0,0,0,0,0,0,0,0,0,0
0,0,0,0,0,0,0,0,0,0,0,0,0,0,0,0,0,0,0,0,0
0,0,0,0,0,0,0,0,0,0,0,0,0,0,0,0,0,0,0,0,0
0,0,0,0,0,0,0,0,0,0,0,0,0,0,0,0,0,0,0,0,0
0,0,0,0,0,0,0,0,0,0,0,0,0,0,0,0,0,0,0,0,0
0,0,0,0,0,0,0,0,0,0,0,0,0,0,0,0,0,0,0,0,0
endlayer

layer
0,0,0,0,0,0,0,0,0,0,0,0,0,0,0,0,0,0,0,0,0
0,0,0,0,0,0,0,0,0,0,0,0,0,0,0,0,0,0,0,0,0
0,0,0,0,0,0,0,0,0,0,0,0,0,0,0,0,0,0,0,0,0
0,0,0,0,0,0,0,0,0,0,0,0,0,0,0,0,0,0,0,0,0
0,0,0,0,0,0,0,0,0,0,0,0,0,0,0,0,0,0,0,0,0
0,0,0,0,0,0,0,0,0,0,0,0,0,0,0,0,0,0,0,0,0
0,0,0,0,0,0,0,0,3,3,3,3,3,0,0,0,0,0,0,0,0
0,0,0,0,0,0,0,3,3,3,3,3,3,3,0,0,0,0,0,0,0
0,0,0,0,0,0,3,3,3,3,3,3,3,3,3,0,0,0,0,0,0
0,0,0,0,0,0,3,3,3,3,3,3,3,3,3,0,0,0,0,0,0
0,0,0,0,0,0,3,3,3,29,3,3,3,3,3,0,0,0,0,0,0
0,0,0,0,0,0,3,3,3,3,3,3,3,3,3,0,0,0,0,0,0
0,0,0,0,0,0,3,3,3,3,3,3,3,3,3,0,0,0,0,0,0
0,0,0,0,0,0,0,3,3,3,3,3,3,3,0,0,0,0,0,0,0
0,0,0,0,0,0,0,0,3,3,3,3,3,0,0,0,0,0,0,0,0
0,0,0,0,0,0,0,0,0,0,0,0,0,0,0,0,0,0,0,0,0
0,0,0,0,0,0,0,0,0,0,0,0,0,0,0,0,0,0,0,0,0
0,0,0,0,0,0,0,0,0,0,0,0,0,0,0,0,0,0,0,0,0
0,0,0,0,0,0,0,0,0,0,0,0,0,0,0,0,0,0,0,0,0
0,0,0,0,0,0,0,0,0,0,0,0,0,0,0,0,0,0,0,0,0
0,0,0,0,0,0,0,0,0,0,0,0,0,0,0,0,0,0,0,0,0
endlayer

layer
0,0,0,0,0,0,0,0,0,0,0,0,0,0,0,0,0,0,0,0,0
0,0,0,0,0,0,0,0,0,0,0,0,0,0,0,0,0,0,0,0,0
0,0,0,0,0,0,0,0,0,0,0,0,0,0,0,0,0,0,0,0,0
0,0,0,0,0,0,0,0,0,0,0,0,0,0,0,0,0,0,0,0,0
0,0,0,0,0,0,0,0,0,0,0,0,0,0,0,0,0,0,0,0,0
0,0,0,0,0,0,0,0,0,0,0,0,0,0,0,0,0,0,0,0,0
0,0,0,0,0,0,0,0,3,3,3,3,3,0,0,0,0,0,0,0,0
0,0,0,0,0,0,0,3,0,0,0,0,0,3,0,0,0,0,0,0,0
0,0,0,0,0,0,3,0,0,0,0,0,0,0,3,0,0,0,0,0,0
0,0,0,0,0,0,3,0,0,0,0,0,0,0,3,0,0,0,0,0,0
0,0,0,0,0,0,3,0,0,0,2,0,0,33,3,0,0,0,0,0,0
0,0,0,0,0,0,3,0,0,0,0,0,0,0,3,0,0,0,0,0,0
0,0,0,0,0,0,3,0,0,0,0,0,0,0,3,0,0,0,0,0,0
0,0,0,0,0,0,0,3,0,0,0,0,0,3,0,0,0,0,0,0,0
0,0,0,0,0,0,0,0,3,3,3,3,3,0,0,0,0,0,0,0,0
0,0,0,0,0,0,0,0,0,0,0,0,0,0,0,0,0,0,0,0,0
0,0,0,0,0,0,0,0,0,0,0,0,0,0,0,0,0,0,0,0,0
0,0,0,0,0,0,0,0,0,0,0,0,0,0,0,0,0,0,0,0,0
0,0,0,0,0,0,0,0,0,0,0,0,0,0,0,0,0,0,0,0,0
0,0,0,0,0,0,0,0,0,0,0,0,0,0,0,0,0,0,0,0,0
0,0,0,0,0,0,0,0,0,0,0,0,0,0,0,0,0,0,0,0,0
endlayer

layer
0,0,0,0,0,0,0,0,0,0,0,0,0,0,0,0,0,0,0,0,0
0,0,0,0,0,0,0,0,0,0,0,0,0,0,0,0,0,0,0,0,0
0,0,0,0,0,0,0,0,0,0,0,0,0,0,0,0,0,0,0,0,0
0,0,0,0,0,0,0,0,0,0,0,0,0,0,0,0,0,0,0,0,0
0,0,0,0,0,0,0,0,0,0,0,0,0,0,0,0,0,0,0,0,0
0,0,0,0,0,0,0,0,0,0,0,0,0,0,0,0,0,0,0,0,0
0,0,0,0,0,0,0,0,3,30,3,30,3,0,0,0,0,0,0,0,0
0,0,0,0,0,0,0,3,0,0,0,0,0,3,0,0,0,0,0,0,0
0,0,0,0,0,0,3,0,0,0,0,0,0,0,3,0,0,0,0,0,0
0,0,0,0,0,0,3,0,0,0,0,0,0,0,30,0,0,0,0,0,0
0,0,0,0,0,0,3,0,0,0,3,0,0,0,3,0,0,0,0,0,0
0,0,0,0,0,0,30,0,0,0,0,0,0,0,3,0,0,0,0,0,0
0,0,0,0,0,0,3,0,0,0,0,0,0,0,3,0,0,0,0,0,0
0,0,0,0,0,0,0,3,0,0,0,0,0,3,0,0,0,0,0,0,0
0,0,0,0,0,0,0,0,3,3,30,3,3,0,0,0,0,0,0,0,0
0,0,0,0,0,0,0,0,0,0,0,0,0,0,0,0,0,0,0,0,0
0,0,0,0,0,0,0,0,0,0,0,0,0,0,0,0,0,0,0,0,0
0,0,0,0,0,0,0,0,0,0,0,0,0,0,0,0,0,0,0,0,0
0,0,0,0,0,0,0,0,0,0,0,0,0,0,0,0,0,0,0,0,0
0,0,0,0,0,0,0,0,0,0,0,0,0,0,0,0,0,0,0,0,0
0,0,0,0,0,0,0,0,0,0,0,0,0,0,0,0,0,0,0,0,0
endlayer

layer
0,0,0,0,0,0,0,0,0,0,0,0,0,0,0,0,0,0,0,0,0
0,0,0,0,0,0,0,0,0,0,0,0,0,0,0,0,0,0,0,0,0
0,0,0,0,0,0,0,0,0,0,0,0,0,0,0,0,0,0,0,0,0
0,0,0,0,0,0,0,0,0,0,0,0,0,0,0,0,0,0,0,0,0
0,0,0,0,0,0,0,0,0,0,0,0,0,0,0,0,0,0,0,0,0
0,0,0,0,0,0,0,0,0,0,0,0,0,0,0,0,0,0,0,0,0
0,0,0,0,0,0,0,0,3,3,3,30,3,0,0,0,0,0,0,0,0
0,0,0,0,0,0,0,3,0,0,0,0,0,3,0,0,0,0,0,0,0
0,0,0,0,0,0,3,0,0,0,0,0,0,0,3,0,0,0,0,0,0
0,0,0,0,0,0,30,0,0,0,0,0,0,0,3,0,0,0,0,0,0
0,0,0,0,0,0,3,0,0,0,3,0,0,0,3,0,0,0,0,0,0
0,0,0,0,0,0,30,0,0,0,0,0,0,0,30,0,0,0,0,0,0
0,0,0,0,0,0,3,0,0,0,0,0,0,0,3,0,0,0,0,0,0
0,0,0,0,0,0,0,3,0,0,0,0,0,3,0,0,0,0,0,0,0
0,0,0,0,0,0,0,0,3,3,30,3,3,0,0,0,0,0,0,0,0
0,0,0,0,0,0,0,0,0,0,0,0,0,0,0,0,0,0,0,0,0
0,0,0,0,0,0,0,0,0,0,0,0,0,0,0,0,0,0,0,0,0
0,0,0,0,0,0,0,0,0,0,0,0,0,0,0,0,0,0,0,0,0
0,0,0,0,0,0,0,0,0,0,0,0,0,0,0,0,0,0,0,0,0
0,0,0,0,0,0,0,0,0,0,0,0,0,0,0,0,0,0,0,0,0
0,0,0,0,0,0,0,0,0,0,0,0,0,0,0,0,0,0,0,0,0
endlayer

layer
0,0,0,0,0,0,0,0,0,0,0,0,0,0,0,0,0,0,0,0,0
0,0,0,0,0,0,0,0,0,0,0,0,0,0,0,0,0,0,0,0,0
0,0,0,0,0,0,0,0,0,0,0,0,0,0,0,0,0,0,0,0,0
0,0,0,0,0,0,0,0,0,0,0,0,0,0,0,0,0,0,0,0,0
0,0,0,0,0,0,0,0,0,0,0,0,0,0,0,0,0,0,0,0,0
0,0,0,0,0,0,0,0,0,0,0,0,0,0,0,0,0,0,0,0,0
0,0,0,0,0,0,0,0,3,3,3,3,3,0,0,0,0,0,0,0,0
0,0,0,0,0,0,0,3,0,0,0,0,0,3,0,0,0,0,0,0,0
0,0,0,0,0,0,3,0,0,0,0,0,0,0,3,0,0,0,0,0,0
0,0,0,0,0,0,3,0,0,0,0,0,0,0,3,0,0,0,0,0,0
0,0,0,0,0,0,3,0,0,0,3,0,0,0,3,0,0,0,0,0,0
0,0,0,0,0,0,3,0,0,0,0,0,0,0,3,0,0,0,0,0,0
0,0,0,0,0,0,3,0,0,0,0,0,0,0,3,0,0,0,0,0,0
0,0,0,0,0,0,0,3,0,0,0,0,0,3,0,0,0,0,0,0,0
0,0,0,0,0,0,0,0,3,3,3,3,3,0,0,0,0,0,0,0,0
0,0,0,0,0,0,0,0,0,0,0,0,0,0,0,0,0,0,0,0,0
0,0,0,0,0,0,0,0,0,0,0,0,0,0,0,0,0,0,0,0,0
0,0,0,0,0,0,0,0,0,0,0,0,0,0,0,0,0,0,0,0,0
0,0,0,0,0,0,0,0,0,0,0,0,0,0,0,0,0,0,0,0,0
0,0,0,0,0,0,0,0,0,0,0,0,0,0,0,0,0,0,0,0,0
0,0,0,0,0,0,0,0,0,0,0,0,0,0,0,0,0,0,0,0,0
endlayer

layer
0,0,0,0,0,0,0,0,0,0,0,0,0,0,0,0,0,0,0,0,0
0,0,0,0,0,0,0,0,0,0,0,0,0,0,0,0,0,0,0,0,0
0,0,0,0,0,0,0,0,0,0,0,0,0,0,0,0,0,0,0,0,0
0,0,0,0,0,0,0,0,0,0,0,0,0,0,0,0,0,0,0,0,0
0,0,0,0,0,0,0,0,0,0,0,0,0,0,0,0,0,0,0,0,0
0,0,0,0,0,0,0,0,0,0,0,0,0,0,0,0,0,0,0,0,0
0,0,0,0,0,0,0,0,0,0,0,0,0,0,0,0,0,0,0,0,0
0,0,0,0,0,0,0,0,3,3,3,3,3,0,0,0,0,0,0,0,0
0,0,0,0,0,0,0,3,3,3,3,3,3,3,0,0,0,0,0,0,0
0,0,0,0,0,0,0,3,3,3,3,3,3,3,0,0,0,0,0,0,0
0,0,0,0,0,0,0,3,3,3,3,3,3,3,0,0,0,0,0,0,0
0,0,0,0,0,0,0,3,3,3,3,3,3,3,0,0,0,0,0,0,0
0,0,0,0,0,0,0,3,3,3,3,3,3,3,0,0,0,0,0,0,0
0,0,0,0,0,0,0,0,3,3,3,3,3,0,0,0,0,0,0,0,0
0,0,0,0,0,0,0,0,0,0,0,0,0,0,0,0,0,0,0,0,0
0,0,0,0,0,0,0,0,0,0,0,0,0,0,0,0,0,0,0,0,0
0,0,0,0,0,0,0,0,0,0,0,0,0,0,0,0,0,0,0,0,0
0,0,0,0,0,0,0,0,0,0,0,0,0,0,0,0,0,0,0,0,0
0,0,0,0,0,0,0,0,0,0,0,0,0,0,0,0,0,0,0,0,0
0,0,0,0,0,0,0,0,0,0,0,0,0,0,0,0,0,0,0,0,0
0,0,0,0,0,0,0,0,0,0,0,0,0,0,0,0,0,0,0,0,0
endlayer

layer
0,0,0,0,0,0,0,0,0,0,0,0,0,0,0,0,0,0,0,0,0
0,0,0,0,0,0,0,0,0,0,0,0,0,0,0,0,0,0,0,0,0
0,0,0,0,0,0,0,0,0,0,0,0,0,0,0,0,0,0,0,0,0
0,0,0,0,0,0,0,0,0,0,0,0,0,0,0,0,0,0,0,0,0
0,0,0,0,0,0,0,0,0,0,0,0,0,0,0,0,0,0,0,0,0
0,0,0,0,0,0,0,0,0,0,0,0,0,0,0,0,0,0,0,0,0
0,0,0,0,0,0,0,0,0,0,0,0,0,0,0,0,0,0,0,0,0
0,0,0,0,0,0,0,0,0,0,0,0,0,0,0,0,0,0,0,0,0
0,0,0,0,0,0,0,0,0,0,0,0,0,0,0,0,0,0,0,0,0
0,0,0,0,0,0,0,0,0,30,30,30,0,0,0,0,0,0,0,0,0
0,0,0,0,0,0,0,0,0,30,30,30,0,0,0,0,0,0,0,0,0
0,0,0,0,0,0,0,0,0,30,30,30,0,0,0,0,0,0,0,0,0
0,0,0,0,0,0,0,0,0,0,0,0,0,0,0,0,0,0,0,0,0
0,0,0,0,0,0,0,0,0,0,0,0,0,0,0,0,0,0,0,0,0
0,0,0,0,0,0,0,0,0,0,0,0,0,0,0,0,0,0,0,0,0
0,0,0,0,0,0,0,0,0,0,0,0,0,0,0,0,0,0,0,0,0
0,0,0,0,0,0,0,0,0,0,0,0,0,0,0,0,0,0,0,0,0
0,0,0,0,0,0,0,0,0,0,0,0,0,0,0,0,0,0,0,0,0
0,0,0,0,0,0,0,0,0,0,0,0,0,0,0,0,0,0,0,0,0
0,0,0,0,0,0,0,0,0,0,0,0,0,0,0,0,0,0,0,0,0
0,0,0,0,0,0,0,0,0,0,0,0,0,0,0,0,0,0,0,0,0
endlayer

