weight=1
acceptable_target_blocks=1,2,3,12,13,24
embed_into_distance=1
dimensions=17,7,5
max_leveling=2
leveling_buffer=1
max_cut_in=25


rule1=0,0,35-5
rule2=0,100,4
rule3=0,100,48
rule4=0,100,71-1
rule5=0,100,102
rule6=0,100,35-3
rule7=0,100,84
rule8=0,100,71-8
rule9=0,100,35-11
rule10=0,100,44-3
rule11=0,100,101
rule12=0,100,20
rule13=0,100,76-5


layer
1,1,1,1,1
1,3,3,1,1
1,3,3,1,1
1,1,3,1,1
1,2,2,2,2
1,2,2,2,2
1,2,2,2,2
endlayer

layer
0,0,0,0,0
0,5,5,0,0
0,5,5,0,0
0,0,6,0,0
0,2,2,2,2
0,2,7,0,4
0,2,2,2,2
endlayer

layer
0,0,0,0,0
0,5,5,0,0
0,5,5,0,0
0,0,0,0,0
0,2,9,2,2
0,2,0,0,8
0,2,9,2,2
endlayer

layer
0,0,0,0,0
0,5,5,0,0
0,5,5,0,0
0,0,0,0,0
0,10,10,10,10
0,2,2,2,2
0,10,10,10,10
endlayer

layer
0,0,0,0,0
0,5,5,0,0
0,5,5,0,0
0,0,0,0,0
0,0,0,0,0
0,0,0,0,0
0,0,0,0,0
endlayer

layer
0,0,0,0,0
0,5,5,0,0
0,5,5,0,0
0,0,0,0,0
0,0,0,0,0
0,0,0,0,0
0,0,0,0,0
endlayer

layer
0,0,0,0,0
0,5,5,0,0
0,5,5,0,0
0,0,0,0,0
0,0,0,0,0
0,0,0,0,0
0,0,0,0,0
endlayer

layer
0,0,0,0,0
0,5,5,0,0
0,5,5,0,0
0,0,0,0,0
0,0,0,0,0
0,0,0,0,0
0,0,0,0,0
endlayer

layer
0,0,0,0,0
0,5,5,0,0
0,5,5,0,0
0,0,0,0,0
0,0,0,0,0
0,0,0,0,0
0,0,0,0,0
endlayer

layer
0,0,0,0,0
0,5,5,0,0
0,5,5,0,0
0,0,0,0,0
0,0,0,0,0
0,0,0,0,0
0,0,0,0,0
endlayer

layer
0,0,0,0,0
0,5,5,0,0
0,5,5,0,0
0,0,0,0,0
0,0,0,0,0
0,0,0,0,0
0,0,0,0,0
endlayer

layer
0,0,0,0,0
0,5,5,0,0
0,5,5,0,0
0,0,0,0,0
0,0,0,0,0
0,0,0,0,0
0,0,0,0,0
endlayer

layer
0,0,0,0,0
0,5,5,0,0
0,5,5,0,0
0,0,0,0,0
0,0,0,0,0
0,0,0,0,0
0,0,0,0,0
endlayer

layer
0,0,0,0,0
0,5,5,0,0
0,5,5,0,0
0,0,0,0,0
0,0,0,0,0
0,0,0,0,0
0,0,0,0,0
endlayer

layer
0,11,0,0,0
0,5,5,11,0
11,5,5,0,0
0,0,11,0,0
0,0,0,0,0
0,0,0,0,0
0,0,0,0,0
endlayer

layer
0,11,0,0,0
0,12,12,11,0
11,12,12,0,0
0,0,11,0,0
0,0,0,0,0
0,0,0,0,0
0,0,0,0,0
endlayer

layer
0,11,0,0,0
0,13,0,11,0
11,0,13,0,0
0,0,11,0,0
0,0,0,0,0
0,0,0,0,0
0,0,0,0,0
endlayer

