# Converted from schematic
# THIS TEMPLATE USES DEFAULTS!  Please edit for corrections.
# If you need help, consult template_rules.txt

weight=2
embed_into_distance=1
acceptable_target_blocks=1,2,3,12,13
dimensions=8,10,8
allowable_overhang=0
max_cut_in=2
cut_in_buffer=1
max_leveling=2
leveling_buffer=1
preserve_water=0
preserve_lava=0
preserve_plants=0


rule1=0,100,2
rule2=0,100,5
rule3=0,100,4
rule4=0,100,64-3
rule5=0,100,45
rule6=0,100,64-8
rule7=0,100,102
rule8=0,100,20
rule9=0,100,109
rule10=0,100,98
rule11=0,100,109-2
rule12=0,100,109-3
rule13=0,100,109-1
rule14=0,100,44-5


layer
1,1,1,1,1,1,1,1
1,2,2,2,2,2,2,1
1,2,2,2,2,2,2,1
1,2,2,2,2,2,3,1
1,2,2,2,2,2,2,1
1,2,2,2,2,2,2,1
1,2,2,2,2,2,2,1
1,2,2,2,2,2,2,1
1,2,2,2,2,2,2,1
1,1,1,1,1,1,1,1
endlayer

layer
0,0,0,0,0,0,0,0
0,3,3,3,3,3,3,0
0,3,0,0,0,0,3,0
0,3,0,0,0,0,4,0
0,3,0,0,0,0,3,0
0,3,0,0,0,0,3,0
0,3,0,0,0,0,3,0
0,3,0,0,0,0,3,0
0,3,3,3,3,3,3,0
0,0,0,0,0,0,0,0
endlayer

layer
0,0,0,0,0,0,0,0
0,3,5,7,7,5,3,0
0,5,0,0,0,0,5,0
0,8,0,0,0,0,6,0
0,8,0,0,0,0,5,0
0,5,0,0,0,0,3,0
0,5,0,0,0,0,7,0
0,5,0,0,0,0,7,0
0,3,5,7,7,5,3,0
0,0,0,0,0,0,0,0
endlayer

layer
0,0,0,0,0,0,0,0
0,3,5,5,5,5,3,0
0,5,0,0,0,0,5,0
0,8,0,0,0,0,5,0
0,8,0,0,0,0,5,0
0,5,0,0,0,0,3,0
0,5,0,0,0,0,7,0
0,5,0,0,0,0,7,0
0,3,5,5,5,5,3,0
0,0,0,0,0,0,0,0
endlayer

layer
9,9,9,9,9,9,9,9
10,3,5,5,5,5,10,10
0,5,0,0,0,0,5,0
0,5,0,0,0,0,7,0
0,5,0,0,0,0,5,0
10,5,0,0,0,0,3,10
12,5,0,0,0,0,5,11
12,5,0,0,0,0,5,11
12,3,5,5,5,5,3,11
12,10,0,0,0,0,10,11
endlayer

layer
0,0,0,0,0,0,0,0
9,9,9,9,9,9,9,9
10,5,0,0,0,0,10,10
0,5,0,0,0,0,10,0
10,10,0,0,0,0,10,10
13,10,0,0,0,0,10,13
0,12,0,0,0,0,11,0
0,12,0,0,0,0,11,0
0,12,10,5,5,10,11,0
0,12,10,0,0,10,11,0
endlayer

layer
0,0,0,0,0,0,0,0
0,0,0,0,0,0,0,0
9,9,9,9,9,9,9,9
10,10,10,10,10,10,10,10
13,13,13,13,13,13,13,13
0,0,14,14,14,14,0,0
0,0,14,14,14,14,0,0
0,0,14,14,14,14,0,0
0,0,14,14,14,14,0,0
0,0,14,14,14,14,0,0
endlayer

layer
0,0,0,0,0,0,0,0
0,0,0,0,0,0,0,0
0,0,0,0,0,0,0,0
14,14,14,14,14,14,14,14
0,0,0,0,0,0,0,0
0,0,0,0,0,0,0,0
0,0,0,0,0,0,0,0
0,0,0,0,0,0,0,0
0,0,0,0,0,0,0,0
0,0,0,0,0,0,0,0
endlayer

