# Gilly's Cottage

weight=1
embed_into_distance=3
unacceptable_target_blocks=flowing_water,water,flowing_lava,lava,ice,bedrock,netherrack,soul_sand,Natura:Cloud
dimensions=18,15,13
cut_in_buffer=0
max_leveling=3
leveling_buffer=-3
preserve_water=0
preserve_lava=0
preserve_plants=0

rule1=0,100,preserveBlock
rule2=0,100,stonebrick,stonebrick,stonebrick,stonebrick,stonebrick,stonebrick,stonebrick-2
rule3=0,100,log
rule4=0,100,planks
rule5=0,100,planks-2
rule6=0,100,planks-5
rule7=0,100,wooden_slab-5
rule8=0,100,stained_hardened_clay-3
rule9=0,100,birch_stairs-1
rule10=0,100,birch_stairs-2

rule11=0,100,birch_stairs-7
rule12=0,100,birch_stairs
rule13=0,100,iron_bars
rule14=0,100,fence
rule15=0,100,wooden_door-2
rule16=0,100,wooden_door-8
rule17=0,100,wooden_door-9
rule18=0,100,birch_stairs-3
rule19=0,100,torch-5
rule20=0,100,bed-0
rule21=0,100,bed-8
rule22=0,100,planks-1
rule23=0,100,log-4
rule24=0,100,log-8
rule25=0,100,cauldron
rule26=0,100,furnace-4
rule27=0,100,cobblestone_wall
rule28=0,100,nether_brick_fence
rule29=0,100,carpet-7
rule30=0,100,double_stone_slab-8
rule31=0,100,double_stone_slab-0

layer
1,2,2,2,2,2,2,2,2,2,1,1,1
1,2,2,31,2,2,2,2,31,2,1,1,1
1,2,2,2,1,1,1,1,2,2,1,1,1
1,31,2,2,1,1,1,1,2,2,2,31,1
1,2,1,1,1,1,1,1,1,1,1,2,1
1,2,1,1,1,1,1,1,1,1,1,27,1
1,27,1,1,1,1,1,1,1,1,1,2,1
1,2,1,1,1,1,1,1,1,1,1,2,1
1,27,1,1,1,1,1,1,1,1,1,2,1
1,2,1,1,1,1,1,1,1,1,1,27,1
1,2,1,1,1,1,1,1,1,1,1,2,1
1,31,2,2,2,2,1,1,1,1,1,27,1
1,1,1,1,2,2,1,1,1,1,1,2,1
1,1,1,1,2,31,2,2,2,2,2,31,2
1,1,1,1,2,2,2,2,2,2,2,2,2
endlayer

layer
1,1,2,2,2,2,2,2,2,1,1,1,1
1,1,2,30,2,2,2,2,30,1,1,1,1
1,1,2,2,1,1,1,1,2,1,1,1,1
1,30,2,2,1,1,1,1,2,2,2,30,1
1,2,1,1,1,1,1,1,1,1,1,2,1
1,2,1,1,1,1,1,1,1,1,1,27,1
1,27,1,1,1,1,1,1,1,1,1,2,1
1,2,1,1,1,1,1,1,1,1,1,2,1
1,27,1,1,1,1,1,1,1,1,1,2,1
1,2,1,1,1,1,1,1,1,1,1,27,1
1,2,1,1,1,1,1,1,1,1,1,2,1
1,30,2,2,2,2,1,1,1,1,1,27,1
1,1,1,1,1,2,1,1,1,1,1,2,1
1,1,1,1,1,30,2,2,2,2,2,30,1
1,1,1,1,1,2,2,2,2,2,2,2,2
endlayer

layer
1,1,1,2,2,2,2,2,1,1,1,1,1
1,1,1,31,2,2,2,2,31,1,1,1,1
1,1,1,2,1,1,1,1,2,1,1,1,1
1,31,2,2,1,1,1,1,2,2,2,31,1
1,2,1,1,1,1,1,1,1,1,1,2,1
1,2,1,1,1,1,1,1,1,1,1,27,1
1,27,1,1,1,1,1,1,1,1,1,2,1
1,2,1,1,1,1,1,1,1,1,1,2,1
1,27,1,1,1,1,1,1,1,1,1,2,1
1,2,1,1,1,1,1,1,1,1,1,27,1
1,2,1,1,1,1,1,1,1,1,1,2,1
1,31,2,2,2,2,1,1,1,1,1,27,1
1,1,1,1,1,2,1,1,1,1,1,2,1
1,1,1,1,1,31,2,2,2,2,2,31,1
1,1,1,1,1,1,2,2,2,2,2,2,1
endlayer

layer
1,1,1,1,2,2,2,1,1,1,1,1,1
1,1,1,30,2,8,2,2,30,1,1,1,1
1,1,1,2,8,8,8,8,2,1,1,1,1
1,30,2,2,8,8,8,8,2,2,2,30,1
1,2,8,8,8,8,8,8,8,8,8,2,1
1,2,8,8,8,8,8,8,8,8,8,2,1
1,2,8,8,8,8,8,8,8,8,8,2,1
1,2,8,8,8,8,8,8,8,8,8,2,1
1,2,8,8,8,8,8,8,8,8,8,2,1
1,2,8,8,8,8,8,8,8,8,8,2,1
1,2,8,8,8,8,8,8,8,8,8,2,1
1,30,2,2,2,8,8,8,8,8,8,2,1
1,1,1,1,1,2,8,8,8,8,8,2,1
1,1,1,1,1,30,2,2,8,8,2,30,1
1,1,1,1,1,1,1,2,2,2,2,1,1
endlayer

layer
0,0,0,0,0,0,0,0,0,0,0,0,0
0,0,0,3,4,15,4,4,3,0,0,0,0
0,0,0,4,0,0,0,0,4,0,0,0,0
0,3,4,3,0,0,0,0,3,4,4,3,0
0,4,0,0,0,0,0,0,5,5,5,4,0
0,4,0,0,0,0,0,0,5,5,5,4,0
0,4,0,0,0,0,0,0,3,5,5,4,0
0,4,0,0,0,0,19,0,18,9,9,3,0
0,4,0,0,0,0,0,0,0,0,0,4,0
0,4,0,0,0,0,0,0,0,0,0,4,0
0,4,0,0,25,0,0,0,0,0,0,4,0
0,3,4,3,4,0,0,0,0,0,0,4,0
0,0,0,0,0,4,0,0,0,0,0,4,0
0,0,0,0,0,3,4,4,15,15,4,3,0
0,0,0,0,0,0,0,0,0,0,0,0,0
endlayer

layer
0,0,0,0,0,0,0,0,0,0,0,0,0
0,0,0,3,4,16,4,4,3,0,0,0,0
0,0,0,4,0,0,0,0,4,0,0,0,0
0,3,4,3,0,0,0,0,3,4,4,3,0
0,4,0,0,0,0,0,0,5,5,5,4,0
0,0,0,0,0,0,0,0,5,5,5,4,0
0,0,0,0,0,0,0,0,3,9,9,4,0
0,4,0,0,0,0,0,0,0,0,0,3,0
0,0,0,0,0,0,0,0,0,0,0,4,0
0,0,0,0,0,0,0,0,0,0,0,0,0
0,4,0,0,26,0,0,0,0,0,0,0,0
0,3,4,3,4,0,0,0,0,0,0,0,0
0,0,0,0,0,4,0,0,0,0,0,4,0
0,0,0,0,0,3,4,4,16,17,4,3,0
0,0,0,0,0,0,0,0,0,0,0,0,0
endlayer

layer
0,0,0,0,0,0,0,0,0,0,0,0,0
0,0,0,3,4,4,4,4,3,0,0,0,0
0,0,0,4,0,0,0,0,4,0,0,0,0
0,3,4,3,0,0,0,0,3,4,4,3,0
0,4,0,0,0,0,0,11,10,0,0,4,0
0,13,0,0,0,0,0,11,10,0,0,4,0
0,13,0,0,0,0,0,0,3,0,0,4,0
0,4,0,0,0,0,0,0,0,0,0,3,0
0,13,0,0,0,0,0,0,0,0,0,4,0
0,13,0,0,0,0,0,0,0,0,0,13,0
0,4,0,0,27,0,0,0,0,0,0,13,0
0,3,4,3,4,0,0,0,0,0,0,13,0
0,0,0,0,0,4,0,0,0,0,0,4,0
0,0,0,0,0,3,4,4,4,4,4,3,0
0,0,0,0,0,0,0,0,0,0,0,0,0
endlayer

layer
0,0,0,0,0,0,0,0,0,0,0,0,0
0,0,0,3,4,4,4,4,3,0,0,0,0
0,0,0,4,0,0,0,0,4,0,0,0,0
0,3,4,3,0,0,0,0,3,4,4,3,0
0,4,0,0,0,0,11,10,0,0,0,4,0
0,4,0,0,0,0,11,10,0,0,0,4,0
0,4,0,0,0,0,0,0,3,0,0,4,0
0,4,0,0,0,0,0,0,0,0,0,3,0
0,4,0,0,0,0,0,0,0,0,0,4,0
0,4,0,0,0,0,0,0,0,0,0,4,0
0,4,0,0,27,0,0,0,0,0,0,4,0
0,3,4,3,4,0,0,0,0,0,0,4,0
0,0,0,0,0,4,0,0,0,0,0,4,0
0,0,0,0,0,3,4,4,4,4,4,3,0
0,0,0,0,0,0,0,0,0,0,0,0,0
endlayer

layer
0,0,7,7,7,7,7,7,7,7,0,0,0
0,0,7,6,6,6,6,6,6,7,0,0,0
7,7,7,6,5,5,5,5,6,7,0,0,0
7,6,6,3,24,24,24,24,24,24,24,3,0
7,6,5,23,5,5,10,0,0,0,0,23,0
7,6,5,23,5,5,10,0,0,0,0,23,0
7,6,5,23,5,5,12,12,3,0,0,23,0
7,6,5,23,5,5,5,5,5,5,5,3,0
7,6,5,23,5,5,5,5,5,5,5,6,7
7,6,5,23,5,5,5,5,5,5,5,6,7
7,6,5,23,5,5,5,5,5,5,5,6,7
7,6,6,3,24,5,5,5,5,5,5,6,7
7,7,7,7,7,6,5,5,5,5,5,6,7
0,0,0,0,7,6,6,6,6,6,6,6,7
0,0,0,0,7,7,7,7,7,7,7,7,7
endlayer

layer
0,0,0,0,0,0,0,0,0,0,0,0,0
0,0,0,14,14,14,14,14,14,0,0,0,0
0,0,0,14,7,7,7,7,14,0,0,0,0
0,14,14,3,4,4,4,4,4,4,4,3,0
0,14,7,4,0,0,0,0,0,0,0,4,0
0,14,7,4,0,0,0,0,0,0,0,4,0
0,14,7,4,0,0,0,0,3,0,0,4,0
0,14,7,4,0,0,19,0,0,4,4,3,0
0,14,7,4,0,0,0,0,0,4,7,14,0
0,14,7,4,0,0,21,20,0,4,7,14,0
0,14,7,4,27,0,0,0,0,4,7,14,0
0,14,14,3,4,4,4,4,4,3,7,14,0
0,0,0,0,0,14,7,7,7,7,7,14,0
0,0,0,0,0,14,14,14,14,14,14,14,0
0,0,0,0,0,0,0,0,0,0,0,0,0
endlayer


layer
0,0,0,0,0,0,0,0,0,0,0,0,0
0,0,0,0,0,0,0,0,0,0,0,0,0
0,0,0,0,0,0,0,0,0,0,0,0,0
0,0,0,3,4,0,0,0,4,4,4,3,0
0,0,0,4,0,0,0,0,0,0,0,4,0
0,0,0,0,0,0,0,0,0,0,0,0,0
0,0,0,0,0,0,0,0,3,0,0,4,0
0,0,0,4,0,0,0,0,0,4,4,3,0
0,0,0,0,0,0,0,0,0,4,0,0,0
0,0,0,0,0,0,0,0,0,4,0,0,0
0,0,0,4,27,0,0,0,0,4,0,0,0
0,0,0,3,4,0,0,0,4,3,0,0,0
0,0,0,0,0,0,0,0,0,0,0,0,0
0,0,0,0,0,0,0,0,0,0,0,0,0
0,0,0,0,0,0,0,0,0,0,0,0,0
endlayer

layer
0,0,0,0,0,0,0,0,0,0,0,0,0
0,0,0,0,0,0,0,0,0,0,0,0,0
0,0,0,0,0,0,0,0,0,0,0,0,0
0,0,0,3,4,13,13,13,4,4,4,3,0
0,0,0,4,0,0,0,0,0,0,0,4,0
0,0,0,13,0,0,0,0,0,0,0,13,0
0,0,0,13,0,0,0,0,3,0,0,4,0
0,0,0,4,0,0,0,0,0,4,4,3,0
0,0,0,13,0,0,0,0,0,4,0,0,0
0,0,0,13,0,0,0,0,0,4,0,0,0
0,0,0,4,27,0,0,0,0,4,0,0,0
0,0,0,3,4,13,13,13,4,3,0,0,0
0,0,0,0,0,0,0,0,0,0,0,0,0
0,0,0,0,0,0,0,0,0,0,0,0,0
0,0,0,0,0,0,0,0,0,0,0,0,0
endlayer

layer
0,0,0,0,0,0,0,0,0,0,0,0,0
0,0,0,0,0,0,0,0,0,0,0,0,0
0,0,0,0,0,0,0,0,0,0,0,0,0
0,0,0,3,4,4,4,4,4,4,4,3,0
0,0,0,4,0,0,0,0,0,0,0,4,0
0,0,0,4,0,0,0,0,0,0,0,4,0
0,0,0,4,0,0,0,0,3,0,0,4,0
0,0,0,4,0,0,0,0,0,4,4,3,0
0,0,0,4,0,0,0,0,0,4,0,0,0
0,0,0,4,0,0,0,0,0,4,0,0,0
0,0,0,4,27,0,0,0,0,4,0,0,0
0,0,0,3,4,4,4,4,4,3,0,0,0
0,0,0,0,0,0,0,0,0,0,0,0,0
0,0,0,0,0,0,0,0,0,0,0,0,0
0,0,0,0,0,0,0,0,0,0,0,0,0
endlayer

layer
0,0,0,0,0,0,0,0,0,0,0,0,0
0,0,0,0,0,0,0,0,0,0,0,0,0
0,0,7,7,7,7,7,7,7,7,7,7,7
0,0,7,6,6,6,6,6,6,6,6,6,7
0,0,7,6,22,22,22,22,22,22,22,6,7
0,0,7,6,22,22,22,22,22,14,22,6,7
0,0,7,6,22,22,22,22,22,22,22,6,7
0,0,7,6,22,22,22,22,22,6,6,6,7
0,0,7,6,22,22,22,22,22,6,7,7,7
0,0,7,6,22,22,22,22,22,6,7,0,0
0,0,7,6,22,22,22,22,22,6,7,0,0
0,0,7,6,6,6,6,6,6,6,7,0,0
0,0,7,7,7,7,7,7,7,7,7,0,0
0,0,0,0,0,0,0,0,0,0,0,0,0
0,0,0,0,0,0,0,0,0,0,0,0,0
endlayer

layer
0,0,0,0,0,0,0,0,0,0,0,0,0
0,0,0,0,0,0,0,0,0,0,0,0,0
0,0,0,0,0,0,0,0,0,0,0,0,0
0,0,0,28,28,28,28,28,28,28,28,28,0
0,0,0,28,7,7,7,7,7,7,7,28,0
0,0,0,28,7,7,7,7,7,13,7,28,0
0,0,0,28,7,7,7,7,7,7,7,28,0
0,0,0,28,7,7,7,7,7,28,28,28,0
0,0,0,28,7,7,7,7,7,28,0,0,0
0,0,0,28,7,7,7,7,7,28,0,0,0
0,0,0,28,27,7,7,7,7,28,0,0,0
0,0,0,28,28,28,28,28,28,28,0,0,0
0,0,0,0,0,0,0,0,0,0,0,0,0
0,0,0,0,0,0,0,0,0,0,0,0,0
0,0,0,0,0,0,0,0,0,0,0,0,0
endlayer

layer
0,0,0,0,0,0,0,0,0,0,0,0,0
0,0,0,0,0,0,0,0,0,0,0,0,0
0,0,0,0,0,0,0,0,0,0,0,0,0
0,0,0,0,0,0,0,0,0,0,0,0,0
0,0,0,0,0,0,0,0,0,0,0,0,0
0,0,0,0,0,0,0,0,0,29,0,0,0
0,0,0,0,0,0,0,0,0,0,0,0,0
0,0,0,0,0,0,0,0,0,0,0,0,0
0,0,0,0,0,0,0,0,0,0,0,0,0
0,0,0,0,0,0,0,0,0,0,0,0,0
0,0,0,0,27,0,0,0,0,0,0,0,0
0,0,0,0,0,0,0,0,0,0,0,0,0
0,0,0,0,0,0,0,0,0,0,0,0,0
0,0,0,0,0,0,0,0,0,0,0,0,0
0,0,0,0,0,0,0,0,0,0,0,0,0
endlayer

layer
0,0,0,0,0,0,0,0,0,0,0,0,0
0,0,0,0,0,0,0,0,0,0,0,0,0
0,0,0,0,0,0,0,0,0,0,0,0,0
0,0,0,0,0,0,0,0,0,0,0,0,0
0,0,0,0,0,0,0,0,0,0,0,0,0
0,0,0,0,0,0,0,0,0,0,0,0,0
0,0,0,0,0,0,0,0,0,0,0,0,0
0,0,0,0,0,0,0,0,0,0,0,0,0
0,0,0,0,0,0,0,0,0,0,0,0,0
0,0,0,0,0,0,0,0,0,0,0,0,0
0,0,0,0,27,0,0,0,0,0,0,0,0
0,0,0,0,0,0,0,0,0,0,0,0,0
0,0,0,0,0,0,0,0,0,0,0,0,0
0,0,0,0,0,0,0,0,0,0,0,0,0
0,0,0,0,0,0,0,0,0,0,0,0,0
endlayer

layer
0,0,0,0,0,0,0,0,0,0,0,0,0
0,0,0,0,0,0,0,0,0,0,0,0,0
0,0,0,0,0,0,0,0,0,0,0,0,0
0,0,0,0,0,0,0,0,0,0,0,0,0
0,0,0,0,0,0,0,0,0,0,0,0,0
0,0,0,0,0,0,0,0,0,0,0,0,0
0,0,0,0,0,0,0,0,0,0,0,0,0
0,0,0,0,0,0,0,0,0,0,0,0,0
0,0,0,0,0,0,0,0,0,0,0,0,0
0,0,0,0,0,0,0,0,0,0,0,0,0
0,0,0,0,27,0,0,0,0,0,0,0,0
0,0,0,0,0,0,0,0,0,0,0,0,0
0,0,0,0,0,0,0,0,0,0,0,0,0
0,0,0,0,0,0,0,0,0,0,0,0,0
0,0,0,0,0,0,0,0,0,0,0,0,0
endlayer


