# Gilly's Bakery
# mineshaftCorridor, pyramidDesertyChest, pyramidJungleChest, pyramidJungleDispenser, dungeonChest 
# strongholdCorridor, strongholdLibrary, strongholdCrossing, villageBlacksmith, bonusChest

weight=1
embed_into_distance=3
unacceptable_target_blocks=flowing_water,water,flowing_lava,lava,ice,bedrock,netherrack,soul_sand,Natura:Cloud
dimensions=19,12,13
cut_in_buffer=0
max_leveling=3
leveling_buffer=-1
preserve_water=0
preserve_lava=0
preserve_plants=0

rule1=0,100,preserveBlock
rule2=0,100,stained_hardened_clay-9
rule3=0,100,stonebrick,stonebrick,stonebrick,stonebrick,stonebrick,stonebrick,stonebrick-2
rule4=0,100,log
rule5=0,100,planks-2
rule6=0,100,planks-5
rule7=0,100,wooden_slab-5
rule8=0,100,double_stone_slab-9
rule9=0,100,planks

rule10=0,100,mycelium
rule11=0,100,oak_stairs-1
rule12=0,100,oak_stairs-3
rule13=0,100,oak_stairs-6
rule14=0,100,iron_bars
rule15=0,100,fence
rule16=0,100,lit_pumpkin
rule17=0,100,cauldron
rule18=0,100,furnace-3
rule19=0,100,wooden_door-2
rule20=0,100,wooden_door-8
rule21=0,100,wooden_door-9
rule22=0,100,stone_slab-13
rule23=0,100,oak_stairs
rule24=0,100,torch-5
rule25=0,100,minecraft:bed-0
rule26=0,100,minecraft:bed-8
rule27=0,100,furnace-5
rule28=0,100,planks-1
rule29=0,100,log-4
rule30=0,100,log-8
rule31=0,100,stone_brick_stairs
rule32=0,100,stone_brick_stairs-1
rule33=0,100,stone_slab
rule34=0,100,ChestGenHook:mineshaftCorridor:5-2
rule35=0,100,ChestGenHook:strongholdLibrary:5-2
rule36=0,100,nether_brick_fence
rule37=0,100,stone_brick_stairs-3
rule38=0,100,stone_brick_stairs-2
rule39=0,100,double_stone_slab-8
rule40=0,100,cobblestone_wall
rule41=0,100,stained_hardened_clay-3
rule42=0,100,double_stone_slab-0
rule43=0,100,sandstone-2
rule44=0,100,oak_stairs-2
rule45=0,100,carpet-7

layer
1,1,1,1,1,1,1,1,1,3,3,3,1
1,42,3,40,3,40,3,40,3,3,3,3,3
1,3,1,1,1,1,1,1,1,3,3,3,3
1,40,1,1,1,1,1,1,1,3,3,3,3
1,3,1,1,1,1,1,1,1,1,1,3,1
1,40,1,1,1,1,1,1,1,1,1,40,1
1,3,1,1,1,1,1,1,1,1,1,3,1
1,3,1,1,1,1,1,1,1,1,1,3,1
1,40,1,1,1,1,1,1,1,1,1,40,1
1,3,1,1,1,1,1,1,1,1,1,3,1
1,42,3,40,3,40,3,40,3,40,3,42,1
1,1,1,3,3,1,1,1,1,1,1,3,3
endlayer

layer
1,1,1,1,1,1,1,1,1,3,3,3,1
1,39,3,40,3,40,3,40,3,3,3,3,3
1,3,1,1,1,1,1,1,1,3,3,3,3
1,40,1,1,1,1,1,1,1,3,3,3,3
1,3,1,1,1,1,1,1,1,1,1,3,1
1,40,1,1,1,1,1,1,1,1,1,40,1
1,3,1,1,1,1,1,1,1,1,1,3,1
1,3,1,1,1,1,1,1,1,1,1,3,1
1,40,1,1,1,1,1,1,1,1,1,40,1
1,3,1,1,1,1,1,1,1,1,1,3,1
1,39,3,40,3,40,3,40,3,40,3,39,1
1,1,1,1,3,3,1,1,1,1,3,3,1
endlayer

layer
1,1,1,1,1,1,1,1,1,3,3,3,1
1,42,3,40,3,40,3,40,3,3,3,3,3
1,3,1,1,1,1,1,1,1,3,3,3,3
1,40,1,1,1,1,1,1,1,3,3,3,3
1,3,1,1,1,1,1,1,1,1,1,3,1
1,40,1,1,1,1,1,1,1,1,1,40,1
1,3,1,1,1,1,1,1,1,1,1,3,1
1,3,1,1,1,1,1,1,1,1,1,3,1
1,40,1,1,1,1,1,1,1,1,1,40,1
1,3,1,1,1,1,1,1,1,1,1,3,1
1,42,3,40,3,40,3,40,3,40,3,42,1
1,1,1,1,1,3,3,3,3,3,3,1,1
endlayer

layer
1,1,1,1,1,1,1,1,1,3,3,3,1
1,39,3,3,3,3,3,3,3,3,10,16,3
1,3,2,2,41,41,41,41,41,3,10,10,3
1,3,2,2,41,41,41,41,41,3,3,3,3
1,3,2,2,41,41,41,41,41,3,3,3,1
1,3,2,2,2,2,2,2,2,2,2,3,1
1,3,2,2,2,2,2,2,2,2,2,3,1
1,3,2,2,2,2,2,2,2,2,2,3,1
1,3,2,2,2,2,2,2,2,2,2,3,1
1,3,2,2,2,2,2,2,2,2,2,3,1
1,39,3,3,3,3,3,2,2,3,3,39,1
1,1,1,1,1,1,3,3,3,3,1,1,1
endlayer

layer
0,0,0,0,0,0,0,0,0,3,3,3,0
0,4,43,43,43,43,43,43,43,39,0,17,3
0,43,9,9,34,0,0,0,0,0,0,0,3
0,43,9,9,35,0,0,0,0,0,0,39,3
0,43,9,9,4,39,39,39,0,0,0,43,0
0,8,11,11,44,0,0,0,0,0,0,8,0
0,8,0,0,0,0,0,0,0,0,0,8,0
0,8,0,0,0,0,0,0,0,0,0,8,0
0,8,0,0,0,0,0,0,0,0,0,8,0
0,43,0,0,0,0,0,0,0,0,0,43,0
0,4,43,8,8,43,43,19,19,43,43,4,0
0,0,0,0,0,0,0,0,0,0,0,0,0
endlayer

layer
0,0,0,0,0,0,0,0,0,3,3,3,0
0,4,5,5,5,5,5,5,5,27,0,0,3
0,5,9,9,13,0,0,0,0,0,0,0,3
0,5,9,9,13,0,0,0,0,0,0,18,3
0,5,11,11,4,24,0,0,0,0,0,5,0
0,0,0,0,0,0,0,0,0,0,0,0,0
0,0,0,0,0,0,0,0,0,0,0,0,0
0,0,0,0,0,0,0,0,0,0,0,0,0
0,0,0,0,0,0,0,0,0,0,0,0,0
0,5,0,0,0,0,0,0,0,0,0,5,0
0,4,5,0,0,5,5,20,21,5,5,4,0
0,0,0,0,0,0,0,0,0,0,0,0,0
endlayer

layer
0,0,0,0,0,0,0,0,0,3,3,3,0
0,4,5,5,5,5,5,5,5,27,0,0,3
0,5,0,0,12,13,0,0,0,0,22,0,3
0,5,0,0,12,13,0,0,0,0,0,18,3
0,5,0,0,4,0,0,0,0,0,0,5,0
0,14,0,0,0,0,0,0,0,0,0,14,0
0,14,0,0,0,0,0,0,0,0,0,14,0
0,14,0,0,0,0,0,0,0,0,0,14,0
0,14,0,0,0,0,0,0,0,0,0,14,0
0,5,0,0,0,0,0,0,0,0,0,5,0
0,4,5,14,14,5,5,15,15,5,5,4,0
0,0,0,0,0,0,0,0,0,0,0,0,0
endlayer

layer
0,0,0,0,0,0,0,0,0,31,3,3,0
0,4,5,5,5,5,5,5,5,3,3,0,3
0,5,0,0,0,12,13,0,0,0,3,3,3
0,5,0,0,0,12,13,0,0,0,0,3,38
0,5,0,0,4,0,0,0,0,0,0,5,0
0,5,0,0,0,0,0,0,0,0,0,5,0
0,5,0,0,0,0,0,0,0,0,0,5,0
0,5,0,0,0,0,0,0,0,0,0,5,0
0,5,0,0,0,0,0,0,0,0,0,5,0
0,5,0,0,0,0,0,0,0,0,0,5,0
0,4,5,5,5,5,5,5,5,5,5,4,0
0,0,0,0,0,0,0,0,0,0,0,0,0
endlayer

layer
0,0,0,0,0,0,0,0,0,0,3,3,0
0,4,30,30,30,30,30,30,30,30,3,0,3
0,29,0,0,0,0,12,9,9,9,9,3,3
0,29,0,0,0,0,12,9,9,9,9,29,0
0,29,0,0,4,23,23,9,9,9,9,29,0
0,29,0,0,9,9,9,9,9,9,9,29,0
0,29,9,9,9,9,9,9,9,9,9,29,0
0,29,9,9,9,9,9,9,9,9,9,29,0
0,29,9,9,9,9,9,9,9,9,9,29,0
0,29,9,9,9,9,9,9,9,9,9,29,0
0,4,30,30,30,30,30,30,30,30,30,4,0
0,0,0,0,0,0,0,0,0,0,0,0,0
endlayer

layer
0,0,0,0,0,0,0,0,0,0,3,3,0
0,4,5,5,5,5,5,5,5,5,3,0,3
0,5,0,0,0,0,0,0,0,0,0,3,3
0,5,0,0,0,0,0,0,0,0,0,5,0
0,5,0,0,4,0,0,0,0,0,0,5,0
0,4,5,5,5,5,0,0,24,0,0,5,0
0,15,0,0,0,5,0,0,0,0,0,5,0
0,15,0,0,0,19,0,0,0,0,0,5,0
0,15,0,0,0,5,0,0,26,25,0,5,0
0,15,0,0,0,5,0,0,0,0,0,5,0
0,15,15,15,15,4,5,5,5,5,5,4,0
0,0,0,0,0,0,0,0,0,0,0,0,0
endlayer

layer
0,0,0,0,0,0,0,0,0,0,3,3,0
0,4,5,5,5,0,0,0,0,5,3,0,3
0,5,0,0,0,0,0,0,0,0,0,3,3
0,5,0,0,0,0,0,0,0,0,0,5,0
0,5,0,0,4,0,0,0,0,0,0,5,0
0,4,5,5,5,5,0,0,0,0,0,0,0
0,0,0,0,0,5,0,0,0,0,0,0,0
0,0,0,0,0,20,0,0,0,0,0,0,0
0,0,0,0,0,5,0,0,0,0,0,0,0
0,0,0,0,0,5,0,0,0,0,0,5,0
0,0,0,0,0,4,5,0,0,0,5,4,0
0,0,0,0,0,0,0,0,0,0,0,0,0
endlayer

layer
0,0,0,0,0,0,0,0,0,0,3,3,0
0,4,5,5,5,14,14,14,14,5,3,0,3
0,5,0,0,0,0,0,0,0,0,0,3,3
0,5,0,0,0,0,0,0,0,0,0,5,0
0,5,0,0,4,0,0,0,0,0,0,5,0
0,4,5,5,5,5,0,0,0,0,0,14,0
0,0,0,0,0,5,0,0,0,0,0,14,0
0,0,0,0,0,5,0,0,0,0,0,14,0
0,0,0,0,0,5,0,0,0,0,0,14,0
0,0,0,0,0,5,0,0,0,0,0,5,0
0,0,0,0,0,4,5,14,14,14,5,4,0
0,0,0,0,0,0,0,0,0,0,0,0,0
endlayer

layer
0,0,0,0,0,0,0,0,0,0,3,3,0
0,4,5,5,5,5,5,5,5,5,3,0,3
0,5,0,0,0,0,0,0,0,0,0,3,3
0,5,0,0,0,0,0,0,0,0,0,5,0
0,5,0,0,4,0,0,0,0,0,0,5,0
0,4,5,5,5,5,0,0,0,0,0,5,0
0,0,0,0,0,5,0,0,0,0,0,5,0
0,0,0,0,0,5,0,0,0,0,0,5,0
0,0,0,0,0,5,0,0,0,0,0,5,0
0,0,0,0,0,5,0,0,0,0,0,5,0
0,0,0,0,0,4,5,5,5,5,5,4,0
0,0,0,0,0,0,0,0,0,0,0,0,0
endlayer

layer
7,7,7,7,7,7,7,7,7,7,31,3,0
7,6,6,6,6,6,6,6,6,6,3,0,3
7,6,28,28,28,28,28,28,28,28,28,3,38
7,6,28,15,28,28,28,28,28,28,28,6,7
7,6,28,28,28,28,28,28,28,28,28,6,7
7,6,6,6,6,6,28,28,28,28,28,6,7
7,7,7,7,7,6,28,28,28,28,28,6,7
0,0,0,0,7,6,28,28,28,28,28,6,7
0,0,0,0,7,6,28,28,28,28,28,6,7
0,0,0,0,7,6,28,28,28,28,28,6,7
0,0,0,0,7,6,6,6,6,6,6,6,7
0,0,0,0,7,7,7,7,7,7,7,7,7
endlayer

layer
0,0,0,0,0,0,0,0,0,0,0,3,0
0,36,36,36,36,36,36,36,36,36,3,0,3
0,36,7,7,7,7,7,7,7,7,7,3,0
0,36,7,14,7,7,7,7,7,7,7,36,0
0,36,7,7,7,7,7,7,7,7,7,36,0
0,36,36,36,36,36,7,7,7,7,7,36,0
0,0,0,0,0,36,7,7,7,7,7,36,0
0,0,0,0,0,36,7,7,7,7,7,36,0
0,0,0,0,0,36,7,7,7,7,7,36,0
0,0,0,0,0,36,7,7,7,7,7,36,0
0,0,0,0,0,36,36,36,36,36,36,36,0
0,0,0,0,0,0,0,0,0,0,0,0,0
endlayer

layer
0,0,0,0,0,0,0,0,0,0,0,3,0
0,0,0,0,0,0,0,0,0,0,3,0,3
0,0,0,0,0,0,0,0,0,0,0,3,0
0,0,0,45,0,0,0,0,0,0,0,0,0
0,0,0,0,0,0,0,0,0,0,0,0,0
0,0,0,0,0,0,0,0,0,0,0,0,0
0,0,0,0,0,0,0,0,0,0,0,0,0
0,0,0,0,0,0,0,0,0,0,0,0,0
0,0,0,0,0,0,0,0,0,0,0,0,0
0,0,0,0,0,0,0,0,0,0,0,0,0
0,0,0,0,0,0,0,0,0,0,0,0,0
0,0,0,0,0,0,0,0,0,0,0,0,0
endlayer

layer
0,0,0,0,0,0,0,0,0,0,0,3,0
0,0,0,0,0,0,0,0,0,0,3,0,3
0,0,0,0,0,0,0,0,0,0,0,3,0
0,0,0,0,0,0,0,0,0,0,0,0,0
0,0,0,0,0,0,0,0,0,0,0,0,0
0,0,0,0,0,0,0,0,0,0,0,0,0
0,0,0,0,0,0,0,0,0,0,0,0,0
0,0,0,0,0,0,0,0,0,0,0,0,0
0,0,0,0,0,0,0,0,0,0,0,0,0
0,0,0,0,0,0,0,0,0,0,0,0,0
0,0,0,0,0,0,0,0,0,0,0,0,0
0,0,0,0,0,0,0,0,0,0,0,0,0
endlayer


layer
0,0,0,0,0,0,0,0,0,0,0,31,0
0,0,0,0,0,0,0,0,0,0,37,14,38
0,0,0,0,0,0,0,0,0,0,0,32,0
0,0,0,0,0,0,0,0,0,0,0,0,0
0,0,0,0,0,0,0,0,0,0,0,0,0
0,0,0,0,0,0,0,0,0,0,0,0,0
0,0,0,0,0,0,0,0,0,0,0,0,0
0,0,0,0,0,0,0,0,0,0,0,0,0
0,0,0,0,0,0,0,0,0,0,0,0,0
0,0,0,0,0,0,0,0,0,0,0,0,0
0,0,0,0,0,0,0,0,0,0,0,0,0
0,0,0,0,0,0,0,0,0,0,0,0,0
endlayer


layer
0,0,0,0,0,0,0,0,0,0,0,33,0
0,0,0,0,0,0,0,0,0,0,33,0,33
0,0,0,0,0,0,0,0,0,0,0,33,0
0,0,0,0,0,0,0,0,0,0,0,0,0
0,0,0,0,0,0,0,0,0,0,0,0,0
0,0,0,0,0,0,0,0,0,0,0,0,0
0,0,0,0,0,0,0,0,0,0,0,0,0
0,0,0,0,0,0,0,0,0,0,0,0,0
0,0,0,0,0,0,0,0,0,0,0,0,0
0,0,0,0,0,0,0,0,0,0,0,0,0
0,0,0,0,0,0,0,0,0,0,0,0,0
0,0,0,0,0,0,0,0,0,0,0,0,0
endlayer
