# Converted from schematic
# THIS TEMPLATE USES DEFAULTS!  Please edit for corrections.
# If you need help, consult template_rules.txt

weight=3
embed_into_distance=1
acceptable_target_blocks=1,2,3,12,13
dimensions=7,9,8
allowable_overhang=0
max_cut_in=2
cut_in_buffer=1
max_leveling=2
leveling_buffer=1
preserve_water=0
preserve_lava=0
preserve_plants=0


rule1=0,100,2
rule2=0,100,5
rule3=0,100,3
rule4=0,100,17
rule5=0,100,37
rule6=0,100,85
rule7=0,100,64-1
rule8=0,100,72
rule9=0,100,47
rule10=0,100,31-1
rule11=0,100,54-5
rule12=0,100,26-3
rule13=0,100,26-11
rule14=0,100,50-4
rule15=0,100,20
rule16=0,100,64-9
rule17=0,100,50-3
rule18=0,100,44-2
rule19=0,100,43-2
rule20=0,100,44-3
rule21=0,100,4
rule22=0,100,50-5
rule23=0,100,43-3


layer
1,1,1,1,1,1,1,1
1,3,3,3,3,3,3,1
1,3,4,4,4,4,3,1
1,3,4,2,2,4,3,2
1,3,4,2,2,4,2,2
1,3,4,2,2,4,3,2
1,3,4,4,4,4,3,1
1,3,3,3,3,3,3,1
1,1,1,1,3,1,1,1
endlayer

layer
0,0,0,0,0,0,0,0
0,2,2,2,2,2,2,0
0,2,11,0,0,2,2,5
0,2,0,0,6,0,2,6
0,2,0,0,0,8,7,0
0,2,12,0,0,0,2,6
0,2,13,0,0,9,2,5
0,2,2,2,2,2,2,0
0,0,10,10,0,0,0,5
endlayer

layer
0,0,0,0,0,0,0,0
0,2,2,15,15,2,2,0
0,2,14,0,0,0,15,0
0,15,0,0,8,17,2,14
0,15,0,0,0,0,16,0
0,15,0,0,0,17,2,14
0,2,14,0,0,0,15,0
0,2,2,15,15,2,2,0
0,0,0,0,0,0,0,0
endlayer

layer
0,0,0,0,0,0,0,0
17,2,2,15,15,2,2,0
0,2,0,0,0,0,15,0
0,15,0,0,0,0,2,18
0,15,0,0,0,0,2,18
0,15,0,0,0,0,2,18
0,2,0,0,0,0,15,0
0,2,2,15,15,2,2,0
0,0,0,0,0,0,0,0
endlayer

layer
0,0,0,18,18,0,0,0
0,2,2,2,2,2,2,0
0,2,18,19,19,19,19,18
18,2,18,4,4,2,19,0
18,2,18,4,4,2,2,0
18,2,18,4,4,2,2,0
0,2,18,18,18,19,2,18
0,2,2,2,2,2,2,0
0,0,0,18,18,0,0,0
endlayer

layer
20,20,20,20,20,20,20,20
20,21,21,21,21,21,21,20
20,21,0,0,0,0,21,20
20,21,0,0,0,0,21,20
20,21,23,0,0,22,21,20
20,21,0,0,0,0,21,20
20,21,0,0,0,0,21,20
20,21,21,21,21,21,21,20
20,20,20,20,20,20,20,20
endlayer

layer
0,0,0,0,0,0,0,0
0,0,0,0,0,0,0,0
0,0,20,20,20,20,0,0
0,0,20,23,23,20,0,0
0,0,20,23,23,20,0,0
0,0,20,23,23,20,0,0
0,0,20,20,20,20,0,0
0,0,0,0,0,0,0,0
0,0,0,0,0,0,0,0
endlayer

