# Converted from schematic
# THIS TEMPLATE USES DEFAULTS!  Please edit for corrections.
# If you need help, consult template_rules.txt

weight=2
embed_into_distance=1
acceptable_target_blocks=1,2,3,12,13
dimensions=6,9,9
allowable_overhang=0
max_cut_in=2
cut_in_buffer=1
max_leveling=2
leveling_buffer=1
preserve_water=0
preserve_lava=0
preserve_plants=0


rule1=0,100,2
rule2=0,100,3
rule3=0,100,17
rule4=0,100,5
rule5=0,100,61-5
rule6=0,100,54-3
rule7=0,100,58
rule8=0,100,26
rule9=0,100,72
rule10=0,100,64-2
rule11=0,100,26-8
rule12=0,100,20
rule13=0,100,50-1
rule14=0,100,125
rule15=0,100,64-10
rule16=0,100,47
rule17=0,100,44-3
rule18=0,100,4


layer
1,1,1,1,1,1,1,1,1
1,1,2,2,2,2,2,1,1
1,2,3,3,3,3,3,2,1
1,2,3,3,3,4,3,2,1
1,2,3,3,4,3,3,2,1
1,2,3,3,4,3,3,2,1
1,2,3,3,3,3,3,2,1
1,1,2,2,3,2,2,1,1
1,1,1,1,1,1,1,1,1
endlayer

layer
0,0,0,0,0,0,0,0,0
0,0,4,4,4,4,4,0,0
0,4,0,0,0,7,5,4,0
0,4,0,11,8,0,0,4,0
0,4,0,0,0,0,0,4,0
0,4,4,0,0,0,6,4,0
0,4,4,0,9,0,6,4,0
0,0,4,4,10,4,4,0,0
0,0,0,0,0,0,0,0,0
endlayer

layer
0,0,0,0,0,0,0,0,0
0,0,4,12,12,12,4,0,0
0,4,0,0,0,0,13,4,0
0,12,0,0,0,0,0,12,0
0,12,0,0,0,0,0,12,0
0,12,16,0,0,0,0,12,0
0,4,16,0,0,0,0,4,0
0,0,14,12,15,12,14,0,0
0,0,0,0,0,0,0,0,0
endlayer

layer
0,0,0,0,0,0,0,0,0
0,0,4,12,12,12,4,0,0
0,4,0,0,0,0,0,4,0
0,12,0,0,0,0,0,12,0
0,12,0,0,0,0,0,12,0
0,12,0,0,0,0,0,12,0
0,4,0,0,0,0,0,4,0
0,0,4,4,4,4,4,0,0
0,0,13,0,0,0,13,0,0
endlayer

layer
0,0,17,17,17,17,17,0,0
0,17,18,18,18,18,18,0,0
17,18,18,18,18,18,18,18,17
17,18,18,0,0,0,18,18,17
17,18,18,0,0,0,18,18,17
17,18,18,0,0,0,18,18,17
17,18,18,18,18,18,18,18,17
0,17,18,18,18,18,18,17,0
0,0,17,17,17,17,17,0,0
endlayer

layer
0,0,0,0,0,0,0,0,0
0,0,0,0,0,0,0,0,0
0,0,17,17,17,17,17,0,0
0,0,17,18,18,18,17,0,0
0,0,17,18,18,18,17,0,0
0,0,17,18,18,18,17,0,0
0,0,17,17,17,17,17,0,0
0,0,0,0,0,0,0,0,0
0,0,0,0,0,0,0,0,0
endlayer

