weight=1

embed_into_distance=1
acceptable_target_blocks=1,2,3,12,13

dimensions=26,9,9

allowable_overhang=0

max_cut_in=25

cut_in_buffer=1

max_leveling=2

leveling_buffer=1

preserve_water=0

preserve_lava=0

preserve_plants=0




rule1=0,0,35-14

rule2=0,100,98

rule3=0,100,98-3

rule4=0,100,4

rule5=0,80,35-12,35-7,5-2,35-12,35-7,5-2,86,103,133

rule6=0,100,54,EasyChest,MediumChest,HardChest

rule7=0,50,58

rule8=0,100,64

rule9=0,100,109

rule10=0,100,64-8

rule11=0,100,109-3

rule12=0,100,5-1

rule13=0,100,109-1

rule14=0,100,47

rule15=0,50,61-5

rule16=0,100,102

rule17=0,100,44-13

rule18=0,100,109-7

rule19=0,100,109-2

rule20=0,100,26-10

rule21=0,100,26-2

rule22=0,100,126-1

rule23=0,100,109-5

rule24=0,100,65-3

rule25=0,100,49

rule26=0,100,69-10

rule27=0,100,55

rule28=0,100,93-13

rule29=0,100,55-15

rule30=0,100,75-2

rule31=0,100,55-14

rule32=0,100,55-13

rule33=0,100,35-11

rule34=0,100,76-3

rule35=0,100,35-3

rule36=0,100,20

rule37=0,100,5-2

rule38=0,100,65-2

rule39=0,100,76-1

rule40=0,100,123

rule41=0,100,126-3

rule42=0,100,5-3




layer
1,1,2,2,2,3,3,1,1
1,2,2,4,4,4,2,2,1
3,2,4,4,4,4,4,2,2
3,4,4,4,4,4,4,4,2
2,4,4,4,4,4,4,4,2
2,4,4,4,4,4,4,4,3
2,4,4,4,4,4,4,4,3
1,2,2,4,4,4,2,2,1
1,1,3,3,2,2,2,1,1
endlayer

layer
0,0,2,2,8,3,3,0,0
0,3,2,0,0,0,2,3,0
3,2,0,0,0,0,7,2,2
3,0,0,0,0,0,0,5,2
2,5,0,0,0,0,0,5,2
2,5,0,0,0,0,0,0,3
2,5,0,9,2,2,6,6,3
0,3,2,2,2,2,2,3,0
0,0,3,3,2,2,2,0,0
endlayer

layer
0,0,3,2,10,2,3,0,0
0,3,2,0,0,0,2,3,0
3,2,0,0,0,0,0,2,3
2,0,0,0,0,0,0,5,2
2,5,0,0,0,0,0,5,2
2,5,0,0,0,0,0,0,2
3,5,0,0,11,2,6,6,3
0,3,2,2,2,2,2,3,0
0,0,3,2,2,2,3,0,0
endlayer

layer
0,0,3,3,2,2,2,0,0
0,3,2,0,0,0,2,3,0
2,2,0,0,0,0,0,2,3
2,0,0,0,0,0,0,0,3
2,0,0,0,0,0,0,0,2
3,0,0,0,0,0,0,0,2
3,0,0,0,0,11,0,0,2
0,3,2,2,2,2,2,3,0
0,0,2,2,2,3,3,0,0
endlayer

layer
0,0,3,3,3,2,2,0,0
0,2,2,12,12,12,2,2,0
2,2,12,12,12,12,12,2,3
2,12,12,12,12,12,12,12,3
3,12,12,12,12,12,12,12,3
3,12,12,12,12,13,12,12,2
3,2,2,0,0,0,2,2,2
0,2,2,2,2,2,2,2,0
0,0,2,2,3,3,3,0,0
endlayer

layer
0,0,0,3,3,2,0,0,0
0,0,2,2,2,2,2,0,0
0,2,2,15,0,0,2,2,0
2,2,0,0,0,0,14,2,3
3,2,5,0,0,0,0,2,3
3,2,5,0,0,0,0,2,2
0,2,2,9,0,0,2,2,0
0,0,2,2,2,2,2,0,0
0,0,0,2,3,3,0,0,0
endlayer

layer
0,0,0,0,0,0,0,0,0
0,0,0,2,3,3,0,0,0
0,0,2,0,0,0,2,0,0
0,3,0,0,0,0,14,2,0
0,3,5,0,0,0,0,3,0
0,2,5,0,0,0,0,3,0
0,0,2,0,11,0,2,0,0
0,0,0,3,3,2,0,0,0
0,0,0,0,0,0,0,0,0
endlayer

layer
0,0,0,0,0,0,0,0,0
0,0,0,2,16,3,0,0,0
0,0,3,0,0,0,3,0,0
0,3,0,0,0,0,0,2,0
0,16,0,0,0,0,0,16,0
0,2,0,0,0,0,17,3,0
0,0,3,0,0,11,3,0,0
0,0,0,3,16,2,0,0,0
0,0,0,0,0,0,0,0,0
endlayer

layer
0,0,0,0,0,0,0,0,0
0,0,0,3,16,2,0,0,0
0,0,3,0,0,0,3,0,0
0,2,0,0,0,0,0,3,0
0,16,0,0,0,0,0,16,0
0,3,0,0,18,13,2,2,0
0,0,3,0,0,0,3,0,0
0,0,0,2,16,3,0,0,0
0,0,0,0,0,0,0,0,0
endlayer

layer
0,0,0,0,0,0,0,0,0
0,0,0,3,3,2,0,0,0
0,0,2,0,0,0,2,0,0
0,2,0,0,0,0,0,3,0
0,3,0,0,0,0,0,3,0
0,3,0,18,19,0,2,2,0
0,0,2,0,0,0,2,0,0
0,0,0,2,3,3,0,0,0
0,0,0,0,0,0,0,0,0
endlayer

layer
0,0,0,0,0,0,0,0,0
0,0,0,2,3,3,0,0,0
0,0,2,12,12,12,2,0,0
0,3,12,12,12,12,12,2,0
0,3,12,12,12,12,12,3,0
0,2,12,19,0,0,12,3,0
0,0,2,12,12,0,2,0,0
0,0,0,3,3,2,0,0,0
0,0,0,0,0,0,0,0,0
endlayer

layer
0,0,0,0,0,0,0,0,0
0,0,0,2,2,3,0,0,0
0,0,3,13,2,2,3,0,0
0,3,0,0,0,21,20,2,0
0,2,0,0,0,0,0,2,0
0,2,0,0,0,0,5,3,0
0,0,3,5,0,22,3,0,0
0,0,0,3,2,2,0,0,0
0,0,0,0,0,0,0,0,0
endlayer

layer
0,0,0,0,0,0,0,0,0
0,0,0,3,2,2,0,0,0
0,0,3,0,11,2,3,0,0
0,2,0,0,0,0,0,3,0
0,16,0,0,0,0,0,16,0
0,3,0,0,0,0,5,2,0
0,0,3,5,0,0,3,0,0
0,0,0,2,16,3,0,0,0
0,0,0,0,0,0,0,0,0
endlayer

layer
0,0,0,0,0,0,0,0,0
0,0,0,3,16,2,0,0,0
0,0,2,0,0,11,2,0,0
0,2,0,0,0,23,0,3,0
0,16,0,0,0,0,0,16,0
0,3,0,0,0,0,0,2,0
0,0,2,0,0,0,2,0,0
0,0,0,2,16,3,0,0,0
0,0,0,0,0,0,0,0,0
endlayer

layer
0,0,0,0,0,0,0,0,0
0,0,0,2,3,3,0,0,0
0,0,2,0,0,0,2,0,0
0,3,0,0,0,9,17,2,0
0,3,0,0,0,0,0,3,0
0,2,0,0,0,0,0,3,0
0,0,2,0,0,0,2,0,0
0,0,0,3,3,2,0,0,0
0,0,0,0,0,0,0,0,0
endlayer

layer
0,0,0,0,0,0,0,0,0
0,0,0,2,2,3,0,0,0
0,0,3,12,0,0,3,0,0
0,3,12,12,12,0,12,2,0
0,2,12,12,12,9,12,2,0
0,2,12,12,12,12,12,3,0
0,0,3,12,12,12,3,0,0
0,0,0,3,2,2,0,0,0
0,0,0,0,0,0,0,0,0
endlayer

layer
0,0,0,0,0,0,0,0,0
0,0,0,3,2,2,0,0,0
0,0,3,0,22,0,3,0,0
0,2,30,27,0,0,0,3,0
0,2,25,28,0,0,24,2,0
0,3,31,29,26,0,0,2,0
0,0,3,25,25,25,3,0,0
0,0,0,2,2,3,0,0,0
0,0,0,0,0,0,0,0,0
endlayer

layer
0,0,0,0,0,0,0,0,0
0,0,0,3,16,2,0,0,0
0,0,2,0,0,0,2,0,0
0,2,0,0,0,0,0,3,0
0,16,32,0,0,0,24,3,0
0,3,0,0,0,30,0,2,0
0,0,2,31,29,25,2,0,0
0,0,0,2,16,3,0,0,0
0,0,0,0,0,0,0,0,0
endlayer

layer
0,0,0,0,0,0,0,0,0
0,0,0,2,16,3,0,0,0
0,0,2,0,0,0,2,0,0
0,3,0,0,0,0,0,2,0
0,16,0,0,0,0,24,3,0
0,2,0,0,34,33,0,3,0
0,0,2,0,0,33,2,0,0
0,0,0,3,16,2,0,0,0
0,0,0,0,0,0,0,0,0
endlayer

layer
0,0,0,0,0,0,0,0,0
0,0,0,2,2,3,0,0,0
0,0,2,0,0,0,2,0,0
0,3,0,0,0,0,0,2,0
0,2,0,0,30,0,24,2,0
0,2,0,0,35,33,0,3,0
0,0,2,0,0,33,2,0,0
0,0,0,3,2,2,0,0,0
0,0,0,0,0,0,0,0,0
endlayer

layer
0,0,0,0,0,0,0,0,0
0,0,16,36,36,36,16,0,0
0,16,36,37,37,37,36,16,0
0,36,37,37,35,37,37,36,0
0,36,37,35,25,35,38,36,0
0,36,37,37,39,37,37,36,0
0,16,36,37,37,37,36,16,0
0,0,16,36,36,36,16,0,0
0,0,0,0,0,0,0,0,0
endlayer

layer
0,0,0,0,0,0,0,0,0
0,0,0,16,16,16,0,0,0
0,0,16,16,0,16,16,0,0
0,16,16,0,35,0,16,16,0
0,16,0,35,30,35,0,16,0
0,16,16,0,35,0,16,16,0
0,0,16,16,0,16,16,0,0
0,0,0,16,16,16,0,0,0
0,0,0,0,0,0,0,0,0
endlayer

layer
0,0,0,0,0,0,0,0,0
0,0,0,16,16,16,0,0,0
0,0,16,16,0,16,16,0,0
0,16,16,0,0,0,16,16,0
0,16,0,0,40,0,0,16,0
0,16,16,0,0,0,16,16,0
0,0,16,16,0,16,16,0,0
0,0,0,16,16,16,0,0,0
0,0,0,0,0,0,0,0,0
endlayer

layer
0,0,0,0,0,0,0,0,0
0,0,0,16,16,16,0,0,0
0,0,16,16,0,16,16,0,0
0,16,16,0,0,0,16,16,0
0,16,0,0,40,0,0,16,0
0,16,16,0,0,0,16,16,0
0,0,16,16,0,16,16,0,0
0,0,0,16,16,16,0,0,0
0,0,0,0,0,0,0,0,0
endlayer

layer
0,0,0,0,0,0,0,0,0
0,0,0,41,41,41,0,0,0
0,0,41,42,42,42,41,0,0
0,41,42,42,42,42,42,41,0
0,41,42,42,42,42,42,41,0
0,41,42,42,42,42,42,41,0
0,0,41,42,42,42,41,0,0
0,0,0,41,41,41,0,0,0
0,0,0,0,0,0,0,0,0
endlayer

layer
0,0,0,0,0,0,0,0,0
0,0,0,0,0,0,0,0,0
0,0,0,0,0,0,0,0,0
0,0,0,41,41,41,0,0,0
0,0,0,41,42,41,0,0,0
0,0,0,41,41,41,0,0,0
0,0,0,0,0,0,0,0,0
0,0,0,0,0,0,0,0,0
0,0,0,0,0,0,0,0,0
endlayer

