#based on an unnamed building in the City of GreenField http://www.planetminecraft.com/project/greenfield---new-life-size-city-project/

acceptable_target_blocks=1,2,3,12,13,24
weight=1
embed_into_distance=1
dimensions=50,21,21
max_leveling=4
leveling_buffer=0
max_cut_in=25
preserve_plants=1



preserve_water=1


rule1=0,100,48,48,48,48,48,48,48,48,48,48,48,48,48,48,48,48,48,48,48,48,48,48,48,48,48,48,48,48,48,48,48,48,48,48,48,48,48,48,48,48,48,48,48,48,48,48,48,48,48,48,48,48,48,48,48,48,48,48,48,48,48,48,48,48,48,48,48,48,48,48,48,48,48,48,48,48,48,48,48,48,48,48,48,48,48,48,48,48,48,48,48,48,48,48,48,48,48,48,48,48,48,48,48,48,48,48,48,48,48,48,48,48,48,48,48,48,48,73
rule2=0,100,98,98,98,98,98-1,98-1,98-2
rule3=0,100,48,48,48,48,48,48,48,48,48,48,48,48,48,48,48,48,48,48,48,48,48,48,48,48,48,48,48,48,48,48,48,48,48,48,48,48,48,48,48,48,48,48,48,48,48,48,48,48,48,48,48,48,48,48,48,48,48,48,48,48,48,48,48,48,48,48,48,48,48,48,48,48,48,48,48,48,48,48,48,48,48,48,48,48,48,48,48,48,48,48,48,48,48,48,48,48,48,48,48,48,48,48,48,48,48,48,15
rule4=0,100,9
rule5=0,100,98-3
rule6=0,100,24
rule7=0,100,71-1
rule8=0,100,109-3
rule9=0,100,71
rule10=0,100,70
rule11=0,100,109-2
rule12=0,80,20
rule13=0,100,109-2
rule14=0,50,118
rule15=0,100,102
rule16=0,50,65-2
rule17=0,100,71-2
rule18=1,5,HardMobSpawn,HardMobSpawn,HardMobSpawn,EasyChest,MediumChest,HardChest,35-7,35-12,5-2
rule19=0,100,71-3
rule20=0,100,71-8
rule21=0,100,77-2
rule22=0,100,71-9
rule23=0,100,68-4
rule24=0,100,44-5
rule25=0,100,109
rule26=0,100,98,98,98,98,98-1,98-1,98-2
rule27=0,100,35-11
rule28=0,85,48
rule29=0,100,109-1
rule30=0,100,109-3
rule31=1,100,48
rule32=0,100,109-7
rule33=0,100,64-2
rule34=0,100,64-1
rule35=0,100,64-8
rule36=0,100,109-6
rule37=0,70,98-2,98-1,98-2,4
rule38=1,50,20
rule39=1,90,98-2,98-1,98-2,4
rule40=2,50,48,48,48,48,48,48,48,48,48,48,48,48,48,48,48,48,48,48,48,48,48,48,48,48,48,48,48,48,48,48,48,48,48,48,48,48,48,48,48,48,48,48,48,48,48,48,48,48,48,48,48,48,48,48,48,48,48,48,48,48,48,48,48,48,48,48,48,48,48,48,48,48,48,48,48,48,48,48,48,48,48,48,48,48,48,48,48,48,48,48,48,48,48,48,48,48,48,15
rule41=0,100,4
rule42=0,100,35-3
rule43=0,90,101
rule44=0,100,42
rule45=0,100,67
rule46=0,100,44-3
rule47=0,100,67-2
rule48=0,100,67-3


layer
1,1,2,1,2,1,1,1,1,1,1,1,1,1,1,1,2,1,2,1,1
1,2,1,1,1,1,1,1,1,1,1,1,1,1,1,1,1,1,1,2,1
2,1,1,1,1,1,1,1,1,1,1,1,1,1,1,1,1,1,1,1,2
1,1,1,1,1,1,1,1,1,1,1,1,1,1,1,1,1,1,1,1,1
2,1,1,1,1,1,1,1,1,1,1,1,1,1,1,1,1,1,1,1,2
1,1,1,1,1,1,1,1,1,1,1,1,1,1,1,1,1,1,1,1,1
2,1,3,1,1,1,3,1,1,1,1,1,1,1,3,1,1,1,3,1,2
1,1,1,1,1,1,1,1,1,1,1,1,1,1,1,1,1,1,1,1,1
2,1,1,1,1,1,1,1,1,1,1,1,1,1,1,1,1,1,1,1,2
1,1,1,1,1,1,1,1,1,1,1,1,1,1,1,1,1,1,1,1,1
2,1,3,1,1,1,1,1,1,1,1,1,1,1,1,1,1,1,3,1,2
1,1,1,1,1,1,1,1,1,1,1,1,1,1,1,1,1,1,1,1,1
2,1,1,1,1,1,1,1,1,1,1,1,1,1,1,1,1,1,1,1,2
1,1,1,1,1,1,1,1,1,1,1,1,1,1,1,1,1,1,1,1,1
2,1,1,1,1,1,3,1,1,1,1,1,1,1,3,1,1,1,1,1,2
1,1,5,5,5,5,5,5,5,1,4,4,4,1,1,1,1,1,1,1,1
2,1,5,5,5,5,5,5,5,1,4,4,4,1,1,1,1,1,1,1,2
1,1,5,5,5,5,5,5,5,1,1,1,1,1,1,1,1,1,1,1,1
2,1,5,5,5,5,5,5,5,1,1,1,1,1,1,1,1,1,1,1,2
1,2,1,1,1,1,1,1,1,1,1,1,1,1,1,1,1,1,1,2,1
1,1,2,1,2,1,2,1,2,1,2,1,2,1,2,1,2,1,2,1,1
endlayer

layer
0,0,2,0,2,12,12,0,15,0,12,0,15,0,12,12,2,0,2,0,0
0,2,1,6,0,0,0,0,0,0,0,0,0,0,0,0,0,6,1,2,0
2,1,13,0,0,8,3,0,0,0,0,0,0,0,3,13,0,0,8,1,2
0,6,13,0,0,8,13,0,0,0,0,0,0,0,8,13,0,0,8,6,0
2,1,13,0,0,8,13,0,0,0,0,0,0,0,8,13,0,0,8,1,2
0,6,13,0,0,8,13,0,0,0,0,0,0,0,8,13,0,0,8,6,0
2,1,3,0,0,8,3,0,0,0,0,0,0,0,3,13,0,0,3,1,2
0,6,13,0,0,0,14,0,0,0,0,0,0,0,14,0,0,0,8,6,0
2,1,13,0,0,0,0,0,0,0,0,0,0,0,0,0,0,0,8,1,2
0,6,13,0,0,0,0,0,0,0,0,0,0,0,0,0,0,0,8,6,0
2,1,3,0,0,0,3,0,0,0,0,0,0,0,3,0,0,0,3,1,2
0,6,0,0,0,0,0,0,0,0,0,0,0,0,0,0,0,0,0,6,0
2,1,0,0,0,0,0,0,0,0,0,0,0,0,0,0,0,0,0,1,2
0,6,0,10,0,0,0,0,0,0,0,0,0,0,0,0,0,0,0,6,0
2,1,1,17,1,1,3,1,1,1,0,0,0,1,3,0,0,0,0,1,2
0,6,14,10,0,0,0,0,0,1,0,0,0,1,1,0,0,0,0,6,0
2,1,0,0,0,0,17,17,17,1,16,0,0,1,1,1,1,1,9,1,2
0,6,0,0,0,19,19,19,0,1,0,0,0,1,1,1,1,11,10,7,0
2,1,2,2,2,19,19,19,18,1,1,1,1,1,1,1,1,0,0,1,2
0,2,1,6,1,6,1,6,1,6,1,6,1,6,1,6,1,6,1,2,0
0,0,2,0,2,0,2,0,2,0,2,0,2,0,2,0,2,0,2,0,0
endlayer

layer
0,0,2,0,2,12,12,0,15,0,12,0,15,0,12,12,2,0,2,0,0
0,2,1,6,0,0,0,0,0,0,0,0,0,0,0,0,0,6,1,2,0
2,1,0,0,0,0,3,0,0,0,0,0,0,0,3,0,0,0,0,1,2
0,6,0,0,0,0,0,0,0,0,0,0,0,0,0,0,0,0,0,6,0
2,1,0,0,0,0,0,0,0,0,0,0,0,0,0,0,0,0,0,1,2
0,6,0,0,0,0,0,0,0,0,0,0,0,0,0,0,0,0,0,6,0
2,1,3,0,0,0,3,0,0,0,0,0,0,0,3,0,0,0,3,1,2
0,6,0,0,0,0,0,0,0,0,0,0,0,0,0,0,0,0,0,6,0
2,1,0,0,0,0,0,0,0,0,0,0,0,0,0,0,0,0,0,1,2
0,6,0,0,0,0,0,0,0,0,0,0,0,0,0,0,0,0,0,6,0
2,1,3,0,0,0,3,0,0,0,0,0,0,0,3,0,0,0,3,1,2
0,6,0,0,0,0,0,0,0,0,0,0,0,0,0,0,0,0,0,6,0
2,1,0,0,0,0,0,0,0,0,0,0,0,0,0,0,0,0,0,1,2
0,6,0,0,23,0,0,0,0,21,0,0,0,0,0,0,0,0,0,6,0
2,1,1,20,1,1,3,1,1,1,0,0,0,1,3,0,0,0,0,1,2
0,6,0,0,0,0,0,0,0,1,0,0,0,1,1,0,0,21,0,6,0
2,1,0,0,0,0,20,20,22,1,16,0,0,1,1,1,1,1,20,1,2
0,6,0,0,0,20,20,20,0,1,0,0,0,1,1,1,11,0,0,20,0
2,1,0,0,0,22,22,22,0,1,1,1,1,1,1,1,1,0,0,1,2
0,2,1,6,1,6,1,6,1,6,1,6,1,6,1,6,1,6,1,2,0
0,0,2,0,2,0,2,0,2,0,2,0,2,0,2,0,2,0,2,0,0
endlayer

layer
0,0,2,0,2,12,12,12,12,12,12,12,12,12,12,12,2,0,2,0,0
0,2,1,6,0,0,0,0,0,0,0,0,0,0,0,0,0,6,1,2,0
2,1,0,0,0,0,3,0,0,0,0,0,0,0,3,0,0,0,0,1,2
0,6,0,0,0,0,0,0,0,0,0,0,0,0,0,0,0,0,0,6,0
2,1,0,0,0,0,0,0,0,0,0,0,0,0,0,0,0,0,0,1,2
0,6,0,0,0,0,0,0,0,0,0,0,0,0,0,0,0,0,0,6,0
2,1,3,0,0,0,3,0,0,0,0,0,0,0,3,0,0,0,3,1,2
0,6,0,0,0,0,0,0,0,0,0,0,0,0,0,0,0,0,0,6,0
2,1,0,0,0,0,0,0,0,0,0,0,0,0,0,0,0,0,0,1,2
0,6,0,0,0,0,0,0,0,0,0,0,0,0,0,0,0,0,0,6,0
2,1,3,0,0,0,3,0,0,0,0,0,0,0,3,0,0,0,3,1,2
0,6,0,0,0,0,0,0,0,0,0,0,0,0,0,0,0,0,0,6,0
2,1,0,0,0,0,0,0,0,0,0,0,0,0,0,0,0,0,0,1,2
0,6,0,0,0,0,0,0,0,0,0,0,0,0,0,0,0,0,0,6,0
2,1,1,1,1,1,3,1,1,1,0,0,0,1,3,0,0,0,0,1,2
0,6,0,0,0,0,0,0,0,1,0,0,0,1,1,0,0,0,23,6,0
2,1,0,0,0,0,0,0,0,1,16,0,0,1,1,1,1,1,1,1,2
0,6,0,0,0,0,0,0,0,1,0,0,0,1,1,11,0,0,0,6,0
2,1,0,0,0,0,0,0,0,1,1,1,1,1,1,1,1,0,0,1,2
0,2,1,6,1,6,1,6,1,6,1,6,1,6,1,6,1,6,1,2,0
0,0,2,0,2,0,2,0,2,0,2,0,2,0,2,0,2,0,2,0,0
endlayer

layer
0,0,2,0,2,24,25,24,24,24,25,24,24,24,25,24,2,0,2,0,0
0,2,1,12,2,12,2,12,2,12,2,12,2,12,2,12,2,12,1,2,0
2,1,0,0,0,0,3,0,0,0,0,0,0,0,3,0,0,0,0,1,2
0,15,0,0,0,0,0,0,0,0,0,0,0,0,0,0,0,0,0,12,0
2,1,0,0,0,0,0,0,0,0,0,0,0,0,0,0,0,0,0,1,2
0,12,0,0,0,0,0,0,0,0,0,0,0,0,0,0,0,0,0,12,0
2,1,3,0,0,0,3,0,0,0,0,0,0,0,3,0,0,0,3,1,2
0,12,0,0,0,0,0,0,0,0,0,0,0,0,0,0,0,0,0,12,0
2,1,0,0,0,0,0,0,0,0,0,0,0,0,0,0,0,0,0,1,2
0,12,0,0,0,0,0,0,0,0,0,0,0,0,0,0,0,0,0,12,0
2,1,3,0,0,0,3,0,0,0,0,0,0,0,3,0,0,0,3,1,2
0,12,0,0,0,0,0,0,0,0,0,0,0,0,0,0,0,0,0,12,0
2,1,0,0,0,0,0,0,0,0,0,0,0,0,0,0,0,0,0,1,2
0,12,0,0,0,0,0,0,0,0,0,0,0,0,0,0,0,0,0,12,0
2,1,1,1,1,1,3,1,1,1,0,0,0,1,3,0,0,0,0,1,2
0,12,0,0,0,0,0,0,0,1,0,0,0,1,1,0,0,0,0,12,0
2,1,0,0,0,0,0,0,0,1,16,0,0,1,26,1,1,1,1,1,2
0,12,0,0,0,0,0,0,0,1,0,0,0,1,11,0,0,0,0,12,0
2,1,0,0,0,0,0,0,0,1,1,1,1,1,1,1,1,0,0,1,2
0,2,1,12,1,12,1,12,1,12,1,12,1,12,1,12,1,12,1,2,0
0,0,2,0,2,0,2,0,2,0,2,0,2,0,2,0,2,0,2,0,0
endlayer

layer
0,0,25,0,25,0,0,0,0,0,0,0,0,0,0,0,25,0,25,0,0
0,2,2,27,2,12,2,12,2,12,2,12,2,12,2,12,2,27,2,2,0
8,2,28,28,28,28,28,28,28,28,28,28,28,28,28,28,28,28,28,2,13
0,27,28,28,28,28,28,28,28,28,28,28,28,28,28,28,28,28,28,27,0
8,2,28,28,28,28,28,28,28,28,28,28,28,28,28,28,28,28,28,2,13
0,27,28,28,28,28,28,28,28,28,28,28,28,28,28,28,28,28,28,27,0
8,2,28,28,28,28,3,28,28,28,28,28,28,28,3,28,28,28,28,2,13
0,27,28,28,28,28,28,28,28,28,28,28,28,28,28,28,28,28,28,27,0
8,2,28,28,28,28,28,28,28,28,28,28,28,28,28,28,28,28,28,2,13
0,27,28,28,28,28,28,28,28,28,28,28,28,28,28,28,28,28,28,27,0
8,2,28,28,28,28,28,28,28,28,28,28,28,28,28,28,28,28,28,2,13
0,27,28,28,28,28,28,28,28,28,28,28,28,28,28,28,28,28,28,27,0
8,2,28,28,28,28,28,28,28,28,28,28,28,28,28,28,28,28,28,2,13
0,27,28,28,28,28,28,28,28,28,28,28,28,28,28,28,28,28,28,27,0
8,2,28,28,28,28,3,28,28,28,28,28,28,28,3,28,28,28,28,2,13
0,27,28,28,28,28,28,28,28,28,0,0,0,28,28,28,28,28,28,27,0
8,2,28,28,28,28,28,28,28,28,16,0,0,28,0,30,28,28,28,2,13
0,27,28,28,28,28,28,28,28,28,28,28,28,28,0,0,0,28,28,27,0
8,2,28,28,28,28,28,28,28,28,28,28,28,28,28,28,28,28,28,2,13
0,2,2,27,2,27,2,27,2,27,2,27,2,27,2,27,2,27,2,2,0
0,0,29,0,29,0,29,0,29,0,29,0,29,0,29,0,29,0,29,0,0
endlayer

layer
0,0,0,0,0,0,0,0,0,0,0,0,0,0,0,0,0,0,0,0,0
0,2,2,0,2,0,2,0,2,0,2,0,2,0,2,0,2,0,2,2,0
0,2,31,31,31,31,31,31,31,31,31,31,31,31,31,31,31,31,31,2,0
0,0,31,31,31,31,31,31,31,31,31,31,31,31,31,31,31,31,31,0,0
0,2,31,31,31,31,31,31,31,31,31,31,31,31,31,31,31,31,31,2,0
0,0,31,31,31,31,31,31,31,31,31,31,31,31,31,31,31,31,31,0,0
0,2,31,31,31,31,3,31,31,31,31,31,31,31,3,31,31,31,31,2,0
0,0,31,31,31,31,31,31,31,31,31,31,31,31,31,31,31,31,31,0,0
0,2,31,31,31,31,31,31,31,31,31,31,31,31,31,31,31,31,31,2,0
0,0,31,31,31,31,31,31,31,31,31,31,31,31,31,31,31,31,31,0,0
0,2,31,31,31,31,31,31,31,31,31,31,31,31,31,31,31,31,31,2,0
0,0,31,31,31,31,31,31,31,31,31,31,31,31,31,31,31,31,31,0,0
0,2,31,31,31,31,31,31,31,31,31,31,31,31,31,31,31,31,31,2,0
0,0,31,31,31,31,31,31,31,31,31,31,31,31,31,31,31,31,31,0,0
0,2,31,31,31,31,3,31,31,31,31,31,31,31,3,31,31,31,31,2,0
0,0,31,31,31,31,31,31,31,31,0,0,0,31,31,31,31,31,31,0,0
0,2,31,31,31,31,31,31,31,31,16,0,0,31,0,0,30,26,31,2,0
0,0,31,31,31,31,31,31,31,31,31,31,31,31,0,0,0,26,31,0,0
0,2,31,31,31,31,31,31,31,31,31,31,31,31,31,31,31,31,31,2,0
0,2,2,0,2,0,2,0,2,0,2,0,2,0,2,0,2,0,2,2,0
0,0,0,0,0,0,0,0,0,0,0,0,0,0,0,0,0,0,0,0,0
endlayer

layer
0,0,0,0,0,0,0,0,0,0,0,0,0,0,0,0,0,0,0,0,0
0,2,2,0,2,0,2,0,2,0,2,0,2,0,2,0,2,0,2,2,0
0,2,1,12,1,12,1,12,1,12,1,12,1,12,1,12,1,12,1,2,0
0,0,12,0,0,0,0,0,0,0,1,0,0,0,0,0,0,0,12,0,0
0,2,1,0,18,18,18,18,18,0,1,0,18,18,18,18,18,0,1,2,0
0,0,12,0,18,18,18,18,18,0,1,0,18,18,18,18,18,0,12,0,0
0,2,1,0,18,18,3,18,18,0,1,0,18,18,3,18,18,0,1,2,0
0,0,12,0,18,18,18,18,18,0,1,0,18,18,18,18,18,0,12,0,0
0,2,1,0,18,18,18,18,18,0,1,0,18,18,18,18,18,0,1,2,0
0,0,12,0,0,0,0,0,0,0,1,0,0,0,0,0,0,0,12,0,0
0,2,1,1,1,1,1,1,33,1,1,1,33,1,1,1,1,1,1,2,0
0,0,12,0,0,0,1,0,0,0,0,0,0,0,0,0,0,0,12,0,0
0,2,1,0,0,0,34,0,0,0,0,0,0,0,0,0,0,0,1,2,0
0,0,12,0,18,18,1,0,0,0,0,0,0,0,0,0,0,0,12,0,0
0,2,1,0,18,18,3,1,1,1,0,0,0,1,3,1,1,9,1,2,0
0,0,12,0,18,18,18,18,18,1,0,0,0,1,1,1,0,10,12,0,0
0,2,1,0,18,18,18,18,18,1,16,0,0,1,0,0,0,0,1,2,0
0,0,12,0,0,0,0,0,0,1,0,0,0,1,0,32,11,0,12,0,0
0,2,1,12,1,12,1,12,1,1,1,1,1,1,1,12,1,12,1,2,0
0,2,2,0,2,0,2,0,2,0,2,0,2,0,2,0,2,0,2,2,0
0,0,0,0,0,0,0,0,0,0,0,0,0,0,0,0,0,0,0,0,0
endlayer

layer
0,0,0,0,0,0,0,0,0,0,0,0,0,0,0,0,0,0,0,0,0
0,2,2,0,2,0,2,0,2,0,2,0,2,0,2,0,2,0,2,2,0
0,2,1,12,1,12,1,12,1,12,1,12,1,12,1,12,1,12,1,2,0
0,0,12,0,0,0,0,0,0,0,1,0,0,0,0,0,0,0,12,0,0
0,2,1,0,0,0,0,0,0,0,1,0,0,0,0,0,0,0,1,2,0
0,0,12,0,0,0,0,0,0,0,1,0,0,0,0,0,0,0,12,0,0
0,2,1,0,0,0,3,0,0,0,1,0,0,0,3,0,0,0,1,2,0
0,0,12,0,0,0,0,0,0,0,1,0,0,0,0,0,0,0,12,0,0
0,2,1,0,0,0,0,0,0,0,1,0,0,0,0,0,0,0,1,2,0
0,0,12,0,0,0,0,0,0,0,1,0,0,0,0,0,0,0,12,0,0
0,2,1,1,1,1,1,1,35,1,1,1,35,1,1,1,1,1,1,2,0
0,0,12,0,0,0,1,0,0,0,0,0,0,0,0,0,0,0,12,0,0
0,2,1,0,0,0,35,0,0,0,0,0,0,0,0,0,0,0,1,2,0
0,0,12,0,0,0,1,0,0,0,0,0,0,0,0,0,21,0,12,0,0
0,2,1,0,0,0,3,1,1,1,0,0,0,1,3,1,1,20,1,2,0
0,0,12,0,0,0,0,0,0,1,0,0,0,1,1,1,0,0,12,0,0
0,2,1,0,0,0,0,0,0,1,16,0,0,1,0,0,0,0,1,2,0
0,0,12,0,0,0,0,0,0,1,0,0,0,1,32,11,0,0,12,0,0
0,2,1,12,1,12,1,12,1,1,1,1,1,1,1,12,1,12,1,2,0
0,2,2,0,2,0,2,0,2,0,2,0,2,0,2,0,2,0,2,2,0
0,0,0,0,0,0,0,0,0,0,0,0,0,0,0,0,0,0,0,0,0
endlayer

layer
0,0,0,0,0,0,0,0,0,0,0,0,0,0,0,0,0,0,0,0,0
0,2,2,0,2,0,2,0,2,0,2,0,2,0,2,0,2,0,2,2,0
0,2,1,12,1,12,1,12,1,12,1,12,1,12,1,12,1,12,1,2,0
0,0,12,0,0,0,0,0,0,0,1,0,0,0,0,0,0,0,12,0,0
0,2,1,0,0,0,0,0,0,0,1,0,0,0,0,0,0,0,1,2,0
0,0,12,0,0,0,0,0,0,0,1,0,0,0,0,0,0,0,12,0,0
0,2,1,0,0,0,3,0,0,0,1,0,0,0,3,0,0,0,1,2,0
0,0,12,0,0,0,0,0,0,0,1,0,0,0,0,0,0,0,12,0,0
0,2,1,0,0,0,0,0,0,0,1,0,0,0,0,0,0,0,1,2,0
0,0,12,0,0,0,0,0,0,0,1,0,0,0,0,0,0,0,12,0,0
0,2,1,1,1,1,1,1,1,1,1,1,1,1,1,1,1,1,1,2,0
0,0,12,0,0,0,1,0,0,0,0,0,0,0,0,0,0,0,12,0,0
0,2,1,0,0,0,1,0,0,0,0,0,0,0,0,0,0,0,1,2,0
0,0,12,0,0,0,1,0,0,0,0,0,0,0,0,0,0,23,12,0,0
0,2,1,0,0,0,3,1,1,1,0,0,0,1,3,1,1,1,1,2,0
0,0,12,0,0,0,0,0,0,1,0,0,0,1,1,1,1,0,12,0,0
0,2,1,0,0,0,0,0,0,1,16,0,0,1,26,36,0,0,1,2,0
0,0,12,0,0,0,0,0,0,1,0,0,0,1,11,0,0,0,12,0,0
0,2,1,12,1,12,1,12,1,1,1,1,1,1,1,12,1,12,1,2,0
0,2,2,0,2,0,2,0,2,0,2,0,2,0,2,0,2,0,2,2,0
0,0,0,0,0,0,0,0,0,0,0,0,0,0,0,0,0,0,0,0,0
endlayer

layer
0,0,0,0,0,0,0,0,0,0,0,0,0,0,0,0,0,0,0,0,0
0,2,2,0,2,0,2,0,2,0,2,0,2,0,2,0,2,0,2,2,0
0,2,28,28,28,28,28,28,28,28,28,28,28,28,28,28,28,28,28,2,0
0,0,28,28,28,28,28,28,28,28,28,28,28,28,28,28,28,28,28,0,0
0,2,28,28,28,28,28,28,28,28,28,28,28,28,28,28,28,28,28,2,0
0,0,28,28,28,28,28,28,28,28,28,28,28,28,28,28,28,28,28,0,0
0,2,28,28,28,28,3,28,28,28,28,28,28,28,3,28,28,28,28,2,0
0,0,28,28,28,28,28,28,28,28,28,28,28,28,28,28,28,28,28,0,0
0,2,28,28,28,28,28,28,28,28,28,28,28,28,28,28,28,28,28,2,0
0,0,28,28,28,28,28,28,28,28,28,28,28,28,28,28,28,28,28,0,0
0,2,28,28,28,28,28,28,28,28,28,28,28,28,28,28,28,28,28,2,0
0,0,28,28,28,28,28,28,28,28,28,28,28,28,28,28,28,28,28,0,0
0,2,28,28,28,28,28,28,28,28,28,28,28,28,28,28,28,28,28,2,0
0,0,28,28,28,28,28,28,28,28,28,28,28,28,28,28,28,28,28,0,0
0,2,28,28,28,28,3,28,28,28,28,28,28,28,3,28,28,28,28,2,0
0,0,28,28,28,28,28,28,28,28,0,0,0,28,28,28,28,28,28,0,0
0,2,28,28,28,28,28,28,28,28,16,0,0,28,0,30,36,0,28,2,0
0,0,28,28,28,28,28,28,28,28,28,28,28,28,0,0,0,0,28,0,0
0,2,28,28,28,28,28,28,28,28,28,28,28,28,28,28,28,28,28,2,0
0,2,2,0,2,0,2,0,2,0,2,0,2,0,2,0,2,0,2,2,0
0,0,0,0,0,0,0,0,0,0,0,0,0,0,0,0,0,0,0,0,0
endlayer

layer
0,0,0,0,0,0,0,0,0,0,0,0,0,0,0,0,0,0,0,0,0
0,2,2,0,2,0,2,0,2,0,2,0,2,0,2,0,2,0,2,2,0
0,2,31,31,31,31,31,31,31,31,31,31,31,31,31,31,31,31,31,2,0
0,0,31,31,31,31,31,31,31,31,31,31,31,31,31,31,31,31,31,0,0
0,2,31,31,31,31,31,31,31,31,31,31,31,31,31,31,31,31,31,2,0
0,0,31,31,31,31,31,31,31,31,31,31,31,31,31,31,31,31,31,0,0
0,2,31,31,31,31,3,31,31,31,31,31,31,31,3,31,31,31,31,2,0
0,0,31,31,31,31,31,31,31,31,31,31,31,31,31,31,31,31,31,0,0
0,2,31,31,31,31,31,31,31,31,31,31,31,31,31,31,31,31,31,2,0
0,0,31,31,31,31,31,31,31,31,31,31,31,31,31,31,31,31,31,0,0
0,2,31,31,31,31,31,31,31,31,31,31,31,31,31,31,31,31,31,2,0
0,0,31,31,31,31,31,31,31,31,31,31,31,31,31,31,31,31,31,0,0
0,2,31,31,31,31,31,31,31,31,31,31,31,31,31,31,31,31,31,2,0
0,0,31,31,31,31,31,31,31,31,31,31,31,31,31,31,31,31,31,0,0
0,2,31,31,31,31,3,31,31,31,31,31,31,31,3,31,31,31,31,2,0
0,0,31,31,31,31,31,31,31,31,0,0,0,31,31,31,31,31,31,0,0
0,2,31,31,31,31,31,31,31,31,16,0,0,31,0,0,30,26,31,2,0
0,0,31,31,31,31,31,31,31,31,31,31,31,31,0,0,0,26,31,0,0
0,2,31,31,31,31,31,31,31,31,31,31,31,31,31,31,31,31,31,2,0
0,2,2,0,2,0,2,0,2,0,2,0,2,0,2,0,2,0,2,2,0
0,0,0,0,0,0,0,0,0,0,0,0,0,0,0,0,0,0,0,0,0
endlayer

layer
0,0,0,0,0,0,0,0,0,0,0,0,0,0,0,0,0,0,0,0,0
0,2,2,0,2,0,2,0,2,0,2,0,2,0,2,0,2,0,2,2,0
0,2,1,12,1,12,1,12,1,12,1,12,1,12,1,12,1,12,1,2,0
0,0,12,0,0,0,0,0,0,0,1,0,0,0,0,0,0,0,12,0,0
0,2,1,0,18,18,18,18,18,0,1,0,18,18,18,18,18,0,1,2,0
0,0,12,0,18,18,18,18,18,0,1,0,18,18,18,18,18,0,12,0,0
0,2,1,0,18,18,3,18,18,0,1,0,18,18,3,18,18,0,1,2,0
0,0,12,0,18,18,18,18,18,0,1,0,18,18,18,18,18,0,12,0,0
0,2,1,0,18,18,18,18,18,0,1,0,18,18,18,18,18,0,1,2,0
0,0,12,0,0,0,0,0,0,0,1,0,0,0,0,0,0,0,12,0,0
0,2,1,1,1,1,1,1,33,1,1,1,33,1,1,1,1,1,1,2,0
0,0,12,0,0,0,1,0,0,0,0,0,0,0,0,0,0,0,12,0,0
0,2,1,0,0,0,34,0,0,0,0,0,0,0,0,0,0,0,1,2,0
0,0,12,0,18,18,1,0,0,0,0,0,0,0,0,0,0,0,12,0,0
0,2,1,0,18,18,3,1,1,1,0,0,0,1,3,1,1,9,1,2,0
0,0,12,0,18,18,18,18,18,1,0,0,0,1,1,1,0,10,12,0,0
0,2,1,0,18,18,18,18,18,1,16,0,0,1,0,0,0,0,1,2,0
0,0,12,0,0,0,0,0,0,1,0,0,0,1,0,32,11,0,12,0,0
0,2,1,12,1,12,1,12,1,1,1,1,1,1,1,12,1,12,1,2,0
0,2,2,0,2,0,2,0,2,0,2,0,2,0,2,0,2,0,2,2,0
0,0,0,0,0,0,0,0,0,0,0,0,0,0,0,0,0,0,0,0,0
endlayer

layer
0,0,0,0,0,0,0,0,0,0,0,0,0,0,0,0,0,0,0,0,0
0,2,2,0,2,0,2,0,2,0,2,0,2,0,2,0,2,0,2,2,0
0,2,1,12,1,12,1,12,1,12,1,12,1,12,1,12,1,12,1,2,0
0,0,12,0,0,0,0,0,0,0,1,0,0,0,0,0,0,0,12,0,0
0,2,1,0,0,0,0,0,0,0,1,0,0,0,0,0,0,0,1,2,0
0,0,12,0,0,0,0,0,0,0,1,0,0,0,0,0,0,0,12,0,0
0,2,1,0,0,0,3,0,0,0,1,0,0,0,3,0,0,0,1,2,0
0,0,12,0,0,0,0,0,0,0,1,0,0,0,0,0,0,0,12,0,0
0,2,1,0,0,0,0,0,0,0,1,0,0,0,0,0,0,0,1,2,0
0,0,12,0,0,0,0,0,0,0,1,0,0,0,0,0,0,0,12,0,0
0,2,1,1,1,1,1,1,35,1,1,1,35,1,1,1,1,1,1,2,0
0,0,12,0,0,0,1,0,0,0,0,0,0,0,0,0,0,0,12,0,0
0,2,1,0,0,0,35,0,0,0,0,0,0,0,0,0,0,0,1,2,0
0,0,12,0,0,0,1,0,0,0,0,0,0,0,0,0,21,0,12,0,0
0,2,1,0,0,0,3,1,1,1,0,0,0,1,3,1,1,20,1,2,0
0,0,12,0,0,0,0,0,0,1,0,0,0,1,1,1,0,0,12,0,0
0,2,1,0,0,0,0,0,0,1,16,0,0,1,0,0,0,0,1,2,0
0,0,12,0,0,0,0,0,0,1,0,0,0,1,32,11,0,0,12,0,0
0,2,1,12,1,12,1,12,1,1,1,1,1,1,1,12,1,12,1,2,0
0,2,2,0,2,0,2,0,2,0,2,0,2,0,2,0,2,0,2,2,0
0,0,0,0,0,0,0,0,0,0,0,0,0,0,0,0,0,0,0,0,0
endlayer

layer
0,0,0,0,0,0,0,0,0,0,0,0,0,0,0,0,0,0,0,0,0
0,2,2,0,2,0,2,0,2,0,2,0,2,0,2,0,2,0,2,2,0
0,2,1,12,1,12,1,12,1,12,1,12,1,12,1,12,1,12,1,2,0
0,0,12,0,0,0,0,0,0,0,1,0,0,0,0,0,0,0,12,0,0
0,2,1,0,0,0,0,0,0,0,1,0,0,0,0,0,0,0,1,2,0
0,0,12,0,0,0,0,0,0,0,1,0,0,0,0,0,0,0,12,0,0
0,2,1,0,0,0,3,0,0,0,1,0,0,0,3,0,0,0,1,2,0
0,0,12,0,0,0,0,0,0,0,1,0,0,0,0,0,0,0,12,0,0
0,2,1,0,0,0,0,0,0,0,1,0,0,0,0,0,0,0,1,2,0
0,0,12,0,0,0,0,0,0,0,1,0,0,0,0,0,0,0,12,0,0
0,2,1,1,1,1,1,1,1,1,1,1,1,1,1,1,1,1,1,2,0
0,0,12,0,0,0,1,0,0,0,0,0,0,0,0,0,0,0,12,0,0
0,2,1,0,0,0,1,0,0,0,0,0,0,0,0,0,0,0,1,2,0
0,0,12,0,0,0,1,0,0,0,0,0,0,0,0,0,0,23,12,0,0
0,2,1,0,0,0,3,1,1,1,0,0,0,1,3,1,1,1,1,2,0
0,0,12,0,0,0,0,0,0,1,0,0,0,1,1,1,1,0,12,0,0
0,2,1,0,0,0,0,0,0,1,16,0,0,1,26,36,0,0,1,2,0
0,0,12,0,0,0,0,0,0,1,0,0,0,1,11,0,0,0,12,0,0
0,2,1,12,1,12,1,12,1,1,1,1,1,1,1,12,1,12,1,2,0
0,2,2,0,2,0,2,0,2,0,2,0,2,0,2,0,2,0,2,2,0
0,0,0,0,0,0,0,0,0,0,0,0,0,0,0,0,0,0,0,0,0
endlayer

layer
0,0,0,0,0,0,0,0,0,0,0,0,0,0,0,0,0,0,0,0,0
0,2,2,0,2,0,2,0,2,0,2,0,2,0,2,0,2,0,2,2,0
0,2,28,28,28,28,28,28,28,28,28,28,28,28,28,28,28,28,28,2,0
0,0,28,28,28,28,28,28,28,28,28,28,28,28,28,28,28,28,28,0,0
0,2,28,28,28,28,28,28,28,28,28,28,28,28,28,28,28,28,28,2,0
0,0,28,28,28,28,28,28,28,28,28,28,28,28,28,28,28,28,28,0,0
0,2,28,28,28,28,3,28,28,28,28,28,28,28,3,28,28,28,28,2,0
0,0,28,28,28,28,28,28,28,28,28,28,28,28,28,28,28,28,28,0,0
0,2,28,28,28,28,28,28,28,28,28,28,28,28,28,28,28,28,28,2,0
0,0,28,28,28,28,28,28,28,28,28,28,28,28,28,28,28,28,28,0,0
0,2,28,28,28,28,28,28,28,28,28,28,28,28,28,28,28,28,28,2,0
0,0,28,28,28,28,28,28,28,28,28,28,28,28,28,28,28,28,28,0,0
0,2,28,28,28,28,28,28,28,28,28,28,28,28,28,28,28,28,28,2,0
0,0,28,28,28,28,28,28,28,28,28,28,28,28,28,28,28,28,28,0,0
0,2,28,28,28,28,3,28,28,28,28,28,28,28,3,28,28,28,28,2,0
0,0,28,28,28,28,28,28,28,28,0,0,0,28,28,28,28,28,28,0,0
0,2,28,28,28,28,28,28,28,28,16,0,0,28,0,30,36,0,28,2,0
0,0,28,28,28,28,28,28,28,28,28,28,28,28,0,0,0,0,28,0,0
0,2,28,28,28,28,28,28,28,28,28,28,28,28,28,28,28,28,28,2,0
0,2,2,0,2,0,2,0,2,0,2,0,2,0,2,0,2,0,2,2,0
0,0,0,0,0,0,0,0,0,0,0,0,0,0,0,0,0,0,0,0,0
endlayer

layer
0,0,0,0,0,0,0,0,0,0,0,0,0,0,0,0,0,0,0,0,0
0,2,2,0,2,0,2,0,2,0,2,0,2,0,2,0,2,0,2,2,0
0,2,31,31,31,31,31,31,31,31,31,31,31,31,31,31,31,31,31,2,0
0,0,31,31,31,31,31,31,31,31,31,31,31,31,31,31,31,31,31,0,0
0,2,31,31,31,31,31,31,31,31,31,31,31,31,31,31,31,31,31,2,0
0,0,31,31,31,31,31,31,31,31,31,31,31,31,31,31,31,31,31,0,0
0,2,31,31,31,31,3,31,31,31,31,31,31,31,3,31,31,31,31,2,0
0,0,31,31,31,31,31,31,31,31,31,31,31,31,31,31,31,31,31,0,0
0,2,31,31,31,31,31,31,31,31,31,31,31,31,31,31,31,31,31,2,0
0,0,31,31,31,31,31,31,31,31,31,31,31,31,31,31,31,31,31,0,0
0,2,31,31,31,31,31,31,31,31,31,31,31,31,31,31,31,31,31,2,0
0,0,31,31,31,31,31,31,31,31,31,31,31,31,31,31,31,31,31,0,0
0,2,31,31,31,31,31,31,31,31,31,31,31,31,31,31,31,31,31,2,0
0,0,31,31,31,31,31,31,31,31,31,31,31,31,31,31,31,31,31,0,0
0,2,31,31,31,31,3,31,31,31,31,31,31,31,3,31,31,31,31,2,0
0,0,31,31,31,31,31,31,31,31,0,0,0,31,31,31,31,31,31,0,0
0,2,31,31,31,31,31,31,31,31,16,0,0,31,0,0,30,26,31,2,0
0,0,31,31,31,31,31,31,31,31,31,31,31,31,0,0,0,26,31,0,0
0,2,31,31,31,31,31,31,31,31,31,31,31,31,31,31,31,31,31,2,0
0,2,2,0,2,0,2,0,2,0,2,0,2,0,2,0,2,0,2,2,0
0,0,0,0,0,0,0,0,0,0,0,0,0,0,0,0,0,0,0,0,0
endlayer

layer
0,0,0,0,0,0,0,0,0,0,0,0,0,0,0,0,0,0,0,0,0
0,2,2,0,2,0,2,0,2,0,2,0,2,0,2,0,2,0,2,2,0
0,2,1,12,1,12,1,12,1,12,1,12,1,12,1,12,1,12,1,2,0
0,0,12,0,0,0,0,0,0,0,1,0,0,0,0,0,0,0,12,0,0
0,2,1,0,18,18,18,18,18,0,1,0,18,18,18,18,18,0,1,2,0
0,0,12,0,18,18,18,18,18,0,1,0,18,18,18,18,18,0,12,0,0
0,2,1,0,18,18,3,18,18,0,1,0,18,18,3,18,18,0,1,2,0
0,0,12,0,18,18,18,18,18,0,1,0,18,18,18,18,18,0,12,0,0
0,2,1,0,18,18,18,18,18,0,1,0,18,18,18,18,18,0,1,2,0
0,0,12,0,0,0,0,0,0,0,1,0,0,0,0,0,0,0,12,0,0
0,2,1,1,1,1,1,1,33,1,1,1,33,1,1,1,1,1,1,2,0
0,0,12,0,0,0,1,0,0,0,0,0,0,0,0,0,0,0,12,0,0
0,2,1,0,0,0,34,0,0,0,0,0,0,0,0,0,0,0,1,2,0
0,0,12,0,18,18,1,0,0,0,0,0,0,0,0,0,0,0,12,0,0
0,2,1,0,18,18,3,1,1,1,0,0,0,1,3,1,1,9,1,2,0
0,0,12,0,18,18,18,18,18,1,0,0,0,1,1,1,0,10,12,0,0
0,2,1,0,18,18,18,18,18,1,16,0,0,1,0,0,0,0,1,2,0
0,0,12,0,0,0,0,0,0,1,0,0,0,1,0,32,11,0,12,0,0
0,2,1,12,1,12,1,12,1,1,1,1,1,1,1,12,1,12,1,2,0
0,2,2,0,2,0,2,0,2,0,2,0,2,0,2,0,2,0,2,2,0
0,0,0,0,0,0,0,0,0,0,0,0,0,0,0,0,0,0,0,0,0
endlayer

layer
0,0,0,0,0,0,0,0,0,0,0,0,0,0,0,0,0,0,0,0,0
0,2,2,0,2,0,2,0,2,0,2,0,2,0,2,0,2,0,2,2,0
0,2,1,12,1,12,1,12,1,12,1,12,1,12,1,12,1,12,1,2,0
0,0,12,0,0,0,0,0,0,0,1,0,0,0,0,0,0,0,12,0,0
0,2,1,0,0,0,0,0,0,0,1,0,0,0,0,0,0,0,1,2,0
0,0,12,0,0,0,0,0,0,0,1,0,0,0,0,0,0,0,12,0,0
0,2,1,0,0,0,3,0,0,0,1,0,0,0,3,0,0,0,1,2,0
0,0,12,0,0,0,0,0,0,0,1,0,0,0,0,0,0,0,12,0,0
0,2,1,0,0,0,0,0,0,0,1,0,0,0,0,0,0,0,1,2,0
0,0,12,0,0,0,0,0,0,0,1,0,0,0,0,0,0,0,12,0,0
0,2,1,1,1,1,1,1,35,1,1,1,35,1,1,1,1,1,1,2,0
0,0,12,0,0,0,1,0,0,0,0,0,0,0,0,0,0,0,12,0,0
0,2,1,0,0,0,35,0,0,0,0,0,0,0,0,0,0,0,1,2,0
0,0,12,0,0,0,1,0,0,0,0,0,0,0,0,0,21,0,12,0,0
0,2,1,0,0,0,3,1,1,1,0,0,0,1,3,1,1,20,1,2,0
0,0,12,0,0,0,0,0,0,1,0,0,0,1,1,1,0,0,12,0,0
0,2,1,0,0,0,0,0,0,1,16,0,0,1,0,0,0,0,1,2,0
0,0,12,0,0,0,0,0,0,1,0,0,0,1,32,11,0,0,12,0,0
0,2,1,12,1,12,1,12,1,1,1,1,1,1,1,12,1,12,1,2,0
0,2,2,0,2,0,2,0,2,0,2,0,2,0,2,0,2,0,2,2,0
0,0,0,0,0,0,0,0,0,0,0,0,0,0,0,0,0,0,0,0,0
endlayer

layer
0,0,0,0,0,0,0,0,0,0,0,0,0,0,0,0,0,0,0,0,0
0,2,2,0,2,0,2,0,2,0,2,0,2,0,2,0,2,0,2,2,0
0,2,1,12,1,12,1,12,1,12,1,12,1,12,1,12,1,12,1,2,0
0,0,12,0,0,0,0,0,0,0,1,0,0,0,0,0,0,0,12,0,0
0,2,1,0,0,0,0,0,0,0,1,0,0,0,0,0,0,0,1,2,0
0,0,12,0,0,0,0,0,0,0,1,0,0,0,0,0,0,0,12,0,0
0,2,1,0,0,0,3,0,0,0,1,0,0,0,3,0,0,0,1,2,0
0,0,12,0,0,0,0,0,0,0,1,0,0,0,0,0,0,0,12,0,0
0,2,1,0,0,0,0,0,0,0,1,0,0,0,0,0,0,0,1,2,0
0,0,12,0,0,0,0,0,0,0,1,0,0,0,0,0,0,0,12,0,0
0,2,1,1,1,1,1,1,1,1,1,1,1,1,1,1,1,1,1,2,0
0,0,12,0,0,0,1,0,0,0,0,0,0,0,0,0,0,0,12,0,0
0,2,1,0,0,0,1,0,0,0,0,0,0,0,0,0,0,0,1,2,0
0,0,12,0,0,0,1,0,0,0,0,0,0,0,0,0,0,23,12,0,0
0,2,1,0,0,0,3,1,1,1,0,0,0,1,3,1,1,1,1,2,0
0,0,12,0,0,0,0,0,0,1,0,0,0,1,1,1,1,0,12,0,0
0,2,1,0,0,0,0,0,0,1,16,0,0,1,26,36,0,0,1,2,0
0,0,12,0,0,0,0,0,0,1,0,0,0,1,11,0,0,0,12,0,0
0,2,1,12,1,12,1,12,1,1,1,1,1,1,1,12,1,12,1,2,0
0,2,2,0,2,0,2,0,2,0,2,0,2,0,2,0,2,0,2,2,0
0,0,0,0,0,0,0,0,0,0,0,0,0,0,0,0,0,0,0,0,0
endlayer

layer
0,0,0,0,0,0,0,0,0,0,0,0,0,0,0,0,0,0,0,0,0
0,2,2,0,2,0,2,0,2,0,2,0,2,0,2,0,2,0,2,2,0
0,2,28,28,28,28,28,28,28,28,28,28,28,28,28,28,28,28,28,2,0
0,0,28,28,28,28,28,28,28,28,28,28,28,28,28,28,28,28,28,0,0
0,2,28,28,28,28,28,28,28,28,28,28,28,28,28,28,28,28,28,2,0
0,0,28,28,28,28,28,28,28,28,28,28,28,28,28,28,28,28,28,0,0
0,2,28,28,28,28,3,28,28,28,28,28,28,28,3,28,28,28,28,2,0
0,0,28,28,28,28,28,28,28,28,28,28,28,28,28,28,28,28,28,0,0
0,2,28,28,28,28,28,28,28,28,28,28,28,28,28,28,28,28,28,2,0
0,0,28,28,28,28,28,28,28,28,28,28,28,28,28,28,28,28,28,0,0
0,2,28,28,28,28,28,28,28,28,28,28,28,28,28,28,28,28,28,2,0
0,0,28,28,28,28,28,28,28,28,28,28,28,28,28,28,28,28,28,0,0
0,2,28,28,28,28,28,28,28,28,28,28,28,28,28,28,28,28,28,2,0
0,0,28,28,28,28,28,28,28,28,28,28,28,28,28,28,28,28,28,0,0
0,2,28,28,28,28,3,28,28,28,28,28,28,28,3,28,28,28,28,2,0
0,0,28,28,28,28,28,28,28,28,0,0,0,28,28,28,28,28,28,0,0
0,2,28,28,28,28,28,28,28,28,16,0,0,28,0,30,36,0,28,2,0
0,0,28,28,28,28,28,28,28,28,28,28,28,28,0,0,0,0,28,0,0
0,2,28,28,28,28,28,28,28,28,28,28,28,28,28,28,28,28,28,2,0
0,2,2,0,2,0,2,0,2,0,2,0,2,0,2,0,2,0,2,2,0
0,0,0,0,0,0,0,0,0,0,0,0,0,0,0,0,0,0,0,0,0
endlayer

layer
0,0,0,0,0,0,0,0,0,0,0,0,0,0,0,0,0,0,0,0,0
0,2,2,0,2,0,2,0,2,0,2,0,2,0,2,0,2,0,2,2,0
0,2,31,31,31,31,31,31,31,31,31,31,31,31,31,31,31,31,31,2,0
0,0,31,31,31,31,31,31,31,31,31,31,31,31,31,31,31,31,31,0,0
0,2,31,31,31,31,31,31,31,31,31,31,31,31,31,31,31,31,31,2,0
0,0,31,31,31,31,31,31,31,31,31,31,31,31,31,31,31,31,31,0,0
0,2,31,31,31,31,3,31,31,31,31,31,31,31,3,31,31,31,31,2,0
0,0,31,31,31,31,31,31,31,31,31,31,31,31,31,31,31,31,31,0,0
0,2,31,31,31,31,31,31,31,31,31,31,31,31,31,31,31,31,31,2,0
0,0,31,31,31,31,31,31,31,31,31,31,31,31,31,31,31,31,31,0,0
0,2,31,31,31,31,31,31,31,31,31,31,31,31,31,31,31,31,31,2,0
0,0,31,31,31,31,31,31,31,31,31,31,31,31,31,31,31,31,31,0,0
0,2,31,31,31,31,31,31,31,31,31,31,31,31,31,31,31,31,31,2,0
0,0,31,31,31,31,31,31,31,31,31,31,31,31,31,31,31,31,31,0,0
0,2,31,31,31,31,3,31,31,31,31,31,31,31,3,31,31,31,31,2,0
0,0,31,31,31,31,31,31,31,31,0,0,0,31,31,31,31,31,31,0,0
0,2,31,31,31,31,31,31,31,31,16,0,0,31,0,0,30,26,31,2,0
0,0,31,31,31,31,31,31,31,31,31,31,31,31,0,0,0,26,31,0,0
0,2,31,31,31,31,31,31,31,31,31,31,31,31,31,31,31,31,31,2,0
0,2,2,0,2,0,2,0,2,0,2,0,2,0,2,0,2,0,2,2,0
0,0,0,0,0,0,0,0,0,0,0,0,0,0,0,0,0,0,0,0,0
endlayer

layer
0,0,0,0,0,0,0,0,0,0,0,0,0,0,0,0,0,0,0,0,0
0,37,37,0,37,0,37,0,37,0,37,0,37,0,37,0,37,0,37,37,0
0,37,1,38,1,38,1,38,1,38,1,38,1,38,1,38,1,38,1,37,0
0,0,38,0,0,0,0,0,0,0,1,0,0,0,0,0,0,0,38,0,0
0,37,1,0,18,18,18,18,18,0,1,0,18,18,18,18,18,0,1,37,0
0,0,38,0,18,18,18,18,18,0,1,0,18,18,18,18,18,0,38,0,0
0,37,1,0,18,18,3,18,18,0,1,0,18,18,3,18,18,0,1,37,0
0,0,38,0,18,18,18,18,18,0,1,0,18,18,18,18,18,0,38,0,0
0,37,1,0,18,18,18,18,18,0,1,0,18,18,18,18,18,0,1,37,0
0,0,38,0,0,0,0,0,0,0,1,0,0,0,0,0,0,0,38,0,0
0,37,1,1,1,1,1,1,33,1,1,1,33,1,1,1,1,1,1,37,0
0,0,38,0,0,0,1,0,0,0,0,0,0,0,0,0,0,0,38,0,0
0,2,1,0,0,0,34,0,0,0,0,0,0,0,0,0,0,0,1,37,0
0,0,38,0,18,18,1,0,0,0,0,0,0,0,0,0,0,0,38,0,0
0,2,1,0,18,18,3,1,1,1,0,0,0,1,3,1,1,9,1,2,0
0,0,38,0,18,18,18,18,18,1,0,0,0,1,1,1,0,10,38,0,0
0,2,1,0,18,18,18,18,18,1,16,0,0,1,0,0,0,0,1,2,0
0,0,38,0,0,0,0,0,0,1,0,0,0,1,0,32,11,0,38,0,0
0,2,1,38,1,38,1,38,1,1,1,1,1,1,1,38,1,38,1,2,0
0,2,2,0,2,0,2,0,2,0,2,0,2,0,2,0,2,0,2,2,0
0,0,0,0,0,0,0,0,0,0,0,0,0,0,0,0,0,0,0,0,0
endlayer

layer
0,0,0,0,0,0,0,0,0,0,0,0,0,0,0,0,0,0,0,0,0
0,39,39,0,39,0,39,0,39,0,39,0,39,0,39,0,39,0,39,39,0
0,39,1,38,1,38,1,38,1,38,1,38,1,38,1,38,1,38,1,39,0
0,0,38,0,0,0,0,0,0,0,1,0,0,0,0,0,0,0,38,0,0
0,39,1,0,0,0,0,0,0,0,1,0,0,0,0,0,0,0,1,39,0
0,0,38,0,0,0,0,0,0,0,1,0,0,0,0,0,0,0,38,0,0
0,39,1,0,0,0,3,0,0,0,1,0,0,0,3,0,0,0,1,39,0
0,0,38,0,0,0,0,0,0,0,1,0,0,0,0,0,0,0,38,0,0
0,39,1,0,0,0,0,0,0,0,1,0,0,0,0,0,0,0,1,39,0
0,0,38,0,0,0,0,0,0,0,1,0,0,0,0,0,0,0,38,0,0
0,39,1,1,1,1,1,1,35,1,1,1,35,1,1,1,1,1,1,39,0
0,0,38,0,0,0,1,0,0,0,0,0,0,0,0,0,0,0,38,0,0
0,2,1,0,0,0,35,0,0,0,0,0,0,0,0,0,0,0,1,39,0
0,0,38,0,0,0,1,0,0,0,0,0,0,0,0,0,21,0,38,0,0
0,2,1,0,0,0,3,1,1,1,0,0,0,1,3,1,1,20,1,2,0
0,0,38,0,0,0,0,0,0,1,0,0,0,1,1,1,0,0,38,0,0
0,2,1,0,0,0,0,0,0,1,16,0,0,1,0,0,0,0,1,2,0
0,0,38,0,0,0,0,0,0,1,0,0,0,1,32,11,0,0,38,0,0
0,2,1,38,1,38,1,38,1,1,1,1,1,1,1,38,1,38,1,2,0
0,2,2,0,2,0,2,0,2,0,2,0,2,0,2,0,2,0,2,2,0
0,0,0,0,0,0,0,0,0,0,0,0,0,0,0,0,0,0,0,0,0
endlayer

layer
0,0,0,0,0,0,0,0,0,0,0,0,0,0,0,0,0,0,0,0,0
0,39,39,0,39,0,39,0,39,0,39,0,39,0,39,0,39,0,39,39,0
0,39,1,38,1,38,1,38,1,38,1,38,1,38,1,38,1,38,1,39,0
0,0,38,0,0,0,0,0,0,0,1,0,0,0,0,0,0,0,38,0,0
0,39,1,0,0,0,0,0,0,0,1,0,0,0,0,0,0,0,1,39,0
0,0,38,0,0,0,0,0,0,0,1,0,0,0,0,0,0,0,38,0,0
0,39,1,0,0,0,3,0,0,0,1,0,0,0,3,0,0,0,1,39,0
0,0,38,0,0,0,0,0,0,0,1,0,0,0,0,0,0,0,38,0,0
0,39,1,0,0,0,0,0,0,0,1,0,0,0,0,0,0,0,1,39,0
0,0,38,0,0,0,0,0,0,0,1,0,0,0,0,0,0,0,38,0,0
0,39,1,1,1,1,1,1,1,1,1,1,1,1,1,1,1,1,1,39,0
0,0,38,0,0,0,1,0,0,0,0,0,0,0,0,0,0,0,38,0,0
0,2,1,0,0,0,1,0,0,0,0,0,0,0,0,0,0,0,1,39,0
0,0,38,0,0,0,1,0,0,0,0,0,0,0,0,0,0,23,38,0,0
0,2,1,0,0,0,3,1,1,1,0,0,0,1,3,1,1,1,1,2,0
0,0,38,0,0,0,0,0,0,1,0,0,0,1,1,1,1,0,38,0,0
0,2,1,0,0,0,0,0,0,1,16,0,0,1,26,36,0,0,1,2,0
0,0,38,0,0,0,0,0,0,1,0,0,0,1,11,0,0,0,38,0,0
0,2,1,38,1,38,1,38,1,1,1,1,1,1,1,38,1,38,1,2,0
0,2,2,0,2,0,2,0,2,0,2,0,2,0,2,0,2,0,2,2,0
0,0,0,0,0,0,0,0,0,0,0,0,0,0,0,0,0,0,0,0,0
endlayer

layer
0,0,0,0,0,0,0,0,0,0,0,0,0,0,0,0,0,0,0,0,0
0,39,39,0,39,0,39,0,39,0,39,0,39,0,39,0,39,0,39,39,0
0,39,28,28,28,28,28,28,28,28,28,28,28,28,28,28,28,28,28,39,0
0,0,28,28,28,28,28,28,28,28,28,28,28,28,28,28,28,28,28,0,0
0,39,28,28,28,28,28,28,28,28,28,28,28,28,28,28,28,28,28,39,0
0,0,28,28,28,28,28,28,28,28,28,28,28,28,28,28,28,28,28,0,0
0,39,28,28,28,28,3,28,28,28,28,28,28,28,3,28,28,28,28,39,0
0,0,28,28,28,28,28,28,28,28,28,28,28,28,28,28,28,28,28,0,0
0,39,28,28,28,28,28,28,28,28,28,28,28,28,28,28,28,28,28,39,0
0,0,28,28,28,28,28,28,28,28,28,28,28,28,28,28,28,28,28,0,0
0,39,28,28,28,28,28,28,28,28,28,28,28,28,28,28,28,28,28,39,0
0,0,28,28,28,28,28,28,28,28,28,28,28,28,28,28,28,28,28,0,0
0,2,28,28,28,28,28,28,28,28,28,28,28,28,28,28,28,28,28,39,0
0,0,28,28,28,28,28,28,28,28,28,28,28,28,28,28,28,28,28,0,0
0,2,28,28,28,28,3,28,28,28,28,28,28,28,3,28,28,28,28,2,0
0,0,28,28,28,28,28,28,28,28,0,0,0,28,28,28,28,28,28,0,0
0,2,28,28,28,28,28,28,28,28,16,0,0,28,0,30,0,0,28,2,0
0,0,28,28,28,28,28,28,28,28,28,28,28,28,0,0,0,0,28,0,0
0,2,28,28,28,28,28,28,28,28,28,28,28,28,28,28,28,28,28,2,0
0,2,2,0,2,0,2,0,2,0,2,0,2,0,2,0,2,0,2,2,0
0,0,0,0,0,0,0,0,0,0,0,0,0,0,0,0,0,0,0,0,0
endlayer

layer
0,0,0,0,0,0,0,0,0,0,0,0,0,0,0,0,0,0,0,0,0
0,39,39,0,39,0,39,0,39,0,39,0,39,0,39,0,39,0,39,39,0
0,39,31,31,31,31,31,31,31,31,31,31,31,31,31,31,31,31,31,39,0
0,0,31,31,31,31,31,31,31,31,31,31,31,31,31,31,31,31,31,0,0
0,39,31,31,31,31,31,31,31,31,31,31,31,31,31,31,31,31,31,39,0
0,0,31,31,31,31,31,31,31,31,31,31,31,31,31,31,31,31,31,0,0
0,39,31,31,31,31,3,31,31,31,31,31,31,31,3,31,31,31,31,39,0
0,0,31,31,31,31,31,31,31,31,31,31,31,31,31,31,31,31,31,0,0
0,39,31,31,31,31,31,31,31,31,31,31,31,31,31,31,31,31,31,39,0
0,0,31,31,31,31,31,31,31,31,31,31,31,31,31,31,31,31,31,0,0
0,39,31,31,31,31,31,31,31,31,31,31,31,31,31,31,31,31,31,39,0
0,0,31,31,31,31,31,31,31,31,31,31,31,31,31,31,31,31,31,0,0
0,2,31,31,31,31,31,31,31,31,31,31,31,31,31,31,31,31,31,39,0
0,0,31,31,31,31,31,31,31,31,31,31,31,31,31,31,31,31,31,0,0
0,2,31,31,31,31,3,31,31,31,31,31,31,31,3,31,31,31,31,2,0
0,0,31,31,31,31,31,31,31,31,0,0,0,31,31,31,31,31,31,0,0
0,2,31,31,31,31,31,31,31,31,16,0,0,31,0,0,30,26,31,2,0
0,0,31,31,31,31,31,31,31,31,31,31,31,31,0,0,0,26,31,0,0
0,2,31,31,31,31,31,31,31,31,31,31,31,31,31,31,31,31,31,2,0
0,2,2,0,2,0,2,0,2,0,2,0,2,0,2,0,2,0,2,2,0
0,0,0,0,0,0,0,0,0,0,0,0,0,0,0,0,0,0,0,0,0
endlayer

layer
0,0,0,0,0,0,0,0,0,0,0,0,0,0,0,0,0,0,0,0,0
0,39,39,0,39,0,39,0,39,0,39,0,39,0,39,0,39,0,39,39,0
0,39,40,38,40,38,40,38,40,38,40,38,40,38,40,38,40,38,40,39,0
0,0,38,0,0,0,0,0,0,0,0,0,0,0,0,0,0,0,38,0,0
0,39,40,0,18,18,18,18,18,0,0,0,18,18,18,18,18,0,40,39,0
0,0,38,0,18,18,18,18,18,0,0,0,18,18,18,18,18,0,38,0,0
0,39,1,0,18,18,3,18,18,0,0,0,18,18,3,18,18,0,1,39,0
0,0,38,0,18,18,18,18,18,0,0,0,18,18,18,18,18,0,38,0,0
0,39,1,0,18,18,18,18,18,0,0,0,18,18,18,18,18,0,1,39,0
0,0,38,0,0,0,0,0,0,0,0,0,0,0,0,0,0,0,38,0,0
0,39,1,0,0,0,0,0,0,0,0,0,0,0,0,0,0,0,1,39,0
0,0,38,0,0,0,0,0,0,0,0,0,0,0,0,0,0,0,38,0,0
0,2,1,0,18,18,18,18,18,0,0,0,0,0,0,0,0,0,1,39,0
0,0,38,0,18,18,18,18,18,0,0,0,0,0,0,0,0,0,38,0,0
0,2,1,0,18,18,3,18,18,1,0,0,0,1,3,1,1,9,1,2,0
0,0,38,0,18,18,18,18,18,1,0,0,0,1,1,1,0,10,38,0,0
0,2,1,0,18,18,18,18,18,1,16,0,0,1,0,0,0,0,1,2,0
0,0,38,0,0,0,0,0,0,1,0,0,0,1,0,32,11,0,38,0,0
0,2,1,38,1,38,1,38,1,1,1,1,1,1,1,38,1,38,1,2,0
0,2,2,0,2,0,2,0,2,0,2,0,2,0,2,0,2,0,2,2,0
0,0,0,0,0,0,0,0,0,0,0,0,0,0,0,0,0,0,0,0,0
endlayer

layer
0,0,0,0,0,0,0,0,0,0,0,0,0,0,0,0,0,0,0,0,0
0,39,39,0,39,0,39,0,39,0,39,0,39,0,39,0,39,0,39,39,0
0,39,40,38,40,38,40,38,40,38,40,38,40,38,40,38,40,38,40,39,0
0,0,38,0,0,0,0,0,0,0,0,0,0,0,0,0,0,0,38,0,0
0,39,40,0,0,0,0,0,0,0,0,0,0,0,0,0,0,0,40,39,0
0,0,38,0,0,0,0,0,0,0,0,0,0,0,0,0,0,0,38,0,0
0,39,1,0,0,0,3,0,0,0,0,0,0,0,3,0,0,0,1,39,0
0,0,38,0,0,0,0,0,0,0,0,0,0,0,0,0,0,0,38,0,0
0,39,1,0,0,0,0,0,0,0,0,0,0,0,0,0,0,0,1,39,0
0,0,38,0,0,0,0,0,0,0,0,0,0,0,0,0,0,0,38,0,0
0,39,1,0,0,0,0,0,0,0,0,0,0,0,0,0,0,0,1,39,0
0,0,38,0,0,0,0,0,0,0,0,0,0,0,0,0,0,0,38,0,0
0,2,1,0,0,0,0,0,0,0,0,0,0,0,0,0,0,0,1,39,0
0,0,38,0,0,0,0,0,0,0,0,0,0,0,0,0,21,0,38,0,0
0,2,1,0,0,0,3,0,0,1,0,0,0,1,3,1,1,20,1,2,0
0,0,38,0,0,0,0,0,0,1,0,0,0,1,1,1,0,0,38,0,0
0,2,1,0,0,0,0,0,0,1,16,0,0,1,0,0,0,0,1,2,0
0,0,38,0,0,0,0,0,0,1,0,0,0,1,32,11,0,0,38,0,0
0,2,1,38,1,38,1,38,1,1,1,1,1,1,1,38,1,38,1,2,0
0,2,2,0,2,0,2,0,2,0,2,0,2,0,2,0,2,0,2,2,0
0,0,0,0,0,0,0,0,0,0,0,0,0,0,0,0,0,0,0,0,0
endlayer

layer
0,0,0,0,0,0,0,0,0,0,0,0,0,0,0,0,0,0,0,0,0
0,39,39,0,39,0,39,0,39,0,39,0,39,0,39,0,39,0,39,39,0
0,39,40,38,40,38,40,38,40,38,40,38,40,38,40,38,40,38,40,39,0
0,0,38,0,0,0,0,0,0,0,0,0,0,0,0,0,0,0,38,0,0
0,39,40,0,0,0,0,0,0,0,0,0,0,0,0,0,0,0,40,39,0
0,0,38,0,0,0,0,0,0,0,0,0,0,0,0,0,0,0,38,0,0
0,39,1,0,0,0,3,0,0,0,0,0,0,0,3,0,0,0,1,39,0
0,0,38,0,0,0,0,0,0,0,0,0,0,0,0,0,0,0,38,0,0
0,39,1,0,0,0,0,0,0,0,0,0,0,0,0,0,0,0,1,39,0
0,0,38,0,0,0,0,0,0,0,0,0,0,0,0,0,0,0,38,0,0
0,39,1,0,0,0,0,0,0,0,0,0,0,0,0,0,0,0,1,39,0
0,0,38,0,0,0,0,0,0,0,0,0,0,0,0,0,0,0,38,0,0
0,2,1,0,0,0,0,0,0,0,0,0,0,0,0,0,0,0,1,39,0
0,0,38,0,0,0,0,0,0,0,0,0,0,0,0,0,0,23,38,0,0
0,2,1,0,0,0,3,0,0,1,0,0,0,1,3,1,1,1,1,2,0
0,0,38,0,0,0,0,0,0,1,0,0,0,1,1,1,1,0,38,0,0
0,2,1,0,0,0,0,0,0,1,16,0,0,1,26,36,0,0,1,2,0
0,0,38,0,0,0,0,0,0,1,0,0,0,1,11,0,0,0,38,0,0
0,2,1,38,1,38,1,38,1,1,1,1,1,1,1,38,1,38,1,2,0
0,2,2,0,2,0,2,0,2,0,2,0,2,0,2,0,2,0,2,2,0
0,0,0,0,0,0,0,0,0,0,0,0,0,0,0,0,0,0,0,0,0
endlayer

layer
0,0,0,0,0,0,0,0,0,0,0,0,0,0,0,0,0,0,0,0,0
0,39,39,0,39,0,39,0,39,0,39,0,39,0,39,0,39,0,39,39,0
0,39,40,40,40,40,40,40,40,40,40,40,40,40,40,40,40,40,40,39,0
0,0,40,0,0,0,0,0,0,0,0,0,0,0,0,0,0,0,40,0,0
0,39,40,0,0,0,0,0,0,0,0,0,0,0,0,0,0,0,40,39,0
0,0,28,28,28,28,28,28,28,28,28,28,28,28,28,28,28,28,28,0,0
0,39,28,28,28,28,3,28,28,28,28,28,28,28,3,28,28,28,28,39,0
0,0,28,28,28,28,28,28,28,28,28,28,28,28,28,28,28,28,28,0,0
0,39,28,28,28,28,28,28,28,28,28,28,28,28,28,28,28,28,28,39,0
0,0,28,28,28,28,28,28,28,28,28,28,28,28,28,28,28,28,28,0,0
0,39,28,28,28,28,28,28,28,28,28,28,28,28,28,28,28,28,28,39,0
0,0,28,28,28,28,28,28,28,28,28,28,28,28,28,28,28,28,28,0,0
0,2,28,28,28,28,28,28,28,28,28,28,28,28,28,28,28,28,28,39,0
0,0,28,28,28,28,28,28,28,28,28,28,28,28,28,28,28,28,28,0,0
0,2,28,28,28,28,3,28,28,28,28,28,28,28,3,28,28,28,28,2,0
0,0,28,28,28,28,28,28,28,28,0,0,0,28,28,28,28,28,28,0,0
0,2,28,28,28,28,28,28,28,28,16,0,0,28,0,30,36,0,28,2,0
0,0,28,28,28,28,28,28,28,28,28,28,28,28,0,0,0,0,28,0,0
0,2,28,28,28,28,28,28,28,28,28,28,28,28,28,28,28,28,28,2,0
0,2,2,0,2,0,2,0,2,0,2,0,2,0,2,0,2,0,2,2,0
0,0,0,0,0,0,0,0,0,0,0,0,0,0,0,0,0,0,0,0,0
endlayer

layer
0,0,0,0,0,0,0,0,0,0,0,0,0,0,0,0,0,0,0,0,0
0,39,39,0,39,0,39,0,39,0,39,0,39,0,39,0,39,0,39,39,0
0,39,40,40,40,40,40,40,40,40,40,40,40,40,40,40,40,40,40,39,0
0,0,40,40,40,40,40,40,40,40,40,40,40,40,40,40,40,40,40,0,0
0,39,40,40,40,40,40,40,40,40,40,40,40,40,40,40,40,40,40,39,0
0,0,31,31,31,31,31,31,31,31,31,31,31,31,31,31,31,31,31,0,0
0,39,31,31,31,31,3,31,31,31,31,31,31,31,3,31,31,31,31,39,0
0,0,31,31,31,31,31,31,31,31,31,31,31,31,31,31,31,31,31,0,0
0,39,31,31,31,31,31,31,31,31,31,31,31,31,31,31,31,31,31,39,0
0,0,31,31,31,31,31,31,31,31,31,31,31,31,31,31,31,31,31,0,0
0,39,31,31,31,31,31,31,31,31,31,31,31,31,31,31,31,31,31,39,0
0,0,31,31,31,31,31,31,31,31,31,31,31,31,31,31,31,31,31,0,0
0,2,31,31,31,31,31,31,31,31,31,31,31,31,31,31,31,31,31,39,0
0,0,31,31,31,31,31,31,31,31,31,31,31,31,31,31,31,31,31,0,0
0,2,31,31,31,31,3,31,31,31,31,31,31,31,3,31,31,31,31,2,0
0,0,31,31,31,31,31,31,31,31,0,0,0,31,31,31,31,31,31,0,0
0,2,31,31,31,31,31,31,31,31,16,0,0,31,0,0,30,26,31,2,0
0,0,31,31,31,31,31,31,31,31,31,31,31,31,0,0,0,26,31,0,0
0,2,31,31,31,31,31,31,31,31,31,31,31,31,31,31,31,31,31,2,0
0,2,2,0,2,0,2,0,2,0,2,0,2,0,2,0,2,0,2,2,0
0,0,0,0,0,0,0,0,0,0,0,0,0,0,0,0,0,0,0,0,0
endlayer

layer
0,0,0,0,0,0,0,0,0,0,0,0,0,0,0,0,0,0,0,0,0
0,39,39,0,39,0,39,0,39,0,39,0,39,0,39,0,39,0,39,39,0
0,39,40,38,40,38,40,38,40,38,40,38,40,38,40,38,40,38,40,39,0
0,0,38,0,0,0,0,0,0,0,0,0,0,0,0,0,0,0,38,0,0
0,39,40,0,18,18,18,18,18,0,0,0,18,18,18,18,18,0,40,39,0
0,0,38,0,18,18,18,18,18,0,0,0,18,18,18,18,18,0,38,0,0
0,39,1,0,18,18,3,18,18,0,0,0,18,18,3,18,18,0,1,39,0
0,0,38,0,18,18,18,18,18,0,0,0,18,18,18,18,18,0,38,0,0
0,39,1,0,18,18,18,18,18,0,0,0,18,18,18,18,18,0,1,39,0
0,0,38,0,0,0,0,0,0,0,0,0,0,0,0,0,0,0,38,0,0
0,39,1,0,0,0,0,0,0,0,0,0,0,0,0,0,0,0,1,39,0
0,0,38,0,0,0,0,0,0,0,0,0,0,0,0,0,0,0,38,0,0
0,2,1,0,18,18,18,18,18,0,0,0,0,0,0,0,0,0,1,39,0
0,0,38,0,18,18,18,18,18,0,0,0,0,0,0,0,0,0,38,0,0
0,2,1,0,18,18,3,18,18,1,0,0,0,1,3,1,1,9,1,2,0
0,0,38,0,18,18,18,18,18,1,0,0,0,1,1,1,0,10,38,0,0
0,2,1,0,18,18,18,18,18,1,16,0,0,1,0,0,0,0,1,2,0
0,0,38,0,0,0,0,0,0,1,0,0,0,1,0,32,11,0,38,0,0
0,2,1,38,1,38,1,38,1,1,1,1,1,1,1,38,1,38,1,2,0
0,2,2,0,2,0,2,0,2,0,2,0,2,0,2,0,2,0,2,2,0
0,0,0,0,0,0,0,0,0,0,0,0,0,0,0,0,0,0,0,0,0
endlayer

layer
0,0,0,0,0,0,0,0,0,0,0,0,0,0,0,0,0,0,0,0,0
0,39,39,0,39,0,39,0,39,0,39,0,39,0,39,0,39,0,39,39,0
0,39,40,38,40,38,40,38,40,38,40,38,40,38,40,38,40,38,40,39,0
0,0,38,0,0,0,0,0,0,0,0,0,0,0,0,0,0,0,38,0,0
0,39,40,0,0,0,0,0,0,0,0,0,0,0,0,0,0,0,40,39,0
0,0,38,0,0,0,0,0,0,0,0,0,0,0,0,0,0,0,38,0,0
0,39,1,0,0,0,3,0,0,0,0,0,0,0,3,0,0,0,1,39,0
0,0,38,0,0,0,0,0,0,0,0,0,0,0,0,0,0,0,38,0,0
0,39,1,0,0,0,0,0,0,0,0,0,0,0,0,0,0,0,1,39,0
0,0,38,0,0,0,0,0,0,0,0,0,0,0,0,0,0,0,38,0,0
0,39,1,0,0,0,0,0,0,0,0,0,0,0,0,0,0,0,1,39,0
0,0,38,0,0,0,0,0,0,0,0,0,0,0,0,0,0,0,38,0,0
0,2,1,0,0,0,0,0,0,0,0,0,0,0,0,0,0,0,1,39,0
0,0,38,0,0,0,0,0,0,0,0,0,0,0,0,0,21,0,38,0,0
0,2,1,0,0,0,3,0,0,1,0,0,0,1,3,1,1,20,1,2,0
0,0,38,0,0,0,0,0,0,1,0,0,0,1,1,1,0,0,38,0,0
0,2,1,0,0,0,0,0,0,1,16,0,0,1,0,0,0,0,1,2,0
0,0,38,0,0,0,0,0,0,1,0,0,0,1,0,11,0,0,38,0,0
0,2,1,38,1,38,1,38,1,1,1,1,1,1,1,38,1,38,1,2,0
0,2,2,0,2,0,2,0,2,0,2,0,2,0,2,0,2,0,2,2,0
0,0,0,0,0,0,0,0,0,0,0,0,0,0,0,0,0,0,0,0,0
endlayer

layer
0,0,0,0,0,0,0,0,0,0,0,0,0,0,0,0,0,0,0,0,0
0,39,39,0,39,0,39,0,39,0,39,0,39,0,39,0,39,0,39,39,0
0,39,40,38,40,38,40,38,40,38,40,38,40,38,40,38,40,38,40,39,0
0,0,38,0,0,0,0,0,0,0,0,0,0,0,0,0,0,0,38,0,0
0,39,40,0,0,0,0,0,0,0,0,0,0,0,0,0,0,0,40,39,0
0,0,38,0,0,0,0,0,0,0,0,0,0,0,0,0,0,0,38,0,0
0,39,1,0,0,0,3,0,0,0,0,0,0,0,3,0,0,0,1,39,0
0,0,38,0,0,0,0,0,0,0,0,0,0,0,0,0,0,0,38,0,0
0,39,1,0,0,0,0,0,0,0,0,0,0,0,0,0,0,0,1,39,0
0,0,38,0,0,0,0,0,0,0,0,0,0,0,0,0,0,0,38,0,0
0,39,1,0,0,0,0,0,0,0,0,0,0,0,0,0,0,0,1,39,0
0,0,38,0,0,0,0,0,0,0,0,0,0,0,0,0,0,0,38,0,0
0,2,1,0,0,0,0,0,0,0,0,0,0,0,0,0,0,0,1,39,0
0,0,38,0,0,0,0,0,0,0,0,0,0,0,0,0,0,23,38,0,0
0,2,1,0,0,0,3,0,0,1,0,0,0,1,3,1,1,1,1,2,0
0,0,38,0,0,0,0,0,0,1,0,0,0,1,1,1,1,0,38,0,0
0,2,1,0,0,0,0,0,0,1,16,0,0,1,26,36,0,0,1,2,0
0,0,38,0,0,0,0,0,0,1,0,0,0,1,11,0,0,0,38,0,0
0,2,1,38,1,38,1,38,1,1,1,1,1,1,1,38,1,38,1,2,0
0,2,2,0,2,0,2,0,2,0,2,0,2,0,2,0,2,0,2,2,0
0,0,0,0,0,0,0,0,0,0,0,0,0,0,0,0,0,0,0,0,0
endlayer

layer
0,0,0,0,0,0,0,0,0,0,0,0,0,0,0,0,0,0,0,0,0
0,39,39,0,39,0,39,0,39,0,39,0,39,0,39,0,39,0,39,39,0
0,39,40,40,40,40,40,40,40,40,40,40,40,40,40,40,40,40,40,39,0
0,0,40,0,0,0,0,0,0,0,0,0,0,0,0,0,0,0,40,0,0
0,39,40,0,0,0,0,0,0,0,0,0,0,0,0,0,0,0,40,39,0
0,0,40,0,0,0,0,0,0,0,0,0,0,0,0,0,0,0,40,0,0
0,39,28,28,28,28,3,28,28,28,28,28,28,28,3,28,28,28,28,39,0
0,0,28,28,28,28,28,28,28,28,28,28,28,28,28,28,28,28,28,0,0
0,39,28,28,28,28,28,28,28,28,28,28,28,28,28,28,28,28,28,39,0
0,0,28,28,28,28,28,28,28,28,28,28,28,28,28,28,28,28,28,0,0
0,39,28,28,28,28,28,28,28,28,28,28,28,28,28,28,28,28,28,39,0
0,0,28,28,28,28,28,28,28,28,28,28,28,28,28,28,28,28,28,0,0
0,2,28,28,28,28,28,28,28,28,28,28,28,28,28,28,28,28,28,39,0
0,0,28,28,28,28,28,28,28,28,28,28,28,28,28,28,28,28,28,0,0
0,2,28,28,28,28,3,28,28,28,28,28,28,28,3,28,28,28,28,2,0
0,0,28,28,28,28,28,28,28,28,0,0,0,28,28,28,28,28,28,0,0
0,2,28,28,28,28,28,28,28,28,16,0,0,28,0,30,36,0,28,2,0
0,0,28,28,28,28,28,28,28,28,28,28,28,28,0,0,0,0,28,0,0
0,2,28,28,28,28,28,28,28,28,28,28,28,28,28,28,28,28,28,2,0
0,2,2,0,2,0,2,0,2,0,2,0,2,0,2,0,2,0,2,2,0
0,0,0,0,0,0,0,0,0,0,0,0,0,0,0,0,0,0,0,0,0
endlayer

layer
0,0,0,0,0,0,0,0,0,0,0,0,0,0,0,0,0,0,0,0,0
0,39,39,0,39,0,39,0,39,0,39,0,39,0,39,0,39,0,39,39,0
0,39,40,40,40,40,40,40,40,40,40,40,40,40,40,40,40,40,40,39,0
0,0,40,40,40,40,40,40,40,40,40,40,40,40,40,40,40,40,40,0,0
0,39,40,40,40,40,40,40,40,40,40,40,40,40,40,40,40,40,40,39,0
0,0,40,40,40,40,40,40,40,40,40,40,40,40,40,40,40,40,40,0,0
0,39,31,31,31,31,3,31,31,31,31,31,31,31,3,31,31,40,40,39,0
0,0,31,31,31,31,31,31,31,31,31,31,31,31,31,31,31,31,31,0,0
0,39,31,31,31,31,31,31,31,31,31,31,31,31,31,31,31,31,31,39,0
0,0,31,31,31,31,31,31,31,31,31,31,31,31,31,31,31,31,31,0,0
0,39,31,31,31,31,31,31,31,31,31,31,31,31,31,31,31,31,31,39,0
0,0,31,31,31,31,31,31,31,31,31,31,31,31,31,31,31,31,31,0,0
0,2,31,31,31,31,31,31,31,31,31,31,31,31,31,31,31,31,31,39,0
0,0,31,31,31,31,31,31,31,31,31,31,31,31,31,31,31,31,31,0,0
0,2,31,31,31,31,3,31,31,31,31,31,31,31,3,31,31,31,31,2,0
0,0,31,31,31,31,31,31,31,31,0,0,0,31,31,31,31,31,31,0,0
0,2,31,31,31,31,31,31,31,31,16,0,0,31,0,0,30,26,31,2,0
0,0,31,31,31,31,31,31,31,31,31,31,31,31,0,0,0,26,31,0,0
0,2,31,31,31,31,31,31,31,31,31,31,31,31,31,31,31,31,31,2,0
0,2,2,0,2,0,2,0,2,0,2,0,2,0,2,0,2,0,2,2,0
0,0,0,0,0,0,0,0,0,0,0,0,0,0,0,0,0,0,0,0,0
endlayer

layer
0,0,0,0,0,0,0,0,0,0,0,0,0,0,0,0,0,0,0,0,0
0,39,39,0,39,0,39,0,39,0,39,0,39,0,39,0,39,0,39,39,0
0,39,40,38,40,38,40,38,40,38,40,38,40,38,40,38,40,38,40,39,0
0,0,38,0,0,0,0,0,0,0,0,0,0,0,0,0,0,0,38,0,0
0,39,40,0,18,18,18,18,18,0,0,0,18,18,18,18,18,0,40,39,0
0,0,38,0,18,18,18,18,18,0,0,0,18,18,18,18,18,0,38,0,0
0,39,40,0,18,18,3,18,18,0,0,0,18,18,3,18,18,0,40,39,0
0,0,38,0,18,18,18,18,18,0,0,0,18,18,18,18,18,0,38,0,0
0,39,1,0,18,18,18,18,18,0,0,0,18,18,18,18,18,0,1,39,0
0,0,38,0,0,0,0,0,0,0,0,0,0,0,0,0,0,0,38,0,0
0,39,1,0,0,0,0,0,0,0,0,0,0,0,0,0,0,0,1,39,0
0,0,38,0,0,0,0,0,0,0,0,0,0,0,0,0,0,0,38,0,0
0,2,1,0,18,18,18,18,18,0,0,0,0,0,0,0,0,0,1,39,0
0,0,38,0,18,18,18,18,18,0,0,0,0,0,0,0,0,0,38,0,0
0,2,1,0,18,18,3,18,18,1,0,0,0,1,3,1,1,9,1,2,0
0,0,38,0,18,18,18,18,18,1,0,0,0,1,1,1,0,10,38,0,0
0,2,1,0,18,18,18,18,18,1,16,0,0,1,0,0,0,0,1,2,0
0,0,38,0,0,0,0,0,0,1,0,0,0,1,0,32,11,0,38,0,0
0,2,1,38,1,38,1,38,1,1,1,1,1,1,1,38,1,38,1,2,0
0,2,2,0,2,0,2,0,2,0,2,0,2,0,2,0,2,0,2,2,0
0,0,0,0,0,0,0,0,0,0,0,0,0,0,0,0,0,0,0,0,0
endlayer

layer
0,0,0,0,0,0,0,0,0,0,0,0,0,0,0,0,0,0,0,0,0
0,39,39,0,39,0,39,0,39,0,39,0,39,0,39,0,39,0,39,39,0
0,39,40,38,40,38,40,38,40,38,40,38,40,38,40,38,40,38,40,39,0
0,0,38,0,0,0,0,0,0,0,0,0,0,0,0,0,0,0,38,0,0
0,39,40,0,0,0,0,0,0,0,0,0,0,0,0,0,0,0,40,39,0
0,0,38,0,0,0,0,0,0,0,0,0,0,0,0,0,0,0,38,0,0
0,39,40,0,0,0,3,0,0,0,0,0,0,0,3,0,0,0,40,39,0
0,0,38,0,0,0,0,0,0,0,0,0,0,0,0,0,0,0,38,0,0
0,39,1,0,0,0,0,0,0,0,0,0,0,0,0,0,0,0,1,39,0
0,0,38,0,0,0,0,0,0,0,0,0,0,0,0,0,0,0,38,0,0
0,39,1,0,0,0,0,0,0,0,0,0,0,0,0,0,0,0,1,39,0
0,0,38,0,0,0,0,0,0,0,0,0,0,0,0,0,0,0,38,0,0
0,2,1,0,0,0,0,0,0,0,0,0,0,0,0,0,0,0,1,39,0
0,0,38,0,0,0,0,0,0,0,0,0,0,0,0,0,21,0,38,0,0
0,2,1,0,0,0,3,0,0,1,0,0,0,1,3,1,1,20,1,2,0
0,0,38,0,0,0,0,0,0,1,0,0,0,1,1,1,0,0,38,0,0
0,2,1,0,0,0,0,0,0,1,16,0,0,1,0,0,0,0,1,2,0
0,0,38,0,0,0,0,0,0,1,0,0,0,1,32,11,0,0,38,0,0
0,2,1,38,1,38,1,38,1,1,1,1,1,1,1,38,1,38,1,2,0
0,2,2,0,2,0,2,0,2,0,2,0,2,0,2,0,2,0,2,2,0
0,0,0,0,0,0,0,0,0,0,0,0,0,0,0,0,0,0,0,0,0
endlayer

layer
0,0,0,0,0,0,0,0,0,0,0,0,0,0,0,0,0,0,0,0,0
0,39,39,0,39,0,39,0,39,0,39,0,39,0,39,0,39,0,39,39,0
0,39,40,38,40,38,40,38,40,38,40,38,40,38,40,38,40,38,40,39,0
0,0,38,0,0,0,0,0,0,0,0,0,0,0,0,0,0,0,38,0,0
0,39,40,0,0,0,0,0,0,0,0,0,0,0,0,0,0,0,40,39,0
0,0,38,0,0,0,0,0,0,0,0,0,0,0,0,0,0,0,38,0,0
0,39,40,0,0,0,3,0,0,0,0,0,0,0,3,0,0,0,40,39,0
0,0,38,0,0,0,0,0,0,0,0,0,0,0,0,0,0,0,38,0,0
0,39,1,0,0,0,0,0,0,0,0,0,0,0,0,0,0,0,1,39,0
0,0,38,0,0,0,0,0,0,0,0,0,0,0,0,0,0,0,38,0,0
0,39,1,0,0,0,0,0,0,0,0,0,0,0,0,0,0,0,1,39,0
0,0,38,0,0,0,0,0,0,0,0,0,0,0,0,0,0,0,38,0,0
0,2,1,0,0,0,0,0,0,0,0,0,0,0,0,0,0,0,1,39,0
0,0,38,0,0,0,0,0,0,0,0,0,0,0,0,0,0,23,38,0,0
0,2,1,0,0,0,3,0,0,1,0,0,0,1,3,1,1,1,1,2,0
0,0,38,0,0,0,0,0,0,1,0,0,0,1,1,1,1,0,38,0,0
0,2,1,0,0,0,0,0,0,1,16,0,0,1,26,36,0,0,1,2,0
0,0,38,0,0,0,0,0,0,1,0,0,0,1,11,0,0,0,38,0,0
0,2,1,38,1,38,1,38,1,1,1,1,1,1,1,38,1,38,1,2,0
0,2,2,0,2,0,2,0,2,0,2,0,2,0,2,0,2,0,2,2,0
0,0,0,0,0,0,0,0,0,0,0,0,0,0,0,0,0,0,0,0,0
endlayer

layer
0,0,0,0,0,0,0,0,0,0,0,0,0,0,0,0,0,0,0,0,0
0,39,39,0,39,0,39,0,39,0,39,0,39,0,39,0,39,0,39,39,0
0,39,40,40,40,40,40,40,40,40,40,40,40,40,40,40,40,40,40,39,0
0,0,40,0,0,0,0,0,0,0,0,0,0,0,0,0,0,0,40,0,0
0,39,40,0,0,0,0,0,0,0,0,0,0,0,0,0,0,0,40,39,0
0,0,40,0,0,0,0,0,0,0,0,0,0,0,0,0,0,0,40,0,0
0,39,40,0,0,0,3,0,0,0,0,0,0,0,3,0,0,0,40,39,0
0,0,28,28,28,28,28,28,28,28,28,28,28,28,28,28,28,28,28,0,0
0,39,28,28,28,28,28,28,28,28,28,28,28,28,28,28,28,28,28,39,0
0,0,28,28,28,28,28,28,28,28,28,28,28,28,28,28,28,28,28,0,0
0,39,28,28,28,28,28,28,28,28,28,28,28,28,28,28,28,28,28,39,0
0,0,28,28,28,28,28,28,28,28,28,28,28,28,28,28,28,28,28,0,0
0,2,28,28,28,28,28,28,28,28,28,28,28,28,28,28,28,28,28,39,0
0,0,28,28,28,28,28,28,28,28,28,28,28,28,28,28,28,28,28,0,0
0,2,28,28,28,28,3,28,28,28,28,28,28,28,3,28,28,28,28,2,0
0,0,28,28,28,28,28,28,28,28,0,0,0,28,28,28,28,28,28,0,0
0,2,28,28,28,28,28,28,28,28,16,0,0,28,0,30,36,0,28,2,0
0,0,28,28,28,28,28,28,28,28,28,28,28,28,0,0,0,0,28,0,0
0,2,28,28,28,28,28,28,28,28,28,28,28,28,28,28,28,28,28,2,0
0,2,2,0,2,0,2,0,2,0,2,0,2,0,2,0,2,0,2,2,0
0,0,0,0,0,0,0,0,0,0,0,0,0,0,0,0,0,0,0,0,0
endlayer

layer
0,0,0,0,0,0,0,0,0,0,0,0,0,0,0,0,0,0,0,0,0
0,39,39,0,39,0,39,0,39,0,39,0,39,0,39,0,39,0,39,39,0
0,39,40,40,40,40,40,40,40,40,40,40,40,40,40,40,40,40,40,39,0
0,0,40,40,40,40,40,40,40,40,40,40,40,40,40,40,40,40,40,0,0
0,39,40,40,40,40,40,40,40,40,40,40,40,40,40,40,40,40,40,39,0
0,0,40,40,40,40,40,40,40,40,40,40,40,40,40,40,40,40,40,0,0
0,39,40,40,40,40,3,40,40,40,40,40,40,40,3,40,40,40,40,39,0
0,0,31,31,31,31,31,31,31,31,31,31,31,31,31,31,31,31,31,0,0
0,39,31,31,31,31,31,31,31,31,31,31,31,31,31,31,31,31,31,39,0
0,0,31,31,31,31,31,31,31,31,31,31,31,31,31,31,31,31,31,0,0
0,39,31,31,31,31,31,31,31,31,31,31,31,31,31,31,31,31,31,39,0
0,0,31,31,31,31,31,31,31,31,31,31,31,31,31,31,31,31,31,0,0
0,2,31,31,31,31,31,31,31,31,31,31,31,31,31,31,31,31,31,39,0
0,0,31,31,31,31,31,31,31,31,31,31,31,31,31,31,31,31,31,0,0
0,2,31,31,31,31,3,31,31,31,31,31,31,31,3,31,31,31,31,2,0
0,0,31,31,31,31,31,31,31,31,0,0,0,31,31,31,31,31,31,0,0
0,2,31,31,31,31,31,31,31,31,16,0,0,31,0,0,30,26,31,2,0
0,0,31,31,31,31,31,31,31,31,31,31,31,31,0,0,0,26,31,0,0
0,2,31,31,31,31,31,31,31,31,31,31,31,31,31,31,31,31,31,2,0
0,2,2,0,2,0,2,0,2,0,2,0,2,0,2,0,2,0,2,2,0
0,0,0,0,0,0,0,0,0,0,0,0,0,0,0,0,0,0,0,0,0
endlayer

layer
0,0,0,0,0,0,0,0,0,0,0,0,0,0,0,0,0,0,0,0,0
0,39,39,0,39,0,39,0,39,0,39,0,39,0,39,0,39,0,39,39,0
0,39,40,38,40,38,40,38,40,38,40,38,40,38,40,38,40,38,40,39,0
0,0,38,0,0,0,0,0,0,0,0,0,0,0,0,0,0,0,38,0,0
0,39,40,0,18,18,18,18,18,0,0,0,18,18,18,18,18,0,40,39,0
0,0,38,0,18,18,18,18,18,0,0,0,18,18,18,18,18,0,38,0,0
0,39,40,0,18,18,3,18,18,0,0,0,18,18,3,18,18,0,40,39,0
0,0,38,0,18,18,18,18,18,0,0,0,18,18,18,18,18,0,38,0,0
0,39,40,0,18,18,18,18,18,0,0,0,18,18,18,18,18,0,40,39,0
0,0,38,0,0,0,0,0,0,0,0,0,0,0,0,0,0,0,38,0,0
0,39,40,0,0,0,0,0,0,0,0,0,0,0,0,0,0,0,40,39,0
0,0,38,0,0,0,0,0,0,0,0,0,0,0,0,0,0,0,38,0,0
0,2,1,0,18,18,18,18,18,0,0,0,0,0,0,0,0,0,1,39,0
0,0,38,0,18,18,18,18,18,0,0,0,0,0,0,0,0,0,38,0,0
0,2,1,0,18,18,3,18,18,1,0,0,0,1,3,1,1,9,1,2,0
0,0,38,0,18,18,18,18,18,1,0,0,0,1,1,1,0,10,38,0,0
0,2,1,0,18,18,18,18,18,1,16,0,0,1,0,0,0,0,1,2,0
0,0,38,0,0,0,0,0,0,1,0,0,0,1,0,32,11,0,38,0,0
0,2,1,38,1,38,1,38,1,1,1,1,1,1,1,38,1,38,1,2,0
0,2,2,0,2,0,2,0,2,0,2,0,2,0,2,0,2,0,2,2,0
0,0,0,0,0,0,0,0,0,0,0,0,0,0,0,0,0,0,0,0,0
endlayer

layer
0,0,0,0,0,0,0,0,0,0,0,0,0,0,0,0,0,0,0,0,0
0,39,39,0,39,0,39,0,39,0,39,0,39,0,39,0,39,0,39,39,0
0,39,40,38,40,38,40,38,40,38,40,38,40,38,40,38,40,38,40,39,0
0,0,38,0,0,0,0,0,0,0,0,0,0,0,0,0,0,0,38,0,0
0,39,40,0,0,0,0,0,0,0,0,0,0,0,0,0,0,0,40,39,0
0,0,38,0,0,0,0,0,0,0,0,0,0,0,0,0,0,0,38,0,0
0,39,40,0,0,0,3,0,0,0,0,0,0,0,3,0,0,0,40,39,0
0,0,38,0,0,0,0,0,0,0,0,0,0,0,0,0,0,0,38,0,0
0,39,40,0,0,0,0,0,0,0,0,0,0,0,0,0,0,0,40,39,0
0,0,38,0,0,0,0,0,0,0,0,0,0,0,0,0,0,0,38,0,0
0,39,40,0,0,0,0,0,0,0,0,0,0,0,0,0,0,0,40,39,0
0,0,38,0,0,0,0,0,0,0,0,0,0,0,0,0,0,0,38,0,0
0,2,1,0,0,0,0,0,0,0,0,0,0,0,0,0,0,0,1,39,0
0,0,38,0,0,0,0,0,0,0,0,0,0,0,0,0,21,0,38,0,0
0,2,1,0,0,0,3,0,0,1,0,0,0,1,3,1,1,20,1,2,0
0,0,38,0,0,0,0,0,0,1,0,0,0,1,1,1,0,0,38,0,0
0,2,1,0,0,0,0,0,0,1,16,0,0,1,0,0,0,0,1,2,0
0,0,38,0,0,0,0,0,0,1,0,0,0,1,32,11,0,0,38,0,0
0,2,1,38,1,38,1,38,1,1,1,1,1,1,1,38,1,38,1,2,0
0,2,2,0,2,0,2,0,2,0,2,0,2,0,2,0,2,0,2,2,0
0,0,0,0,0,0,0,0,0,0,0,0,0,0,0,0,0,0,0,0,0
endlayer

layer
0,0,0,0,0,0,0,0,0,0,0,0,0,0,0,0,0,0,0,0,0
0,39,39,0,39,0,39,0,39,0,39,0,39,0,39,0,39,0,39,39,0
0,39,40,38,40,38,40,38,40,38,40,38,40,38,40,38,40,38,40,39,0
0,0,38,0,0,0,0,0,0,0,0,0,0,0,0,0,0,0,38,0,0
0,39,40,0,0,0,0,0,0,0,0,0,0,0,0,0,0,0,40,39,0
0,0,38,0,0,0,0,0,0,0,0,0,0,0,0,0,0,0,38,0,0
0,39,40,0,0,0,3,0,0,0,0,0,0,0,3,0,0,0,40,39,0
0,0,38,0,0,0,0,0,0,0,0,0,0,0,0,0,0,0,38,0,0
0,39,40,0,0,0,0,0,0,0,0,0,0,0,0,0,0,0,40,39,0
0,0,38,0,0,0,0,0,0,0,0,0,0,0,0,0,0,0,38,0,0
0,39,40,0,0,0,0,0,0,0,0,0,0,0,0,0,0,0,40,39,0
0,0,38,0,0,0,0,0,0,0,0,0,0,0,0,0,0,0,38,0,0
0,2,1,0,0,0,0,0,0,0,0,0,0,0,0,0,0,0,1,39,0
0,0,38,0,0,0,0,0,0,0,0,0,0,0,0,0,0,23,38,0,0
0,2,1,0,0,0,3,0,0,1,0,0,0,1,3,1,1,1,1,2,0
0,0,38,0,0,0,0,0,0,1,0,0,0,1,1,1,1,0,38,0,0
0,2,1,0,0,0,0,0,0,1,16,0,0,1,26,36,0,0,1,2,0
0,0,38,0,0,0,0,0,0,1,0,0,0,1,11,0,0,0,38,0,0
0,2,1,38,1,38,1,38,1,1,1,1,1,1,1,38,1,38,1,2,0
0,2,2,0,2,0,2,0,2,0,2,0,2,0,2,0,2,0,2,2,0
0,0,0,0,0,0,0,0,0,0,0,0,0,0,0,0,0,0,0,0,0
endlayer

layer
0,0,0,0,0,0,0,0,0,0,0,0,0,0,0,0,0,0,0,0,0
0,39,39,0,39,0,39,0,39,0,39,0,39,0,39,0,39,0,39,39,0
0,39,40,40,40,40,40,40,40,40,40,40,40,40,40,40,40,40,40,39,0
0,0,40,0,0,0,0,0,0,0,0,0,0,0,0,0,0,0,40,0,0
0,39,40,0,0,0,0,0,0,0,0,0,0,0,0,0,0,0,40,39,0
0,0,40,0,0,0,0,0,0,0,0,0,0,0,0,0,0,0,40,0,0
0,39,40,0,0,0,3,0,0,0,0,0,0,0,3,0,0,0,40,39,0
0,0,40,0,0,0,0,0,0,0,0,0,0,0,0,0,0,0,40,0,0
0,39,40,0,0,28,28,28,28,28,28,28,28,28,0,0,0,0,40,39,0
0,0,40,0,0,28,28,28,28,28,28,28,28,28,0,0,0,0,40,0,0
0,39,40,28,28,28,28,28,28,28,28,28,28,28,28,28,28,28,40,39,0
0,0,28,28,28,28,28,28,28,28,28,28,28,28,28,28,28,28,28,0,0
0,2,28,28,28,28,28,28,28,28,28,28,28,28,28,28,28,28,28,39,0
0,0,28,28,28,28,28,28,28,28,28,28,28,28,28,28,28,28,28,0,0
0,2,28,28,28,28,3,28,28,28,28,28,28,28,3,28,28,28,28,2,0
0,0,28,28,28,28,28,28,28,28,0,0,0,28,28,28,28,28,28,0,0
0,2,28,28,28,28,28,28,28,28,16,0,0,28,0,30,36,0,28,2,0
0,0,28,28,28,28,28,28,28,28,28,28,28,28,0,0,0,0,28,0,0
0,2,28,28,28,28,28,28,28,28,28,28,28,28,28,28,28,28,28,2,0
0,2,2,0,2,0,2,0,2,0,2,0,2,0,2,0,2,0,2,2,0
0,0,0,0,0,0,0,0,0,0,0,0,0,0,0,0,0,0,0,0,0
endlayer

layer
0,0,0,0,0,0,0,0,0,0,0,0,0,0,0,0,0,0,0,0,0
0,39,39,0,39,0,39,0,39,0,39,0,39,0,39,0,39,0,39,39,0
0,39,40,40,40,40,40,40,40,40,40,40,40,40,40,40,40,40,40,39,0
0,0,40,40,40,40,40,40,40,40,40,40,40,40,40,40,40,40,40,0,0
0,39,40,40,40,40,40,40,40,40,40,40,40,40,40,40,40,40,40,39,0
0,0,40,40,40,40,40,40,40,40,40,40,40,40,40,40,40,40,40,0,0
0,39,40,40,40,40,3,40,40,40,40,40,40,40,3,40,40,40,40,39,0
0,0,40,40,40,40,40,40,40,40,40,40,40,40,40,40,40,40,40,0,0
0,39,40,40,40,31,31,31,31,31,31,31,31,31,40,40,40,40,40,39,0
0,0,40,40,40,31,31,31,31,31,31,31,31,31,40,40,40,40,40,0,0
0,39,40,31,31,31,31,31,31,31,31,31,31,31,31,31,31,31,40,39,0
0,0,31,31,31,31,31,31,31,31,31,31,31,31,31,31,31,31,31,0,0
0,2,31,31,31,31,31,31,31,31,31,31,31,31,31,31,31,31,31,39,0
0,0,31,31,31,31,31,31,31,31,31,31,31,31,31,31,31,31,31,0,0
0,2,31,31,31,31,3,31,31,31,31,31,31,31,3,31,31,31,31,2,0
0,0,31,31,31,31,31,31,31,31,0,0,0,31,31,31,31,31,31,0,0
0,2,31,31,31,31,31,31,31,31,0,0,0,31,0,0,30,26,31,2,0
0,0,31,31,31,31,31,31,31,31,31,31,31,31,0,0,0,0,31,0,0
0,2,31,31,31,31,31,31,31,31,31,31,31,31,31,31,31,31,31,2,0
0,2,2,0,2,0,2,0,2,0,2,0,2,0,2,0,2,0,2,2,0
0,0,0,0,0,0,0,0,0,0,0,0,0,0,0,0,0,0,0,0,0
endlayer

layer
0,0,0,0,0,0,0,0,0,0,0,0,0,0,0,0,0,0,0,0,0
0,0,0,0,0,0,0,0,0,0,0,0,0,0,0,0,0,0,0,0,0
0,0,0,0,0,0,0,0,0,0,0,0,0,0,0,0,0,0,0,0,0
0,0,0,0,0,0,0,0,0,0,0,0,0,0,0,0,0,0,0,0,0
0,39,40,0,0,0,0,0,0,0,0,0,0,0,0,0,0,0,40,39,0
0,0,40,0,0,0,0,0,0,0,0,0,0,0,0,0,0,0,40,0,0
0,39,40,0,0,0,0,0,0,0,0,0,0,0,0,0,0,0,40,39,0
0,0,40,0,0,0,0,0,0,0,0,0,0,0,0,0,0,0,40,0,0
0,39,40,0,0,42,42,42,42,42,42,42,42,42,0,0,0,0,40,39,0
0,0,40,0,0,42,0,0,0,0,0,0,0,42,0,0,0,0,40,0,0
0,39,40,0,0,42,0,0,0,0,0,0,0,42,42,42,0,0,40,39,0
0,0,1,43,43,42,43,43,43,43,0,0,0,0,0,0,0,0,1,0,0
0,2,1,0,0,42,0,0,0,43,0,0,0,0,0,0,0,0,1,39,0
0,0,1,0,42,42,42,0,0,0,0,0,0,0,0,0,0,0,1,0,0
0,2,1,0,44,42,44,0,0,41,41,41,41,41,0,0,0,10,1,2,0
0,0,1,0,44,42,44,0,0,41,0,15,0,41,41,41,41,9,1,0,0
0,2,1,0,42,42,42,0,0,41,0,15,0,41,0,0,0,10,1,2,0
0,0,1,0,0,0,0,0,0,41,41,41,41,41,41,41,41,41,1,0,0
0,2,1,1,1,1,1,1,1,1,1,1,1,1,1,1,1,1,1,2,0
0,2,2,0,2,0,2,0,2,0,2,0,2,0,2,0,2,0,2,2,0
0,0,0,0,0,0,0,0,0,0,0,0,0,0,0,0,0,0,0,0,0
endlayer

layer
0,0,0,0,0,0,0,0,0,0,0,0,0,0,0,0,0,0,0,0,0
0,0,0,0,0,0,0,0,0,0,0,0,0,0,0,0,0,0,0,0,0
0,0,0,0,0,0,0,0,0,0,0,0,0,0,0,0,0,0,0,0,0
0,0,0,0,0,0,0,0,0,0,0,0,0,0,0,0,0,0,0,0,0
0,0,0,0,0,0,0,0,0,0,0,0,0,0,0,0,0,0,0,0,0
0,0,0,0,0,0,0,0,0,0,0,0,0,0,0,0,0,0,0,0,0
0,0,0,0,0,0,0,0,0,0,0,0,0,0,0,0,0,0,0,0,0
0,0,0,0,0,0,0,0,0,0,0,0,0,0,0,0,0,0,0,0,0
0,0,0,0,0,0,0,0,0,0,0,0,0,0,0,0,0,0,0,0,0
0,0,40,0,0,0,0,0,0,0,0,0,0,0,0,0,0,0,40,0,0
0,39,40,0,0,0,0,0,0,0,0,0,0,0,0,0,0,0,40,39,0
0,0,1,43,43,43,43,43,43,43,0,0,0,0,0,0,0,0,1,0,0
0,2,1,0,0,0,0,0,0,43,0,0,0,0,0,0,0,0,1,39,0
0,0,1,0,42,27,42,0,0,0,0,0,0,0,0,0,0,0,1,0,0
0,2,1,0,27,27,27,0,0,0,48,1,47,0,0,0,0,0,1,2,0
0,0,1,0,27,27,27,0,0,0,48,27,47,0,46,45,41,20,1,0,0
0,2,1,0,42,27,42,0,0,0,48,1,47,0,41,0,0,0,1,2,0
0,0,1,0,0,0,0,0,0,0,0,0,0,0,41,41,41,41,1,0,0
0,2,1,1,1,1,1,1,1,1,1,1,1,1,1,1,1,1,1,2,0
0,2,2,0,2,0,2,0,2,0,2,0,2,0,2,0,2,0,2,2,0
0,0,0,0,0,0,0,0,0,0,0,0,0,0,0,0,0,0,0,0,0
endlayer

layer
0,0,0,0,0,0,0,0,0,0,0,0,0,0,0,0,0,0,0,0,0
0,0,0,0,0,0,0,0,0,0,0,0,0,0,0,0,0,0,0,0,0
0,0,0,0,0,0,0,0,0,0,0,0,0,0,0,0,0,0,0,0,0
0,0,0,0,0,0,0,0,0,0,0,0,0,0,0,0,0,0,0,0,0
0,0,0,0,0,0,0,0,0,0,0,0,0,0,0,0,0,0,0,0,0
0,0,0,0,0,0,0,0,0,0,0,0,0,0,0,0,0,0,0,0,0
0,0,0,0,0,0,0,0,0,0,0,0,0,0,0,0,0,0,0,0,0
0,0,0,0,0,0,0,0,0,0,0,0,0,0,0,0,0,0,0,0,0
0,0,0,0,0,0,0,0,0,0,0,0,0,0,0,0,0,0,0,0,0
0,0,0,0,0,0,0,0,0,0,0,0,0,0,0,0,0,0,0,0,0
0,0,0,0,0,0,0,0,0,0,0,0,0,0,0,0,0,0,0,0,0
0,0,0,0,0,0,0,0,0,0,0,0,0,0,0,0,0,0,0,0,0
0,0,0,0,0,0,0,0,0,0,0,0,0,0,0,0,0,0,0,0,0
0,0,0,0,0,0,0,0,0,0,0,0,0,0,0,0,0,0,0,0,0
0,0,0,0,0,0,0,0,0,0,0,0,0,0,0,0,0,0,0,0,0
0,0,0,0,0,0,0,0,0,0,0,0,0,0,0,0,0,46,0,0,0
0,0,0,0,0,0,0,0,0,0,0,0,0,0,0,46,46,46,0,0,0
0,0,0,0,0,0,0,0,0,0,0,0,0,0,0,0,0,0,0,0,0
0,0,0,0,0,0,0,0,0,0,0,0,0,0,0,0,0,0,0,0,0
0,0,0,0,0,0,0,0,0,0,0,0,0,0,0,0,0,0,0,0,0
0,0,0,0,0,0,0,0,0,0,0,0,0,0,0,0,0,0,0,0,0
endlayer

