# Converted from schematic
# THIS TEMPLATE USES DEFAULTS!  Please edit for corrections.
# If you need help, consult template_rules.txt

weight=2
embed_into_distance=13
acceptable_target_blocks=1,2,3,12,13
dimensions=24,18,15
allowable_overhang=0
max_cut_in=2
cut_in_buffer=1
max_leveling=2
leveling_buffer=1
preserve_water=0
preserve_lava=0
preserve_plants=0


rule1=0,100,12
rule2=0,100,1
rule3=0,100,13
rule4=0,100,24
rule5=0,100,54-4
rule6=0,100,54-2
rule7=0,100,54-3
rule8=0,100,50-3
rule9=0,100,89
rule10=0,100,35-14
rule11=0,100,35-11
rule12=0,100,35-5
rule13=0,100,50-5
rule14=0,100,22
rule15=0,100,24-1
rule16=0,100,3
rule17=0,100,20


layer
1,1,1,1,1,1,1,1,1,1,1,1,1,1,1
1,1,1,1,1,1,1,1,1,1,1,1,1,1,1
1,1,1,1,1,1,1,1,1,1,1,1,1,1,1
1,1,1,1,1,1,1,1,1,1,1,1,1,1,1
1,1,1,1,1,1,1,1,1,1,1,1,1,1,1
1,1,1,1,1,1,1,1,1,1,1,1,1,1,1
1,1,1,1,1,1,1,1,1,1,1,1,1,1,1
1,1,1,1,1,1,1,1,1,1,1,1,1,1,1
1,1,1,1,1,1,1,1,1,1,1,1,1,1,1
1,1,1,1,1,1,1,1,1,1,1,1,1,1,1
1,1,1,1,1,1,1,1,1,1,1,1,1,1,1
1,1,1,1,1,1,1,1,1,1,1,1,1,1,1
1,1,1,1,1,1,1,1,1,1,1,1,1,1,1
1,1,1,1,1,1,1,1,1,1,1,1,1,1,1
1,1,1,1,1,1,1,1,1,1,1,1,1,1,1
1,1,1,1,1,1,1,1,1,1,1,1,1,1,1
1,1,1,1,1,1,1,1,1,1,1,1,1,1,1
1,1,1,1,1,1,1,1,1,1,1,1,1,1,1
endlayer

layer
2,2,2,2,2,2,2,2,2,2,2,2,2,2,2
2,2,2,2,2,2,2,2,2,2,2,2,2,2,2
2,2,2,2,2,2,2,2,2,2,3,3,3,3,3
2,2,2,2,2,2,2,2,3,3,3,3,3,3,3
2,2,2,2,2,2,2,2,3,3,3,3,3,3,3
2,2,2,2,2,4,4,4,4,4,3,3,3,3,3
2,2,2,2,2,4,4,4,4,4,2,2,2,2,2
2,2,2,2,2,4,4,4,4,4,2,2,2,2,2
2,2,2,2,2,4,4,4,4,4,2,2,2,2,2
2,2,2,2,2,2,2,4,2,2,2,2,2,2,2
2,2,2,2,2,2,2,4,2,2,2,2,2,2,2
2,2,2,2,2,2,2,2,2,2,2,2,2,2,2
2,2,2,2,2,2,2,2,2,2,2,2,2,2,2
2,2,2,2,2,2,2,2,2,2,2,2,2,2,2
2,2,2,2,2,2,2,2,2,2,2,2,2,2,2
2,2,2,2,2,2,2,2,2,2,2,2,2,2,2
2,2,2,2,2,2,2,2,2,2,2,2,2,2,2
2,2,2,2,2,2,2,2,2,2,2,2,2,2,2
endlayer

layer
2,2,2,2,2,2,2,2,2,2,2,2,2,2,2
2,2,2,2,2,2,2,2,2,2,2,2,2,2,2
2,2,2,2,2,2,2,2,2,2,2,3,3,3,3
2,2,2,2,2,2,2,2,2,2,3,3,3,3,3
2,2,2,2,2,4,4,4,4,4,3,3,3,3,3
2,2,2,2,4,5,5,0,5,5,4,3,3,3,3
2,2,2,2,4,0,0,0,0,0,4,2,2,2,2
2,2,2,2,4,6,0,0,0,6,4,2,2,2,2
2,2,2,2,4,7,0,0,0,6,4,2,2,2,2
2,2,2,2,2,4,4,0,4,4,2,2,2,2,2
2,2,2,2,2,2,4,0,4,2,2,2,2,2,2
2,2,2,2,2,2,2,0,2,2,2,2,2,2,2
2,2,2,2,2,2,2,0,2,2,2,2,2,2,2
2,2,2,2,2,2,2,0,2,2,2,2,2,2,2
2,2,2,2,2,2,2,0,2,2,2,2,2,2,2
2,2,2,2,2,2,2,0,2,2,2,2,2,2,2
2,2,2,2,2,2,2,0,0,4,2,2,2,2,2
2,2,2,2,2,2,2,2,2,2,2,2,2,2,2
endlayer

layer
2,2,2,2,2,2,2,2,2,2,2,2,2,2,2
2,2,2,2,2,2,2,2,2,2,2,2,2,2,2
2,2,2,2,2,2,2,2,2,2,2,2,2,2,2
2,2,2,2,2,2,2,2,2,2,2,2,2,2,2
4,4,4,4,4,4,4,4,4,4,2,2,2,2,2
4,4,4,4,4,0,0,0,0,0,4,2,2,2,2
4,4,4,4,4,0,0,0,0,0,4,2,2,2,2
4,2,2,4,4,0,0,0,0,0,4,2,2,2,2
2,2,2,2,4,0,0,0,0,0,4,2,2,2,2
2,2,2,2,2,4,4,8,4,4,2,2,2,2,2
2,2,2,2,2,2,4,0,4,2,2,2,2,2,2
2,2,2,2,2,2,2,0,2,2,2,2,2,2,2
2,2,2,2,2,2,2,0,2,2,2,2,2,2,2
2,2,2,2,2,2,2,0,2,2,2,2,2,2,2
2,2,2,2,2,2,2,0,2,2,2,2,2,2,2
2,2,2,2,2,2,2,0,2,2,2,2,2,2,2
2,2,2,2,2,2,2,0,0,0,4,2,2,4,4
2,2,2,2,2,2,2,2,2,2,2,2,2,4,4
endlayer

layer
2,2,2,2,2,2,2,2,2,2,2,2,2,2,2
2,2,2,2,2,2,2,2,2,2,2,2,2,2,2
2,2,2,2,2,2,2,2,2,2,2,2,2,2,2
2,2,2,2,2,2,2,2,2,2,2,2,2,2,2
4,4,4,4,4,4,4,4,4,4,2,2,2,2,2
4,4,4,4,4,0,0,0,0,0,4,2,2,2,2
4,4,4,4,4,0,0,0,0,0,4,2,2,2,2
4,4,4,4,4,0,0,0,0,0,4,2,2,2,2
2,2,2,2,4,0,0,0,0,0,4,2,2,2,2
2,2,2,2,2,4,4,4,4,4,2,2,2,2,2
2,2,2,2,2,2,4,4,4,2,2,2,2,2,2
2,2,2,2,2,2,4,4,4,2,2,2,2,2,2
2,2,2,2,4,2,2,2,2,2,2,2,2,2,2
2,2,2,2,4,2,2,2,2,2,2,2,2,2,2
2,2,2,4,2,2,2,4,2,2,2,2,2,2,2
2,2,2,2,2,2,2,9,2,2,2,2,2,4,4
2,2,2,2,2,2,2,0,0,0,0,4,2,4,4
2,2,2,2,2,2,2,2,2,2,2,2,2,4,4
endlayer

layer
2,2,2,2,2,2,2,2,2,2,4,4,2,2,2
2,2,2,2,2,2,2,2,2,2,2,2,2,2,2
2,2,2,2,2,2,2,2,2,2,2,2,2,2,2
2,2,2,2,2,2,2,2,2,2,2,2,2,2,2
4,4,4,4,4,4,2,2,2,2,2,2,2,2,2
4,4,4,4,4,4,4,4,4,4,2,2,2,2,2
4,4,4,4,4,4,4,9,4,4,2,2,2,2,2
4,4,4,4,4,4,4,9,4,4,2,2,2,2,2
2,4,4,4,2,4,4,4,4,4,2,2,2,2,2
2,4,4,4,2,4,4,4,4,4,2,2,2,2,2
2,4,4,4,4,4,4,4,4,4,2,2,2,2,2
2,4,4,4,4,4,4,4,4,4,2,2,2,2,2
2,4,4,4,4,4,4,4,4,4,2,2,2,2,2
2,4,4,4,4,2,2,2,2,2,2,2,2,2,2
2,4,4,4,2,2,2,2,2,2,2,2,2,2,2
2,4,4,4,2,2,2,9,2,2,2,2,2,4,4
2,4,4,4,2,2,4,0,0,0,0,0,4,4,4
2,2,2,2,2,2,2,2,2,4,4,4,2,4,4
endlayer

layer
2,2,2,4,2,4,2,4,2,4,4,4,4,4,4
2,2,2,2,2,2,2,2,2,2,2,2,2,2,2
2,2,2,2,2,2,2,2,2,2,2,2,2,2,3
2,2,2,2,2,2,2,2,2,2,2,2,2,2,3
2,2,4,4,4,2,2,2,2,2,2,2,2,2,3
4,4,4,4,4,4,4,2,4,4,4,4,4,2,2
4,4,4,4,4,4,4,2,4,4,4,4,4,4,4
4,4,4,4,4,4,4,4,4,4,4,4,4,4,4
4,4,4,4,4,4,4,11,4,4,4,4,4,4,4
4,4,4,4,4,4,4,11,4,4,4,4,4,4,4
2,4,4,4,4,4,11,11,11,4,4,4,4,4,4
12,11,11,11,11,11,11,9,11,11,11,11,11,11,10
2,4,4,4,4,4,11,11,11,4,4,4,4,4,4
4,4,4,4,4,4,4,11,4,4,4,4,4,4,4
4,4,4,4,4,4,4,11,4,4,4,4,4,4,4
4,4,4,4,4,4,4,11,4,4,4,4,4,4,4
2,4,4,4,4,4,4,11,4,0,0,0,0,4,2
2,4,2,2,2,2,2,2,2,4,4,4,4,2,2
endlayer

layer
2,2,4,4,4,4,4,4,2,4,4,4,4,4,4
2,2,2,2,2,2,2,2,2,2,2,2,2,2,2
2,2,2,2,2,2,2,2,2,2,2,2,2,2,3
2,2,2,2,2,2,2,2,2,2,2,2,2,2,3
2,2,2,2,2,2,2,2,2,2,2,2,2,2,3
2,4,4,4,4,4,4,4,4,4,4,4,4,4,4
4,0,0,0,0,0,4,4,4,0,0,0,0,0,4
0,0,0,0,0,0,0,4,0,0,0,0,0,0,0
0,0,0,0,0,0,0,0,0,0,0,0,0,0,0
0,0,0,0,0,0,0,0,0,0,0,0,0,0,0
4,0,0,0,13,0,0,0,0,0,13,0,0,0,4
0,0,0,0,0,0,0,0,0,0,0,0,0,0,0
4,0,0,0,0,0,0,0,0,0,0,0,0,0,4
0,0,0,0,0,0,0,0,0,0,0,0,0,0,0
0,0,0,0,0,0,0,0,0,0,0,0,0,0,0
0,0,0,0,0,0,0,0,0,0,0,0,0,0,0
4,0,0,0,0,0,0,0,0,0,0,0,0,0,4
4,4,4,4,4,4,4,14,4,4,4,4,4,4,2
endlayer

layer
2,4,4,1,1,1,1,1,1,1,1,1,1,1,1
4,2,2,2,2,2,4,4,2,4,2,2,2,2,2
2,2,2,2,2,2,2,2,2,2,2,2,2,2,2
4,4,4,4,4,4,2,2,2,2,2,2,2,2,2
2,4,4,4,4,4,4,4,4,4,4,4,4,4,2
4,4,0,0,0,0,0,4,0,0,0,0,0,0,4
4,0,0,0,0,0,0,4,0,0,0,0,0,0,4
0,0,0,0,0,0,0,0,0,0,0,0,0,0,0
0,0,0,0,0,0,0,0,0,0,0,0,0,0,0
0,0,0,0,0,0,0,0,0,0,0,0,0,0,0
4,0,0,0,0,0,0,0,0,0,0,0,0,0,4
0,0,0,0,0,0,0,0,0,0,0,0,0,0,0
4,0,0,0,0,0,0,0,0,0,0,0,0,0,4
0,0,0,0,0,0,0,0,0,0,0,0,0,0,0
0,0,0,0,0,0,0,0,0,0,0,0,0,0,0
0,0,0,0,0,0,0,0,0,0,0,0,0,0,0
4,0,0,0,0,0,0,0,0,0,0,0,0,0,4
4,4,15,15,15,12,15,9,15,10,15,15,15,4,2
endlayer

layer
1,1,1,1,1,1,1,1,1,1,1,1,1,1,1
4,4,4,4,4,4,4,4,4,4,4,4,4,4,2
4,4,4,4,4,4,4,4,4,4,4,4,4,4,4
4,4,4,4,4,4,4,4,16,16,16,16,2,2,2
4,4,4,4,4,4,4,4,4,4,4,4,4,4,2
4,4,0,0,0,0,0,4,0,0,0,0,0,0,4
4,0,0,0,0,0,0,0,0,0,0,0,0,0,4
0,0,0,0,0,0,0,0,0,0,0,0,0,0,0
0,0,0,0,0,0,0,0,0,0,0,0,0,0,0
0,0,0,0,0,0,0,0,0,0,0,0,0,0,0
4,0,0,0,0,0,0,0,0,0,0,0,0,0,4
4,0,0,0,0,0,0,0,0,0,0,0,0,0,4
4,0,0,0,0,0,0,0,0,0,0,0,0,0,4
0,0,0,0,0,0,0,0,0,0,0,0,0,0,0
0,0,0,0,0,0,0,0,0,0,0,0,0,0,0
0,0,0,0,0,0,0,0,0,0,0,0,0,0,0
4,0,0,0,0,0,0,0,0,0,0,0,0,0,4
4,4,15,15,15,12,15,9,15,10,15,15,15,4,2
endlayer

layer
1,1,1,1,1,1,1,1,1,1,1,1,1,1,1
4,4,4,4,4,4,4,4,4,4,4,4,4,1,16
4,4,4,4,4,4,4,4,4,4,4,4,4,4,4
4,4,4,4,4,4,4,4,4,4,4,4,4,4,4
4,13,0,0,0,0,0,4,0,0,0,0,0,13,4
4,0,0,0,0,0,0,0,0,0,0,0,0,0,4
4,0,0,0,0,0,0,0,0,0,0,0,0,0,4
4,0,0,0,0,0,0,0,0,0,0,0,0,0,4
4,0,0,0,0,0,0,0,0,0,0,0,0,0,4
4,0,0,0,0,0,0,0,0,0,0,0,0,0,4
4,0,0,0,0,0,0,0,0,0,0,0,0,0,4
4,0,0,0,0,0,0,0,0,0,0,0,0,0,4
4,0,0,0,0,0,0,0,0,0,0,0,0,0,4
4,0,0,0,0,0,0,0,0,0,0,0,0,0,4
4,0,0,0,0,0,0,0,0,0,0,0,0,0,4
4,0,0,0,0,0,0,0,0,0,0,0,0,0,4
4,0,0,0,0,0,0,0,0,0,0,0,0,0,4
4,4,4,4,4,4,4,4,4,4,4,4,4,4,4
endlayer

layer
1,1,1,1,1,1,1,4,1,1,1,1,1,1,1
4,4,16,16,16,16,16,4,16,16,16,16,16,1,1
4,4,4,4,4,4,4,4,4,4,4,4,4,4,4
4,4,4,4,4,4,4,4,4,4,4,4,4,4,4
4,4,4,4,4,4,4,0,4,4,4,4,4,4,4
4,4,4,4,4,4,4,0,4,4,4,4,4,4,4
4,4,4,4,4,4,4,0,4,4,4,4,4,4,4
4,4,4,4,4,4,4,17,4,4,4,4,4,4,4
4,4,4,4,4,4,4,17,4,4,4,4,4,4,4
4,4,4,4,4,4,17,17,17,4,4,4,4,4,4
4,4,4,4,17,17,17,9,17,17,17,4,4,4,4
4,4,4,4,4,4,17,17,17,4,4,4,4,4,4
4,4,4,4,4,4,4,17,4,4,4,4,4,4,4
4,4,4,4,4,4,4,17,4,4,4,4,4,4,4
4,4,4,4,4,4,4,17,4,4,4,4,4,4,4
4,4,4,4,4,4,4,4,4,4,4,4,4,4,4
4,4,4,4,4,4,4,4,4,4,4,4,4,4,4
4,4,4,4,4,4,4,4,4,4,4,4,4,4,4
endlayer

layer
1,1,1,1,1,1,4,0,4,1,1,4,4,1,1
4,1,1,1,1,1,4,0,4,1,1,1,1,4,1
4,4,4,4,4,4,4,0,4,4,4,4,4,4,4
9,0,0,0,0,0,0,0,0,0,0,0,0,0,9
4,0,0,0,0,0,0,0,0,0,0,0,0,0,4
4,0,0,0,0,0,0,0,0,0,0,0,0,0,4
4,0,0,0,0,0,0,0,0,0,0,0,0,0,4
4,0,0,0,0,0,0,0,0,0,0,0,0,0,4
4,0,0,0,0,0,0,0,0,0,0,0,0,0,4
4,0,0,0,0,0,0,0,0,0,0,0,0,0,4
4,0,0,0,0,0,0,0,0,0,0,0,0,0,4
4,0,0,0,0,0,0,0,0,0,0,0,0,0,4
4,0,0,0,0,0,0,0,0,0,0,0,0,0,4
4,0,0,0,0,0,0,0,0,0,0,0,0,0,4
4,0,0,0,0,0,0,0,0,0,0,0,0,0,4
4,0,0,0,0,0,0,0,0,0,0,0,0,0,4
4,0,0,0,0,0,0,0,0,0,0,0,0,0,4
9,4,4,4,4,4,4,4,4,4,4,4,4,4,9
endlayer

layer
0,0,0,0,0,0,4,0,4,0,0,0,0,0,0
0,0,0,0,0,0,4,0,4,0,0,0,0,0,0
0,0,0,0,0,4,4,0,4,4,0,0,0,0,0
4,4,4,4,4,4,0,0,0,4,4,4,4,4,4
4,0,0,0,0,0,0,0,0,0,0,0,0,0,4
4,0,0,0,0,0,0,0,0,0,0,0,0,0,4
4,0,0,0,0,0,0,0,0,0,0,0,0,0,4
4,0,0,0,0,0,0,0,0,0,0,0,0,0,4
4,0,0,0,0,0,0,0,0,0,0,0,0,0,4
4,0,0,0,0,0,0,0,0,0,0,0,0,0,4
4,0,0,0,0,0,0,0,0,0,0,0,0,0,4
4,0,0,0,0,0,0,0,0,0,0,0,0,0,4
4,0,0,0,0,0,0,0,0,0,0,0,0,0,4
4,0,0,0,0,0,0,0,0,0,0,0,0,0,4
4,0,0,0,0,0,0,0,0,0,0,0,0,0,4
4,0,0,0,0,0,0,0,0,0,0,0,0,0,4
4,0,0,0,0,0,0,0,0,0,0,0,0,0,4
4,4,4,4,4,4,4,4,4,4,4,4,4,4,4
endlayer

layer
0,0,0,0,0,0,0,0,0,0,0,0,0,0,0
0,0,0,0,0,0,4,0,4,0,0,0,0,0,0
0,0,0,0,0,0,4,4,4,0,0,0,0,0,0
0,0,0,0,0,0,4,4,4,0,0,0,0,0,0
0,4,4,4,4,4,4,4,4,4,4,4,4,4,0
0,4,0,0,0,0,0,0,0,0,0,0,0,4,0
0,4,0,0,0,0,0,0,0,0,0,0,0,4,0
0,4,0,0,0,0,0,0,0,0,0,0,0,4,0
0,4,0,0,0,0,0,0,0,0,0,0,0,4,0
0,4,0,0,0,0,0,0,0,0,0,0,0,4,0
0,4,0,0,0,0,0,0,0,0,0,0,0,4,0
0,4,0,0,0,0,0,0,0,0,0,0,0,4,0
0,4,0,0,0,0,0,0,0,0,0,0,0,4,0
0,4,0,0,0,0,0,0,0,0,0,0,0,4,0
0,4,0,0,0,0,0,0,0,0,0,0,0,4,0
0,4,0,0,0,0,0,0,0,0,0,0,0,4,0
0,4,4,4,4,4,4,4,4,4,4,4,4,4,0
0,0,0,0,0,0,0,0,0,0,0,0,0,0,0
endlayer

layer
0,0,0,0,0,0,0,0,0,0,0,0,0,0,0
0,0,0,0,0,0,0,0,0,0,0,0,0,0,0
0,0,0,0,0,0,0,0,0,0,0,0,0,0,0
0,0,0,0,0,0,4,0,4,0,0,0,0,0,0
0,0,0,0,0,0,4,4,4,0,0,0,0,0,0
0,0,4,4,4,4,4,4,4,4,4,4,4,0,0
0,0,4,0,0,0,0,0,0,0,0,0,4,0,0
0,0,4,0,0,0,0,0,0,0,0,0,4,0,0
0,0,4,0,0,0,0,0,0,0,0,0,4,0,0
0,0,4,0,0,0,0,0,0,0,0,0,4,0,0
0,0,4,0,0,0,0,0,0,0,0,0,4,0,0
0,0,4,0,0,0,0,0,0,0,0,0,4,0,0
0,0,4,0,0,0,0,0,0,0,0,0,4,0,0
0,0,4,0,0,0,0,0,0,0,0,0,4,0,0
0,0,4,0,0,0,0,0,0,0,0,0,4,0,0
0,0,4,4,4,4,4,4,4,4,4,4,4,0,0
0,0,0,0,0,0,0,0,0,0,0,0,0,0,0
0,0,0,0,0,0,0,0,0,0,0,0,0,0,0
endlayer

layer
0,0,0,0,0,0,0,0,0,0,0,0,0,0,0
0,0,0,0,0,0,0,0,0,0,0,0,0,0,0
0,0,0,0,0,0,0,0,0,0,0,0,0,0,0
0,0,0,0,0,0,0,0,0,0,0,0,0,0,0
0,0,0,0,0,0,4,0,4,0,0,0,0,0,0
0,0,0,0,0,0,4,0,4,0,0,0,0,0,0
0,0,0,4,4,4,4,4,4,4,4,4,0,0,0
0,0,0,4,0,0,0,0,0,0,0,4,0,0,0
0,0,0,4,0,0,0,0,0,0,0,4,0,0,0
0,0,0,4,0,0,0,0,0,0,0,4,0,0,0
0,0,0,4,9,0,0,0,0,0,9,4,0,0,0
0,0,0,4,0,0,0,0,0,0,0,4,0,0,0
0,0,0,4,0,0,0,0,0,0,0,4,0,0,0
0,0,0,4,0,0,0,0,0,0,0,4,0,0,0
0,0,0,4,4,4,4,4,4,4,4,4,0,0,0
0,0,0,0,0,0,0,0,0,0,0,0,0,0,0
0,0,0,0,0,0,0,0,0,0,0,0,0,0,0
0,0,0,0,0,0,0,0,0,0,0,0,0,0,0
endlayer

layer
0,0,0,0,0,0,0,0,0,0,0,0,0,0,0
0,0,0,0,0,0,0,0,0,0,0,0,0,0,0
0,0,0,0,0,0,0,0,0,0,0,0,0,0,0
0,0,0,0,0,0,0,0,0,0,0,0,0,0,0
0,0,0,0,0,0,0,0,0,0,0,0,0,0,0
0,0,0,0,0,0,4,0,4,0,0,0,0,0,0
0,0,0,0,0,0,4,0,4,0,0,0,0,0,0
0,0,0,0,4,4,4,4,4,4,4,0,0,0,0
0,0,0,0,4,0,0,9,0,0,4,0,0,0,0
0,0,0,0,4,0,0,4,0,0,4,0,0,0,0
0,0,0,0,4,0,4,0,4,0,4,0,0,0,0
0,0,0,0,4,4,4,4,4,4,4,0,0,0,0
0,0,0,0,4,4,9,9,9,4,4,0,0,0,0
0,0,0,0,4,4,4,4,4,4,4,0,0,0,0
0,0,0,0,0,0,0,0,0,0,0,0,0,0,0
0,0,0,0,0,0,0,0,0,0,0,0,0,0,0
0,0,0,0,0,0,0,0,0,0,0,0,0,0,0
0,0,0,0,0,0,0,0,0,0,0,0,0,0,0
endlayer

layer
0,0,0,0,0,0,0,0,0,0,0,0,0,0,0
0,0,0,0,0,0,0,0,0,0,0,0,0,0,0
0,0,0,0,0,0,0,0,0,0,0,0,0,0,0
0,0,0,0,0,0,0,0,0,0,0,0,0,0,0
0,0,0,0,0,0,0,0,0,0,0,0,0,0,0
0,0,0,0,0,0,0,0,0,0,0,0,0,0,0
0,0,0,0,0,0,0,0,0,0,0,0,0,0,0
0,0,0,0,0,0,4,0,4,0,0,0,0,0,0
0,0,0,0,0,4,4,4,4,4,0,0,0,0,0
0,0,0,0,0,4,4,4,4,4,0,0,0,0,0
0,0,0,0,0,4,4,0,4,4,0,0,0,0,0
0,0,0,0,0,4,4,4,4,4,0,0,0,0,0
0,0,0,0,0,4,4,4,4,4,0,0,0,0,0
0,0,0,0,0,0,0,0,0,0,0,0,0,0,0
0,0,0,0,0,0,0,0,0,0,0,0,0,0,0
0,0,0,0,0,0,0,0,0,0,0,0,0,0,0
0,0,0,0,0,0,0,0,0,0,0,0,0,0,0
0,0,0,0,0,0,0,0,0,0,0,0,0,0,0
endlayer

layer
0,0,0,0,0,0,0,0,0,0,0,0,0,0,0
0,0,0,0,0,0,0,0,0,0,0,0,0,0,0
0,0,0,0,0,0,0,0,0,0,0,0,0,0,0
0,0,0,0,0,0,0,0,0,0,0,0,0,0,0
0,0,0,0,0,0,0,0,0,0,0,0,0,0,0
0,0,0,0,0,0,0,0,0,0,0,0,0,0,0
0,0,0,0,0,0,0,0,0,0,0,0,0,0,0
0,0,0,0,0,0,0,0,0,0,0,0,0,0,0
0,0,0,0,0,0,0,0,0,0,0,0,0,0,0
0,0,0,0,0,0,4,0,4,0,0,0,0,0,0
0,0,0,0,0,0,0,0,0,0,0,0,0,0,0
0,0,0,0,0,0,4,0,4,0,0,0,0,0,0
0,0,0,0,0,0,0,0,0,0,0,0,0,0,0
0,0,0,0,0,0,0,0,0,0,0,0,0,0,0
0,0,0,0,0,0,0,0,0,0,0,0,0,0,0
0,0,0,0,0,0,0,0,0,0,0,0,0,0,0
0,0,0,0,0,0,0,0,0,0,0,0,0,0,0
0,0,0,0,0,0,0,0,0,0,0,0,0,0,0
endlayer

layer
0,0,0,0,0,0,0,0,0,0,0,0,0,0,0
0,0,0,0,0,0,0,0,0,0,0,0,0,0,0
0,0,0,0,0,0,0,0,0,0,0,0,0,0,0
0,0,0,0,0,0,0,0,0,0,0,0,0,0,0
0,0,0,0,0,0,0,0,0,0,0,0,0,0,0
0,0,0,0,0,0,0,0,0,0,0,0,0,0,0
0,0,0,0,0,0,0,0,0,0,0,0,0,0,0
0,0,0,0,0,0,0,0,0,0,0,0,0,0,0
0,0,0,0,0,0,0,0,0,0,0,0,0,0,0
0,0,0,0,0,0,4,0,4,0,0,0,0,0,0
0,0,0,0,0,0,0,0,0,0,0,0,0,0,0
0,0,0,0,0,0,4,0,4,0,0,0,0,0,0
0,0,0,0,0,0,0,0,0,0,0,0,0,0,0
0,0,0,0,0,0,0,0,0,0,0,0,0,0,0
0,0,0,0,0,0,0,0,0,0,0,0,0,0,0
0,0,0,0,0,0,0,0,0,0,0,0,0,0,0
0,0,0,0,0,0,0,0,0,0,0,0,0,0,0
0,0,0,0,0,0,0,0,0,0,0,0,0,0,0
endlayer

layer
0,0,0,0,0,0,0,0,0,0,0,0,0,0,0
0,0,0,0,0,0,0,0,0,0,0,0,0,0,0
0,0,0,0,0,0,0,0,0,0,0,0,0,0,0
0,0,0,0,0,0,0,0,0,0,0,0,0,0,0
0,0,0,0,0,0,0,0,0,0,0,0,0,0,0
0,0,0,0,0,0,0,0,0,0,0,0,0,0,0
0,0,0,0,0,0,0,0,0,0,0,0,0,0,0
0,0,0,0,0,0,0,0,0,0,0,0,0,0,0
0,0,0,0,0,4,4,4,4,4,0,0,0,0,0
0,0,0,0,0,4,4,4,4,4,0,0,0,0,0
0,0,0,0,0,4,4,4,4,4,0,0,0,0,0
0,0,0,0,0,4,4,4,4,4,0,0,0,0,0
0,0,0,0,0,4,4,4,4,4,0,0,0,0,0
0,0,0,0,0,0,0,0,0,0,0,0,0,0,0
0,0,0,0,0,0,0,0,0,0,0,0,0,0,0
0,0,0,0,0,0,0,0,0,0,0,0,0,0,0
0,0,0,0,0,0,0,0,0,0,0,0,0,0,0
0,0,0,0,0,0,0,0,0,0,0,0,0,0,0
endlayer

layer
0,0,0,0,0,0,0,0,0,0,0,0,0,0,0
0,0,0,0,0,0,0,0,0,0,0,0,0,0,0
0,0,0,0,0,0,0,0,0,0,0,0,0,0,0
0,0,0,0,0,0,0,0,0,0,0,0,0,0,0
0,0,0,0,0,0,0,0,0,0,0,0,0,0,0
0,0,0,0,0,0,0,0,0,0,0,0,0,0,0
0,0,0,0,0,0,0,0,0,0,0,0,0,0,0
0,0,0,0,0,0,0,0,0,0,0,0,0,0,0
0,0,0,0,0,0,0,0,0,0,0,0,0,0,0
0,0,0,0,0,0,4,4,4,0,0,0,0,0,0
0,0,0,0,0,0,4,4,4,0,0,0,0,0,0
0,0,0,0,0,0,4,4,4,0,0,0,0,0,0
0,0,0,0,0,0,0,0,0,0,0,0,0,0,0
0,0,0,0,0,0,0,0,0,0,0,0,0,0,0
0,0,0,0,0,0,0,0,0,0,0,0,0,0,0
0,0,0,0,0,0,0,0,0,0,0,0,0,0,0
0,0,0,0,0,0,0,0,0,0,0,0,0,0,0
0,0,0,0,0,0,0,0,0,0,0,0,0,0,0
endlayer

layer
0,0,0,0,0,0,0,0,0,0,0,0,0,0,0
0,0,0,0,0,0,0,0,0,0,0,0,0,0,0
0,0,0,0,0,0,0,0,0,0,0,0,0,0,0
0,0,0,0,0,0,0,0,0,0,0,0,0,0,0
0,0,0,0,0,0,0,0,0,0,0,0,0,0,0
0,0,0,0,0,0,0,0,0,0,0,0,0,0,0
0,0,0,0,0,0,0,0,0,0,0,0,0,0,0
0,0,0,0,0,0,0,0,0,0,0,0,0,0,0
0,0,0,0,0,0,0,0,0,0,0,0,0,0,0
0,0,0,0,0,0,0,0,0,0,0,0,0,0,0
0,0,0,0,0,0,0,4,0,0,0,0,0,0,0
0,0,0,0,0,0,0,0,0,0,0,0,0,0,0
0,0,0,0,0,0,0,0,0,0,0,0,0,0,0
0,0,0,0,0,0,0,0,0,0,0,0,0,0,0
0,0,0,0,0,0,0,0,0,0,0,0,0,0,0
0,0,0,0,0,0,0,0,0,0,0,0,0,0,0
0,0,0,0,0,0,0,0,0,0,0,0,0,0,0
0,0,0,0,0,0,0,0,0,0,0,0,0,0,0
endlayer

