# Converted from schematic
# THIS TEMPLATE USES DEFAULTS!  Please edit for corrections.
# If you need help, consult template_rules.txt

weight=3
embed_into_distance=1
acceptable_target_blocks=1,2,3,12,13
dimensions=6,11,9
allowable_overhang=0
max_cut_in=2
cut_in_buffer=1
max_leveling=2
leveling_buffer=1
preserve_water=0
preserve_lava=0
preserve_plants=0


rule1=0,100,24
rule2=0,100,128-2
rule3=0,100,128-1
rule4=0,100,128
rule5=0,100,54-3
rule6=0,100,44-1
rule7=0,100,24-1
rule8=0,100,64
rule9=0,100,5
rule10=0,100,128-3
rule11=0,100,20
rule12=0,100,24-2
rule13=0,100,64-8
rule14=0,100,47
rule15=0,100,50-1
rule16=0,100,50-2


layer
1,1,1,1,1,1,1,1,1
1,1,1,1,1,1,1,1,1
1,1,1,1,1,1,1,1,1
1,1,1,1,1,1,1,1,1
1,1,1,1,1,1,1,1,1
1,1,1,1,1,1,1,1,1
1,1,1,1,1,1,1,1,1
1,1,1,1,1,1,1,1,1
1,1,1,1,1,1,1,1,1
1,1,1,1,1,1,1,1,1
1,1,1,1,1,1,1,1,1
endlayer

layer
0,0,0,0,0,0,0,0,0
0,10,4,6,0,6,4,2,0
0,10,1,1,1,1,1,2,0
0,1,0,0,0,0,0,1,0
0,1,0,0,0,0,0,1,0
0,1,0,0,0,0,0,1,0
0,1,0,0,0,0,5,1,0
0,1,9,0,0,0,5,1,0
0,10,1,0,0,0,1,2,0
0,3,3,7,8,7,3,3,0
0,0,0,0,0,0,0,0,0
endlayer

layer
0,0,0,0,0,0,0,0,0
0,0,0,0,0,0,0,0,0
0,0,12,11,11,11,12,0,0
0,1,0,0,0,0,0,1,0
0,11,0,0,0,0,0,11,0
0,11,0,0,0,0,0,11,0
0,11,0,0,0,0,0,11,0
0,1,14,0,0,0,0,1,0
0,0,12,0,0,0,12,0,0
0,0,0,7,13,7,0,0,0
0,0,0,0,0,0,0,0,0
endlayer

layer
0,0,0,0,0,0,0,0,0
0,0,0,0,0,0,0,0,0
0,0,12,11,11,11,12,0,0
0,1,15,0,0,0,15,1,0
0,11,0,0,0,0,0,11,0
0,11,0,0,0,0,0,11,0
0,11,0,0,0,0,0,11,0
0,1,16,0,0,0,16,1,0
0,0,12,0,0,0,12,0,0
0,0,0,7,7,7,0,0,0
0,0,0,0,0,0,0,0,0
endlayer

layer
0,0,0,0,0,0,0,0,0
0,4,4,4,4,4,4,2,0
0,10,1,1,1,1,1,2,0
0,1,1,0,0,0,1,2,0
0,1,1,0,0,0,1,2,0
0,1,1,0,0,0,1,2,0
0,1,1,0,0,0,1,2,0
0,1,1,0,0,0,1,2,0
0,10,1,1,1,1,1,2,0
0,3,3,3,3,3,3,3,0
0,0,0,0,0,0,0,0,0
endlayer

layer
0,0,0,0,0,0,0,0,0
0,0,0,0,0,0,0,0,0
0,0,4,4,4,4,2,0,0
0,0,10,11,11,11,2,0,0
0,0,10,11,11,11,2,0,0
0,0,10,1,1,1,2,0,0
0,0,10,11,11,11,2,0,0
0,0,10,11,11,11,2,0,0
0,0,3,3,3,3,2,0,0
0,0,0,0,0,0,0,0,0
0,0,0,0,0,0,0,0,0
endlayer

