# Converted from schematic
# THIS TEMPLATE USES DEFAULTS!  Please edit for corrections.
# If you need help, consult template_rules.txt

weight=1
embed_into_distance=1
acceptable_target_blocks=1,2,3,12,13
dimensions=8,13,13
allowable_overhang=0
max_cut_in=2
cut_in_buffer=1
max_leveling=2
leveling_buffer=1
preserve_water=0
preserve_lava=0
preserve_plants=0


rule1=0,100,24
rule2=0,100,24-2
rule3=0,100,159-1
rule4=0,100,87
rule5=0,100,128
rule6=0,100,128-2
rule7=0,100,128-1
rule8=0,100,24-1
rule9=0,100,51-15
rule10=0,100,128-3
rule11=0,100,128-6
rule12=0,100,128-4
rule13=0,100,50-5
rule14=0,100,128-5
rule15=0,100,128-7
rule16=0,100,22
rule17=0,100,89


layer
1,1,1,1,1,1,1,1,1,1,1,1,1
1,1,1,1,1,1,1,1,1,1,1,1,1
1,1,1,1,1,1,1,1,1,1,1,1,1
1,1,1,1,1,2,2,2,2,1,1,1,1
1,1,1,1,1,1,1,1,2,1,1,1,1
1,1,1,1,1,1,3,1,2,1,1,1,1
1,1,1,1,1,3,4,3,2,1,1,1,1
1,1,1,1,1,1,3,1,2,1,1,1,1
1,1,1,1,1,2,2,2,2,1,1,1,1
1,1,1,1,1,1,1,1,1,1,1,1,1
1,1,1,1,1,1,1,1,1,1,1,1,1
1,1,1,1,1,1,1,1,1,1,1,1,1
1,1,1,1,1,1,1,1,1,1,1,1,1
endlayer

layer
0,0,0,0,0,0,0,0,0,0,0,0,0
0,10,5,5,5,2,0,2,5,5,5,5,0
0,10,2,1,1,2,0,2,1,1,2,6,0
0,10,1,0,0,0,0,0,0,0,1,6,0
0,10,1,0,0,0,0,0,0,0,1,6,0
0,2,2,0,0,0,0,0,0,0,2,2,0
0,0,0,0,0,0,9,0,0,0,0,0,0
0,2,2,0,0,0,0,0,0,0,2,2,0
0,10,1,0,0,0,0,0,0,0,1,6,0
0,10,1,0,0,0,0,0,0,0,1,6,0
0,10,2,1,1,8,0,8,1,1,2,6,0
0,10,7,7,7,8,0,8,7,7,7,7,0
0,0,0,0,0,0,0,0,0,0,0,0,0
endlayer

layer
0,0,0,0,0,0,0,0,0,0,0,0,0
0,15,12,12,12,2,0,2,12,12,12,11,0
0,15,2,0,13,2,0,2,13,0,2,11,0
0,15,0,0,0,0,0,0,0,0,0,11,0
0,15,13,0,0,0,0,0,0,0,13,11,0
0,2,2,0,0,0,0,0,0,0,2,2,0
0,0,0,0,0,0,0,0,0,0,0,0,0
0,2,2,0,0,0,0,0,0,0,2,2,0
0,15,13,0,0,0,0,0,0,0,13,11,0
0,15,0,0,0,0,0,0,0,0,0,11,0
0,15,2,0,13,8,0,8,13,0,2,11,0
0,15,14,14,14,8,0,8,14,14,14,11,0
0,0,0,0,0,0,0,0,0,0,0,0,0
endlayer

layer
0,0,0,0,0,0,0,0,0,0,0,0,0
0,2,2,2,2,2,2,2,2,2,2,2,0
0,2,2,2,2,2,8,2,2,2,2,2,0
0,2,2,0,0,0,0,0,0,0,2,2,0
0,2,2,0,0,0,0,0,0,0,2,2,0
0,2,2,0,0,0,0,0,0,0,2,2,0
0,2,8,0,0,0,0,0,0,0,8,2,0
0,2,2,0,0,0,0,0,0,0,2,2,0
0,2,2,0,0,0,0,0,0,0,2,2,0
0,2,2,0,0,0,0,0,0,0,2,2,0
0,2,2,2,2,8,8,8,2,2,2,2,0
0,2,2,2,2,8,0,8,2,2,2,2,0
0,0,0,0,0,0,0,0,0,0,0,0,0
endlayer

layer
0,0,0,0,0,0,0,0,0,0,0,0,0
0,0,0,0,0,0,8,0,0,0,0,0,0
0,0,2,2,2,2,2,2,2,2,2,0,0
0,0,2,1,1,1,1,1,1,1,2,0,0
0,0,2,1,1,2,2,2,1,1,2,0,0
0,0,2,1,1,3,1,3,1,1,2,0,0
0,8,2,1,1,2,16,2,1,1,2,8,0
0,0,2,1,1,3,2,3,1,1,2,0,0
0,0,2,1,1,1,1,1,1,1,2,0,0
0,0,2,1,1,1,1,1,1,1,2,0,0
0,0,2,2,2,2,2,2,2,2,2,0,0
0,0,0,0,0,8,8,8,0,0,0,0,0
0,0,0,0,0,0,0,0,0,0,0,0,0
endlayer

layer
0,0,0,0,0,0,0,0,0,0,0,0,0
0,0,0,0,0,0,0,0,0,0,0,0,0
0,0,0,0,0,0,0,0,0,0,0,0,0
0,0,0,2,2,2,2,2,2,2,0,0,0
0,0,0,2,1,1,1,1,1,2,0,0,0
0,0,0,2,1,1,1,1,1,2,0,0,0
0,0,0,2,1,1,1,1,1,2,0,0,0
0,0,0,2,1,1,1,1,1,2,0,0,0
0,0,0,2,1,1,1,1,1,2,0,0,0
0,0,0,2,2,2,2,2,2,2,0,0,0
0,0,0,0,0,0,0,0,0,0,0,0,0
0,0,0,0,0,0,0,0,0,0,0,0,0
0,0,0,0,0,0,0,0,0,0,0,0,0
endlayer

layer
0,0,0,0,0,0,0,0,0,0,0,0,0
0,0,0,0,0,0,0,0,0,0,0,0,0
0,0,0,0,0,0,0,0,0,0,0,0,0
0,0,0,0,0,0,0,0,0,0,0,0,0
0,0,0,0,2,2,2,2,2,0,0,0,0
0,0,0,0,2,1,1,1,2,0,0,0,0
0,0,0,0,2,1,1,1,2,0,0,0,0
0,0,0,0,2,1,1,1,2,0,0,0,0
0,0,0,0,2,2,2,2,2,0,0,0,0
0,0,0,0,0,0,0,0,0,0,0,0,0
0,0,0,0,0,0,0,0,0,0,0,0,0
0,0,0,0,0,0,0,0,0,0,0,0,0
0,0,0,0,0,0,0,0,0,0,0,0,0
endlayer

layer
0,0,0,0,0,0,0,0,0,0,0,0,0
0,0,0,0,0,0,0,0,0,0,0,0,0
0,0,0,0,0,0,0,0,0,0,0,0,0
0,0,0,0,0,0,0,0,0,0,0,0,0
0,0,0,0,0,0,0,0,0,0,0,0,0
0,0,0,0,0,2,2,2,0,0,0,0,0
0,0,0,0,0,2,17,2,0,0,0,0,0
0,0,0,0,0,2,2,2,0,0,0,0,0
0,0,0,0,0,0,0,0,0,0,0,0,0
0,0,0,0,0,0,0,0,0,0,0,0,0
0,0,0,0,0,0,0,0,0,0,0,0,0
0,0,0,0,0,0,0,0,0,0,0,0,0
0,0,0,0,0,0,0,0,0,0,0,0,0
endlayer

