# Converted from schematic
# THIS TEMPLATE USES DEFAULTS!  Please edit for corrections.
# If you need help, consult template_rules.txt

weight=2
embed_into_distance=4
acceptable_target_blocks=1,2,3,12,13,24,78
dimensions=43,8,8
allowable_overhang=32
max_cut_in=0
cut_in_buffer=0
max_leveling=4
leveling_buffer=0
preserve_water=0
preserve_lava=0
preserve_plants=0


rule1=0,100,24
rule2=0,100,172
rule3=0,100,44-1
rule4=0,100,24-2
rule5=0,100,65-5
rule6=0,100,65-4
rule7=0,100,44-9


layer
1,1,1,1,1,1,1,1
1,1,1,1,1,1,1,1
1,1,1,1,1,1,1,1
1,1,1,1,1,1,1,1
1,1,1,1,1,1,1,1
1,1,1,1,1,1,1,1
1,1,1,1,1,1,1,1
1,1,1,1,1,1,1,1
endlayer

layer
1,1,2,2,2,2,1,1
1,1,1,1,1,1,1,1
2,1,1,1,1,1,1,2
2,1,1,1,1,1,1,2
2,1,1,1,1,1,1,2
2,1,1,1,1,1,1,2
1,1,1,1,1,1,1,1
1,1,2,2,2,2,1,1
endlayer

layer
1,1,2,2,2,2,1,1
1,1,1,1,1,1,1,1
2,1,1,1,1,1,1,2
2,1,1,1,1,1,1,2
2,1,1,1,1,1,1,2
2,1,1,1,1,1,1,2
1,1,1,1,1,1,1,1
1,1,2,2,2,2,1,1
endlayer

layer
1,1,2,2,2,2,1,1
1,1,1,1,1,1,1,1
2,1,1,1,1,1,1,2
2,1,1,1,1,1,1,2
2,1,1,1,1,1,1,2
2,1,1,1,1,1,1,2
1,1,1,1,1,1,1,1
1,1,2,2,2,2,1,1
endlayer

layer
0,1,2,0,0,2,1,0
1,1,1,0,0,1,1,1
2,3,0,0,0,0,0,2
2,0,0,0,0,0,0,2
2,0,0,0,0,0,0,2
2,0,0,0,0,0,3,2
1,1,1,0,0,1,1,1
0,1,2,0,0,2,1,0
endlayer

layer
0,0,2,0,0,2,0,0
0,1,1,0,0,1,1,0
2,0,0,0,0,0,0,2
2,3,0,0,0,0,0,2
2,0,0,0,0,0,3,2
2,0,0,0,0,0,0,2
0,1,1,0,0,1,1,0
0,0,2,0,0,2,0,0
endlayer

layer
0,0,2,0,0,2,0,0
0,1,1,0,0,1,1,0
2,0,0,0,0,0,0,2
2,0,0,0,0,0,3,2
2,3,0,0,0,0,0,2
2,0,0,0,0,0,0,2
0,1,1,0,0,1,1,0
0,0,2,0,0,2,0,0
endlayer

layer
0,0,2,0,0,2,0,0
0,1,1,0,0,1,1,0
2,0,0,0,0,0,3,2
2,0,0,0,0,0,0,2
2,0,0,0,0,0,0,2
2,3,0,0,0,0,0,2
0,1,1,1,1,1,1,0
0,0,2,2,2,2,0,0
endlayer

layer
0,0,2,2,2,2,0,0
0,1,1,1,1,1,1,0
2,0,0,0,0,3,0,2
2,0,0,0,0,0,0,2
2,0,0,0,0,0,0,2
2,0,3,0,0,0,0,2
0,1,1,1,1,1,1,0
0,0,2,2,2,2,0,0
endlayer

layer
0,0,2,2,2,0,0,0
0,1,1,1,1,1,1,0
0,1,0,0,3,0,0,2
2,0,0,0,0,0,0,2
2,0,0,0,0,0,0,2
2,0,0,3,0,0,1,0
0,1,1,1,1,1,1,0
0,0,0,2,2,2,0,0
endlayer

layer
0,0,2,2,0,0,0,0
0,1,1,1,1,1,1,0
0,1,0,3,0,0,0,2
0,1,0,0,0,0,0,2
2,0,0,0,0,0,1,0
2,0,0,0,3,0,1,0
0,1,1,1,1,1,1,0
0,0,0,0,2,2,0,0
endlayer

layer
0,0,2,2,0,0,0,0
0,1,1,1,1,1,1,0
0,1,3,0,0,0,0,2
0,1,0,0,0,0,1,2
2,1,0,0,0,0,1,0
2,0,0,0,0,3,1,0
0,1,1,1,1,1,1,0
0,0,0,0,2,2,0,0
endlayer

layer
0,0,2,0,0,0,0,0
0,1,1,1,1,1,1,0
0,1,0,0,0,0,1,2
0,1,3,0,0,0,1,0
0,1,0,0,0,3,1,0
2,1,0,0,0,0,1,0
0,1,1,1,1,1,1,0
0,0,0,0,0,2,0,0
endlayer

layer
0,0,2,0,0,0,0,0
0,1,1,1,1,1,1,0
0,1,0,0,0,0,1,2
0,1,0,0,0,3,1,0
0,1,3,0,0,0,1,0
2,1,0,0,0,0,1,0
0,1,1,1,1,1,1,0
0,0,0,0,0,2,0,0
endlayer

layer
0,0,0,0,0,0,0,0
0,1,1,1,1,1,1,0
0,4,0,0,0,3,4,0
0,4,0,0,0,0,4,0
0,4,0,0,0,0,4,0
0,4,3,0,0,0,4,0
0,1,1,1,1,1,1,0
0,0,0,0,0,0,0,0
endlayer

layer
0,0,0,0,0,0,0,0
0,1,1,1,1,1,1,0
0,4,0,0,3,0,4,0
0,0,0,0,0,0,0,0
0,0,0,0,0,0,0,0
0,4,0,3,0,0,4,0
0,1,1,1,1,1,1,0
0,0,0,0,0,0,0,0
endlayer

layer
0,0,0,0,0,0,0,0
0,1,1,1,1,1,1,0
0,4,0,3,0,0,4,0
0,0,0,0,0,0,0,0
0,0,0,0,0,0,0,0
0,4,0,0,3,0,4,0
0,1,1,1,1,1,1,0
0,0,0,0,0,0,0,0
endlayer

layer
0,0,0,0,0,0,0,0
0,1,1,1,1,1,1,0
0,4,3,0,0,0,4,0
0,0,0,0,0,0,0,0
0,0,0,0,0,0,0,0
0,4,0,0,0,3,4,0
0,1,1,1,1,1,1,0
0,0,0,0,0,0,0,0
endlayer

layer
0,0,0,0,0,0,0,0
0,1,1,1,1,1,1,0
0,4,0,0,0,0,4,0
0,4,3,0,0,0,4,0
0,4,0,0,0,3,4,0
0,4,0,0,0,0,4,0
0,1,1,1,1,1,1,0
0,0,0,0,0,0,0,0
endlayer

layer
0,0,0,0,0,0,0,0
0,1,1,1,1,1,1,0
0,1,0,0,3,3,4,0
0,1,0,0,0,3,4,0
0,4,3,0,0,0,1,0
0,4,3,3,0,0,1,0
0,1,1,1,1,1,1,0
0,0,0,0,0,0,0,0
endlayer

layer
0,0,0,0,0,0,0,0
0,0,1,1,1,1,1,0
0,1,0,0,0,5,4,0
0,1,0,0,0,0,1,0
0,1,0,0,0,0,1,0
0,4,6,0,0,0,1,0
0,1,1,1,1,1,0,0
0,0,0,0,0,0,0,0
endlayer

layer
0,0,0,0,0,0,0,0
0,0,1,1,1,1,1,0
0,1,0,0,0,5,1,0
0,1,0,0,0,0,1,0
0,1,0,0,0,0,1,0
0,1,6,0,0,0,1,0
0,1,1,1,1,1,0,0
0,0,0,0,0,0,0,0
endlayer

layer
0,0,0,7,7,0,0,0
0,0,1,1,1,1,1,0
0,1,1,1,1,5,1,0
0,1,1,1,1,1,1,0
0,1,1,1,1,1,1,0
0,1,6,1,1,1,1,0
0,1,1,1,1,1,0,0
0,0,0,7,7,0,0,0
endlayer

layer
0,0,0,0,0,0,0,0
0,0,1,0,0,1,0,0
0,1,0,0,0,0,1,0
0,1,0,0,0,0,1,0
0,1,0,0,0,0,1,0
0,1,0,0,0,0,1,0
0,0,1,0,0,1,0,0
0,0,0,0,0,0,0,0
endlayer

layer
0,0,0,0,0,0,0,0
0,0,1,0,0,1,0,0
0,1,0,0,0,0,1,0
0,1,0,0,0,0,1,0
0,1,0,0,0,0,1,0
0,1,0,0,0,0,1,0
0,0,1,0,0,1,0,0
0,0,0,0,0,0,0,0
endlayer

layer
0,0,0,0,0,0,0,0
0,0,1,0,0,1,0,0
0,1,0,0,0,0,1,0
0,1,0,0,0,0,1,0
0,1,0,0,0,0,1,0
0,1,0,0,0,0,1,0
0,0,1,0,0,1,0,0
0,0,0,0,0,0,0,0
endlayer

layer
0,0,0,0,0,0,0,0
0,0,1,0,0,1,0,0
0,1,0,0,0,0,1,0
0,1,0,0,0,0,1,0
0,1,0,0,0,0,1,0
0,1,0,0,0,0,1,0
0,0,1,0,0,1,0,0
0,0,0,0,0,0,0,0
endlayer

layer
0,0,0,0,0,0,0,0
0,0,1,4,4,1,0,0
0,1,0,0,0,0,1,0
0,1,0,0,0,0,1,0
0,1,0,0,0,0,1,0
0,1,0,0,0,0,1,0
0,0,1,4,4,1,0,0
0,0,0,0,0,0,0,0
endlayer

layer
0,0,0,0,0,0,0,0
0,0,1,1,1,1,0,0
0,1,0,0,0,0,1,0
0,1,0,0,0,0,1,0
0,1,0,0,0,0,1,0
0,1,0,0,0,0,1,0
0,0,1,1,4,1,0,0
0,0,0,0,0,0,0,0
endlayer

layer
0,0,0,0,0,0,0,0
0,0,1,1,1,1,0,0
0,1,0,0,0,0,1,0
0,1,0,0,0,0,1,0
0,1,0,0,0,0,1,0
0,1,0,0,0,0,1,0
0,0,1,1,1,1,0,0
0,0,0,0,0,0,0,0
endlayer

layer
0,0,0,0,0,0,0,0
0,0,1,1,1,1,0,0
0,1,0,0,0,0,1,0
0,1,0,0,0,0,1,0
0,1,0,0,0,0,1,0
0,1,0,0,0,0,1,0
0,0,1,1,1,1,0,0
0,0,0,0,0,0,0,0
endlayer

layer
0,0,0,0,0,0,0,0
0,0,1,1,1,0,0,0
0,1,0,0,0,0,1,0
0,1,0,0,0,0,1,0
0,1,0,0,0,0,1,0
0,1,0,0,0,0,1,0
0,0,0,1,1,1,0,0
0,0,0,0,0,0,0,0
endlayer

layer
0,0,0,0,0,0,0,0
0,0,1,1,1,0,0,0
0,1,0,0,0,0,1,0
0,1,0,0,0,0,1,0
0,1,0,0,0,0,1,0
0,1,0,0,0,0,1,0
0,0,0,1,1,1,0,0
0,0,0,0,0,0,0,0
endlayer

layer
0,0,0,0,0,0,0,0
0,0,1,1,0,0,0,0
0,1,0,0,0,0,1,0
0,1,0,0,0,0,1,0
0,1,0,0,0,0,1,0
0,1,0,0,0,0,1,0
0,0,0,0,1,1,0,0
0,0,0,0,0,0,0,0
endlayer

layer
0,0,0,0,0,0,0,0
0,0,1,1,0,0,0,0
0,1,0,0,0,0,1,0
0,1,0,0,0,0,1,0
0,1,0,0,0,0,1,0
0,1,0,0,0,0,1,0
0,0,0,0,1,1,0,0
0,0,0,0,0,0,0,0
endlayer

layer
0,0,0,0,0,0,0,0
0,0,1,0,0,0,0,0
0,1,0,0,0,0,1,0
0,1,0,0,0,0,1,0
0,1,0,0,0,0,1,0
0,1,0,0,0,0,1,0
0,0,0,0,0,1,0,0
0,0,0,0,0,0,0,0
endlayer

layer
0,0,0,0,0,0,0,0
0,0,1,0,0,0,0,0
0,1,0,0,0,0,1,0
0,1,0,0,0,0,1,0
0,1,0,0,0,0,1,0
0,1,0,0,0,0,1,0
0,0,0,0,0,1,0,0
0,0,0,0,0,0,0,0
endlayer

layer
0,0,0,0,0,0,0,0
0,0,0,0,0,0,0,0
0,0,0,0,0,0,1,0
0,1,0,0,0,0,1,0
0,1,0,0,0,0,1,0
0,1,0,0,0,0,0,0
0,0,0,0,0,0,0,0
0,0,0,0,0,0,0,0
endlayer

layer
0,0,0,0,0,0,0,0
0,0,0,0,0,0,0,0
0,0,0,0,0,0,1,0
0,1,0,0,0,0,1,0
0,1,0,0,0,0,1,0
0,1,0,0,0,0,0,0
0,0,0,0,0,0,0,0
0,0,0,0,0,0,0,0
endlayer

layer
0,0,0,0,0,0,0,0
0,0,0,0,0,0,0,0
0,0,0,0,0,0,1,0
0,0,0,0,0,0,1,0
0,1,0,0,0,0,0,0
0,1,0,0,0,0,0,0
0,0,0,0,0,0,0,0
0,0,0,0,0,0,0,0
endlayer

layer
0,0,0,0,0,0,0,0
0,0,0,0,0,0,0,0
0,0,0,0,0,0,1,0
0,0,0,0,0,0,1,0
0,1,0,0,0,0,0,0
0,1,0,0,0,0,0,0
0,0,0,0,0,0,0,0
0,0,0,0,0,0,0,0
endlayer

layer
0,0,0,0,0,0,0,0
0,0,0,0,0,0,0,0
0,0,0,0,0,0,1,0
0,0,0,0,0,0,0,0
0,0,0,0,0,0,0,0
0,1,0,0,0,0,0,0
0,0,0,0,0,0,0,0
0,0,0,0,0,0,0,0
endlayer

layer
0,0,0,0,0,0,0,0
0,0,0,0,0,0,0,0
0,0,0,0,0,0,1,0
0,0,0,0,0,0,0,0
0,0,0,0,0,0,0,0
0,1,0,0,0,0,0,0
0,0,0,0,0,0,0,0
0,0,0,0,0,0,0,0
endlayer

