# Converted from schematic
# THIS TEMPLATE USES DEFAULTS!  Please edit for corrections.
# If you need help, consult template_rules.txt

weight=3
embed_into_distance=1
acceptable_target_blocks=1,2,3,12,13
dimensions=6,11,11
allowable_overhang=0
max_cut_in=2
cut_in_buffer=1
max_leveling=2
leveling_buffer=1
preserve_water=0
preserve_lava=0
preserve_plants=0


rule1=0,100,24
rule2=0,100,159-1
rule3=0,100,44-1
rule4=0,100,24-2
rule5=0,100,54-5
rule6=0,100,24-1
rule7=0,100,64-2
rule8=0,100,58
rule9=0,100,20
rule10=0,100,64-8
rule11=0,100,128-2
rule12=0,100,128
rule13=0,100,43-1
rule14=0,100,128-1
rule15=0,100,50-4
rule16=0,100,50-3
rule17=0,100,128-3


layer
1,1,1,1,1,1,1,1,1,1,1
1,1,1,1,1,1,1,1,1,1,1
1,1,1,1,1,1,1,1,1,1,1
1,1,1,1,1,1,1,1,1,1,1
1,1,1,1,2,2,2,1,1,1,1
1,1,1,1,2,1,2,1,1,1,1
1,1,1,1,2,2,2,1,1,1,1
1,1,1,1,1,1,1,1,1,1,1
1,1,1,1,1,1,1,1,1,1,1
1,1,1,1,1,1,1,1,1,1,1
1,1,1,1,1,1,1,1,1,1,1
endlayer

layer
0,0,0,0,0,0,0,0,0,0,0
0,3,3,3,3,3,3,3,3,3,0
0,3,4,1,1,1,1,1,4,3,0
0,3,1,8,0,0,0,5,1,3,0
0,3,1,0,0,0,0,0,1,3,0
0,3,1,0,0,0,0,0,1,3,0
0,3,1,0,0,0,0,0,1,3,0
0,3,1,0,0,0,0,0,1,3,0
0,3,1,1,1,1,7,1,1,3,0
0,3,3,3,3,6,0,6,3,3,0
0,0,0,0,0,0,0,0,0,0,0
endlayer

layer
0,0,0,0,0,0,0,0,0,0,0
0,0,0,0,0,0,0,0,0,0,0
0,0,4,9,9,1,9,9,4,0,0
0,0,9,0,0,0,0,0,9,0,0
0,0,9,0,0,0,0,0,9,0,0
0,0,9,0,0,0,0,0,9,0,0
0,0,1,0,0,0,0,0,1,0,0
0,0,9,0,0,0,0,0,9,0,0
0,0,9,9,9,1,10,1,1,0,0
0,0,0,0,0,6,0,6,0,0,0
0,0,0,0,0,0,0,0,0,0,0
endlayer

layer
0,0,0,0,0,0,0,0,0,0,0
0,4,4,4,4,4,4,4,4,4,0
0,4,1,1,1,1,1,1,1,4,0
0,4,1,0,0,0,0,0,1,4,0
0,4,1,0,0,0,0,0,1,4,0
0,4,1,0,0,0,0,0,1,4,0
0,4,1,0,0,0,0,0,1,4,0
0,4,1,0,0,0,0,0,1,4,0
0,4,1,1,1,1,1,1,1,4,0
0,4,4,4,4,4,4,4,4,4,0
0,0,0,0,0,0,0,0,0,0,0
endlayer

layer
0,0,0,0,0,0,0,0,0,0,0
0,12,12,12,12,12,12,12,12,11,0
0,17,1,1,1,1,1,1,13,11,0
0,17,1,0,0,4,0,0,1,11,0
0,17,1,0,16,4,15,0,1,11,0
0,17,1,0,16,4,15,0,1,11,0
0,17,1,0,0,4,0,0,1,11,0
0,17,1,1,1,1,1,1,1,11,0
0,17,13,13,13,13,13,1,1,11,0
0,17,14,14,14,14,14,14,14,11,0
0,0,0,0,0,0,0,0,0,0,0
endlayer

layer
0,0,0,0,0,0,0,0,0,0,0
0,0,0,0,0,0,0,0,0,0,0
0,0,17,12,12,12,12,12,11,0,0
0,0,17,1,1,1,1,1,11,0,0
0,0,17,9,9,1,9,9,11,0,0
0,0,17,9,9,1,9,9,11,0,0
0,0,17,9,9,1,9,9,11,0,0
0,0,17,1,1,1,1,1,11,0,0
0,0,14,14,14,14,14,14,11,0,0
0,0,0,0,0,0,0,0,0,0,0
0,0,0,0,0,0,0,0,0,0,0
endlayer

