# Converted from schematic
# THIS TEMPLATE USES DEFAULTS!  Please edit for corrections.
# If you need help, consult template_rules.txt

weight=3
embed_into_distance=1
acceptable_target_blocks=1,2,3,12,13
dimensions=6,9,7
allowable_overhang=0
max_cut_in=2
cut_in_buffer=1
max_leveling=2
leveling_buffer=1
preserve_water=0
preserve_lava=0
preserve_plants=0


rule1=0,100,2
rule2=0,100,3
rule3=0,100,17
rule4=0,100,5
rule5=0,100,98
rule6=0,100,26-10
rule7=0,100,26-2
rule8=0,100,64
rule9=0,100,58
rule10=0,100,54-2
rule11=0,100,61-4
rule12=0,100,20
rule13=0,100,125
rule14=0,100,47
rule15=0,100,64-10
rule16=0,100,50-2
rule17=0,100,67
rule18=0,100,67-2
rule19=0,100,67-1
rule20=0,100,4
rule21=0,100,67-3


layer
1,1,1,1,1,1,1
2,2,2,3,2,2,2
2,3,3,3,3,3,2
2,3,3,4,3,3,2
2,3,3,4,3,3,2
2,3,4,3,3,3,2
2,3,3,3,3,3,2
2,2,2,2,2,2,2
1,1,1,1,1,1,1
endlayer

layer
0,0,0,0,0,0,0
5,5,5,8,5,5,5
5,10,0,0,0,4,5
5,10,0,0,0,4,5
5,0,0,0,0,0,5
5,0,0,0,0,0,5
5,11,9,0,7,6,5
5,5,5,5,5,5,5
0,0,0,0,0,0,0
endlayer

layer
0,0,0,0,0,0,0
0,13,12,15,12,13,0
4,0,0,0,0,14,4
12,0,0,0,0,14,12
12,0,0,0,0,0,12
12,0,0,0,0,0,12
4,16,0,0,0,0,4
0,4,12,12,12,4,0
0,0,0,0,0,0,0
endlayer

layer
0,16,0,0,0,16,0
0,4,4,4,4,4,0
4,0,0,0,0,0,4
12,0,0,0,0,0,12
12,0,0,0,0,0,12
12,0,0,0,0,0,12
4,0,0,0,0,0,4
0,4,12,12,12,4,0
0,0,0,0,0,0,0
endlayer

layer
17,17,17,17,17,17,17
21,20,20,20,20,20,18
21,20,0,0,0,20,18
21,20,0,0,0,20,18
21,20,0,0,0,20,18
21,20,0,0,0,20,18
21,20,0,0,0,20,18
21,20,20,20,20,20,18
19,19,19,19,19,19,19
endlayer

layer
0,0,0,0,0,0,0
0,17,17,17,17,17,0
0,21,20,20,20,18,0
0,21,20,20,20,18,0
0,21,20,20,20,18,0
0,21,20,20,20,18,0
0,21,20,20,20,18,0
0,19,19,19,19,19,0
0,0,0,0,0,0,0
endlayer

