# Converted from schematic
# THIS TEMPLATE USES DEFAULTS!  Please edit for corrections.
# If you need help, consult template_rules.txt

weight=2
embed_into_distance=1
acceptable_target_blocks=1,2,3,12,13
dimensions=6,12,10
allowable_overhang=0
max_cut_in=2
cut_in_buffer=1
max_leveling=2
leveling_buffer=1
preserve_water=0
preserve_lava=0
preserve_plants=0


rule1=0,100,2
rule2=0,100,3
rule3=0,100,17
rule4=0,100,5
rule5=0,100,35-7
rule6=0,100,126
rule7=0,100,54-3
rule8=0,100,58
rule9=0,100,118-3
rule10=0,100,44-2
rule11=0,100,64-3
rule12=0,100,85
rule13=0,100,26
rule14=0,100,47
rule15=0,100,54-2
rule16=0,100,26-8
rule17=0,100,20
rule18=0,100,64-8
rule19=0,100,72
rule20=0,100,50-4
rule21=0,100,50-1
rule22=0,100,50-3
rule23=0,100,67-2
rule24=0,100,67-1
rule25=0,100,67
rule26=0,100,4
rule27=0,100,67-3


layer
1,1,1,1,1,1,1,1,1,1
1,2,2,2,2,2,1,1,1,1
1,2,4,4,4,4,3,3,1,1
1,2,4,4,4,4,1,1,1,1
1,2,4,4,4,4,1,1,1,1
1,2,4,4,4,4,4,4,2,1
1,2,4,5,5,5,4,4,2,1
1,2,4,5,4,5,4,4,2,1
1,2,4,5,5,5,4,4,2,1
1,2,4,4,4,4,4,4,2,1
1,2,2,2,2,2,2,4,2,1
1,1,1,1,1,1,1,1,1,1
endlayer

layer
0,0,6,6,6,0,0,0,0,0
0,3,4,4,4,3,0,0,0,0
6,4,0,0,0,11,0,0,0,0
6,4,0,0,0,3,0,0,0,0
6,4,0,0,0,4,0,0,0,0
0,4,0,0,0,4,4,4,3,0
0,4,0,0,0,0,0,7,4,6
10,4,14,0,0,0,0,0,4,6
10,4,15,0,0,0,0,0,4,6
10,4,16,13,12,12,9,8,4,6
0,3,4,4,4,4,4,4,3,0
0,0,10,10,10,10,10,6,0,0
endlayer

layer
0,0,0,0,0,0,0,0,0,0
0,3,4,17,4,3,0,0,0,0
0,4,0,0,0,18,0,0,0,0
0,17,0,0,0,3,0,0,0,0
0,17,0,0,0,4,0,0,0,0
0,4,0,0,0,4,17,17,3,0
0,4,0,0,0,0,0,0,17,0
0,17,0,0,0,0,0,0,17,0
0,17,0,0,0,0,0,0,17,0
0,4,0,0,12,19,0,0,17,0
0,3,17,17,4,4,17,17,3,0
0,0,0,0,0,0,0,0,0,0
endlayer

layer
0,0,0,6,0,0,0,0,0,0
0,3,4,4,4,3,20,0,0,0
0,4,0,0,0,4,0,0,0,0
6,4,0,0,0,3,20,0,0,0
6,4,0,0,0,4,0,0,0,0
0,4,0,0,0,4,4,4,3,0
22,4,0,0,0,0,0,0,4,6
10,4,0,0,0,0,0,0,4,6
10,4,0,0,0,0,0,0,4,6
0,4,0,0,12,0,0,0,4,6
22,3,4,4,4,4,4,4,3,0
0,21,10,10,0,0,10,6,0,0
endlayer

layer
27,25,25,25,25,25,25,0,0,0
27,4,4,4,4,4,23,0,0,0
27,4,0,0,0,4,23,0,0,0
27,4,0,0,0,3,23,0,0,0
27,4,0,0,0,4,23,25,25,23
27,4,0,0,0,4,4,4,26,23
27,4,12,0,0,0,12,4,26,23
27,4,20,0,0,0,0,4,26,23
27,4,0,0,0,0,22,4,26,23
27,4,12,0,12,0,12,4,26,23
27,4,4,4,4,4,4,4,26,23
27,24,24,24,24,24,24,24,24,24
endlayer

layer
0,0,0,0,0,0,0,0,0,0
0,25,25,25,25,23,0,0,0,0
0,27,5,5,5,23,0,0,0,0
0,27,5,17,5,23,0,0,0,0
0,27,5,5,5,23,0,0,0,0
0,27,26,26,26,23,25,25,0,0
0,27,5,5,26,5,5,23,0,0
0,27,5,5,26,5,5,23,0,0
0,27,5,5,26,5,5,23,0,0
0,27,5,5,26,5,5,23,0,0
0,24,24,24,24,24,24,24,0,0
0,0,0,0,0,0,0,0,0,0
endlayer

