# Converted from schematic
# THIS TEMPLATE USES DEFAULTS!  Please edit for corrections.
# If you need help, consult template_rules.txt

weight=1
embed_into_distance=2
acceptable_target_blocks=1,2,3,12,13
dimensions=9,5,5
allowable_overhang=0
max_cut_in=2
cut_in_buffer=1
max_leveling=2
leveling_buffer=1
preserve_water=0
preserve_lava=0
preserve_plants=0


rule1=0,100,preserveBlock
rule2=0,100,4
rule3=0,100,48
rule4=0,100,9
rule5=0,100,67
rule6=0,100,67-1
rule7=0,100,20
rule8=0,100,89
rule9=0,100,44-3


layer
1,3,3,2,1
3,3,3,3,2
3,3,3,3,3
3,3,3,3,2
1,3,3,3,1
endlayer

layer
1,3,2,3,1
3,4,4,4,3
3,4,4,4,2
3,4,4,4,3
1,3,2,2,1
endlayer

layer
1,2,3,3,1
3,4,4,4,3
2,4,4,4,2
3,4,4,4,2
1,3,3,3,1
endlayer

layer
0,0,0,0,0
0,0,0,0,0
2,0,0,0,2
0,0,0,0,0
0,0,0,0,0
endlayer

layer
0,0,0,0,0
0,0,0,0,0
2,0,0,0,2
0,0,0,0,0
0,0,0,0,0
endlayer

layer
0,0,0,0,0
0,0,0,0,0
2,0,0,0,2
0,0,0,0,0
0,0,0,0,0
endlayer

layer
5,5,5,5,5
2,3,3,3,3
2,2,7,2,3
3,3,3,2,2
6,6,6,6,6
endlayer

layer
0,0,0,0,0
5,5,5,5,5
2,2,8,2,3
6,6,6,6,6
0,0,0,0,0
endlayer

layer
0,0,0,0,0
0,0,0,0,0
9,9,9,9,9
0,0,0,0,0
0,0,0,0,0
endlayer

