# Converted from schematic
# THIS TEMPLATE USES DEFAULTS!  Please edit for corrections.
# If you need help, consult template_rules.txt

weight=1
embed_into_distance=1
acceptable_target_blocks=1,2,3,12,13,79
dimensions=7,9,10
allowable_overhang=0
max_cut_in=2
cut_in_buffer=0
max_leveling=2
leveling_buffer=1
preserve_water=0
preserve_lava=0
preserve_plants=0


rule1=0,100,80
rule2=0,100,126
rule3=0,100,78
rule4=0,100,64-1
rule5=0,100,58
rule6=0,100,50-2
rule7=0,100,102
rule8=0,100,64-11
rule9=0,100,79


layer
1,1,1,1,1,1,1,1,1,1
1,1,1,1,1,1,1,1,1,1
1,1,1,1,1,1,1,1,1,1
1,1,1,1,1,1,1,1,1,1
1,1,1,1,1,1,1,1,1,1
1,1,1,1,1,1,1,1,1,1
1,1,1,1,1,1,1,1,1,1
1,1,1,1,1,1,1,1,1,1
1,1,1,1,1,1,1,1,1,1
endlayer

layer
3,0,1,1,1,1,1,1,1,1
1,0,1,1,1,1,1,1,2,0
3,0,1,1,1,1,1,1,1,1
3,0,1,1,1,1,1,1,0,0
0,0,1,1,1,1,1,1,0,0
0,0,1,1,1,1,1,1,0,0
3,0,1,1,1,1,1,1,0,0
1,0,1,1,1,1,1,1,0,1
3,3,1,1,1,1,1,1,3,0
endlayer

layer
0,0,1,1,1,1,1,1,1,1
1,0,1,0,0,0,0,4,0,0
0,0,1,0,0,0,0,1,1,1
0,0,1,0,0,0,0,1,0,0
0,0,1,0,0,0,0,1,0,0
0,0,1,0,0,0,0,1,0,0
0,0,1,0,0,0,0,1,0,0
1,0,1,6,0,0,5,1,0,1
0,0,1,1,1,1,1,1,0,0
endlayer

layer
0,0,1,1,7,7,1,7,1,1
1,0,1,0,0,0,0,8,0,0
0,0,7,0,0,0,0,1,1,1
0,0,7,0,0,0,0,1,0,0
0,0,1,0,0,0,0,7,0,0
0,0,7,0,0,0,0,7,0,0
0,0,7,0,0,0,0,7,0,0
1,0,1,0,0,0,0,1,0,1
0,0,1,1,7,7,1,1,0,0
endlayer

layer
0,0,1,1,7,7,1,1,1,1
1,0,1,0,0,0,0,1,1,1
0,0,1,0,0,0,0,1,1,1
0,0,1,0,0,0,0,1,0,0
0,0,1,0,0,0,0,7,0,0
0,0,1,0,0,0,0,7,0,0
0,0,1,0,0,0,0,7,0,0
1,0,1,0,0,0,0,1,0,1
0,0,1,1,7,7,1,1,0,0
endlayer

layer
0,0,1,1,1,1,1,1,0,0
1,1,1,1,1,1,1,1,1,1
0,0,1,1,9,9,1,1,0,0
0,0,1,1,9,9,1,1,0,0
0,0,1,1,9,9,1,1,0,0
0,0,1,1,9,9,1,1,0,0
0,0,1,1,9,9,1,1,0,0
1,1,1,1,1,1,1,1,1,1
0,0,1,1,1,1,1,1,0,0
endlayer

layer
0,0,0,0,0,0,0,0,0,0
0,0,0,1,1,1,1,0,0,0
0,0,0,1,0,0,1,0,0,0
0,0,0,1,0,0,1,0,0,0
0,0,0,1,0,0,1,0,0,0
0,0,0,1,0,0,1,0,0,0
0,0,0,1,0,0,1,0,0,0
0,0,0,1,1,1,1,0,0,0
0,0,0,0,0,0,0,0,0,0
endlayer

