# Converted from schematic
# THIS TEMPLATE USES DEFAULTS!  Please edit for corrections.
# If you need help, consult template_rules.txt

weight=1
embed_into_distance=1
acceptable_target_blocks=1,2,3,12,13
dimensions=8,12,17
allowable_overhang=0
max_cut_in=2
cut_in_buffer=1
max_leveling=2
leveling_buffer=1
preserve_water=0
preserve_lava=0
preserve_plants=0


rule1=0,100,2
rule2=0,100,3
rule3=0,100,18-12
rule4=0,100,98
rule5=0,100,5
rule6=0,100,98-1
rule7=0,100,109
rule8=0,100,1
rule9=0,100,4
rule10=0,100,5-1
rule11=0,100,26-9
rule12=0,100,26-1
rule13=0,100,44-2
rule14=0,100,64-6
rule15=0,100,85
rule16=0,100,64-1
rule17=0,100,102
rule18=0,100,64-8
rule19=0,100,64-9
rule20=0,100,53-2
rule21=0,100,53-7
rule22=0,100,53-6
rule23=0,100,126-8
rule24=0,100,53-3
rule25=0,100,53
rule26=0,100,50-3
rule27=0,100,50-1
rule28=0,100,53-1
rule29=0,100,50-2
rule30=0,100,50-4
rule31=0,100,126


layer
1,1,1,1,1,1,2,1,1,1,2,1,1,1,1,1,1
1,2,2,2,2,2,2,2,2,2,2,2,2,2,2,2,1
1,2,2,2,2,2,2,2,2,2,2,2,2,2,2,2,1
1,2,2,2,2,2,2,2,2,2,2,2,2,2,2,2,1
1,2,2,2,2,2,2,2,2,2,2,2,2,2,2,2,1
1,2,2,2,2,2,2,2,2,2,2,2,2,2,2,2,1
1,2,2,2,2,2,2,2,2,2,2,2,2,2,2,2,1
1,2,2,2,2,2,2,2,2,2,2,2,2,2,2,2,1
1,2,2,2,2,2,2,2,2,2,2,2,2,2,2,2,1
1,2,2,2,2,2,2,2,2,2,2,2,2,2,2,2,1
1,2,2,2,2,2,2,2,2,2,2,2,2,2,2,2,1
1,1,1,1,1,1,1,1,1,1,1,1,1,1,1,1,1
endlayer

layer
3,3,3,3,3,3,4,0,0,0,4,3,3,3,3,3,3
3,4,4,4,4,4,4,7,7,7,4,4,4,4,4,4,3
3,4,5,5,5,8,6,6,4,4,4,4,5,5,5,4,3
3,4,5,5,5,5,4,1,1,1,6,4,5,5,5,4,3
3,4,5,5,5,5,4,1,1,1,4,4,5,5,5,4,3
3,4,5,5,5,8,4,4,4,4,6,4,5,5,5,4,3
3,4,5,5,5,4,4,4,4,4,4,4,5,5,5,4,3
3,4,5,5,5,5,5,5,5,5,5,5,5,5,5,4,3
3,4,5,5,5,5,5,5,5,5,5,5,5,5,5,4,3
3,4,5,5,5,5,5,5,5,5,5,5,5,5,5,4,3
3,4,4,4,4,4,4,4,4,4,4,4,4,4,4,4,3
3,3,3,3,3,3,3,3,3,3,3,3,3,3,3,3,3
endlayer

layer
0,0,0,0,0,0,15,0,0,0,15,0,0,0,0,0,0
0,9,10,10,10,9,15,0,0,0,15,9,10,10,10,9,0
0,10,0,0,0,10,0,0,0,0,0,10,11,13,11,10,0
0,10,0,0,0,16,0,0,0,0,0,10,12,13,12,10,0
0,10,0,0,0,16,0,0,0,0,0,10,0,0,0,10,0
0,10,0,0,0,10,0,0,0,0,0,10,0,0,0,10,0
0,9,0,0,0,10,10,10,10,10,10,10,10,14,10,9,0
0,10,0,0,0,0,0,0,0,0,0,0,0,0,0,10,0
0,10,0,0,0,0,0,0,0,0,0,0,0,0,0,10,0
0,10,0,0,0,0,0,0,0,0,0,0,0,0,0,10,0
0,9,10,10,10,9,10,10,9,10,10,9,10,10,10,9,0
0,0,0,0,0,0,0,0,0,0,0,0,0,0,0,0,0
endlayer

layer
0,0,0,0,0,0,0,0,0,0,0,0,0,0,0,0,0
0,9,10,17,10,9,15,0,0,0,15,9,10,17,10,9,0
0,10,0,0,0,10,0,0,0,0,0,10,0,0,0,10,0
0,17,0,0,0,19,0,0,0,0,0,17,0,0,0,17,0
0,17,0,0,0,18,0,0,0,0,0,17,0,0,0,17,0
0,10,0,0,0,10,0,0,0,0,0,10,0,0,0,10,0
0,9,0,0,0,10,10,17,17,17,10,10,10,18,10,9,0
0,10,0,0,0,0,0,0,0,0,0,0,0,0,0,10,0
0,10,0,0,0,0,0,0,0,0,0,0,0,0,0,10,0
0,10,0,0,0,0,0,0,0,0,0,0,0,0,0,10,0
0,9,10,17,10,9,10,10,9,10,10,9,10,17,10,9,0
0,0,0,0,0,0,0,0,0,0,0,0,0,0,0,0,0
endlayer

layer
24,0,0,0,0,0,20,0,0,0,24,22,0,0,0,21,20
24,9,10,17,10,9,20,0,0,0,24,9,10,17,10,9,20
24,10,0,0,0,10,20,0,0,0,24,10,0,0,0,10,20
24,10,0,0,0,10,20,0,0,0,24,10,0,0,0,10,20
24,10,0,0,0,10,20,0,0,0,24,10,0,0,0,10,20
24,10,0,0,0,10,5,25,25,25,5,10,0,0,0,10,20
24,9,0,0,0,10,10,10,10,10,10,10,10,10,10,9,20
24,10,0,0,0,0,0,0,0,0,0,0,0,0,0,10,20
24,10,0,0,0,0,0,0,0,0,0,0,0,0,0,10,20
24,10,0,0,0,0,0,0,0,0,0,0,0,0,0,10,20
24,9,10,17,10,9,10,10,9,10,10,9,10,17,10,9,20
24,22,0,0,0,23,23,23,23,23,23,23,0,0,0,21,20
endlayer

layer
0,24,0,0,0,20,0,0,0,0,0,24,22,0,21,20,0
0,24,10,10,10,20,0,0,0,0,0,24,10,10,10,20,0
0,24,0,27,0,20,0,0,0,0,0,24,0,0,0,20,0
0,24,0,0,0,20,0,0,0,0,0,24,0,0,0,20,0
0,24,0,0,0,20,0,0,0,0,0,24,0,0,0,20,0
0,24,30,0,0,20,0,0,0,0,0,24,0,0,0,20,0
0,24,0,0,0,5,25,25,25,25,25,5,5,5,5,20,0
0,24,0,0,0,0,0,0,0,0,27,0,0,0,0,20,0
0,24,0,0,0,0,0,0,0,0,0,0,0,0,26,20,0
0,24,0,0,0,0,0,0,29,0,0,0,0,0,0,20,0
0,24,10,10,10,5,28,28,28,28,28,5,10,10,10,20,0
0,24,22,0,21,20,13,13,13,13,13,24,22,0,21,20,0
endlayer

layer
0,0,24,5,20,0,0,0,0,0,0,0,24,5,20,0,0
0,0,24,5,20,0,0,0,0,0,0,0,24,5,20,0,0
0,0,24,0,20,0,0,0,0,0,0,0,24,27,20,0,0
0,0,24,0,20,0,0,0,0,0,0,0,24,0,20,0,0
0,0,24,0,20,0,0,0,0,0,0,0,24,0,20,0,0
0,0,24,0,20,0,0,0,0,0,0,0,24,0,20,0,0
0,0,24,0,20,0,0,0,0,0,0,0,24,5,20,0,0
0,0,24,0,5,25,25,25,25,25,25,25,5,5,20,0,0
0,0,24,0,0,0,0,0,0,0,0,0,0,0,20,0,0
0,0,24,5,5,28,28,28,28,28,28,28,5,5,20,0,0
0,0,24,5,20,0,0,0,0,0,0,0,24,5,20,0,0
0,0,24,5,20,0,0,0,0,0,0,0,24,5,20,0,0
endlayer

layer
0,0,0,31,0,0,0,0,0,0,0,0,0,13,0,0,0
0,0,0,31,0,0,0,0,0,0,0,0,0,31,0,0,0
0,0,0,31,0,0,0,0,0,0,0,0,0,31,0,0,0
0,0,0,31,0,0,0,0,0,0,0,0,0,31,0,0,0
0,0,0,31,0,0,0,0,0,0,0,0,0,31,0,0,0
0,0,0,31,0,0,0,0,0,0,0,0,0,31,0,0,0
0,0,0,31,0,0,0,0,0,0,0,0,0,31,0,0,0
0,0,0,31,0,0,0,0,0,0,0,0,0,31,0,0,0
0,0,0,31,31,31,31,31,31,31,31,31,31,31,0,0,0
0,0,0,31,0,0,0,0,0,0,0,0,0,31,0,0,0
0,0,0,31,0,0,0,0,0,0,0,0,0,31,0,0,0
0,0,0,31,0,0,0,0,0,0,0,0,0,31,0,0,0
endlayer

