# Converted from schematic
# THIS TEMPLATE USES DEFAULTS!  Please edit for corrections.
# If you need help, consult template_rules.txt

weight=1
embed_into_distance=1
acceptable_target_blocks=1,2,3,12,13
dimensions=8,8,9
allowable_overhang=0
max_cut_in=2
cut_in_buffer=1
max_leveling=2
leveling_buffer=1
preserve_water=0
preserve_lava=0
preserve_plants=0


rule1=0,100,2
rule2=0,100,98
rule3=0,100,109-1
rule4=0,100,17
rule5=0,100,4
rule6=0,100,85
rule7=0,100,64
rule8=0,100,102
rule9=0,100,64-8
rule10=0,100,134-2
rule11=0,100,134-1
rule12=0,100,5
rule13=0,100,126-9
rule14=0,100,134-3
rule15=0,100,134
rule16=0,100,126-1


layer
1,2,2,2,2,2,2,2,1
1,2,2,2,2,2,2,2,1
1,2,2,2,2,2,2,2,1
1,2,2,2,2,2,2,2,1
1,2,2,2,2,2,2,2,1
1,2,2,2,2,2,2,2,1
1,2,2,2,2,2,2,2,1
1,1,1,2,2,2,1,1,1
endlayer

layer
0,2,2,2,2,2,2,2,0
0,2,2,2,2,2,2,2,0
0,2,2,2,2,2,2,2,0
0,2,2,2,2,2,2,2,0
0,2,2,2,2,2,2,2,0
0,2,2,2,2,2,2,2,0
0,2,2,2,2,2,2,2,0
0,0,0,2,3,2,0,0,0
endlayer

layer
0,4,5,5,5,5,5,4,0
0,5,0,0,0,0,0,5,0
0,5,0,0,0,0,0,5,0
0,5,0,0,0,0,0,5,0
0,5,0,0,0,0,0,5,0
0,5,0,0,0,0,0,5,0
0,4,5,5,7,5,5,4,0
0,0,0,6,0,6,0,0,0
endlayer

layer
0,4,5,5,5,5,5,4,0
0,5,0,0,0,0,0,5,0
0,8,0,0,0,0,0,8,0
0,5,0,0,0,0,0,5,0
0,8,0,0,0,0,0,8,0
0,5,0,0,0,0,0,5,0
0,4,8,5,9,5,8,4,0
0,0,0,6,0,6,0,0,0
endlayer

layer
14,4,5,5,5,5,5,4,10
14,5,0,0,0,0,0,5,10
14,5,0,0,0,0,0,5,10
14,5,0,0,0,0,0,5,10
14,5,0,0,0,0,0,5,10
14,5,0,0,0,0,0,5,10
14,4,5,5,12,5,5,4,10
0,0,14,11,13,11,10,0,0
endlayer

layer
0,14,12,12,12,12,12,10,0
0,14,0,0,0,0,0,10,0
0,14,0,0,0,0,0,10,0
0,14,0,0,0,0,0,10,0
0,14,0,0,0,0,0,10,0
0,14,0,0,0,0,0,10,0
0,14,12,12,12,12,12,10,0
0,0,0,0,0,0,0,0,0
endlayer

layer
0,0,14,12,12,12,10,0,0
0,0,14,0,0,0,10,0,0
0,0,14,0,0,0,10,0,0
0,0,14,0,0,0,10,0,0
0,0,14,0,0,0,10,0,0
0,0,14,0,0,0,10,0,0
0,0,14,12,12,12,10,0,0
0,0,0,0,0,0,0,0,0
endlayer

layer
0,0,0,15,15,10,0,0,0
0,0,0,14,16,10,0,0,0
0,0,0,14,16,10,0,0,0
0,0,0,14,16,10,0,0,0
0,0,0,14,16,10,0,0,0
0,0,0,14,16,10,0,0,0
0,0,0,14,11,10,0,0,0
0,0,0,0,0,0,0,0,0
endlayer

