# Converted from schematic
# THIS TEMPLATE USES DEFAULTS!  Please edit for corrections.
# If you need help, consult template_rules.txt

weight=3
embed_into_distance=1
acceptable_target_blocks=1,2,3,12,13
dimensions=7,8,9
allowable_overhang=0
max_cut_in=2
cut_in_buffer=1
max_leveling=2
leveling_buffer=1
preserve_water=0
preserve_lava=0
preserve_plants=0


rule1=0,100,2
rule2=0,100,3
rule3=0,100,17
rule4=0,100,5
rule5=0,100,134-2
rule6=0,100,126-1
rule7=0,100,134-1
rule8=0,100,134
rule9=0,100,5-1
rule10=0,100,4
rule11=0,100,47
rule12=0,100,26-10
rule13=0,100,26-2
rule14=0,100,64
rule15=0,100,85
rule16=0,100,54-2
rule17=0,100,134-3
rule18=0,100,20
rule19=0,100,50-2
rule20=0,100,50-1
rule21=0,100,64-9
rule22=0,100,72
rule23=0,100,134-4
rule24=0,100,67
rule25=0,100,67-2
rule26=0,100,67-1
rule27=0,100,43-2
rule28=0,100,67-3


layer
1,1,1,4,4,4,1,1,1
1,2,2,2,4,2,2,2,1
1,2,3,3,3,3,3,2,1
1,2,3,4,4,4,3,2,1
1,2,3,4,4,4,3,2,1
1,2,3,3,3,3,3,2,1
1,2,2,2,2,2,2,2,1
1,1,1,1,1,1,1,1,1
endlayer

layer
8,8,6,0,0,0,6,8,5
17,9,4,4,14,4,4,9,5
6,4,4,0,0,0,11,4,6
0,4,0,15,0,0,0,4,0
0,4,0,0,0,0,0,4,0
6,4,16,0,0,13,12,4,6
17,10,4,4,4,4,4,10,5
7,7,6,0,0,0,6,7,7
endlayer

layer
0,0,0,0,0,0,0,0,0
0,9,18,4,21,4,18,9,0
0,4,0,20,0,20,0,4,0
0,18,0,22,0,0,0,18,0
0,18,0,0,0,0,0,18,0
0,4,19,0,0,0,19,4,0
0,9,4,18,18,18,4,9,0
0,0,0,0,0,0,0,0,0
endlayer

layer
0,0,0,23,23,23,0,0,0
0,9,18,4,4,4,18,9,0
0,4,0,0,0,0,0,4,0
0,18,0,0,0,0,0,18,0
0,18,0,0,0,0,0,18,0
0,4,0,0,0,0,0,4,0
0,9,4,18,18,18,4,9,0
0,0,0,0,0,0,0,0,0
endlayer

layer
28,24,24,24,24,24,24,24,24
28,10,27,27,4,4,4,10,25
28,4,4,4,4,4,4,4,25
6,10,4,3,3,3,4,10,6
6,10,4,3,3,3,4,10,6
28,4,4,4,4,4,4,4,25
28,10,10,10,10,10,10,10,25
26,26,0,6,6,6,0,26,25
endlayer

layer
0,0,0,0,0,0,0,0,0
0,24,24,24,24,24,24,25,0
0,28,10,10,10,10,10,25,0
0,28,10,10,10,10,10,25,0
0,28,10,10,10,10,10,25,0
0,28,10,10,10,10,10,25,0
0,28,26,26,26,26,26,26,0
0,0,0,0,0,0,0,0,0
endlayer

layer
0,0,0,0,0,0,0,0,0
0,0,0,0,0,0,0,0,0
0,0,24,24,24,24,24,0,0
0,0,28,0,0,0,25,0,0
0,0,28,0,0,0,25,0,0
0,0,26,26,26,26,25,0,0
0,0,0,0,0,0,0,0,0
0,0,0,0,0,0,0,0,0
endlayer

