# Converted from schematic
# THIS TEMPLATE USES DEFAULTS!  Please edit for corrections.
# If you need help, consult template_rules.txt

weight=1
embed_into_distance=7
acceptable_target_blocks=1,2,3,12,13
dimensions=14,10,12
allowable_overhang=0
max_cut_in=2
cut_in_buffer=1
max_leveling=2
leveling_buffer=1
preserve_water=0
preserve_lava=0
preserve_plants=0


rule1=0,100,3
rule2=0,100,4
rule3=0,100,54-3
rule4=0,100,65-4
rule5=0,100,54-4
rule6=0,100,54-2
rule7=0,100,50-1
rule8=0,100,50-2
rule9=0,100,43
rule10=0,100,5
rule11=0,100,2
rule12=0,100,1
rule13=0,100,96-2
rule14=0,100,64-6
rule15=0,100,54-5
rule16=0,100,61-4
rule17=0,100,26
rule18=0,100,26-8
rule19=0,100,58
rule20=0,100,64-3
rule21=0,100,102
rule22=0,100,64-8
rule23=0,100,67-2
rule24=0,100,67-1
rule25=0,100,67-3
rule26=0,100,67


layer
1,1,1,1,1,1,1,1,1,1,1,1
1,1,1,1,1,1,1,1,1,1,1,1
1,1,1,1,1,1,1,1,1,1,1,1
1,1,1,1,1,1,1,1,1,1,1,1
1,1,1,1,1,1,1,2,2,2,2,2
1,1,1,1,1,1,1,2,2,2,2,2
1,1,1,1,1,1,1,2,2,2,2,2
1,1,1,1,1,1,1,2,2,2,2,2
1,1,1,1,1,1,1,2,2,2,2,2
1,1,1,1,1,1,1,2,2,2,2,2
endlayer

layer
1,1,1,1,1,1,1,1,1,1,1,1
1,1,1,1,1,1,1,1,1,1,1,1
1,1,1,1,1,1,1,1,1,1,1,1
1,1,1,1,1,1,1,1,1,1,1,1
1,1,1,1,1,1,1,2,2,2,2,2
1,1,1,1,1,1,1,2,6,0,3,2
1,1,1,1,1,1,1,2,6,0,3,2
1,1,1,1,1,1,1,2,0,0,0,2
1,1,1,1,1,1,1,2,5,5,4,2
1,1,1,1,1,1,1,2,2,2,2,2
endlayer

layer
1,1,1,1,1,1,1,1,1,1,1,1
1,1,1,1,1,1,1,1,1,1,1,1
1,1,1,1,1,1,1,1,1,1,1,1
1,1,1,1,1,1,1,1,1,1,1,1
1,1,1,1,1,1,1,2,2,2,2,2
1,1,1,1,1,1,1,2,0,0,0,2
1,1,1,1,1,1,1,2,0,0,0,2
1,1,1,1,1,1,1,2,0,0,0,2
1,1,1,1,1,1,1,2,0,0,4,2
1,1,1,1,1,1,1,2,2,2,2,2
endlayer

layer
1,1,1,1,1,1,1,1,1,1,1,1
1,1,1,1,1,1,1,1,1,1,1,1
1,1,1,1,1,1,1,1,1,1,1,1
1,1,1,1,1,1,1,1,1,1,1,1
1,1,1,1,1,1,1,2,2,2,2,2
1,1,1,1,1,1,1,2,7,0,7,2
1,1,1,1,1,1,1,2,0,0,0,2
1,1,1,1,1,1,1,2,0,0,0,2
1,1,1,1,1,1,1,2,8,0,4,2
1,1,1,1,1,1,1,2,2,2,2,2
endlayer

layer
1,1,1,1,1,1,1,1,1,1,1,1
1,1,1,1,1,1,1,1,1,1,1,1
1,1,1,1,1,1,1,1,1,1,1,1
1,1,1,1,1,1,1,1,1,1,1,1
1,1,1,1,1,1,1,2,2,2,2,2
1,1,1,1,1,1,1,2,2,2,2,2
1,1,1,1,1,1,1,2,2,2,2,2
1,1,1,1,1,1,1,2,2,2,2,2
1,1,1,1,1,1,1,2,2,2,4,2
1,1,1,1,1,1,1,2,2,2,2,2
endlayer

layer
1,1,1,1,1,1,1,1,1,1,1,1
1,1,1,1,1,1,1,1,1,1,1,1
1,1,1,1,1,1,1,1,1,1,1,1
1,1,1,1,1,1,1,1,1,1,1,1
1,1,1,1,1,1,1,1,1,1,1,1
1,1,1,1,1,1,1,1,1,1,1,1
1,1,1,1,1,1,1,1,1,1,1,1
1,1,1,1,1,1,1,1,1,1,1,1
1,1,1,1,1,1,1,1,1,1,4,1
1,1,1,1,1,1,1,1,1,1,1,1
endlayer

layer
11,12,12,11,11,9,2,2,2,2,2,9
11,11,12,11,11,2,10,10,10,10,10,2
11,11,11,11,11,2,10,10,10,10,10,2
11,11,11,11,11,2,10,10,10,10,10,2
9,2,2,2,2,2,10,10,10,10,10,2
2,10,10,10,10,10,10,10,10,10,10,2
2,10,10,10,10,10,10,10,10,10,10,2
2,10,10,10,10,10,10,10,10,10,10,2
10,10,10,10,10,10,10,10,10,10,4,2
9,2,2,2,2,2,2,2,2,2,2,9
endlayer

layer
0,0,0,0,0,9,2,2,2,2,2,9
0,0,0,0,0,2,0,0,0,0,0,2
0,0,0,0,0,2,18,17,0,0,3,2
0,0,0,0,0,2,0,0,0,0,3,2
9,2,2,2,2,2,2,2,2,14,2,2
2,0,0,0,15,15,19,15,15,0,3,2
2,0,0,0,0,0,0,0,0,0,3,2
2,0,0,0,0,0,0,0,0,0,0,2
20,0,0,0,16,16,19,16,16,0,13,2
9,2,2,2,2,2,2,2,2,2,2,9
endlayer

layer
0,0,0,0,0,9,2,21,21,21,2,9
0,0,0,0,0,2,0,0,0,0,0,2
0,0,0,0,0,21,0,0,0,0,0,21
0,0,0,0,0,2,0,0,0,0,0,2
9,2,21,21,2,2,2,2,2,22,2,2
2,0,0,0,0,0,0,0,0,0,0,2
21,0,0,0,0,0,0,0,0,0,0,21
2,0,0,0,0,0,0,0,0,0,0,21
22,0,0,0,0,0,0,0,0,0,0,2
9,2,21,21,2,2,2,21,21,21,2,9
endlayer

layer
0,0,0,0,0,9,2,21,21,21,2,9
0,0,0,0,0,2,0,0,0,0,0,2
0,0,0,0,0,21,0,0,0,0,0,21
0,0,0,0,0,2,0,0,0,0,0,2
9,2,21,21,2,2,2,2,2,2,2,2
2,0,0,0,0,0,0,0,0,0,0,2
21,0,0,0,0,0,0,0,0,0,0,21
2,0,0,0,0,0,0,0,0,0,0,21
2,0,0,0,0,0,0,0,0,0,0,2
9,2,21,21,2,2,2,21,21,21,2,9
endlayer

layer
0,0,0,0,0,9,2,2,2,2,2,9
0,0,0,0,0,2,7,0,0,0,7,2
0,0,0,0,0,2,0,0,0,0,0,2
0,0,0,0,0,2,8,0,0,0,8,2
9,2,2,2,2,2,2,2,2,2,2,2
2,7,0,0,0,0,7,0,0,0,7,2
2,0,0,0,0,0,0,0,0,0,0,2
2,0,0,0,0,0,0,0,0,0,0,2
2,8,0,0,0,0,8,0,0,0,8,2
9,2,2,2,2,2,2,2,2,2,2,9
endlayer

layer
0,0,0,0,0,25,2,2,2,2,2,23
0,0,0,0,0,25,2,0,0,0,2,23
0,0,0,0,0,25,2,0,0,0,2,23
0,0,0,0,0,25,2,0,0,0,2,23
26,26,26,26,26,2,2,2,2,2,2,2
2,2,2,2,2,2,2,2,2,2,2,2
2,0,0,0,0,0,0,0,0,0,0,2
2,0,0,0,0,0,0,0,0,0,0,2
2,2,2,2,2,2,2,2,2,2,2,2
24,24,24,24,24,24,24,24,24,24,24,24
endlayer

layer
0,0,0,0,0,0,25,2,2,2,23,0
0,0,0,0,0,0,25,2,0,2,23,0
0,0,0,0,0,0,25,2,0,2,23,0
0,0,0,0,0,0,25,2,0,2,23,0
0,0,0,0,0,0,25,2,2,2,23,0
26,26,26,26,26,26,2,2,2,2,2,26
2,2,2,2,2,2,2,2,2,2,2,2
2,2,2,2,2,2,2,2,2,2,2,2
24,24,24,24,24,24,24,24,24,24,24,24
0,0,0,0,0,0,0,0,0,0,0,0
endlayer

layer
0,0,0,0,0,0,0,25,2,23,0,0
0,0,0,0,0,0,0,25,2,23,0,0
0,0,0,0,0,0,0,25,2,23,0,0
0,0,0,0,0,0,0,25,2,23,0,0
0,0,0,0,0,0,0,25,2,23,0,0
0,0,0,0,0,0,0,25,2,23,0,0
26,26,26,26,26,26,26,2,2,2,26,26
24,24,24,24,24,24,24,24,24,24,24,24
0,0,0,0,0,0,0,0,0,0,0,0
0,0,0,0,0,0,0,0,0,0,0,0
endlayer

