# Converted from schematic
# THIS TEMPLATE USES DEFAULTS!  Please edit for corrections.
# If you need help, consult template_rules.txt

weight=1
embed_into_distance=1
acceptable_target_blocks=1,2,3,12,13,79
dimensions=8,11,13
allowable_overhang=0
max_cut_in=2
cut_in_buffer=0
max_leveling=2
leveling_buffer=1
preserve_water=0
preserve_lava=0
preserve_plants=0


rule1=0,100,80
rule2=0,100,3
rule3=0,100,78
rule4=0,100,44
rule5=0,100,79
rule6=0,100,87
rule7=0,100,64-1
rule8=0,100,51-15
rule9=0,100,64-8
rule10=0,100,102
rule11=0,100,50-3


layer
1,1,1,1,1,1,1,1,1,1,1,1,1
1,1,1,1,1,1,1,1,1,1,1,1,1
1,1,1,1,1,1,1,1,1,1,1,1,1
1,1,1,1,1,1,1,1,1,1,1,1,1
1,1,1,1,1,1,1,1,1,1,1,1,1
1,1,1,1,1,1,1,1,1,1,1,1,1
1,1,1,1,1,1,1,1,1,1,1,1,1
1,1,1,2,1,1,1,1,1,1,1,1,1
1,1,1,1,1,1,1,1,1,1,2,1,1
1,1,1,1,1,1,1,1,1,1,1,1,1
1,1,1,1,1,1,1,1,1,1,1,1,1
endlayer

layer
3,3,3,3,3,3,3,3,3,3,3,3,3
3,3,3,3,3,3,1,5,5,5,5,1,0
3,3,3,3,3,3,5,1,1,1,1,1,1
3,1,5,5,5,5,5,1,1,1,1,1,4
3,5,1,1,1,1,1,1,1,1,1,1,1
3,5,1,1,1,1,1,1,1,1,1,5,0
3,5,6,1,1,1,1,1,1,1,1,5,0
3,5,1,1,1,1,1,1,1,1,1,5,0
3,5,1,1,1,1,1,1,1,1,1,5,0
3,1,5,5,5,5,5,5,5,5,5,1,0
3,3,3,3,3,3,3,3,3,3,3,3,0
endlayer

layer
0,0,0,0,0,0,0,0,0,0,0,0,0
0,0,0,0,0,0,1,1,1,1,1,1,0
0,0,0,0,0,0,1,0,0,0,0,1,1
0,1,1,1,1,1,1,0,0,0,0,7,0
0,1,0,0,0,0,0,0,0,0,0,1,1
0,1,1,0,0,0,0,0,0,0,0,1,0
0,1,8,1,0,0,0,0,0,0,0,1,0
0,1,1,0,0,0,0,0,0,0,0,1,0
0,1,0,0,0,0,0,0,0,0,0,1,0
0,1,1,1,1,1,1,1,1,1,1,1,0
0,0,0,0,0,0,0,0,0,0,0,0,0
endlayer

layer
0,0,0,0,0,0,0,0,0,0,0,0,0
0,0,0,0,0,0,1,1,10,10,1,1,0
0,0,0,0,0,0,1,0,0,0,0,1,1
0,1,1,10,10,1,1,0,0,0,0,9,0
0,1,0,0,0,0,0,0,0,0,0,1,1
0,10,0,0,0,0,0,0,0,0,0,1,0
0,10,0,0,0,0,0,0,0,0,0,10,0
0,10,0,0,0,0,0,0,0,0,0,1,0
0,1,0,0,0,0,0,0,0,0,0,1,0
0,1,1,10,10,1,1,1,10,10,1,1,0
0,0,0,0,0,0,0,0,0,0,0,0,0
endlayer

layer
0,0,0,0,0,1,1,0,0,0,0,1,1
0,0,0,0,0,1,1,1,1,1,1,1,1
0,0,0,0,0,1,1,0,0,0,0,1,1
1,1,1,1,1,1,1,0,0,0,11,1,1
0,1,0,0,0,0,0,0,0,0,0,1,1
0,1,0,0,0,0,0,0,0,0,0,1,1
0,1,0,0,0,0,0,0,0,0,0,1,1
0,1,0,0,0,0,0,0,0,0,0,1,1
0,1,0,0,0,0,0,0,0,0,0,1,1
1,1,1,1,1,1,1,1,1,1,1,1,1
0,0,0,0,0,1,1,0,0,0,0,1,1
endlayer

layer
0,0,0,0,0,0,1,1,0,0,1,1,0
0,0,0,0,0,0,1,1,1,1,1,1,0
0,0,0,0,0,0,1,1,0,0,1,1,0
0,0,0,0,0,0,1,1,0,0,1,1,0
1,1,1,1,1,1,1,1,0,0,1,1,0
0,1,0,0,0,0,0,0,0,0,1,1,0
0,10,0,0,0,0,0,0,0,0,1,1,0
0,1,0,0,0,0,0,0,0,0,1,1,0
1,1,1,1,1,1,1,1,1,1,1,1,0
0,0,0,0,0,0,1,1,1,1,1,1,0
0,0,0,0,0,0,1,1,0,0,1,1,0
endlayer

layer
0,0,0,0,0,0,0,1,1,1,1,0,0
0,0,0,0,0,0,0,1,1,1,1,0,0
0,0,0,0,0,0,0,1,1,1,1,0,0
0,0,0,0,0,0,0,1,1,1,1,0,0
0,0,0,0,0,0,0,1,1,1,1,0,0
1,1,1,1,1,1,1,1,1,1,1,0,0
0,1,0,0,0,0,0,1,1,1,1,0,0
1,1,1,1,1,1,1,1,1,1,1,0,0
0,0,0,0,0,0,0,1,1,1,1,0,0
0,0,0,0,0,0,0,1,1,1,1,0,0
0,0,0,0,0,0,0,1,1,1,1,0,0
endlayer

layer
0,0,0,0,0,0,0,0,1,1,0,0,0
0,0,0,0,0,0,0,0,1,1,0,0,0
0,0,0,0,0,0,0,0,1,1,0,0,0
0,0,0,0,0,0,0,0,1,1,0,0,0
0,0,0,0,0,0,0,0,1,1,0,0,0
0,0,0,0,0,0,0,0,1,1,0,0,0
1,1,1,1,1,1,1,1,1,1,0,0,0
0,0,0,0,0,0,0,0,1,1,0,0,0
0,0,0,0,0,0,0,0,1,1,0,0,0
0,0,0,0,0,0,0,0,1,1,0,0,0
0,0,0,0,0,0,0,0,1,1,0,0,0
endlayer

