# Converted from schematic
# THIS TEMPLATE USES DEFAULTS!  Please edit for corrections.
# If you need help, consult template_rules.txt

weight=1
embed_into_distance=1
acceptable_target_blocks=1,2,3,12,13,79
dimensions=9,8,11
allowable_overhang=0
max_cut_in=2
cut_in_buffer=0
max_leveling=2
leveling_buffer=1
preserve_water=0
preserve_lava=0
preserve_plants=0


rule1=0,100,80
rule2=0,100,78


layer
1,1,1,1,1,1,1,1,1,1,1
1,1,1,1,1,1,1,1,1,1,1
1,1,1,1,1,1,1,1,1,1,1
1,1,1,1,1,1,1,1,1,1,1
1,1,1,1,1,1,1,1,1,1,1
1,1,1,1,1,1,1,1,1,1,1
1,1,1,1,1,1,1,1,1,1,1
1,1,1,1,1,1,1,1,1,1,1
endlayer

layer
2,2,1,2,2,2,2,2,2,2,2
2,1,1,1,1,1,1,1,1,1,2
2,1,1,1,1,1,1,1,1,1,2
2,1,1,1,1,1,1,1,1,1,2
2,1,1,1,1,1,1,1,1,1,2
2,1,1,1,1,1,1,1,1,1,2
2,1,1,1,1,1,1,1,1,1,2
2,2,2,2,2,2,2,2,2,2,2
endlayer

layer
0,0,0,0,0,0,0,0,0,0,0
0,1,0,1,1,1,1,1,1,1,0
0,1,0,0,0,0,0,0,0,1,0
0,1,0,0,0,0,0,0,0,1,0
0,0,0,0,0,0,0,0,0,1,0
0,1,0,0,0,0,0,0,1,1,0
0,1,1,1,0,1,1,0,1,1,0
0,0,0,0,0,0,0,0,0,0,0
endlayer

layer
0,0,0,0,0,0,0,0,0,0,0
0,0,0,0,1,0,0,0,1,1,0
0,1,0,0,0,0,0,0,0,1,0
0,0,0,0,0,0,0,0,0,0,0
0,0,0,0,0,0,0,0,0,0,0
0,1,0,0,0,0,0,0,0,1,0
0,1,0,0,0,1,0,0,1,1,0
0,0,0,0,0,0,0,0,0,0,0
endlayer

layer
0,0,0,0,0,0,0,0,0,0,0
0,0,0,0,0,0,0,0,1,1,0
0,0,0,0,0,0,0,0,0,1,0
0,0,0,0,0,0,0,0,0,0,0
0,0,0,0,0,0,0,0,0,0,0
0,0,0,0,0,0,0,0,0,1,0
0,1,0,0,1,1,1,1,1,1,0
0,0,0,0,0,0,0,0,0,0,0
endlayer

layer
0,0,0,0,0,0,1,1,1,1,1
0,0,0,0,0,0,1,1,1,1,0
0,0,0,0,0,0,1,1,1,1,0
0,0,0,0,0,0,0,0,0,1,0
0,0,0,0,0,0,0,0,0,1,0
0,0,0,0,0,0,1,1,1,1,0
0,1,1,1,1,1,1,1,1,1,0
1,1,1,1,1,1,1,1,1,1,1
endlayer

layer
0,0,0,0,0,0,0,0,0,0,0
0,0,0,0,0,0,0,1,1,1,1
0,0,0,0,0,0,0,1,1,1,0
0,0,0,0,0,0,0,1,1,1,0
0,0,0,0,0,0,1,1,1,1,0
0,0,0,0,0,0,1,1,1,1,0
1,0,0,0,1,1,1,1,1,1,1
0,0,0,0,0,0,0,0,0,0,0
endlayer

layer
0,0,0,0,0,0,0,0,0,0,0
0,0,0,0,0,0,0,0,0,0,0
0,0,0,0,0,0,1,1,1,1,1
0,0,0,0,0,0,1,1,1,1,0
0,0,0,0,0,0,0,1,1,1,0
0,0,0,0,0,0,1,1,1,1,1
0,0,0,0,0,0,0,0,0,0,0
0,0,0,0,0,0,0,0,0,0,0
endlayer

layer
0,0,0,0,0,0,0,0,0,0,0
0,0,0,0,0,0,0,0,0,0,0
0,0,0,0,0,0,0,0,0,0,0
0,0,0,0,0,0,0,1,1,1,1
0,0,0,0,0,0,1,1,1,1,1
0,0,0,0,0,0,0,0,0,0,0
0,0,0,0,0,0,0,0,0,0,0
0,0,0,0,0,0,0,0,0,0,0
endlayer

