# Converted from schematic
# THIS TEMPLATE USES DEFAULTS!  Please edit for corrections.
# If you need help, consult template_rules.txt

weight=1
embed_into_distance=1
acceptable_target_blocks=1,2,3,12,13,79
dimensions=13,20,22
allowable_overhang=0
max_cut_in=2
cut_in_buffer=0
max_leveling=2
leveling_buffer=1
preserve_water=0
preserve_lava=0
preserve_plants=0


rule1=0,100,2
rule2=0,100,80
rule3=0,100,3
rule4=0,100,60-7
rule5=0,100,9
rule6=0,100,35-1
rule7=0,100,89
rule8=0,100,87
rule9=0,100,78
rule10=0,100,79
rule11=0,100,58
rule12=0,100,61-3
rule13=0,100,54-3
rule14=0,100,59-7
rule15=0,100,44
rule16=0,100,51-15
rule17=0,100,50-3
rule18=0,100,50-5


layer
1,1,1,1,1,1,1,1,1,2,2,2,2,2,2,1,1,1,1,1,1,1
1,1,1,1,1,1,1,2,2,2,2,2,2,2,2,2,2,1,1,1,1,1
1,1,1,1,1,3,2,2,2,2,2,2,2,2,2,2,2,2,3,1,1,1
1,1,1,1,3,2,2,8,2,2,6,6,6,6,2,2,2,2,2,3,1,1
1,1,1,1,2,2,2,8,2,2,6,6,6,6,2,2,2,2,2,2,1,1
1,1,1,2,2,2,2,2,2,2,2,2,2,2,2,2,2,2,2,2,2,1
1,1,1,2,2,2,2,2,2,2,2,2,2,2,2,2,2,2,2,2,2,1
1,1,2,2,2,2,2,2,2,2,2,2,2,2,2,2,2,2,2,2,2,2
2,2,2,2,2,2,2,2,2,2,2,2,2,2,2,2,2,2,2,2,2,2
2,2,2,2,2,2,2,2,2,2,2,7,7,2,2,2,2,2,2,2,2,2
2,2,2,2,2,2,2,2,2,2,2,7,7,2,2,2,2,2,2,2,2,2
2,2,2,2,2,2,2,2,2,2,2,2,2,2,2,2,2,2,2,2,2,2
1,1,2,2,2,2,2,2,2,2,2,2,2,2,2,2,2,2,2,2,2,2
1,1,1,2,2,2,2,2,2,2,2,2,2,2,2,2,2,2,2,2,2,1
1,1,1,2,2,2,2,4,4,4,4,4,4,4,4,4,4,2,2,2,2,1
1,1,1,1,2,2,2,4,4,4,4,4,4,4,4,4,4,2,2,2,1,1
1,1,1,1,3,2,2,4,4,4,4,4,4,4,4,4,4,2,2,3,1,1
1,1,1,1,1,3,2,5,5,5,5,5,5,5,5,5,5,2,3,1,1,1
1,1,1,1,1,1,1,2,2,2,2,2,2,2,2,2,2,1,1,1,1,1
1,1,1,1,1,1,1,1,1,2,2,2,2,2,2,1,1,1,1,1,1,1
endlayer

layer
9,9,9,9,9,9,9,9,9,2,2,10,10,2,2,9,9,9,9,9,9,9
9,9,9,9,9,9,9,2,2,2,2,0,0,2,2,2,2,9,9,9,9,9
9,9,9,9,9,2,2,15,15,0,0,0,0,0,0,0,11,2,2,9,9,9
9,9,9,9,2,2,2,16,15,0,0,0,0,0,0,0,12,2,2,2,9,9
9,9,9,9,2,2,2,16,15,0,0,0,0,0,0,0,0,2,2,2,9,9
9,9,9,2,2,2,2,15,15,0,0,0,0,0,0,0,13,2,2,2,2,9
9,9,9,2,2,2,2,2,2,2,2,0,0,2,2,2,2,2,2,2,2,9
9,9,2,2,2,2,2,2,2,0,0,0,0,2,2,2,2,2,2,2,2,2
2,2,2,2,2,2,2,2,0,0,0,0,0,0,0,0,0,0,0,2,2,2
0,0,0,0,0,0,0,0,0,0,0,0,0,0,0,0,0,0,0,0,0,10
0,0,0,0,0,0,0,0,0,0,0,0,0,0,0,0,0,0,0,0,0,10
2,2,2,2,2,2,2,2,0,0,0,0,0,0,0,0,0,0,0,2,2,2
9,9,2,2,2,2,2,2,2,0,0,0,0,2,2,2,2,2,2,2,2,2
9,9,9,2,2,2,2,2,2,2,2,0,0,2,2,2,2,2,2,2,2,9
9,9,9,2,2,2,0,14,14,14,14,14,14,14,14,14,14,0,2,2,2,9
9,9,9,9,2,2,0,14,14,14,14,14,14,14,14,14,14,0,2,2,9,9
9,9,9,9,2,2,0,14,14,14,14,14,14,14,14,14,14,0,2,2,9,9
9,9,9,9,9,2,2,0,0,0,0,0,0,0,0,0,0,2,2,9,9,9
9,9,9,9,9,9,9,2,2,2,2,0,0,2,2,2,2,9,9,9,9,9
9,9,9,9,9,9,9,9,9,2,2,10,10,2,2,9,9,9,9,9,9,9
endlayer

layer
0,0,0,0,0,0,0,0,0,2,2,10,10,2,2,0,0,0,0,0,0,0
0,0,0,0,0,0,0,2,2,2,2,0,0,2,2,2,2,0,0,0,0,0
0,0,0,0,0,2,2,0,0,0,0,0,0,0,0,0,0,2,2,0,0,0
0,0,0,0,2,2,2,0,0,0,0,0,0,0,0,0,0,2,2,2,0,0
0,0,0,0,2,2,2,0,0,0,0,0,0,0,0,0,0,2,2,2,0,0
0,0,0,2,2,2,2,0,0,0,0,0,0,0,0,0,0,2,2,2,2,0
0,0,0,2,2,2,2,2,2,2,2,0,0,2,2,2,2,2,2,2,2,0
0,0,2,2,2,2,2,2,2,0,0,0,0,0,0,0,0,0,0,0,2,2
2,2,2,2,2,2,2,2,0,0,0,0,0,0,0,0,0,0,0,2,2,2
0,0,0,0,0,0,0,0,0,0,0,0,0,0,0,0,0,0,0,0,0,10
0,0,0,0,0,0,0,0,0,0,0,0,0,0,0,0,0,0,0,0,0,10
2,2,2,2,2,2,2,2,0,0,0,0,0,0,0,0,0,0,0,2,2,2
0,0,2,2,2,2,2,2,2,0,0,0,0,0,0,0,0,0,0,0,2,2
0,0,0,2,2,2,2,2,2,2,2,0,0,2,2,2,2,2,2,2,2,0
0,0,0,2,2,2,0,0,0,0,0,0,0,0,0,0,0,0,2,2,2,0
0,0,0,0,2,7,0,0,0,0,0,0,0,0,0,0,0,0,7,2,0,0
0,0,0,0,2,2,0,0,0,0,0,0,0,0,0,0,0,0,2,2,0,0
0,0,0,0,0,2,2,0,0,0,0,0,0,0,0,0,0,2,2,0,0,0
0,0,0,0,0,0,0,2,2,2,2,0,0,2,2,2,2,0,0,0,0,0
0,0,0,0,0,0,0,0,0,2,2,10,10,2,2,0,0,0,0,0,0,0
endlayer

layer
0,0,0,0,0,0,0,0,0,2,2,2,2,2,2,0,0,0,0,0,0,0
0,0,0,0,0,0,0,2,2,2,2,2,2,2,2,2,2,0,0,0,0,0
0,0,0,0,0,9,2,0,0,0,0,0,0,0,0,0,0,2,9,0,0,0
0,0,0,0,9,2,2,0,0,0,0,0,0,0,0,0,17,2,2,9,0,0
0,0,0,0,2,2,2,0,0,0,0,0,0,0,0,0,17,2,2,2,0,0
0,0,0,2,2,2,2,0,0,0,0,0,0,0,0,0,0,2,2,2,2,0
0,0,0,2,2,2,2,2,2,2,2,2,2,2,2,2,2,2,2,2,2,0
0,0,2,2,2,2,2,2,2,0,0,0,0,0,0,0,0,0,0,0,2,2
2,2,2,2,2,2,2,2,0,0,0,0,0,0,0,0,0,0,0,2,2,2
2,2,2,2,2,2,2,2,0,0,0,0,0,0,0,0,0,0,0,2,2,2
2,2,2,2,2,2,2,2,0,0,0,0,0,0,0,0,0,0,0,2,2,2
2,2,2,2,2,2,2,2,0,0,0,0,0,0,0,0,0,0,0,2,2,2
0,0,2,2,2,2,2,2,2,0,0,0,0,0,0,0,0,0,0,0,2,2
0,0,0,2,2,2,2,2,2,2,2,2,2,2,2,2,2,2,2,2,2,0
0,0,0,2,2,2,0,0,0,0,0,0,0,0,0,0,0,0,2,2,2,0
0,0,0,0,2,7,0,0,0,0,0,0,0,0,0,0,0,0,7,2,0,0
0,0,0,0,9,2,0,0,0,0,0,0,0,0,0,0,0,0,2,9,0,0
0,0,0,0,0,9,2,0,0,0,0,0,0,0,0,0,0,2,9,0,0,0
0,0,0,0,0,0,0,2,2,2,2,2,2,2,2,2,2,0,0,0,0,0
0,0,0,0,0,0,0,0,0,2,2,2,2,2,2,0,0,0,0,0,0,0
endlayer

layer
0,0,0,0,0,0,0,0,0,9,2,2,2,2,9,0,0,0,0,0,0,0
0,0,0,0,0,0,0,2,2,2,2,2,2,2,2,2,2,0,0,0,0,0
0,0,0,0,0,0,2,2,2,2,2,2,2,2,2,2,2,2,0,0,0,0
0,0,0,0,0,2,2,2,2,2,2,2,2,2,2,2,2,2,2,0,0,0
0,0,0,0,2,2,2,2,2,2,2,2,2,2,2,2,2,2,2,2,0,0
0,0,0,2,2,2,2,2,2,2,2,2,2,2,2,2,2,2,2,2,2,0
0,0,0,2,2,2,2,2,2,2,2,2,2,2,2,2,2,2,2,2,2,0
0,0,9,2,2,2,2,2,2,0,0,0,0,0,0,0,0,0,0,0,2,9
0,9,2,2,2,2,2,2,2,0,0,0,0,0,0,0,0,0,0,18,2,2
0,9,2,2,2,2,2,2,2,0,0,0,0,0,0,0,0,0,0,2,2,2
0,9,2,2,2,2,2,2,2,0,0,0,0,0,0,0,0,0,0,2,2,2
0,9,2,2,2,2,2,2,2,0,0,0,0,0,0,0,0,0,0,18,2,2
0,0,9,2,2,2,2,2,2,0,0,0,0,0,0,0,0,0,0,0,2,9
0,0,0,2,2,2,2,2,2,2,2,2,2,2,2,2,2,2,2,2,2,0
0,0,0,2,2,2,0,0,0,0,0,0,0,0,0,0,0,0,2,2,2,0
0,0,0,0,2,2,0,0,0,0,0,0,0,0,0,0,0,0,2,2,0,0
0,0,0,0,0,2,0,0,0,0,0,0,0,0,0,0,0,0,2,0,0,0
0,0,0,0,0,0,2,0,0,0,0,0,0,0,0,0,0,2,0,0,0,0
0,0,0,0,0,0,0,2,2,2,2,2,2,2,2,2,2,0,0,0,0,0
0,0,0,0,0,0,0,0,0,9,2,2,2,2,9,0,0,0,0,0,0,0
endlayer

layer
0,0,0,0,0,0,0,0,0,0,9,9,9,9,0,0,0,0,0,0,0,0
0,0,0,0,0,0,0,9,2,2,2,2,2,2,2,2,9,0,0,0,0,0
0,0,0,0,0,0,2,2,2,2,2,2,2,2,2,2,2,2,0,0,0,0
0,0,0,0,0,2,2,2,2,2,2,2,2,2,2,2,2,2,2,0,0,0
0,0,0,0,2,2,2,2,2,2,2,2,2,2,2,2,2,2,2,2,0,0
0,0,0,9,2,2,2,2,2,2,2,2,2,2,2,2,2,2,2,2,9,0
0,0,0,2,2,2,2,2,2,2,2,2,2,2,2,2,2,2,2,2,2,0
0,0,0,2,2,2,2,2,2,2,2,2,2,2,2,2,2,2,2,2,2,0
0,0,9,2,2,2,2,2,2,2,2,2,2,2,2,2,2,2,2,2,2,9
0,0,9,2,2,2,2,2,2,2,2,0,0,2,2,2,2,2,2,2,2,9
0,0,9,2,2,2,2,2,2,2,2,0,0,2,2,2,2,2,2,2,2,9
0,0,9,2,2,2,2,2,2,2,2,2,2,2,2,2,2,2,2,2,2,9
0,0,0,2,2,2,2,2,2,2,2,2,2,2,2,2,2,2,2,2,2,0
0,0,0,2,2,2,2,2,2,2,2,2,2,2,2,2,2,2,2,2,2,0
0,0,0,9,2,2,2,2,2,2,2,2,2,2,2,2,2,2,2,2,9,0
0,0,0,0,2,2,2,2,2,2,2,2,2,2,2,2,2,2,2,2,0,0
0,0,0,0,0,2,2,2,2,2,2,2,2,2,2,2,2,2,2,0,0,0
0,0,0,0,0,0,2,2,2,2,2,2,2,2,2,2,2,2,0,0,0,0
0,0,0,0,0,0,0,9,2,2,2,2,2,2,2,2,9,0,0,0,0,0
0,0,0,0,0,0,0,0,0,0,9,9,9,9,0,0,0,0,0,0,0,0
endlayer

layer
0,0,0,0,0,0,0,0,0,0,0,0,0,0,0,0,0,0,0,0,0,0
0,0,0,0,0,0,0,0,9,2,2,2,2,2,2,9,0,0,0,0,0,0
0,0,0,0,0,0,9,2,2,2,2,2,2,2,2,2,2,9,0,0,0,0
0,0,0,0,0,9,2,2,2,2,2,2,2,2,2,2,2,2,9,0,0,0
0,0,0,0,9,2,2,2,2,2,2,2,2,2,2,2,2,2,2,9,0,0
0,0,0,0,2,2,2,2,2,2,2,2,2,2,2,2,2,2,2,2,0,0
0,0,0,9,2,2,2,2,2,2,2,2,2,2,2,2,2,2,2,2,9,0
0,0,0,2,2,2,2,2,2,2,2,2,2,2,2,2,2,2,2,2,2,0
0,0,0,2,2,2,2,2,2,2,2,2,2,2,2,2,2,2,2,2,2,0
0,0,0,2,2,2,2,2,2,2,2,0,0,2,2,2,2,2,2,2,2,0
0,0,0,2,2,2,2,2,2,2,2,0,0,2,2,2,2,2,2,2,2,0
0,0,0,2,2,2,2,2,2,2,2,2,2,2,2,2,2,2,2,2,2,0
0,0,0,2,2,2,2,2,2,2,2,2,2,2,2,2,2,2,2,2,2,0
0,0,0,9,2,2,2,2,2,2,2,2,2,2,2,2,2,2,2,2,9,0
0,0,0,0,2,2,2,2,2,2,2,2,2,2,2,2,2,2,2,2,0,0
0,0,0,0,9,2,2,2,2,2,2,2,2,2,2,2,2,2,2,9,0,0
0,0,0,0,0,9,2,2,2,2,2,2,2,2,2,2,2,2,9,0,0,0
0,0,0,0,0,0,9,2,2,2,2,2,2,2,2,2,2,9,0,0,0,0
0,0,0,0,0,0,0,0,9,2,2,2,2,2,2,9,0,0,0,0,0,0
0,0,0,0,0,0,0,0,0,0,0,0,0,0,0,0,0,0,0,0,0,0
endlayer

layer
0,0,0,0,0,0,0,0,0,0,0,0,0,0,0,0,0,0,0,0,0,0
0,0,0,0,0,0,0,0,0,9,9,9,9,9,9,0,0,0,0,0,0,0
0,0,0,0,0,0,0,9,2,2,2,2,2,2,2,2,9,0,0,0,0,0
0,0,0,0,0,0,9,2,2,2,2,2,2,2,2,2,2,9,0,0,0,0
0,0,0,0,0,9,2,2,2,2,2,2,2,2,2,2,2,2,9,0,0,0
0,0,0,0,9,2,2,2,2,2,2,2,2,2,2,2,2,2,2,9,0,0
0,0,0,0,2,2,2,2,2,2,2,2,2,2,2,2,2,2,2,2,0,0
0,0,0,9,2,2,2,2,2,2,2,2,2,2,2,2,2,2,2,2,9,0
0,0,0,9,2,2,2,2,2,2,2,2,2,2,2,2,2,2,2,2,9,0
0,0,0,9,2,2,2,2,2,2,2,0,0,2,2,2,2,2,2,2,9,0
0,0,0,9,2,2,2,2,2,2,2,0,0,2,2,2,2,2,2,2,9,0
0,0,0,9,2,2,2,2,2,2,2,2,2,2,2,2,2,2,2,2,9,0
0,0,0,9,2,2,2,2,2,2,2,2,2,2,2,2,2,2,2,2,9,0
0,0,0,0,2,2,2,2,2,2,2,2,2,2,2,2,2,2,2,2,0,0
0,0,0,0,9,2,2,2,2,2,2,2,2,2,2,2,2,2,2,9,0,0
0,0,0,0,0,9,2,2,2,2,2,2,2,2,2,2,2,2,9,0,0,0
0,0,0,0,0,0,9,2,2,2,2,2,2,2,2,2,2,9,0,0,0,0
0,0,0,0,0,0,0,9,2,2,2,2,2,2,2,2,9,0,0,0,0,0
0,0,0,0,0,0,0,0,0,9,9,9,9,9,9,0,0,0,0,0,0,0
0,0,0,0,0,0,0,0,0,0,0,0,0,0,0,0,0,0,0,0,0,0
endlayer

layer
0,0,0,0,0,0,0,0,0,0,0,0,0,0,0,0,0,0,0,0,0,0
0,0,0,0,0,0,0,0,0,0,0,0,0,0,0,0,0,0,0,0,0,0
0,0,0,0,0,0,0,0,9,9,9,2,2,9,9,9,0,0,0,0,0,0
0,0,0,0,0,0,0,9,2,2,2,2,2,2,2,2,9,0,0,0,0,0
0,0,0,0,0,0,9,2,2,2,2,2,2,2,2,2,2,9,0,0,0,0
0,0,0,0,0,9,2,2,2,2,2,2,2,2,2,2,2,2,9,0,0,0
0,0,0,0,9,2,2,2,2,2,2,2,2,2,2,2,2,2,2,9,0,0
0,0,0,0,9,2,2,2,2,2,2,2,2,2,2,2,2,2,2,9,0,0
0,0,0,0,9,2,2,2,2,2,2,2,2,2,2,2,2,2,2,9,0,0
0,0,0,0,2,2,2,2,2,2,2,0,0,2,2,2,2,2,2,2,0,0
0,0,0,0,2,2,2,2,2,2,2,0,0,2,2,2,2,2,2,2,0,0
0,0,0,0,9,2,2,2,2,2,2,2,2,2,2,2,2,2,2,9,0,0
0,0,0,0,9,2,2,2,2,2,2,2,2,2,2,2,2,2,2,9,0,0
0,0,0,0,9,2,2,2,2,2,2,2,2,2,2,2,2,2,2,9,0,0
0,0,0,0,0,9,2,2,2,2,2,2,2,2,2,2,2,2,9,0,0,0
0,0,0,0,0,0,9,2,2,2,2,2,2,2,2,2,2,9,0,0,0,0
0,0,0,0,0,0,0,9,2,2,2,2,2,2,2,2,9,0,0,0,0,0
0,0,0,0,0,0,0,0,9,9,9,2,2,9,9,9,0,0,0,0,0,0
0,0,0,0,0,0,0,0,0,0,0,0,0,0,0,0,0,0,0,0,0,0
0,0,0,0,0,0,0,0,0,0,0,0,0,0,0,0,0,0,0,0,0,0
endlayer

layer
0,0,0,0,0,0,0,0,0,0,0,0,0,0,0,0,0,0,0,0,0,0
0,0,0,0,0,0,0,0,0,0,0,0,0,0,0,0,0,0,0,0,0,0
0,0,0,0,0,0,0,0,0,0,0,9,9,0,0,0,0,0,0,0,0,0
0,0,0,0,0,0,0,0,9,9,9,2,2,9,9,9,0,0,0,0,0,0
0,0,0,0,0,0,0,9,2,2,2,2,2,2,2,2,9,0,0,0,0,0
0,0,0,0,0,0,9,2,2,2,2,2,2,2,2,2,2,9,0,0,0,0
0,0,0,0,0,9,2,2,2,2,2,2,2,2,2,2,2,2,9,0,0,0
0,0,0,0,0,9,2,2,2,2,2,2,2,2,2,2,2,2,9,0,0,0
0,0,0,0,0,9,2,2,2,2,2,2,2,2,2,2,2,2,9,0,0,0
0,0,0,0,9,2,2,2,2,2,2,0,0,2,2,2,2,2,2,9,0,0
0,0,0,0,9,2,2,2,2,2,2,0,0,2,2,2,2,2,2,9,0,0
0,0,0,0,0,9,2,2,2,2,2,2,2,2,2,2,2,2,9,0,0,0
0,0,0,0,0,9,2,2,2,2,2,2,2,2,2,2,2,2,9,0,0,0
0,0,0,0,0,9,2,2,2,2,2,2,2,2,2,2,2,2,9,0,0,0
0,0,0,0,0,0,9,2,2,2,2,2,2,2,2,2,2,9,0,0,0,0
0,0,0,0,0,0,0,9,2,2,2,2,2,2,2,2,9,0,0,0,0,0
0,0,0,0,0,0,0,0,9,9,9,2,2,9,9,9,0,0,0,0,0,0
0,0,0,0,0,0,0,0,0,0,0,9,9,0,0,0,0,0,0,0,0,0
0,0,0,0,0,0,0,0,0,0,0,0,0,0,0,0,0,0,0,0,0,0
0,0,0,0,0,0,0,0,0,0,0,0,0,0,0,0,0,0,0,0,0,0
endlayer

layer
0,0,0,0,0,0,0,0,0,0,0,0,0,0,0,0,0,0,0,0,0,0
0,0,0,0,0,0,0,0,0,0,0,0,0,0,0,0,0,0,0,0,0,0
0,0,0,0,0,0,0,0,0,0,0,0,0,0,0,0,0,0,0,0,0,0
0,0,0,0,0,0,0,0,0,0,0,9,9,0,0,0,0,0,0,0,0,0
0,0,0,0,0,0,0,0,9,9,9,9,9,9,9,9,0,0,0,0,0,0
0,0,0,0,0,0,0,9,9,2,2,2,2,2,2,9,9,0,0,0,0,0
0,0,0,0,0,0,9,9,2,2,2,2,2,2,2,2,9,9,0,0,0,0
0,0,0,0,0,0,9,2,2,2,2,2,2,2,2,2,2,9,0,0,0,0
0,0,0,0,0,0,9,2,2,2,2,2,2,2,2,2,2,9,0,0,0,0
0,0,0,0,0,9,9,2,2,2,2,0,0,2,2,2,2,9,9,0,0,0
0,0,0,0,0,9,9,2,2,2,2,0,0,2,2,2,2,9,9,0,0,0
0,0,0,0,0,0,9,2,2,2,2,2,2,2,2,2,2,9,0,0,0,0
0,0,0,0,0,0,9,2,2,2,2,2,2,2,2,2,2,9,0,0,0,0
0,0,0,0,0,0,9,9,2,2,2,2,2,2,2,2,9,9,0,0,0,0
0,0,0,0,0,0,0,0,9,2,2,2,2,2,2,9,9,0,0,0,0,0
0,0,0,0,0,0,0,0,9,9,9,9,9,9,9,9,0,0,0,0,0,0
0,0,0,0,0,0,0,0,0,0,0,9,9,0,0,0,0,0,0,0,0,0
0,0,0,0,0,0,0,0,0,0,0,0,0,0,0,0,0,0,0,0,0,0
0,0,0,0,0,0,0,0,0,0,0,0,0,0,0,0,0,0,0,0,0,0
0,0,0,0,0,0,0,0,0,0,0,0,0,0,0,0,0,0,0,0,0,0
endlayer

layer
0,0,0,0,0,0,0,0,0,0,0,0,0,0,0,0,0,0,0,0,0,0
0,0,0,0,0,0,0,0,0,0,0,0,0,0,0,0,0,0,0,0,0,0
0,0,0,0,0,0,0,0,0,0,0,0,0,0,0,0,0,0,0,0,0,0
0,0,0,0,0,0,0,0,0,0,0,0,0,0,0,0,0,0,0,0,0,0
0,0,0,0,0,0,0,0,0,0,0,0,0,0,0,0,0,0,0,0,0,0
0,0,0,0,0,0,0,0,0,9,9,9,9,9,9,0,0,0,0,0,0,0
0,0,0,0,0,0,0,0,9,9,9,9,9,9,9,9,0,0,0,0,0,0
0,0,0,0,0,0,0,9,9,9,2,2,2,2,9,9,9,0,0,0,0,0
0,0,0,0,0,0,0,9,9,2,2,2,2,2,2,9,9,0,0,0,0,0
0,0,0,0,0,0,0,9,9,2,2,10,10,2,2,9,9,0,0,0,0,0
0,0,0,0,0,0,0,9,9,2,2,10,10,2,2,9,9,0,0,0,0,0
0,0,0,0,0,0,0,9,9,2,2,2,2,2,2,9,9,0,0,0,0,0
0,0,0,0,0,0,0,9,9,9,2,2,2,2,9,9,9,0,0,0,0,0
0,0,0,0,0,0,0,0,9,9,9,9,9,9,9,9,0,0,0,0,0,0
0,0,0,0,0,0,0,0,0,9,9,9,9,9,9,0,0,0,0,0,0,0
0,0,0,0,0,0,0,0,0,0,0,0,0,0,0,0,0,0,0,0,0,0
0,0,0,0,0,0,0,0,0,0,0,0,0,0,0,0,0,0,0,0,0,0
0,0,0,0,0,0,0,0,0,0,0,0,0,0,0,0,0,0,0,0,0,0
0,0,0,0,0,0,0,0,0,0,0,0,0,0,0,0,0,0,0,0,0,0
0,0,0,0,0,0,0,0,0,0,0,0,0,0,0,0,0,0,0,0,0,0
endlayer

layer
0,0,0,0,0,0,0,0,0,0,0,0,0,0,0,0,0,0,0,0,0,0
0,0,0,0,0,0,0,0,0,0,0,0,0,0,0,0,0,0,0,0,0,0
0,0,0,0,0,0,0,0,0,0,0,0,0,0,0,0,0,0,0,0,0,0
0,0,0,0,0,0,0,0,0,0,0,0,0,0,0,0,0,0,0,0,0,0
0,0,0,0,0,0,0,0,0,0,0,0,0,0,0,0,0,0,0,0,0,0
0,0,0,0,0,0,0,0,0,0,0,0,0,0,0,0,0,0,0,0,0,0
0,0,0,0,0,0,0,0,0,0,0,0,0,0,0,0,0,0,0,0,0,0
0,0,0,0,0,0,0,0,0,0,9,9,9,9,0,0,0,0,0,0,0,0
0,0,0,0,0,0,0,0,0,9,9,9,9,9,9,0,0,0,0,0,0,0
0,0,0,0,0,0,0,0,0,9,9,0,0,9,9,0,0,0,0,0,0,0
0,0,0,0,0,0,0,0,0,9,9,0,0,9,9,0,0,0,0,0,0,0
0,0,0,0,0,0,0,0,0,9,9,9,9,9,9,0,0,0,0,0,0,0
0,0,0,0,0,0,0,0,0,0,9,9,9,9,0,0,0,0,0,0,0,0
0,0,0,0,0,0,0,0,0,0,0,0,0,0,0,0,0,0,0,0,0,0
0,0,0,0,0,0,0,0,0,0,0,0,0,0,0,0,0,0,0,0,0,0
0,0,0,0,0,0,0,0,0,0,0,0,0,0,0,0,0,0,0,0,0,0
0,0,0,0,0,0,0,0,0,0,0,0,0,0,0,0,0,0,0,0,0,0
0,0,0,0,0,0,0,0,0,0,0,0,0,0,0,0,0,0,0,0,0,0
0,0,0,0,0,0,0,0,0,0,0,0,0,0,0,0,0,0,0,0,0,0
0,0,0,0,0,0,0,0,0,0,0,0,0,0,0,0,0,0,0,0,0,0
endlayer

