# Converted from schematic
# THIS TEMPLATE USES DEFAULTS!  Please edit for corrections.
# If you need help, consult template_rules.txt

weight=2
embed_into_distance=6
acceptable_target_blocks=1,2,3,12,13,24
dimensions=9,24,13
allowable_overhang=0
max_cut_in=2
cut_in_buffer=1
max_leveling=2
leveling_buffer=1
preserve_water=0
preserve_lava=0
preserve_plants=0


rule1=0,100,12
rule2=0,100,24-2
rule3=0,100,24
rule4=0,100,35-1
rule5=0,100,87
rule6=0,100,35-11
rule7=0,100,44-1
rule8=0,100,24-1
rule9=0,100,51-15
rule10=0,100,43-1
rule11=0,100,50-1
rule12=0,100,50-2
rule13=0,100,89


layer
1,1,1,1,1,1,1,1,1,1,1,1,1
1,1,1,1,1,1,1,1,1,1,1,1,1
1,1,1,1,1,1,1,1,1,1,1,1,1
1,1,1,1,1,1,1,1,1,1,1,1,1
1,1,1,1,1,1,1,1,1,1,1,1,1
1,1,1,1,1,1,1,1,1,1,1,1,1
1,1,1,1,1,1,1,1,1,1,1,1,1
1,1,1,1,1,1,1,1,1,1,1,1,1
1,1,1,1,1,1,1,1,1,1,1,1,1
1,1,1,1,1,1,1,1,1,1,1,1,1
1,1,1,1,1,1,1,1,1,1,1,1,1
1,1,1,1,1,1,1,1,1,1,1,1,1
1,1,1,1,1,1,1,1,1,1,1,1,1
1,1,1,1,1,1,1,1,1,1,1,1,1
1,1,1,1,1,1,1,1,1,1,1,1,1
1,1,1,1,1,1,1,1,1,1,1,1,1
1,1,1,1,1,1,1,1,1,1,1,1,1
1,1,1,1,1,1,1,1,1,1,1,1,1
1,1,1,1,1,1,1,1,1,1,1,1,1
1,1,1,1,1,1,1,1,1,1,1,1,1
1,1,1,1,1,1,1,1,1,1,1,1,1
1,1,1,1,1,1,1,1,1,1,1,1,1
1,1,1,1,1,1,1,1,1,1,1,1,1
1,1,1,1,1,1,1,1,1,1,1,1,1
endlayer

layer
1,1,1,1,3,3,3,3,3,1,1,1,1
1,1,1,2,3,3,3,3,3,3,1,1,1
1,1,1,2,3,3,3,3,3,2,1,1,1
1,1,2,3,3,3,3,3,3,3,2,1,1
1,2,3,3,3,3,3,3,3,3,3,2,1
2,3,3,3,3,3,3,3,3,3,3,3,2
2,3,3,3,3,3,3,3,3,3,3,3,2
2,2,3,3,3,3,3,3,3,3,3,2,2
2,2,2,3,3,4,3,4,3,3,2,0,2
2,2,2,2,3,3,6,3,3,2,0,0,2
2,2,2,3,3,4,3,4,3,3,2,0,2
2,2,3,3,3,3,3,3,3,3,3,2,2
2,3,3,3,3,3,3,3,3,3,3,3,2
2,3,3,3,3,3,3,3,3,3,3,3,2
1,2,3,3,3,3,3,3,3,3,3,2,1
1,1,2,3,3,3,3,3,3,3,2,1,1
1,1,1,2,3,3,3,3,3,2,1,1,1
1,1,1,2,3,3,3,3,3,2,1,1,1
1,1,1,1,2,5,3,5,3,1,1,1,1
1,1,1,1,1,3,3,3,1,1,1,1,1
1,1,1,1,1,3,3,3,1,1,1,1,1
1,1,1,1,1,3,3,3,1,1,1,1,1
1,1,1,1,1,1,1,1,1,1,1,1,1
1,1,1,1,1,1,1,1,1,1,1,1,1
endlayer

layer
1,1,1,1,8,2,3,2,8,1,1,1,1
1,1,1,2,0,0,8,0,0,2,1,1,1
1,1,1,2,0,0,0,0,0,2,1,1,1
1,1,2,2,0,0,0,0,0,2,2,1,1
1,2,0,0,8,0,0,0,8,0,0,2,1
2,2,7,0,0,0,0,0,0,0,7,2,2
2,2,7,0,0,0,0,0,0,0,7,2,2
2,2,0,0,8,0,0,0,8,0,0,2,2
2,2,2,2,0,0,0,0,0,2,2,0,2
2,2,2,2,0,0,0,0,0,0,0,0,2
2,2,2,2,0,0,0,0,0,2,2,0,2
2,2,0,0,8,0,0,0,8,0,0,2,2
2,2,7,0,0,0,0,0,0,0,7,2,2
2,2,7,0,0,0,0,0,0,0,7,2,2
1,2,0,0,8,0,7,0,8,0,0,2,1
1,1,2,2,0,0,10,0,0,2,2,1,1
1,1,1,2,0,0,10,0,0,2,1,1,1
1,1,1,2,0,0,10,0,0,2,1,1,1
1,1,1,1,8,9,10,9,8,1,1,1,1
1,1,1,1,1,2,10,2,1,1,1,1,1
1,1,1,1,1,2,3,2,1,1,1,1,1
1,1,1,1,1,8,3,8,1,1,1,1,1
1,1,1,1,1,1,1,1,1,1,1,1,1
1,1,1,1,1,1,1,1,1,1,1,1,1
endlayer

layer
1,1,1,1,8,2,3,2,8,1,1,1,1
1,1,1,2,0,0,13,0,0,2,1,1,1
1,1,1,2,0,0,0,0,0,2,1,1,1
1,1,2,2,0,0,0,0,0,2,2,1,1
1,2,11,0,8,0,0,0,8,0,11,2,1
2,0,0,0,0,0,0,0,0,0,0,0,2
2,0,0,0,0,0,0,0,0,0,0,0,2
2,2,12,0,8,0,0,0,8,0,12,2,2
2,2,2,2,0,0,0,0,0,2,2,0,2
2,2,2,2,0,0,0,0,0,0,0,0,2
2,2,2,2,0,0,0,0,0,2,2,0,2
2,2,11,0,8,0,0,0,8,0,11,2,2
2,0,0,0,0,0,0,0,0,0,0,0,2
2,0,0,0,0,0,0,0,0,0,0,0,2
1,2,12,0,8,0,0,0,8,0,0,2,1
1,1,2,2,0,0,0,0,0,2,2,1,1
1,1,1,2,0,0,7,0,0,2,1,1,1
1,1,1,2,0,0,10,0,0,2,1,1,1
1,1,1,1,8,0,10,0,8,1,1,1,1
1,1,1,1,1,2,10,2,1,1,1,1,1
1,1,1,1,1,2,10,2,1,1,1,1,1
1,1,1,1,1,8,10,8,1,1,1,1,1
1,1,1,1,1,1,1,1,1,1,1,1,1
1,1,1,1,1,1,1,1,1,1,1,1,1
endlayer

layer
1,1,1,1,2,2,2,2,2,1,1,1,1
1,1,1,2,2,2,2,2,2,2,1,1,1
1,1,1,2,2,2,2,2,2,2,1,1,1
1,1,1,2,2,2,2,2,2,2,1,1,1
1,2,2,2,2,2,2,2,2,2,2,2,1
1,2,2,2,2,2,2,2,2,2,2,2,1
1,2,2,2,2,2,2,2,2,2,2,2,1
1,2,2,2,2,2,2,2,2,2,2,2,1
1,2,2,2,2,2,2,2,2,2,2,2,1
1,2,2,2,2,2,13,2,2,2,2,2,1
1,2,2,2,2,2,2,2,2,2,2,2,1
1,2,2,2,2,2,2,2,2,2,2,2,1
1,2,2,2,2,2,2,2,2,2,2,2,1
1,2,2,2,2,2,0,2,2,2,2,2,1
1,2,2,2,2,2,0,2,2,2,2,2,1
1,1,2,2,2,2,0,2,2,2,2,1,1
1,1,2,2,2,2,0,2,2,2,2,1,1
1,1,2,2,2,2,0,2,2,2,2,1,1
1,1,2,2,2,2,7,2,2,2,2,1,1
1,1,2,2,2,2,10,2,2,2,2,1,1
1,1,2,2,2,2,10,2,2,2,2,1,1
1,1,2,2,2,8,10,8,2,2,2,1,1
1,1,2,2,2,1,1,1,2,2,2,1,1
1,1,2,2,2,1,1,1,2,2,2,1,1
endlayer

layer
1,1,1,1,1,1,1,1,1,1,1,1,1
1,1,1,1,1,1,1,1,1,1,1,1,1
1,1,1,1,1,1,1,1,1,1,1,1,1
1,1,1,1,1,1,1,1,1,1,1,1,1
1,1,1,1,1,1,1,1,1,1,1,1,1
1,1,1,1,1,1,1,1,1,1,1,1,1
1,1,1,1,1,1,1,1,1,1,1,1,1
1,1,1,1,1,1,1,1,1,1,1,1,1
1,1,1,1,1,1,1,1,1,1,1,1,1
1,1,1,1,1,1,1,1,1,1,1,1,1
1,1,1,1,1,1,1,1,1,1,1,1,1
1,1,1,1,1,1,1,1,1,1,1,1,1
1,1,1,1,1,1,1,1,1,1,1,1,1
1,1,1,1,1,1,2,1,1,1,1,1,1
1,1,1,1,1,1,2,1,1,1,1,1,1
1,1,2,2,2,2,0,2,2,2,2,1,1
1,1,2,2,2,2,0,2,2,2,2,1,1
1,1,2,2,2,3,0,3,2,2,2,1,1
1,1,2,2,2,3,0,3,2,2,2,1,1
1,1,2,2,2,3,0,3,2,2,2,1,1
1,1,2,2,2,3,7,3,2,2,2,1,1
1,1,2,2,2,8,10,8,2,2,2,1,1
1,1,2,2,2,1,1,1,2,2,2,1,1
1,1,2,2,2,1,1,1,2,2,2,1,1
endlayer

layer
0,0,0,0,0,0,0,0,0,0,0,0,0
0,0,0,0,0,0,0,0,0,0,0,0,0
0,0,0,0,0,0,0,0,0,0,0,0,0
0,0,0,0,0,0,0,0,0,0,0,0,0
0,0,0,0,0,0,0,0,0,0,0,0,0
0,0,0,0,0,0,0,0,0,0,0,0,0
0,0,0,0,0,0,0,0,0,0,0,0,0
0,0,0,0,0,0,0,0,0,0,0,0,0
0,0,0,0,0,0,0,0,0,0,0,0,0
0,0,0,0,0,0,0,0,0,0,0,0,0
0,0,0,0,0,0,0,0,0,0,0,0,0
0,0,0,0,0,0,0,0,0,0,0,0,0
0,0,0,0,0,0,0,0,0,0,0,0,0
0,0,0,0,0,0,0,0,0,0,0,0,0
0,0,0,0,0,0,0,0,0,0,0,0,0
0,0,0,2,2,2,2,2,2,2,0,0,0
0,0,0,2,2,2,2,2,2,2,0,0,0
0,0,0,2,2,2,0,2,2,2,0,0,0
0,0,0,2,2,2,0,2,2,2,0,0,0
0,0,0,2,2,2,0,2,2,2,0,0,0
0,0,0,2,2,2,0,2,2,2,0,0,0
0,0,0,2,2,8,0,8,2,2,0,0,0
0,0,0,2,2,0,0,0,2,2,0,0,0
0,0,0,0,0,0,0,0,0,0,0,0,0
endlayer

layer
0,0,0,0,0,0,0,0,0,0,0,0,0
0,0,0,0,0,0,0,0,0,0,0,0,0
0,0,0,0,0,0,0,0,0,0,0,0,0
0,0,0,0,0,0,0,0,0,0,0,0,0
0,0,0,0,0,0,0,0,0,0,0,0,0
0,0,0,0,0,0,0,0,0,0,0,0,0
0,0,0,0,0,0,0,0,0,0,0,0,0
0,0,0,0,0,0,0,0,0,0,0,0,0
0,0,0,0,0,0,0,0,0,0,0,0,0
0,0,0,0,0,0,0,0,0,0,0,0,0
0,0,0,0,0,0,0,0,0,0,0,0,0
0,0,0,0,0,0,0,0,0,0,0,0,0
0,0,0,0,0,0,0,0,0,0,0,0,0
0,0,0,0,0,0,0,0,0,0,0,0,0
0,0,0,0,0,0,0,0,0,0,0,0,0
0,0,0,0,0,0,0,0,0,0,0,0,0
0,0,0,0,2,2,2,2,2,0,0,0,0
0,0,0,0,2,2,2,2,2,0,0,0,0
0,0,0,0,2,2,2,2,2,0,0,0,0
0,0,0,0,2,2,0,2,2,0,0,0,0
0,0,0,0,2,2,0,2,2,0,0,0,0
0,0,0,0,2,8,0,8,2,0,0,0,0
0,0,0,0,0,0,0,0,0,0,0,0,0
0,0,0,0,0,0,0,0,0,0,0,0,0
endlayer

layer
0,0,0,0,0,0,0,0,0,0,0,0,0
0,0,0,0,0,0,0,0,0,0,0,0,0
0,0,0,0,0,0,0,0,0,0,0,0,0
0,0,0,0,0,0,0,0,0,0,0,0,0
0,0,0,0,0,0,0,0,0,0,0,0,0
0,0,0,0,0,0,0,0,0,0,0,0,0
0,0,0,0,0,0,0,0,0,0,0,0,0
0,0,0,0,0,0,0,0,0,0,0,0,0
0,0,0,0,0,0,0,0,0,0,0,0,0
0,0,0,0,0,0,0,0,0,0,0,0,0
0,0,0,0,0,0,0,0,0,0,0,0,0
0,0,0,0,0,0,0,0,0,0,0,0,0
0,0,0,0,0,0,0,0,0,0,0,0,0
0,0,0,0,0,0,0,0,0,0,0,0,0
0,0,0,0,0,0,0,0,0,0,0,0,0
0,0,0,0,0,0,0,0,0,0,0,0,0
0,0,0,0,0,0,0,0,0,0,0,0,0
0,0,0,0,0,2,2,2,0,0,0,0,0
0,0,0,0,0,2,2,2,0,0,0,0,0
0,0,0,0,0,2,2,2,0,0,0,0,0
0,0,0,0,0,2,2,2,0,0,0,0,0
0,0,0,0,0,0,2,0,0,0,0,0,0
0,0,0,0,0,0,2,0,0,0,0,0,0
0,0,0,0,0,0,0,0,0,0,0,0,0
endlayer

