# Converted from schematic
# THIS TEMPLATE USES DEFAULTS!  Please edit for corrections.
# If you need help, consult template_rules.txt

weight=2
embed_into_distance=1
acceptable_target_blocks=1,2,3,12,13
dimensions=8,10,13
allowable_overhang=0
max_cut_in=2
cut_in_buffer=1
max_leveling=2
leveling_buffer=1
preserve_water=0
preserve_lava=0
preserve_plants=0


rule1=0,100,24
rule2=0,100,35-14
rule3=0,100,128-1
rule4=0,100,61-4
rule5=0,100,54-4
rule6=0,100,64
rule7=0,100,24-2
rule8=0,100,58
rule9=0,100,102
rule10=0,100,20
rule11=0,100,64-8
rule12=0,100,50-1
rule13=0,100,50-3
rule14=0,100,50-4


layer
1,1,1,1,1,1,1,1,1,1,1,1,1
1,1,1,1,1,1,1,1,1,1,1,1,1
1,1,1,1,1,1,1,1,1,1,1,1,1
1,1,1,1,1,1,1,1,1,1,1,1,1
1,1,1,1,1,1,1,1,1,1,1,1,1
1,1,1,1,1,1,1,1,1,1,1,1,1
1,1,1,1,1,1,1,1,1,1,1,1,1
1,1,1,1,1,1,1,1,1,1,1,1,1
1,1,1,1,1,1,1,1,1,1,1,1,1
1,1,1,1,1,1,1,1,1,1,1,1,1
endlayer

layer
0,0,0,0,0,0,0,0,0,0,0,0,0
0,1,1,1,0,0,0,0,0,1,1,1,0
0,1,1,1,1,1,1,1,1,1,1,1,0
0,1,1,1,1,1,1,1,1,1,1,1,0
0,0,1,1,1,2,2,2,1,1,1,0,0
0,0,1,1,1,2,2,2,1,1,1,0,0
0,1,1,1,1,1,1,1,1,1,1,1,0
0,1,1,1,1,1,1,1,1,1,1,1,0
0,1,1,1,0,0,3,0,0,1,1,1,0
0,0,0,0,0,0,0,0,0,0,0,0,0
endlayer

layer
0,0,0,0,0,0,0,0,0,0,0,0,0
0,1,1,1,0,0,0,0,0,1,1,1,0
0,1,0,0,1,1,1,1,1,0,0,1,0
0,1,0,0,0,0,0,0,0,0,0,1,0
0,0,7,0,0,0,0,0,0,0,1,0,0
0,0,7,0,0,0,0,0,0,0,1,0,0
0,1,0,0,0,0,0,0,0,0,0,1,0
0,1,8,5,1,1,6,1,1,5,4,1,0
0,1,1,1,0,0,0,0,0,1,1,1,0
0,0,0,0,0,0,0,0,0,0,0,0,0
endlayer

layer
0,0,0,0,0,0,0,0,0,0,0,0,0
0,7,9,7,0,0,0,0,0,7,9,7,0
0,9,0,0,10,10,7,10,10,0,0,9,0
0,7,0,0,0,0,0,0,0,0,0,7,0
0,0,10,0,0,0,0,0,0,0,10,0,0
0,0,10,0,0,0,0,0,0,0,10,0,0
0,7,0,0,0,0,0,0,0,0,0,7,0
0,9,0,0,7,7,11,7,7,0,0,9,0
0,7,9,7,0,0,0,0,0,7,9,7,0
0,0,0,0,0,0,0,0,0,0,0,0,0
endlayer

layer
0,0,0,0,0,0,0,0,0,0,0,0,0
0,7,9,7,0,0,0,0,0,7,9,7,0
0,9,0,0,7,7,7,7,7,0,0,9,0
0,7,0,0,0,0,12,0,0,0,0,7,0
0,0,10,0,0,0,0,0,0,0,10,0,0
0,0,10,0,0,0,0,0,0,0,10,0,0
0,7,0,0,0,0,0,0,0,0,0,7,0
0,9,0,0,7,7,7,7,7,0,0,9,0
0,7,9,7,0,0,12,0,0,7,9,7,0
0,0,0,0,0,0,0,0,0,0,0,0,0
endlayer

layer
0,0,0,0,0,0,0,0,0,0,0,0,0
0,1,1,1,0,0,0,0,0,1,1,1,0
0,1,14,0,7,7,7,7,7,0,13,1,0
0,1,0,0,0,0,0,0,0,0,0,1,0
0,0,7,0,0,0,0,0,0,0,7,0,0
0,0,7,0,0,0,0,0,0,0,7,0,0
0,1,0,0,0,0,0,0,0,0,0,1,0
0,1,14,0,7,7,7,7,7,0,13,1,0
0,1,1,1,0,0,0,0,0,1,1,1,0
0,0,0,0,0,0,0,0,0,0,0,0,0
endlayer

layer
1,1,1,0,0,0,0,0,0,0,1,1,1
1,1,1,1,0,1,0,1,0,1,1,1,1
1,1,1,1,1,1,1,1,1,1,1,1,1
1,1,1,1,10,10,10,10,10,1,1,1,1
0,0,1,1,10,10,10,10,10,1,1,0,0
0,0,1,1,10,10,10,10,10,1,1,0,0
1,1,1,1,10,10,10,10,10,1,1,1,1
1,1,1,1,1,1,1,1,1,1,1,1,1
1,1,1,1,0,1,0,1,0,1,1,1,1
1,1,1,0,0,0,0,0,0,0,1,1,1
endlayer

layer
1,0,1,0,0,0,0,0,0,0,1,0,1
0,0,0,0,0,1,0,1,0,0,0,0,0
1,0,0,0,0,0,0,0,0,0,0,0,1
0,0,0,0,0,0,0,0,0,0,0,0,0
0,0,0,0,0,0,0,0,0,0,0,0,0
0,0,0,0,0,0,0,0,0,0,0,0,0
0,0,0,0,0,0,0,0,0,0,0,0,0
1,0,0,0,0,0,0,0,0,0,0,0,1
0,0,0,0,0,1,0,1,0,0,0,0,0
1,0,1,0,0,0,0,0,0,0,1,0,1
endlayer

