# Converted from schematic
# THIS TEMPLATE USES DEFAULTS!  Please edit for corrections.
# If you need help, consult template_rules.txt

weight=1
embed_into_distance=1
acceptable_target_blocks=1,2,3,12,13
dimensions=8,11,13
allowable_overhang=0
max_cut_in=2
cut_in_buffer=1
max_leveling=2
leveling_buffer=1
preserve_water=0
preserve_lava=0
preserve_plants=0


rule1=0,100,24
rule2=0,100,12
rule3=0,100,128-2
rule4=0,100,24-2
rule5=0,100,64-1
rule6=0,100,64-8
rule7=0,100,102
rule8=0,100,50-3
rule9=0,100,128-3
rule10=0,100,128-0
rule11=0,100,128-1


layer
2,2,2,2,2,2,2,2,2,2,2,2,1
2,2,2,2,2,2,2,2,2,2,2,2,1
2,2,2,2,2,2,2,2,2,2,2,2,1
2,2,2,2,2,2,2,2,2,2,2,2,1
2,2,2,2,2,2,2,2,2,2,2,2,1
2,2,2,2,2,2,2,2,2,2,2,2,1
2,2,2,2,2,2,2,2,2,2,2,2,1
2,2,2,2,2,2,2,2,2,2,2,2,1
2,2,2,2,2,2,2,2,2,2,2,2,1
2,2,2,2,2,2,2,2,2,2,2,2,1
2,2,2,2,2,2,2,2,2,2,2,2,1
endlayer

layer
0,0,0,0,0,0,0,0,0,0,0,0,0
0,0,0,0,0,0,1,1,1,1,1,1,0
0,0,0,0,0,0,1,4,4,4,4,1,0
0,1,1,1,1,1,1,4,4,4,4,1,3
0,1,4,4,4,4,4,4,4,4,4,1,0
0,1,4,4,4,4,4,4,4,4,4,1,0
0,1,4,4,4,4,4,4,4,4,4,1,0
0,1,4,4,4,4,4,4,4,4,4,1,0
0,1,4,4,4,4,4,4,4,4,4,1,0
0,1,1,1,1,1,1,1,1,1,1,1,0
0,0,0,0,0,0,0,0,0,0,0,0,0
endlayer

layer
0,0,0,0,0,0,0,0,0,0,0,0,0
0,0,0,0,0,0,1,1,1,1,1,1,0
0,0,0,0,0,0,1,0,0,0,0,1,0
0,1,1,1,1,1,1,0,0,0,0,5,0
0,1,0,0,0,0,0,0,0,0,0,1,0
0,1,0,0,0,0,0,0,0,0,0,1,0
0,1,0,0,0,0,0,0,0,0,0,1,0
0,1,0,0,0,0,0,0,0,0,0,1,0
0,1,0,0,0,0,0,0,0,0,0,1,0
0,1,1,1,1,1,1,1,1,1,1,1,0
0,0,0,0,0,0,0,0,0,0,0,0,0
endlayer

layer
0,0,0,0,0,0,0,0,0,0,0,0,0
0,0,0,0,0,0,1,1,7,7,1,1,0
0,0,0,0,0,0,4,0,0,0,0,4,0
0,1,1,7,7,1,4,0,0,0,0,6,0
0,1,0,0,0,0,0,0,0,0,0,4,0
0,1,0,0,0,0,0,0,0,0,0,1,0
0,1,0,0,0,0,0,0,0,0,0,7,0
0,1,0,0,0,0,0,0,0,0,0,1,0
0,1,0,0,0,0,0,0,0,0,0,4,0
0,1,1,7,7,1,4,1,7,7,1,1,0
0,0,0,0,0,0,0,0,0,0,0,0,0
endlayer

layer
0,0,0,0,0,0,0,0,0,0,0,0,0
0,0,0,0,0,9,1,1,1,1,1,1,3
0,10,10,10,10,4,4,0,0,0,0,4,3
0,1,1,1,1,1,4,0,0,0,8,4,3
0,1,0,0,0,0,0,0,0,0,0,4,3
0,1,0,0,0,0,0,0,0,0,0,4,3
0,1,0,0,0,0,0,0,0,0,0,4,3
0,1,0,0,0,0,0,0,0,0,0,4,3
0,1,0,0,0,0,0,0,0,0,0,4,3
0,1,1,1,1,1,1,1,1,1,1,1,3
0,0,0,0,0,0,0,0,0,0,0,0,0
endlayer

layer
0,0,0,0,0,0,0,0,0,0,0,0,0
0,0,0,0,0,0,9,4,4,4,4,3,0
0,0,0,0,0,0,9,4,0,0,4,3,0
0,10,10,10,10,10,4,4,0,0,4,3,0
0,4,4,4,4,4,4,4,0,0,4,3,0
0,1,0,0,0,0,0,0,0,0,4,3,0
0,7,0,0,0,0,0,0,0,0,4,3,0
0,1,0,0,0,0,0,0,0,0,4,3,0
0,4,4,4,4,4,4,4,4,4,4,3,0
0,11,11,11,11,11,11,4,4,4,4,3,0
0,0,0,0,0,0,0,0,0,0,0,0,0
endlayer

layer
0,0,0,0,0,0,0,0,0,0,0,0,0
0,0,0,0,0,0,0,9,4,4,3,0,0
0,0,0,0,0,0,0,9,4,4,3,0,0
0,0,0,0,0,0,0,9,4,4,3,0,0
0,10,10,10,10,10,10,4,4,4,3,0,0
0,4,4,4,4,4,4,4,4,4,3,0,0
0,4,0,0,0,0,0,0,4,4,3,0,0
0,4,4,4,4,4,4,4,4,4,3,0,0
0,11,11,11,11,11,11,4,4,4,3,0,0
0,0,0,0,0,0,0,9,4,4,3,0,0
0,0,0,0,0,0,0,0,0,0,0,0,0
endlayer

layer
0,0,0,0,0,0,0,0,0,0,0,0,0
0,0,0,0,0,0,0,0,9,3,0,0,0
0,0,0,0,0,0,0,0,9,3,0,0,0
0,0,0,0,0,0,0,0,9,3,0,0,0
0,0,0,0,0,0,0,0,9,3,0,0,0
0,10,10,10,10,10,10,10,4,3,0,0,0
0,4,4,4,4,4,4,4,4,3,0,0,0
0,11,11,11,11,11,11,11,4,3,0,0,0
0,0,0,0,0,0,0,0,9,3,0,0,0
0,0,0,0,0,0,0,0,9,3,0,0,0
0,0,0,0,0,0,0,0,0,0,0,0,0
endlayer

