# Gilly's underground Hangar access port

# Uses Blocks from Chisel and Tinkers Construct

# template generated by Ruins mod version 14.6 Ingame Parser
# Structure created by Gilly

weight=1
embed_into_distance=24
acceptable_target_blocks=
unacceptable_target_blocks=flowing_water,water,flowing_lava,lava,ice,bedrock,netherrack,soul_sand,Natura:Cloud
dimensions=28,11,7
allowable_overhang=0
max_leveling=3
leveling_buffer=-1
preserve_water=0
preserve_lava=0

rule1=0,100,preserveBlock
rule2=0,100,minecraft:stained_hardened_clay-9
rule3=0,100,minecraft:stonebrick-0
rule4=0,100,minecraft:stone_slab-5
rule5=0,100,minecraft:water-0
rule6=0,100,minecraft:ladder-5
rule7=0,100,minecraft:ladder-4
rule8=0,100,minecraft:glowstone-0
rule9=0,100,chisel:factoryblock-6
rule10=0,100,chisel:factoryblock-5
rule11=0,100,chisel:glass-7
rule12=0,100,minecraft:iron_bars-0
rule13=0,100,chisel:road_line-0
rule14=0,100,minecraft:stained_hardened_clay-5
rule15=0,100,TConstruct:slime.pad-0
rule16=0,100,chisel:factoryblock-1
rule17=0,100,TConstruct:slime.pad-4
rule18=0,100,minecraft:stone_brick_stairs-7
rule19=0,100,minecraft:stone_brick_stairs-6
rule20=0,100,minecraft:stone_brick_stairs-3
rule21=0,100,minecraft:stone_brick_stairs-2

layer
1,2,2,2,2,2,1
1,2,1,1,1,2,1
1,2,1,1,1,2,1
1,2,1,1,1,2,1
1,2,2,2,2,2,1
1,2,3,3,3,2,1
1,2,3,3,3,2,1
1,2,3,3,3,2,1
1,2,3,3,3,2,1
1,2,3,3,3,2,1
1,2,2,2,2,2,1
endlayer

layer
1,2,1,1,1,2,1
1,1,1,1,1,1,1
1,1,1,1,1,1,1
1,1,1,1,1,1,1
1,2,2,2,2,1,1
1,1,0,4,4,2,1
1,1,0,4,5,5,2
1,1,0,4,5,5,2
1,1,0,4,4,2,1
1,1,0,0,0,1,1
1,2,1,1,1,2,1
endlayer

layer
1,2,1,1,1,2,1
1,1,2,2,2,1,1
1,1,2,2,2,1,1
1,1,2,2,2,1,1
1,2,2,2,2,1,1
1,1,0,0,0,2,1
1,1,0,0,0,6,2
1,1,0,0,0,7,2
1,1,0,0,0,2,1
1,1,0,0,0,1,1
1,2,1,1,1,2,1
endlayer

layer
1,2,1,1,1,2,1
1,1,2,2,2,1,1
1,1,2,8,2,1,1
1,1,2,2,2,1,1
1,2,2,2,2,1,1
1,1,0,0,0,2,1
1,1,0,0,0,6,2
1,1,0,0,0,7,2
1,1,0,0,0,2,1
1,1,0,0,0,1,1
1,2,1,1,1,2,1
endlayer

layer
1,2,2,2,2,2,2
1,2,10,10,10,9,9
1,2,10,11,10,9,9
1,2,10,10,10,9,9
1,2,2,2,2,2,2
1,2,0,0,12,2,2
1,2,0,0,12,6,9
1,2,0,0,12,7,9
1,2,0,0,12,2,2
1,2,0,0,0,2,2
1,2,2,2,2,2,2
endlayer

layer
1,2,2,2,2,2,13
1,2,12,12,12,0,0
1,2,12,0,0,0,0
1,2,12,12,12,0,0
1,2,2,2,2,2,0
1,1,0,0,0,2,0
1,1,0,0,12,6,0
1,1,0,0,12,7,0
1,1,0,0,0,2,13
1,1,0,0,0,2,1
1,2,1,1,1,2,1
endlayer

layer
1,2,2,2,2,2,0
1,2,12,12,12,0,0
1,2,12,0,0,0,0
1,2,12,12,12,0,0
1,2,2,2,2,2,0
1,1,0,0,0,2,0
1,1,0,0,12,6,0
1,1,0,0,12,7,0
1,1,0,0,0,2,0
1,1,0,0,0,2,1
1,2,1,1,1,2,1
endlayer

layer
1,2,2,2,2,2,0
1,2,12,12,12,0,0
1,2,12,0,0,0,0
1,2,12,12,12,0,0
1,2,2,2,2,2,0
1,1,0,0,0,2,0
1,1,0,0,12,6,0
1,1,0,0,12,7,0
1,1,0,0,0,2,0
1,1,0,0,0,2,1
1,2,1,1,1,2,1
endlayer

layer
1,2,2,2,2,14,0
1,2,12,12,12,14,0
1,2,12,15,12,14,0
1,2,12,12,12,14,0
1,2,2,2,2,14,0
1,1,0,0,0,14,0
1,1,0,0,12,6,0
1,1,0,0,12,7,0
1,1,0,0,0,14,0
1,1,0,0,0,14,0
1,2,1,1,1,14,0
endlayer

layer
1,2,2,2,2,2,0
1,2,12,12,12,2,0
1,2,12,15,12,2,0
1,2,12,12,12,2,0
1,2,2,2,2,2,0
1,1,0,0,0,2,0
1,1,0,0,12,6,0
1,1,0,0,12,7,0
1,1,0,0,0,2,0
1,1,0,0,0,2,0
1,2,1,1,1,2,0
endlayer

layer
1,2,2,2,2,2,0
1,2,12,12,12,2,0
1,2,12,15,12,2,0
1,2,12,12,12,2,0
1,2,2,2,2,2,0
1,1,0,0,0,2,0
1,1,0,0,12,6,0
1,1,0,0,12,7,0
1,1,0,0,0,2,0
1,1,0,0,0,2,0
1,2,1,1,1,2,0
endlayer

layer
1,2,2,2,2,2,16
1,2,12,12,12,2,16
1,2,12,17,12,2,16
1,2,12,12,12,2,16
1,2,2,2,2,2,16
1,2,0,0,12,2,16
1,2,0,0,12,6,16
1,2,0,0,12,7,16
1,2,0,0,12,2,16
1,2,0,0,0,2,16
1,2,2,2,2,2,16
endlayer

layer
1,2,2,2,2,2,2
1,2,12,12,12,2,2
1,2,12,15,12,2,2
1,2,12,12,12,2,2
1,2,2,2,2,2,2
1,2,0,0,0,2,2
1,2,0,0,12,6,2
1,2,0,0,12,7,2
1,2,0,0,0,2,2
1,2,0,0,0,2,2
1,2,2,2,2,2,2
endlayer

layer
1,2,2,2,2,2,2
1,2,12,12,12,2,2
1,2,12,15,12,2,2
1,2,12,12,12,2,2
1,2,2,2,2,2,2
1,2,0,0,0,2,2
1,2,0,0,12,6,2
1,2,0,0,12,7,2
1,2,0,0,0,2,2
1,2,0,0,0,2,2
1,2,2,2,2,2,2
endlayer

layer
1,2,2,2,2,2,2
1,2,12,12,12,2,2
1,2,12,17,12,2,2
1,2,12,12,12,2,2
1,2,2,2,2,2,2
1,2,0,0,0,2,2
1,2,0,0,12,6,2
1,2,0,0,12,7,2
1,2,0,0,0,2,2
1,2,0,0,0,2,2
1,2,2,2,2,2,2
endlayer

layer
1,2,2,2,2,2,2
1,2,12,12,12,2,2
1,2,12,15,12,2,2
1,2,12,12,12,2,2
1,2,2,2,2,2,2
1,2,0,0,0,2,2
1,2,0,0,12,6,2
1,2,0,0,12,7,2
1,2,0,0,0,2,2
1,2,0,0,0,2,2
1,2,2,2,2,2,2
endlayer

layer
1,2,2,2,2,2,1
1,2,12,12,12,2,2
1,2,12,17,12,2,2
1,2,12,12,12,2,2
1,2,2,2,2,2,2
1,2,0,0,0,2,2
1,2,0,0,12,6,2
1,2,0,0,12,7,2
1,2,0,0,0,2,2
1,2,0,0,0,2,2
1,2,2,2,2,2,2
endlayer

layer
1,2,2,2,2,2,1
1,2,12,12,12,2,1
1,2,12,15,12,2,2
1,2,12,12,12,2,2
1,2,2,2,2,2,2
1,2,0,0,0,2,2
1,2,0,0,12,6,2
1,2,0,0,12,7,2
1,2,0,0,0,2,2
1,2,0,0,0,2,2
1,2,2,2,2,2,2
endlayer

layer
1,2,2,2,2,2,1
1,2,12,12,12,2,1
18,2,12,17,12,2,1
1,2,12,12,12,2,2
18,2,2,2,2,2,2
1,2,0,0,0,2,2
18,2,0,0,12,6,2
1,2,0,0,12,7,2
18,2,0,0,0,2,2
1,2,0,0,0,2,2
1,2,2,2,2,2,2
endlayer

layer
1,2,2,2,2,2,1
1,2,12,12,12,2,1
3,2,12,17,12,2,1
1,2,12,12,12,2,1
3,2,2,2,2,2,2
1,2,0,0,0,2,2
3,2,0,0,12,6,2
1,2,0,0,12,7,2
3,2,0,0,0,2,2
1,2,0,0,0,2,2
1,2,2,2,2,2,1
endlayer

layer
1,2,2,2,2,2,1
1,2,12,12,12,2,1
3,2,12,0,12,2,1
1,2,12,12,12,2,1
3,2,2,2,2,2,1
1,2,0,0,0,2,2
3,2,0,0,12,6,2
1,2,0,0,12,7,2
3,2,0,0,0,2,2
1,2,0,0,0,2,1
1,2,2,2,2,2,1
endlayer

layer
1,2,2,2,2,2,1
1,2,12,12,12,2,1
3,2,12,15,12,2,1
1,2,12,12,12,2,1
3,2,2,2,2,2,1
1,2,0,0,0,2,1
3,2,0,0,12,6,9
1,2,0,0,12,7,9
3,2,0,0,0,2,1
1,2,0,0,0,2,1
1,2,2,2,2,2,1
endlayer

layer
1,2,2,2,2,2,1
1,2,12,12,12,2,1
3,2,12,0,12,2,19
1,2,12,12,12,2,1
3,2,2,2,2,2,1
1,2,0,0,0,2,1
3,2,0,0,12,6,1
1,2,0,0,12,7,1
3,2,0,0,0,2,1
1,2,0,0,0,2,1
1,2,2,2,2,2,1
endlayer

layer
1,2,2,2,2,2,1
1,2,12,12,12,2,1
3,2,12,17,12,2,3
1,2,12,12,12,2,1
3,2,2,2,2,2,1
1,2,0,0,0,2,1
3,2,0,0,12,6,1
1,2,0,0,12,7,1
3,2,0,0,0,2,1
1,2,0,0,0,2,1
1,2,2,2,2,2,1
endlayer

layer
1,2,2,2,2,2,1
1,2,12,12,12,2,1
3,2,12,15,12,2,3
1,2,12,12,12,2,1
3,2,2,2,2,2,19
1,2,0,0,0,2,1
3,2,0,0,12,6,1
1,2,0,0,12,7,1
3,2,0,0,0,2,1
1,2,0,0,0,2,19
1,2,2,2,2,2,1
endlayer

layer
1,2,2,2,2,2,1
1,2,12,12,12,2,1
3,2,12,15,12,2,3
1,2,12,12,12,2,1
3,2,2,2,2,2,3
1,0,0,0,0,2,1
3,2,0,0,12,6,1
1,0,0,0,12,7,1
3,2,0,0,0,2,1
1,0,0,0,0,2,3
1,2,2,2,2,2,1
endlayer

layer
1,2,2,2,2,2,1
1,2,12,12,12,2,1
3,2,12,15,12,2,3
1,2,12,12,12,2,1
3,2,2,2,2,2,3
1,2,0,0,12,2,1
3,3,0,0,12,6,1
1,2,0,0,12,7,1
3,3,0,0,12,2,1
1,2,0,0,0,2,3
1,2,2,2,2,2,1
endlayer

layer
1,1,0,0,0,1,1
1,0,0,0,0,0,1
3,21,0,0,0,20,3
1,0,0,0,0,0,1
3,21,0,0,0,20,3
1,0,0,0,0,0,1
3,21,0,0,0,0,1
1,0,0,0,0,0,1
3,21,0,0,0,0,1
1,0,0,0,0,3,3
1,1,0,0,0,1,1
endlayer

