# Gilly's underground lab, vertical shaft 3

# template generated by Ruins mod version 14.6 Ingame Parser
# Structure created by Gilly

weight=1
embed_into_distance=23
acceptable_target_blocks=
unacceptable_target_blocks=flowing_water,water,flowing_lava,lava,ice,bedrock,netherrack,soul_sand,Natura:Cloud
dimensions=35,19,17
allowable_overhang=0
max_leveling=3
leveling_buffer=-1
preserve_water=0
preserve_lava=0

rule1=0,100,preserveBlock
rule2=0,100,stained_hardened_clay-9
rule3=0,100,stonebrick-0
rule4=0,100,glowstone-0
rule5=0,100,water-0
rule6=0,100,stained_glass_pane-3
rule7=0,100,stone_slab-5
rule8=0,100,ladder-3
rule9=0,100,ladder-2
rule10=0,100,stone_slab-13
rule11=0,100,iron_bars-0
rule12=0,100,stone_slab-8
rule13=0,100,stone_brick_stairs-3
rule14=0,100,stone_brick_stairs-2
rule15=0,100,stained_hardened_clay-3
rule16=0,100,double_stone_slab-0
rule17=0,100,stone_brick_stairs-5
rule18=0,100,stone_brick_stairs-6
rule19=0,100,stone_brick_stairs-7
rule20=0,100,stone_brick_stairs-4

layer
1,1,1,1,1,2,2,1,1,1,1,1,1,1,1,1,1
2,2,2,2,2,3,3,2,2,2,2,2,2,1,1,1,1
2,1,1,1,3,3,3,3,1,1,2,2,2,2,2,1,1
2,1,1,1,3,3,3,3,1,1,1,2,2,4,2,2,1
2,1,1,1,1,1,1,1,1,1,1,1,2,2,2,2,2
2,1,1,1,1,1,1,1,1,1,1,1,1,1,2,2,2
2,1,1,1,1,1,1,1,1,1,1,1,1,1,1,1,2
2,1,1,1,1,1,1,1,1,1,1,1,1,1,1,1,2
2,1,1,1,1,1,1,1,1,1,1,1,1,1,1,1,2
2,1,1,1,1,1,1,1,1,1,1,1,1,1,1,1,2
2,1,1,1,1,1,1,1,1,1,1,1,1,1,1,1,2
2,1,1,1,1,1,1,1,1,1,1,1,1,1,1,1,2
2,2,2,1,1,1,1,1,1,1,1,1,1,1,1,1,2
2,2,2,2,2,1,1,1,1,1,1,1,1,1,1,1,2
1,2,2,4,2,2,2,1,1,1,1,1,1,1,1,1,2
1,1,2,2,2,4,2,2,1,1,1,1,1,1,1,2,2
1,1,1,1,2,2,2,2,2,1,1,1,1,1,2,2,2
1,1,1,1,1,1,2,2,2,2,2,2,2,2,2,2,1
1,1,1,1,1,1,1,1,1,1,1,1,1,1,1,1,1
endlayer

layer
1,1,1,1,1,2,2,1,1,1,1,1,1,1,1,1,1
2,1,1,1,2,5,5,2,1,1,2,3,3,1,1,1,1
1,0,0,0,7,5,5,7,0,0,3,6,6,3,3,1,1
1,0,0,0,7,7,7,7,0,0,0,3,6,6,6,3,1
1,0,0,0,0,0,0,0,0,0,0,0,3,3,6,6,2
1,0,0,0,0,0,0,0,0,0,0,0,0,0,3,3,2
1,0,0,0,0,0,0,0,0,0,0,0,0,0,0,0,1
1,0,0,0,0,0,0,0,0,0,0,0,0,0,0,0,1
1,0,0,0,0,0,0,0,0,0,0,0,0,0,0,0,1
1,0,0,0,0,0,0,0,0,0,0,0,0,0,0,0,1
1,0,0,0,0,0,0,0,0,0,0,0,0,0,0,0,1
1,0,0,0,0,0,0,0,0,0,0,0,0,0,0,0,1
2,3,3,0,0,0,0,0,0,0,0,0,0,0,0,0,1
2,6,6,3,3,0,0,0,0,0,0,0,0,0,0,0,1
1,3,6,6,6,3,3,0,0,0,0,0,0,0,0,0,1
1,1,3,3,6,6,6,3,0,0,0,0,0,0,0,2,1
1,1,1,1,3,3,6,6,3,0,0,0,0,0,2,2,1
1,1,1,1,1,1,3,3,2,1,1,1,1,1,1,1,1
1,1,1,1,1,1,1,1,1,1,1,1,1,1,1,1,1
endlayer

layer
1,1,1,1,1,2,2,1,1,1,1,1,1,1,1,1,1
2,1,1,1,2,9,8,2,1,1,2,3,3,1,1,1,1
1,0,0,0,0,0,0,0,0,0,10,6,6,3,3,1,1
1,0,0,0,0,0,0,0,0,0,0,10,6,6,6,3,1
1,0,0,0,0,0,0,0,0,0,0,0,10,10,6,6,2
1,0,0,0,0,0,0,0,0,0,0,0,0,0,10,10,2
1,0,0,0,0,0,0,0,0,0,0,0,0,0,0,0,1
1,0,0,0,0,0,0,0,0,0,0,0,0,0,0,0,1
1,0,0,0,0,0,0,0,0,0,0,0,0,0,0,0,1
1,0,0,0,0,0,0,0,0,0,0,0,0,0,0,0,1
1,0,0,0,0,0,0,0,0,0,0,0,0,0,0,0,1
1,0,0,0,0,0,0,0,0,0,0,0,0,0,0,0,1
2,10,10,0,0,0,0,0,0,0,0,0,0,0,0,0,1
2,6,6,10,10,0,0,0,0,0,0,0,0,0,0,0,1
1,3,6,6,6,10,10,0,0,0,0,0,0,0,0,0,1
1,1,3,3,6,6,6,10,0,0,0,0,0,0,0,2,1
1,1,1,1,3,3,6,6,10,0,0,0,0,0,2,2,1
1,1,1,1,1,1,3,3,2,1,1,1,1,1,1,1,1
1,1,1,1,1,1,1,1,1,1,1,1,1,1,1,1,1
endlayer

layer
1,1,1,1,1,2,2,1,1,1,1,1,1,1,1,1,1
2,1,1,1,2,9,8,2,1,1,2,3,3,1,1,1,1
1,0,0,0,0,0,0,0,0,0,10,6,6,3,3,1,1
1,0,0,0,0,0,0,0,0,0,0,10,6,6,6,3,1
1,0,0,0,0,0,0,0,0,0,0,0,10,10,6,6,2
1,0,0,0,0,0,0,0,0,0,0,0,0,0,10,10,2
1,0,0,0,0,0,0,0,0,0,0,0,0,0,0,0,1
1,0,0,0,0,0,0,0,0,0,0,0,0,0,0,0,1
1,0,0,0,0,0,0,0,0,0,0,0,0,0,0,0,1
1,0,0,0,0,0,0,0,0,0,0,0,0,0,0,0,1
1,0,0,0,0,0,0,0,0,0,0,0,0,0,0,0,1
1,0,0,0,0,0,0,0,0,0,0,0,0,0,0,0,1
2,10,10,0,0,0,0,0,0,0,0,0,0,0,0,0,1
2,6,6,10,10,0,0,0,0,0,0,0,0,0,0,0,1
1,3,6,6,6,10,10,0,0,0,0,0,0,0,0,0,1
1,1,3,3,6,6,6,10,0,0,0,0,0,0,0,2,1
1,1,1,1,3,3,6,6,10,0,0,0,0,0,2,2,1
1,1,1,1,1,1,3,3,2,1,1,1,1,1,1,1,1
1,1,1,1,1,1,1,1,1,1,1,1,1,1,1,1,1
endlayer

layer
1,1,1,1,1,2,2,1,1,1,1,1,1,1,1,1,1
2,1,1,1,2,9,8,2,1,1,2,3,3,1,1,1,1
1,0,0,0,11,11,11,11,0,0,10,6,6,3,3,1,1
1,0,0,0,0,0,0,0,0,0,0,10,6,6,6,3,1
1,0,0,0,0,0,0,0,0,0,0,0,10,10,6,6,2
1,0,0,0,0,0,0,0,0,0,0,0,0,0,10,10,2
1,0,0,0,0,0,0,0,0,0,0,0,0,0,0,0,1
1,0,0,0,0,0,0,0,0,0,0,0,0,0,0,0,1
1,0,0,0,0,0,0,0,0,0,0,0,0,0,0,0,1
1,0,0,0,0,0,0,0,0,0,0,0,0,0,0,0,1
1,0,0,0,0,0,0,0,0,0,0,0,0,0,0,0,1
1,0,0,0,0,0,0,0,0,0,0,0,0,0,0,0,1
2,10,10,0,0,0,0,0,0,0,0,0,0,0,0,0,1
2,6,6,10,10,0,0,0,0,0,0,0,0,0,0,0,1
1,3,6,6,6,10,10,0,0,0,0,0,0,0,0,0,1
1,1,3,3,6,6,6,10,0,0,0,0,0,0,0,2,1
1,1,1,1,3,3,6,6,10,0,0,0,0,0,2,2,1
1,1,1,1,1,1,3,3,2,1,1,1,1,1,1,1,1
1,1,1,1,1,1,1,1,1,1,1,1,1,1,1,1,1
endlayer

layer
1,1,1,1,1,2,2,1,1,1,1,1,1,1,1,1,1
2,1,1,1,2,9,8,2,1,1,2,3,3,1,1,1,1
1,0,0,0,0,11,11,0,0,0,10,6,6,3,3,1,1
1,0,0,0,0,0,0,0,0,0,0,10,6,6,6,3,1
1,0,0,0,0,0,0,0,0,0,0,0,10,10,6,6,2
1,0,0,0,0,0,0,0,0,0,0,0,0,0,10,10,2
1,0,0,0,0,0,0,0,0,0,0,0,0,0,0,0,1
1,0,0,0,0,0,0,0,0,0,0,0,0,0,0,0,1
1,0,0,0,0,0,0,0,0,0,0,0,0,0,0,0,1
1,0,0,0,0,0,0,0,0,0,0,0,0,0,0,0,1
1,0,0,0,0,0,0,0,0,0,0,0,0,0,0,0,1
1,0,0,0,0,0,0,0,0,0,0,0,0,0,0,0,1
2,10,10,0,0,0,0,0,0,0,0,0,0,0,0,0,1
2,6,6,10,10,0,0,0,0,0,0,0,0,0,0,0,1
1,3,6,6,6,10,10,0,0,0,0,0,0,0,0,0,1
1,1,3,3,6,6,6,10,0,0,0,0,0,0,0,2,1
1,1,1,1,3,3,6,6,10,0,0,0,0,0,2,2,1
1,1,1,1,1,1,3,3,2,1,1,1,1,1,1,1,1
1,1,1,1,1,1,1,1,1,1,1,1,1,1,1,1,1
endlayer

layer
1,1,1,1,1,2,2,1,1,1,1,1,1,1,1,1,1
2,2,2,2,2,9,8,2,2,2,2,2,2,1,1,1,1
2,0,0,0,0,11,11,0,0,0,2,2,2,2,2,1,1
2,0,0,0,0,0,0,0,0,0,0,2,2,4,4,2,1
2,0,0,0,0,0,0,0,0,0,0,0,2,2,2,2,2
2,0,0,0,0,0,0,0,0,0,0,0,0,0,2,2,2
2,0,0,0,0,0,0,0,0,0,0,0,0,0,0,0,2
2,0,0,0,0,0,0,0,0,0,0,0,0,0,0,0,2
2,0,0,0,0,0,0,0,0,0,0,0,0,0,0,0,2
2,0,0,0,0,0,0,0,0,0,0,0,0,0,0,0,2
2,0,0,0,0,0,0,0,0,0,0,0,0,0,0,0,2
2,0,0,0,0,0,0,0,0,0,0,0,0,0,0,0,2
2,2,2,0,0,0,0,0,0,0,0,0,0,0,0,0,2
2,2,2,2,2,0,0,0,0,0,0,0,0,0,0,0,2
1,2,2,4,2,2,2,0,0,0,0,0,0,0,0,0,2
1,1,2,2,2,4,2,2,0,0,0,0,0,0,0,2,2
1,1,4,2,2,4,2,2,2,0,0,0,0,0,2,2,2
1,1,1,1,1,1,2,2,2,2,2,2,2,2,2,2,1
1,1,1,1,1,1,1,1,1,1,1,1,1,1,1,1,1
endlayer

layer
1,1,1,1,1,2,2,1,1,1,1,1,1,1,1,1,1
2,2,2,2,2,9,8,2,2,2,2,2,2,2,2,2,2
2,0,0,0,0,11,11,0,0,0,0,2,2,2,2,2,2
2,0,0,0,0,0,0,0,0,0,0,0,2,2,11,2,2
2,0,0,0,0,0,0,0,0,0,0,0,0,0,2,2,2
2,0,0,0,0,0,0,0,0,0,0,0,0,0,0,0,2
2,0,0,0,0,0,0,0,0,0,0,0,0,0,0,0,2
2,0,0,0,0,0,0,0,0,0,0,0,0,0,0,0,2
2,0,0,0,0,0,0,0,0,0,0,0,0,0,0,0,2
2,0,0,0,0,0,0,0,0,0,0,0,0,0,0,0,2
2,0,0,0,0,0,0,0,0,0,0,0,0,0,0,0,2
2,0,0,0,0,0,0,0,0,0,0,0,0,0,0,0,2
2,0,0,0,0,0,0,0,0,12,12,12,12,12,12,12,2
2,2,2,0,0,0,0,0,0,12,12,12,12,12,12,12,2
2,2,2,2,2,0,0,0,0,12,12,12,12,12,12,12,2
2,2,2,2,2,2,2,0,0,12,12,12,12,12,12,2,2
2,2,11,2,2,11,2,2,0,12,12,12,12,12,2,2,2
2,2,2,2,2,2,2,2,2,2,2,2,2,2,2,2,2
1,1,1,1,1,1,1,1,1,1,1,1,1,1,1,1,1
endlayer

layer
0,0,0,0,0,0,0,0,0,0,0,0,0,0,0,0,0
2,3,3,3,2,9,8,2,3,3,2,0,0,0,0,0,0
3,0,0,0,0,11,11,0,0,0,0,3,0,0,0,0,0
13,0,0,0,0,0,0,0,0,0,0,0,3,3,0,0,0
13,0,0,0,0,0,0,0,0,0,0,0,0,0,3,3,0
13,0,0,0,0,0,0,0,0,0,0,0,0,0,0,0,2
13,0,0,0,0,0,0,0,0,0,0,0,0,0,0,0,3
13,0,0,0,0,0,0,0,0,0,0,0,0,0,0,0,14
13,0,0,0,0,0,0,0,0,0,0,0,0,0,0,0,14
13,0,0,0,0,0,0,0,0,0,0,0,0,0,0,0,14
13,0,0,0,0,0,0,0,0,0,0,0,0,0,0,0,14
3,0,0,0,0,0,0,0,0,0,0,0,0,0,0,0,14
2,0,0,0,0,0,0,0,0,11,11,11,11,11,11,11,14
2,3,3,0,0,0,0,0,0,11,0,0,0,0,0,0,14
0,0,0,3,3,0,0,0,0,11,0,0,0,0,0,0,3
0,0,0,0,0,3,3,0,0,11,0,0,0,0,0,2,3
0,0,0,0,0,0,0,3,0,11,0,0,0,0,2,2,3
0,0,0,0,0,0,0,0,3,2,3,0,0,3,3,3,3
0,0,0,0,0,0,0,0,0,0,0,0,0,0,0,0,0
endlayer

layer
0,0,0,0,0,0,0,0,0,0,0,0,0,0,0,0,0
2,3,3,3,2,9,8,2,3,3,2,0,0,0,0,0,0
3,0,0,0,0,11,11,0,0,0,0,3,0,0,0,0,0
0,0,0,0,0,0,0,0,0,0,0,0,3,3,0,0,0
0,0,0,0,0,0,0,0,0,0,0,0,0,0,3,3,0
0,0,0,0,0,0,0,0,0,0,0,0,0,0,0,0,2
0,0,0,0,0,0,0,0,0,0,0,0,0,0,0,0,3
0,0,0,0,0,0,0,0,0,0,0,0,0,0,0,0,0
0,0,0,0,0,0,0,0,0,0,0,0,0,0,0,0,0
0,0,0,0,0,0,0,0,0,0,0,0,0,0,0,0,0
0,0,0,0,0,0,0,0,0,0,0,0,0,0,0,0,0
3,0,0,0,0,0,0,0,0,0,0,0,0,0,0,0,0
2,0,0,0,0,0,0,0,0,0,0,0,0,0,0,0,0
2,3,3,0,0,0,0,0,0,0,0,0,0,0,0,0,0
0,0,0,3,3,0,0,0,0,0,0,0,0,0,0,0,3
0,0,0,0,0,3,3,0,0,0,0,0,0,0,0,2,3
0,0,0,0,0,0,0,3,0,0,0,0,0,0,2,2,3
0,0,0,0,0,0,0,0,3,2,3,0,0,3,3,3,3
0,0,0,0,0,0,0,0,0,0,0,0,0,0,0,0,0
endlayer

layer
0,0,0,0,0,0,0,0,0,0,0,0,0,0,0,0,0
2,15,15,15,2,9,8,2,15,15,2,0,0,0,0,0,0
15,0,0,0,0,11,11,0,0,0,0,15,0,0,0,0,0
11,0,0,0,0,0,0,0,0,0,0,0,15,15,0,0,0
11,0,0,0,0,0,0,0,0,0,0,0,0,0,15,15,0
11,0,0,0,0,0,0,0,0,0,0,0,0,0,0,0,2
11,0,0,0,0,0,0,0,0,0,0,0,0,0,0,0,15
11,0,0,0,0,0,0,0,0,0,0,0,0,0,0,0,11
11,0,0,0,0,0,0,0,0,0,0,0,0,0,0,0,11
11,0,0,0,0,0,0,0,0,0,0,0,0,0,0,0,11
11,0,0,0,0,0,0,0,0,0,0,0,0,0,0,0,11
15,0,0,0,0,0,0,0,0,0,0,0,0,0,0,0,11
2,0,0,0,0,0,0,0,0,0,0,0,0,0,0,0,11
2,15,15,0,0,0,0,0,0,0,0,0,0,0,0,0,11
0,0,0,15,15,0,0,0,0,0,0,0,0,0,0,0,15
0,0,0,0,0,15,15,0,0,0,0,0,0,0,0,2,15
0,0,0,0,0,0,0,15,0,0,0,0,0,0,2,2,15
0,0,0,0,0,0,0,0,15,2,15,0,0,15,15,15,15
0,0,0,0,0,0,0,0,0,0,0,0,0,0,0,0,0
endlayer

layer
0,0,0,0,0,0,0,0,0,0,0,0,0,0,0,0,0
2,3,3,3,2,9,8,2,3,3,2,0,0,0,0,0,0
3,0,0,0,0,11,11,0,0,0,0,3,0,0,0,0,0
3,0,0,0,0,0,0,0,0,0,0,0,3,3,0,0,0
3,0,0,0,0,0,0,0,0,0,0,0,0,0,3,3,0
3,0,0,0,0,0,0,0,0,0,0,0,0,0,0,0,2
3,0,0,0,0,0,0,0,0,0,0,0,0,0,0,0,3
3,0,0,0,0,0,0,0,0,0,0,0,0,0,0,0,3
3,0,0,0,0,0,0,0,0,0,0,0,0,0,0,0,3
3,0,0,0,0,0,0,0,0,0,0,0,0,0,0,0,3
3,0,0,0,0,0,0,0,0,0,0,0,0,0,0,0,3
3,0,0,0,0,0,0,0,0,0,0,0,0,0,0,0,3
2,0,0,0,0,0,0,0,0,0,0,0,0,0,0,0,3
2,3,3,0,0,0,0,0,0,0,0,0,0,0,0,0,3
0,0,0,3,3,0,0,0,0,0,0,0,0,0,0,0,3
0,0,0,0,0,3,3,0,0,0,0,0,0,0,0,2,3
0,0,0,0,0,0,0,3,0,0,0,0,0,0,2,2,3
0,0,0,0,0,0,0,0,3,2,3,3,3,3,3,3,3
0,0,0,0,0,0,0,0,0,0,0,0,0,0,0,0,0
endlayer

layer
1,1,1,1,1,1,1,1,1,1,1,1,1,1,1,1,1
2,3,3,3,2,9,8,2,3,3,2,0,0,0,0,0,3
3,0,0,0,0,11,11,0,0,0,0,3,0,0,0,0,3
3,0,0,0,0,0,0,0,0,0,0,0,3,3,0,0,3
3,0,0,0,0,0,0,0,0,0,0,0,0,0,3,3,3
3,0,0,0,0,0,0,0,0,0,0,0,0,0,0,0,2
3,0,0,0,0,0,0,0,0,0,0,0,0,0,0,0,3
3,0,0,0,0,0,0,0,0,0,0,0,0,0,0,0,3
3,0,0,0,0,0,0,0,0,0,0,0,0,0,0,0,3
3,0,0,0,0,0,0,0,0,0,0,0,0,0,0,0,3
3,0,0,0,0,0,0,0,0,0,0,0,0,0,0,0,3
3,0,0,0,0,0,0,0,0,0,0,0,0,0,0,0,3
2,0,0,0,0,0,0,0,0,0,0,0,0,0,0,0,3
2,3,3,0,0,0,0,0,0,0,0,0,0,0,0,0,3
3,0,0,3,3,0,0,0,0,0,0,0,0,0,0,0,3
3,0,0,0,0,3,3,0,0,0,0,0,0,0,0,2,3
3,0,0,0,0,0,0,3,0,0,0,0,0,0,2,2,3
3,0,0,0,0,0,0,0,3,2,3,3,3,3,3,3,3
1,1,1,1,1,1,1,1,1,1,1,1,1,1,1,1,1
endlayer

layer
1,1,1,1,1,1,1,1,1,1,1,1,1,1,1,1,1
2,2,2,2,2,9,8,2,2,2,2,16,16,16,16,16,3
2,0,0,0,11,11,11,11,0,0,0,2,16,16,16,16,3
2,0,0,0,0,0,0,0,0,0,0,0,2,2,16,16,3
2,0,0,0,0,0,0,0,0,0,0,0,0,0,2,2,3
2,0,0,0,0,0,0,0,0,0,0,0,0,0,0,0,2
2,0,0,0,0,0,0,0,0,0,0,0,0,0,0,0,2
2,0,0,0,0,0,0,0,0,0,0,0,0,0,0,0,2
2,0,0,0,0,0,0,0,0,0,0,0,0,0,0,0,2
2,0,0,0,0,0,0,0,0,0,0,0,0,0,0,0,2
2,0,0,0,0,0,0,0,0,0,0,0,0,0,0,0,2
2,0,0,0,0,0,0,0,0,0,0,0,0,0,0,0,2
2,0,0,0,0,0,0,0,0,0,0,0,0,0,0,0,2
2,2,2,0,0,0,0,0,0,0,0,0,0,0,0,0,2
3,16,16,2,2,0,0,0,0,0,0,0,0,0,0,0,2
3,16,16,16,16,2,2,0,0,0,0,0,0,0,0,2,2
3,16,16,16,16,16,16,2,0,0,0,0,0,0,2,2,2
3,16,16,16,16,16,16,16,2,2,2,2,2,2,2,2,2
1,1,1,1,1,1,1,1,1,1,1,1,1,1,1,1,1
endlayer

layer
2,2,2,2,2,2,2,2,2,2,2,2,1,1,1,1,1
2,2,2,2,2,9,8,2,2,2,2,2,2,2,1,1,1
2,0,0,0,0,11,11,0,0,0,2,2,2,2,2,2,1
2,0,0,0,0,0,0,0,0,0,0,2,2,4,2,2,2
2,0,0,0,0,0,0,0,0,0,0,0,2,2,2,2,2
2,0,0,0,0,0,0,0,0,0,0,0,0,0,2,2,2
2,0,0,0,0,0,0,0,0,0,0,0,0,0,0,0,2
2,0,0,0,0,0,0,0,0,0,0,0,0,0,0,0,2
2,0,0,0,0,0,0,0,0,0,0,0,0,0,0,0,2
2,0,0,0,0,0,0,0,0,0,0,0,0,0,0,0,2
2,0,0,0,0,0,0,0,0,0,0,0,0,0,0,0,2
2,0,0,0,0,0,0,0,0,0,0,0,0,0,0,0,2
2,2,2,0,0,0,0,0,0,0,0,0,0,0,0,0,2
2,2,2,2,2,0,0,0,0,0,0,0,0,0,0,0,2
2,2,2,4,2,2,2,0,0,0,0,0,0,0,0,0,2
1,2,2,2,2,4,2,2,0,0,0,0,0,0,0,2,2
1,1,2,2,2,2,2,2,2,0,0,0,0,0,2,2,2
1,1,1,1,2,2,2,2,2,2,2,2,2,2,2,2,1
1,1,1,1,1,1,1,1,1,1,1,1,1,1,1,1,1
endlayer

layer
2,2,2,2,2,2,2,2,2,2,2,2,1,1,1,1,1
2,2,2,2,2,9,8,2,2,2,2,3,3,2,1,1,1
2,0,0,0,0,11,11,0,0,0,3,6,6,3,3,2,1
2,0,0,0,0,0,0,0,0,0,0,3,6,6,6,3,2
2,0,0,0,0,0,0,0,0,0,0,0,3,3,6,6,2
2,0,0,0,0,0,0,0,0,0,0,0,0,0,3,3,2
2,0,0,0,0,0,0,0,0,0,0,0,0,0,0,0,2
2,0,0,0,0,0,0,0,0,0,0,0,0,0,0,0,2
2,0,0,0,0,0,0,0,0,0,0,0,0,0,0,0,2
2,0,0,0,0,0,0,0,0,0,0,0,0,0,0,0,2
2,0,0,0,0,0,0,0,0,0,0,0,0,0,0,0,2
2,0,0,0,0,0,0,0,0,0,0,0,0,0,0,0,2
2,3,3,0,0,0,0,0,0,0,0,0,0,0,0,0,2
2,6,6,3,3,0,0,0,0,0,0,0,0,0,0,0,2
2,3,6,6,6,3,3,0,0,0,0,0,0,0,0,0,2
1,2,3,3,6,6,6,3,0,0,0,0,0,0,0,2,2
1,1,2,2,3,3,6,6,3,0,0,0,0,0,2,2,2
1,1,1,1,2,2,3,3,2,2,2,2,2,2,2,2,1
1,1,1,1,1,1,1,1,1,1,1,1,1,1,1,1,1
endlayer

layer
1,2,2,2,2,2,2,2,2,2,2,1,1,1,1,1,1
2,2,2,2,2,9,8,2,2,2,2,3,3,2,1,1,1
2,0,0,0,0,11,11,0,0,0,10,6,6,3,3,2,1
2,0,0,0,0,0,0,0,0,0,0,10,6,6,6,3,2
2,0,0,0,0,0,0,0,0,0,0,0,10,10,6,6,2
2,0,0,0,0,0,0,0,0,0,0,0,0,0,10,10,2
2,0,0,0,0,0,0,0,0,0,0,0,0,0,0,0,2
2,0,0,0,0,0,0,0,0,0,0,0,0,0,0,0,2
2,0,0,0,0,0,0,0,0,0,0,0,0,0,0,0,2
2,0,0,0,0,0,0,0,0,0,0,0,0,0,0,0,2
2,0,0,0,0,0,0,0,0,0,0,0,0,0,0,0,2
2,0,0,0,0,0,0,0,0,0,0,0,0,0,0,0,2
2,10,10,0,0,0,0,0,0,0,0,0,0,0,0,0,2
2,6,6,10,10,0,0,0,0,0,0,0,0,0,0,0,2
2,3,6,6,6,10,10,0,0,0,0,0,0,0,0,0,2
1,2,3,3,6,6,6,10,0,0,0,0,0,0,0,2,2
1,1,2,2,3,3,6,6,10,0,0,0,0,0,2,2,2
1,1,1,1,2,2,3,3,2,2,2,2,2,2,2,2,1
1,1,1,1,1,1,1,1,1,1,1,1,1,1,1,1,1
endlayer

layer
1,1,2,2,2,2,2,2,2,2,1,1,1,1,1,1,1
2,2,2,2,2,9,8,2,2,2,2,3,3,2,1,1,1
2,0,0,0,0,11,11,0,0,0,10,6,6,3,3,2,1
2,0,0,0,0,0,0,0,0,0,0,10,6,6,6,3,2
2,0,0,0,0,0,0,0,0,0,0,0,10,10,6,6,2
2,0,0,0,0,0,0,0,0,0,0,0,0,0,10,10,2
2,0,0,0,0,0,0,0,0,0,0,0,0,0,0,0,2
2,0,0,0,0,0,0,0,0,0,0,0,0,0,0,0,2
2,0,0,0,0,0,0,0,0,0,0,0,0,0,0,0,2
2,0,0,0,0,0,0,0,0,0,0,0,0,0,0,0,2
2,0,0,0,0,0,0,0,0,0,0,0,0,0,0,0,2
2,0,0,0,0,0,0,0,0,0,0,0,0,0,0,0,2
2,10,10,0,0,0,0,0,0,0,0,0,0,0,0,0,2
2,6,6,10,10,0,0,0,0,0,0,0,0,0,0,0,2
2,3,6,6,6,10,10,0,0,0,0,0,0,0,0,0,2
1,2,3,3,6,6,6,10,0,0,0,0,0,0,0,2,2
1,1,2,2,3,3,6,6,10,0,0,0,0,0,2,2,2
1,1,1,1,2,2,3,3,2,2,2,2,2,2,2,2,1
1,1,1,1,1,1,1,1,1,1,1,1,1,1,1,1,1
endlayer

layer
1,1,1,2,2,2,2,2,2,1,1,1,1,1,1,1,1
2,2,2,2,2,9,8,2,2,2,2,3,3,2,1,1,1
2,0,0,0,0,11,11,0,0,0,10,6,6,3,3,2,1
2,0,0,0,0,0,0,0,0,0,0,10,6,6,6,3,2
2,0,0,0,0,0,0,0,0,0,0,0,10,10,6,6,2
2,0,0,0,0,0,0,0,0,0,0,0,0,0,10,10,2
2,0,0,0,0,0,0,0,0,0,0,0,0,0,0,0,2
2,0,0,0,0,0,0,0,0,0,0,0,0,0,0,0,2
2,0,0,0,0,0,0,0,0,0,0,0,0,0,0,0,2
2,0,0,0,0,0,0,0,0,0,0,0,0,0,0,0,2
2,0,0,0,0,0,0,0,0,0,0,0,0,0,0,0,2
2,0,0,0,0,0,0,0,0,0,0,0,0,0,0,0,2
2,10,10,0,0,0,0,0,0,0,0,0,0,0,0,0,2
2,6,6,10,10,0,0,0,0,0,0,0,0,0,0,0,2
2,3,6,6,6,10,10,0,0,0,0,0,0,0,0,0,2
1,2,3,3,6,6,6,10,0,0,0,0,0,0,0,2,2
1,1,2,2,3,3,6,6,10,0,0,0,0,0,2,2,2
1,1,1,1,2,2,3,3,2,2,2,2,2,2,2,2,1
1,1,1,1,1,1,1,1,1,1,1,1,1,1,1,1,1
endlayer

layer
1,1,1,1,2,2,2,2,1,1,1,1,1,1,1,1,1
2,2,2,2,2,9,8,2,2,2,2,3,3,2,1,1,1
2,0,0,17,0,11,11,0,17,0,10,6,6,3,3,2,1
2,0,0,0,0,0,0,0,0,0,0,10,6,6,6,3,2
2,18,0,0,0,0,0,0,0,0,0,0,10,10,6,6,2
2,0,0,0,0,0,0,0,0,0,0,0,0,0,10,10,2
2,18,0,0,0,0,0,0,0,0,0,0,0,0,0,0,2
2,0,0,0,0,0,0,0,0,0,0,0,0,0,0,19,2
2,18,0,0,0,0,0,0,0,0,0,0,0,0,0,0,2
2,0,0,0,0,0,0,0,0,0,0,0,0,0,0,19,2
2,18,0,0,0,0,0,0,0,0,0,0,0,0,0,0,2
2,0,0,0,0,0,0,0,0,0,0,0,0,0,0,19,2
2,10,10,0,0,0,0,0,0,0,0,0,0,0,0,0,2
2,6,6,10,10,0,0,0,0,0,0,0,0,0,0,19,2
2,3,6,6,6,10,10,0,0,0,0,0,0,0,0,0,2
1,2,3,3,6,6,6,10,0,0,0,0,0,0,0,2,2
1,1,2,2,3,3,6,6,10,0,20,0,20,0,2,2,2
1,1,1,1,2,2,3,3,2,2,2,2,2,2,2,2,1
1,1,1,1,1,1,1,1,1,1,1,1,1,1,1,1,1
endlayer

layer
1,1,1,1,1,2,2,1,1,1,1,2,1,1,1,1,1
2,2,2,2,2,9,8,2,2,2,2,2,2,2,1,1,1
2,0,0,3,0,11,11,0,3,0,2,2,2,2,2,2,1
2,0,0,0,0,0,0,0,0,0,0,2,2,4,2,2,2
2,3,0,0,0,0,0,0,0,0,0,0,2,2,2,2,2
2,0,0,0,0,0,0,0,0,0,0,0,0,0,2,2,2
2,3,0,0,0,0,0,0,0,0,0,0,0,0,0,0,2
2,0,0,0,0,0,0,0,0,0,0,0,0,0,0,3,2
2,3,0,0,0,0,0,0,0,0,0,0,0,0,0,0,2
2,0,0,0,0,0,0,0,0,0,0,0,0,0,0,3,2
2,3,0,0,0,0,0,0,0,0,0,0,0,0,0,0,2
2,0,0,0,0,0,0,0,0,0,0,0,0,0,0,3,2
2,2,2,0,0,0,0,0,0,0,0,0,0,0,0,0,2
2,2,2,2,2,0,0,0,0,0,0,0,0,0,0,3,2
2,2,2,4,2,2,2,0,0,0,0,0,0,0,0,0,2
1,2,2,2,2,4,2,2,0,0,0,0,0,0,0,2,2
1,1,2,2,2,2,2,2,2,0,3,0,3,0,2,2,2
1,1,1,1,2,2,2,2,2,2,2,2,2,2,2,2,1
1,1,1,1,1,1,1,1,1,1,1,1,1,1,1,1,1
endlayer

layer
1,1,1,1,1,1,1,1,1,1,1,2,1,1,1,1,1
2,2,2,2,2,9,8,2,2,2,2,2,2,2,1,1,1
2,0,0,3,0,11,11,0,3,0,2,3,6,6,2,2,1
2,0,0,0,0,0,0,0,0,0,0,0,3,6,6,6,2
2,3,0,0,0,0,0,0,0,0,0,0,0,3,3,3,2
2,0,0,0,0,0,0,0,0,0,0,0,0,0,0,0,2
2,3,0,0,0,0,0,0,0,0,0,0,0,0,0,0,2
2,0,0,0,0,0,0,0,0,0,0,0,0,0,0,3,2
2,3,0,0,0,0,0,0,0,0,0,0,0,0,0,0,2
2,0,0,0,0,0,0,0,0,0,0,0,0,0,0,3,2
2,3,0,0,0,0,0,0,0,0,0,0,0,0,0,0,2
2,0,0,0,0,0,0,0,0,0,0,0,0,0,0,3,2
2,0,0,0,0,0,0,0,0,0,0,0,0,0,0,0,2
2,3,3,0,0,0,0,0,0,0,0,0,0,0,0,3,2
2,6,6,3,3,0,0,0,0,0,0,0,0,0,0,0,2
1,2,6,6,6,3,3,0,0,0,0,0,0,0,0,2,2
1,1,2,2,6,6,6,3,2,0,3,0,3,0,2,2,2
1,1,1,1,2,2,2,2,2,2,2,2,2,2,2,2,1
1,1,1,1,1,1,1,1,1,1,1,1,1,1,1,1,1
endlayer

layer
1,1,1,1,1,1,1,1,1,1,1,2,1,1,1,1,1
2,2,2,2,2,9,8,2,2,2,2,2,2,2,1,1,1
2,0,0,3,0,11,11,0,3,0,2,10,6,6,2,2,1
2,0,0,0,0,0,0,0,0,0,0,0,10,6,6,6,2
2,3,0,0,0,0,0,0,0,0,0,0,0,10,10,10,2
2,0,0,0,0,0,0,0,0,0,0,0,0,0,0,0,2
2,3,0,0,0,0,0,0,0,0,0,0,0,0,0,0,2
2,0,0,0,0,0,0,0,0,0,0,0,0,0,0,3,2
2,3,0,0,0,0,0,0,0,0,0,0,0,0,0,0,2
2,0,0,0,0,0,0,0,0,0,0,0,0,0,0,3,2
2,3,0,0,0,0,0,0,0,0,0,0,0,0,0,0,2
2,0,0,0,0,0,0,0,0,0,0,0,0,0,0,3,2
2,0,0,0,0,0,0,0,0,0,0,0,0,0,0,0,2
2,10,10,0,0,0,0,0,0,0,0,0,0,0,0,3,2
2,6,6,10,10,0,0,0,0,0,0,0,0,0,0,0,2
1,2,6,6,6,10,10,0,0,0,0,0,0,0,0,2,2
1,1,2,2,6,6,6,10,2,0,3,0,3,0,2,2,2
1,1,1,1,2,2,2,2,2,2,2,2,2,2,2,2,1
1,1,1,1,1,1,1,1,1,1,1,1,1,1,1,1,1
endlayer

layer
1,1,1,1,1,1,1,1,1,1,1,2,1,1,1,1,1
2,2,0,2,2,9,8,2,2,0,2,2,2,2,1,1,1
2,0,0,3,0,11,11,0,3,0,2,10,6,6,2,2,1
0,0,0,0,0,0,0,0,0,0,0,0,10,6,6,6,2
2,3,0,0,0,0,0,0,0,0,0,0,0,10,10,10,2
0,0,0,0,0,0,0,0,0,0,0,0,0,0,0,0,2
2,3,0,0,0,0,0,0,0,0,0,0,0,0,0,0,0
0,0,0,0,0,0,0,0,0,0,0,0,0,0,0,3,2
2,3,0,0,0,0,0,0,0,0,0,0,0,0,0,0,0
0,0,0,0,0,0,0,0,0,0,0,0,0,0,0,3,2
2,3,0,0,0,0,0,0,0,0,0,0,0,0,0,0,0
0,0,0,0,0,0,0,0,0,0,0,0,0,0,0,3,2
2,0,0,0,0,0,0,0,0,0,0,0,0,0,0,0,0
2,10,10,0,0,0,0,0,0,0,0,0,0,0,0,3,2
2,6,6,10,10,0,0,0,0,0,0,0,0,0,0,0,0
1,2,6,6,6,10,10,0,0,0,0,0,0,0,0,2,2
1,1,2,2,6,6,6,10,2,0,3,0,3,0,2,2,2
1,1,1,1,2,2,2,2,2,0,2,0,2,0,2,2,1
1,1,1,1,1,1,1,1,1,1,1,1,1,1,1,1,1
endlayer

layer
1,1,1,1,1,1,1,1,1,1,1,2,1,1,1,1,1
2,2,2,3,2,9,8,2,3,2,2,2,2,2,1,1,1
2,0,0,3,0,11,11,0,3,0,3,2,2,2,2,2,1
2,0,0,0,0,0,0,0,0,0,0,3,2,4,2,2,2
3,3,0,0,0,0,0,0,0,0,0,0,2,3,2,2,2
2,0,0,0,0,0,0,0,0,0,0,0,0,0,2,10,2
3,3,0,0,0,0,0,0,0,0,0,0,0,0,0,0,2
2,0,0,0,0,0,0,0,0,0,0,0,0,0,0,3,3
3,3,0,0,0,0,0,0,0,0,0,0,0,0,0,0,2
2,0,0,0,0,0,0,0,0,0,0,0,0,0,0,3,3
3,3,0,0,0,0,0,0,0,0,0,0,0,0,0,0,2
2,0,0,0,0,0,0,0,0,0,0,0,0,0,0,3,3
2,0,0,0,0,0,0,0,0,0,0,0,0,0,0,0,2
2,2,3,3,2,0,0,0,0,0,0,0,0,0,0,3,3
2,4,2,4,2,3,2,0,0,0,0,0,0,0,0,0,2
1,2,2,4,2,2,2,3,0,0,0,0,0,0,0,2,2
1,1,2,2,2,2,2,2,2,0,3,0,3,0,2,2,2
1,1,1,1,2,2,2,2,2,2,3,2,3,2,2,2,1
1,1,1,1,1,1,1,1,1,1,1,1,1,1,1,1,1
endlayer

layer
1,1,1,0,0,0,0,0,0,0,0,2,0,0,1,1,1
11,11,11,3,2,9,8,2,3,11,2,2,3,3,0,1,1
11,0,0,3,0,11,11,0,3,0,10,6,6,6,2,2,1
11,0,0,0,0,0,0,0,0,0,0,10,6,6,6,2,2
3,3,0,0,0,0,0,0,0,0,0,0,2,10,6,6,2
11,0,0,0,0,0,0,0,0,0,0,0,0,0,2,10,2
3,3,0,0,0,0,0,0,0,0,0,0,0,0,0,0,11
11,0,0,0,0,0,0,0,0,0,0,0,0,0,0,3,3
3,3,0,0,0,0,0,0,0,0,0,0,0,0,0,0,11
11,0,0,0,0,0,0,0,0,0,0,0,0,0,0,3,3
3,3,0,0,0,0,0,0,0,0,0,0,0,0,0,0,11
11,0,0,0,0,0,0,0,0,0,0,0,0,0,0,3,3
11,0,0,0,0,0,0,0,0,0,0,0,0,0,0,0,11
2,2,10,10,2,0,0,0,0,0,0,0,0,0,0,3,3
10,6,6,6,6,10,2,0,0,0,0,0,0,0,0,0,11
0,2,6,6,2,6,6,10,0,0,0,0,0,0,0,2,2
1,0,10,10,2,6,6,2,2,0,3,0,3,0,2,2,2
1,1,1,0,0,10,10,2,11,11,3,11,3,11,2,2,1
1,1,1,1,1,0,0,0,0,0,0,0,0,1,1,1,1
endlayer

layer
0,0,0,0,0,0,0,0,0,0,0,2,0,0,0,1,1
0,0,0,0,2,9,8,2,0,0,2,2,10,10,0,0,1
0,0,0,0,11,11,11,11,0,0,10,6,6,6,2,2,0
0,0,0,0,0,0,0,0,0,0,0,10,6,6,6,2,2
0,0,0,0,0,0,0,0,0,0,0,0,2,10,6,6,2
0,0,0,0,0,0,0,0,0,0,0,0,0,0,2,10,2
0,0,0,0,0,0,0,0,0,0,0,0,0,0,0,0,0
0,0,0,0,0,0,0,0,0,0,0,0,0,0,0,0,0
0,0,0,0,0,0,0,0,0,0,0,0,0,0,0,0,0
0,0,0,0,0,0,0,0,0,0,0,0,0,0,0,0,0
0,0,0,0,0,0,0,0,0,0,0,0,0,0,0,0,0
0,0,0,0,0,0,0,0,0,0,0,0,0,0,0,0,0
0,0,0,0,0,0,0,0,0,0,0,0,0,0,0,0,0
2,2,10,10,2,0,0,0,0,0,0,0,0,0,0,0,0
10,6,6,6,6,10,2,0,0,0,0,0,0,0,0,0,0
0,2,6,6,2,6,6,10,0,0,0,0,0,0,0,2,0
0,0,10,10,2,6,6,2,2,0,0,0,0,0,2,2,1
1,1,0,0,0,10,10,2,0,0,0,0,0,0,0,1,1
1,1,1,0,0,0,0,0,0,0,0,0,0,0,1,1,1
endlayer

layer
0,0,0,0,0,0,0,0,0,0,0,2,0,0,0,0,1
0,0,0,0,0,0,0,0,0,0,2,2,10,10,0,0,0
0,0,0,0,0,0,0,0,0,0,10,6,6,6,2,2,0
0,0,0,0,0,0,0,0,0,0,0,10,6,6,6,2,0
0,0,0,0,0,0,0,0,0,0,0,0,2,10,6,6,2
0,0,0,0,0,0,0,0,0,0,0,0,0,0,2,10,2
0,0,0,0,0,0,0,0,0,0,0,0,0,0,0,0,0
0,0,0,0,0,0,0,0,0,0,0,0,0,0,0,0,0
0,0,0,0,0,0,0,0,0,0,0,0,0,0,0,0,0
0,0,0,0,0,0,0,0,0,0,0,0,0,0,0,0,0
0,0,0,0,0,0,0,0,0,0,0,0,0,0,0,0,0
0,0,0,0,0,0,0,0,0,0,0,0,0,0,0,0,0
0,0,0,0,0,0,0,0,0,0,0,0,0,0,0,0,0
2,2,10,10,2,0,0,0,0,0,0,0,0,0,0,0,0
10,6,6,6,6,10,2,0,0,0,0,0,0,0,0,0,0
0,2,6,6,2,6,6,10,0,0,0,0,0,0,0,0,0
0,0,10,10,2,6,6,2,2,0,0,0,0,0,0,0,0
0,0,0,0,0,10,10,2,0,0,0,0,0,0,0,0,1
1,1,0,0,0,0,0,0,0,0,0,0,0,0,0,1,1
endlayer

layer
0,0,0,0,0,0,0,0,0,0,0,2,0,0,0,0,0
0,0,0,0,0,0,0,0,0,0,2,2,10,10,0,0,0
0,0,0,0,0,0,0,0,0,0,10,6,6,6,2,2,0
0,0,0,0,0,0,0,0,0,0,0,10,6,6,6,2,0
0,0,0,0,0,0,0,0,0,0,0,0,2,10,10,2,0
0,0,0,0,0,0,0,0,0,0,0,0,0,0,2,0,0
0,0,0,0,0,0,0,0,0,0,0,0,0,0,0,0,0
0,0,0,0,0,0,0,0,0,0,0,0,0,0,0,0,0
0,0,0,0,0,0,0,0,0,0,0,0,0,0,0,0,0
0,0,0,0,0,0,0,0,0,0,0,0,0,0,0,0,0
0,0,0,0,0,0,0,0,0,0,0,0,0,0,0,0,0
0,0,0,0,0,0,0,0,0,0,0,0,0,0,0,0,0
0,0,0,0,0,0,0,0,0,0,0,0,0,0,0,0,0
10,2,2,10,2,0,0,0,0,0,0,0,0,0,0,0,0
10,6,6,6,6,10,2,0,0,0,0,0,0,0,0,0,0
0,2,6,6,2,6,6,10,0,0,0,0,0,0,0,0,0
0,0,10,10,2,6,6,2,2,0,0,0,0,0,0,0,0
0,0,0,0,0,10,10,2,0,0,0,0,0,0,0,0,0
0,0,0,0,0,0,0,0,0,0,0,0,0,0,0,0,0
endlayer

layer
0,0,0,0,0,0,0,0,0,0,0,2,0,0,0,0,0
0,0,0,0,0,0,0,0,0,0,2,2,10,10,0,0,0
0,0,0,0,0,0,0,0,0,0,10,6,6,6,2,0,0
0,0,0,0,0,0,0,0,0,0,0,10,10,10,2,2,0
0,0,0,0,0,0,0,0,0,0,0,0,2,10,2,2,0
0,0,0,0,0,0,0,0,0,0,0,0,0,0,2,0,0
0,0,0,0,0,0,0,0,0,0,0,0,0,0,0,0,0
0,0,0,0,0,0,0,0,0,0,0,0,0,0,0,0,0
0,0,0,0,0,0,0,0,0,0,0,0,0,0,0,0,0
0,0,0,0,0,0,0,0,0,0,0,0,0,0,0,0,0
0,0,0,0,0,0,0,0,0,0,0,0,0,0,0,0,0
0,0,0,0,0,0,0,0,0,0,0,0,0,0,0,0,0
0,0,0,0,0,0,0,0,0,0,0,0,0,0,0,0,0
10,2,2,10,2,0,0,0,0,0,0,0,0,0,0,0,0
10,6,6,6,6,10,2,0,0,0,0,0,0,0,0,0,0
0,2,6,6,2,6,6,10,0,0,0,0,0,0,0,0,0
0,0,10,10,2,6,6,2,2,0,0,0,0,0,0,0,0
0,0,0,0,0,10,10,2,0,0,0,0,0,0,0,0,0
0,0,0,0,0,0,0,0,0,0,0,0,0,0,0,0,0
endlayer

layer
0,0,0,0,0,0,0,0,0,0,0,2,0,0,0,0,0
0,0,0,0,0,0,0,0,0,0,2,2,2,2,0,0,0
0,0,0,0,0,0,0,0,0,0,2,2,4,2,2,0,0
0,0,0,0,0,0,0,0,0,0,0,0,2,2,2,0,0
0,0,0,0,0,0,0,0,0,0,0,0,2,0,0,0,0
0,0,0,0,0,0,0,0,0,0,0,0,0,0,0,0,0
0,0,0,0,0,0,0,0,0,0,0,0,0,0,0,0,0
0,0,0,0,0,0,0,0,0,0,0,0,0,0,0,0,0
0,0,0,0,0,0,0,0,0,0,0,0,0,0,0,0,0
0,0,0,0,0,0,0,0,0,0,0,0,0,0,0,0,0
0,0,0,0,0,0,0,0,0,0,0,0,0,0,0,0,0
0,0,0,0,0,0,0,0,0,0,0,0,0,0,0,0,0
0,0,0,0,0,0,0,0,0,0,0,0,0,0,0,0,0
10,2,2,10,2,0,0,0,0,0,0,0,0,0,0,0,0
10,6,6,6,6,10,2,0,0,0,0,0,0,0,0,0,0
0,2,6,6,2,6,6,10,0,0,0,0,0,0,0,0,0
0,0,10,10,2,6,6,2,0,0,0,0,0,0,0,0,0
0,0,0,0,0,10,10,2,0,0,0,0,0,0,0,0,0
0,0,0,0,0,0,0,0,0,0,0,0,0,0,0,0,0
endlayer

layer
0,0,0,0,0,0,0,0,0,0,0,2,0,0,0,0,0
0,0,0,0,0,0,0,0,0,0,2,2,2,2,0,0,0
0,0,0,0,0,0,0,0,0,0,2,2,2,2,0,0,0
0,0,0,0,0,0,0,0,0,0,0,0,0,0,0,0,0
0,0,0,0,0,0,0,0,0,0,0,0,0,0,0,0,0
0,0,0,0,0,0,0,0,0,0,0,0,0,0,0,0,0
0,0,0,0,0,0,0,0,0,0,0,0,0,0,0,0,0
0,0,0,0,0,0,0,0,0,0,0,0,0,0,0,0,0
0,0,0,0,0,0,0,0,0,0,0,0,0,0,0,0,0
0,0,0,0,0,0,0,0,0,0,0,0,0,0,0,0,0
0,0,0,0,0,0,0,0,0,0,0,0,0,0,0,0,0
0,0,0,0,0,0,0,0,0,0,0,0,0,0,0,0,0
0,0,0,0,0,0,0,0,0,0,0,0,0,0,0,0,0
10,2,2,10,2,0,0,0,0,0,0,0,0,0,0,0,0
10,6,6,6,6,10,2,0,0,0,0,0,0,0,0,0,0
0,2,6,6,2,6,6,2,0,0,0,0,0,0,0,0,0
0,0,10,10,2,6,6,2,0,0,0,0,0,0,0,0,0
0,0,0,0,0,10,10,2,0,0,0,0,0,0,0,0,0
0,0,0,0,0,0,0,0,0,0,0,0,0,0,0,0,0
endlayer

layer
0,0,0,0,0,0,0,0,0,0,0,2,0,0,0,0,0
0,0,0,0,0,0,0,0,0,0,0,2,0,0,0,0,0
0,0,0,0,0,0,0,0,0,0,0,0,0,0,0,0,0
0,0,0,0,0,0,0,0,0,0,0,0,0,0,0,0,0
0,0,0,0,0,0,0,0,0,0,0,0,0,0,0,0,0
0,0,0,0,0,0,0,0,0,0,0,0,0,0,0,0,0
0,0,0,0,0,0,0,0,0,0,0,0,0,0,0,0,0
0,0,0,0,0,0,0,0,0,0,0,0,0,0,0,0,0
0,0,0,0,0,0,0,0,0,0,0,0,0,0,0,0,0
0,0,0,0,0,0,0,0,0,0,0,0,0,0,0,0,0
0,0,0,0,0,0,0,0,0,0,0,0,0,0,0,0,0
0,0,0,0,0,0,0,0,0,0,0,0,0,0,0,0,0
0,0,0,0,0,0,0,0,0,0,0,0,0,0,0,0,0
10,10,10,10,2,0,0,0,0,0,0,0,0,0,0,0,0
10,6,6,6,2,2,2,0,0,0,0,0,0,0,0,0,0
0,2,6,6,2,4,2,0,0,0,0,0,0,0,0,0,0
0,0,10,10,2,2,2,0,0,0,0,0,0,0,0,0,0
0,0,0,0,0,0,0,0,0,0,0,0,0,0,0,0,0
0,0,0,0,0,0,0,0,0,0,0,0,0,0,0,0,0
endlayer

layer
0,0,0,0,0,0,0,0,0,0,0,0,0,0,0,0,0
0,0,0,0,0,0,0,0,0,0,0,0,0,0,0,0,0
0,0,0,0,0,0,0,0,0,0,0,0,0,0,0,0,0
0,0,0,0,0,0,0,0,0,0,0,0,0,0,0,0,0
0,0,0,0,0,0,0,0,0,0,0,0,0,0,0,0,0
0,0,0,0,0,0,0,0,0,0,0,0,0,0,0,0,0
0,0,0,0,0,0,0,0,0,0,0,0,0,0,0,0,0
0,0,0,0,0,0,0,0,0,0,0,0,0,0,0,0,0
0,0,0,0,0,0,0,0,0,0,0,0,0,0,0,0,0
0,0,0,0,0,0,0,0,0,0,0,0,0,0,0,0,0
0,0,0,0,0,0,0,0,0,0,0,0,0,0,0,0,0
0,0,0,0,0,0,0,0,0,0,0,0,0,0,0,0,0
0,0,0,0,0,0,0,0,0,0,0,0,0,0,0,0,0
2,2,2,2,2,0,0,0,0,0,0,0,0,0,0,0,0
2,2,4,2,2,2,0,0,0,0,0,0,0,0,0,0,0
0,2,2,2,2,2,0,0,0,0,0,0,0,0,0,0,0
0,0,0,0,0,0,0,0,0,0,0,0,0,0,0,0,0
0,0,0,0,0,0,0,0,0,0,0,0,0,0,0,0,0
0,0,0,0,0,0,0,0,0,0,0,0,0,0,0,0,0
endlayer

layer
0,0,0,0,0,0,0,0,0,0,0,0,0,0,0,0,0
0,0,0,0,0,0,0,0,0,0,0,0,0,0,0,0,0
0,0,0,0,0,0,0,0,0,0,0,0,0,0,0,0,0
0,0,0,0,0,0,0,0,0,0,0,0,0,0,0,0,0
0,0,0,0,0,0,0,0,0,0,0,0,0,0,0,0,0
0,0,0,0,0,0,0,0,0,0,0,0,0,0,0,0,0
0,0,0,0,0,0,0,0,0,0,0,0,0,0,0,0,0
0,0,0,0,0,0,0,0,0,0,0,0,0,0,0,0,0
0,0,0,0,0,0,0,0,0,0,0,0,0,0,0,0,0
0,0,0,0,0,0,0,0,0,0,0,0,0,0,0,0,0
0,0,0,0,0,0,0,0,0,0,0,0,0,0,0,0,0
0,0,0,0,0,0,0,0,0,0,0,0,0,0,0,0,0
0,0,0,0,0,0,0,0,0,0,0,0,0,0,0,0,0
0,0,2,0,2,0,0,0,0,0,0,0,0,0,0,0,0
0,0,2,2,2,0,0,0,0,0,0,0,0,0,0,0,0
0,2,2,0,2,0,0,0,0,0,0,0,0,0,0,0,0
0,0,0,0,0,0,0,0,0,0,0,0,0,0,0,0,0
0,0,0,0,0,0,0,0,0,0,0,0,0,0,0,0,0
0,0,0,0,0,0,0,0,0,0,0,0,0,0,0,0,0
endlayer

