# Gilly's Adobe houses

# template generated by Ruins mod version 14.6 Ingame Parser
# Structure created by Gilly

weight=1
embed_into_distance=4
acceptable_target_blocks=
unacceptable_target_blocks=flowing_water,water,flowing_lava,lava,ice,bedrock,netherrack,soul_sand,Natura:Cloud
dimensions=11,25,16
allowable_overhang=0
max_leveling=7
leveling_buffer=-1
preserve_water=0
preserve_lava=0

rule1=0,100,preserveBlock
rule2=0,100,double_stone_slab-9
rule3=0,100,sandstone-2
rule4=0,100,wooden_door-5
rule5=0,100,wooden_door-6
rule6=0,100,wooden_door-7
rule7=0,100,wooden_door-8
rule8=0,100,stone_slab-1
rule9=0,100,spruce_stairs-0
rule10=0,100,spruce_stairs-2
rule11=0,100,hay_block-0
rule12=0,100,spruce_stairs-3
rule13=0,100,fence-0
rule14=0,100,sandstone_stairs-0
rule15=0,100,spruce_stairs-1
rule16=0,100,sandstone_stairs-2
rule17=0,100,sandstone_stairs-3
rule18=0,100,wooden_slab-1
rule19=0,100,sandstone_stairs-1

layer
1,1,2,2,2,2,2,2,2,2,1,1,1,1,1,1
1,1,2,1,1,1,1,1,2,1,1,1,1,1,1,1
1,1,2,1,1,1,1,1,2,1,1,1,1,1,1,1
1,1,2,1,1,1,1,1,2,1,1,1,1,1,1,1
1,1,2,1,1,1,1,1,2,1,1,1,1,1,1,1
1,1,2,1,1,1,1,1,2,2,2,2,2,1,1,1
1,1,2,2,2,2,2,2,2,2,2,2,2,1,1,1
1,1,1,1,1,2,1,1,1,1,1,2,1,1,1,1
1,1,1,1,1,2,1,1,1,1,1,2,1,1,1,1
1,1,1,1,1,2,1,1,1,1,1,2,1,1,1,1
2,2,2,2,2,2,1,1,1,1,1,2,2,2,2,1
2,1,1,1,1,1,2,1,1,1,1,2,2,2,2,1
2,1,1,1,1,1,2,2,2,2,2,2,2,2,2,1
2,1,1,1,1,1,2,1,1,1,1,1,2,2,2,1
2,1,1,1,1,1,2,1,1,1,1,1,2,2,1,1
2,1,1,1,1,1,2,1,1,1,1,1,2,1,1,1
2,2,2,2,2,2,2,1,1,1,1,1,2,1,1,1
2,1,1,1,1,2,2,1,1,1,1,1,2,2,2,2
1,1,1,1,1,2,2,2,2,2,2,2,2,2,2,2
1,1,1,1,1,2,2,2,2,2,1,1,1,1,1,2
1,1,1,1,1,1,1,1,1,2,1,1,1,1,1,2
1,1,1,1,1,1,1,1,1,2,1,1,1,1,1,2
1,1,1,1,1,1,1,1,1,2,1,1,1,1,1,2
1,1,1,1,1,1,1,1,1,2,1,1,1,1,1,2
1,1,1,1,1,1,1,1,2,2,2,2,2,2,2,2
endlayer

layer
1,1,2,2,2,2,2,2,2,2,1,1,1,1,1,1
1,1,2,1,1,1,1,1,2,1,1,1,1,1,1,1
1,1,2,1,1,1,1,1,2,1,1,1,1,1,1,1
1,1,2,1,1,1,1,1,2,1,1,1,1,1,1,1
1,1,2,1,1,1,1,1,2,1,1,1,1,1,1,1
1,1,2,1,1,1,1,1,2,2,2,2,2,1,1,1
1,1,2,2,2,2,2,2,2,2,2,2,2,1,1,1
1,1,1,1,1,2,1,1,1,1,1,2,1,1,1,1
1,1,1,1,1,2,1,1,1,1,1,2,1,1,1,1
1,1,1,1,1,2,1,1,1,1,1,2,1,1,1,1
2,2,2,2,2,2,1,1,1,1,1,2,2,2,2,1
2,1,1,1,1,1,2,1,1,1,1,2,2,2,2,1
2,1,1,1,1,1,2,2,2,2,2,2,2,2,2,1
2,1,1,1,1,1,2,1,1,1,1,1,2,2,2,1
2,1,1,1,1,1,2,1,1,1,1,1,2,2,1,1
2,1,1,1,1,1,2,1,1,1,1,1,2,1,1,1
2,2,2,2,2,2,2,1,1,1,1,1,2,1,1,1
2,1,1,1,1,2,2,1,1,1,1,1,2,2,2,2
1,1,1,1,1,2,2,2,2,2,2,2,2,2,2,2
1,1,1,1,1,2,2,2,2,2,1,1,1,1,1,2
1,1,1,1,1,1,1,1,1,2,1,1,1,1,1,2
1,1,1,1,1,1,1,1,1,2,1,1,1,1,1,2
1,1,1,1,1,1,1,1,1,2,1,1,1,1,1,2
1,1,1,1,1,1,1,1,1,2,1,1,1,1,1,2
1,1,1,1,1,1,1,1,2,2,2,2,2,2,2,2
endlayer

layer
1,1,2,2,2,2,2,2,2,2,1,1,1,1,1,1
1,1,2,1,1,1,1,1,2,2,1,1,1,1,1,1
1,1,2,1,1,1,1,1,2,1,1,1,1,1,1,1
1,1,2,1,1,1,1,1,2,1,1,1,1,1,1,1
1,1,2,1,1,1,1,1,2,1,1,1,1,1,1,1
1,1,2,1,1,1,1,1,2,2,2,1,1,1,1,1
1,1,2,2,2,2,2,2,2,2,2,2,2,1,1,1
1,1,1,1,1,2,1,1,1,1,1,2,2,1,1,1
1,1,1,1,1,2,1,1,1,1,1,2,1,1,1,1
1,1,1,1,1,2,1,1,1,1,1,2,1,1,1,1
2,2,2,2,2,2,1,1,1,1,1,2,2,1,1,1
2,1,1,1,1,1,2,1,1,1,1,2,2,2,1,1
2,1,1,1,1,1,2,2,2,2,2,2,2,2,1,1
2,1,1,1,1,1,2,1,1,1,1,1,2,2,1,1
2,1,1,1,1,1,2,1,1,1,1,1,2,2,1,1
2,1,1,1,1,1,2,1,1,1,1,1,2,1,1,1
2,2,2,2,2,2,2,1,1,1,1,1,2,1,1,1
2,2,1,1,1,2,2,1,1,1,1,1,2,2,2,1
1,1,1,1,1,2,2,2,2,2,2,2,2,2,2,2
1,1,1,1,1,1,1,2,2,2,1,1,1,1,1,2
1,1,1,1,1,1,1,1,1,2,1,1,1,1,1,2
1,1,1,1,1,1,1,1,1,2,1,1,1,1,1,2
1,1,1,1,1,1,1,1,1,2,1,1,1,1,1,2
1,1,1,1,1,1,1,1,2,2,1,1,1,1,1,2
1,1,1,1,1,1,1,1,2,2,2,2,2,2,2,2
endlayer

layer
1,1,2,2,2,2,2,2,2,1,1,1,1,1,1,1
1,1,2,1,1,1,1,1,2,2,1,1,1,1,1,1
1,1,2,1,1,1,1,1,2,2,1,1,1,1,1,1
1,1,2,1,1,1,1,1,2,2,1,1,1,1,1,1
1,1,2,1,1,1,1,1,2,2,1,1,1,1,1,1
1,1,2,1,1,1,1,1,2,2,1,1,1,1,1,1
1,1,2,2,2,2,2,2,2,2,2,2,1,1,1,1
1,1,1,1,1,2,1,1,1,1,1,2,2,1,1,1
1,1,1,1,1,2,1,1,1,1,1,2,2,1,1,1
1,1,1,1,1,2,1,1,1,1,1,2,2,1,1,1
2,2,2,2,2,2,1,1,1,1,1,2,2,1,1,1
2,1,1,1,1,1,2,1,1,1,1,2,2,1,1,1
2,1,1,1,1,1,2,2,2,2,2,2,2,1,1,1
2,1,1,1,1,1,2,1,1,1,1,1,2,2,1,1
2,1,1,1,1,1,2,1,1,1,1,1,2,2,1,1
2,1,1,1,1,1,2,1,1,1,1,1,2,2,1,1
2,2,2,2,2,2,2,1,1,1,1,1,2,2,1,1
1,2,2,2,2,2,2,1,1,1,1,1,2,2,1,1
1,1,1,1,1,1,2,2,2,2,2,2,2,2,2,2
1,1,1,1,1,1,1,1,2,2,1,1,1,1,1,2
1,1,1,1,1,1,1,1,2,2,1,1,1,1,1,2
1,1,1,1,1,1,1,1,2,2,1,1,1,1,1,2
1,1,1,1,1,1,1,1,2,2,1,1,1,1,1,2
1,1,1,1,1,1,1,1,2,2,1,1,1,1,1,2
1,1,1,1,1,1,1,1,1,2,2,2,2,2,2,2
endlayer

layer
1,1,3,2,2,3,2,2,3,1,1,1,1,1,1,1
1,1,2,2,2,2,2,2,2,1,1,1,1,1,1,1
1,1,2,2,2,2,2,2,2,2,1,1,1,1,1,1
1,1,3,2,2,2,2,2,2,2,1,1,1,1,1,1
1,1,2,2,2,2,2,2,2,2,1,1,1,1,1,1
1,1,2,2,2,2,2,2,2,1,1,1,1,1,1,1
1,1,3,2,2,2,2,2,2,2,2,3,1,1,1,1
1,1,1,1,1,2,2,2,2,2,2,2,1,1,1,1
1,1,1,1,1,2,2,2,2,2,2,2,2,1,1,1
1,1,1,1,1,2,2,2,2,2,2,2,2,1,1,1
3,2,2,3,2,2,2,2,2,2,2,2,2,1,1,1
2,2,2,2,2,2,2,2,2,2,2,2,1,1,1,1
2,2,2,2,2,2,2,2,2,2,2,2,3,1,1,1
3,2,2,2,2,2,2,2,2,2,2,2,2,1,1,1
2,2,2,2,2,2,2,2,2,2,2,2,2,2,1,1
2,2,2,2,2,2,2,2,2,2,2,2,2,2,1,1
3,2,2,2,2,2,2,2,2,2,2,2,2,2,1,1
1,1,2,2,2,1,2,2,2,2,2,2,2,1,1,1
1,1,1,1,1,1,3,2,2,2,2,2,2,2,2,3
1,1,1,1,1,1,1,1,1,2,2,2,2,2,2,2
1,1,1,1,1,1,1,1,2,2,2,2,2,2,2,2
1,1,1,1,1,1,1,1,2,2,2,2,2,2,2,3
1,1,1,1,1,1,1,1,2,2,2,2,2,2,2,2
1,1,1,1,1,1,1,1,1,2,2,2,2,2,2,2
1,1,1,1,1,1,1,1,1,3,2,2,3,2,2,3
endlayer

layer
1,1,2,2,2,2,2,2,2,1,1,1,1,1,1,1
1,1,2,0,0,0,0,0,2,1,1,1,1,1,1,1
1,1,2,0,0,0,0,0,3,1,1,1,1,1,1,1
1,1,2,0,0,0,0,0,4,1,1,1,1,1,1,1
1,1,2,0,0,0,0,0,3,1,1,1,1,1,1,1
1,1,2,0,0,0,0,0,2,1,1,1,1,1,1,1
1,1,2,2,2,2,2,2,2,2,2,2,1,1,1,1
1,1,1,1,1,2,0,0,0,0,0,2,1,1,1,1
1,1,1,1,1,2,0,0,0,0,0,3,1,1,1,1
1,1,1,1,1,2,0,0,0,0,0,4,1,1,1,1
2,2,2,2,2,2,0,0,0,0,0,3,1,1,1,1
2,0,0,0,0,0,2,0,0,0,0,2,1,1,1,1
2,0,0,0,0,0,2,2,2,2,2,2,2,1,1,1
2,0,0,0,0,0,2,0,0,0,0,0,2,1,1,1
2,0,0,0,0,0,2,0,0,0,0,0,3,1,1,1
2,0,0,0,0,0,2,0,0,0,0,0,4,1,1,1
2,2,3,5,3,2,2,0,0,0,0,0,3,1,1,1
1,1,1,1,1,1,2,0,0,0,0,0,2,1,1,1
1,1,1,1,1,1,2,2,2,2,2,2,2,2,2,2
1,1,1,1,1,1,1,1,1,2,0,0,0,0,0,2
1,1,1,1,1,1,1,1,1,3,0,0,0,0,0,2
1,1,1,1,1,1,1,1,1,6,0,0,0,0,0,2
1,1,1,1,1,1,1,1,1,3,0,0,0,0,0,2
1,1,1,1,1,1,1,1,1,2,0,0,0,0,0,2
1,1,1,1,1,1,1,1,1,2,2,2,2,2,2,2
endlayer

layer
1,1,3,2,0,2,0,2,3,1,1,1,1,1,1,1
1,1,2,0,0,0,0,0,2,1,1,1,1,1,1,1
1,1,0,0,0,0,0,0,3,1,1,1,1,1,1,1
1,1,2,0,0,0,0,0,7,1,1,1,1,1,1,1
1,1,0,0,0,0,0,0,3,1,1,1,1,1,1,1
1,1,2,0,0,0,0,0,2,1,1,1,1,1,1,1
1,1,3,2,2,0,2,2,2,2,2,3,1,1,1,1
1,1,1,1,1,2,0,0,0,0,0,2,1,1,1,1
1,1,1,1,1,0,0,0,0,0,0,3,1,1,1,1
1,1,1,1,1,2,0,0,0,0,0,7,1,1,1,1
3,2,0,2,2,2,0,0,0,0,0,3,1,1,1,1
2,0,0,0,0,0,2,0,0,0,0,2,1,1,1,1
0,0,0,0,0,0,2,2,2,2,2,2,3,1,1,1
2,0,0,0,0,0,2,0,0,0,0,0,2,1,1,1
0,0,0,0,0,0,2,0,0,0,0,0,3,1,1,1
2,0,0,0,0,0,2,0,0,0,0,0,7,1,1,1
3,2,3,7,3,2,2,0,0,0,0,0,3,1,1,1
1,1,1,1,1,1,2,0,0,0,0,0,2,1,1,1
1,1,1,1,1,1,3,2,2,2,2,2,2,2,2,3
1,1,1,1,1,1,1,1,1,2,0,0,0,0,0,2
1,1,1,1,1,1,1,1,1,3,0,0,0,0,0,0
1,1,1,1,1,1,1,1,1,7,0,0,0,0,0,2
1,1,1,1,1,1,1,1,1,3,0,0,0,0,0,0
1,1,1,1,1,1,1,1,1,2,0,0,0,0,0,2
1,1,1,1,1,1,1,1,1,3,2,0,2,0,2,3
endlayer

layer
1,1,2,2,2,2,2,2,2,1,1,1,1,1,1,1
1,1,2,0,0,0,0,0,2,1,1,1,1,1,1,1
1,1,2,0,0,0,0,0,2,1,1,1,1,1,1,1
1,1,2,0,0,0,0,0,3,1,1,1,1,1,1,1
1,1,2,0,0,0,0,0,2,1,1,1,1,1,1,1
1,1,2,0,0,0,0,0,2,1,1,1,1,1,1,1
1,1,2,2,2,2,2,2,2,2,2,2,1,1,1,1
1,1,1,1,1,2,0,0,0,0,0,2,1,1,1,1
1,1,1,1,1,2,0,0,0,0,0,2,1,1,1,1
1,1,1,1,1,2,0,0,0,0,0,3,1,1,1,1
2,2,2,2,2,2,0,0,0,0,0,2,1,1,1,1
2,0,0,0,0,0,2,0,0,0,0,2,1,1,1,1
2,0,0,0,0,0,2,2,2,2,2,2,2,1,1,1
2,0,0,0,0,0,2,0,0,0,0,0,2,1,1,1
2,0,0,0,0,0,2,0,0,0,0,0,2,1,1,1
2,0,0,0,0,0,2,0,0,0,0,0,3,1,1,1
2,2,2,3,2,2,2,0,0,0,0,0,2,1,1,1
1,1,1,1,1,1,2,0,0,0,0,0,2,1,1,1
1,1,1,1,1,1,2,2,2,2,2,2,2,2,2,2
1,1,1,1,1,1,1,1,1,2,0,0,0,0,0,2
1,1,1,1,1,1,1,1,1,2,0,0,0,0,0,2
1,1,1,1,1,1,1,1,1,3,0,0,0,0,0,2
1,1,1,1,1,1,1,1,1,2,0,0,0,0,0,2
1,1,1,1,1,1,1,1,1,2,0,0,0,0,0,2
1,1,1,1,1,1,1,1,1,2,2,2,2,2,2,2
endlayer

layer
1,1,3,2,2,3,2,2,3,1,1,1,1,1,1,1
1,1,2,0,0,0,0,0,2,1,1,1,1,1,1,1
1,1,2,0,0,0,0,0,2,1,1,1,1,1,1,1
1,1,3,0,0,0,0,0,2,1,1,1,1,1,1,1
1,1,2,0,0,0,0,0,2,1,1,1,1,1,1,1
1,1,2,0,0,0,0,0,2,1,1,1,1,1,1,1
1,1,3,2,2,2,2,2,2,2,2,3,1,1,1,1
1,1,1,1,1,2,0,0,0,0,0,2,1,1,1,1
1,1,1,1,1,2,0,0,0,0,0,2,1,1,1,1
1,1,1,1,1,2,0,0,0,0,0,2,1,1,1,1
3,2,2,3,2,2,0,0,0,0,0,2,1,1,1,1
2,0,0,0,0,0,2,0,0,0,0,2,1,1,1,1
2,0,0,0,0,0,2,2,2,2,2,2,3,1,1,1
3,0,0,0,0,0,2,0,0,0,0,0,2,1,1,1
2,0,0,0,0,0,2,0,0,0,0,0,2,1,1,1
2,0,0,0,0,0,2,0,0,0,0,0,2,1,1,1
3,2,2,2,2,2,2,0,0,0,0,0,2,1,1,1
1,1,1,1,1,1,2,0,0,0,0,0,2,1,1,1
1,1,1,1,1,1,3,2,2,2,2,2,2,2,2,3
1,1,1,1,1,1,1,1,1,2,0,0,0,0,0,2
1,1,1,1,1,1,1,1,1,2,0,0,0,0,0,2
1,1,1,1,1,1,1,1,1,2,0,0,0,0,0,3
1,1,1,1,1,1,1,1,1,2,0,0,0,0,0,2
1,1,1,1,1,1,1,1,1,2,0,0,0,0,0,2
1,1,1,1,1,1,1,1,1,3,2,2,3,2,2,3
endlayer

layer
1,1,8,9,9,9,9,9,8,1,1,1,1,1,1,1
1,1,12,11,11,11,11,11,10,1,1,1,1,1,1,1
1,1,12,11,11,11,11,11,10,1,1,1,1,1,1,1
1,1,12,11,11,13,11,11,10,1,1,1,1,1,1,1
1,1,12,11,11,11,11,11,10,1,1,1,1,1,1,1
1,1,12,11,11,11,11,11,10,1,1,1,1,1,1,1
1,1,8,15,15,15,2,2,14,14,3,8,1,1,1,1
1,1,1,1,1,3,0,0,0,0,0,3,1,1,1,1
1,1,1,1,1,17,0,0,0,0,0,16,1,1,1,1
1,1,1,1,1,17,0,0,0,0,0,16,1,1,1,1
8,14,14,14,14,14,0,0,0,0,0,16,1,1,1,1
17,18,18,18,18,18,2,0,0,0,0,3,1,1,1,1
17,18,18,18,18,18,3,2,2,2,3,14,8,1,1,1
17,18,18,0,18,18,16,2,2,2,2,2,16,1,1,1
17,18,18,18,18,18,16,2,11,11,11,2,16,1,1,1
17,18,18,18,18,18,16,2,11,13,11,2,16,1,1,1
8,19,19,19,19,19,8,2,11,11,11,2,16,1,1,1
1,1,1,1,1,1,17,2,2,2,2,2,16,1,1,1
1,1,1,1,1,1,8,19,19,17,14,14,14,14,14,8
1,1,1,1,1,1,1,1,1,17,18,18,18,18,18,16
1,1,1,1,1,1,1,1,1,17,18,18,18,18,18,16
1,1,1,1,1,1,1,1,1,17,18,18,0,18,18,16
1,1,1,1,1,1,1,1,1,17,18,18,18,18,18,16
1,1,1,1,1,1,1,1,1,17,18,18,18,18,18,16
1,1,1,1,1,1,1,1,1,8,19,19,19,19,19,8
endlayer

layer
1,1,1,1,1,1,1,1,1,1,1,1,1,1,1,1
1,1,1,1,1,1,1,1,1,1,1,1,1,1,1,1
1,1,1,1,1,1,1,1,1,1,1,1,1,1,1,1
1,1,1,1,1,1,1,1,1,1,1,1,1,1,1,1
1,1,1,1,1,1,1,1,1,1,1,1,1,1,1,1
1,1,1,1,1,1,1,1,1,1,1,1,1,1,1,1
1,1,1,1,1,1,8,1,1,1,8,1,1,1,1,1
1,1,1,1,1,8,8,8,8,8,8,8,1,1,1,1
1,1,1,1,1,1,8,8,8,8,8,1,1,1,1,1
1,1,1,1,1,1,8,8,0,8,8,1,1,1,1,1
1,1,1,1,1,1,8,8,8,8,8,1,1,1,1,1
1,1,1,1,1,1,8,8,8,8,8,8,1,1,1,1
1,1,1,1,1,1,8,1,1,1,8,1,1,1,1,1
1,1,1,1,1,1,1,1,1,1,1,1,1,1,1,1
1,1,1,1,1,1,1,1,1,1,1,1,1,1,1,1
1,1,1,1,1,1,1,1,1,1,1,1,1,1,1,1
1,1,1,1,1,1,1,1,1,1,1,1,1,1,1,1
1,1,1,1,1,1,1,1,1,1,1,1,1,1,1,1
1,1,1,1,1,1,1,1,1,1,1,1,1,1,1,1
1,1,1,1,1,1,1,1,1,1,1,1,1,1,1,1
1,1,1,1,1,1,1,1,1,1,1,1,1,1,1,1
1,1,1,1,1,1,1,1,1,1,1,1,1,1,1,1
1,1,1,1,1,1,1,1,1,1,1,1,1,1,1,1
1,1,1,1,1,1,1,1,1,1,1,1,1,1,1,1
1,1,1,1,1,1,1,1,1,1,1,1,1,1,1,1
endlayer

