# Gilly's Adobe houses

# template generated by Ruins mod version 14.6 Ingame Parser
# Structure created by Gilly

weight=1
embed_into_distance=4
acceptable_target_blocks=
unacceptable_target_blocks=flowing_water,water,flowing_lava,lava,ice,bedrock,netherrack,soul_sand,Natura:Cloud
dimensions=11,22,22
allowable_overhang=0
max_leveling=7
leveling_buffer=-1
preserve_water=0
preserve_lava=0

rule1=0,100,preserveBlock
rule2=0,100,double_stone_slab-9
rule3=0,100,sandstone-2
rule4=0,100,wooden_door-6
rule5=0,100,wooden_door-7
rule6=0,100,wooden_door-4
rule7=0,100,wooden_door-8
rule8=0,100,stone_slab-1
rule9=0,100,spruce_stairs-0
rule10=0,100,spruce_stairs-2
rule11=0,100,hay_block-0
rule12=0,100,spruce_stairs-3
rule13=0,100,sandstone_stairs-0
rule14=0,100,sandstone_stairs-2
rule15=0,100,sandstone_stairs-3
rule16=0,100,fence-0
rule17=0,100,stone_slab-9
rule18=0,100,spruce_stairs-1
rule19=0,100,sandstone_stairs-1
rule20=0,100,wooden_slab-1

layer
1,1,1,2,2,2,2,2,2,2,1,1,1,1,1,1,1,1,1,1,1,1
1,1,1,2,1,1,1,1,1,2,1,1,1,1,1,1,1,1,1,1,1,1
1,1,1,2,1,1,1,1,1,2,1,1,1,1,1,2,2,2,2,2,2,2
1,1,1,2,1,1,1,1,1,2,1,1,1,1,1,2,1,1,1,1,1,2
1,1,1,2,1,1,1,1,1,2,1,1,1,1,1,2,1,1,1,1,1,2
1,1,1,2,1,1,1,1,1,2,2,2,2,2,2,2,1,1,1,1,1,2
1,1,1,2,2,2,2,2,2,2,1,1,1,1,1,2,1,1,1,1,1,2
1,1,2,2,2,2,2,2,2,2,1,1,1,1,1,2,1,1,1,1,1,2
1,1,1,1,1,2,2,2,2,2,1,1,1,1,1,2,2,2,2,2,2,2
1,1,1,1,1,2,2,2,2,2,1,1,1,1,1,2,2,1,1,1,1,2
1,1,1,1,1,2,2,2,2,2,1,1,1,1,1,2,2,1,1,1,1,1
1,1,1,1,1,2,2,2,2,2,2,2,2,2,2,2,2,1,1,1,1,1
2,1,1,1,1,2,2,1,1,1,1,1,2,2,2,1,1,1,1,1,1,1
2,2,2,2,2,2,2,1,1,1,1,1,2,2,1,1,1,1,1,1,1,1
2,1,1,1,1,1,2,1,1,1,1,1,2,2,1,1,1,1,2,2,1,1
2,1,1,1,1,1,2,1,1,1,1,1,2,2,2,2,2,2,2,1,1,1
2,1,1,1,1,1,2,1,1,1,1,1,2,1,1,1,1,1,2,1,1,1
2,1,1,1,1,1,2,2,2,2,2,2,2,1,1,1,1,1,2,1,1,1
2,1,1,1,1,1,2,2,1,1,1,2,2,1,1,1,1,1,2,1,1,1
2,2,2,2,2,2,2,2,1,1,1,2,2,1,1,1,1,1,2,1,1,1
1,1,1,1,1,1,1,2,1,1,1,2,2,1,1,1,1,1,2,1,1,1
1,1,1,1,1,1,1,1,1,1,1,1,2,2,2,2,2,2,2,1,1,1
endlayer

layer
1,1,1,2,2,2,2,2,2,2,1,1,1,1,1,1,1,1,1,1,1,1
1,1,1,2,1,1,1,1,1,2,1,1,1,1,1,1,1,1,1,1,1,1
1,1,1,2,1,1,1,1,1,2,1,1,1,1,1,2,2,2,2,2,2,2
1,1,1,2,1,1,1,1,1,2,1,1,1,1,1,2,1,1,1,1,1,2
1,1,1,2,1,1,1,1,1,2,1,1,1,1,1,2,1,1,1,1,1,2
1,1,1,2,1,1,1,1,1,2,2,2,2,2,2,2,1,1,1,1,1,2
1,1,1,2,2,2,2,2,2,2,1,1,1,1,1,2,1,1,1,1,1,2
1,1,2,2,2,2,2,2,2,2,1,1,1,1,1,2,1,1,1,1,1,2
1,1,1,1,1,2,2,2,2,2,1,1,1,1,1,2,2,2,2,2,2,2
1,1,1,1,1,2,2,2,2,2,1,1,1,1,1,2,2,1,1,1,1,2
1,1,1,1,1,2,2,2,2,2,1,1,1,1,1,2,2,1,1,1,1,1
1,1,1,1,1,2,2,2,2,2,2,2,2,2,2,2,2,1,1,1,1,1
2,1,1,1,1,2,2,1,1,1,1,1,2,2,2,1,1,1,1,1,1,1
2,2,2,2,2,2,2,1,1,1,1,1,2,2,1,1,1,1,1,1,1,1
2,1,1,1,1,1,2,1,1,1,1,1,2,2,1,1,1,1,2,2,1,1
2,1,1,1,1,1,2,1,1,1,1,1,2,2,2,2,2,2,2,1,1,1
2,1,1,1,1,1,2,1,1,1,1,1,2,1,1,1,1,1,2,1,1,1
2,1,1,1,1,1,2,2,2,2,2,2,2,1,1,1,1,1,2,1,1,1
2,1,1,1,1,1,2,2,1,1,1,2,2,1,1,1,1,1,2,1,1,1
2,2,2,2,2,2,2,2,1,1,1,2,2,1,1,1,1,1,2,1,1,1
1,1,1,1,1,1,1,2,1,1,1,2,2,1,1,1,1,1,2,1,1,1
1,1,1,1,1,1,1,1,1,1,1,1,2,2,2,2,2,2,2,1,1,1
endlayer

layer
1,1,1,2,2,2,2,2,2,2,1,1,1,1,1,1,1,1,1,1,1,1
1,1,1,2,1,1,1,1,1,2,1,1,1,1,1,1,1,1,1,1,1,1
1,1,1,2,1,1,1,1,1,2,1,1,1,1,1,2,2,2,2,2,2,2
1,1,1,2,1,1,1,1,1,2,1,1,1,1,1,2,1,1,1,1,1,2
1,1,1,2,1,1,1,1,1,2,1,1,1,1,1,2,1,1,1,1,1,2
1,1,1,2,1,1,1,1,1,2,2,2,2,2,2,2,1,1,1,1,1,2
1,1,1,2,2,2,2,2,2,2,1,1,1,1,1,2,1,1,1,1,1,2
1,1,1,2,2,2,2,2,2,2,1,1,1,1,1,2,1,1,1,1,1,2
1,1,1,1,1,1,2,2,2,2,1,1,1,1,1,2,2,2,2,2,2,2
1,1,1,1,1,1,2,2,2,2,1,1,1,1,1,2,2,1,1,1,2,2
1,1,1,1,1,1,2,2,2,2,1,1,1,1,1,2,2,1,1,1,1,1
1,1,1,1,1,2,2,2,2,2,2,2,2,2,2,2,1,1,1,1,1,1
2,2,1,1,1,2,2,1,1,1,1,1,2,2,1,1,1,1,1,1,1,1
2,2,2,2,2,2,2,1,1,1,1,1,2,2,1,1,1,1,1,1,1,1
2,1,1,1,1,1,2,1,1,1,1,1,2,2,1,1,1,2,2,1,1,1
2,1,1,1,1,1,2,1,1,1,1,1,2,2,2,2,2,2,2,1,1,1
2,1,1,1,1,1,2,1,1,1,1,1,2,1,1,1,1,1,2,1,1,1
2,1,1,1,1,1,2,2,2,2,2,2,2,1,1,1,1,1,2,1,1,1
2,1,1,1,1,1,2,2,1,1,1,2,2,1,1,1,1,1,2,1,1,1
2,2,2,2,2,2,2,2,1,1,1,2,2,1,1,1,1,1,2,1,1,1
1,1,1,1,1,1,1,1,1,1,1,1,2,1,1,1,1,1,2,1,1,1
1,1,1,1,1,1,1,1,1,1,1,1,2,2,2,2,2,2,2,1,1,1
endlayer

layer
1,1,1,2,2,2,2,2,2,2,1,1,1,1,1,1,1,1,1,1,1,1
1,1,1,2,1,1,1,1,1,2,1,1,1,1,1,1,1,1,1,1,1,1
1,1,1,2,1,1,1,1,1,2,1,1,1,1,1,2,2,2,2,2,2,2
1,1,1,2,1,1,1,1,1,2,1,1,1,1,1,2,1,1,1,1,1,2
1,1,1,2,1,1,1,1,1,2,1,1,1,1,1,2,1,1,1,1,1,2
1,1,1,2,1,1,1,1,1,2,2,2,2,2,2,2,1,1,1,1,1,2
1,1,1,2,2,2,2,2,2,2,1,1,1,1,1,2,1,1,1,1,1,2
1,1,1,1,2,2,2,2,2,2,1,1,1,1,1,2,1,1,1,1,1,2
1,1,1,1,1,1,1,2,2,2,1,1,1,1,1,2,2,2,2,2,2,2
1,1,1,1,1,1,1,2,2,2,1,1,1,1,1,2,2,2,2,2,2,1
1,1,1,1,1,1,1,2,2,2,1,1,1,1,1,2,1,1,1,1,1,1
1,1,1,1,1,1,2,2,2,2,2,2,2,2,2,2,1,1,1,1,1,1
1,2,2,2,2,2,2,1,1,1,1,1,2,1,1,1,1,1,1,1,1,1
2,2,2,2,2,2,2,1,1,1,1,1,2,2,1,1,1,1,1,1,1,1
2,1,1,1,1,1,2,1,1,1,1,1,2,2,2,2,2,2,1,1,1,1
2,1,1,1,1,1,2,1,1,1,1,1,2,2,2,2,2,2,2,1,1,1
2,1,1,1,1,1,2,1,1,1,1,1,2,1,1,1,1,1,2,1,1,1
2,1,1,1,1,1,2,2,2,2,2,2,2,1,1,1,1,1,2,1,1,1
2,1,1,1,1,1,2,2,2,2,2,2,2,1,1,1,1,1,2,1,1,1
2,2,2,2,2,2,2,1,1,1,1,1,2,1,1,1,1,1,2,1,1,1
1,1,1,1,1,1,1,1,1,1,1,1,2,1,1,1,1,1,2,1,1,1
1,1,1,1,1,1,1,1,1,1,1,1,2,2,2,2,2,2,2,1,1,1
endlayer

layer
1,1,1,3,2,2,3,2,2,3,1,1,1,1,1,1,1,1,1,1,1,1
1,1,1,2,2,2,2,2,2,2,1,1,1,1,1,1,1,1,1,1,1,1
1,1,1,2,2,2,2,2,2,2,1,1,1,1,1,3,2,2,3,2,2,3
1,1,1,3,2,2,2,2,2,3,1,1,1,1,1,2,2,2,2,2,2,2
1,1,1,2,2,2,2,2,2,2,1,1,1,1,1,2,2,2,2,2,2,2
1,1,1,2,2,2,2,2,2,2,2,2,3,2,2,2,2,2,2,2,2,3
1,1,1,3,2,2,2,2,2,2,2,2,2,2,2,2,2,2,2,2,2,2
1,1,1,1,1,2,2,2,2,2,2,2,2,2,2,2,2,2,2,2,2,2
1,1,1,1,1,1,1,1,2,2,2,2,2,2,2,2,2,2,2,2,2,3
1,1,1,1,1,1,1,1,2,2,2,2,2,2,2,2,1,2,2,2,1,1
1,1,1,1,1,1,1,1,2,2,2,2,2,2,2,2,1,1,1,1,1,1
1,1,1,1,1,1,3,2,2,2,2,2,2,2,2,3,1,1,1,1,1,1
1,1,2,2,2,1,2,2,2,2,2,2,2,1,1,1,1,1,1,1,1,1
3,2,2,2,2,2,2,2,2,2,2,2,2,1,1,1,1,1,1,1,1,1
2,2,2,2,2,2,2,2,2,2,2,2,3,2,2,2,2,1,1,1,1,1
2,2,2,2,2,2,2,2,2,2,2,2,2,2,2,2,2,2,3,1,1,1
3,2,2,2,2,2,2,2,2,2,2,2,2,2,2,2,2,2,2,1,1,1
2,2,2,2,2,2,2,2,2,2,2,2,2,2,2,2,2,2,2,1,1,1
2,2,2,2,2,2,2,1,2,2,2,1,3,2,2,2,2,2,3,1,1,1
3,2,2,3,2,2,3,1,1,1,1,1,2,2,2,2,2,2,2,1,1,1
1,1,1,1,1,1,1,1,1,1,1,1,2,2,2,2,2,2,2,1,1,1
1,1,1,1,1,1,1,1,1,1,1,1,3,2,2,3,2,2,3,1,1,1
endlayer

layer
1,1,1,2,2,2,2,2,2,2,1,1,1,1,1,1,1,1,1,1,1,1
1,1,1,2,0,0,0,0,0,2,1,1,1,1,1,1,1,1,1,1,1,1
1,1,1,2,0,0,0,0,0,2,1,1,1,1,1,2,2,2,2,2,2,2
1,1,1,2,0,0,0,0,0,2,1,1,1,1,1,2,0,0,0,0,0,2
1,1,1,2,0,0,0,0,0,2,1,1,1,1,1,2,0,0,0,0,0,2
1,1,1,2,0,0,0,0,0,2,2,2,2,2,2,2,0,0,0,0,0,2
1,1,1,2,2,3,4,3,2,2,0,0,0,0,0,2,0,0,0,0,0,2
1,1,1,1,1,1,1,1,1,2,0,0,0,0,0,2,0,0,0,0,0,2
1,1,1,1,1,1,1,1,1,3,0,0,0,0,0,2,2,3,4,3,2,2
1,1,1,1,1,1,1,1,1,5,0,0,0,0,0,2,1,1,1,1,1,1
1,1,1,1,1,1,1,1,1,3,0,0,0,0,0,2,1,1,1,1,1,1
1,1,1,1,1,1,2,2,2,2,2,2,2,2,2,2,1,1,1,1,1,1
1,1,1,1,1,1,2,0,0,0,0,0,2,1,1,1,1,1,1,1,1,1
2,2,3,6,3,2,2,0,0,0,0,0,2,1,1,1,1,1,1,1,1,1
2,0,0,0,0,0,2,0,0,0,0,0,2,1,1,1,1,1,1,1,1,1
2,0,0,0,0,0,2,0,0,0,0,0,2,2,3,6,3,2,2,1,1,1
2,0,0,0,0,0,2,0,0,0,0,0,2,0,0,0,0,0,2,1,1,1
2,0,0,0,0,0,2,2,3,4,3,2,2,0,0,0,0,0,2,1,1,1
2,0,0,0,0,0,2,1,1,1,1,1,2,0,0,0,0,0,2,1,1,1
2,2,2,2,2,2,2,1,1,1,1,1,2,0,0,0,0,0,2,1,1,1
1,1,1,1,1,1,1,1,1,1,1,1,2,0,0,0,0,0,2,1,1,1
1,1,1,1,1,1,1,1,1,1,1,1,2,2,2,2,2,2,2,1,1,1
endlayer

layer
1,1,1,3,2,0,2,0,2,3,1,1,1,1,1,1,1,1,1,1,1,1
1,1,1,2,0,0,0,0,0,2,1,1,1,1,1,1,1,1,1,1,1,1
1,1,1,0,0,0,0,0,0,0,1,1,1,1,1,3,2,0,2,0,2,3
1,1,1,2,0,0,0,0,0,2,1,1,1,1,1,2,0,0,0,0,0,2
1,1,1,0,0,0,0,0,0,2,1,1,1,1,1,2,0,0,0,0,0,0
1,1,1,2,0,0,0,0,0,2,2,0,2,0,2,0,0,0,0,0,0,2
1,1,1,3,2,3,7,3,2,2,0,0,0,0,0,2,0,0,0,0,0,0
1,1,1,1,1,1,1,1,1,2,0,0,0,0,0,2,0,0,0,0,0,2
1,1,1,1,1,1,1,1,1,3,0,0,0,0,0,2,2,3,7,3,2,3
1,1,1,1,1,1,1,1,1,7,0,0,0,0,0,2,1,1,1,1,1,1
1,1,1,1,1,1,1,1,1,3,0,0,0,0,0,2,1,1,1,1,1,1
1,1,1,1,1,1,3,2,2,2,2,2,2,2,2,3,1,1,1,1,1,1
1,1,1,1,1,1,2,0,0,0,0,0,2,1,1,1,1,1,1,1,1,1
3,2,3,7,3,2,2,0,0,0,0,0,0,1,1,1,1,1,1,1,1,1
2,0,0,0,0,0,2,0,0,0,0,0,2,1,1,1,1,1,1,1,1,1
0,0,0,0,0,0,2,0,0,0,0,0,2,2,3,7,3,2,3,1,1,1
2,0,0,0,0,0,2,0,0,0,0,0,2,0,0,0,0,0,2,1,1,1
0,0,0,0,0,0,2,2,3,7,3,2,2,0,0,0,0,0,0,1,1,1
2,0,0,0,0,0,2,1,1,1,1,1,2,0,0,0,0,0,2,1,1,1
3,2,0,2,0,2,3,1,1,1,1,1,0,0,0,0,0,0,0,1,1,1
1,1,1,1,1,1,1,1,1,1,1,1,2,0,0,0,0,0,2,1,1,1
1,1,1,1,1,1,1,1,1,1,1,1,3,2,0,2,0,2,3,1,1,1
endlayer

layer
1,1,1,2,2,2,2,2,2,2,1,1,1,1,1,1,1,1,1,1,1,1
1,1,1,2,0,0,0,0,0,2,1,1,1,1,1,1,1,1,1,1,1,1
1,1,1,2,0,0,0,0,0,2,1,1,1,1,1,2,2,2,2,2,2,2
1,1,1,2,0,0,0,0,0,2,1,1,1,1,1,2,0,0,0,0,0,2
1,1,1,2,0,0,0,0,0,2,1,1,1,1,1,2,0,0,0,0,0,2
1,1,1,2,0,0,0,0,0,2,2,2,2,2,2,2,0,0,0,0,0,2
1,1,1,2,2,2,3,2,2,2,0,0,0,0,0,2,0,0,0,0,0,2
1,1,1,1,1,1,1,1,1,2,0,0,0,0,0,2,0,0,0,0,0,2
1,1,1,1,1,1,1,1,1,2,0,0,0,0,0,2,2,2,3,2,2,2
1,1,1,1,1,1,1,1,1,3,0,0,0,0,0,2,1,1,1,1,1,1
1,1,1,1,1,1,1,1,1,2,0,0,0,0,0,2,1,1,1,1,1,1
1,1,1,1,1,1,2,2,2,2,2,2,2,2,2,2,1,1,1,1,1,1
1,1,1,1,1,1,2,0,0,0,0,0,2,1,1,1,1,1,1,1,1,1
2,2,2,3,2,2,2,0,0,0,0,0,2,1,1,1,1,1,1,1,1,1
2,0,0,0,0,0,2,0,0,0,0,0,2,1,1,1,1,1,1,1,1,1
2,0,0,0,0,0,2,0,0,0,0,0,2,2,2,3,2,2,2,1,1,1
2,0,0,0,0,0,2,0,0,0,0,0,2,0,0,0,0,0,2,1,1,1
2,0,0,0,0,0,2,2,2,3,2,2,2,0,0,0,0,0,2,1,1,1
2,0,0,0,0,0,2,1,1,1,1,1,2,0,0,0,0,0,2,1,1,1
2,2,2,2,2,2,2,1,1,1,1,1,2,0,0,0,0,0,2,1,1,1
1,1,1,1,1,1,1,1,1,1,1,1,2,0,0,0,0,0,2,1,1,1
1,1,1,1,1,1,1,1,1,1,1,1,2,2,2,2,2,2,2,1,1,1
endlayer

layer
1,1,1,3,2,2,3,2,2,3,1,1,1,1,1,1,1,1,1,1,1,1
1,1,1,2,0,0,0,0,0,2,1,1,1,1,1,1,1,1,1,1,1,1
1,1,1,2,0,0,0,0,0,2,1,1,1,1,1,3,2,2,3,2,2,3
1,1,1,3,0,0,0,0,0,3,1,1,1,1,1,2,0,0,0,0,0,2
1,1,1,2,0,0,0,0,0,2,1,1,1,1,1,2,0,0,0,0,0,2
1,1,1,2,0,0,0,0,0,2,2,2,3,2,2,2,0,0,0,0,0,3
1,1,1,3,2,2,2,2,2,2,0,0,0,0,0,2,0,0,0,0,0,2
1,1,1,1,1,1,1,1,1,2,0,0,0,0,0,2,0,0,0,0,0,2
1,1,1,1,1,1,1,1,1,2,0,0,0,0,0,2,2,2,2,2,2,3
1,1,1,1,1,1,1,1,1,2,0,0,0,0,0,2,1,1,1,1,1,1
1,1,1,1,1,1,1,1,1,2,0,0,0,0,0,2,1,1,1,1,1,1
1,1,1,1,1,1,3,2,2,2,2,2,2,2,2,3,1,1,1,1,1,1
1,1,1,1,1,1,2,0,0,0,0,0,2,1,1,1,1,1,1,1,1,1
3,2,2,2,2,2,2,0,0,0,0,0,2,1,1,1,1,1,1,1,1,1
2,0,0,0,0,0,2,0,0,0,0,0,3,1,1,1,1,1,1,1,1,1
2,0,0,0,0,0,2,0,0,0,0,0,2,2,2,2,2,2,3,1,1,1
3,0,0,0,0,0,2,0,0,0,0,0,2,0,0,0,0,0,2,1,1,1
2,0,0,0,0,0,2,2,2,2,2,2,2,0,0,0,0,0,2,1,1,1
2,0,0,0,0,0,2,1,1,1,1,1,3,0,0,0,0,0,3,1,1,1
3,2,2,3,2,2,3,1,1,1,1,1,2,0,0,0,0,0,2,1,1,1
1,1,1,1,1,1,1,1,1,1,1,1,2,0,0,0,0,0,2,1,1,1
1,1,1,1,1,1,1,1,1,1,1,1,3,2,2,3,2,2,3,1,1,1
endlayer

layer
1,1,1,8,9,9,9,9,9,8,1,1,1,1,1,1,1,1,1,1,1,1
1,1,1,12,11,11,11,11,11,10,1,1,1,1,1,1,1,1,1,1,1,1
1,1,1,12,11,11,11,11,11,10,1,1,1,1,1,8,13,13,13,13,13,8
1,1,1,12,11,11,16,11,11,10,1,1,1,1,1,15,2,2,2,2,2,14
1,1,1,12,11,11,11,11,11,10,1,1,1,1,1,15,2,11,11,11,2,14
1,1,1,12,11,11,11,11,11,10,3,13,13,13,3,15,2,11,16,11,2,14
1,1,1,8,18,18,18,18,18,3,17,17,0,17,17,2,2,11,11,11,2,14
1,1,1,1,1,1,1,1,1,15,17,0,0,0,17,2,2,2,2,2,2,14
1,1,1,1,1,1,1,1,1,15,0,0,0,0,0,14,19,19,19,19,19,8
1,1,1,1,1,1,1,1,1,15,17,0,0,0,17,14,1,1,1,1,1,1
1,1,1,1,1,1,1,1,1,3,17,17,0,17,17,3,1,1,1,1,1,1
1,1,1,1,1,1,8,13,13,13,3,2,19,19,3,8,1,1,1,1,1,1
1,1,1,1,1,1,15,20,20,20,20,20,14,1,1,1,1,1,1,1,1,1
8,3,13,13,13,3,15,20,20,20,20,20,14,1,1,1,1,1,1,1,1,1
3,0,0,0,0,0,3,20,20,0,20,20,14,1,1,1,1,1,1,1,1,1
15,0,0,0,0,0,2,20,20,20,20,20,8,9,9,9,9,9,8,1,1,1
15,0,0,0,0,0,2,20,20,20,20,20,12,11,11,11,11,11,10,1,1,1
15,0,0,0,0,0,2,19,19,19,19,19,12,11,11,11,11,11,10,1,1,1
3,0,0,0,0,0,3,1,1,1,1,1,12,11,11,16,11,11,10,1,1,1
8,3,19,19,19,3,8,1,1,1,1,1,12,11,11,11,11,11,10,1,1,1
1,1,1,1,1,1,1,1,1,1,1,1,12,11,11,11,11,11,10,1,1,1
1,1,1,1,1,1,1,1,1,1,1,1,8,18,18,18,18,18,8,1,1,1
endlayer

layer
1,1,1,1,1,1,1,1,1,1,1,1,1,1,1,1,1,1,1,1,1,1
1,1,1,1,1,1,1,1,1,1,1,1,1,1,1,1,1,1,1,1,1,1
1,1,1,1,1,1,1,1,1,1,1,1,1,1,1,1,1,1,1,1,1,1
1,1,1,1,1,1,1,1,1,1,1,1,1,1,1,1,1,1,1,1,1,1
1,1,1,1,1,1,1,1,1,1,1,1,1,1,1,1,1,1,1,1,1,1
1,1,1,1,1,1,1,1,1,1,8,1,1,1,8,1,1,1,1,1,1,1
1,1,1,1,1,1,1,1,1,8,8,8,8,8,8,8,1,1,1,1,1,1
1,1,1,1,1,1,1,1,1,1,8,8,8,8,8,1,1,1,1,1,1,1
1,1,1,1,1,1,1,1,1,1,8,8,0,8,8,1,1,1,1,1,1,1
1,1,1,1,1,1,1,1,1,1,8,8,8,8,8,1,1,1,1,1,1,1
1,1,1,1,1,1,1,1,1,8,8,8,8,8,8,8,1,1,1,1,1,1
1,1,1,1,1,1,1,1,1,1,8,1,1,1,8,1,1,1,1,1,1,1
1,1,1,1,1,1,1,1,1,1,1,1,1,1,1,1,1,1,1,1,1,1
1,8,1,1,1,8,1,1,1,1,1,1,1,1,1,1,1,1,1,1,1,1
8,8,8,8,8,8,8,1,1,1,1,1,1,1,1,1,1,1,1,1,1,1
1,8,8,8,8,8,1,1,1,1,1,1,1,1,1,1,1,1,1,1,1,1
1,8,8,0,8,8,1,1,1,1,1,1,1,1,1,1,1,1,1,1,1,1
1,8,8,8,8,8,1,1,1,1,1,1,1,1,1,1,1,1,1,1,1,1
8,8,8,8,8,8,8,1,1,1,1,1,1,1,1,1,1,1,1,1,1,1
1,8,1,1,1,8,1,1,1,1,1,1,1,1,1,1,1,1,1,1,1,1
1,1,1,1,1,1,1,1,1,1,1,1,1,1,1,1,1,1,1,1,1,1
1,1,1,1,1,1,1,1,1,1,1,1,1,1,1,1,1,1,1,1,1,1
endlayer

