# Gilly's Skyport landing pad
# template generated by Ruins mod version 14.6 Ingame Parser
# Structure created by Gilly

weight=1
embed_into_distance=4
acceptable_target_blocks=
unacceptable_target_blocks=flowing_water,water,flowing_lava,lava,ice,bedrock,netherrack,soul_sand,Natura:Cloud
dimensions=24,18,23
allowable_overhang=0
max_leveling=3
leveling_buffer=-1
preserve_water=0
preserve_lava=0

rule1=0,100,preserveBlock
rule2=0,100,chisel:stonebricksmooth-12
rule3=0,100,chisel:cobblestone-10
rule4=0,100,chisel:factoryblock-1
rule5=0,100,minecraft:iron_bars-0
rule6=0,100,TConstruct:slime.pad-4
rule7=0,100,minecraft:glowstone-0
rule8=0,100,chisel:iron_bars-8
rule9=0,100,minecraft:ladder-5
rule10=0,100,minecraft:ladder-4
rule11=0,100,minecraft:stone_brick_stairs-0
rule12=0,100,minecraft:stained_glass_pane-3
rule13=0,100,minecraft:stone_brick_stairs-2
rule14=0,100,minecraft:stonebrick-0
rule15=0,100,minecraft:stone_brick_stairs-1
rule16=0,100,chisel:iron_bars-3
rule17=0,100,minecraft:stone_slab-5
rule18=0,100,minecraft:stone_slab-13
rule19=0,100,chisel:factoryblock-6
rule20=0,100,chisel:iron_bars-9
rule21=0,100,minecraft:stained_hardened_clay-3
rule22=0,100,minecraft:double_stone_slab-8

layer
1,1,1,1,1,1,1,1,1,1,1,1,1,1,1,1,1,1,1,1,1,1,1
1,1,1,1,1,1,1,1,1,1,1,1,1,1,2,1,1,1,1,1,1,1,1
1,1,1,1,1,1,1,1,4,3,3,3,3,3,2,2,1,1,1,1,1,1,1
1,1,1,1,1,1,1,1,3,2,2,2,2,2,2,2,1,1,1,1,1,1,1
3,3,3,3,3,3,3,3,2,2,5,5,5,2,2,2,2,1,1,1,1,1,1
3,2,2,2,2,2,2,2,2,2,5,6,5,2,2,2,2,1,1,1,1,1,1
3,2,2,2,2,2,2,2,2,2,5,5,5,2,2,2,2,2,1,1,1,1,1
3,2,2,2,2,2,2,2,2,2,0,0,0,4,4,2,2,2,1,1,1,1,1
3,2,2,2,2,2,2,2,4,0,0,0,0,0,4,2,2,2,1,1,1,1,1
3,2,2,2,2,2,2,2,9,8,0,0,0,0,4,7,2,2,1,1,1,1,1
3,2,2,2,2,2,2,2,10,8,0,0,0,0,4,2,2,2,1,1,1,1,1
3,2,2,2,2,2,2,2,4,0,0,0,0,0,4,2,2,1,1,1,1,1,1
3,2,2,2,2,2,2,2,2,2,2,2,2,2,2,2,2,1,1,1,1,1,1
3,2,2,2,2,2,2,2,2,3,1,1,1,1,1,4,1,1,1,1,1,1,1
3,2,2,2,2,2,2,2,2,3,1,1,1,1,1,1,1,1,1,1,1,1,1
3,3,3,3,3,3,3,3,3,3,1,1,1,1,1,1,1,1,1,1,1,1,1
1,1,1,1,1,1,1,1,1,1,1,1,1,1,1,1,1,1,1,1,1,1,1
1,1,1,1,1,1,1,1,1,1,1,1,1,1,1,1,1,1,1,1,1,1,1
endlayer

layer
1,1,1,1,1,1,1,1,1,1,1,1,1,1,2,1,1,1,1,1,1,1,1
1,1,1,1,1,1,1,1,1,2,2,2,2,2,2,2,1,1,1,1,1,1,1
1,1,1,1,1,1,1,1,4,4,4,4,4,4,2,2,1,1,1,1,1,1,1
1,1,1,1,1,1,1,2,4,2,2,2,2,2,2,2,2,1,1,1,1,1,1
1,1,1,1,1,1,1,2,4,2,5,5,5,2,2,2,2,1,1,1,1,1,1
1,11,11,11,11,11,11,2,4,2,5,0,5,2,2,2,2,2,1,1,1,1,1
1,13,12,2,2,2,2,2,4,2,5,5,5,2,2,2,2,2,1,1,1,1,1
1,13,12,7,2,2,2,4,2,2,0,0,0,4,2,2,2,2,1,1,1,1,1
1,13,12,2,2,2,2,2,4,0,0,0,0,0,14,12,2,2,1,1,1,1,1
1,13,12,2,2,2,2,2,9,8,0,0,0,0,14,12,2,2,1,1,1,1,1
1,13,12,2,2,2,2,2,10,8,0,0,0,0,14,12,2,2,1,1,1,1,1
1,13,12,2,2,2,2,2,4,0,0,0,0,0,14,12,2,2,1,1,1,1,1
1,13,12,7,2,2,2,2,2,2,2,2,2,2,2,2,2,1,1,1,1,1,1
1,13,12,2,2,2,2,2,4,4,4,4,4,4,4,4,1,1,1,1,1,1,1
1,15,15,15,15,15,15,15,13,1,1,1,1,1,1,1,1,1,1,1,1,1,1
1,1,1,1,1,1,1,1,1,1,1,1,1,1,1,1,1,1,1,1,1,1,1
1,1,1,1,1,1,1,1,1,1,1,1,1,1,1,1,1,1,1,1,1,1,1
1,1,1,1,1,1,1,1,1,1,1,1,1,1,1,1,1,1,1,1,1,1,1
endlayer

layer
1,1,1,1,1,1,1,1,1,1,1,1,1,1,2,1,1,1,1,1,1,1,1
1,1,1,1,1,1,1,1,1,1,1,1,1,1,2,2,1,1,1,1,1,1,1
1,1,1,1,1,1,1,1,4,16,16,16,16,16,2,2,2,1,1,1,1,1,1
1,1,1,1,1,1,1,1,16,2,2,2,2,2,2,2,2,1,1,1,1,1,1
1,1,1,1,1,1,1,1,16,2,5,5,5,2,2,2,2,2,1,1,1,1,1
1,1,1,1,1,1,1,1,16,2,5,6,5,2,2,2,2,2,1,1,1,1,1
1,1,17,11,11,11,11,1,16,2,5,5,5,2,2,2,2,2,1,1,1,1,1
1,1,17,13,12,2,2,4,2,2,0,0,0,4,2,2,2,2,2,1,1,1,1
1,1,17,13,12,7,2,2,4,0,0,0,0,0,18,12,2,2,2,1,1,1,1
1,1,17,13,12,2,2,2,9,8,0,0,0,0,18,12,2,2,2,1,1,1,1
1,1,17,13,12,2,2,2,10,8,0,0,0,0,18,12,2,2,2,1,1,1,1
1,1,17,13,12,7,2,2,4,0,0,0,0,0,18,12,2,2,1,1,1,1,1
1,1,17,13,12,2,2,2,2,2,2,2,2,2,2,2,2,1,1,1,1,1,1
1,1,17,15,15,15,15,15,4,1,1,1,1,1,1,4,1,1,1,1,1,1,1
1,1,1,1,1,1,1,1,1,1,1,1,1,1,1,1,1,1,1,1,1,1,1
1,1,1,1,1,1,1,1,1,1,1,1,1,1,1,1,1,1,1,1,1,1,1
1,1,1,1,1,1,1,1,1,1,1,1,1,1,1,1,1,1,1,1,1,1,1
1,1,1,1,1,1,1,1,1,1,1,1,1,1,1,1,1,1,1,1,1,1,1
endlayer

layer
1,1,1,1,1,1,1,1,1,1,1,1,1,1,2,1,1,1,1,1,1,1,1
1,1,1,1,1,1,1,1,1,2,2,2,2,2,2,2,1,1,1,1,1,1,1
1,1,1,1,1,1,1,1,4,4,4,4,4,4,2,2,2,1,1,1,1,1,1
1,1,1,1,1,1,1,2,4,2,2,2,2,2,2,2,2,1,1,1,1,1,1
1,1,1,1,1,1,1,2,4,2,5,5,5,2,2,2,2,2,1,1,1,1,1
1,1,1,1,1,1,1,2,4,2,5,0,5,2,2,2,2,2,1,1,1,1,1
1,1,1,1,1,1,1,2,4,2,5,5,5,2,2,2,2,2,2,1,1,1,1
1,1,1,1,17,11,11,4,2,2,0,0,0,4,2,2,2,2,2,1,1,1,1
1,1,1,1,17,13,12,7,4,0,0,0,0,0,18,12,2,2,2,1,1,1,1
1,1,1,1,17,13,12,2,9,8,0,0,0,0,18,12,2,2,2,1,1,1,1
1,1,1,1,17,13,12,2,10,8,0,0,0,0,18,12,2,2,2,1,1,1,1
1,1,1,1,17,13,12,7,4,0,0,0,0,0,18,12,2,2,2,1,1,1,1
1,1,1,1,17,15,15,4,2,2,2,2,2,2,2,2,2,1,1,1,1,1,1
1,1,1,1,1,1,1,1,4,4,4,4,4,4,4,4,1,1,1,1,1,1,1
1,1,1,1,1,1,1,1,1,1,1,1,1,1,1,1,1,1,1,1,1,1,1
1,1,1,1,1,1,1,1,1,1,1,1,1,1,1,1,1,1,1,1,1,1,1
1,1,1,1,1,1,1,1,1,1,1,1,1,1,1,1,1,1,1,1,1,1,1
1,1,1,1,1,1,1,1,1,1,1,1,1,1,1,1,1,1,1,1,1,1,1
endlayer

layer
1,1,1,1,1,1,1,1,1,1,1,1,1,1,2,1,1,1,1,1,1,1,1
1,1,1,1,1,1,1,1,1,1,1,1,1,1,2,2,1,1,1,1,1,1,1
1,1,1,1,1,1,1,1,4,16,16,16,16,16,2,2,2,1,1,1,1,1,1
1,1,1,1,1,1,1,1,16,2,2,2,2,2,2,2,2,1,1,1,1,1,1
1,1,1,1,1,1,1,1,16,2,5,5,5,2,2,2,2,2,1,1,1,1,1
1,1,1,1,1,1,1,1,16,2,5,6,5,2,2,2,2,2,1,1,1,1,1
1,1,1,1,1,1,1,1,16,2,5,5,5,2,2,2,2,2,2,1,1,1,1
1,1,1,1,1,1,1,4,2,2,0,0,0,4,2,2,2,2,2,1,1,1,1
1,1,1,1,1,1,17,19,4,0,0,0,0,0,18,12,2,2,2,1,1,1,1
1,1,1,1,1,1,17,19,9,8,0,0,0,0,18,12,2,2,2,1,1,1,1
1,1,1,1,1,1,17,19,10,8,0,0,0,0,18,12,2,2,2,1,1,1,1
1,1,1,1,1,1,17,19,4,0,0,0,0,0,18,12,2,2,2,1,1,1,1
1,1,1,1,1,1,1,4,2,2,2,2,2,2,2,2,2,1,1,1,1,1,1
1,1,1,1,1,1,1,1,4,1,1,1,1,1,1,4,1,1,1,1,1,1,1
1,1,1,1,1,1,1,1,1,1,1,1,1,1,1,1,1,1,1,1,1,1,1
1,1,1,1,1,1,1,1,1,1,1,1,1,1,1,1,1,1,1,1,1,1,1
1,1,1,1,1,1,1,1,1,1,1,1,1,1,1,1,1,1,1,1,1,1,1
1,1,1,1,1,1,1,1,1,1,1,1,1,1,1,1,1,1,1,1,1,1,1
endlayer

layer
1,1,1,1,1,1,1,1,1,1,1,1,1,1,2,1,1,1,1,1,1,1,1
1,1,1,1,1,1,1,1,1,2,2,2,2,2,2,2,1,1,1,1,1,1,1
1,1,1,1,1,1,1,1,4,4,4,4,4,4,2,2,2,1,1,1,1,1,1
1,1,1,1,1,1,1,2,4,2,2,2,2,2,2,2,2,1,1,1,1,1,1
1,1,1,1,0,0,0,2,4,2,5,5,5,2,2,2,2,2,1,1,1,1,1
1,1,1,0,0,0,0,2,4,2,5,0,5,2,2,2,2,2,1,1,1,1,1
1,1,1,0,0,0,0,2,4,2,5,5,5,2,2,2,2,2,2,1,1,1,1
1,1,0,0,0,0,0,4,2,2,0,0,0,4,2,2,2,2,2,1,1,1,1
1,1,0,0,0,0,0,0,4,0,0,0,0,0,18,12,2,2,2,1,1,1,1
1,1,0,0,0,0,0,0,9,8,0,0,0,0,18,12,2,2,2,1,1,1,1
1,1,0,0,0,0,0,0,10,8,0,0,0,0,18,12,2,2,2,1,1,1,1
1,1,0,0,0,0,0,0,4,0,0,0,0,0,18,12,2,2,2,1,1,1,1
1,1,1,0,0,0,0,4,2,2,2,2,2,2,2,2,2,0,0,1,1,1,1
1,1,1,0,0,0,0,0,4,4,4,4,4,4,4,4,0,0,0,1,1,1,1
1,1,1,1,0,0,0,0,0,0,0,0,0,0,0,0,0,0,1,1,1,1,1
1,1,1,1,1,1,0,0,0,0,0,0,0,0,0,0,0,1,1,1,1,1,1
1,1,1,1,1,1,1,1,1,0,0,0,0,0,1,1,1,1,1,1,1,1,1
1,1,1,1,1,1,1,1,1,1,1,1,1,1,1,1,1,1,1,1,1,1,1
endlayer

layer
1,1,1,1,1,1,1,0,0,0,0,0,0,0,2,1,1,1,1,1,1,1,1
1,1,1,1,1,0,0,0,0,0,0,0,0,0,2,2,0,0,1,1,1,1,1
1,1,1,0,0,0,0,0,4,16,16,16,16,16,2,2,2,0,0,0,1,1,1
1,1,0,0,0,0,0,0,16,2,2,2,2,2,2,2,2,0,0,0,0,1,1
1,1,0,0,0,0,0,0,16,2,5,5,5,2,2,2,2,2,0,0,0,1,1
1,0,0,0,0,0,0,0,16,2,5,6,5,2,2,2,2,2,0,0,0,0,1
1,0,0,0,0,0,0,0,16,2,5,5,5,2,2,2,2,2,2,0,0,0,1
0,0,0,0,0,0,0,4,2,2,0,0,0,4,2,2,2,2,2,0,0,0,1
0,0,0,0,0,0,0,0,4,0,0,0,0,0,18,12,2,2,2,0,0,0,1
0,0,0,0,0,0,0,0,9,8,0,0,0,0,18,12,2,2,2,0,0,0,1
0,0,0,0,0,0,0,0,10,8,0,0,0,0,18,12,2,2,2,0,0,0,1
0,0,0,0,0,0,0,0,4,0,0,0,0,0,18,12,2,2,2,0,0,1,1
1,0,0,0,0,0,0,4,2,2,2,2,2,2,2,2,2,0,0,0,0,1,1
1,0,0,0,0,0,0,0,4,0,0,0,0,0,0,4,0,0,0,0,0,1,1
1,1,0,0,0,0,0,0,0,0,0,0,0,0,0,0,0,0,0,0,1,1,1
1,1,1,0,0,0,0,0,0,0,0,0,0,0,0,0,0,0,0,1,1,1,1
1,1,1,1,0,0,0,0,0,0,0,0,0,0,0,0,0,0,1,1,1,1,1
1,1,1,1,1,1,1,0,0,0,0,0,0,0,0,0,1,1,1,1,1,1,1
endlayer

layer
1,1,1,1,0,0,0,0,0,0,0,0,0,0,2,0,0,0,0,1,1,1,1
1,1,0,0,0,0,0,0,0,2,2,2,2,2,2,2,0,0,0,0,0,1,1
1,0,0,0,0,0,0,0,4,4,4,4,4,4,2,2,2,0,0,0,0,0,1
1,0,0,0,0,0,0,2,4,2,2,2,2,2,2,2,2,0,0,0,0,0,1
0,0,0,0,0,0,0,2,4,2,5,5,5,2,2,2,2,2,0,0,0,0,0
0,0,0,0,0,0,0,2,4,2,5,0,5,2,2,2,2,2,0,0,0,0,0
0,0,0,0,0,0,0,2,4,2,5,5,5,2,2,2,2,2,2,0,0,0,0
0,0,0,0,0,0,0,4,2,2,0,0,0,4,2,2,2,2,2,0,0,0,0
0,0,0,0,0,0,0,0,4,0,0,0,0,0,14,2,2,2,2,0,0,0,0
0,0,0,0,0,0,0,0,9,8,0,0,0,0,14,7,2,2,2,0,0,0,0
0,0,0,0,0,0,0,0,10,8,0,0,0,0,14,2,2,2,2,0,0,0,0
0,0,0,0,0,0,0,0,4,0,0,0,0,0,14,2,2,2,2,0,0,0,0
0,0,0,0,0,0,0,4,2,2,2,2,2,2,2,2,2,0,0,0,0,0,0
0,0,0,0,0,0,0,0,4,4,4,4,4,4,4,4,0,0,0,0,0,0,1
1,0,0,0,0,0,0,0,0,0,0,0,0,0,0,0,0,0,0,0,0,0,1
1,0,0,0,0,0,0,0,0,0,0,0,0,0,0,0,0,0,0,0,0,1,1
1,1,0,0,0,0,0,0,0,0,0,0,0,0,0,0,0,0,0,0,1,1,1
1,1,1,1,0,0,0,0,0,0,0,0,0,0,0,0,0,0,0,1,1,1,1
endlayer

layer
1,1,0,0,0,0,0,0,0,0,0,0,0,0,2,0,0,0,0,0,0,1,1
1,0,0,0,0,0,0,0,0,0,0,0,0,0,2,2,0,0,0,0,0,0,1
0,0,0,0,0,0,0,0,3,3,3,3,3,3,3,2,2,0,0,0,0,0,0
0,0,0,0,0,0,0,0,3,3,3,3,3,3,3,2,2,0,0,0,0,0,0
0,0,0,0,0,0,0,0,3,3,5,5,5,3,3,3,2,2,0,0,0,0,0
0,0,0,0,0,0,0,0,3,3,5,6,5,3,3,3,2,2,0,0,0,0,0
0,0,0,0,0,0,0,0,3,3,5,5,5,3,3,3,3,3,3,0,0,0,0
0,0,0,0,0,0,0,4,3,3,0,0,0,3,3,3,3,3,3,0,0,0,0
0,0,0,0,0,0,0,0,4,0,0,0,0,0,0,17,3,3,3,0,0,0,0
0,0,0,0,0,0,0,0,9,8,0,0,0,0,0,17,3,3,3,0,0,0,0
0,0,0,0,0,0,0,0,10,8,0,0,0,0,0,17,3,3,3,0,0,0,0
0,0,0,0,0,0,0,0,4,0,0,0,0,0,0,17,3,3,3,0,0,0,0
0,0,0,0,0,0,0,4,2,3,3,3,3,3,3,3,3,0,0,0,0,0,0
0,0,0,0,0,0,0,0,4,0,0,0,0,0,0,4,0,0,0,0,0,0,0
0,0,0,0,0,0,0,0,0,0,0,0,0,0,0,0,0,0,0,0,0,0,0
0,0,0,0,0,0,0,0,0,0,0,0,0,0,0,0,0,0,0,0,0,0,0
1,0,0,0,0,0,0,0,0,0,0,0,0,0,0,0,0,0,0,0,0,0,1
1,1,0,0,0,0,0,0,0,0,0,0,0,0,0,0,0,0,0,0,0,1,1
endlayer

layer
1,0,0,0,0,0,0,0,0,0,0,0,0,0,2,0,0,0,0,0,0,0,1
0,0,0,0,0,0,0,0,0,0,0,0,0,0,2,2,0,0,0,0,0,0,0
0,0,0,0,0,0,0,0,0,0,0,0,0,0,0,2,2,0,0,0,0,0,0
0,0,0,0,0,0,0,0,0,0,0,0,0,0,0,2,2,0,0,0,0,0,0
0,0,0,0,0,0,0,0,0,0,0,0,0,0,0,0,2,2,0,0,0,0,0
0,0,0,0,0,0,0,0,0,0,0,0,0,0,0,0,2,2,0,0,0,0,0
0,0,0,0,0,0,0,0,0,20,5,5,5,20,20,20,4,0,4,0,0,0,0
0,0,0,0,0,0,0,4,0,20,0,0,0,0,0,0,0,0,0,0,0,0,0
0,0,0,0,0,0,0,0,4,5,0,0,0,0,0,0,0,0,0,0,0,0,0
0,0,0,0,0,0,0,0,9,5,0,0,0,0,0,0,0,0,0,0,0,0,0
0,0,0,0,0,0,0,0,10,5,0,0,0,0,0,0,0,0,0,0,0,0,0
0,0,0,0,0,0,0,0,4,5,0,0,0,0,0,0,4,0,4,0,0,0,0
0,0,0,0,0,0,0,4,2,4,20,20,20,20,20,4,0,0,0,0,0,0,0
0,0,0,0,0,0,0,0,4,0,0,0,0,0,0,4,0,0,0,0,0,0,0
0,0,0,0,0,0,0,0,0,0,0,0,0,0,0,0,0,0,0,0,0,0,0
0,0,0,0,0,0,0,0,0,0,0,0,0,0,0,0,0,0,0,0,0,0,0
0,0,0,0,0,0,0,0,0,0,0,0,0,0,0,0,0,0,0,0,0,0,0
1,0,0,0,0,0,0,0,0,0,0,0,0,0,0,0,0,0,0,0,0,0,1
endlayer

layer
0,0,0,0,0,0,0,0,0,0,0,0,0,0,0,0,0,0,0,0,0,0,0
0,0,0,0,0,0,0,0,0,0,0,0,0,0,0,0,0,0,0,0,0,0,0
0,0,0,0,0,0,0,0,0,0,0,0,0,0,0,2,2,0,0,0,0,0,0
0,0,0,0,0,0,0,0,0,0,0,0,0,0,0,2,2,0,0,0,0,0,0
0,0,0,0,0,0,0,0,0,0,0,0,0,0,0,0,2,2,0,0,0,0,0
0,0,0,0,0,0,0,0,0,0,0,0,0,0,0,0,2,2,0,0,0,0,0
0,0,0,0,0,0,0,0,0,0,0,0,0,0,0,0,4,0,4,0,0,0,0
0,0,0,0,0,0,0,4,0,0,0,0,0,0,0,0,0,0,0,0,0,0,0
0,0,0,0,0,0,0,0,4,0,0,0,0,0,0,0,0,0,0,0,0,0,0
0,0,0,0,0,0,0,0,9,8,0,0,0,0,0,0,0,0,0,0,0,0,0
0,0,0,0,0,0,0,0,10,8,0,0,0,0,0,0,0,0,0,0,0,0,0
0,0,0,0,0,0,0,0,4,0,0,0,0,0,0,0,4,0,4,0,0,0,0
0,0,0,0,0,0,0,4,2,4,0,0,0,0,0,4,0,0,0,0,0,0,0
0,0,0,0,0,0,0,0,4,0,0,0,0,0,0,4,0,0,0,0,0,0,0
0,0,0,0,0,0,0,0,0,0,0,0,0,0,0,0,0,0,0,0,0,0,0
0,0,0,0,0,0,0,0,0,0,0,0,0,0,0,0,0,0,0,0,0,0,0
0,0,0,0,0,0,0,0,0,0,0,0,0,0,0,0,0,0,0,0,0,0,0
0,0,0,0,0,0,0,0,0,0,0,0,0,0,0,0,0,0,0,0,0,0,0
endlayer

layer
0,0,0,0,0,0,0,0,0,0,0,0,0,0,0,0,0,0,0,0,0,0,0
0,0,0,0,0,0,0,0,0,0,0,0,0,0,0,0,0,0,0,0,0,0,0
0,0,0,0,0,0,0,0,0,0,0,0,0,0,0,0,0,0,0,0,0,0,0
0,0,0,0,0,0,0,0,0,0,0,0,0,0,0,0,0,0,0,0,0,0,0
0,0,0,0,0,0,0,0,0,0,0,0,0,0,0,0,2,2,0,0,0,0,0
0,0,0,0,0,0,0,0,0,0,0,0,0,0,0,0,2,2,0,0,0,0,0
0,0,0,0,0,0,0,0,0,0,0,0,0,0,0,0,4,0,4,0,0,0,0
0,0,0,0,0,0,0,4,0,0,0,0,0,0,0,0,0,0,0,0,0,0,0
0,0,0,0,0,0,0,0,4,0,0,0,0,0,0,0,0,0,0,0,0,0,0
0,0,0,0,0,0,0,0,9,8,0,0,0,0,0,0,0,0,0,0,0,0,0
0,0,0,0,0,0,0,0,10,8,0,0,0,0,0,0,0,0,0,0,0,0,0
0,0,0,0,0,0,0,0,4,0,0,0,0,0,0,0,4,0,4,0,0,0,0
0,0,0,0,0,0,0,4,2,4,0,0,0,0,0,4,0,0,0,0,0,0,0
0,0,0,0,0,0,0,0,4,0,0,0,0,0,0,4,0,0,0,0,0,0,0
0,0,0,0,0,0,0,0,0,0,0,0,0,0,0,0,0,0,0,0,0,0,0
0,0,0,0,0,0,0,0,0,0,0,0,0,0,0,0,0,0,0,0,0,0,0
0,0,0,0,0,0,0,0,0,0,0,0,0,0,0,0,0,0,0,0,0,0,0
0,0,0,0,0,0,0,0,0,0,0,0,0,0,0,0,0,0,0,0,0,0,0
endlayer

layer
0,0,0,0,0,0,0,0,0,0,0,0,0,0,0,0,0,0,0,0,0,0,0
0,0,0,0,0,0,0,0,0,0,0,0,0,0,0,0,0,0,0,0,0,0,0
0,0,0,0,0,0,0,0,0,0,0,0,0,0,0,0,0,0,0,0,0,0,0
0,0,0,0,0,0,0,0,0,0,0,0,0,0,0,0,0,0,0,0,0,0,0
0,0,0,0,0,0,0,0,0,0,0,0,0,0,0,0,0,0,0,0,0,0,0
0,0,0,0,0,0,0,0,0,0,0,0,0,0,0,0,0,0,0,0,0,0,0
0,0,0,0,0,0,0,0,0,0,0,0,0,0,0,0,4,0,4,0,0,0,0
0,0,0,0,0,0,0,4,0,0,0,0,0,0,0,0,0,4,0,0,0,0,0
0,0,0,0,0,0,0,4,4,0,0,0,0,0,0,0,0,4,0,0,0,0,0
0,0,0,0,0,0,0,4,9,8,0,0,0,0,0,0,0,4,0,0,0,0,0
0,0,0,0,0,0,0,4,10,8,0,0,0,0,0,0,0,4,0,0,0,0,0
0,0,0,0,0,0,0,4,4,0,0,0,0,0,0,0,4,4,4,0,0,0,0
0,0,0,0,0,0,0,4,2,4,0,0,0,0,0,4,0,0,0,0,0,0,0
0,0,0,0,0,0,0,0,4,4,4,4,4,4,4,4,0,0,0,0,0,0,0
0,0,0,0,0,0,0,0,0,0,0,0,0,0,0,0,0,0,0,0,0,0,0
0,0,0,0,0,0,0,0,0,0,0,0,0,0,0,0,0,0,0,0,0,0,0
0,0,0,0,0,0,0,0,0,0,0,0,0,0,0,0,0,0,0,0,0,0,0
0,0,0,0,0,0,0,0,0,0,0,0,0,0,0,0,0,0,0,0,0,0,0
endlayer

layer
0,0,0,0,0,0,0,0,0,0,0,0,0,0,0,0,0,0,0,0,0,0,0
0,0,0,0,0,0,0,0,0,0,0,0,0,0,0,0,0,0,0,0,0,0,0
0,0,0,0,0,0,0,0,0,0,0,0,0,0,0,0,0,0,0,0,0,0,0
0,0,0,0,0,0,0,0,0,0,0,0,0,0,0,0,0,0,0,0,0,0,0
0,0,0,0,0,0,0,0,0,0,0,0,0,0,0,0,0,0,0,0,0,0,0
0,0,0,0,0,0,0,0,0,0,0,0,0,0,0,0,0,0,0,0,0,0,0
0,0,0,0,0,0,0,0,0,0,0,0,0,0,0,0,4,0,4,0,0,0,0
0,0,0,0,0,0,0,4,0,0,0,0,0,0,0,0,0,0,0,0,0,0,0
0,0,0,0,0,0,0,0,4,0,0,0,0,0,0,0,0,0,0,0,0,0,0
0,0,0,0,0,0,0,0,9,8,0,0,0,0,0,0,0,0,0,0,0,0,0
0,0,0,0,0,0,0,0,10,8,0,0,0,0,0,0,0,0,0,0,0,0,0
0,0,0,0,0,0,0,0,4,0,0,0,0,0,0,0,4,0,4,0,0,0,0
0,0,0,0,0,0,0,4,2,4,0,0,0,0,0,4,0,0,0,0,0,0,0
0,0,0,0,0,0,0,0,4,0,0,0,0,0,0,4,0,0,0,0,0,0,0
0,0,0,0,0,0,0,0,0,0,0,0,0,0,0,0,0,0,0,0,0,0,0
0,0,0,0,0,0,0,0,0,0,0,0,0,0,0,0,0,0,0,0,0,0,0
0,0,0,0,0,0,0,0,0,0,0,0,0,0,0,0,0,0,0,0,0,0,0
0,0,0,0,0,0,0,0,0,0,0,0,0,0,0,0,0,0,0,0,0,0,0
endlayer

layer
0,0,0,0,0,0,0,0,0,0,0,0,0,0,0,0,0,0,0,0,0,0,0
0,0,0,0,0,0,0,0,0,0,0,0,0,0,0,0,0,0,0,0,0,0,0
0,0,0,0,0,0,0,0,0,0,0,0,0,0,0,0,0,0,0,0,0,0,0
0,0,0,0,0,0,0,0,0,0,0,0,0,0,0,0,0,0,0,0,0,0,0
0,0,0,0,0,0,0,0,0,0,0,0,0,0,0,0,0,0,0,0,0,0,0
0,0,0,0,0,0,0,0,0,0,0,0,0,0,0,0,0,0,0,0,0,0,0
0,0,0,0,0,0,0,0,0,0,0,0,0,0,0,0,4,0,4,0,0,0,0
0,0,0,0,0,0,0,4,0,0,0,0,0,0,0,0,0,4,0,0,0,0,0
0,0,0,0,0,0,0,4,4,0,0,0,0,0,0,0,0,4,0,0,0,0,0
0,0,0,0,0,0,0,4,9,8,0,0,0,0,0,0,0,4,0,0,0,0,0
0,0,0,0,0,0,0,4,10,8,0,0,0,0,0,0,0,4,0,0,0,0,0
0,0,0,0,0,0,0,4,4,0,0,0,0,0,0,0,4,4,4,0,0,0,0
0,0,0,0,0,0,0,4,2,4,0,0,0,0,0,4,0,0,0,0,0,0,0
0,0,0,0,0,0,0,0,4,4,4,4,4,4,4,4,0,0,0,0,0,0,0
0,0,0,0,0,0,0,0,0,0,0,0,0,0,0,0,0,0,0,0,0,0,0
0,0,0,0,0,0,0,0,0,0,0,0,0,0,0,0,0,0,0,0,0,0,0
0,0,0,0,0,0,0,0,0,0,0,0,0,0,0,0,0,0,0,0,0,0,0
0,0,0,0,0,0,0,0,0,0,0,0,0,0,0,0,0,0,0,0,0,0,0
endlayer

layer
0,0,0,0,0,0,0,0,0,0,0,0,0,0,0,0,0,0,0,0,0,0,0
0,0,0,0,0,0,0,0,0,0,0,0,0,0,0,0,0,0,0,0,0,0,0
0,0,0,0,0,0,0,0,0,0,0,0,0,0,0,0,0,0,0,0,0,0,0
0,0,0,0,0,0,0,0,0,0,0,0,0,0,0,0,0,0,0,0,0,0,0
0,0,0,0,0,0,0,0,0,0,0,0,0,0,0,0,0,0,0,0,0,0,0
0,0,0,0,0,0,0,0,0,0,0,0,0,0,0,0,0,0,0,0,0,0,0
0,0,0,0,0,0,0,0,0,0,0,0,0,0,0,0,4,0,4,0,0,0,0
0,0,0,0,0,0,0,4,0,0,0,0,0,0,0,0,0,0,0,0,0,0,0
0,0,0,0,0,0,0,0,4,0,0,0,0,0,0,0,0,0,0,0,0,0,0
0,0,0,0,0,0,0,0,9,8,0,0,0,0,0,0,0,0,0,0,0,0,0
0,0,0,0,0,0,0,0,10,8,0,0,0,0,0,0,0,0,0,0,0,0,0
0,0,0,0,0,0,0,0,4,0,0,0,0,0,0,0,4,0,4,0,0,0,0
0,0,0,0,0,0,0,4,2,4,0,0,0,0,0,4,0,0,0,0,0,0,0
0,0,0,0,0,0,0,0,4,0,0,0,0,0,0,4,0,0,0,0,0,0,0
0,0,0,0,0,0,0,0,0,0,0,0,0,0,0,0,0,0,0,0,0,0,0
0,0,0,0,0,0,0,0,0,0,0,0,0,0,0,0,0,0,0,0,0,0,0
0,0,0,0,0,0,0,0,0,0,0,0,0,0,0,0,0,0,0,0,0,0,0
0,0,0,0,0,0,0,0,0,0,0,0,0,0,0,0,0,0,0,0,0,0,0
endlayer

layer
0,0,0,0,0,0,0,0,0,0,0,0,0,0,0,0,0,0,0,0,0,0,0
0,0,0,0,0,0,0,0,0,0,0,0,0,0,0,0,0,0,0,0,0,0,0
0,0,0,0,0,0,0,0,0,0,0,0,0,0,0,0,0,0,0,0,0,0,0
0,0,0,0,0,0,0,0,0,0,0,0,0,0,0,0,0,0,0,0,0,0,0
0,0,0,0,0,0,0,0,0,0,0,0,0,0,0,0,0,0,0,0,0,0,0
0,0,0,0,0,0,0,0,0,0,0,0,0,0,0,0,0,0,0,0,0,0,0
0,0,0,0,4,0,0,0,0,0,0,0,0,0,0,0,4,0,4,4,4,0,0
0,0,0,4,4,4,4,4,0,0,0,0,0,0,0,0,0,4,0,4,0,0,0
0,0,0,0,4,0,0,4,4,0,0,0,0,0,0,0,0,4,0,4,0,0,0
0,0,0,0,4,0,0,4,9,8,0,0,0,0,0,0,0,4,0,4,0,0,0
0,0,0,0,4,0,0,4,10,8,0,0,0,0,0,0,0,4,0,4,0,0,0
0,0,0,0,4,0,0,4,4,0,0,0,0,0,0,0,4,4,4,4,4,0,0
0,0,0,0,4,0,0,4,2,4,0,0,0,0,0,4,4,0,0,4,0,0,0
0,0,0,4,4,4,4,4,4,4,4,4,4,4,4,4,4,4,4,4,0,0,0
0,0,0,0,4,0,0,0,4,0,0,0,4,0,0,0,4,0,0,0,0,0,0
0,0,0,0,4,0,0,0,4,0,0,0,4,0,0,0,4,0,0,0,0,0,0
0,0,0,0,0,0,0,0,0,0,0,0,0,0,0,0,0,0,0,0,0,0,0
0,0,0,0,0,0,0,0,0,0,0,0,0,0,0,0,0,0,0,0,0,0,0
endlayer

layer
0,0,0,0,0,0,0,0,0,0,0,0,0,0,0,0,0,0,0,0,0,0,0
0,0,0,0,0,0,0,0,0,0,0,0,0,0,0,0,0,0,0,0,0,0,0
0,0,0,0,0,0,0,0,0,0,0,0,0,0,0,0,0,0,0,0,0,0,0
0,0,0,0,0,0,0,0,0,0,0,0,0,0,0,0,0,0,0,0,0,0,0
0,0,0,0,0,0,0,0,0,0,0,0,0,0,0,0,0,0,0,0,0,0,0
0,0,0,0,0,0,0,0,0,0,0,0,0,0,0,0,0,0,0,0,0,0,0
0,0,2,2,2,2,2,0,0,0,0,0,0,0,0,0,4,2,2,2,2,2,0
0,2,2,2,7,2,2,2,0,0,0,0,0,0,0,0,4,2,2,2,2,2,0
0,2,2,2,2,2,2,2,4,0,0,0,0,0,0,0,4,2,2,2,2,2,0
0,2,2,2,2,2,2,2,9,8,0,0,0,0,0,0,4,2,2,7,2,2,0
0,2,2,2,2,2,2,2,10,8,0,0,0,0,0,0,4,2,2,2,2,2,0
0,2,2,2,7,2,2,2,4,0,0,0,0,0,0,0,4,2,2,2,2,2,0
0,2,2,2,2,2,2,2,2,4,0,0,0,0,0,4,2,2,2,2,2,2,0
0,2,2,2,2,2,2,2,2,2,0,0,0,0,0,4,2,2,2,7,2,2,0
0,2,2,2,2,2,2,2,2,2,2,2,2,2,2,2,2,2,2,2,2,2,0
0,2,2,2,7,2,2,2,7,2,2,2,7,2,2,2,7,2,2,2,2,0,0
0,0,2,2,2,2,2,2,2,2,2,2,2,2,2,2,2,2,2,2,0,0,0
0,0,0,0,0,0,0,0,0,0,0,0,0,0,0,0,0,0,0,0,0,0,0
endlayer

layer
0,0,0,0,0,0,0,0,0,0,0,0,0,0,0,0,0,0,0,0,0,0,0
0,0,0,0,0,0,0,0,0,0,0,0,0,0,0,0,0,0,0,0,0,0,0
0,0,0,0,0,0,0,0,0,0,0,0,0,0,0,0,0,0,0,0,0,0,0
0,0,0,0,0,0,0,0,0,0,0,0,0,0,0,0,0,0,0,0,0,0,0
0,0,0,0,0,0,0,0,0,0,0,0,0,0,0,0,0,0,0,0,0,0,0
0,0,21,21,21,21,21,0,0,0,0,0,0,0,0,0,21,21,21,21,21,21,0
0,21,22,22,22,22,22,21,0,0,0,0,0,0,0,4,2,22,22,22,22,22,21
21,22,22,22,5,22,22,22,21,0,0,0,0,0,0,4,2,22,22,22,22,22,21
21,22,22,22,22,22,22,19,4,0,0,0,0,0,0,4,2,22,22,22,22,22,21
21,22,22,22,22,22,22,19,9,8,0,0,0,0,0,4,2,22,22,5,22,22,21
21,22,22,22,22,22,22,19,10,8,0,0,0,0,0,4,2,22,22,22,22,22,21
21,22,22,22,5,22,22,19,4,0,0,0,0,0,0,4,2,22,22,22,22,22,21
21,22,22,22,22,22,22,22,2,4,0,0,0,0,0,4,22,22,22,22,22,22,21
21,22,22,22,22,22,22,22,22,2,4,4,4,4,4,22,22,22,22,5,22,22,21
21,22,22,22,22,22,22,22,22,22,22,22,22,22,22,22,22,22,22,22,22,22,21
21,22,22,22,5,22,22,22,5,22,22,22,5,22,22,22,5,22,22,22,22,21,0
0,21,22,22,22,22,22,22,22,22,22,22,22,22,22,22,22,22,22,22,21,0,0
0,0,21,21,21,21,21,21,21,21,21,21,21,21,21,21,21,21,21,21,0,0,0
endlayer

layer
0,0,0,0,0,0,0,0,0,0,0,0,0,0,0,0,0,0,0,0,0,0,0
0,0,0,0,0,0,0,0,0,0,0,0,0,0,0,0,0,0,0,0,0,0,0
0,0,0,0,0,0,0,0,0,0,0,0,0,0,0,0,0,0,0,0,0,0,0
0,0,0,0,0,0,0,0,0,0,0,0,0,0,0,0,0,0,0,0,0,0,0
0,0,0,0,0,0,0,0,0,0,0,0,0,0,0,0,0,0,0,0,0,0,0
0,0,2,2,2,2,2,0,0,0,0,0,0,0,0,2,2,2,2,2,2,2,0
0,2,0,0,0,0,0,2,0,0,0,0,0,0,0,4,2,0,0,0,0,0,2
2,0,0,0,0,0,0,0,2,0,0,0,0,0,0,0,2,0,0,0,0,0,2
2,0,0,0,0,0,0,0,4,0,0,0,0,0,0,0,2,0,0,0,0,0,2
2,0,0,0,0,0,0,0,9,8,0,0,0,0,0,0,2,0,0,0,0,0,2
2,0,0,0,0,0,0,0,10,8,0,0,0,0,0,0,2,0,0,0,0,0,2
2,0,0,0,0,0,0,0,4,0,0,0,0,0,0,0,2,0,0,0,0,0,2
2,0,0,0,0,0,0,0,2,4,4,4,4,4,4,4,2,0,0,0,0,0,2
2,0,0,0,0,0,0,0,0,2,2,2,2,2,2,2,0,0,0,0,0,0,2
2,0,0,0,0,0,0,0,0,0,0,0,0,0,0,0,0,0,0,0,0,0,2
2,0,0,0,0,0,0,0,0,0,0,0,0,0,0,0,0,0,0,0,0,2,0
0,2,0,0,0,0,0,0,0,0,0,0,0,0,0,0,0,0,0,0,2,0,0
0,0,2,2,2,2,2,2,2,2,2,2,2,2,2,2,2,2,2,2,0,0,0
endlayer

layer
0,0,0,0,0,0,0,0,0,0,0,0,0,0,0,0,0,0,0,0,0,0,0
0,0,0,0,0,0,0,0,0,0,0,0,0,0,0,0,0,0,0,0,0,0,0
0,0,0,0,0,0,0,0,0,0,0,0,0,0,0,0,0,0,0,0,0,0,0
0,0,0,0,0,0,0,0,0,0,0,0,0,0,0,0,0,0,0,0,0,0,0
0,0,0,0,0,0,0,0,0,0,0,0,0,0,0,0,0,0,0,0,0,0,0
0,0,0,0,0,0,0,0,0,0,0,0,0,0,0,2,2,0,0,0,0,0,0
0,0,0,0,0,0,0,0,0,0,0,0,0,0,0,4,2,0,0,0,0,0,0
0,0,0,0,0,0,0,0,2,0,0,0,0,0,0,4,2,0,0,0,0,0,0
0,0,0,0,0,0,0,0,4,0,0,0,0,0,0,4,2,0,0,0,0,0,0
0,0,0,0,0,0,0,0,0,8,0,0,0,0,0,4,2,0,0,0,0,0,0
0,0,0,0,0,0,0,0,0,8,0,0,0,0,0,4,2,0,0,0,0,0,0
0,0,0,0,0,0,0,0,4,0,0,0,0,0,0,4,2,0,0,0,0,0,0
0,0,0,0,0,0,0,0,2,4,0,0,0,0,0,4,2,0,0,0,0,0,0
0,0,0,0,0,0,0,0,0,2,2,2,2,2,2,2,0,0,0,0,0,0,0
0,0,0,0,0,0,0,0,0,0,0,0,0,0,0,0,0,0,0,0,0,0,0
0,0,0,0,0,0,0,0,0,0,0,0,0,0,0,0,0,0,0,0,0,0,0
0,0,0,0,0,0,0,0,0,0,0,0,0,0,0,0,0,0,0,0,0,0,0
0,0,0,0,0,0,0,0,0,0,0,0,0,0,0,0,0,0,0,0,0,0,0
endlayer

layer
0,0,0,0,0,0,0,0,0,0,0,0,0,0,0,0,0,0,0,0,0,0,0
0,0,0,0,0,0,0,0,0,0,0,0,0,0,0,0,0,0,0,0,0,0,0
0,0,0,0,0,0,0,0,0,0,0,0,0,0,0,0,0,0,0,0,0,0,0
0,0,0,0,0,0,0,0,0,0,0,0,0,0,0,0,0,0,0,0,0,0,0
0,0,0,0,0,0,0,0,0,0,0,0,0,0,0,0,0,0,0,0,0,0,0
0,0,0,0,0,0,0,0,0,0,0,0,0,0,0,2,2,0,0,0,0,0,0
0,0,0,0,0,0,0,0,0,0,0,0,0,0,0,4,2,0,0,0,0,0,0
0,0,0,0,0,0,0,0,2,0,0,0,0,0,0,0,2,0,0,0,0,0,0
0,0,0,0,0,0,0,0,4,5,0,0,0,0,0,0,2,0,0,0,0,0,0
0,0,0,0,0,0,0,0,0,5,0,0,0,0,0,0,2,0,0,0,0,0,0
0,0,0,0,0,0,0,0,0,5,0,0,0,0,0,0,2,0,0,0,0,0,0
0,0,0,0,0,0,0,0,4,5,0,0,0,0,0,0,2,0,0,0,0,0,0
0,0,0,0,0,0,0,0,2,4,4,4,4,4,4,4,2,0,0,0,0,0,0
0,0,0,0,0,0,0,0,0,2,2,2,2,2,2,2,0,0,0,0,0,0,0
0,0,0,0,0,0,0,0,0,0,0,0,0,0,0,0,0,0,0,0,0,0,0
0,0,0,0,0,0,0,0,0,0,0,0,0,0,0,0,0,0,0,0,0,0,0
0,0,0,0,0,0,0,0,0,0,0,0,0,0,0,0,0,0,0,0,0,0,0
0,0,0,0,0,0,0,0,0,0,0,0,0,0,0,0,0,0,0,0,0,0,0
endlayer

layer
0,0,0,0,0,0,0,0,0,0,0,0,0,0,0,0,0,0,0,0,0,0,0
0,0,0,0,0,0,0,0,0,0,0,0,0,0,0,0,0,0,0,0,0,0,0
0,0,0,0,0,0,0,0,0,0,0,0,0,0,0,0,0,0,0,0,0,0,0
0,0,0,0,0,0,0,0,0,0,0,0,0,0,0,0,0,0,0,0,0,0,0
0,0,0,0,0,0,0,0,0,0,0,0,0,0,0,0,0,0,0,0,0,0,0
0,0,0,0,0,0,0,0,0,0,0,0,0,0,0,2,2,0,0,0,0,0,0
0,0,0,0,0,0,0,0,0,0,0,0,0,0,0,4,2,0,0,0,0,0,0
0,0,0,0,0,0,0,0,2,0,0,0,0,0,0,4,2,0,0,0,0,0,0
0,0,0,0,0,0,0,0,4,0,0,0,0,0,0,4,2,0,0,0,0,0,0
0,0,0,0,0,0,0,0,0,0,0,0,0,0,0,4,2,0,0,0,0,0,0
0,0,0,0,0,0,0,0,0,0,0,0,0,0,0,4,2,0,0,0,0,0,0
0,0,0,0,0,0,0,0,4,0,0,0,0,0,0,4,2,0,0,0,0,0,0
0,0,0,0,0,0,0,0,2,4,0,0,0,0,0,4,2,0,0,0,0,0,0
0,0,0,0,0,0,0,0,0,2,2,2,2,2,2,2,0,0,0,0,0,0,0
0,0,0,0,0,0,0,0,0,0,0,0,0,0,0,0,0,0,0,0,0,0,0
0,0,0,0,0,0,0,0,0,0,0,0,0,0,0,0,0,0,0,0,0,0,0
0,0,0,0,0,0,0,0,0,0,0,0,0,0,0,0,0,0,0,0,0,0,0
0,0,0,0,0,0,0,0,0,0,0,0,0,0,0,0,0,0,0,0,0,0,0
endlayer

layer
0,0,0,0,0,0,0,0,0,0,0,0,0,0,0,0,0,0,0,0,0,0,0
0,0,0,0,0,0,0,0,0,0,0,0,0,0,0,0,0,0,0,0,0,0,0
0,0,0,0,0,0,0,0,0,0,0,0,0,0,0,0,0,0,0,0,0,0,0
0,0,0,0,0,0,0,0,0,0,0,0,0,0,0,0,0,0,0,0,0,0,0
0,0,0,0,0,0,0,0,0,0,0,0,0,0,0,0,0,0,0,0,0,0,0
0,0,0,0,0,0,0,0,0,0,0,0,0,0,0,2,2,0,0,0,0,0,0
0,0,0,0,0,0,0,0,0,0,0,0,0,0,0,4,2,0,0,0,0,0,0
0,0,0,0,0,0,0,0,2,0,0,0,0,0,0,0,2,0,0,0,0,0,0
0,0,0,0,0,0,0,0,4,0,0,0,0,0,0,0,2,0,0,0,0,0,0
0,0,0,0,0,0,0,0,4,0,0,0,0,0,0,0,2,0,0,0,0,0,0
0,0,0,0,0,0,0,0,4,0,0,0,0,0,0,0,2,0,0,0,0,0,0
0,0,0,0,0,0,0,0,4,0,0,0,0,0,0,0,2,0,0,0,0,0,0
0,0,0,0,0,0,0,0,2,4,4,4,4,4,4,4,2,0,0,0,0,0,0
0,0,0,0,0,0,0,0,0,2,2,2,2,2,2,2,0,0,0,0,0,0,0
0,0,0,0,0,0,0,0,0,0,0,0,0,0,0,0,0,0,0,0,0,0,0
0,0,0,0,0,0,0,0,0,0,0,0,0,0,0,0,0,0,0,0,0,0,0
0,0,0,0,0,0,0,0,0,0,0,0,0,0,0,0,0,0,0,0,0,0,0
0,0,0,0,0,0,0,0,0,0,0,0,0,0,0,0,0,0,0,0,0,0,0
endlayer

