# Gilly's Adobe houses

# template generated by Ruins mod version 14.6 Ingame Parser
# Structure created by Gilly

weight=1
embed_into_distance=4
acceptable_target_blocks=
unacceptable_target_blocks=flowing_water,water,flowing_lava,lava,ice,bedrock,netherrack,soul_sand,Natura:Cloud
dimensions=11,17,20
allowable_overhang=0
max_leveling=7
leveling_buffer=-1
preserve_water=0
preserve_lava=0

rule1=0,100,preserveBlock
rule2=0,100,double_stone_slab-9
rule3=0,100,sandstone-2
rule4=0,100,wooden_door-6
rule5=0,100,wooden_door-5
rule6=0,100,wooden_door-8
rule7=0,100,stone_slab-1
rule8=0,100,sandstone_stairs-0
rule9=0,100,sandstone_stairs-2
rule10=0,100,sandstone_stairs-3
rule11=0,100,spruce_stairs-0
rule12=0,100,hay_block-0
rule13=0,100,spruce_stairs-3
rule14=0,100,fence-0
rule15=0,100,sandstone_stairs-1
rule16=0,100,spruce_stairs-2
rule17=0,100,spruce_stairs-1
rule18=0,100,wooden_slab-1

layer
1,1,1,1,1,1,1,2,2,2,2,2,2,2,1,1,1,1,1,1
1,1,1,1,1,1,1,2,1,1,1,1,1,2,1,1,1,1,1,1
1,1,1,1,1,1,1,2,1,1,1,1,1,2,1,1,1,1,1,1
1,1,1,1,1,1,1,2,1,1,1,1,1,2,2,2,2,2,2,2
1,2,2,2,2,2,2,2,1,1,1,1,1,2,1,1,1,1,1,2
1,2,1,1,1,1,1,2,1,1,1,1,1,2,1,1,1,1,1,2
1,2,1,1,1,1,1,2,2,2,2,2,2,2,1,1,1,1,1,2
1,2,1,1,1,1,1,2,2,2,2,2,2,2,1,1,1,1,1,2
1,2,1,1,1,1,1,2,2,2,2,2,2,2,1,1,1,1,1,2
1,2,1,1,1,1,1,2,2,2,2,2,2,2,2,2,2,2,2,2
2,2,2,2,2,2,2,2,2,2,2,2,2,2,1,1,1,1,1,2
2,1,1,1,1,1,2,2,2,1,1,1,1,1,1,1,1,1,1,1
2,1,1,1,1,1,2,2,2,1,1,1,1,1,1,1,1,1,1,1
2,1,1,1,1,1,2,2,2,1,1,1,1,1,1,1,1,1,1,1
2,1,1,1,1,1,2,1,1,1,1,1,1,1,1,1,1,1,1,1
2,1,1,1,1,1,2,1,1,1,1,1,1,1,1,1,1,1,1,1
2,2,2,2,2,2,2,2,1,1,1,1,1,1,1,1,1,1,1,1
endlayer

layer
1,1,1,1,1,1,1,2,2,2,2,2,2,2,1,1,1,1,1,1
1,1,1,1,1,1,1,2,1,1,1,1,1,2,1,1,1,1,1,1
1,1,1,1,1,1,1,2,1,1,1,1,1,2,1,1,1,1,1,1
1,1,1,1,1,1,1,2,1,1,1,1,1,2,2,2,2,2,2,2
1,2,2,2,2,2,2,2,1,1,1,1,1,2,1,1,1,1,1,2
1,2,1,1,1,1,1,2,1,1,1,1,1,2,1,1,1,1,1,2
1,2,1,1,1,1,1,2,2,2,2,2,2,2,1,1,1,1,1,2
1,2,1,1,1,1,1,2,2,2,2,2,2,2,1,1,1,1,1,2
1,2,1,1,1,1,1,2,2,2,2,2,2,2,1,1,1,1,1,2
1,2,1,1,1,1,1,2,2,2,2,2,2,2,2,2,2,2,2,2
2,2,2,2,2,2,2,2,2,2,2,2,2,2,1,1,1,1,1,2
2,1,1,1,1,1,2,2,2,1,1,1,1,1,1,1,1,1,1,1
2,1,1,1,1,1,2,2,2,1,1,1,1,1,1,1,1,1,1,1
2,1,1,1,1,1,2,2,2,1,1,1,1,1,1,1,1,1,1,1
2,1,1,1,1,1,2,1,1,1,1,1,1,1,1,1,1,1,1,1
2,1,1,1,1,1,2,1,1,1,1,1,1,1,1,1,1,1,1,1
2,2,2,2,2,2,2,2,1,1,1,1,1,1,1,1,1,1,1,1
endlayer

layer
1,1,1,1,1,1,1,2,2,2,2,2,2,2,1,1,1,1,1,1
1,1,1,1,1,1,1,2,1,1,1,1,1,2,1,1,1,1,1,1
1,1,1,1,1,1,1,2,1,1,1,1,1,2,1,1,1,1,1,1
1,1,1,1,1,1,1,2,1,1,1,1,1,2,2,2,2,2,2,2
1,2,2,2,2,2,2,2,1,1,1,1,1,2,1,1,1,1,1,2
1,2,1,1,1,1,1,2,1,1,1,1,1,2,1,1,1,1,1,2
1,2,1,1,1,1,1,2,2,2,2,2,2,2,1,1,1,1,1,2
1,2,1,1,1,1,1,2,2,2,2,2,2,2,1,1,1,1,1,2
1,2,1,1,1,1,1,2,2,2,2,2,2,2,1,1,1,1,1,2
1,2,1,1,1,1,1,2,2,2,2,2,2,2,2,2,2,2,2,2
2,2,2,2,2,2,2,2,2,1,1,1,1,2,2,1,1,1,2,2
2,1,1,1,1,1,2,2,2,1,1,1,1,1,1,1,1,1,1,1
2,1,1,1,1,1,2,2,2,1,1,1,1,1,1,1,1,1,1,1
2,1,1,1,1,1,2,2,1,1,1,1,1,1,1,1,1,1,1,1
2,1,1,1,1,1,2,1,1,1,1,1,1,1,1,1,1,1,1,1
2,1,1,1,1,1,2,2,1,1,1,1,1,1,1,1,1,1,1,1
2,2,2,2,2,2,2,2,1,1,1,1,1,1,1,1,1,1,1,1
endlayer

layer
1,1,1,1,1,1,1,2,2,2,2,2,2,2,1,1,1,1,1,1
1,1,1,1,1,1,1,2,1,1,1,1,1,2,1,1,1,1,1,1
1,1,1,1,1,1,1,2,1,1,1,1,1,2,1,1,1,1,1,1
1,1,1,1,1,1,1,2,1,1,1,1,1,2,2,2,2,2,2,2
1,2,2,2,2,2,2,2,1,1,1,1,1,2,1,1,1,1,1,2
1,2,1,1,1,1,1,2,1,1,1,1,1,2,1,1,1,1,1,2
1,2,1,1,1,1,1,2,2,2,2,2,2,2,1,1,1,1,1,2
1,2,1,1,1,1,1,2,2,2,2,2,2,2,1,1,1,1,1,2
1,2,1,1,1,1,1,2,2,2,2,2,2,2,1,1,1,1,1,2
1,2,1,1,1,1,1,2,2,1,1,1,1,2,2,2,2,2,2,2
2,2,2,2,2,2,2,2,2,1,1,1,1,1,2,2,2,2,2,1
2,1,1,1,1,1,2,2,2,1,1,1,1,1,1,1,1,1,1,1
2,1,1,1,1,1,2,2,1,1,1,1,1,1,1,1,1,1,1,1
2,1,1,1,1,1,2,2,1,1,1,1,1,1,1,1,1,1,1,1
2,1,1,1,1,1,2,2,1,1,1,1,1,1,1,1,1,1,1,1
2,1,1,1,1,1,2,2,1,1,1,1,1,1,1,1,1,1,1,1
2,2,2,2,2,2,2,1,1,1,1,1,1,1,1,1,1,1,1,1
endlayer

layer
1,1,1,1,1,1,1,3,2,2,3,2,2,3,1,1,1,1,1,1
1,1,1,1,1,1,1,2,2,2,2,2,2,2,1,1,1,1,1,1
1,1,1,1,1,1,1,2,2,2,2,2,2,2,1,1,1,1,1,1
1,1,1,1,1,1,1,3,2,2,2,2,2,2,2,2,3,2,2,3
1,3,2,2,3,2,2,2,2,2,2,2,2,2,2,2,2,2,2,2
1,2,2,2,2,2,2,2,2,2,2,2,2,2,2,2,2,2,2,2
1,2,2,2,2,2,2,2,2,2,2,2,2,2,2,2,2,2,2,3
1,3,2,2,2,2,2,2,2,2,2,2,2,2,2,2,2,2,2,2
1,2,2,2,2,2,2,2,2,1,1,1,1,2,2,2,2,2,2,2
1,2,2,2,2,2,2,2,2,1,1,1,1,3,2,2,2,2,2,3
3,2,2,2,2,2,2,3,1,1,1,1,1,1,1,2,2,2,1,1
2,2,2,2,2,2,2,2,1,1,1,1,1,1,1,1,1,1,1,1
2,2,2,2,2,2,2,2,1,1,1,1,1,1,1,1,1,1,1,1
3,2,2,2,2,2,2,2,1,1,1,1,1,1,1,1,1,1,1,1
2,2,2,2,2,2,2,2,1,1,1,1,1,1,1,1,1,1,1,1
2,2,2,2,2,2,2,1,1,1,1,1,1,1,1,1,1,1,1,1
3,2,2,3,2,2,3,1,1,1,1,1,1,1,1,1,1,1,1,1
endlayer

layer
1,1,1,1,1,1,1,2,2,2,2,2,2,2,1,1,1,1,1,1
1,1,1,1,1,1,1,2,0,0,0,0,0,2,1,1,1,1,1,1
1,1,1,1,1,1,1,2,0,0,0,0,0,2,1,1,1,1,1,1
1,1,1,1,1,1,1,2,0,0,0,0,0,2,2,2,2,2,2,2
1,2,2,2,2,2,2,2,0,0,0,0,0,2,0,0,0,0,0,2
1,2,0,0,0,0,0,2,0,0,0,0,0,2,0,0,0,0,0,2
1,2,0,0,0,0,0,2,2,3,4,3,2,2,0,0,0,0,0,2
1,2,0,0,0,0,0,3,1,1,1,1,1,2,0,0,0,0,0,2
1,2,0,0,0,0,0,5,1,1,1,1,1,2,0,0,0,0,0,2
1,2,0,0,0,0,0,3,1,1,1,1,1,2,2,3,4,3,2,2
2,2,2,2,2,2,2,2,1,1,1,1,1,1,1,1,1,1,1,1
2,0,0,0,0,0,2,1,1,1,1,1,1,1,1,1,1,1,1,1
2,0,0,0,0,0,3,1,1,1,1,1,1,1,1,1,1,1,1,1
2,0,0,0,0,0,5,1,1,1,1,1,1,1,1,1,1,1,1,1
2,0,0,0,0,0,3,1,1,1,1,1,1,1,1,1,1,1,1,1
2,0,0,0,0,0,2,1,1,1,1,1,1,1,1,1,1,1,1,1
2,2,2,2,2,2,2,1,1,1,1,1,1,1,1,1,1,1,1,1
endlayer

layer
1,1,1,1,1,1,1,3,2,0,2,0,2,3,1,1,1,1,1,1
1,1,1,1,1,1,1,2,0,0,0,0,0,2,1,1,1,1,1,1
1,1,1,1,1,1,1,0,0,0,0,0,0,2,1,1,1,1,1,1
1,1,1,1,1,1,1,2,0,0,0,0,0,2,2,0,2,0,2,3
1,3,2,0,2,0,2,2,0,0,0,0,0,2,0,0,0,0,0,2
1,2,0,0,0,0,0,2,0,0,0,0,0,2,0,0,0,0,0,0
1,0,0,0,0,0,0,2,2,3,6,3,2,2,0,0,0,0,0,2
1,2,0,0,0,0,0,3,1,1,1,1,1,2,0,0,0,0,0,0
1,0,0,0,0,0,0,6,1,1,1,1,1,2,0,0,0,0,0,2
1,2,0,0,0,0,0,3,1,1,1,1,1,3,2,3,6,3,2,3
3,2,2,2,2,2,2,3,1,1,1,1,1,1,1,1,1,1,1,1
2,0,0,0,0,0,2,1,1,1,1,1,1,1,1,1,1,1,1,1
0,0,0,0,0,0,3,1,1,1,1,1,1,1,1,1,1,1,1,1
2,0,0,0,0,0,6,1,1,1,1,1,1,1,1,1,1,1,1,1
0,0,0,0,0,0,3,1,1,1,1,1,1,1,1,1,1,1,1,1
2,0,0,0,0,0,2,1,1,1,1,1,1,1,1,1,1,1,1,1
3,2,0,2,0,2,3,1,1,1,1,1,1,1,1,1,1,1,1,1
endlayer

layer
1,1,1,1,1,1,1,2,2,2,2,2,2,2,1,1,1,1,1,1
1,1,1,1,1,1,1,2,0,0,0,0,0,2,1,1,1,1,1,1
1,1,1,1,1,1,1,2,0,0,0,0,0,2,1,1,1,1,1,1
1,1,1,1,1,1,1,2,0,0,0,0,0,2,2,2,2,2,2,2
1,2,2,2,2,2,2,2,0,0,0,0,0,2,0,0,0,0,0,2
1,2,0,0,0,0,0,2,0,0,0,0,0,2,0,0,0,0,0,2
1,2,0,0,0,0,0,2,2,2,3,2,2,2,0,0,0,0,0,2
1,2,0,0,0,0,0,2,1,1,1,1,1,2,0,0,0,0,0,2
1,2,0,0,0,0,0,3,1,1,1,1,1,2,0,0,0,0,0,2
1,2,0,0,0,0,0,2,1,1,1,1,1,2,2,2,3,2,2,2
2,2,2,2,2,2,2,2,1,1,1,1,1,1,1,1,1,1,1,1
2,0,0,0,0,0,2,1,1,1,1,1,1,1,1,1,1,1,1,1
2,0,0,0,0,0,2,1,1,1,1,1,1,1,1,1,1,1,1,1
2,0,0,0,0,0,3,1,1,1,1,1,1,1,1,1,1,1,1,1
2,0,0,0,0,0,2,1,1,1,1,1,1,1,1,1,1,1,1,1
2,0,0,0,0,0,2,1,1,1,1,1,1,1,1,1,1,1,1,1
2,2,2,2,2,2,2,1,1,1,1,1,1,1,1,1,1,1,1,1
endlayer

layer
1,1,1,1,1,1,1,3,2,2,3,2,2,3,1,1,1,1,1,1
1,1,1,1,1,1,1,2,0,0,0,0,0,2,1,1,1,1,1,1
1,1,1,1,1,1,1,2,0,0,0,0,0,2,1,1,1,1,1,1
1,1,1,1,1,1,1,3,0,0,0,0,0,2,2,2,3,2,2,3
1,3,2,2,3,2,2,2,0,0,0,0,0,2,0,0,0,0,0,2
1,2,0,0,0,0,0,2,0,0,0,0,0,2,0,0,0,0,0,2
1,2,0,0,0,0,0,2,2,2,2,2,2,2,0,0,0,0,0,3
1,3,0,0,0,0,0,2,1,1,1,1,1,2,0,0,0,0,0,2
1,2,0,0,0,0,0,2,1,1,1,1,1,2,0,0,0,0,0,2
1,2,0,0,0,0,0,2,1,1,1,1,1,3,2,2,2,2,2,3
3,2,2,2,2,2,2,3,1,1,1,1,1,1,1,1,1,1,1,1
2,0,0,0,0,0,2,1,1,1,1,1,1,1,1,1,1,1,1,1
2,0,0,0,0,0,2,1,1,1,1,1,1,1,1,1,1,1,1,1
3,0,0,0,0,0,2,1,1,1,1,1,1,1,1,1,1,1,1,1
2,0,0,0,0,0,2,1,1,1,1,1,1,1,1,1,1,1,1,1
2,0,0,0,0,0,2,1,1,1,1,1,1,1,1,1,1,1,1,1
3,2,2,3,2,2,3,1,1,1,1,1,1,1,1,1,1,1,1,1
endlayer

layer
1,1,1,1,1,1,1,7,3,8,8,8,3,7,1,1,1,1,1,1
1,1,1,1,1,1,1,3,0,0,0,0,0,3,1,1,1,1,1,1
1,1,1,1,1,1,1,10,0,0,0,0,0,9,1,1,1,1,1,1
1,1,1,1,1,1,1,10,0,0,0,0,0,9,8,8,8,8,8,7
1,7,11,11,11,11,11,10,0,0,0,0,0,2,2,2,2,2,2,9
1,13,12,12,12,12,12,3,0,0,0,0,0,3,2,12,12,12,2,9
1,13,12,12,12,12,12,16,3,15,15,15,3,15,2,12,14,12,2,9
1,13,12,12,14,12,12,16,1,1,1,1,1,10,2,12,12,12,2,9
1,13,12,12,12,12,12,16,1,1,1,1,1,10,2,2,2,2,2,9
1,13,12,12,12,12,12,16,1,1,1,1,1,7,15,15,15,15,15,7
7,8,2,2,2,2,17,7,1,1,1,1,1,1,1,1,1,1,1,1
10,18,18,18,18,18,9,1,1,1,1,1,1,1,1,1,1,1,1,1
10,18,18,18,18,18,9,1,1,1,1,1,1,1,1,1,1,1,1,1
10,18,18,0,18,18,9,1,1,1,1,1,1,1,1,1,1,1,1,1
10,18,18,18,18,18,9,1,1,1,1,1,1,1,1,1,1,1,1,1
10,18,18,18,18,18,9,1,1,1,1,1,1,1,1,1,1,1,1,1
7,15,15,15,15,15,7,1,1,1,1,1,1,1,1,1,1,1,1,1
endlayer

layer
1,1,1,1,1,1,1,1,7,1,1,1,7,1,1,1,1,1,1,1
1,1,1,1,1,1,1,7,7,7,7,7,7,7,1,1,1,1,1,1
1,1,1,1,1,1,1,1,7,7,7,7,7,1,1,1,1,1,1,1
1,1,1,1,1,1,1,1,7,7,0,7,7,1,1,1,1,1,1,1
1,1,1,1,1,1,1,1,7,7,7,7,7,1,1,1,1,1,1,1
1,1,1,1,1,1,1,7,7,7,7,7,7,7,1,1,1,1,1,1
1,1,1,1,1,1,1,1,7,1,1,1,7,1,1,1,1,1,1,1
1,1,1,1,1,1,1,1,1,1,1,1,1,1,1,1,1,1,1,1
1,1,1,1,1,1,1,1,1,1,1,1,1,1,1,1,1,1,1,1
1,1,1,1,1,1,1,1,1,1,1,1,1,1,1,1,1,1,1,1
1,1,1,1,1,1,1,1,1,1,1,1,1,1,1,1,1,1,1,1
1,1,1,1,1,1,1,1,1,1,1,1,1,1,1,1,1,1,1,1
1,1,1,1,1,1,1,1,1,1,1,1,1,1,1,1,1,1,1,1
1,1,1,1,1,1,1,1,1,1,1,1,1,1,1,1,1,1,1,1
1,1,1,1,1,1,1,1,1,1,1,1,1,1,1,1,1,1,1,1
1,1,1,1,1,1,1,1,1,1,1,1,1,1,1,1,1,1,1,1
1,1,1,1,1,1,1,1,1,1,1,1,1,1,1,1,1,1,1,1
endlayer

