# Gilly's Windmill

# Template generated by Ruins mod version 14.6 Ingame Parser
# Structure designed by Gilly

weight=1
embed_into_distance=3
acceptable_target_blocks=
unacceptable_target_blocks=flowing_water,water,flowing_lava,lava,ice,bedrock,netherrack,soul_sand,gravel,sand,stone,Natura:Cloud
dimensions=24,15,12
allowable_overhang=0
max_leveling=3
leveling_buffer=-1
preserve_water=0
preserve_lava=0

rule1=0,100,preserveBlock
rule2=0,100,stonebrick-0
rule3=0,100,cobblestone_wall-0
rule4=0,100,stained_hardened_clay-8
rule5=0,100,hardened_clay-0
rule6=0,100,log-0
rule7=0,100,log-8
rule8=0,100,hay_block-0
rule9=0,100,hay_block-4
rule10=0,100,hay_block-8
rule11=0,100,stone_slab-3
rule12=0,100,log-4
rule13=1,100,torch-5
rule14=0,100,ladder-2
rule15=0,100,fence-0
rule16=0,100,stone_brick_stairs-0
rule17=0,100,stone_brick_stairs-2
rule18=0,100,stone_brick_stairs-3
rule19=0,100,stone_slab-0
rule20=0,100,double_stone_slab-0
rule21=0,100,stone_brick_stairs-1
rule22=0,100,iron_bars-0
rule23=0,100,stone_brick_stairs-4
rule24=0,100,stone_brick_stairs-6
rule25=0,100,stone_brick_stairs-7
rule26=0,100,stone_brick_stairs-5
rule27=0,100,stone_slab-13
rule28=0,100,planks-0
rule29=0,100,oak_stairs-4
rule30=0,100,wooden_slab-8
rule31=0,100,oak_stairs-0
rule32=0,100,oak_stairs-5
rule33=0,100,oak_stairs-1

layer
1,1,1,1,1,1,1,1,1,1,1,1
1,1,1,1,1,1,1,1,1,1,1,1
1,2,3,2,3,2,3,2,3,2,1,1
2,2,2,1,1,1,1,1,2,2,2,1
3,2,1,1,1,1,1,1,1,2,3,1
2,1,1,1,1,1,1,1,1,1,2,1
3,1,1,1,1,1,1,1,1,1,3,1
2,1,1,1,1,1,1,1,1,1,2,1
3,1,1,1,1,1,1,1,1,1,3,1
2,1,1,1,1,1,1,1,1,1,2,1
3,2,1,1,1,1,1,1,1,2,3,1
2,2,2,1,1,1,1,1,2,2,2,1
2,2,2,2,2,2,2,2,2,2,2,1
1,2,2,2,2,2,2,2,2,2,1,1
1,2,2,2,3,2,3,2,2,2,1,1
endlayer

layer
1,1,1,1,1,1,1,1,1,1,1,1
1,1,1,1,1,1,1,1,1,1,1,1
1,2,3,2,3,2,3,2,3,2,1,1
2,2,2,1,1,1,1,1,2,2,2,1
3,2,1,1,1,1,1,1,1,2,3,1
2,1,1,1,1,1,1,1,1,1,2,1
3,1,1,1,1,1,1,1,1,1,3,1
2,1,1,1,1,1,1,1,1,1,2,1
3,1,1,1,1,1,1,1,1,1,3,1
2,1,1,1,1,1,1,1,1,1,2,1
3,2,1,1,1,1,1,1,1,2,3,1
2,2,2,1,1,1,1,1,2,2,2,1
1,2,2,2,2,2,2,2,2,2,1,1
1,1,2,2,2,2,2,2,2,1,1,1
1,1,2,2,3,2,3,2,2,1,1,1
endlayer

layer
1,1,1,1,1,1,1,1,1,1,1,1
1,1,1,1,1,1,1,1,1,1,1,1
1,2,2,2,3,2,3,2,2,2,1,1
2,2,2,1,1,1,1,1,2,2,2,1
2,2,1,1,1,1,1,1,1,2,2,1
2,1,1,1,1,1,1,1,1,1,2,1
3,1,1,1,1,1,1,1,1,1,3,1
2,1,1,1,1,1,1,1,1,1,2,1
3,1,1,1,1,1,1,1,1,1,3,1
2,1,1,1,1,1,1,1,1,1,2,1
2,2,1,1,1,1,1,1,1,2,2,1
2,2,2,1,1,1,1,1,2,2,2,1
1,2,2,2,2,2,2,2,2,2,1,1
1,1,1,2,2,2,2,2,1,1,1,1
1,1,1,2,2,2,2,2,1,1,1,1
endlayer

layer
1,1,1,1,1,1,1,1,1,1,1,1
1,1,1,1,1,1,1,1,1,1,1,1
1,1,2,2,2,2,2,2,2,1,1,1
1,2,2,4,4,4,4,4,2,2,1,1
2,2,4,4,4,4,5,4,4,2,2,1
2,4,4,4,4,5,4,5,4,4,2,1
2,4,4,4,5,5,5,5,5,4,2,1
2,4,5,4,5,4,4,5,4,4,2,1
2,4,4,5,5,5,4,4,5,5,2,1
2,4,4,5,5,5,5,5,5,4,2,1
2,2,4,4,5,5,5,4,4,2,2,1
1,2,2,4,4,5,4,4,2,2,1,1
1,1,2,2,2,2,2,2,2,1,1,1
1,1,1,1,2,2,2,1,1,1,1,1
1,1,1,1,1,1,1,1,1,1,1,1
endlayer

layer
1,1,0,0,0,0,0,0,0,1,1,1
1,0,0,0,0,0,0,0,0,0,1,1
0,0,2,6,7,7,7,6,2,0,0,1
0,2,2,8,9,8,0,8,2,2,0,0
2,2,9,10,0,0,0,0,0,2,2,0
6,8,10,9,0,0,0,11,0,0,6,0
12,9,8,0,0,0,11,8,11,0,12,0
12,0,0,0,13,0,0,11,0,0,12,0
12,0,0,0,0,0,0,0,0,0,12,0
6,7,6,14,0,0,0,0,0,0,6,0
2,2,0,0,0,0,0,0,9,2,2,0
0,2,2,0,0,0,0,0,2,2,0,0
0,0,2,6,15,0,15,6,2,0,0,1
1,0,0,0,0,0,0,0,0,0,1,1
1,1,0,0,0,0,0,0,0,1,1,1
endlayer

layer
1,0,0,0,0,0,0,0,0,0,0,1
0,0,0,0,0,0,0,0,0,0,0,0
0,0,16,6,15,0,15,6,16,0,0,0
0,3,2,9,0,0,0,0,2,3,0,0
18,2,8,0,0,0,0,0,0,2,17,0
6,9,0,0,0,0,0,19,0,0,6,0
15,0,0,0,0,0,19,20,19,0,15,0
0,0,0,0,0,0,0,19,0,0,0,0
15,0,0,0,0,0,0,0,0,0,15,0
6,0,6,14,0,0,0,0,0,0,6,0
18,2,0,0,0,0,0,0,10,2,17,0
0,3,2,0,0,0,0,0,2,3,0,0
0,0,21,6,15,0,15,6,21,0,0,0
0,0,0,0,0,0,0,0,0,0,0,0
1,0,0,0,0,0,0,0,0,0,0,1
endlayer

layer
0,0,0,0,0,0,0,0,0,0,0,0
0,0,0,0,0,0,0,0,0,0,0,0
0,0,0,6,15,0,15,6,0,0,0,0
0,3,2,8,0,0,0,0,2,3,0,0
0,2,9,0,0,0,0,0,0,2,0,0
6,0,0,0,0,0,0,0,0,0,6,0
15,0,0,0,0,0,0,3,0,0,15,0
0,0,0,0,0,0,0,0,0,0,0,0
15,0,0,0,0,0,0,0,0,0,15,0
6,0,6,14,0,0,0,0,0,0,6,0
0,2,0,0,0,0,0,0,0,2,0,0
0,3,2,0,0,0,0,0,2,3,0,0
0,0,0,6,15,0,15,6,0,0,0,0
0,0,0,0,0,0,0,0,0,0,0,0
0,0,0,0,0,0,0,0,0,0,0,0
endlayer

layer
0,0,0,0,0,0,0,0,0,0,0,0
0,0,0,0,0,0,0,0,0,0,0,0
0,0,0,6,15,15,15,6,0,0,0,0
0,3,18,0,0,0,0,0,17,3,0,0
0,16,0,0,0,0,0,0,0,16,0,0
6,0,0,0,0,0,0,0,0,0,6,0
15,0,0,0,0,0,0,3,0,0,15,0
15,0,0,0,0,0,0,0,0,0,15,0
15,0,0,0,0,0,0,0,0,0,15,0
6,0,6,14,0,0,0,0,0,0,6,0
0,21,0,0,0,0,0,0,0,21,0,0
0,3,18,0,0,0,0,0,17,3,0,0
0,0,0,6,15,15,15,6,0,0,0,0
0,0,0,0,0,0,0,0,0,0,0,0
0,0,0,0,0,0,0,0,0,0,0,0
endlayer

layer
0,0,0,0,0,0,0,0,0,0,0,0
0,0,0,0,0,0,0,0,0,0,0,0
0,0,0,6,22,22,22,6,0,0,0,0
0,2,23,0,0,0,0,0,23,2,0,0
0,25,2,0,0,0,0,0,2,24,0,0
6,0,0,0,0,0,0,0,0,0,6,0
22,0,0,0,0,0,0,3,0,0,22,0
22,0,0,0,0,0,0,0,0,0,22,0
22,0,0,0,0,0,0,0,0,0,22,0
6,0,6,14,0,0,0,0,0,0,6,0
0,25,2,0,0,0,0,0,2,24,0,0
0,2,26,0,0,0,0,0,26,2,0,0
0,0,0,6,15,15,15,6,0,0,0,0
0,0,0,0,0,0,0,0,0,0,0,0
0,0,0,0,0,0,0,0,0,0,0,0
endlayer

layer
0,0,0,0,0,0,0,0,0,0,0,0
0,0,0,0,0,0,0,0,0,0,0,0
0,0,0,6,7,7,7,6,0,0,0,0
0,18,16,0,27,0,27,0,16,16,0,0
0,18,2,7,7,7,7,7,2,17,0,0
6,0,12,0,0,0,0,0,12,0,6,0
12,27,12,0,0,0,0,3,12,27,12,0
12,0,12,0,0,0,0,0,12,0,12,22
12,27,12,0,0,0,0,0,12,27,12,22
6,0,12,14,0,0,0,0,12,0,6,22
0,18,2,7,7,7,7,7,2,17,0,0
0,21,21,0,27,0,27,0,21,17,0,0
0,0,0,6,7,7,7,6,0,0,0,0
0,0,0,0,0,0,0,0,0,0,0,0
0,0,0,0,0,0,0,0,0,0,0,0
endlayer

layer
0,0,0,0,0,0,0,0,0,0,0,0
0,0,0,0,0,0,0,0,0,0,0,0
0,0,0,15,15,15,15,15,0,0,0,0
0,0,0,18,16,2,16,17,0,0,0,0
0,0,2,6,28,28,28,6,2,0,0,0
15,16,6,28,28,28,28,28,6,16,15,0
15,18,28,28,28,28,28,3,28,17,15,0
15,2,28,28,28,28,28,28,28,2,15,29
15,18,28,28,28,28,28,28,28,17,15,22
15,21,6,14,28,28,28,28,6,21,15,22
0,0,2,6,28,28,28,6,2,0,0,0
0,0,0,18,21,2,21,17,0,0,0,0
0,0,0,15,15,15,15,15,0,0,0,0
0,0,0,0,0,0,0,0,0,0,0,0
0,0,0,0,0,0,0,0,0,0,0,0
endlayer

layer
0,0,0,0,0,0,0,0,0,0,0,0
0,0,0,0,0,0,0,0,0,0,0,0
0,0,0,0,0,0,0,0,0,0,0,0
0,0,0,0,0,0,0,0,0,0,0,0
0,0,2,6,7,7,7,6,2,0,0,0
0,0,6,9,8,0,0,0,6,0,0,0
0,0,12,9,0,0,0,3,12,0,0,0
0,0,12,0,0,13,0,0,12,0,0,29
0,0,12,0,0,0,0,10,12,0,0,22
0,0,6,14,0,0,0,9,6,0,0,22
0,0,2,6,7,7,7,6,2,0,0,0
0,0,0,0,0,0,0,0,0,0,0,0
0,0,0,0,0,0,0,0,0,0,0,0
0,0,0,0,0,0,0,0,0,0,0,0
0,0,0,0,0,0,0,0,0,0,0,0
endlayer

layer
0,0,0,0,0,0,0,0,0,0,0,0
0,0,0,0,0,0,0,0,0,0,0,0
0,0,0,0,0,0,0,0,0,0,0,0
0,0,0,0,0,0,0,0,0,0,0,0
0,0,15,6,0,0,0,6,15,0,0,0
0,0,6,10,0,0,0,0,6,0,0,0
0,0,0,0,0,0,0,3,0,0,0,0
0,0,0,0,0,0,0,0,0,0,0,29
0,0,0,0,0,0,0,0,0,0,0,22
0,0,6,14,0,0,0,8,6,0,0,22
0,0,15,6,0,0,0,6,15,0,0,0
0,0,0,0,0,0,0,0,0,0,0,0
0,0,0,0,0,0,0,0,0,0,0,0
0,0,0,0,0,0,0,0,0,0,0,0
0,0,0,0,0,0,0,0,0,0,0,0
endlayer

layer
0,0,0,0,0,0,0,0,0,0,0,0
0,0,0,0,0,0,0,0,0,0,0,0
0,0,0,0,0,0,0,0,0,0,0,0
0,0,0,0,0,0,0,0,0,0,0,0
0,0,15,6,0,0,0,6,15,0,0,0
0,0,6,9,0,0,0,0,6,0,0,0
0,0,0,0,0,0,0,3,0,0,0,0
0,0,0,0,0,0,0,0,0,0,0,29
0,0,0,0,0,0,0,0,0,0,0,22
0,0,6,14,0,0,0,0,6,0,0,22
0,0,15,6,0,0,0,6,15,0,0,0
0,0,0,0,0,0,0,0,0,0,0,0
0,0,0,0,0,0,0,0,0,0,0,0
0,0,0,0,0,0,0,0,0,0,0,0
0,0,0,0,0,0,0,0,0,0,0,0
endlayer

layer
0,0,0,0,0,0,0,0,0,0,0,22
0,0,0,0,0,0,0,0,0,0,0,22
0,0,0,0,0,0,0,0,0,0,0,22
0,0,0,0,0,0,0,0,0,0,0,22
0,0,15,6,22,22,22,6,15,0,0,22
0,0,6,0,0,0,0,0,6,0,0,22
0,0,22,0,0,0,0,3,22,0,0,22
0,0,22,0,0,0,0,0,22,0,0,28
0,0,22,0,0,0,0,0,22,0,0,22
0,0,6,14,0,0,0,0,6,0,0,22
0,0,15,6,22,22,22,6,15,0,0,0
0,0,0,0,0,0,0,0,0,0,0,0
0,0,0,0,0,0,0,0,0,0,0,0
0,0,0,0,0,0,0,0,0,0,0,0
0,0,0,0,0,0,0,0,0,0,0,0
endlayer

layer
0,0,0,0,0,0,0,0,0,0,0,22
0,0,0,0,0,0,0,0,0,0,0,22
0,0,0,0,0,0,0,0,0,0,0,22
0,0,0,0,0,0,0,0,0,0,0,22
0,0,15,6,7,7,7,6,15,0,0,22
0,0,6,0,0,0,0,0,6,0,0,22
0,0,12,0,0,0,0,3,12,0,0,22
0,0,12,0,0,0,0,0,12,0,0,28
0,0,12,30,30,30,30,30,12,0,0,22
0,0,6,14,30,30,30,30,6,0,0,22
0,0,15,6,7,7,7,6,15,0,0,0
0,0,0,0,0,0,0,0,0,0,0,0
0,0,0,0,0,0,0,0,0,0,0,0
0,0,0,0,0,0,0,0,0,0,0,0
0,0,0,0,0,0,0,0,0,0,0,0
endlayer

layer
0,0,0,0,0,0,0,0,0,0,0,0
0,0,0,0,0,0,0,0,0,0,0,31
0,0,0,0,0,0,0,0,0,0,0,31
0,0,0,9,0,0,0,9,0,0,0,31
0,0,9,6,15,15,15,6,10,0,0,31
0,10,6,0,0,0,0,0,6,10,0,28
0,0,23,0,0,0,0,3,23,0,0,28
0,7,7,7,7,7,7,7,7,7,7,7
0,0,26,0,0,13,0,0,26,0,0,28
0,10,6,14,0,0,0,0,6,10,0,28
0,0,9,6,15,15,15,6,10,0,0,32
0,0,0,9,0,0,0,9,0,0,0,32
0,0,0,0,0,0,0,0,0,0,0,32
0,0,0,0,0,0,0,0,0,0,0,32
0,0,0,0,0,0,0,0,0,0,0,0
endlayer

layer
0,0,0,0,0,0,0,0,0,0,0,0
0,0,0,0,0,0,0,0,0,0,0,0
0,0,0,0,0,0,0,0,0,0,0,0
0,0,0,9,9,9,9,9,0,0,0,0
0,0,10,6,7,7,7,6,9,0,0,0
0,10,6,0,0,0,0,23,6,10,0,22
0,10,12,0,0,0,25,3,12,10,0,22
0,10,12,0,0,0,0,26,12,10,0,28
0,10,12,0,0,0,0,0,12,10,0,22
0,10,6,0,0,0,0,0,6,10,0,22
0,0,10,6,7,7,7,6,10,0,0,22
0,0,0,9,9,9,9,9,0,0,0,22
0,0,0,0,0,0,0,0,0,0,0,22
0,0,0,0,0,0,0,0,0,0,0,22
0,0,0,0,0,0,0,0,0,0,0,22
endlayer

layer
0,0,0,0,0,0,0,0,0,0,0,0
0,0,0,0,0,0,0,0,0,0,0,0
0,0,0,0,0,0,0,0,0,0,0,0
0,0,0,0,0,9,0,0,0,0,0,0
0,0,0,9,9,9,9,9,0,0,0,0
0,0,10,0,0,0,0,0,10,0,0,22
0,0,10,0,0,0,0,0,10,0,0,22
0,10,10,0,0,0,0,0,10,10,0,28
0,0,10,0,0,0,0,0,10,0,0,22
0,0,10,0,0,0,0,0,10,0,0,22
0,0,0,9,9,9,9,9,0,0,0,22
0,0,0,0,0,9,0,0,0,0,0,22
0,0,0,0,0,0,0,0,0,0,0,22
0,0,0,0,0,0,0,0,0,0,0,22
0,0,0,0,0,0,0,0,0,0,0,22
endlayer

layer
0,0,0,0,0,0,0,0,0,0,0,0
0,0,0,0,0,0,0,0,0,0,0,0
0,0,0,0,0,0,0,0,0,0,0,0
0,0,0,0,0,0,0,0,0,0,0,0
0,0,0,0,9,9,9,0,0,0,0,0
0,0,0,9,8,0,8,10,0,0,0,22
0,0,10,8,0,0,0,8,10,0,0,22
0,0,10,0,0,0,0,0,10,0,0,33
0,0,10,8,0,0,0,8,10,0,0,0
0,0,0,9,8,0,8,10,0,0,0,0
0,0,0,0,9,9,9,0,0,0,0,0
0,0,0,0,0,0,0,0,0,0,0,0
0,0,0,0,0,0,0,0,0,0,0,0
0,0,0,0,0,0,0,0,0,0,0,0
0,0,0,0,0,0,0,0,0,0,0,0
endlayer

layer
0,0,0,0,0,0,0,0,0,0,0,0
0,0,0,0,0,0,0,0,0,0,0,0
0,0,0,0,0,0,0,0,0,0,0,0
0,0,0,0,0,0,0,0,0,0,0,0
0,0,0,0,0,0,0,0,0,0,0,0
0,0,0,0,0,9,0,0,0,0,0,22
0,0,0,0,8,8,8,0,0,0,0,22
0,0,0,10,8,8,8,10,0,0,0,33
0,0,0,0,8,8,8,0,0,0,0,0
0,0,0,0,0,9,0,0,0,0,0,0
0,0,0,0,0,0,0,0,0,0,0,0
0,0,0,0,0,0,0,0,0,0,0,0
0,0,0,0,0,0,0,0,0,0,0,0
0,0,0,0,0,0,0,0,0,0,0,0
0,0,0,0,0,0,0,0,0,0,0,0
endlayer

layer
0,0,0,0,0,0,0,0,0,0,0,0
0,0,0,0,0,0,0,0,0,0,0,0
0,0,0,0,0,0,0,0,0,0,0,0
0,0,0,0,0,0,0,0,0,0,0,0
0,0,0,0,0,0,0,0,0,0,0,0
0,0,0,0,0,0,0,0,0,0,0,22
0,0,0,0,0,0,0,0,0,0,0,22
0,0,0,0,0,0,0,0,0,0,0,33
0,0,0,0,0,0,0,0,0,0,0,0
0,0,0,0,0,0,0,0,0,0,0,0
0,0,0,0,0,0,0,0,0,0,0,0
0,0,0,0,0,0,0,0,0,0,0,0
0,0,0,0,0,0,0,0,0,0,0,0
0,0,0,0,0,0,0,0,0,0,0,0
0,0,0,0,0,0,0,0,0,0,0,0
endlayer

layer
0,0,0,0,0,0,0,0,0,0,0,0
0,0,0,0,0,0,0,0,0,0,0,0
0,0,0,0,0,0,0,0,0,0,0,0
0,0,0,0,0,0,0,0,0,0,0,0
0,0,0,0,0,0,0,0,0,0,0,0
0,0,0,0,0,0,0,0,0,0,0,22
0,0,0,0,0,0,0,0,0,0,0,22
0,0,0,0,0,0,0,0,0,0,0,33
0,0,0,0,0,0,0,0,0,0,0,0
0,0,0,0,0,0,0,0,0,0,0,0
0,0,0,0,0,0,0,0,0,0,0,0
0,0,0,0,0,0,0,0,0,0,0,0
0,0,0,0,0,0,0,0,0,0,0,0
0,0,0,0,0,0,0,0,0,0,0,0
0,0,0,0,0,0,0,0,0,0,0,0
endlayer

layer
0,0,0,0,0,0,0,0,0,0,0,0
0,0,0,0,0,0,0,0,0,0,0,0
0,0,0,0,0,0,0,0,0,0,0,0
0,0,0,0,0,0,0,0,0,0,0,0
0,0,0,0,0,0,0,0,0,0,0,0
0,0,0,0,0,0,0,0,0,0,0,22
0,0,0,0,0,0,0,0,0,0,0,22
0,0,0,0,0,0,0,0,0,0,0,22
0,0,0,0,0,0,0,0,0,0,0,0
0,0,0,0,0,0,0,0,0,0,0,0
0,0,0,0,0,0,0,0,0,0,0,0
0,0,0,0,0,0,0,0,0,0,0,0
0,0,0,0,0,0,0,0,0,0,0,0
0,0,0,0,0,0,0,0,0,0,0,0
0,0,0,0,0,0,0,0,0,0,0,0
endlayer

