# Gilly's underground Hangar

# Uses Blocks from Chisel mod

# template generated by Ruins mod version 14.6 Ingame Parser
# Structure created by Gilly

weight=1
embed_into_distance=21
acceptable_target_blocks=
unacceptable_target_blocks=flowing_water,water,flowing_lava,lava,ice,bedrock,netherrack,soul_sand,Natura:Cloud
dimensions=13,39,43
allowable_overhang=0
max_leveling=3
leveling_buffer=-1
preserve_water=0
preserve_lava=0

rule1=0,100,preserveBlock
rule2=0,100,minecraft:glowstone-0
rule3=0,100,minecraft:cauldron-0
rule4=0,100,chisel:limestone-13
rule5=0,100,chisel:limestone-9
rule6=0,100,chisel:limestone-1
rule7=0,100,minecraft:stained_hardened_clay-9
rule8=0,100,minecraft:stone_slab-13
rule9=0,100,minecraft:stone_slab-5
rule10=0,100,chisel:iron_bars-5
rule11=0,100,chisel:factoryblock-1
rule12=0,100,chisel:limestone_slab-13
rule13=0,100,chisel:limestone_slab-15
rule14=0,100,chisel:limestone_slab-1
rule15=0,100,minecraft:stained_glass_pane-3
rule16=0,100,chisel:technical-14
rule17=0,100,chisel:stonebricksmooth-10
rule18=0,100,minecraft:stone_brick_stairs-4
rule19=0,100,chisel:technical2-1
rule20=0,100,minecraft:stone_brick_stairs-0
rule21=0,100,minecraft:stone_brick_stairs-3
rule22=0,100,minecraft:stone_brick_stairs-2
rule23=0,100,chisel:cobblestone-10
rule24=0,100,chisel:technical-15
rule25=0,100,chisel:stonebricksmooth-14
rule26=0,100,chisel:technical-2
rule27=0,100,minecraft:stone_brick_stairs-1
rule28=0,100,minecraft:ladder-4
rule29=0,100,chisel:factoryblock-6
rule30=0,100,chisel:glass-14
rule31=0,100,chisel:glass-7
rule32=0,100,chisel:factoryblock-5
rule33=0,100,chisel:road_line-0
rule34=0,100,chisel:oak_planks-11
rule35=0,100,chisel:birch_planks-14
rule36=0,100,chisel:spruce_planks-14
rule37=0,100,chisel:factoryblock-4
rule38=0,100,chisel:spruce_planks-6
rule39=0,100,chisel:dark_oak_planks-7
rule40=0,100,chisel:spruce_planks-15
rule41=0,100,chisel:technical-6
rule42=0,100,chisel:spruce_planks-11
rule43=0,100,chisel:dark_oak_planks-6
rule44=0,100,chisel:oak_planks-15
rule45=0,100,minecraft:stained_hardened_clay-5
rule46=0,100,chisel:stained_glass_yellow-13
rule47=0,100,chisel:dark_oak_planks-14
rule48=0,100,chisel:technical2-2
rule49=0,100,chisel:technical-13
rule50=0,100,chisel:warningSign-1
rule51=0,100,chisel:warningSign-9
rule52=0,100,chisel:warningSign-0
rule53=0,100,minecraft:stained_hardened_clay-6
rule54=0,100,minecraft:stained_hardened_clay-8
rule55=0,100,minecraft:stained_hardened_clay-4
rule56=0,100,minecraft:stone_brick_stairs-5
rule57=0,100,minecraft:stone_slab-8

layer
1,1,1,1,1,1,1,1,1,1,1,1,1,1,1,1,1,1,1,1,1,1,1,1,1,1,1,1,1,1,1,1,1,1,1,1,1,1,1,1,1,1,1
1,1,1,1,2,1,1,1,2,1,1,1,1,1,2,1,1,1,2,1,1,1,1,1,2,1,1,1,2,1,1,1,1,1,2,1,1,1,2,1,1,1,1
1,1,1,1,3,0,0,0,3,1,1,1,1,1,3,0,0,0,3,1,1,1,1,1,3,0,0,0,3,1,1,1,1,1,3,0,0,0,3,1,1,1,1
1,1,1,1,0,0,0,0,0,1,1,1,1,1,0,0,0,0,0,1,1,1,1,1,0,0,0,0,0,1,1,1,1,1,0,0,0,0,0,1,1,1,1
1,1,1,1,0,0,0,0,0,1,1,1,1,1,0,0,0,0,0,1,1,1,1,1,0,0,0,0,0,1,1,1,1,1,0,0,0,0,0,1,1,1,1
1,1,1,1,2,0,0,0,2,1,1,1,1,1,2,0,0,0,2,1,1,1,1,1,2,0,0,0,2,1,1,1,1,1,2,0,0,0,2,1,1,1,1
1,1,1,1,3,4,4,4,3,1,1,1,1,1,3,4,4,4,3,1,1,1,1,1,3,4,4,4,3,1,1,1,1,1,3,4,4,4,3,1,1,1,1
1,1,1,1,4,5,6,5,4,1,1,1,1,1,4,5,6,5,4,1,1,1,1,1,4,5,6,5,4,1,1,1,1,1,4,5,6,5,4,1,1,1,1
1,1,1,1,4,6,6,6,4,1,1,1,1,1,4,6,6,6,4,1,1,1,1,1,4,6,6,6,4,1,1,1,1,1,4,6,6,6,4,1,1,1,1
1,1,1,1,4,5,6,5,4,1,1,1,1,1,4,5,6,5,4,1,1,1,1,1,4,5,6,5,4,1,1,1,1,1,4,5,6,5,4,1,1,1,1
1,1,1,1,3,4,4,4,3,1,7,7,7,1,3,4,4,4,3,1,1,1,1,1,3,4,4,4,3,1,7,7,7,1,3,4,4,4,3,1,1,1,1
1,1,1,1,2,1,1,1,2,1,7,8,7,1,2,1,1,1,2,1,1,1,1,1,2,1,1,1,2,1,7,8,7,1,2,1,1,1,2,1,1,1,1
1,1,1,7,3,7,7,7,3,7,7,8,7,7,3,7,7,7,3,7,1,7,1,7,3,7,7,7,3,7,7,8,7,7,3,7,7,7,3,7,1,1,1
1,1,1,1,1,7,7,7,7,7,7,8,7,7,7,7,7,7,7,7,7,7,7,7,7,7,7,7,7,7,7,8,7,7,7,7,7,7,7,7,7,7,7
1,1,1,1,1,7,9,9,9,9,9,9,9,9,9,9,9,9,9,9,9,9,9,9,9,9,9,9,9,9,9,9,9,9,9,9,9,9,9,9,9,7,0
1,1,1,1,1,7,9,7,7,7,7,7,7,7,7,7,7,7,7,7,7,7,7,7,7,7,7,7,7,7,7,7,7,7,7,7,7,7,7,7,7,7,7
1,1,1,1,1,7,9,7,1,1,1,1,1,1,1,1,1,1,1,1,1,1,1,1,1,1,1,1,1,1,1,1,1,1,1,1,1,1,1,1,1,1,1
7,7,7,7,7,7,9,7,7,7,7,7,7,1,1,1,1,1,1,1,1,1,1,1,1,1,1,1,1,1,1,1,1,1,1,1,1,1,1,1,1,1,1
0,0,0,0,0,8,9,8,0,0,0,0,0,1,1,1,7,7,7,7,7,7,7,7,7,7,7,7,7,7,7,7,7,7,7,7,7,1,1,1,1,1,1
7,7,7,7,7,7,9,7,7,7,7,7,7,1,1,7,7,0,0,0,0,0,0,0,0,0,0,0,0,0,0,0,0,0,0,0,7,7,1,1,1,1,1
1,1,1,1,1,7,9,7,1,1,1,1,1,1,7,7,0,0,0,0,0,0,0,0,0,0,0,0,0,0,0,0,0,0,0,0,0,7,7,1,1,1,1
1,1,1,1,1,7,9,7,1,1,1,1,1,1,7,0,0,0,0,0,0,0,0,0,0,0,0,0,0,0,0,0,0,0,0,0,0,0,7,1,1,1,1
1,1,1,1,1,7,9,7,1,1,1,1,1,1,7,0,0,0,0,0,0,0,0,0,0,0,0,0,0,0,0,0,0,0,0,0,0,0,7,1,1,1,1
1,1,1,1,1,7,9,7,1,1,1,1,1,1,7,0,0,0,0,0,0,0,0,0,0,0,0,0,0,0,0,0,0,0,0,0,0,0,7,1,1,1,1
1,1,1,1,1,7,9,7,1,1,1,1,1,1,7,0,0,0,0,0,0,0,0,0,0,0,0,0,0,0,0,0,0,0,0,0,0,0,7,1,1,1,1
7,7,7,7,7,7,9,7,7,7,7,7,7,7,7,0,0,0,0,0,0,0,0,0,0,0,0,0,0,0,0,0,0,0,0,0,0,0,7,1,1,1,1
0,0,0,0,0,8,9,9,9,9,9,9,9,10,0,0,0,0,0,0,7,0,0,0,0,0,0,0,0,0,0,0,7,0,0,0,0,0,7,1,1,1,1
7,7,7,7,7,7,9,7,7,7,7,7,7,7,7,0,0,0,0,0,0,0,0,0,0,0,0,0,0,0,0,0,0,0,0,0,0,0,7,1,1,1,1
1,1,1,1,1,7,9,7,1,1,1,1,1,1,7,0,0,0,0,0,0,0,0,0,0,0,0,0,0,0,0,0,0,0,0,0,0,0,7,1,1,1,1
1,1,1,1,1,7,9,7,1,1,1,1,1,1,7,0,0,0,0,0,0,0,0,0,0,0,0,0,0,0,0,0,0,0,0,0,0,0,7,1,1,1,1
1,1,1,1,1,7,9,7,1,1,1,1,1,1,7,0,0,0,0,0,0,0,0,0,0,0,0,0,0,0,0,0,0,0,0,0,0,0,7,1,1,1,1
1,1,1,1,1,7,9,7,1,1,1,1,1,1,7,0,0,0,0,0,0,0,0,0,0,0,0,0,0,0,0,0,0,0,0,0,0,0,7,1,1,1,1
1,1,1,1,1,7,9,7,1,1,1,1,1,1,7,7,0,0,0,0,0,0,0,0,0,0,0,0,0,0,0,0,0,0,0,0,0,7,7,1,1,1,1
7,7,7,7,7,7,9,7,7,7,7,7,7,1,1,7,7,0,0,0,0,0,0,0,0,0,0,0,0,0,0,0,0,0,0,0,7,7,1,1,1,1,1
0,0,0,0,0,8,9,8,0,0,0,0,0,1,1,1,7,7,7,7,7,7,7,7,7,7,7,7,7,7,7,7,7,7,7,7,7,1,1,1,1,1,1
7,7,7,7,7,7,9,7,7,7,7,7,7,1,1,1,1,1,1,1,1,1,1,1,1,1,1,1,1,1,1,1,1,1,1,1,1,1,1,1,1,1,1
1,1,1,1,1,7,9,7,1,1,1,1,1,1,1,1,1,1,1,1,1,1,1,1,1,1,1,1,1,1,1,1,1,1,1,1,1,1,1,1,1,1,1
1,1,1,1,1,7,8,7,1,1,1,1,1,1,1,1,1,1,1,1,1,1,1,1,1,1,1,1,1,1,1,1,1,1,1,1,1,1,1,1,1,1,1
1,1,1,1,1,7,0,7,1,1,1,1,1,1,1,1,1,1,1,1,1,1,1,1,1,1,1,1,1,1,1,1,1,1,1,1,1,1,1,1,1,1,1
endlayer

layer
1,1,7,7,7,7,7,7,7,7,7,1,7,7,7,7,7,7,7,7,7,1,7,7,7,7,7,7,7,7,7,1,7,7,7,7,7,7,7,7,7,1,1
1,1,7,11,11,11,11,11,11,11,7,1,7,11,11,11,11,11,11,11,7,1,7,11,11,11,11,11,11,11,7,1,7,11,11,11,11,11,11,11,7,1,1
1,1,7,11,0,12,12,12,0,11,7,1,7,11,0,12,12,12,0,11,7,1,7,11,0,12,12,12,0,11,7,1,7,11,0,12,12,12,0,11,7,1,1
1,1,7,11,12,13,14,13,12,11,7,1,7,11,12,13,14,13,12,11,7,1,7,11,12,13,14,13,12,11,7,1,7,11,12,13,14,13,12,11,7,1,1
1,1,7,11,12,14,14,14,12,11,7,1,7,11,12,14,14,14,12,11,7,1,7,11,12,14,14,14,12,11,7,1,7,11,12,14,14,14,12,11,7,1,1
1,1,7,11,12,13,14,13,12,11,7,1,7,11,12,13,14,13,12,11,7,1,7,11,12,13,14,13,12,11,7,1,7,11,12,13,14,13,12,11,7,1,1
1,1,7,11,0,12,12,12,0,11,7,1,7,11,0,12,12,12,0,11,7,1,7,11,0,12,12,12,0,11,7,1,7,11,0,12,12,12,0,11,7,1,1
1,1,7,11,0,0,0,0,0,11,7,1,7,11,0,0,0,0,0,11,7,1,7,11,0,0,0,0,0,11,7,1,7,11,0,0,0,0,0,11,7,1,1
1,1,7,11,0,0,0,0,0,11,7,1,7,11,0,0,0,0,0,11,7,1,7,11,0,0,0,0,0,11,7,1,7,11,0,0,0,0,0,11,7,1,1
1,1,7,11,0,0,0,0,0,11,7,1,7,11,0,0,0,0,0,11,7,1,7,11,0,0,0,0,0,11,7,1,7,11,0,0,0,0,0,11,7,1,1
1,1,7,11,0,0,0,0,0,11,7,7,7,11,0,0,0,0,0,11,7,1,7,11,0,0,0,0,0,11,7,7,7,11,0,0,0,0,0,11,7,1,1
1,1,7,11,11,11,11,11,11,11,7,0,7,11,11,11,11,11,11,11,7,1,7,11,11,11,11,11,11,11,7,0,7,11,11,11,11,11,11,11,7,1,1
1,1,7,15,15,15,15,15,15,15,7,0,7,15,15,15,15,15,15,15,7,7,7,15,15,15,15,15,15,15,7,0,7,15,15,15,15,15,15,15,7,1,1
1,1,1,7,7,7,7,7,7,7,7,0,7,7,7,7,7,7,7,7,7,0,7,7,7,7,7,7,7,7,7,0,7,7,7,7,7,7,7,7,7,7,7
1,1,1,1,1,7,0,0,0,0,0,0,0,0,0,0,0,0,0,0,0,0,0,0,0,0,0,0,0,0,0,0,0,0,0,0,0,0,0,0,0,10,0
1,1,1,1,1,7,0,7,7,7,7,16,7,7,7,7,7,7,7,7,7,7,7,7,7,7,7,7,7,7,7,16,7,7,7,7,7,7,7,7,7,7,7
1,1,1,1,1,7,0,7,1,1,1,1,1,1,1,1,1,1,1,1,1,1,1,1,1,1,1,1,1,1,1,1,1,1,1,1,1,1,1,1,1,1,1
1,1,1,7,7,7,0,7,7,7,1,1,1,1,1,1,1,1,1,1,1,1,1,1,1,1,1,1,1,1,1,1,1,1,1,1,1,1,1,1,1,1,1
7,7,7,0,0,10,0,10,0,0,7,7,7,1,1,1,7,7,7,7,7,7,7,7,7,7,7,7,7,7,7,7,7,7,7,7,7,1,1,1,1,1,1
1,1,1,7,7,7,0,7,7,7,1,1,1,1,1,7,7,0,0,0,0,0,0,0,0,0,0,0,0,0,0,0,0,0,0,0,7,7,1,1,1,1,1
1,1,1,1,1,7,0,7,1,1,1,1,1,1,7,7,0,0,0,0,0,2,0,0,0,0,2,0,0,0,0,2,0,0,0,0,0,7,7,1,1,1,1
1,1,1,1,1,7,0,7,1,1,1,1,1,1,7,0,0,0,0,0,0,0,0,0,0,0,0,0,0,0,0,0,0,0,0,0,0,0,7,1,1,1,1
1,1,1,1,1,7,0,7,1,1,1,1,1,1,7,0,0,0,0,0,0,0,0,0,0,0,0,0,0,0,0,0,0,0,0,0,0,0,7,1,1,1,1
1,1,1,1,1,7,0,7,1,1,1,1,1,1,7,0,0,0,0,0,0,0,0,0,0,0,0,0,0,0,0,0,0,0,0,0,0,0,7,1,1,1,1
1,1,1,1,1,7,0,7,1,1,1,1,1,1,7,0,2,0,0,0,0,2,0,0,0,0,2,0,0,0,0,2,0,0,0,0,2,0,7,1,1,1,1
1,1,1,7,7,7,0,7,7,7,7,7,7,7,7,0,0,0,0,7,7,7,0,0,0,0,0,0,0,0,0,7,7,7,0,0,0,0,7,1,1,1,1
7,7,7,0,0,10,0,0,0,0,0,0,0,10,8,0,0,0,0,0,7,0,0,0,0,0,0,0,0,0,0,0,7,0,0,0,0,0,7,1,1,1,1
1,1,1,7,7,7,0,7,7,7,7,7,7,7,7,0,0,0,0,7,7,7,0,0,0,0,0,0,0,0,0,7,7,7,0,0,0,0,7,1,1,1,1
1,1,1,1,1,7,0,7,1,1,1,1,1,1,7,0,2,0,0,0,0,2,0,0,0,0,2,0,0,0,0,2,0,0,0,0,2,0,7,1,1,1,1
1,1,1,1,1,7,0,7,1,1,1,1,1,1,7,0,0,0,0,0,0,0,0,0,0,0,0,0,0,0,0,0,0,0,0,0,0,0,7,1,1,1,1
1,1,1,1,1,7,0,7,1,1,1,1,1,1,7,0,0,0,0,0,0,0,0,0,0,0,0,0,0,0,0,0,0,0,0,0,0,0,7,1,1,1,1
1,1,1,1,1,7,0,7,1,1,1,1,1,1,7,0,0,0,0,0,0,0,0,0,0,0,0,0,0,0,0,0,0,0,0,0,0,0,7,1,1,1,1
1,1,1,1,1,7,0,7,1,1,1,1,1,1,7,7,0,0,0,0,0,2,0,0,0,0,2,0,0,0,0,2,0,0,0,0,0,7,7,1,1,1,1
1,1,1,7,7,7,0,7,7,7,1,1,1,1,1,7,7,0,0,0,0,0,0,0,0,0,0,0,0,0,0,0,0,0,0,0,7,7,1,1,1,1,1
7,7,7,0,0,10,0,10,0,0,7,7,7,1,1,1,7,7,7,7,7,7,7,7,7,7,7,7,7,7,7,7,7,7,7,7,7,1,1,1,1,1,1
1,1,1,7,7,7,0,7,7,7,1,1,1,1,1,1,1,1,1,1,1,1,1,1,1,1,1,1,1,1,1,1,1,1,1,1,1,1,1,1,1,1,1
1,1,1,1,1,7,0,7,1,1,1,1,1,1,1,1,1,1,1,1,1,1,1,1,1,1,1,1,1,1,1,1,1,1,1,1,1,1,1,1,1,1,1
1,1,1,1,1,7,10,7,1,1,1,1,1,1,1,1,1,1,1,1,1,1,1,1,1,1,1,1,1,1,1,1,1,1,1,1,1,1,1,1,1,1,1
1,1,1,1,1,7,0,7,1,1,1,1,1,1,1,1,1,1,1,1,1,1,1,1,1,1,1,1,1,1,1,1,1,1,1,1,1,1,1,1,1,1,1
endlayer

layer
1,1,7,17,17,17,17,17,17,17,7,1,7,17,17,17,17,17,17,17,7,1,7,17,17,17,17,17,17,17,7,1,7,17,17,17,17,17,17,17,7,1,1
1,1,17,0,0,0,0,0,0,0,17,1,17,0,0,0,0,0,0,0,17,1,17,0,0,0,0,0,0,0,17,1,17,0,0,0,0,0,0,0,17,1,1
1,1,17,0,0,0,0,0,0,0,17,1,17,0,0,0,0,0,0,0,17,1,17,0,0,0,0,0,0,0,17,1,17,0,0,0,0,0,0,0,17,1,1
1,1,17,0,0,0,0,0,0,0,17,1,17,0,0,0,0,0,0,0,17,1,17,0,0,0,0,0,0,0,17,1,17,0,0,0,0,0,0,0,17,1,1
1,1,17,0,0,0,0,0,0,0,17,1,17,0,0,0,0,0,0,0,17,1,17,0,0,0,0,0,0,0,17,1,17,0,0,0,0,0,0,0,17,1,1
1,1,17,0,0,0,0,0,0,0,17,1,17,0,0,0,0,0,0,0,17,1,17,0,0,0,0,0,0,0,17,1,17,0,0,0,0,0,0,0,17,1,1
1,1,17,0,0,0,0,0,0,0,17,1,17,0,0,0,0,0,0,0,17,1,17,0,0,0,0,0,0,0,17,1,17,0,0,0,0,0,0,0,17,1,1
1,1,17,0,0,0,0,0,0,0,17,1,17,0,0,0,0,0,0,0,17,1,17,0,0,0,0,0,0,0,17,1,17,0,0,0,0,0,0,0,17,1,1
1,1,17,0,0,0,0,0,0,0,17,1,17,0,0,0,0,0,0,0,17,1,17,0,0,0,0,0,0,0,17,1,17,0,0,0,0,0,0,0,17,1,1
1,1,17,0,0,0,0,0,0,0,17,1,17,0,0,0,0,0,0,0,17,1,17,0,0,0,0,0,0,0,17,1,17,0,0,0,0,0,0,0,17,1,1
1,1,17,0,0,0,0,0,0,0,17,7,17,0,0,0,0,0,0,0,17,1,17,0,0,0,0,0,0,0,17,7,17,0,0,0,0,0,0,0,17,1,1
1,1,17,0,0,0,0,0,0,0,10,0,10,0,0,0,0,0,0,0,17,1,17,0,0,0,0,0,0,0,10,0,10,0,0,0,0,0,0,0,17,1,1
1,1,7,18,18,18,18,18,18,18,7,0,7,18,18,18,18,18,18,18,7,7,7,18,18,18,18,18,18,18,7,0,7,18,18,18,18,18,18,18,7,1,1
1,1,1,7,7,7,7,7,7,7,7,0,7,7,7,7,7,7,7,7,7,0,7,7,7,7,7,7,7,7,7,0,7,7,7,7,7,7,7,7,7,7,7
1,1,1,1,1,7,0,0,0,0,0,0,0,0,0,0,0,0,0,0,0,0,0,0,0,0,0,0,0,0,0,0,0,0,0,0,0,0,0,0,0,19,0
1,1,1,1,1,7,0,7,7,7,7,7,10,7,7,7,10,7,7,7,10,7,7,7,10,7,7,7,10,7,7,7,10,7,7,7,10,7,7,7,10,7,7
1,1,1,1,2,7,0,7,2,1,1,1,2,1,1,1,2,1,1,1,2,1,1,1,2,1,1,1,2,1,1,1,2,1,1,1,2,1,1,1,2,1,1
1,1,1,7,0,7,0,7,0,7,1,1,1,1,1,1,3,7,7,7,3,7,16,7,3,7,7,7,3,7,19,7,3,7,7,7,3,1,1,1,1,1,1
1,1,1,7,0,19,0,19,0,7,1,1,1,1,1,7,15,15,15,15,15,15,15,15,15,15,15,15,15,15,15,15,15,15,15,15,15,7,1,1,1,1,1
1,1,1,7,0,7,0,7,0,7,1,1,1,1,7,15,15,21,20,20,20,20,20,20,20,20,20,20,20,20,20,20,20,20,20,20,15,15,7,1,1,1,1
1,1,1,1,2,7,0,7,2,1,1,1,2,3,15,15,20,20,11,11,11,3,11,11,11,11,3,11,11,11,11,3,11,11,11,22,20,15,15,3,2,1,1
1,1,1,1,1,7,0,7,1,1,1,1,1,7,15,20,21,11,23,11,23,11,23,23,23,23,11,23,23,23,23,11,23,11,23,11,22,20,15,7,1,1,1
1,1,1,1,1,7,0,7,1,1,1,1,1,7,15,21,11,23,23,11,23,11,23,24,25,23,11,23,25,24,23,11,23,11,23,23,11,22,15,7,1,1,1
1,1,1,1,1,7,0,7,1,1,1,1,1,7,15,21,11,23,23,11,23,11,23,23,23,23,11,23,23,23,23,11,23,11,23,23,11,22,15,7,1,1,1
1,1,1,1,2,7,0,7,2,1,1,1,2,3,15,21,3,11,11,11,11,3,11,11,11,11,3,11,11,11,11,3,11,11,11,11,3,22,15,3,2,1,1
1,1,1,7,0,7,0,7,10,7,7,7,10,7,15,21,11,23,23,11,23,11,23,23,23,23,11,23,23,23,23,11,23,11,23,23,11,22,15,7,1,1,1
1,1,1,7,0,16,0,0,0,0,0,0,0,19,15,21,11,25,24,11,23,11,23,25,26,23,11,23,26,25,23,11,23,11,24,25,11,22,15,19,1,1,1
1,1,1,7,0,7,0,7,10,7,7,7,10,7,15,21,11,23,23,11,23,11,23,23,23,23,11,23,23,23,23,11,23,11,23,23,11,22,15,7,1,1,1
1,1,1,1,2,7,0,7,2,1,1,1,2,3,15,21,3,11,11,11,11,3,11,11,11,11,3,11,11,11,11,3,11,11,11,11,3,22,15,3,2,1,1
1,1,1,1,1,7,0,7,1,1,1,1,1,7,15,21,11,23,23,11,23,11,23,23,23,23,11,23,23,23,23,11,23,11,23,23,11,22,15,7,1,1,1
1,1,1,1,1,7,0,7,1,1,1,1,1,7,15,21,11,23,23,11,23,11,23,24,25,23,11,23,25,24,23,11,23,11,23,23,11,22,15,7,1,1,1
1,1,1,1,1,7,0,7,1,1,1,1,1,7,15,27,21,11,23,11,23,11,23,23,23,23,11,23,23,23,23,11,23,11,23,11,27,22,15,7,1,1,1
1,1,1,1,2,7,0,7,2,1,1,1,2,3,15,15,27,21,11,11,11,3,11,11,11,11,3,11,11,11,11,3,11,11,11,27,22,15,15,3,2,1,1
1,1,1,7,0,7,0,7,0,7,1,1,1,1,7,15,15,27,27,27,27,27,27,27,27,27,27,27,27,27,27,27,27,27,27,22,15,15,7,1,1,1,1
1,1,1,7,0,19,0,19,0,7,1,1,1,1,1,7,15,15,15,15,15,15,15,15,15,15,15,15,15,15,15,15,15,15,15,15,15,7,1,1,1,1,1
1,1,1,7,0,7,0,7,0,7,1,1,1,1,1,1,3,7,7,7,3,7,19,7,3,7,7,7,3,7,16,7,3,7,7,7,3,1,1,1,1,1,1
1,1,1,1,2,7,0,7,2,1,1,1,2,1,1,1,2,1,1,1,2,1,1,1,2,1,1,1,2,1,1,1,2,1,1,1,2,1,1,1,2,1,1
1,1,1,1,1,7,16,7,1,1,1,1,1,1,1,1,1,1,1,1,1,1,1,1,1,1,1,1,1,1,1,1,1,1,1,1,1,1,1,1,1,1,1
1,1,1,1,1,7,0,7,1,1,1,1,1,1,1,1,1,1,1,1,1,1,1,1,1,1,1,1,1,1,1,1,1,1,1,1,1,1,1,1,1,1,1
endlayer

layer
1,1,7,17,17,17,17,17,17,17,7,1,7,17,17,17,17,17,17,17,7,1,7,17,17,17,17,17,17,17,7,1,7,17,17,17,17,17,17,17,7,1,1
1,1,17,0,0,0,0,0,0,0,17,1,17,0,0,0,0,0,0,0,17,1,17,0,0,0,0,0,0,0,17,1,17,0,0,0,0,0,0,0,17,1,1
1,1,17,0,0,0,0,0,0,0,17,1,17,0,0,0,0,0,0,0,17,1,17,0,0,0,0,0,0,0,17,1,17,0,0,0,0,0,0,0,17,1,1
1,1,17,0,0,0,0,0,0,0,17,1,17,0,0,0,0,0,0,0,17,1,17,0,0,0,0,0,0,0,17,1,17,0,0,0,0,0,0,0,17,1,1
1,1,17,0,0,0,0,0,0,0,17,1,17,0,0,0,0,0,0,0,17,1,17,0,0,0,0,0,0,0,17,1,17,0,0,0,0,0,0,0,17,1,1
1,1,17,0,0,0,0,0,0,0,17,1,17,0,0,0,0,0,0,0,17,1,17,0,0,0,0,0,0,0,17,1,17,0,0,0,0,0,0,0,17,1,1
1,1,17,0,0,0,0,0,0,0,17,1,17,0,0,0,0,0,0,0,17,1,17,0,0,0,0,0,0,0,17,1,17,0,0,0,0,0,0,0,17,1,1
1,1,17,0,0,0,0,0,0,0,17,1,17,0,0,0,0,0,0,0,17,1,17,0,0,0,0,0,0,0,17,1,17,0,0,0,0,0,0,0,17,1,1
1,1,17,0,0,0,0,0,0,0,17,1,17,0,0,0,0,0,0,0,17,1,17,0,0,0,0,0,0,0,17,1,17,0,0,0,0,0,0,0,17,1,1
1,1,17,0,0,0,0,0,0,0,17,1,17,0,0,0,0,0,0,0,17,1,17,0,0,0,0,0,0,0,17,1,17,0,0,0,0,0,0,0,17,1,1
1,1,17,0,0,0,0,0,0,0,17,7,17,0,0,0,0,0,0,0,17,1,17,0,0,0,0,0,0,0,17,7,17,0,0,0,0,0,0,0,17,1,1
1,1,17,28,0,0,0,0,0,0,10,0,10,0,0,0,0,0,0,28,17,1,17,28,0,0,0,0,0,0,10,0,10,0,0,0,0,0,0,28,17,1,1
7,7,7,29,29,29,29,29,29,29,7,0,7,29,29,29,29,29,29,29,7,7,7,29,29,29,29,29,29,29,7,0,7,29,29,29,29,29,29,29,7,7,7
7,7,7,29,29,29,29,29,29,29,7,30,7,29,29,29,29,29,29,29,7,30,7,29,29,29,29,29,29,29,7,30,7,29,29,29,29,29,29,29,7,7,7
7,7,7,7,7,7,7,7,7,7,7,30,7,7,7,7,7,7,7,7,7,30,7,7,7,7,7,7,7,7,7,30,7,7,7,7,7,7,7,7,7,7,7
7,7,7,7,7,7,7,7,7,7,7,7,7,7,7,7,7,7,7,7,7,7,7,7,7,7,7,7,7,7,7,7,7,7,7,7,7,7,7,7,7,7,7
7,7,7,7,31,7,7,7,31,7,7,7,31,7,7,7,31,7,7,7,31,7,7,7,31,7,7,7,31,7,7,7,31,7,7,7,31,7,7,7,31,7,7
7,7,7,7,7,7,7,7,7,7,7,7,7,7,7,7,7,7,7,7,7,7,7,7,7,7,7,7,7,7,7,7,7,7,7,7,7,7,7,7,7,7,7
7,7,7,7,7,32,32,7,7,7,7,7,7,7,7,7,7,29,29,29,29,29,29,29,29,29,29,29,29,29,29,29,29,29,29,29,7,7,7,7,7,7,7
7,7,7,7,7,7,7,7,7,7,7,7,7,7,7,7,29,0,0,0,0,0,0,0,0,0,0,0,0,0,0,0,0,0,0,0,29,7,7,7,7,7,7
7,7,7,7,31,7,7,7,31,7,7,7,31,7,7,29,0,0,0,0,0,0,0,0,0,0,0,0,0,0,0,0,0,0,0,0,0,29,7,7,31,7,7
7,7,7,7,7,7,7,7,7,7,7,7,7,7,29,0,0,0,0,0,0,0,0,0,0,0,0,0,0,0,0,0,0,0,0,0,0,0,29,7,7,7,7
7,7,7,7,7,7,7,7,7,7,7,7,7,7,29,0,0,0,0,0,0,0,0,0,0,0,0,0,0,0,0,0,0,0,0,0,0,0,29,7,7,7,7
7,7,7,7,7,7,7,7,7,7,7,7,7,7,29,0,0,0,0,0,0,0,0,0,0,0,0,0,0,0,0,0,0,0,0,0,0,0,29,7,7,7,7
7,7,7,7,31,7,7,7,31,7,7,7,31,7,29,0,0,0,0,0,0,0,0,0,0,0,0,0,0,0,0,0,0,0,0,0,0,0,29,7,31,7,7
29,29,7,7,7,7,7,7,7,7,7,7,7,7,29,0,0,0,0,0,0,0,0,0,0,0,0,0,0,0,0,0,0,0,0,0,0,0,29,7,7,7,7
29,29,7,7,7,32,32,7,7,7,7,7,7,7,29,0,0,0,0,0,0,0,0,0,0,0,0,0,0,0,0,0,0,0,0,0,0,0,29,7,7,7,7
29,29,7,7,7,7,7,7,7,7,7,7,7,7,29,0,0,0,0,0,0,0,0,0,0,0,0,0,0,0,0,0,0,0,0,0,0,0,29,7,7,7,7
7,7,7,7,31,7,7,7,31,7,7,7,31,7,29,0,0,0,0,0,0,0,0,0,0,0,0,0,0,0,0,0,0,0,0,0,0,0,29,7,31,7,7
7,7,7,7,7,7,7,7,7,7,7,7,7,7,29,0,0,0,0,0,0,0,0,0,0,0,0,0,0,0,0,0,0,0,0,0,0,0,29,7,7,7,7
1,29,7,7,7,7,7,7,7,7,7,7,7,7,29,0,0,0,0,0,0,0,0,0,0,0,0,0,0,0,0,0,0,0,0,0,0,0,29,7,7,7,7
1,29,7,7,7,7,7,7,7,7,7,7,7,7,29,0,0,0,0,0,0,0,0,0,0,0,0,0,0,0,0,0,0,0,0,0,0,0,29,7,7,7,7
7,7,7,7,31,7,7,7,31,7,7,7,31,7,7,29,0,0,0,0,0,0,0,0,0,0,0,0,0,0,0,0,0,0,0,0,0,29,7,7,31,7,7
7,7,7,7,7,7,7,7,7,7,7,7,7,7,7,7,29,0,0,0,0,0,0,0,0,0,0,0,0,0,0,0,0,0,0,0,29,7,7,7,7,7,7
7,7,7,7,7,32,32,7,7,7,7,7,7,7,7,7,7,29,29,29,29,29,29,29,29,29,29,29,29,29,29,29,29,29,29,29,7,7,7,7,7,7,7
7,7,7,7,7,7,7,7,7,7,7,7,7,7,7,7,7,7,7,7,7,7,7,7,7,7,7,7,7,7,7,7,7,7,7,7,7,7,7,7,7,7,7
7,7,7,7,31,7,7,7,31,7,7,7,31,7,7,7,31,7,7,7,31,7,7,7,31,7,7,7,31,7,7,7,31,7,7,7,31,7,7,7,31,7,7
7,7,7,7,7,7,7,7,7,7,7,7,7,7,7,7,7,7,7,7,7,7,7,7,7,7,7,7,7,7,7,7,7,7,7,7,7,7,7,7,7,7,7
7,7,7,7,7,7,7,7,7,7,7,7,7,7,7,7,7,7,7,7,7,7,7,7,7,7,7,7,7,7,7,7,7,7,7,7,7,7,7,7,7,7,7
endlayer

layer
1,1,7,17,17,17,17,17,17,17,7,1,7,17,17,17,17,17,17,17,7,1,7,17,17,17,17,17,17,17,7,1,7,17,17,17,17,17,17,17,7,1,1
1,1,17,0,0,0,0,0,0,0,17,1,17,0,0,0,0,0,0,0,17,1,17,0,0,0,0,0,0,0,17,1,17,0,0,0,0,0,0,0,17,1,1
1,1,27,0,0,0,0,0,0,0,27,1,27,0,0,0,0,0,0,0,27,1,27,0,0,0,0,0,0,0,27,1,27,0,0,0,0,0,0,0,27,1,1
1,1,22,0,0,0,0,0,0,0,21,1,22,0,0,0,0,0,0,0,21,1,22,0,0,0,0,0,0,0,21,1,22,0,0,0,0,0,0,0,21,1,1
1,1,22,0,0,0,0,0,0,0,21,1,22,0,0,0,0,0,0,0,21,1,22,0,0,0,0,0,0,0,21,1,22,0,0,0,0,0,0,0,21,1,1
1,1,22,0,0,0,0,0,0,0,21,1,22,0,0,0,0,0,0,0,21,1,22,0,0,0,0,0,0,0,21,1,22,0,0,0,0,0,0,0,21,1,1
1,1,22,0,0,0,0,0,0,0,21,1,22,0,0,0,0,0,0,0,21,1,22,0,0,0,0,0,0,0,21,1,22,0,0,0,0,0,0,0,21,1,1
1,1,22,0,0,0,0,0,0,0,21,1,22,0,0,0,0,0,0,0,21,1,22,0,0,0,0,0,0,0,21,1,22,0,0,0,0,0,0,0,21,1,1
1,1,22,0,0,0,0,0,0,0,21,1,22,0,0,0,0,0,0,0,21,1,22,0,0,0,0,0,0,0,21,1,22,0,0,0,0,0,0,0,21,1,1
1,1,22,0,0,0,0,0,0,0,21,1,22,0,0,0,0,0,0,0,21,1,22,0,0,0,0,0,0,0,21,1,22,0,0,0,0,0,0,0,21,1,1
1,1,22,0,0,0,0,0,0,0,21,7,22,0,0,0,0,0,0,0,21,1,22,0,0,0,0,0,0,0,21,7,22,0,0,0,0,0,0,0,21,1,1
1,1,22,0,0,0,0,0,0,0,21,7,22,0,0,0,0,0,0,0,21,1,22,0,0,0,0,0,0,0,21,7,22,0,0,0,0,0,0,0,21,1,1
7,11,27,0,0,0,0,0,0,0,27,11,27,0,0,0,0,0,0,0,27,11,27,0,0,0,0,0,0,0,27,11,27,0,0,0,0,0,0,0,27,11,7
7,0,33,0,0,0,0,0,0,0,33,0,33,0,0,0,0,0,0,0,33,0,33,0,0,0,0,0,0,0,33,0,33,0,0,0,0,0,0,0,33,0,7
7,0,33,33,0,0,0,0,0,33,33,0,33,33,0,0,0,0,0,33,33,0,33,33,0,0,0,0,0,33,33,0,33,33,0,0,0,0,0,33,33,0,7
7,0,0,0,0,0,0,0,0,0,0,0,0,0,0,0,0,0,0,0,0,0,0,0,0,0,0,0,0,0,0,0,0,0,0,0,0,0,0,0,0,0,7
7,0,0,0,0,0,0,0,0,0,0,0,0,0,0,0,0,0,0,0,0,0,0,0,0,0,0,0,0,0,0,0,0,0,0,0,0,0,0,0,0,0,7
7,0,0,0,0,0,0,0,0,0,0,0,0,0,0,0,33,0,0,0,0,0,0,0,0,0,0,0,0,0,0,0,0,0,0,0,33,0,0,0,0,0,7
7,0,0,0,0,0,0,0,0,0,0,0,0,0,0,0,33,0,0,0,0,0,0,0,0,0,0,0,0,0,0,0,0,0,0,0,33,0,0,0,0,0,7
7,0,0,0,0,0,0,0,0,0,0,0,0,0,0,0,0,0,0,0,0,0,0,0,0,0,0,0,0,0,0,0,0,0,0,0,0,0,0,0,0,0,7
7,0,0,0,0,0,0,0,0,0,0,0,0,33,33,0,0,0,0,0,0,0,0,0,0,0,0,0,0,0,0,0,0,0,0,0,0,0,33,33,0,0,7
7,0,0,0,0,0,0,0,0,0,0,0,0,0,0,0,0,0,0,0,0,0,0,0,0,0,0,0,0,0,0,0,0,0,0,0,0,0,0,0,0,0,7
7,0,0,0,0,0,0,0,0,0,0,0,0,0,0,0,0,0,0,0,0,0,0,0,0,0,0,0,0,0,0,0,0,0,0,0,0,0,0,0,0,0,7
7,0,0,0,0,0,0,0,0,0,0,0,0,0,0,0,0,0,0,0,0,0,0,0,0,0,0,0,0,0,0,0,0,0,0,0,0,0,0,0,0,0,7
7,33,33,0,0,0,0,0,0,0,0,0,0,0,0,0,0,0,0,0,0,0,0,0,0,0,0,0,0,0,0,0,0,0,0,0,0,0,0,0,0,0,7
0,0,33,0,0,0,0,0,0,0,0,0,0,0,0,0,0,0,0,0,0,0,0,0,0,0,0,0,0,0,0,0,0,0,0,0,0,0,0,0,0,0,7
0,0,33,0,0,0,0,0,0,0,0,0,0,0,0,0,0,0,0,0,0,0,0,0,0,0,0,0,0,0,0,0,0,0,0,0,0,0,0,0,0,0,7
0,0,33,0,0,0,0,0,0,0,0,0,0,0,0,0,0,0,0,0,0,0,0,0,0,0,0,0,0,0,0,0,0,0,0,0,0,0,0,0,0,0,7
7,0,33,0,0,0,0,0,0,0,0,0,0,0,0,0,0,0,0,0,0,0,0,0,0,0,0,0,0,0,0,0,0,0,0,0,0,0,0,0,0,0,7
7,0,33,0,0,0,0,0,0,0,0,0,0,0,0,0,0,0,0,0,0,0,0,0,0,0,0,0,0,0,0,0,0,0,0,0,0,0,0,0,0,0,7
1,0,33,0,0,0,0,0,0,0,0,0,0,0,0,0,0,0,0,0,0,0,0,0,0,0,0,0,0,0,0,0,0,0,0,0,0,0,0,0,0,0,7
1,0,33,0,0,0,0,0,0,0,0,0,0,0,0,0,0,0,0,0,0,0,0,0,0,0,0,0,0,0,0,0,0,0,0,0,0,0,0,0,0,0,7
7,33,33,0,0,0,0,0,0,0,0,0,0,33,33,0,0,0,0,0,0,0,0,0,0,0,0,0,0,0,0,0,0,0,0,0,0,0,33,33,0,0,7
7,0,0,0,0,0,0,0,0,0,0,0,0,0,0,0,0,0,0,0,0,0,0,0,0,0,0,0,0,0,0,0,0,0,0,0,0,0,0,0,0,0,7
7,34,26,0,0,0,0,0,0,0,0,0,0,0,0,0,33,0,0,0,0,0,0,0,0,0,0,0,0,0,0,0,0,0,0,0,33,0,0,0,0,0,7
7,26,36,35,0,0,0,0,0,0,0,0,0,0,0,0,33,0,0,0,0,0,0,0,0,0,0,0,0,0,0,0,0,0,0,0,33,0,0,0,0,0,7
7,36,37,0,0,38,37,0,0,0,0,0,0,0,0,0,0,0,0,0,0,0,0,0,0,0,0,0,0,0,0,0,0,0,0,0,0,0,0,0,0,0,7
7,11,44,43,42,41,40,39,0,0,0,11,0,0,0,0,0,0,0,0,0,11,0,0,0,0,0,0,0,0,0,11,0,0,0,0,0,0,0,0,0,11,7
7,7,7,7,7,7,7,7,7,7,7,7,7,7,7,7,7,7,7,7,7,7,7,7,7,7,7,7,7,7,7,7,7,7,7,7,7,7,7,7,7,7,7
endlayer

layer
1,1,7,17,25,17,26,17,25,17,7,1,7,17,25,17,26,17,25,17,7,1,7,17,25,17,26,17,25,17,7,1,7,17,25,17,26,17,25,17,7,1,1
1,1,17,0,0,0,0,0,0,0,17,1,17,0,0,0,0,0,0,0,17,1,17,0,0,0,0,0,0,0,17,1,17,0,0,0,0,0,0,0,17,1,1
1,1,17,0,0,0,0,0,0,0,17,1,17,0,0,0,0,0,0,0,17,1,17,0,0,0,0,0,0,0,17,1,17,0,0,0,0,0,0,0,17,1,1
1,1,17,0,0,0,0,0,0,0,17,1,17,0,0,0,0,0,0,0,17,1,17,0,0,0,0,0,0,0,17,1,17,0,0,0,0,0,0,0,17,1,1
1,1,17,0,0,0,0,0,0,0,17,1,17,0,0,0,0,0,0,0,17,1,17,0,0,0,0,0,0,0,17,1,17,0,0,0,0,0,0,0,17,1,1
1,1,17,0,0,0,0,0,0,0,17,1,17,0,0,0,0,0,0,0,17,1,17,0,0,0,0,0,0,0,17,1,17,0,0,0,0,0,0,0,17,1,1
1,1,17,0,0,0,0,0,0,0,17,1,17,0,0,0,0,0,0,0,17,1,17,0,0,0,0,0,0,0,17,1,17,0,0,0,0,0,0,0,17,1,1
1,1,17,0,0,0,0,0,0,0,17,1,17,0,0,0,0,0,0,0,17,1,17,0,0,0,0,0,0,0,17,1,17,0,0,0,0,0,0,0,17,1,1
1,1,17,0,0,0,0,0,0,0,17,1,17,0,0,0,0,0,0,0,17,1,17,0,0,0,0,0,0,0,17,1,17,0,0,0,0,0,0,0,17,1,1
1,1,17,0,0,0,0,0,0,0,17,1,17,0,0,0,0,0,0,0,17,1,17,0,0,0,0,0,0,0,17,1,17,0,0,0,0,0,0,0,17,1,1
1,1,17,0,0,0,0,0,0,0,17,1,17,0,0,0,0,0,0,0,17,1,17,0,0,0,0,0,0,0,17,1,17,0,0,0,0,0,0,0,17,1,1
1,1,17,0,0,0,0,0,0,0,17,1,17,0,0,0,0,0,0,0,17,1,17,0,0,0,0,0,0,0,17,1,17,0,0,0,0,0,0,0,17,1,1
7,11,17,0,0,0,0,0,0,0,17,11,17,0,0,0,0,0,0,0,17,11,17,0,0,0,0,0,0,0,17,11,17,0,0,0,0,0,0,0,17,11,7
7,0,0,0,0,0,0,0,0,0,0,0,0,0,0,0,0,0,0,0,0,0,0,0,0,0,0,0,0,0,0,0,0,0,0,0,0,0,0,0,0,0,7
45,0,0,0,0,0,0,0,0,0,0,0,0,0,0,0,0,0,0,0,0,0,0,0,0,0,0,0,0,0,0,0,0,0,0,0,0,0,0,0,0,0,45
7,0,0,0,0,0,0,0,0,0,0,0,0,0,0,0,0,0,0,0,0,0,0,0,0,0,0,0,0,0,0,0,0,0,0,0,0,0,0,0,0,0,7
7,0,0,0,0,0,0,0,0,0,0,0,0,0,0,0,0,0,0,0,0,0,0,0,0,0,0,0,0,0,0,0,0,0,0,0,0,0,0,0,0,0,7
7,0,0,0,0,0,0,0,0,0,0,0,0,0,0,0,0,0,0,0,0,0,0,0,0,0,0,0,0,0,0,0,0,0,0,0,0,0,0,0,0,0,7
7,0,0,0,0,0,0,0,0,0,0,0,0,0,0,0,0,0,0,0,0,0,0,0,0,0,0,0,0,0,0,0,0,0,0,0,0,0,0,0,0,0,7
7,0,0,0,0,0,0,0,0,0,0,0,0,0,0,0,0,0,0,0,0,0,0,0,0,0,0,0,0,0,0,0,0,0,0,0,0,0,0,0,0,0,7
7,0,0,0,0,0,0,0,0,0,0,0,0,0,0,0,0,0,0,0,0,0,0,0,0,0,0,0,0,0,0,0,0,0,0,0,0,0,0,0,0,0,7
7,0,0,0,0,0,0,0,0,0,0,0,0,0,0,0,0,0,0,0,0,0,0,0,0,0,0,0,0,0,0,0,0,0,0,0,0,0,0,0,0,0,7
7,0,0,0,0,0,0,0,0,0,0,0,0,0,0,0,0,0,0,0,0,0,0,0,0,0,0,0,0,0,0,0,0,0,0,0,0,0,0,0,0,0,7
7,0,0,0,0,0,0,0,0,0,0,0,0,0,0,0,0,0,0,0,0,0,0,0,0,0,0,0,0,0,0,0,0,0,0,0,0,0,0,0,0,0,7
7,0,0,0,0,0,0,0,0,0,0,0,0,0,0,0,0,0,0,0,0,0,0,0,0,0,0,0,0,0,0,0,0,0,0,0,0,0,0,0,0,0,7
0,0,0,0,0,0,0,0,0,0,0,0,0,0,0,0,0,0,0,0,0,0,0,0,0,0,0,0,0,0,0,0,0,0,0,0,0,0,0,0,0,0,7
0,0,0,0,0,0,0,0,0,0,0,0,0,0,0,0,0,0,0,0,0,0,0,0,0,0,0,0,0,0,0,0,0,0,0,0,0,0,0,0,0,0,7
0,0,0,0,0,0,0,0,0,0,0,0,0,0,0,0,0,0,0,0,0,0,0,0,0,0,0,0,0,0,0,0,0,0,0,0,0,0,0,0,0,0,7
7,0,0,0,0,0,0,0,0,0,0,0,0,0,0,0,0,0,0,0,0,0,0,0,0,0,0,0,0,0,0,0,0,0,0,0,0,0,0,0,0,0,7
7,0,0,0,0,0,0,0,0,0,0,0,0,0,0,0,0,0,0,0,0,0,0,0,0,0,0,0,0,0,0,0,0,0,0,0,0,0,0,0,0,0,7
1,0,0,0,0,0,0,0,0,0,0,0,0,0,0,0,0,0,0,0,0,0,0,0,0,0,0,0,0,0,0,0,0,0,0,0,0,0,0,0,0,0,7
1,0,0,0,0,0,0,0,0,0,0,0,0,0,0,0,0,0,0,0,0,0,0,0,0,0,0,0,0,0,0,0,0,0,0,0,0,0,0,0,0,0,7
7,0,0,0,0,0,0,0,0,0,0,0,0,0,0,0,0,0,0,0,0,0,0,0,0,0,0,0,0,0,0,0,0,0,0,0,0,0,0,0,0,0,7
7,0,0,0,0,0,0,0,0,0,0,0,0,0,0,0,0,0,0,0,0,0,0,0,0,0,0,0,0,0,0,0,0,0,0,0,0,0,0,0,0,0,7
7,46,0,0,0,0,0,0,0,0,0,0,0,0,0,0,0,0,0,0,0,0,0,0,0,0,0,0,0,0,0,0,0,0,0,0,0,0,0,0,0,0,7
45,36,0,0,0,0,0,0,0,0,0,0,0,0,0,0,0,0,0,0,0,0,0,0,0,0,0,0,0,0,0,0,0,0,0,0,0,0,0,0,0,0,45
7,41,47,0,0,0,46,0,0,0,0,0,0,0,0,0,0,0,0,0,0,0,0,0,0,0,0,0,0,0,0,0,0,0,0,0,0,0,0,0,0,0,7
7,11,0,0,0,48,44,36,0,0,0,11,0,0,0,0,0,0,0,0,0,11,0,0,0,0,0,0,0,0,0,11,0,0,0,0,0,0,0,0,0,11,7
7,7,7,45,49,7,7,7,49,7,7,7,7,7,49,7,7,7,49,7,7,7,7,7,49,7,7,7,49,7,7,7,7,7,49,7,7,7,49,45,7,7,7
endlayer

layer
1,1,7,17,24,17,17,17,24,17,7,1,7,17,24,17,17,17,24,17,7,1,7,17,24,17,17,17,24,17,7,1,7,17,24,17,17,17,24,17,7,1,1
1,1,17,0,0,0,0,0,0,0,17,1,17,0,0,0,0,0,0,0,17,1,17,0,0,0,0,0,0,0,17,1,17,0,0,0,0,0,0,0,17,1,1
1,1,17,0,0,0,0,0,0,0,17,1,17,0,0,0,0,0,0,0,17,1,17,0,0,0,0,0,0,0,17,1,17,0,0,0,0,0,0,0,17,1,1
1,1,17,0,0,0,0,0,0,0,17,1,17,0,0,0,0,0,0,0,17,1,17,0,0,0,0,0,0,0,17,1,17,0,0,0,0,0,0,0,17,1,1
1,1,17,0,0,0,0,0,0,0,17,1,17,0,0,0,0,0,0,0,17,1,17,0,0,0,0,0,0,0,17,1,17,0,0,0,0,0,0,0,17,1,1
1,1,17,0,0,0,0,0,0,0,17,1,17,0,0,0,0,0,0,0,17,1,17,0,0,0,0,0,0,0,17,1,17,0,0,0,0,0,0,0,17,1,1
1,1,17,0,0,0,0,0,0,0,17,1,17,0,0,0,0,0,0,0,17,1,17,0,0,0,0,0,0,0,17,1,17,0,0,0,0,0,0,0,17,1,1
1,1,17,0,0,0,0,0,0,0,17,1,17,0,0,0,0,0,0,0,17,1,17,0,0,0,0,0,0,0,17,1,17,0,0,0,0,0,0,0,17,1,1
1,1,17,0,0,0,0,0,0,0,17,1,17,0,0,0,0,0,0,0,17,1,17,0,0,0,0,0,0,0,17,1,17,0,0,0,0,0,0,0,17,1,1
1,1,17,0,0,0,0,0,0,0,17,1,17,0,0,0,0,0,0,0,17,1,17,0,0,0,0,0,0,0,17,1,17,0,0,0,0,0,0,0,17,1,1
1,1,17,0,0,0,0,0,0,0,17,1,17,0,0,0,0,0,0,0,17,1,17,0,0,0,0,0,0,0,17,1,17,0,0,0,0,0,0,0,17,1,1
1,1,17,0,0,0,0,0,0,0,17,1,17,0,0,0,0,0,0,0,17,1,17,0,0,0,0,0,0,0,17,1,17,0,0,0,0,0,0,0,17,1,1
7,11,52,0,0,0,0,0,0,0,52,11,52,0,0,0,0,0,0,0,52,11,51,0,0,0,0,0,0,0,51,11,50,0,0,0,0,0,0,0,50,11,7
7,0,0,0,0,0,0,0,0,0,0,0,0,0,0,0,0,0,0,0,0,0,0,0,0,0,0,0,0,0,0,0,0,0,0,0,0,0,0,0,0,0,7
45,0,0,0,0,0,0,0,0,0,0,0,0,0,0,0,0,0,0,0,0,0,0,0,0,0,0,0,0,0,0,0,0,0,0,0,0,0,0,0,0,0,45
7,0,0,0,0,0,0,0,0,0,0,0,0,0,0,0,0,0,0,0,0,0,0,0,0,0,0,0,0,0,0,0,0,0,0,0,0,0,0,0,0,0,7
7,0,0,0,0,0,0,0,0,0,0,0,0,0,0,0,0,0,0,0,0,0,0,0,0,0,0,0,0,0,0,0,0,0,0,0,0,0,0,0,0,0,7
7,0,0,0,0,0,0,0,0,0,0,0,0,0,0,0,0,0,0,0,0,0,0,0,0,0,0,0,0,0,0,0,0,0,0,0,0,0,0,0,0,0,7
7,0,0,0,0,0,0,0,0,0,0,0,0,0,0,0,0,0,0,0,0,0,0,0,0,0,0,0,0,0,0,0,0,0,0,0,0,0,0,0,0,0,7
7,0,0,0,0,0,0,0,0,0,0,0,0,0,0,0,0,0,0,0,0,0,0,0,0,0,0,0,0,0,0,0,0,0,0,0,0,0,0,0,0,0,7
7,0,0,0,0,0,0,0,0,0,0,0,0,0,0,0,0,0,0,0,0,0,0,0,0,0,0,0,0,0,0,0,0,0,0,0,0,0,0,0,0,0,7
7,0,0,0,0,0,0,0,0,0,0,0,0,0,0,0,0,0,0,0,0,0,0,0,0,0,0,0,0,0,0,0,0,0,0,0,0,0,0,0,0,0,7
7,0,0,0,0,0,0,0,0,0,0,0,0,0,0,0,0,0,0,0,0,0,0,0,0,0,0,0,0,0,0,0,0,0,0,0,0,0,0,0,0,0,7
7,0,0,0,0,0,0,0,0,0,0,0,0,0,0,0,0,0,0,0,0,0,0,0,0,0,0,0,0,0,0,0,0,0,0,0,0,0,0,0,0,0,7
7,0,0,0,0,0,0,0,0,0,0,0,0,0,0,0,0,0,0,0,0,0,0,0,0,0,0,0,0,0,0,0,0,0,0,0,0,0,0,0,0,0,7
0,0,0,0,0,0,0,0,0,0,0,0,0,0,0,0,0,0,0,0,0,0,0,0,0,0,0,0,0,0,0,0,0,0,0,0,0,0,0,0,0,0,7
0,0,0,0,0,0,0,0,0,0,0,0,0,0,0,0,0,0,0,0,0,0,0,0,0,0,0,0,0,0,0,0,0,0,0,0,0,0,0,0,0,0,7
0,0,0,0,0,0,0,0,0,0,0,0,0,0,0,0,0,0,0,0,0,0,0,0,0,0,0,0,0,0,0,0,0,0,0,0,0,0,0,0,0,0,7
7,0,0,0,0,0,0,0,0,0,0,0,0,0,0,0,0,0,0,0,0,0,0,0,0,0,0,0,0,0,0,0,0,0,0,0,0,0,0,0,0,0,7
7,0,0,0,0,0,0,0,0,0,0,0,0,0,0,0,0,0,0,0,0,0,0,0,0,0,0,0,0,0,0,0,0,0,0,0,0,0,0,0,0,0,7
1,0,0,0,0,0,0,0,0,0,0,0,0,0,0,0,0,0,0,0,0,0,0,0,0,0,0,0,0,0,0,0,0,0,0,0,0,0,0,0,0,0,7
1,0,0,0,0,0,0,0,0,0,0,0,0,0,0,0,0,0,0,0,0,0,0,0,0,0,0,0,0,0,0,0,0,0,0,0,0,0,0,0,0,0,7
7,0,0,0,0,0,0,0,0,0,0,0,0,0,0,0,0,0,0,0,0,0,0,0,0,0,0,0,0,0,0,0,0,0,0,0,0,0,0,0,0,0,7
7,0,0,0,0,0,0,0,0,0,0,0,0,0,0,0,0,0,0,0,0,0,0,0,0,0,0,0,0,0,0,0,0,0,0,0,0,0,0,0,0,0,7
7,0,0,0,0,0,0,0,0,0,0,0,0,0,0,0,0,0,0,0,0,0,0,0,0,0,0,0,0,0,0,0,0,0,0,0,0,0,0,0,0,0,7
45,0,0,0,0,0,0,0,0,0,0,0,0,0,0,0,0,0,0,0,0,0,0,0,0,0,0,0,0,0,0,0,0,0,0,0,0,0,0,0,0,0,45
7,48,0,0,0,0,0,0,0,0,0,0,0,0,0,0,0,0,0,0,0,0,0,0,0,0,0,0,0,0,0,0,0,0,0,0,0,0,0,0,0,0,7
7,11,0,0,0,0,0,0,0,0,0,11,0,0,0,0,0,0,0,0,0,11,0,0,0,0,0,0,0,0,0,11,0,0,0,0,0,0,0,0,0,11,7
7,7,7,45,7,7,7,7,7,7,7,7,7,7,7,7,7,7,7,7,7,7,7,7,7,7,7,7,7,7,7,7,7,7,7,7,7,7,7,45,7,7,7
endlayer

layer
1,1,7,55,55,55,55,55,55,55,7,1,7,55,55,55,55,55,55,55,7,1,7,54,54,54,54,54,54,54,7,1,7,53,53,53,53,53,53,53,7,1,1
1,1,55,0,0,0,0,0,0,0,55,1,55,0,0,0,0,0,0,0,55,1,54,0,0,0,0,0,0,0,54,1,53,0,0,0,0,0,0,0,53,1,1
1,1,55,0,0,0,0,0,0,0,55,1,55,0,0,0,0,0,0,0,55,1,54,0,0,0,0,0,0,0,54,1,53,0,0,0,0,0,0,0,53,1,1
1,1,55,0,0,0,0,0,0,0,55,1,55,0,0,0,0,0,0,0,55,1,54,0,0,0,0,0,0,0,54,1,53,0,0,0,0,0,0,0,53,1,1
1,1,55,0,0,0,0,0,0,0,55,1,55,0,0,0,0,0,0,0,55,1,54,0,0,0,0,0,0,0,54,1,53,0,0,0,0,0,0,0,53,1,1
1,1,55,0,0,0,0,0,0,0,55,1,55,0,0,0,0,0,0,0,55,1,54,0,0,0,0,0,0,0,54,1,53,0,0,0,0,0,0,0,53,1,1
1,1,55,0,0,0,0,0,0,0,55,1,55,0,0,0,0,0,0,0,55,1,54,0,0,0,0,0,0,0,54,1,53,0,0,0,0,0,0,0,53,1,1
1,1,55,0,0,0,0,0,0,0,55,1,55,0,0,0,0,0,0,0,55,1,54,0,0,0,0,0,0,0,54,1,53,0,0,0,0,0,0,0,53,1,1
1,1,55,0,0,0,0,0,0,0,55,1,55,0,0,0,0,0,0,0,55,1,54,0,0,0,0,0,0,0,54,1,53,0,0,0,0,0,0,0,53,1,1
1,1,55,0,0,0,0,0,0,0,55,1,55,0,0,0,0,0,0,0,55,1,54,0,0,0,0,0,0,0,54,1,53,0,0,0,0,0,0,0,53,1,1
1,1,55,0,0,0,0,0,0,0,55,1,55,0,0,0,0,0,0,0,55,1,54,0,0,0,0,0,0,0,54,1,53,0,0,0,0,0,0,0,53,1,1
1,1,55,0,0,0,0,0,0,0,55,1,55,0,0,0,0,0,0,0,55,1,54,0,0,0,0,0,0,0,54,1,53,0,0,0,0,0,0,0,53,1,1
7,11,55,0,0,0,0,0,0,0,55,11,55,0,0,0,0,0,0,0,55,11,54,0,0,0,0,0,0,0,54,11,53,0,0,0,0,0,0,0,53,11,7
7,0,0,0,0,0,0,0,0,0,0,0,0,0,0,0,0,0,0,0,0,0,0,0,0,0,0,0,0,0,0,0,0,0,0,0,0,0,0,0,0,0,7
45,0,0,0,0,0,0,0,0,0,0,0,0,0,0,0,0,0,0,0,0,0,0,0,0,0,0,0,0,0,0,0,0,0,0,0,0,0,0,0,0,0,45
45,0,0,0,0,0,0,0,0,0,0,0,0,0,0,0,0,0,0,0,0,0,0,0,0,0,0,0,0,0,0,0,0,0,0,0,0,0,0,0,0,0,45
45,0,0,0,0,0,0,0,0,0,0,0,0,0,0,0,0,0,0,0,0,0,0,0,0,0,0,0,0,0,0,0,0,0,0,0,0,0,0,0,0,0,45
45,0,0,0,0,0,0,0,0,0,0,0,0,0,0,0,0,0,0,0,0,0,0,0,0,0,0,0,0,0,0,0,0,0,0,0,0,0,0,0,0,0,45
45,0,0,0,0,0,0,0,0,0,0,0,0,0,0,0,0,0,0,0,0,0,0,0,0,0,0,0,0,0,0,0,0,0,0,0,0,0,0,0,0,0,45
45,0,0,0,0,0,0,0,0,0,0,0,0,0,0,0,0,0,0,0,0,0,0,0,0,0,0,0,0,0,0,0,0,0,0,0,0,0,0,0,0,0,45
45,0,0,0,0,0,0,0,0,0,0,0,0,0,0,0,0,0,0,0,0,0,0,0,0,0,0,0,0,0,0,0,0,0,0,0,0,0,0,0,0,0,45
45,0,0,0,0,0,0,0,0,0,0,0,0,0,0,0,0,0,0,0,0,0,0,0,0,0,0,0,0,0,0,0,0,0,0,0,0,0,0,0,0,0,45
45,0,0,0,0,0,0,0,0,0,0,0,0,0,0,0,0,0,0,0,0,0,0,0,0,0,0,0,0,0,0,0,0,0,0,0,0,0,0,0,0,0,45
45,0,0,0,0,0,0,0,0,0,0,0,0,0,0,0,0,0,0,0,0,0,0,0,0,0,0,0,0,0,0,0,0,0,0,0,0,0,0,0,0,0,45
45,0,0,0,0,0,0,0,0,0,0,0,0,0,0,0,0,0,0,0,0,0,0,0,0,0,0,0,0,0,0,0,0,0,0,0,0,0,0,0,0,0,45
45,0,0,0,0,0,0,0,0,0,0,0,0,0,0,0,0,0,0,0,0,0,0,0,0,0,0,0,0,0,0,0,0,0,0,0,0,0,0,0,0,0,45
45,0,0,0,0,0,0,0,0,0,0,0,0,0,0,0,0,0,0,0,0,0,0,0,0,0,0,0,0,0,0,0,0,0,0,0,0,0,0,0,0,0,45
45,0,0,0,0,0,0,0,0,0,0,0,0,0,0,0,0,0,0,0,0,0,0,0,0,0,0,0,0,0,0,0,0,0,0,0,0,0,0,0,0,0,45
45,0,0,0,0,0,0,0,0,0,0,0,0,0,0,0,0,0,0,0,0,0,0,0,0,0,0,0,0,0,0,0,0,0,0,0,0,0,0,0,0,0,45
45,0,0,0,0,0,0,0,0,0,0,0,0,0,0,0,0,0,0,0,0,0,0,0,0,0,0,0,0,0,0,0,0,0,0,0,0,0,0,0,0,0,45
1,0,0,0,0,0,0,0,0,0,0,0,0,0,0,0,0,0,0,0,0,0,0,0,0,0,0,0,0,0,0,0,0,0,0,0,0,0,0,0,0,0,45
1,0,0,0,0,0,0,0,0,0,0,0,0,0,0,0,0,0,0,0,0,0,0,0,0,0,0,0,0,0,0,0,0,0,0,0,0,0,0,0,0,0,45
45,0,0,0,0,0,0,0,0,0,0,0,0,0,0,0,0,0,0,0,0,0,0,0,0,0,0,0,0,0,0,0,0,0,0,0,0,0,0,0,0,0,45
45,0,0,0,0,0,0,0,0,0,0,0,0,0,0,0,0,0,0,0,0,0,0,0,0,0,0,0,0,0,0,0,0,0,0,0,0,0,0,0,0,0,45
45,0,0,0,0,0,0,0,0,0,0,0,0,0,0,0,0,0,0,0,0,0,0,0,0,0,0,0,0,0,0,0,0,0,0,0,0,0,0,0,0,0,45
45,0,0,0,0,0,0,0,0,0,0,0,0,0,0,0,0,0,0,0,0,0,0,0,0,0,0,0,0,0,0,0,0,0,0,0,0,0,0,0,0,0,45
7,0,0,0,0,0,0,0,0,0,0,0,0,0,0,0,0,0,0,0,0,0,0,0,0,0,0,0,0,0,0,0,0,0,0,0,0,0,0,0,0,0,7
7,11,0,0,0,0,0,0,0,0,0,11,0,0,0,0,0,0,0,0,0,11,0,0,0,0,0,0,0,0,0,11,0,0,0,0,0,0,0,0,0,11,7
7,7,7,45,45,45,45,45,45,45,45,7,45,45,45,45,45,45,45,45,45,7,45,45,45,45,45,45,45,45,45,7,45,45,45,45,45,45,45,45,7,7,7
endlayer

layer
1,1,7,17,17,17,17,17,17,17,7,1,7,17,17,17,17,17,17,17,7,1,7,17,17,17,17,17,17,17,7,1,7,17,17,17,17,17,17,17,7,1,1
1,1,17,0,0,0,0,0,0,0,17,1,17,0,0,0,0,0,0,0,17,1,17,0,0,0,0,0,0,0,17,1,17,0,0,0,0,0,0,0,17,1,1
1,1,17,0,0,0,0,0,0,0,17,1,17,0,0,0,0,0,0,0,17,1,17,0,0,0,0,0,0,0,17,1,17,0,0,0,0,0,0,0,17,1,1
1,1,17,0,0,0,0,0,0,0,17,1,17,0,0,0,0,0,0,0,17,1,17,0,0,0,0,0,0,0,17,1,17,0,0,0,0,0,0,0,17,1,1
1,1,17,0,0,0,0,0,0,0,17,1,17,0,0,0,0,0,0,0,17,1,17,0,0,0,0,0,0,0,17,1,17,0,0,0,0,0,0,0,17,1,1
1,1,17,0,0,0,0,0,0,0,17,1,17,0,0,0,0,0,0,0,17,1,17,0,0,0,0,0,0,0,17,1,17,0,0,0,0,0,0,0,17,1,1
1,1,17,0,0,0,0,0,0,0,17,1,17,0,0,0,0,0,0,0,17,1,17,0,0,0,0,0,0,0,17,1,17,0,0,0,0,0,0,0,17,1,1
1,1,17,0,0,0,0,0,0,0,17,1,17,0,0,0,0,0,0,0,17,1,17,0,0,0,0,0,0,0,17,1,17,0,0,0,0,0,0,0,17,1,1
1,1,17,0,0,0,0,0,0,0,17,1,17,0,0,0,0,0,0,0,17,1,17,0,0,0,0,0,0,0,17,1,17,0,0,0,0,0,0,0,17,1,1
1,1,17,0,0,0,0,0,0,0,17,1,17,0,0,0,0,0,0,0,17,1,17,0,0,0,0,0,0,0,17,1,17,0,0,0,0,0,0,0,17,1,1
1,1,17,0,0,0,0,0,0,0,17,1,17,0,0,0,0,0,0,0,17,1,17,0,0,0,0,0,0,0,17,1,17,0,0,0,0,0,0,0,17,1,1
1,1,17,0,0,0,0,0,0,0,17,1,17,0,0,0,0,0,0,0,17,1,17,0,0,0,0,0,0,0,17,1,17,0,0,0,0,0,0,0,17,1,1
7,11,17,0,0,0,0,0,0,0,17,11,17,0,0,0,0,0,0,0,17,11,17,0,0,0,0,0,0,0,17,11,17,0,0,0,0,0,0,0,17,11,7
7,0,0,0,0,0,0,0,0,0,0,0,0,0,0,0,0,0,0,0,0,0,0,0,0,0,0,0,0,0,0,0,0,0,0,0,0,0,0,0,0,0,7
7,0,0,0,0,0,0,0,0,0,0,0,0,0,0,0,0,0,0,0,0,0,0,0,0,0,0,0,0,0,0,0,0,0,0,0,0,0,0,0,0,0,7
7,0,0,0,0,0,0,0,0,0,0,0,0,0,0,0,0,0,0,0,0,0,0,0,0,0,0,0,0,0,0,0,0,0,0,0,0,0,0,0,0,0,7
7,0,0,0,0,0,0,0,0,0,0,0,0,0,0,0,0,0,0,0,0,0,0,0,0,0,0,0,0,0,0,0,0,0,0,0,0,0,0,0,0,0,7
7,0,0,0,0,0,0,0,0,0,0,0,0,0,0,0,0,0,0,0,0,0,0,0,0,0,0,0,0,0,0,0,0,0,0,0,0,0,0,0,0,0,7
7,0,0,0,0,0,0,0,0,0,0,0,0,0,0,0,0,0,0,0,0,0,0,0,0,0,0,0,0,0,0,0,0,0,0,0,0,0,0,0,0,0,7
7,0,0,0,0,0,0,0,0,0,0,0,0,0,0,0,0,0,0,0,0,0,0,0,0,0,0,0,0,0,0,0,0,0,0,0,0,0,0,0,0,0,7
7,0,0,0,0,0,0,0,0,0,0,0,0,0,0,0,0,0,0,0,0,0,0,0,0,0,0,0,0,0,0,0,0,0,0,0,0,0,0,0,0,0,7
7,0,0,0,0,0,0,0,0,0,0,0,0,0,0,0,0,0,0,0,0,0,0,0,0,0,0,0,0,0,0,0,0,0,0,0,0,0,0,0,0,0,7
7,0,0,0,0,0,0,0,0,0,0,0,0,0,0,0,0,0,0,0,0,0,0,0,0,0,0,0,0,0,0,0,0,0,0,0,0,0,0,0,0,0,7
7,0,0,0,0,0,0,0,0,0,0,0,0,0,0,0,0,0,0,0,0,0,0,0,0,0,0,0,0,0,0,0,0,0,0,0,0,0,0,0,0,0,7
7,0,0,0,0,0,0,0,0,0,0,0,0,0,0,0,0,0,0,0,0,0,0,0,0,0,0,0,0,0,0,0,0,0,0,0,0,0,0,0,0,0,7
7,0,0,0,0,0,0,0,0,0,0,0,0,0,0,0,0,0,0,0,0,0,0,0,0,0,0,0,0,0,0,0,0,0,0,0,0,0,0,0,0,0,7
7,0,0,0,0,0,0,0,0,0,0,0,0,0,0,0,0,0,0,0,0,0,0,0,0,0,0,0,0,0,0,0,0,0,0,0,0,0,0,0,0,0,7
7,0,0,0,0,0,0,0,0,0,0,0,0,0,0,0,0,0,0,0,0,0,0,0,0,0,0,0,0,0,0,0,0,0,0,0,0,0,0,0,0,0,7
7,0,0,0,0,0,0,0,0,0,0,0,0,0,0,0,0,0,0,0,0,0,0,0,0,0,0,0,0,0,0,0,0,0,0,0,0,0,0,0,0,0,7
7,0,0,0,0,0,0,0,0,0,0,0,0,0,0,0,0,0,0,0,0,0,0,0,0,0,0,0,0,0,0,0,0,0,0,0,0,0,0,0,0,0,7
1,0,0,0,0,0,0,0,0,0,0,0,0,0,0,0,0,0,0,0,0,0,0,0,0,0,0,0,0,0,0,0,0,0,0,0,0,0,0,0,0,0,7
1,0,0,0,0,0,0,0,0,0,0,0,0,0,0,0,0,0,0,0,0,0,0,0,0,0,0,0,0,0,0,0,0,0,0,0,0,0,0,0,0,0,7
7,0,0,0,0,0,0,0,0,0,0,0,0,0,0,0,0,0,0,0,0,0,0,0,0,0,0,0,0,0,0,0,0,0,0,0,0,0,0,0,0,0,7
7,0,0,0,0,0,0,0,0,0,0,0,0,0,0,0,0,0,0,0,0,0,0,0,0,0,0,0,0,0,0,0,0,0,0,0,0,0,0,0,0,0,7
7,0,0,0,0,0,0,0,0,0,0,0,0,0,0,0,0,0,0,0,0,0,0,0,0,0,0,0,0,0,0,0,0,0,0,0,0,0,0,0,0,0,7
7,0,0,0,0,0,0,0,0,0,0,0,0,0,0,0,0,0,0,0,0,0,0,0,0,0,0,0,0,0,0,0,0,0,0,0,0,0,0,0,0,0,7
7,0,0,0,0,0,0,0,0,0,0,0,0,0,0,0,0,0,0,0,0,0,0,0,0,0,0,0,0,0,0,0,0,0,0,0,0,0,0,0,0,0,7
7,11,0,0,0,0,0,0,0,0,0,11,0,0,0,0,0,0,0,0,0,11,0,0,0,0,0,0,0,0,0,11,0,0,0,0,0,0,0,0,0,11,7
7,7,7,7,7,7,7,7,7,7,7,7,7,7,7,7,7,7,7,7,7,7,7,7,7,7,7,7,7,7,7,7,7,7,7,7,7,7,7,7,7,7,7
endlayer

layer
1,1,7,7,7,7,7,7,7,7,7,1,7,7,7,7,7,7,7,7,7,1,7,7,7,7,7,7,7,7,7,1,7,7,7,7,7,7,7,7,7,1,1
1,1,7,7,7,7,7,7,7,7,7,1,7,7,7,7,7,7,7,7,7,1,7,7,7,7,7,7,7,7,7,1,7,7,7,7,7,7,7,7,7,1,1
1,1,7,7,7,7,7,7,7,7,7,1,7,7,7,7,7,7,7,7,7,1,7,7,7,7,7,7,7,7,7,1,7,7,7,7,7,7,7,7,7,1,1
1,1,7,7,7,7,7,7,7,7,7,1,7,7,7,7,7,7,7,7,7,1,7,7,7,7,7,7,7,7,7,1,7,7,7,7,7,7,7,7,7,1,1
1,1,7,7,7,7,7,7,7,7,7,1,7,7,7,7,7,7,7,7,7,1,7,7,7,7,7,7,7,7,7,1,7,7,7,7,7,7,7,7,7,1,1
1,1,7,7,7,7,7,7,7,7,7,1,7,7,7,7,7,7,7,7,7,1,7,7,7,7,7,7,7,7,7,1,7,7,7,7,7,7,7,7,7,1,1
1,1,7,7,3,7,7,7,3,7,7,1,7,7,3,7,7,7,3,7,7,1,7,7,3,7,7,7,3,7,7,1,7,7,3,7,7,7,3,7,7,1,1
1,1,7,7,7,7,7,7,7,7,7,1,7,7,7,7,7,7,7,7,7,1,7,7,7,7,7,7,7,7,7,1,7,7,7,7,7,7,7,7,7,1,1
1,1,7,7,7,7,7,7,7,7,7,1,7,7,7,7,7,7,7,7,7,1,7,7,7,7,7,7,7,7,7,1,7,7,7,7,7,7,7,7,7,1,1
1,1,7,7,7,7,7,7,7,7,7,1,7,7,7,7,7,7,7,7,7,1,7,7,7,7,7,7,7,7,7,1,7,7,7,7,7,7,7,7,7,1,1
1,1,7,7,3,7,7,7,3,7,7,1,7,7,3,7,7,7,3,7,7,1,7,7,3,7,7,7,3,7,7,1,7,7,3,7,7,7,3,7,7,1,1
1,1,7,7,7,7,7,7,7,7,7,1,7,7,7,7,7,7,7,7,7,1,7,7,7,7,7,7,7,7,7,1,7,7,7,7,7,7,7,7,7,1,1
7,11,17,56,56,56,56,56,56,56,17,11,17,56,56,56,56,56,56,56,17,11,17,56,56,56,56,56,56,56,17,11,17,56,56,56,56,56,56,56,17,11,7
7,11,0,0,0,0,0,0,0,0,0,11,0,0,0,0,0,0,0,0,0,11,0,0,0,0,0,0,0,0,0,11,0,0,0,0,0,0,0,0,0,11,7
7,0,0,0,0,0,0,0,0,0,0,0,0,0,0,0,0,0,0,0,0,0,0,0,0,0,0,0,0,0,0,0,0,0,0,0,0,0,0,0,0,0,7
7,0,0,0,0,0,0,0,0,0,0,0,0,0,0,0,0,0,0,0,0,0,0,0,0,0,0,0,0,0,0,0,0,0,0,0,0,0,0,0,0,0,7
7,0,0,0,0,0,0,0,0,0,0,0,0,0,0,0,0,0,0,0,0,0,0,0,0,0,0,0,0,0,0,0,0,0,0,0,0,0,0,0,0,0,7
7,0,0,0,0,0,0,0,0,0,0,0,0,0,0,0,0,0,0,0,0,0,0,0,0,0,0,0,0,0,0,0,0,0,0,0,0,0,0,0,0,0,7
7,0,0,0,0,0,0,0,0,0,0,0,0,0,0,0,0,0,0,0,0,0,0,0,0,0,0,0,0,0,0,0,0,0,0,0,0,0,0,0,0,0,7
7,0,0,0,0,0,0,0,0,0,0,0,0,0,0,0,0,0,0,0,0,0,0,0,0,0,0,0,0,0,0,0,0,0,0,0,0,0,0,0,0,0,7
7,0,0,0,0,0,0,0,0,0,0,0,0,0,0,0,0,0,0,0,0,0,0,0,0,0,0,0,0,0,0,0,0,0,0,0,0,0,0,0,0,0,7
7,0,0,0,0,0,0,0,0,0,0,0,0,0,0,0,0,0,0,0,0,0,0,0,0,0,0,0,0,0,0,0,0,0,0,0,0,0,0,0,0,0,7
7,0,0,0,0,0,0,0,0,0,0,0,0,0,0,0,0,0,0,0,0,0,0,0,0,0,0,0,0,0,0,0,0,0,0,0,0,0,0,0,0,0,7
7,0,0,0,0,0,0,0,0,0,0,0,0,0,0,0,0,0,0,0,0,0,0,0,0,0,0,0,0,0,0,0,0,0,0,0,0,0,0,0,0,0,7
7,0,0,0,0,0,0,0,0,0,0,0,0,0,0,0,0,0,0,0,0,0,0,0,0,0,0,0,0,0,0,0,0,0,0,0,0,0,0,0,0,0,7
7,0,0,0,0,0,0,0,0,0,0,0,0,0,0,0,0,0,0,0,0,0,0,0,0,0,0,0,0,0,0,0,0,0,0,0,0,0,0,0,0,0,7
7,0,0,0,0,0,0,0,0,0,0,0,0,0,0,0,0,0,0,0,0,0,0,0,0,0,0,0,0,0,0,0,0,0,0,0,0,0,0,0,0,0,7
7,0,0,0,0,0,0,0,0,0,0,0,0,0,0,0,0,0,0,0,0,0,0,0,0,0,0,0,0,0,0,0,0,0,0,0,0,0,0,0,0,0,7
7,0,0,0,0,0,0,0,0,0,0,0,0,0,0,0,0,0,0,0,0,0,0,0,0,0,0,0,0,0,0,0,0,0,0,0,0,0,0,0,0,0,7
7,0,0,0,0,0,0,0,0,0,0,0,0,0,0,0,0,0,0,0,0,0,0,0,0,0,0,0,0,0,0,0,0,0,0,0,0,0,0,0,0,0,7
1,0,0,0,0,0,0,0,0,0,0,0,0,0,0,0,0,0,0,0,0,0,0,0,0,0,0,0,0,0,0,0,0,0,0,0,0,0,0,0,0,0,7
1,0,0,0,0,0,0,0,0,0,0,0,0,0,0,0,0,0,0,0,0,0,0,0,0,0,0,0,0,0,0,0,0,0,0,0,0,0,0,0,0,0,7
7,0,0,0,0,0,0,0,0,0,0,0,0,0,0,0,0,0,0,0,0,0,0,0,0,0,0,0,0,0,0,0,0,0,0,0,0,0,0,0,0,0,7
7,0,0,0,0,0,0,0,0,0,0,0,0,0,0,0,0,0,0,0,0,0,0,0,0,0,0,0,0,0,0,0,0,0,0,0,0,0,0,0,0,0,7
7,0,0,0,0,0,0,0,0,0,0,0,0,0,0,0,0,0,0,0,0,0,0,0,0,0,0,0,0,0,0,0,0,0,0,0,0,0,0,0,0,0,7
7,0,0,0,0,0,0,0,0,0,0,0,0,0,0,0,0,0,0,0,0,0,0,0,0,0,0,0,0,0,0,0,0,0,0,0,0,0,0,0,0,0,7
7,11,0,0,0,0,0,0,0,0,0,11,0,0,0,0,0,0,0,0,0,11,0,0,0,0,0,0,0,0,0,11,0,0,0,0,0,0,0,0,0,11,7
7,11,0,0,0,0,0,0,0,0,0,11,0,0,0,0,0,0,0,0,0,11,0,0,0,0,0,0,0,0,0,11,0,0,0,0,0,0,0,0,0,11,7
7,7,7,7,7,7,7,7,7,7,7,7,7,7,7,7,7,7,7,7,7,7,7,7,7,7,7,7,7,7,7,7,7,7,7,7,7,7,7,7,7,7,7
endlayer

layer
1,1,1,1,1,1,1,1,1,1,1,1,1,1,1,1,1,1,1,1,1,1,1,1,1,1,1,1,1,1,1,1,1,1,1,1,1,1,1,1,1,1,1
1,1,1,7,7,7,7,7,7,7,1,1,1,7,7,7,7,7,7,7,1,1,1,7,7,7,7,7,7,7,1,1,1,7,7,7,7,7,7,7,1,1,1
1,1,1,7,7,7,7,7,7,7,1,1,1,7,7,7,7,7,7,7,1,1,1,7,7,7,7,7,7,7,1,1,1,7,7,7,7,7,7,7,1,1,1
1,1,1,7,7,7,7,7,7,7,1,1,1,7,7,7,7,7,7,7,1,1,1,7,7,7,7,7,7,7,1,1,1,7,7,7,7,7,7,7,1,1,1
1,1,1,7,7,7,7,7,7,7,1,1,1,7,7,7,7,7,7,7,1,1,1,7,7,7,7,7,7,7,1,1,1,7,7,7,7,7,7,7,1,1,1
1,1,1,7,7,7,7,7,7,7,1,1,1,7,7,7,7,7,7,7,1,1,1,7,7,7,7,7,7,7,1,1,1,7,7,7,7,7,7,7,1,1,1
1,1,1,7,2,7,7,7,2,7,1,1,1,7,2,7,7,7,2,7,1,1,1,7,2,7,7,7,2,7,1,1,1,7,2,7,7,7,2,7,1,1,1
1,1,1,7,7,7,7,7,7,7,1,1,1,7,7,7,7,7,7,7,1,1,1,7,7,7,7,7,7,7,1,1,1,7,7,7,7,7,7,7,1,1,1
1,1,1,7,7,7,7,7,7,7,1,1,1,7,7,7,7,7,7,7,1,1,1,7,7,7,7,7,7,7,1,1,1,7,7,7,7,7,7,7,1,1,1
1,1,1,7,7,7,7,7,7,7,1,1,1,7,7,7,7,7,7,7,1,1,1,7,7,7,7,7,7,7,1,1,1,7,7,7,7,7,7,7,1,1,1
1,1,1,7,2,7,7,7,2,7,1,1,1,7,2,7,7,7,2,7,1,1,1,7,2,7,7,7,2,7,1,1,1,7,2,7,7,7,2,7,1,1,1
1,1,1,7,7,7,7,7,7,7,1,1,1,7,7,7,7,7,7,7,7,1,1,7,7,7,7,7,7,7,1,1,1,7,7,7,7,7,7,7,1,1,1
7,11,7,7,7,7,7,7,7,7,7,11,7,7,7,7,7,7,7,7,7,11,7,7,7,7,7,7,7,7,7,11,7,7,7,7,7,7,7,7,7,11,7
7,11,0,0,0,0,0,0,0,0,0,11,0,0,0,0,0,0,0,0,0,11,0,0,0,0,0,0,0,0,0,11,0,0,0,0,0,0,0,0,0,11,7
7,11,0,0,0,0,0,0,0,0,0,11,0,0,0,0,0,0,0,0,0,11,0,0,0,0,0,0,0,0,0,11,0,0,0,0,0,0,0,0,0,11,7
7,11,0,0,0,0,0,0,0,0,0,11,0,0,0,0,0,0,0,0,0,0,0,0,0,0,0,0,0,0,0,0,0,0,0,0,0,0,0,0,0,11,7
7,11,0,0,0,0,0,0,0,0,0,11,0,0,0,0,0,0,0,0,0,0,0,0,0,0,0,0,0,0,0,0,0,0,0,0,0,0,0,0,0,11,7
7,11,0,0,0,0,0,0,0,0,0,11,0,0,0,0,0,0,0,0,0,0,0,0,0,0,0,0,0,0,0,0,0,0,0,0,0,0,0,0,0,11,7
7,11,0,0,0,0,0,0,0,0,0,11,0,0,0,0,0,0,0,0,0,0,0,0,0,0,0,0,0,0,0,0,0,0,0,0,0,0,0,0,0,11,7
7,11,0,0,0,0,0,0,0,0,0,11,0,0,0,0,0,0,0,0,0,0,0,0,0,0,0,0,0,0,0,0,0,0,0,0,0,0,0,0,0,11,7
7,11,0,0,0,0,0,0,0,0,0,11,0,0,0,0,0,0,0,0,0,0,0,0,0,0,0,0,0,0,0,0,0,0,0,0,0,0,0,0,0,11,7
7,11,0,0,0,0,0,0,0,0,0,11,0,0,0,0,0,0,0,0,0,0,0,0,0,0,0,0,0,0,0,0,0,0,0,0,0,0,0,0,0,11,7
7,11,0,0,0,0,0,0,0,0,0,11,0,0,0,0,0,0,0,0,0,0,0,0,0,0,0,0,0,0,0,0,0,0,0,0,0,0,0,0,0,11,7
7,11,0,0,0,0,0,0,0,0,0,11,0,0,0,0,0,0,0,0,0,0,0,0,0,0,0,0,0,0,0,0,0,0,0,0,0,0,0,0,0,11,7
7,11,0,0,0,0,0,0,0,0,0,11,0,0,0,0,0,0,0,0,0,0,0,0,0,0,0,0,0,0,0,0,0,0,0,0,0,0,0,0,0,11,7
7,11,0,0,0,0,0,0,0,0,0,11,0,0,0,0,0,0,0,0,0,0,0,0,0,0,0,0,0,0,0,0,0,0,0,0,0,0,0,0,0,11,7
7,11,0,0,0,0,0,0,0,0,0,11,0,0,0,0,0,0,0,0,0,0,0,0,0,0,0,0,0,0,0,0,0,0,0,0,0,0,0,0,0,11,7
7,11,0,0,0,0,0,0,0,0,0,11,0,0,0,0,0,0,0,0,0,0,0,0,0,0,0,0,0,0,0,0,0,0,0,0,0,0,0,0,0,11,7
7,11,0,0,0,0,0,0,0,0,0,11,0,0,0,0,0,0,0,0,0,0,0,0,0,0,0,0,0,0,0,0,0,0,0,0,0,0,0,0,0,11,7
7,11,0,0,0,0,0,0,0,0,0,11,0,0,0,0,0,0,0,0,0,0,0,0,0,0,0,0,0,0,0,0,0,0,0,0,0,0,0,0,0,11,7
1,11,0,0,0,0,0,0,0,0,0,11,0,0,0,0,0,0,0,0,0,0,0,0,0,0,0,0,0,0,0,0,0,0,0,0,0,0,0,0,0,11,7
1,11,0,0,0,0,0,0,0,0,0,11,0,0,0,0,0,0,0,0,0,0,0,0,0,0,0,0,0,0,0,0,0,0,0,0,0,0,0,0,0,11,7
7,11,0,0,0,0,0,0,0,0,0,11,0,0,0,0,0,0,0,0,0,0,0,0,0,0,0,0,0,0,0,0,0,0,0,0,0,0,0,0,0,11,7
7,11,0,0,0,0,0,0,0,0,0,11,0,0,0,0,0,0,0,0,0,0,0,0,0,0,0,0,0,0,0,0,0,0,0,0,0,0,0,0,0,11,7
7,11,0,0,0,0,0,0,0,0,0,11,0,0,0,0,0,0,0,0,0,0,0,0,0,0,0,0,0,0,0,0,0,0,0,0,0,0,0,0,0,11,7
7,11,0,0,0,0,0,0,0,0,0,11,0,0,0,0,0,0,0,0,0,11,0,0,0,0,0,0,0,0,0,11,0,0,0,0,0,0,0,0,0,11,7
7,11,0,0,0,0,0,0,0,0,0,11,0,0,0,0,0,0,0,0,0,11,0,0,0,0,0,0,0,0,0,11,0,0,0,0,0,0,0,0,0,11,7
7,11,0,0,0,0,0,0,0,0,0,11,0,0,0,0,0,0,0,0,0,11,0,0,0,0,0,0,0,0,0,11,0,0,0,0,0,0,0,0,0,11,7
7,7,7,7,7,7,7,7,7,7,7,7,7,7,7,7,7,7,7,7,7,7,7,7,7,7,7,7,7,7,7,7,7,7,7,7,7,7,7,7,7,7,7
endlayer

layer
1,1,1,1,1,1,1,1,1,1,1,1,1,1,1,1,1,1,1,1,1,1,1,1,1,1,1,1,1,1,1,1,1,1,1,1,1,1,1,1,1,1,1
1,1,1,1,1,1,1,1,1,1,1,1,1,1,1,1,1,1,1,1,1,1,1,1,1,1,1,1,1,1,1,1,1,1,1,1,1,1,1,1,1,1,1
1,1,1,1,1,1,1,1,1,1,1,1,1,1,1,1,1,1,1,1,1,1,1,1,1,1,1,1,1,1,1,1,1,1,1,1,1,1,1,1,1,1,1
1,1,1,1,1,1,1,1,1,1,1,1,1,1,1,1,1,1,1,1,1,1,1,1,1,1,1,1,1,1,1,1,1,1,1,1,1,1,1,1,1,1,1
1,1,1,1,1,1,1,1,1,1,1,1,1,1,1,1,1,1,1,1,1,1,1,1,1,1,1,1,1,1,1,1,1,1,1,1,1,1,1,1,1,1,1
1,1,1,1,1,1,1,1,1,1,1,1,1,1,1,1,1,1,1,1,1,1,1,1,1,1,1,1,1,1,1,1,1,1,1,1,1,1,1,1,1,1,1
1,1,1,1,1,1,1,1,1,1,1,1,1,1,1,1,1,1,1,1,1,1,1,1,1,1,1,1,1,1,1,1,1,1,1,1,1,1,1,1,1,1,1
1,1,1,1,1,1,1,1,1,1,1,1,1,1,1,1,1,1,1,1,1,1,1,1,1,1,1,1,1,1,1,1,1,1,1,1,1,1,1,1,1,1,1
1,1,1,1,1,1,1,1,1,1,1,1,1,1,1,1,1,1,1,1,1,1,1,1,1,1,1,1,1,1,1,1,1,1,1,1,1,1,1,1,1,1,1
1,1,1,1,1,1,1,1,1,1,1,1,1,1,1,1,1,1,1,1,1,1,1,1,1,1,1,1,1,1,1,1,1,1,1,1,1,1,1,1,1,1,1
1,1,1,1,1,1,1,1,1,1,1,1,1,1,1,1,1,1,1,1,1,1,1,1,1,1,1,1,1,1,1,1,1,1,1,1,1,1,1,1,1,1,1
1,1,1,1,1,1,1,1,1,1,1,1,1,1,1,1,1,1,1,1,1,1,1,1,1,1,1,1,1,1,1,1,1,1,1,1,1,1,1,1,1,1,1
1,7,7,7,7,7,7,7,7,7,7,7,7,7,7,7,7,7,7,7,7,7,7,7,7,7,7,7,7,7,7,7,7,7,7,7,7,7,7,7,7,7,1
1,7,7,7,7,7,7,7,7,7,7,7,7,7,7,7,7,7,7,7,7,7,7,7,7,7,7,7,7,7,7,7,7,7,7,7,7,7,7,7,7,7,1
1,7,7,7,7,7,7,7,7,7,7,7,7,7,7,7,7,7,7,7,7,7,7,7,7,7,7,7,7,7,7,7,7,7,7,7,7,7,7,7,7,7,1
1,7,7,7,7,7,3,7,7,7,7,7,7,7,7,7,7,7,7,7,7,7,3,7,7,7,7,7,7,7,3,7,7,7,7,7,7,7,7,7,7,7,1
1,7,7,7,7,7,7,7,7,7,7,7,7,7,7,7,7,7,7,7,7,7,7,7,7,7,7,7,7,7,7,7,7,7,7,7,7,7,7,7,7,7,1
1,7,7,7,7,7,7,7,7,7,7,7,7,3,7,7,7,7,7,7,7,7,7,7,7,7,7,7,7,7,7,7,7,7,7,7,7,7,7,3,7,7,1
1,7,7,7,7,7,7,7,7,7,7,7,7,7,7,7,22,27,27,27,27,27,27,27,27,27,27,27,27,27,27,27,27,27,27,27,27,7,7,7,7,7,1
1,7,7,7,7,7,7,7,7,7,7,7,7,7,7,22,27,0,0,0,0,0,0,0,0,0,0,0,0,0,0,0,0,0,0,0,21,27,7,7,7,7,1
1,7,7,7,7,7,7,7,7,7,7,7,7,7,27,22,0,0,0,0,0,0,0,0,0,0,0,0,0,0,0,0,0,0,0,0,0,21,27,7,7,7,1
1,7,7,7,7,7,7,7,7,7,7,7,7,7,22,0,0,0,0,0,0,0,0,0,0,0,0,0,0,0,0,0,0,0,0,0,0,0,21,7,7,7,1
1,7,7,7,7,7,3,7,7,7,7,7,7,7,22,0,0,0,0,0,0,0,0,0,0,0,0,0,0,0,0,0,0,0,0,0,0,0,21,7,7,7,1
1,7,7,7,7,7,7,7,7,7,7,7,7,7,22,0,0,0,0,0,0,0,0,0,0,0,0,0,0,0,0,0,0,0,0,0,0,0,21,7,7,7,1
1,7,7,7,7,7,7,7,7,7,7,7,7,7,22,0,0,0,0,0,0,0,0,0,0,0,0,0,0,0,0,0,0,0,0,0,0,0,21,7,7,7,1
1,7,7,7,7,7,7,7,7,7,7,7,7,7,22,0,0,0,0,0,0,0,0,0,0,0,0,0,0,0,0,0,0,0,0,0,0,0,21,7,7,7,1
1,7,3,7,7,7,7,7,7,7,7,2,3,7,22,0,0,0,0,0,0,0,0,0,0,0,0,0,0,0,0,0,0,0,0,0,0,0,21,7,3,2,1
1,7,7,7,7,7,7,7,7,7,7,7,7,7,22,0,0,0,0,0,0,0,0,0,0,0,0,0,0,0,0,0,0,0,0,0,0,0,21,7,7,7,1
1,7,7,7,7,7,7,7,7,7,7,7,7,7,22,0,0,0,0,0,0,0,0,0,0,0,0,0,0,0,0,0,0,0,0,0,0,0,21,7,7,7,1
1,7,7,7,7,7,3,7,7,7,7,7,7,7,22,0,0,0,0,0,0,0,0,0,0,0,0,0,0,0,0,0,0,0,0,0,0,0,21,7,7,7,1
1,7,7,7,7,7,7,7,7,7,7,7,7,7,22,0,0,0,0,0,0,0,0,0,0,0,0,0,0,0,0,0,0,0,0,0,0,0,21,7,7,7,1
1,7,7,7,7,7,7,7,7,7,7,7,7,7,22,0,0,0,0,0,0,0,0,0,0,0,0,0,0,0,0,0,0,0,0,0,0,0,21,7,7,7,1
1,7,7,7,7,7,7,7,7,7,7,7,7,7,22,20,0,0,0,0,0,0,0,0,0,0,0,0,0,0,0,0,0,0,0,0,0,21,20,7,7,7,1
1,7,7,7,7,7,7,7,7,7,7,7,7,7,7,22,20,0,0,0,0,0,0,0,0,0,0,0,0,0,0,0,0,0,0,0,21,20,7,7,7,7,1
1,7,7,7,7,7,7,7,7,7,7,7,7,7,7,7,22,20,20,20,20,20,20,20,20,20,20,20,20,20,20,20,20,20,20,20,20,7,7,7,7,7,1
1,7,7,7,7,7,7,7,7,7,7,7,7,3,7,7,7,7,7,7,7,7,7,7,7,7,7,7,7,7,7,7,7,7,7,7,7,7,7,3,7,7,1
1,7,7,7,7,7,3,7,7,7,7,7,7,7,7,7,7,7,7,7,7,7,7,7,7,7,7,7,7,7,7,7,7,7,7,7,7,7,7,7,7,7,1
1,7,7,7,7,7,7,7,7,7,7,7,7,7,7,7,7,7,7,7,7,7,3,7,7,7,7,7,7,7,3,7,7,7,7,7,7,7,7,7,7,7,1
1,7,7,7,7,7,7,7,7,7,7,7,7,7,7,7,7,7,7,7,7,7,7,7,7,7,7,7,7,7,7,7,7,7,7,7,7,7,7,7,7,7,1
endlayer

layer
1,1,1,1,1,1,1,1,1,1,1,1,1,1,1,1,1,1,1,1,1,1,1,1,1,1,1,1,1,1,1,1,1,1,1,1,1,1,1,1,1,1,1
1,1,1,1,1,1,1,1,1,1,1,1,1,1,1,1,1,1,1,1,1,1,1,1,1,1,1,1,1,1,1,1,1,1,1,1,1,1,1,1,1,1,1
1,1,1,1,1,1,1,1,1,1,1,1,1,1,1,1,1,1,1,1,1,1,1,1,1,1,1,1,1,1,1,1,1,1,1,1,1,1,1,1,1,1,1
1,1,1,1,1,1,1,1,1,1,1,1,1,1,1,1,1,1,1,1,1,1,1,1,1,1,1,1,1,1,1,1,1,1,1,1,1,1,1,1,1,1,1
1,1,1,1,1,1,1,1,1,1,1,1,1,1,1,1,1,1,1,1,1,1,1,1,1,1,1,1,1,1,1,1,1,1,1,1,1,1,1,1,1,1,1
1,1,1,1,1,1,1,1,1,1,1,1,1,1,1,1,1,1,1,1,1,1,1,1,1,1,1,1,1,1,1,1,1,1,1,1,1,1,1,1,1,1,1
1,1,1,1,1,1,1,1,1,1,1,1,1,1,1,1,1,1,1,1,1,1,1,1,1,1,1,1,1,1,1,1,1,1,1,1,1,1,1,1,1,1,1
1,1,1,1,1,1,1,1,1,1,1,1,1,1,1,1,1,1,1,1,1,1,1,1,1,1,1,1,1,1,1,1,1,1,1,1,1,1,1,1,1,1,1
1,1,1,1,1,1,1,1,1,1,1,1,1,1,1,1,1,1,1,1,1,1,1,1,1,1,1,1,1,1,1,1,1,1,1,1,1,1,1,1,1,1,1
1,1,1,1,1,1,1,1,1,1,1,1,1,1,1,1,1,1,1,1,1,1,1,1,1,1,1,1,1,1,1,1,1,1,1,1,1,1,1,1,1,1,1
1,1,1,1,1,1,1,1,1,1,1,1,1,1,1,1,1,1,1,1,1,1,1,1,1,1,1,1,1,1,1,1,1,1,1,1,1,1,1,1,1,1,1
1,1,1,1,1,1,1,1,1,1,1,1,1,1,1,1,1,1,1,1,1,1,1,1,1,1,1,1,1,1,1,1,1,1,1,1,1,1,1,1,1,1,1
1,1,7,7,7,7,7,7,7,7,7,7,7,7,7,7,7,7,7,7,7,7,7,7,7,7,7,7,7,7,7,7,7,7,7,7,7,7,7,7,7,1,1
1,1,7,7,7,7,7,7,7,7,7,7,7,7,7,7,7,7,7,7,7,7,7,7,7,7,7,7,7,7,7,7,7,7,7,7,7,7,7,7,7,1,1
1,1,7,7,7,7,7,7,7,7,7,7,7,7,7,7,7,7,7,7,7,7,7,7,7,7,7,7,7,7,7,7,7,7,7,7,7,7,7,7,7,1,1
1,1,7,7,7,7,2,7,7,7,7,7,7,7,7,7,7,7,7,7,7,7,2,7,7,7,7,7,7,7,2,7,7,7,7,7,7,7,7,7,7,1,1
1,1,7,7,7,7,7,7,7,7,7,7,7,7,7,7,7,7,7,7,7,7,7,7,7,7,7,7,7,7,7,7,7,7,7,7,7,7,7,7,7,1,1
1,1,7,7,7,7,7,7,7,7,7,7,7,2,7,7,15,15,15,15,15,15,15,15,15,15,15,15,15,15,15,15,15,15,15,15,15,7,7,2,7,1,1
1,1,7,7,7,7,7,7,7,7,7,7,7,7,7,15,15,57,57,57,57,57,57,57,57,57,57,57,57,57,57,57,57,57,57,57,15,15,7,7,7,1,1
1,1,7,7,7,7,7,7,7,7,7,7,7,7,15,15,57,0,0,0,0,0,0,0,0,0,0,0,0,0,0,0,0,0,0,0,57,15,15,7,7,1,1
1,1,7,7,7,7,7,7,7,7,7,7,7,15,15,57,0,0,0,0,0,0,0,0,0,0,0,0,0,0,0,0,0,0,0,0,0,57,15,15,7,1,1
1,1,7,7,7,7,7,7,7,7,7,7,7,15,57,0,0,0,0,0,0,0,0,0,0,0,0,0,0,0,0,0,0,0,0,0,0,0,57,15,7,1,1
1,1,7,7,7,7,2,7,7,7,7,7,7,15,57,0,0,0,0,0,0,0,0,0,0,0,0,0,0,0,0,0,0,0,0,0,0,0,57,15,7,1,1
1,1,7,7,7,7,7,7,7,7,7,7,7,15,57,0,0,0,0,0,0,0,0,0,0,0,0,0,0,0,0,0,0,0,0,0,0,0,57,15,7,1,1
1,1,7,7,7,7,7,7,7,7,7,7,7,15,57,0,0,0,0,0,0,0,0,0,0,0,0,0,0,0,0,0,0,0,0,0,0,0,57,15,7,1,1
1,1,7,7,7,7,7,7,7,7,7,7,7,15,57,0,0,0,0,0,0,0,0,0,0,0,0,0,0,0,0,0,0,0,0,0,0,0,57,15,7,1,1
1,1,2,7,7,7,7,7,7,7,7,7,7,15,57,0,0,0,0,0,0,0,0,0,0,0,0,0,0,0,0,0,0,0,0,0,0,0,57,15,7,1,1
1,1,7,7,7,7,7,7,7,7,7,7,7,15,57,0,0,0,0,0,0,0,0,0,0,0,0,0,0,0,0,0,0,0,0,0,0,0,57,15,7,1,1
1,1,7,7,7,7,7,7,7,7,7,7,7,15,57,0,0,0,0,0,0,0,0,0,0,0,0,0,0,0,0,0,0,0,0,0,0,0,57,15,7,1,1
1,1,7,7,7,7,2,7,7,7,7,7,7,15,57,0,0,0,0,0,0,0,0,0,0,0,0,0,0,0,0,0,0,0,0,0,0,0,57,15,7,1,1
1,1,7,7,7,7,7,7,7,7,7,7,7,15,57,0,0,0,0,0,0,0,0,0,0,0,0,0,0,0,0,0,0,0,0,0,0,0,57,15,7,1,1
1,1,7,7,7,7,7,7,7,7,7,7,7,15,57,0,0,0,0,0,0,0,0,0,0,0,0,0,0,0,0,0,0,0,0,0,0,0,57,15,7,1,1
1,1,7,7,7,7,7,7,7,7,7,7,7,15,15,57,0,0,0,0,0,0,0,0,0,0,0,0,0,0,0,0,0,0,0,0,0,57,15,15,7,1,1
1,1,7,7,7,7,7,7,7,7,7,7,7,7,15,15,57,0,0,0,0,0,0,0,0,0,0,0,0,0,0,0,0,0,0,0,57,15,15,7,7,1,1
1,1,7,7,7,7,7,7,7,7,7,7,7,7,7,15,15,57,57,57,57,57,57,57,57,57,57,57,57,57,57,57,57,57,57,57,15,15,7,7,7,1,1
1,1,7,7,7,7,7,7,7,7,7,7,7,2,7,7,15,15,15,15,15,15,15,15,15,15,15,15,15,15,15,15,15,15,15,15,15,7,7,2,7,1,1
1,1,7,7,7,7,2,7,7,7,7,7,7,7,7,7,7,7,7,7,7,7,7,7,7,7,7,7,7,7,7,7,7,7,7,7,7,7,7,7,7,1,1
1,1,7,7,7,7,7,7,7,7,7,7,7,7,7,7,7,7,7,7,7,7,2,7,7,7,7,7,7,7,2,7,7,7,7,7,7,7,7,7,7,1,1
1,1,7,7,7,7,7,7,7,7,7,7,7,7,7,7,7,7,7,7,7,7,7,7,7,7,7,7,7,7,7,7,7,7,7,7,7,7,7,7,7,1,1
endlayer

