# Gilly's Reactor Access Port

# Uses Blocks from Chisel and Tinkers Construct

# template generated by Ruins mod version 14.6 Ingame Parser
# Structure created by Gilly

weight=1
embed_into_distance=14
acceptable_target_blocks=
unacceptable_target_blocks=flowing_water,water,flowing_lava,lava,ice,bedrock,netherrack,soul_sand,Natura:Cloud
dimensions=25,11,11
allowable_overhang=0
max_leveling=4
leveling_buffer=-1
preserve_water=0
preserve_lava=0

rule1=0,100,chisel:factoryblock-1
rule2=0,100,chisel:stonebricksmooth-12
rule3=0,100,chisel:technical-4
rule4=0,100,preserveBlock
rule5=0,100,minecraft:iron_bars-0
rule6=0,100,minecraft:ladder-3
rule7=0,100,minecraft:ladder-2
rule8=0,100,minecraft:glowstone-0
rule9=0,100,chisel:cobblestone-10
rule10=0,100,chisel:glass-7
rule11=0,100,TConstruct:slime.pad-6
rule12=0,100,chisel:glass-13
rule13=0,100,chisel:technical-1
rule14=0,100,ChestGenHook:villageBlacksmith:5-2
rule15=0,100,chisel:technical-14
rule16=0,100,chisel:technical2-1
rule17=0,100,minecraft:stained_hardened_clay-9
rule18=0,100,minecraft:stone_brick_stairs-1
rule19=0,100,minecraft:double_stone_slab-8
rule20=0,100,chisel:factoryblock-6
rule21=0,100,chisel:warningSign-0

layer
4,4,4,4,4,1,2,2,3,2,1
4,4,4,4,4,2,0,0,0,0,2
4,4,4,4,4,2,0,5,5,0,2
4,4,4,4,4,2,1,7,6,1,2
4,4,4,4,4,1,2,2,2,2,1
4,4,4,4,4,4,4,4,4,4,4
1,2,2,2,1,4,4,4,4,4,4
2,5,5,5,2,4,4,8,4,4,4
2,5,0,5,2,4,4,4,4,4,4
2,5,5,5,2,4,4,4,4,4,4
1,2,2,2,1,1,4,4,4,4,4
endlayer

layer
4,4,4,4,4,1,2,2,2,2,1
4,4,4,4,4,2,0,0,0,0,2
4,4,4,4,4,2,0,5,5,0,2
4,4,4,4,4,2,1,7,6,1,2
4,4,4,4,4,1,2,2,2,2,1
4,4,4,4,2,9,9,9,9,9,1
1,2,2,2,1,9,9,9,9,9,1
2,5,5,5,2,9,9,10,9,9,1
2,5,11,5,2,9,9,9,9,9,1
2,5,5,5,2,9,9,9,9,9,1
1,2,2,2,1,1,1,1,1,1,1
endlayer

layer
4,4,4,4,4,1,2,2,2,2,1
4,4,4,4,4,2,0,0,0,0,2
4,4,4,4,4,2,0,5,5,0,2
4,4,4,4,4,2,1,7,6,1,2
4,4,4,4,4,1,2,12,12,2,1
4,4,4,4,2,0,0,0,0,0,2
1,2,2,2,1,14,0,0,0,13,2
2,5,5,5,2,0,0,0,0,13,2
2,5,0,5,15,0,0,0,0,13,2
2,5,5,5,2,0,0,0,0,0,2
1,2,2,2,1,1,2,2,2,2,1
endlayer

layer
4,4,4,4,4,1,2,2,2,2,1
4,4,4,4,4,2,0,0,0,0,2
4,4,4,4,4,2,0,5,5,0,2
4,4,4,4,4,2,1,7,6,1,2
4,4,4,4,4,1,2,12,12,2,1
4,4,4,4,2,0,0,0,0,0,2
1,2,2,2,1,0,0,0,0,0,2
2,5,5,5,2,0,0,0,0,0,2
2,5,0,5,2,0,0,0,0,0,2
2,5,5,5,2,0,0,0,0,0,2
1,2,2,2,1,1,2,2,2,2,1
endlayer

layer
4,4,4,4,4,1,2,2,2,2,1
4,4,4,4,4,2,0,0,0,0,2
4,4,4,4,4,2,0,5,5,0,2
4,4,4,4,4,2,1,7,6,1,2
4,4,4,4,4,1,2,12,12,2,1
4,4,4,4,2,0,0,0,0,0,2
1,2,2,2,1,0,0,0,0,0,2
2,5,5,5,2,0,0,0,0,0,2
2,5,11,5,2,0,0,0,0,0,2
2,5,5,5,2,0,0,0,0,0,2
1,2,2,2,1,1,2,2,2,2,1
endlayer

layer
4,4,4,4,4,1,2,2,2,2,1
4,4,4,4,4,2,0,0,0,0,2
4,4,4,4,4,2,0,5,5,0,2
4,4,4,4,4,2,1,7,6,1,2
4,4,4,4,4,1,2,2,2,2,1
4,4,4,4,2,0,0,0,0,0,2
1,2,2,2,1,0,0,0,0,0,2
2,5,5,5,2,0,0,0,0,0,2
2,5,0,5,16,0,0,0,0,0,2
2,5,5,5,2,0,0,0,0,0,2
1,2,2,2,1,1,2,2,2,2,1
endlayer

layer
4,4,4,4,4,1,2,2,2,2,1
4,4,4,4,4,2,0,0,0,0,2
4,4,4,4,4,2,0,5,5,0,2
4,4,4,4,4,2,1,7,6,1,2
4,4,4,4,4,1,2,2,2,2,1
4,4,4,4,2,2,2,2,2,2,1
1,2,2,2,1,2,2,2,2,2,1
2,5,5,5,2,2,2,2,2,2,1
2,5,0,5,2,2,2,2,2,2,1
2,5,5,5,2,2,2,2,2,2,1
1,2,2,2,1,1,1,1,1,1,1
endlayer

layer
4,4,4,4,4,1,2,2,2,2,1
4,4,4,4,4,2,0,0,0,0,2
4,4,4,4,4,2,5,5,5,5,2
4,4,4,4,4,2,1,7,6,1,2
4,4,4,4,4,1,2,2,2,2,1
4,4,4,4,4,4,4,4,4,4,4
1,2,2,2,1,4,4,4,4,4,4
2,5,5,5,2,4,4,4,4,4,4
2,5,11,5,2,4,4,4,4,4,4
2,5,5,5,2,4,4,4,4,4,4
1,2,2,2,1,1,4,4,4,4,4
endlayer

layer
4,4,4,4,4,1,2,2,2,2,1
4,4,4,4,4,2,0,0,0,0,2
4,4,4,4,4,2,0,5,5,0,2
4,4,4,4,4,2,1,7,6,1,2
4,4,4,4,4,1,2,2,2,2,1
4,4,4,4,4,4,4,4,4,4,4
1,2,2,2,1,4,4,4,4,4,4
2,5,5,5,2,4,4,4,4,4,4
2,5,0,5,2,4,4,4,4,4,4
2,5,5,5,2,4,4,4,4,4,4
1,2,2,2,1,1,4,4,4,4,4
endlayer

layer
4,4,4,4,4,1,2,2,2,2,1
4,4,4,4,4,2,0,0,0,0,2
4,4,2,2,2,2,0,5,5,0,2
4,1,2,2,2,2,1,7,6,1,2
1,2,2,2,2,1,2,2,2,2,1
1,2,2,2,2,2,2,2,2,2,2
1,2,2,2,1,2,2,2,2,2,2
2,5,5,5,2,2,2,2,2,2,2
2,5,0,5,2,2,2,2,2,2,2
2,5,5,5,2,2,2,2,2,2,2
1,2,2,2,1,1,2,2,2,2,2
endlayer

layer
4,4,4,4,4,1,2,2,2,2,1
4,4,4,4,4,2,0,0,0,0,2
4,4,2,2,2,2,0,5,5,0,2
4,1,17,17,17,2,1,7,6,1,2
1,17,17,17,17,1,2,2,2,2,1
1,17,17,17,17,17,17,17,17,17,2
1,2,2,2,1,17,17,17,17,17,2
2,5,5,5,2,2,17,17,17,17,2
2,5,11,5,2,2,18,18,18,18,2
2,5,5,5,2,2,4,4,4,4,4
1,2,2,2,1,1,4,4,4,4,4
endlayer

layer
4,4,4,4,4,1,2,2,2,2,1
4,4,4,4,4,2,0,0,0,0,2
4,4,2,2,2,2,0,5,5,0,2
4,1,17,17,17,2,1,7,6,1,2
1,17,17,17,17,1,2,2,2,2,1
1,17,17,17,17,17,17,17,17,17,2
1,2,2,2,1,1,17,17,17,17,2
2,5,5,5,2,2,18,18,18,18,2
2,5,0,5,2,4,4,4,4,4,4
2,5,5,5,2,4,4,4,4,4,4
1,1,1,1,1,1,4,4,4,4,4
endlayer

layer
4,4,4,4,4,1,2,2,2,2,1
4,4,4,4,4,2,0,0,0,0,2
4,4,2,2,2,2,0,5,5,0,2
4,1,17,17,17,17,1,7,6,1,2
1,17,17,17,17,1,2,2,2,2,1
1,17,17,17,17,17,17,17,17,17,2
1,2,2,2,1,1,18,18,18,18,2
1,5,5,5,1,4,4,4,4,4,4
1,5,0,5,1,4,4,4,4,4,4
1,5,5,5,1,4,4,4,4,4,4
1,2,2,2,1,1,4,4,4,4,4
endlayer

layer
4,4,4,4,4,1,1,1,1,1,1
4,4,4,4,4,2,0,0,0,0,2
4,4,2,2,2,2,0,5,5,0,2
4,1,19,19,19,17,1,7,6,1,2
1,19,19,19,19,1,20,20,20,20,1
1,19,19,19,19,1,18,18,18,18,2
1,2,2,2,1,1,4,4,4,4,4
2,5,5,5,2,4,4,4,4,4,4
2,5,11,5,2,4,4,4,4,4,4
2,5,5,5,2,4,4,4,4,4,4
1,1,1,1,1,1,4,4,4,4,4
endlayer

layer
4,4,4,4,4,1,1,0,0,1,1
4,4,4,4,4,2,0,0,0,0,2
4,4,2,2,2,2,0,5,5,0,2
4,1,1,1,1,1,1,7,6,1,2
2,0,0,0,0,0,0,0,0,4,4
2,0,0,0,0,0,0,0,0,4,4
1,2,2,2,1,1,0,0,0,4,4
1,5,5,5,1,0,0,0,4,4,4
1,5,11,5,1,0,0,4,4,4,4
1,5,5,5,1,4,4,4,4,4,4
1,2,2,2,1,1,4,4,4,4,4
endlayer

layer
4,4,4,4,4,1,1,1,1,1,1
4,4,4,4,4,2,0,0,0,0,2
4,4,2,2,2,2,0,5,5,0,2
4,1,0,0,0,0,21,7,6,21,4
1,1,0,0,0,0,0,0,0,0,4
1,1,0,0,0,0,0,0,0,0,4
1,1,1,1,1,1,0,0,0,0,4
0,5,5,5,0,0,0,0,0,4,4
0,5,11,5,0,0,0,0,0,4,4
0,5,5,5,0,0,0,4,4,4,4
1,1,1,1,1,4,4,4,4,4,4
endlayer

layer
4,4,4,4,0,1,1,0,0,1,1
4,4,0,0,0,2,0,0,0,1,4
4,0,2,2,2,2,0,5,5,1,4
4,1,1,1,1,1,1,7,6,1,4
0,0,0,0,0,0,0,0,0,0,0
0,0,0,0,0,0,0,0,0,0,0
1,1,0,0,1,1,0,0,0,0,0
1,5,5,5,1,0,0,0,0,0,4
1,5,11,5,1,0,0,0,0,0,4
1,5,5,5,1,0,0,0,0,4,4
1,0,0,0,1,0,0,4,4,4,4
endlayer

layer
4,4,0,0,0,1,1,1,1,1,1
4,0,0,0,0,2,0,0,0,0,4
0,0,2,2,2,2,0,5,5,0,0
0,1,0,0,0,0,1,7,6,1,0
1,1,0,0,0,0,0,0,0,0,0
1,1,0,0,0,0,0,0,0,0,0
1,1,0,0,0,1,0,0,0,0,0
0,5,5,5,0,0,0,0,0,0,0
0,5,11,5,0,0,0,0,0,0,0
0,5,5,5,0,0,0,0,0,0,4
1,1,1,1,1,0,0,0,0,4,4
endlayer

layer
4,0,0,0,0,1,1,0,0,1,1
0,0,0,0,0,2,0,0,0,1,0
0,0,2,2,2,2,0,5,5,1,0
0,1,1,1,1,1,1,7,6,1,0
0,0,0,0,0,0,0,0,0,0,0
0,0,0,0,0,0,0,0,0,0,0
1,1,0,0,1,1,0,0,0,0,0
1,5,5,5,1,0,0,0,0,0,0
1,5,11,5,1,0,0,0,0,0,0
1,5,5,5,1,0,0,0,0,0,0
1,0,0,0,1,0,0,0,0,0,4
endlayer

layer
0,0,0,0,0,1,1,1,1,1,1
0,0,0,0,0,2,0,0,0,0,0
0,0,2,2,2,2,0,5,5,0,0
0,1,0,0,0,0,1,7,6,1,0
1,1,0,0,0,0,0,0,0,0,0
1,1,0,0,0,0,0,0,0,0,0
1,1,0,0,0,1,0,0,0,0,0
0,5,5,5,0,0,0,0,0,0,0
0,5,11,5,0,0,0,0,0,0,0
0,5,5,5,0,0,0,0,0,0,0
1,1,1,1,1,0,0,0,0,0,0
endlayer

layer
0,0,0,0,0,1,1,0,0,1,1
0,0,0,0,0,2,1,0,0,1,0
0,0,0,0,0,2,1,5,5,1,0
0,1,1,1,1,1,1,7,6,1,0
0,0,0,0,1,0,0,0,0,0,0
0,0,0,0,1,0,0,0,0,0,0
1,1,0,0,1,1,0,0,0,0,0
1,0,0,0,1,0,0,0,0,0,0
1,0,0,0,1,0,0,0,0,0,0
1,0,0,0,1,0,0,0,0,0,0
1,0,0,0,1,0,0,0,0,0,0
endlayer

layer
0,0,0,0,0,1,1,1,1,1,1
0,0,0,0,0,0,0,0,0,0,0
0,0,0,0,0,0,0,5,5,0,0
0,1,0,0,0,0,1,7,6,1,0
0,1,0,0,0,0,0,0,0,0,0
0,1,0,0,0,0,0,0,0,0,0
1,1,1,1,1,1,0,0,0,0,0
0,0,0,0,0,0,0,0,0,0,0
0,0,0,0,0,0,0,0,0,0,0
0,0,0,0,0,0,0,0,0,0,0
1,1,1,1,1,1,0,0,0,0,0
endlayer

layer
0,0,0,0,0,1,1,0,0,1,1
0,0,0,0,0,0,1,0,0,1,0
0,0,0,0,0,0,1,5,5,1,0
1,1,1,1,1,1,1,7,6,1,0
1,0,0,0,0,0,0,0,0,0,0
1,0,0,0,0,0,0,0,0,0,0
1,0,0,0,0,1,0,0,0,0,0
1,0,0,0,0,0,0,0,0,0,0
1,0,0,0,0,0,0,0,0,0,0
1,0,0,0,0,0,0,0,0,0,0
1,0,0,0,0,0,0,0,0,0,0
endlayer

layer
0,0,0,0,0,1,0,0,0,0,1
0,0,0,0,0,1,1,1,1,1,1
0,0,0,0,0,0,0,0,0,0,0
0,0,0,0,0,0,1,7,6,1,0
0,0,0,0,0,0,0,0,0,0,0
0,0,0,0,0,0,0,0,0,0,0
1,1,1,1,1,1,0,0,0,0,0
0,0,0,0,0,0,0,0,0,0,0
0,0,0,0,0,0,0,0,0,0,0
0,0,0,0,0,0,0,0,0,0,0
0,0,0,0,0,0,0,0,0,0,0
endlayer

layer
0,0,0,0,0,0,0,0,0,0,0
0,0,0,0,0,0,1,0,0,1,0
0,0,0,0,0,0,1,0,0,1,0
0,0,0,0,0,0,1,7,6,1,0
0,0,0,0,0,0,0,0,0,0,0
0,0,0,0,0,0,0,0,0,0,0
0,0,0,0,0,0,0,0,0,0,0
0,0,0,0,0,0,0,0,0,0,0
0,0,0,0,0,0,0,0,0,0,0
0,0,0,0,0,0,0,0,0,0,0
0,0,0,0,0,0,0,0,0,0,0
endlayer

