# Gilly's underground lab, vertical shaft 2

# template generated by Ruins mod version 14.6 Ingame Parser
# Structure created by Gilly

weight=1
embed_into_distance=23
acceptable_target_blocks=
unacceptable_target_blocks=flowing_water,water,flowing_lava,lava,ice,bedrock,netherrack,soul_sand,Natura:Cloud
dimensions=33,13,15
allowable_overhang=0
max_leveling=3
leveling_buffer=-1
preserve_water=0
preserve_lava=0

rule1=0,100,preserveBlock
rule2=0,100,stained_hardened_clay-9
rule3=0,100,stonebrick-0
rule4=0,100,stone_slab-5
rule5=0,100,water-0
rule6=0,100,ladder-5
rule7=0,100,ladder-4
rule8=0,100,iron_bars-0
rule9=0,100,glowstone-0
rule10=0,100,stone_brick_stairs-0
rule11=0,100,stone_brick_stairs-3
rule12=0,100,stone_brick_stairs-1
rule13=0,100,stained_hardened_clay-3
rule14=0,100,double_stone_slab-0
rule15=0,100,stained_glass_pane-3
rule16=0,100,stone_slab-13
rule17=0,100,stone_brick_stairs-5
rule18=0,100,stone_brick_stairs-6
rule19=0,100,stone_brick_stairs-4

layer
1,2,2,2,2,2,2,2,2,2,2,2,2,2,1
1,2,1,1,1,1,1,1,1,1,1,1,1,2,1
1,2,1,1,1,1,1,1,1,1,1,3,3,2,1
1,2,1,1,1,1,1,1,1,1,1,3,3,2,2
1,2,1,1,1,1,1,1,1,1,1,3,3,2,2
1,2,1,1,1,1,1,1,1,1,1,3,3,2,1
1,2,1,1,1,1,1,1,1,1,1,1,1,2,1
1,2,1,1,1,1,1,1,1,1,1,1,1,2,1
1,2,1,1,1,1,1,1,1,1,1,1,1,2,1
1,2,1,1,1,1,1,1,1,1,1,1,1,2,1
1,2,1,1,1,1,1,1,1,1,1,1,1,2,1
1,2,1,1,1,1,1,1,1,1,1,1,2,2,1
1,2,2,2,2,2,2,2,2,2,2,2,2,2,1
endlayer

layer
1,2,1,1,1,1,1,1,1,1,1,1,1,2,1
1,1,0,0,0,0,0,0,0,0,0,0,0,1,1
1,1,0,0,0,0,0,0,0,0,0,4,4,2,1
1,1,0,0,0,0,0,0,0,0,0,4,5,5,2
1,1,0,0,0,0,0,0,0,0,0,4,5,5,2
1,1,0,0,0,0,0,0,0,0,0,4,4,2,1
1,1,0,0,0,0,0,0,0,0,0,0,0,1,1
1,1,0,0,0,0,0,0,0,0,0,0,0,1,1
1,1,0,0,0,0,0,0,0,0,0,0,0,2,1
1,1,0,0,0,0,0,0,0,0,0,0,0,1,1
1,1,0,0,0,0,0,0,0,0,0,0,0,1,1
1,1,0,0,0,0,0,0,0,0,0,0,2,2,1
1,2,1,1,1,1,1,2,1,1,1,2,2,2,1
endlayer

layer
1,2,1,1,1,1,1,1,1,1,1,1,1,2,1
1,1,0,0,0,0,0,0,0,0,0,0,0,1,1
1,1,0,0,0,0,0,0,0,0,0,0,0,2,1
1,1,0,0,0,0,0,0,0,0,0,0,0,6,2
1,1,0,0,0,0,0,0,0,0,0,0,0,7,2
1,1,0,0,0,0,0,0,0,0,0,0,0,2,1
1,1,0,0,0,0,0,0,0,0,0,0,0,1,1
1,1,0,0,0,0,0,0,0,0,0,0,0,1,1
1,1,0,0,0,0,0,0,0,0,0,0,0,2,1
1,1,0,0,0,0,0,0,0,0,0,0,0,1,1
1,1,0,0,0,0,0,0,0,0,0,0,0,1,1
1,1,0,0,0,0,0,0,0,0,0,2,2,2,1
1,2,1,1,1,1,1,2,1,1,1,2,2,2,1
endlayer

layer
1,2,1,1,1,1,1,1,1,1,1,1,1,2,1
1,1,0,0,0,0,0,0,0,0,0,0,0,1,1
1,1,0,0,0,0,0,0,0,0,0,0,0,2,1
1,1,0,0,0,0,0,0,0,0,0,0,0,6,2
1,1,0,0,0,0,0,0,0,0,0,0,0,7,2
1,1,0,0,0,0,0,0,0,0,0,0,0,2,1
1,1,0,0,0,0,0,0,0,0,0,0,0,1,1
1,1,0,0,0,0,0,0,0,0,0,0,0,1,1
1,1,0,0,0,0,0,0,0,0,0,0,0,2,1
1,1,0,0,0,0,0,0,0,0,0,0,0,1,1
1,1,0,0,0,0,0,0,0,0,0,0,0,2,1
1,1,0,0,0,0,0,0,0,0,0,2,2,2,1
1,2,1,1,1,1,1,2,1,1,2,2,2,2,1
endlayer

layer
1,2,1,1,1,1,1,1,1,1,1,1,1,2,1
1,1,0,0,0,0,0,0,0,0,0,0,0,1,1
1,1,0,0,0,0,0,0,0,0,0,0,8,2,1
1,1,0,0,0,0,0,0,0,0,0,0,8,6,2
1,1,0,0,0,0,0,0,0,0,0,0,8,7,2
1,1,0,0,0,0,0,0,0,0,0,0,8,2,1
1,1,0,0,0,0,0,0,0,0,0,0,0,1,1
1,1,0,0,0,0,0,0,0,0,0,0,0,1,1
1,1,0,0,0,0,0,0,0,0,0,0,0,2,1
1,1,0,0,0,0,0,0,0,0,0,0,0,1,1
1,1,0,0,0,0,0,0,0,0,0,0,2,2,1
1,1,0,0,0,0,0,0,0,0,2,2,2,2,1
1,2,1,1,1,1,1,2,1,2,2,2,2,2,1
endlayer

layer
1,2,1,1,1,1,1,1,1,1,1,1,1,2,1
1,1,0,0,0,0,0,0,0,0,0,0,0,1,1
1,1,0,0,0,0,0,0,0,0,0,0,0,2,1
1,1,0,0,0,0,0,0,0,0,0,0,8,6,2
1,1,0,0,0,0,0,0,0,0,0,0,8,7,2
1,1,0,0,0,0,0,0,0,0,0,0,0,2,1
1,1,0,0,0,0,0,0,0,0,0,0,0,1,1
1,1,0,0,0,0,0,0,0,0,0,0,0,1,1
1,1,0,0,0,0,0,0,0,0,0,0,0,2,1
1,1,0,0,0,0,0,0,0,0,0,0,0,2,1
1,1,0,0,0,0,0,0,0,0,0,2,2,2,1
1,1,0,0,0,0,0,0,0,2,2,2,2,2,1
1,2,1,1,1,1,1,2,2,2,2,2,2,2,1
endlayer

layer
1,2,2,2,2,2,2,2,2,2,2,2,2,2,1
1,2,0,0,0,0,0,0,0,0,0,0,0,2,1
1,2,0,0,0,0,0,0,0,0,0,0,0,2,1
1,2,0,0,0,0,0,0,0,0,0,0,8,6,2
1,2,0,0,0,0,0,0,0,0,0,0,8,7,2
1,2,0,0,0,0,0,0,0,0,0,0,0,2,1
1,2,0,0,0,0,0,0,0,0,0,0,0,2,1
1,2,0,0,0,0,0,0,0,0,0,0,0,2,1
1,2,0,0,0,0,0,0,0,0,0,0,0,2,1
1,2,0,0,0,0,0,0,0,0,0,2,2,2,1
1,2,0,0,0,0,0,0,0,2,2,9,2,2,1
1,2,0,0,0,0,0,0,2,2,2,2,2,2,1
1,2,2,2,2,2,2,2,2,2,2,2,2,2,1
endlayer

layer
1,2,2,2,2,2,2,2,2,2,2,2,2,2,1
1,2,0,0,0,0,0,0,0,0,0,0,0,2,1
1,2,0,0,0,0,0,0,0,0,0,0,0,2,1
1,2,0,0,0,0,0,0,0,0,0,0,8,6,2
1,2,0,0,0,0,0,0,0,0,0,0,8,7,2
1,2,0,0,0,0,0,0,0,0,0,0,0,2,1
1,2,0,0,0,0,0,0,0,0,0,0,0,2,1
1,2,0,0,0,0,0,0,0,0,0,0,0,2,1
1,2,0,0,0,0,0,0,0,0,0,2,2,2,1
1,2,0,0,0,0,0,0,0,2,2,2,2,2,1
1,2,0,0,0,0,0,2,2,2,2,8,2,2,1
1,2,0,0,0,0,0,2,2,2,2,2,2,2,1
1,2,2,2,2,2,2,2,2,2,2,2,2,2,1
endlayer

layer
0,2,3,3,3,10,10,10,10,10,10,10,3,2,0
0,3,0,0,0,0,0,0,0,0,0,0,0,3,0
0,11,0,0,0,0,0,0,0,0,0,0,0,2,0
0,11,0,0,0,0,0,0,0,0,0,0,8,6,0
0,11,0,0,0,0,0,0,0,0,0,0,8,7,0
0,11,0,0,0,0,0,0,0,0,0,0,0,2,0
0,11,0,0,0,0,0,0,0,0,0,0,0,3,0
0,11,0,0,0,0,0,0,0,0,0,0,0,3,0
0,11,0,0,0,0,0,0,0,0,0,3,3,3,0
0,3,0,0,0,0,0,0,0,3,3,0,0,0,0
0,3,0,0,0,0,0,3,3,0,0,0,0,0,0
0,3,0,0,0,0,0,3,0,0,0,0,0,0,0
0,2,3,12,12,12,3,2,0,0,0,0,0,0,0
endlayer

layer
0,2,3,3,3,0,0,0,0,0,0,0,3,2,0
0,3,0,0,0,0,0,0,0,0,0,0,0,3,0
0,0,0,0,0,0,0,0,0,0,0,0,0,2,0
0,0,0,0,0,0,0,0,0,0,0,0,8,6,0
0,0,0,0,0,0,0,0,0,0,0,0,8,7,0
0,0,0,0,0,0,0,0,0,0,0,0,0,2,0
0,0,0,0,0,0,0,0,0,0,0,0,0,3,0
0,0,0,0,0,0,0,0,0,0,0,0,0,3,0
0,0,0,0,0,0,0,0,0,0,0,3,3,3,0
0,3,0,0,0,0,0,0,0,3,3,0,0,0,0
0,3,0,0,0,0,0,3,3,0,0,0,0,0,0
0,3,0,0,0,0,0,3,0,0,0,0,0,0,0
0,2,3,0,0,0,3,2,0,0,0,0,0,0,0
endlayer

layer
0,2,13,13,13,8,8,8,8,8,8,8,13,2,0
0,13,0,0,0,0,0,0,0,0,0,0,0,13,0
0,8,0,0,0,0,0,0,0,0,0,0,0,2,0
0,8,0,0,0,0,0,0,0,0,0,0,8,6,0
0,8,0,0,0,0,0,0,0,0,0,0,8,7,0
0,8,0,0,0,0,0,0,0,0,0,0,0,2,0
0,8,0,0,0,0,0,0,0,0,0,0,0,13,0
0,8,0,0,0,0,0,0,0,0,0,0,0,13,0
0,8,0,0,0,0,0,0,0,0,0,13,13,13,0
0,13,0,0,0,0,0,0,0,13,13,0,0,0,0
0,13,0,0,0,0,0,13,13,0,0,0,0,0,0
0,13,0,0,0,0,0,13,0,0,0,0,0,0,0
0,2,13,8,8,8,13,2,0,0,0,0,0,0,0
endlayer

layer
0,2,3,3,3,3,3,3,3,3,3,3,3,2,0
0,3,0,0,0,0,0,0,0,0,0,0,0,3,0
0,3,0,0,0,0,0,0,0,0,0,0,0,2,0
0,3,0,0,0,0,0,0,0,0,0,0,8,6,0
0,3,0,0,0,0,0,0,0,0,0,0,8,7,0
0,3,0,0,0,0,0,0,0,0,0,0,0,2,0
0,3,0,0,0,0,0,0,0,0,0,0,0,3,0
0,3,0,0,0,0,0,0,0,0,0,0,0,3,0
0,3,0,0,0,0,0,0,0,0,0,3,3,3,0
0,3,0,0,0,0,0,0,0,3,3,0,0,0,0
0,3,0,0,0,0,0,3,3,0,0,0,0,0,0
0,3,0,0,0,0,0,3,0,0,0,0,0,0,0
0,2,3,3,3,3,3,2,0,0,0,0,0,0,0
endlayer

layer
1,2,3,3,3,3,3,3,3,3,3,3,3,2,1
1,3,0,0,0,0,0,0,0,0,0,0,0,3,1
1,3,0,0,0,0,0,0,0,0,0,0,0,2,1
1,3,0,0,0,0,0,0,0,0,0,0,8,6,1
1,3,0,0,0,0,0,0,0,0,0,0,8,7,1
1,3,0,0,0,0,0,0,0,0,0,0,0,2,1
1,3,0,0,0,0,0,0,0,0,0,0,0,3,1
1,3,0,0,0,0,0,0,0,0,0,0,0,3,1
1,3,0,0,0,0,0,0,0,0,0,3,3,3,1
1,3,0,0,0,0,0,0,0,3,3,0,0,3,1
1,3,0,0,0,0,0,3,3,0,0,0,0,3,1
1,3,0,0,0,0,0,3,0,0,0,0,0,3,1
1,2,3,3,3,3,3,2,0,0,0,0,0,3,1
endlayer

layer
1,2,2,2,2,2,2,2,2,2,2,2,2,2,1
1,2,0,0,0,0,0,0,0,0,0,0,0,2,1
1,2,0,0,0,0,0,0,0,0,0,0,8,2,1
1,2,0,0,0,0,0,0,0,0,0,0,8,6,1
1,2,0,0,0,0,0,0,0,0,0,0,8,7,1
1,2,0,0,0,0,0,0,0,0,0,0,8,2,1
1,2,0,0,0,0,0,0,0,0,0,0,0,2,1
1,2,0,0,0,0,0,0,0,0,0,0,2,2,1
1,2,0,0,0,0,0,0,0,0,2,2,2,2,1
1,2,0,0,0,0,0,0,2,2,2,14,14,3,14
1,2,0,0,0,0,0,2,9,14,14,14,14,3,14
1,2,0,0,0,0,2,2,14,14,14,14,14,3,14
1,2,2,2,2,2,2,2,14,14,14,14,14,3,14
endlayer

layer
1,2,2,2,2,2,2,2,2,2,2,2,2,2,2
1,2,0,0,0,0,0,0,0,0,0,0,0,2,2
1,2,0,0,0,0,0,0,0,0,0,0,0,2,2
1,2,0,0,0,0,0,0,0,0,0,0,8,6,2
1,2,0,0,0,0,0,0,0,0,0,0,8,7,2
1,2,0,0,0,0,0,0,0,0,0,0,0,2,2
1,2,0,0,0,0,0,0,0,0,0,0,0,2,2
1,2,0,0,0,0,0,0,0,0,0,3,3,2,2
1,2,0,0,0,0,0,0,0,3,3,15,15,2,2
1,2,0,0,0,0,0,3,3,15,15,15,3,2,2
1,2,0,0,0,0,3,15,15,15,3,3,1,1,1
1,2,0,0,0,0,3,15,3,3,1,1,1,1,1
1,2,2,2,2,2,2,2,2,2,1,1,1,1,1
endlayer

layer
1,2,2,2,2,2,2,2,2,2,2,2,2,2,2
1,2,0,0,0,0,0,0,0,0,0,0,0,2,2
1,2,0,0,0,0,0,0,0,0,0,0,0,2,2
1,2,0,0,0,0,0,0,0,0,0,0,8,6,2
1,2,0,0,0,0,0,0,0,0,0,0,8,7,2
1,2,0,0,0,0,0,0,0,0,0,0,0,2,2
1,2,0,0,0,0,0,0,0,0,0,0,0,2,2
1,2,0,0,0,0,0,0,0,0,0,16,16,2,2
1,2,0,0,0,0,0,0,0,16,16,15,15,2,2
1,2,0,0,0,0,0,16,16,15,15,15,3,2,2
1,2,0,0,0,0,16,15,15,15,3,3,1,1,1
1,2,0,0,0,0,16,15,3,3,1,1,1,1,1
1,2,2,2,2,2,2,2,2,2,1,1,1,1,1
endlayer

layer
1,2,2,2,2,2,2,2,2,2,2,2,2,2,2
1,2,0,0,0,0,0,0,0,0,0,0,0,2,2
1,2,0,0,0,0,0,0,0,0,0,0,0,2,2
1,2,0,0,0,0,0,0,0,0,0,0,8,6,2
1,2,0,0,0,0,0,0,0,0,0,0,8,7,2
1,2,0,0,0,0,0,0,0,0,0,0,0,2,2
1,2,0,0,0,0,0,0,0,0,0,0,0,2,2
1,2,0,0,0,0,0,0,0,0,0,16,16,2,2
1,2,0,0,0,0,0,0,0,16,16,15,15,2,2
1,2,0,0,0,0,0,16,16,15,15,15,3,2,1
1,2,0,0,0,0,16,15,15,15,3,3,1,1,1
1,2,0,0,0,0,16,15,3,3,1,1,1,1,1
1,2,2,2,2,2,2,2,2,2,1,1,1,1,1
endlayer

layer
1,2,2,2,2,2,2,2,2,2,2,2,2,2,2
1,2,0,0,0,0,0,0,0,0,0,0,0,2,2
1,2,0,0,0,0,0,0,0,0,0,0,0,2,2
1,2,0,0,0,0,0,0,0,0,0,0,8,6,2
1,2,0,0,0,0,0,0,0,0,0,0,8,7,2
1,2,0,0,0,0,0,0,0,0,0,0,0,2,2
1,2,0,0,0,0,0,0,0,0,0,0,0,2,2
1,2,0,0,0,0,0,0,0,0,0,16,16,2,2
1,2,0,0,0,0,0,0,0,16,16,15,15,2,1
1,2,0,0,0,0,0,16,16,15,15,15,3,2,1
1,2,0,0,0,0,16,15,15,15,3,3,1,1,1
1,2,0,0,0,0,16,15,3,3,1,1,1,1,1
1,2,2,2,2,2,2,2,2,2,1,1,1,1,1
endlayer

layer
1,2,2,2,2,2,2,2,2,2,2,2,2,2,1
1,2,0,0,0,0,0,0,0,0,0,0,0,2,2
1,2,0,0,0,0,0,0,0,0,0,0,0,2,2
1,2,0,0,0,0,0,0,0,0,0,0,8,6,2
1,2,0,0,0,0,0,0,0,0,0,0,8,7,2
1,2,0,0,0,0,0,0,0,0,0,0,0,2,2
1,2,0,0,0,0,0,0,0,0,0,0,0,2,2
1,2,0,0,0,0,0,0,0,0,0,16,16,2,1
1,2,0,0,0,0,0,0,0,16,16,15,15,2,1
1,2,0,0,0,0,0,16,16,15,15,15,3,2,1
1,2,0,0,0,0,16,15,15,15,3,3,1,1,1
1,2,0,0,0,0,16,15,3,3,1,1,1,1,1
1,2,2,2,2,2,2,2,2,2,1,1,1,1,1
endlayer

layer
1,2,2,2,2,2,2,2,2,2,2,2,2,2,1
1,2,0,0,0,17,0,17,0,17,0,17,0,2,1
1,2,18,0,0,0,0,0,0,0,0,0,0,2,2
1,2,0,0,0,0,0,0,0,0,0,0,8,6,2
1,2,18,0,0,0,0,0,0,0,0,0,8,7,2
1,2,0,0,0,0,0,0,0,0,0,0,0,2,2
1,2,18,0,0,0,0,0,0,0,0,0,0,2,1
1,2,0,0,0,0,0,0,0,0,0,16,16,2,1
1,2,18,0,0,0,0,0,0,16,16,15,15,2,1
1,2,0,0,0,0,0,16,16,15,15,15,3,2,1
1,2,18,0,0,0,16,15,15,15,3,3,1,1,1
1,2,0,0,19,0,16,15,3,3,1,1,1,1,1
1,2,2,2,2,2,2,2,2,2,1,1,1,1,1
endlayer

layer
1,2,2,2,2,2,2,2,2,2,2,2,2,2,1
1,2,0,0,0,3,0,3,0,3,0,3,0,2,1
1,2,3,0,0,0,0,0,0,0,0,0,0,2,1
1,2,0,0,0,0,0,0,0,0,0,0,8,6,2
1,2,3,0,0,0,0,0,0,0,0,0,8,7,2
1,2,0,0,0,0,0,0,0,0,0,0,0,2,1
1,2,3,0,0,0,0,0,0,0,0,0,0,2,1
1,2,0,0,0,0,0,0,0,0,0,3,3,2,1
1,2,3,0,0,0,0,0,0,3,3,2,2,2,1
1,2,0,0,0,0,0,3,3,2,2,9,2,2,1
1,2,3,0,0,0,3,2,2,9,2,2,2,2,1
1,2,0,0,3,0,3,2,2,2,9,2,2,2,1
1,2,2,2,2,2,2,2,2,2,2,2,2,1,1
endlayer

layer
1,2,2,2,2,2,2,2,2,2,2,2,2,2,1
1,2,0,0,0,3,0,3,0,3,0,3,0,2,1
1,2,3,0,0,0,0,0,0,0,0,0,0,2,1
1,2,0,0,0,0,0,0,0,0,0,0,8,6,1
1,2,3,0,0,0,0,0,0,0,0,0,8,7,1
1,2,0,0,0,0,0,0,0,0,0,0,0,2,1
1,2,3,0,0,0,0,0,0,0,0,0,0,2,1
1,2,0,0,0,0,0,0,0,0,0,0,0,2,1
1,2,3,0,0,0,0,0,0,0,0,0,2,2,1
1,2,0,0,0,0,0,0,0,0,2,2,15,2,1
1,2,3,0,0,0,0,0,2,2,15,15,15,2,1
1,2,0,0,3,0,0,2,15,15,15,2,2,2,1
1,2,2,2,2,2,2,2,2,2,2,2,2,1,1
endlayer

layer
1,2,2,2,2,2,2,2,2,2,2,2,2,2,1
1,2,0,0,0,3,0,3,0,3,0,3,0,2,1
1,2,3,0,0,0,0,0,0,0,0,0,0,2,1
1,2,0,0,0,0,0,0,0,0,0,0,8,6,1
1,2,3,0,0,0,0,0,0,0,0,0,8,7,1
1,2,0,0,0,0,0,0,0,0,0,0,0,2,1
1,2,3,0,0,0,0,0,0,0,0,0,0,2,1
1,2,0,0,0,0,0,0,0,0,0,0,0,2,1
1,2,3,0,0,0,0,0,0,0,0,0,16,2,1
1,2,0,0,0,0,0,0,0,0,16,16,15,2,1
1,2,3,0,0,0,0,0,16,16,15,15,15,2,1
1,2,0,0,3,0,0,16,15,15,15,2,2,2,1
1,2,2,2,2,2,2,2,2,2,2,2,2,1,1
endlayer

layer
1,2,2,2,0,2,0,2,0,2,0,2,0,2,1
1,0,0,0,0,3,0,3,0,3,0,3,0,2,1
1,2,3,0,0,0,0,0,0,0,0,0,0,2,1
1,0,0,0,0,0,0,0,0,0,0,0,8,6,1
1,2,3,0,0,0,0,0,0,0,0,0,8,7,1
1,0,0,0,0,0,0,0,0,0,0,0,0,2,1
1,2,3,0,0,0,0,0,0,0,0,0,0,2,1
1,0,0,0,0,0,0,0,0,0,0,0,0,2,1
1,2,3,0,0,0,0,0,0,0,0,0,16,2,1
1,0,0,0,0,0,0,0,0,0,16,16,15,2,1
1,2,3,0,0,0,0,0,16,16,15,15,15,2,1
1,0,0,0,3,0,0,16,15,15,15,2,2,2,1
1,2,2,0,2,0,2,2,2,2,2,2,2,1,1
endlayer

layer
1,2,2,2,2,3,2,3,2,3,2,3,2,2,1
1,2,0,0,0,3,0,3,0,3,0,3,0,2,1
1,3,3,0,0,0,0,0,0,0,0,0,0,2,1
1,2,0,0,0,0,0,0,0,0,0,0,8,6,1
1,3,3,0,0,0,0,0,0,0,0,0,8,7,1
1,2,0,0,0,0,0,0,0,0,0,0,0,2,1
1,3,3,0,0,0,0,0,0,0,0,0,0,2,1
1,2,0,0,0,0,0,0,0,0,0,0,19,2,1
1,3,3,0,0,0,0,0,0,0,19,3,9,2,1
1,2,0,0,0,0,0,0,19,3,9,3,2,2,1
1,3,3,0,0,0,0,3,9,3,2,2,2,2,1
1,2,0,0,3,0,3,3,2,2,9,2,2,2,1
1,2,2,2,3,2,2,2,2,2,2,2,2,1,1
endlayer

layer
1,8,8,8,8,3,8,3,8,3,8,3,8,8,1
1,8,0,0,0,3,0,3,0,3,0,3,0,8,1
0,3,3,0,0,0,0,0,0,0,0,0,0,2,0
0,8,0,0,0,0,0,0,0,0,0,0,8,6,0
0,3,3,0,0,0,0,0,0,0,0,0,8,7,0
0,8,0,0,0,0,0,0,0,0,0,0,0,2,0
0,3,3,0,0,0,0,0,0,0,0,0,0,8,0
0,8,0,0,0,0,0,0,0,0,0,0,19,2,0
0,3,3,0,0,0,0,0,0,0,19,2,15,2,0
0,8,0,0,0,0,0,0,19,2,15,2,3,0,1
0,3,3,0,0,0,0,2,15,2,15,15,3,1,1
1,8,0,0,3,0,16,15,15,2,15,15,3,1,1
1,8,8,8,3,8,2,2,3,2,3,3,1,1,1
endlayer

layer
0,0,0,0,0,0,0,0,0,0,0,0,0,0,0
0,0,0,0,0,0,0,0,0,0,0,0,0,0,0
0,0,0,0,0,0,0,0,0,0,0,0,8,2,0
0,0,0,0,0,0,0,0,0,0,0,0,8,6,0
0,0,0,0,0,0,0,0,0,0,0,0,8,7,0
0,0,0,0,0,0,0,0,0,0,0,0,8,2,0
0,0,0,0,0,0,0,0,0,0,0,0,0,0,0
0,0,0,0,0,0,0,0,0,0,0,0,16,2,0
0,0,0,0,0,0,0,0,0,0,16,2,15,2,0
0,0,0,0,0,0,0,0,16,2,15,2,16,0,0
0,0,0,0,0,0,0,2,15,2,15,15,16,0,0
0,0,0,0,0,0,16,15,15,2,15,15,16,0,1
0,0,0,0,0,0,2,2,16,2,16,16,0,1,1
endlayer

layer
0,0,0,0,0,0,0,0,0,0,0,0,0,0,0
0,0,0,0,0,0,0,0,0,0,0,0,0,0,0
0,0,0,0,0,0,0,0,0,0,0,0,0,0,0
0,0,0,0,0,0,0,0,0,0,0,0,0,0,0
0,0,0,0,0,0,0,0,0,0,0,0,0,0,0
0,0,0,0,0,0,0,0,0,0,0,0,0,0,0
0,0,0,0,0,0,0,0,0,0,0,0,0,0,0
0,0,0,0,0,0,0,0,0,0,0,0,16,2,0
0,0,0,0,0,0,0,0,0,0,16,2,15,2,0
0,0,0,0,0,0,0,0,16,2,15,2,16,0,0
0,0,0,0,0,0,0,2,15,2,15,15,16,0,0
0,0,0,0,0,0,16,15,15,2,15,15,16,0,0
0,0,0,0,0,0,16,2,16,2,16,16,0,0,1
endlayer

layer
0,0,0,0,0,0,0,0,0,0,0,0,0,0,0
0,0,0,0,0,0,0,0,0,0,0,0,0,0,0
0,0,0,0,0,0,0,0,0,0,0,0,0,0,0
0,0,0,0,0,0,0,0,0,0,0,0,0,0,0
0,0,0,0,0,0,0,0,0,0,0,0,0,0,0
0,0,0,0,0,0,0,0,0,0,0,0,0,0,0
0,0,0,0,0,0,0,0,0,0,0,0,0,0,0
0,0,0,0,0,0,0,0,0,0,0,0,16,2,0
0,0,0,0,0,0,0,0,0,0,16,2,15,2,0
0,0,0,0,0,0,0,0,16,2,15,2,16,0,0
0,0,0,0,0,0,0,2,15,2,15,15,16,0,0
0,0,0,0,0,0,16,15,15,2,15,15,16,0,0
0,0,0,0,0,0,16,2,16,2,16,16,0,0,0
endlayer

layer
0,0,0,0,0,0,0,0,0,0,0,0,0,0,0
0,0,0,0,0,0,0,0,0,0,0,0,0,0,0
0,0,0,0,0,0,0,0,0,0,0,0,0,0,0
0,0,0,0,0,0,0,0,0,0,0,0,0,0,0
0,0,0,0,0,0,0,0,0,0,0,0,0,0,0
0,0,0,0,0,0,0,0,0,0,0,0,0,0,0
0,0,0,0,0,0,0,0,0,0,0,0,0,0,0
0,0,0,0,0,0,0,0,0,0,0,0,2,2,0
0,0,0,0,0,0,0,0,0,0,16,2,9,2,0
0,0,0,0,0,0,0,0,16,2,15,2,2,0,0
0,0,0,0,0,0,0,2,15,2,15,15,2,0,0
0,0,0,0,0,0,16,15,15,2,15,15,2,0,0
0,0,0,0,0,0,16,2,16,2,16,16,0,0,0
endlayer

layer
0,0,0,0,0,0,0,0,0,0,0,0,0,0,0
0,0,0,0,0,0,0,0,0,0,0,0,0,0,0
0,0,0,0,0,0,0,0,0,0,0,0,0,0,0
0,0,0,0,0,0,0,0,0,0,0,0,0,0,0
0,0,0,0,0,0,0,0,0,0,0,0,0,0,0
0,0,0,0,0,0,0,0,0,0,0,0,0,0,0
0,0,0,0,0,0,0,0,0,0,0,0,0,0,0
0,0,0,0,0,0,0,0,0,0,0,0,0,0,0
0,0,0,0,0,0,0,0,0,0,2,2,2,0,0
0,0,0,0,0,0,0,0,16,2,9,2,2,0,0
0,0,0,0,0,0,0,2,15,2,2,2,0,0,0
0,0,0,0,0,0,16,15,15,2,2,2,0,0,0
0,0,0,0,0,0,16,2,16,2,0,0,0,0,0
endlayer

layer
0,0,0,0,0,0,0,0,0,0,0,0,0,0,0
0,0,0,0,0,0,0,0,0,0,0,0,0,0,0
0,0,0,0,0,0,0,0,0,0,0,0,0,0,0
0,0,0,0,0,0,0,0,0,0,0,0,0,0,0
0,0,0,0,0,0,0,0,0,0,0,0,0,0,0
0,0,0,0,0,0,0,0,0,0,0,0,0,0,0
0,0,0,0,0,0,0,0,0,0,0,0,0,0,0
0,0,0,0,0,0,0,0,0,0,0,0,0,0,0
0,0,0,0,0,0,0,0,0,0,0,0,0,0,0
0,0,0,0,0,0,0,0,2,2,2,0,0,0,0
0,0,0,0,0,0,0,2,9,2,2,0,0,0,0
0,0,0,0,0,0,2,2,2,2,0,0,0,0,0
0,0,0,0,0,0,2,2,2,0,0,0,0,0,0
endlayer

layer
0,0,0,0,0,0,0,0,0,0,0,0,0,0,0
0,0,0,0,0,0,0,0,0,0,0,0,0,0,0
0,0,0,0,0,0,0,0,0,0,0,0,0,0,0
0,0,0,0,0,0,0,0,0,0,0,0,0,0,0
0,0,0,0,0,0,0,0,0,0,0,0,0,0,0
0,0,0,0,0,0,0,0,0,0,0,0,0,0,0
0,0,0,0,0,0,0,0,0,0,0,0,0,0,0
0,0,0,0,0,0,0,0,0,0,0,0,0,0,0
0,0,0,0,0,0,0,0,0,0,0,0,0,0,0
0,0,0,0,0,0,0,0,0,0,0,0,0,0,0
0,0,0,0,0,0,0,2,2,0,0,0,0,0,0
0,0,0,0,0,0,0,2,2,0,0,0,0,0,0
0,0,0,0,0,0,0,0,0,0,0,0,0,0,0
endlayer

