# Gilly's Skyport rooms
# template generated by Ruins mod version 14.6 Ingame Parser
# Structure created by Gilly

weight=1
embed_into_distance=36
acceptable_target_blocks=
unacceptable_target_blocks=flowing_water,water,flowing_lava,lava,ice,bedrock,netherrack,soul_sand,Natura:Cloud
dimensions=25,19,11
allowable_overhang=0
max_leveling=4
leveling_buffer=-1
preserve_water=0
preserve_lava=0

rule1=0,100,preserveBlock
rule2=0,100,minecraft:glowstone-0
rule3=0,100,minecraft:stained_hardened_clay-9
rule4=0,100,minecraft:ladder-5
rule5=0,100,minecraft:ladder-4
rule6=0,100,minecraft:iron_bars-0
rule7=0,100,minecraft:stonebrick-0
rule8=0,100,minecraft:stained_hardened_clay-3
rule9=0,100,minecraft:double_stone_slab-8
rule10=0,100,minecraft:cauldron-0

layer
1,1,1,1,1,1,1,1,1,1,1
1,1,1,1,1,1,1,1,1,1,1
1,1,1,1,1,1,1,1,1,1,1
1,1,1,2,1,1,1,2,1,1,1
1,1,1,1,1,1,1,1,1,1,1
1,1,1,1,1,1,1,1,1,1,3
1,1,1,1,1,1,1,1,1,1,3
1,1,1,2,1,1,1,2,1,1,3
1,1,1,1,1,1,1,1,1,1,3
1,1,1,1,1,1,1,1,1,1,3
1,1,1,1,1,1,1,1,1,3,3
1,1,1,2,1,1,1,2,1,3,4
1,1,1,1,1,1,1,1,1,3,5
1,1,1,1,1,1,1,1,1,3,3
1,1,1,1,1,1,1,1,1,1,3
1,1,1,2,1,1,1,2,1,1,1
1,1,1,1,1,1,1,1,1,1,1
1,1,1,1,1,1,1,1,1,1,1
1,1,1,1,1,1,1,1,1,1,1
endlayer

layer
1,1,1,1,1,1,1,1,1,1,1
1,3,3,3,3,3,3,3,3,3,1
1,3,3,3,3,3,3,3,3,3,1
1,3,3,6,3,3,3,6,3,3,1
1,3,3,3,3,3,3,3,3,3,1
1,3,3,3,3,3,3,3,3,3,3
1,3,3,3,3,3,3,3,3,3,3
1,3,3,6,3,3,3,6,3,3,3
1,3,3,3,3,3,3,3,3,3,3
1,3,3,3,3,3,3,3,3,3,3
1,3,3,3,3,3,3,3,3,3,3
1,3,3,6,3,3,3,6,3,3,4
1,3,3,3,3,3,3,3,3,3,5
1,3,3,3,3,3,3,3,3,3,3
1,3,3,3,3,3,3,3,3,3,3
1,3,3,6,3,3,3,6,3,3,1
1,3,3,3,3,3,3,3,3,3,1
1,3,3,3,3,3,3,3,3,3,1
1,1,1,1,1,1,1,1,1,1,1
endlayer

layer
7,7,7,7,7,7,7,7,7,7,7
7,0,0,0,0,0,0,0,0,0,7
7,0,0,0,0,0,0,0,0,0,7
7,0,0,0,0,0,0,0,0,0,7
7,0,0,0,0,0,0,0,0,0,7
7,0,0,0,0,0,0,0,0,0,3
7,0,0,0,0,0,0,0,0,0,0
7,0,0,0,0,0,0,0,0,0,0
7,0,0,0,0,0,0,0,0,0,0
7,0,0,0,0,0,0,0,0,0,3
7,0,0,0,0,0,0,0,0,0,3
7,0,0,0,0,0,0,0,0,0,4
7,0,0,0,0,0,0,0,0,0,5
7,0,0,0,0,0,0,0,0,0,3
7,0,0,0,0,0,0,0,0,0,3
7,0,0,0,0,0,0,0,0,0,7
7,0,0,0,0,0,0,0,0,0,7
7,0,0,0,0,0,0,0,0,0,7
7,7,7,7,7,7,7,7,7,7,7
endlayer

layer
7,7,7,7,7,7,7,7,7,7,7
7,0,0,0,0,0,0,0,0,0,7
7,0,0,0,0,0,0,0,0,0,7
7,0,0,0,0,0,0,0,0,0,7
7,0,0,0,0,0,0,0,0,0,7
7,0,0,0,0,0,0,0,0,0,3
7,0,0,0,0,0,0,0,0,0,0
7,0,0,0,0,0,0,0,0,0,0
7,0,0,0,0,0,0,0,0,0,0
7,0,0,0,0,0,0,0,0,0,3
7,0,0,0,0,0,0,0,0,0,3
7,0,0,0,0,0,0,0,0,0,4
7,0,0,0,0,0,0,0,0,0,5
7,0,0,0,0,0,0,0,0,0,3
7,0,0,0,0,0,0,0,0,0,3
7,0,0,0,0,0,0,0,0,0,7
7,0,0,0,0,0,0,0,0,0,7
7,0,0,0,0,0,0,0,0,0,7
7,7,7,7,7,7,7,7,7,7,7
endlayer

layer
7,7,7,7,7,7,7,7,7,7,7
7,0,0,0,0,0,0,0,0,0,7
7,0,0,0,0,0,0,0,0,0,7
7,0,0,0,0,0,0,0,0,0,7
7,0,0,0,0,0,0,0,0,0,7
7,0,0,0,0,0,0,0,0,0,3
7,0,0,0,0,0,0,0,0,0,0
7,0,0,0,0,0,0,0,0,0,0
7,0,0,0,0,0,0,0,0,0,0
7,0,0,0,0,0,0,0,0,0,3
7,0,0,0,0,0,0,0,0,0,3
7,0,0,0,0,0,0,0,0,0,4
7,0,0,0,0,0,0,0,0,0,5
7,0,0,0,0,0,0,0,0,0,3
7,0,0,0,0,0,0,0,0,0,3
7,0,0,0,0,0,0,0,0,0,7
7,0,0,0,0,0,0,0,0,0,7
7,0,0,0,0,0,0,0,0,0,7
7,7,7,7,7,7,7,7,7,7,7
endlayer

layer
8,8,8,8,8,8,8,8,8,8,8
8,0,0,0,0,0,0,0,0,0,8
8,0,0,0,0,0,0,0,0,0,8
8,0,0,0,0,0,0,0,0,0,8
8,0,0,0,0,0,0,0,0,0,8
8,0,0,0,0,0,0,0,0,0,3
8,0,0,0,0,0,0,0,0,0,0
8,0,0,0,0,0,0,0,0,0,0
8,0,0,0,0,0,0,0,0,0,0
8,0,0,0,0,0,0,0,0,0,3
8,0,0,0,0,0,0,0,0,0,3
8,0,0,0,0,0,0,0,0,0,4
8,0,0,0,0,0,0,0,0,0,5
8,0,0,0,0,0,0,0,0,0,3
8,0,0,0,0,0,0,0,0,0,3
8,0,0,0,0,0,0,0,0,0,8
8,0,0,0,0,0,0,0,0,0,8
8,0,0,0,0,0,0,0,0,0,8
8,8,8,8,8,8,8,8,8,8,8
endlayer

layer
7,7,7,7,7,7,7,7,7,7,7
7,0,0,0,0,0,0,0,0,0,7
7,0,0,0,0,0,0,0,0,0,7
7,0,0,0,0,0,0,0,0,0,7
7,0,0,0,0,0,0,0,0,0,7
7,0,0,0,0,0,0,0,0,0,3
7,0,0,0,0,0,0,0,0,0,3
7,0,0,0,0,0,0,0,0,0,3
7,0,0,0,0,0,0,0,0,0,3
7,0,0,0,0,0,0,0,0,0,3
7,0,0,0,0,0,0,0,0,0,3
7,0,0,0,0,0,0,0,0,0,4
7,0,0,0,0,0,0,0,0,0,5
7,0,0,0,0,0,0,0,0,0,3
7,0,0,0,0,0,0,0,0,0,3
7,0,0,0,0,0,0,0,0,0,7
7,0,0,0,0,0,0,0,0,0,7
7,0,0,0,0,0,0,0,0,0,7
7,7,7,7,7,7,7,7,7,7,7
endlayer

layer
1,1,1,1,1,1,1,1,1,1,1
1,9,9,9,9,9,9,9,9,9,1
1,9,9,9,9,9,9,9,9,9,1
1,9,9,9,9,9,9,9,9,9,1
1,9,9,9,9,9,9,9,9,9,1
1,9,9,9,9,10,9,9,9,9,3
1,9,9,9,9,9,9,9,9,9,3
1,9,9,9,9,9,9,9,9,9,3
1,9,9,9,9,9,9,9,9,9,3
1,9,9,9,9,10,9,9,9,9,3
1,9,9,9,9,9,9,9,9,9,3
1,9,9,9,9,9,9,9,9,9,4
1,9,9,9,9,9,9,9,9,9,5
1,9,9,9,9,10,9,9,9,9,3
1,9,9,9,9,9,9,9,9,9,3
1,9,9,9,9,9,9,9,9,9,1
1,9,9,9,9,9,9,9,9,9,1
1,9,9,9,9,9,9,9,9,9,1
1,1,1,1,1,1,1,1,1,1,1
endlayer

layer
1,1,1,1,1,1,1,1,1,1,1
1,1,1,1,1,1,1,1,1,1,1
1,1,1,1,1,1,1,1,1,1,1
1,1,1,2,1,1,1,2,1,1,1
1,1,1,1,1,1,1,1,1,1,1
1,1,1,1,1,2,1,1,1,1,3
1,1,1,1,1,1,1,1,1,1,3
1,1,1,2,1,1,1,2,1,1,3
1,1,1,1,1,1,1,1,1,1,3
1,1,1,1,1,2,1,1,1,1,3
1,1,1,1,1,1,1,1,1,3,3
1,1,1,2,1,1,1,2,1,3,4
1,1,1,1,1,1,1,1,1,3,5
1,1,1,1,1,2,1,1,1,3,3
1,1,1,1,1,1,1,1,1,1,3
1,1,1,2,1,1,1,2,1,1,1
1,1,1,1,1,1,1,1,1,1,1
1,1,1,1,1,1,1,1,1,1,1
1,1,1,1,1,1,1,1,1,1,1
endlayer

layer
1,1,1,1,1,1,1,1,1,1,1
1,3,3,3,3,3,3,3,3,3,1
1,3,3,3,3,3,3,3,3,3,1
1,3,3,6,3,3,3,6,3,3,1
1,3,3,3,3,3,3,3,3,3,1
1,3,3,3,3,3,3,3,3,3,3
1,3,3,3,3,3,3,3,3,3,3
1,3,3,6,3,3,3,6,3,3,3
1,3,3,3,3,3,3,3,3,3,3
1,3,3,3,3,3,3,3,3,3,3
1,3,3,3,3,3,3,3,3,3,3
1,3,3,6,3,3,3,6,3,3,4
1,3,3,3,3,3,3,3,3,3,5
1,3,3,3,3,3,3,3,3,3,3
1,3,3,3,3,3,3,3,3,3,3
1,3,3,6,3,3,3,6,3,3,1
1,3,3,3,3,3,3,3,3,3,1
1,3,3,3,3,3,3,3,3,3,1
1,1,1,1,1,1,1,1,1,1,1
endlayer

layer
7,7,7,7,7,7,7,7,7,7,7
7,0,0,0,0,0,0,0,0,0,7
7,0,0,0,0,0,0,0,0,0,7
7,0,0,0,0,0,0,0,0,0,7
7,0,0,0,0,0,0,0,0,0,7
7,0,0,0,0,0,0,0,0,0,3
7,0,0,0,0,0,0,0,0,0,0
7,0,0,0,0,0,0,0,0,0,0
7,0,0,0,0,0,0,0,0,0,0
7,0,0,0,0,0,0,0,0,0,3
7,0,0,0,0,0,0,0,0,0,3
7,0,0,0,0,0,0,0,0,0,4
7,0,0,0,0,0,0,0,0,0,5
7,0,0,0,0,0,0,0,0,0,3
7,0,0,0,0,0,0,0,0,0,3
7,0,0,0,0,0,0,0,0,0,7
7,0,0,0,0,0,0,0,0,0,7
7,0,0,0,0,0,0,0,0,0,7
7,7,7,7,7,7,7,7,7,7,7
endlayer

layer
7,7,7,7,7,7,7,7,7,7,7
7,0,0,0,0,0,0,0,0,0,7
7,0,0,0,0,0,0,0,0,0,7
7,0,0,0,0,0,0,0,0,0,7
7,0,0,0,0,0,0,0,0,0,7
7,0,0,0,0,0,0,0,0,0,3
7,0,0,0,0,0,0,0,0,0,0
7,0,0,0,0,0,0,0,0,0,0
7,0,0,0,0,0,0,0,0,0,0
7,0,0,0,0,0,0,0,0,0,3
7,0,0,0,0,0,0,0,0,0,3
7,0,0,0,0,0,0,0,0,0,4
7,0,0,0,0,0,0,0,0,0,5
7,0,0,0,0,0,0,0,0,0,3
7,0,0,0,0,0,0,0,0,0,3
7,0,0,0,0,0,0,0,0,0,7
7,0,0,0,0,0,0,0,0,0,7
7,0,0,0,0,0,0,0,0,0,7
7,7,7,7,7,7,7,7,7,7,7
endlayer

layer
7,7,7,7,7,7,7,7,7,7,7
7,0,0,0,0,0,0,0,0,0,7
7,0,0,0,0,0,0,0,0,0,7
7,0,0,0,0,0,0,0,0,0,7
7,0,0,0,0,0,0,0,0,0,7
7,0,0,0,0,0,0,0,0,0,3
7,0,0,0,0,0,0,0,0,0,0
7,0,0,0,0,0,0,0,0,0,0
7,0,0,0,0,0,0,0,0,0,0
7,0,0,0,0,0,0,0,0,0,3
7,0,0,0,0,0,0,0,0,0,3
7,0,0,0,0,0,0,0,0,0,4
7,0,0,0,0,0,0,0,0,0,5
7,0,0,0,0,0,0,0,0,0,3
7,0,0,0,0,0,0,0,0,0,3
7,0,0,0,0,0,0,0,0,0,7
7,0,0,0,0,0,0,0,0,0,7
7,0,0,0,0,0,0,0,0,0,7
7,7,7,7,7,7,7,7,7,7,7
endlayer

layer
8,8,8,8,8,8,8,8,8,8,8
8,0,0,0,0,0,0,0,0,0,8
8,0,0,0,0,0,0,0,0,0,8
8,0,0,0,0,0,0,0,0,0,8
8,0,0,0,0,0,0,0,0,0,8
8,0,0,0,0,0,0,0,0,0,3
8,0,0,0,0,0,0,0,0,0,0
8,0,0,0,0,0,0,0,0,0,0
8,0,0,0,0,0,0,0,0,0,0
8,0,0,0,0,0,0,0,0,0,3
8,0,0,0,0,0,0,0,0,0,3
8,0,0,0,0,0,0,0,0,0,4
8,0,0,0,0,0,0,0,0,0,5
8,0,0,0,0,0,0,0,0,0,3
8,0,0,0,0,0,0,0,0,0,3
8,0,0,0,0,0,0,0,0,0,8
8,0,0,0,0,0,0,0,0,0,8
8,0,0,0,0,0,0,0,0,0,8
8,8,8,8,8,8,8,8,8,8,8
endlayer

layer
7,7,7,7,7,7,7,7,7,7,7
7,0,0,0,0,0,0,0,0,0,7
7,0,0,0,0,0,0,0,0,0,7
7,0,0,0,0,0,0,0,0,0,7
7,0,0,0,0,0,0,0,0,0,7
7,0,0,0,0,0,0,0,0,0,3
7,0,0,0,0,0,0,0,0,0,3
7,0,0,0,0,0,0,0,0,0,3
7,0,0,0,0,0,0,0,0,0,3
7,0,0,0,0,0,0,0,0,0,3
7,0,0,0,0,0,0,0,0,0,3
7,0,0,0,0,0,0,0,0,0,4
7,0,0,0,0,0,0,0,0,0,5
7,0,0,0,0,0,0,0,0,0,3
7,0,0,0,0,0,0,0,0,0,3
7,0,0,0,0,0,0,0,0,0,7
7,0,0,0,0,0,0,0,0,0,7
7,0,0,0,0,0,0,0,0,0,7
7,7,7,7,7,7,7,7,7,7,7
endlayer

layer
1,1,1,1,1,1,1,1,1,1,1
1,9,9,9,9,9,9,9,9,9,1
1,9,9,9,9,9,9,9,9,9,1
1,9,9,9,9,9,9,9,9,9,1
1,9,9,9,9,9,9,9,9,9,1
1,9,9,9,9,10,9,9,9,9,3
1,9,9,9,9,9,9,9,9,9,3
1,9,9,9,9,9,9,9,9,9,3
1,9,9,9,9,9,9,9,9,9,3
1,9,9,9,9,10,9,9,9,9,3
1,9,9,9,9,9,9,9,9,9,3
1,9,9,9,9,9,9,9,9,9,4
1,9,9,9,9,9,9,9,9,9,5
1,9,9,9,9,10,9,9,9,9,3
1,9,9,9,9,9,9,9,9,9,3
1,9,9,9,9,9,9,9,9,9,1
1,9,9,9,9,9,9,9,9,9,1
1,9,9,9,9,9,9,9,9,9,1
1,1,1,1,1,1,1,1,1,1,1
endlayer

layer
1,1,1,1,1,1,1,1,1,1,1
1,1,1,1,1,1,1,1,1,1,1
1,1,1,1,1,1,1,1,1,1,1
1,1,1,2,1,1,1,2,1,1,1
1,1,1,1,1,1,1,1,1,1,1
1,1,1,1,1,2,1,1,1,1,3
1,1,1,1,1,1,1,1,1,1,3
1,1,1,2,1,1,1,2,1,1,3
1,1,1,1,1,1,1,1,1,1,3
1,1,1,1,1,2,1,1,1,1,3
1,1,1,1,1,1,1,1,1,3,3
1,1,1,2,1,1,1,2,1,3,4
1,1,1,1,1,1,1,1,1,3,5
1,1,1,1,1,2,1,1,1,3,3
1,1,1,1,1,1,1,1,1,1,3
1,1,1,2,1,1,1,2,1,1,1
1,1,1,1,1,1,1,1,1,1,1
1,1,1,1,1,1,1,1,1,1,1
1,1,1,1,1,1,1,1,1,1,1
endlayer

layer
1,1,1,1,1,1,1,1,1,1,1
1,3,3,3,3,3,3,3,3,3,1
1,3,3,3,3,3,3,3,3,3,1
1,3,3,6,3,3,3,6,3,3,1
1,3,3,3,3,3,3,3,3,3,1
1,3,3,3,3,3,3,3,3,3,3
1,3,3,3,3,3,3,3,3,3,3
1,3,3,6,3,3,3,6,3,3,3
1,3,3,3,3,3,3,3,3,3,3
1,3,3,3,3,3,3,3,3,3,3
1,3,3,3,3,3,3,3,3,3,3
1,3,3,6,3,3,3,6,3,3,4
1,3,3,3,3,3,3,3,3,3,5
1,3,3,3,3,3,3,3,3,3,3
1,3,3,3,3,3,3,3,3,3,3
1,3,3,6,3,3,3,6,3,3,1
1,3,3,3,3,3,3,3,3,3,1
1,3,3,3,3,3,3,3,3,3,1
1,1,1,1,1,1,1,1,1,1,1
endlayer

layer
7,7,7,7,7,7,7,7,7,7,7
7,0,0,0,0,0,0,0,0,0,7
7,0,0,0,0,0,0,0,0,0,7
7,0,0,0,0,0,0,0,0,0,7
7,0,0,0,0,0,0,0,0,0,7
7,0,0,0,0,0,0,0,0,0,3
7,0,0,0,0,0,0,0,0,0,0
7,0,0,0,0,0,0,0,0,0,0
7,0,0,0,0,0,0,0,0,0,0
7,0,0,0,0,0,0,0,0,0,3
7,0,0,0,0,0,0,0,0,0,3
7,0,0,0,0,0,0,0,0,0,4
7,0,0,0,0,0,0,0,0,0,5
7,0,0,0,0,0,0,0,0,0,3
7,0,0,0,0,0,0,0,0,0,3
7,0,0,0,0,0,0,0,0,0,7
7,0,0,0,0,0,0,0,0,0,7
7,0,0,0,0,0,0,0,0,0,7
7,7,7,7,7,7,7,7,7,7,7
endlayer

layer
7,7,7,7,7,7,7,7,7,7,7
7,0,0,0,0,0,0,0,0,0,7
7,0,0,0,0,0,0,0,0,0,7
7,0,0,0,0,0,0,0,0,0,7
7,0,0,0,0,0,0,0,0,0,7
7,0,0,0,0,0,0,0,0,0,3
7,0,0,0,0,0,0,0,0,0,0
7,0,0,0,0,0,0,0,0,0,0
7,0,0,0,0,0,0,0,0,0,0
7,0,0,0,0,0,0,0,0,0,3
7,0,0,0,0,0,0,0,0,0,3
7,0,0,0,0,0,0,0,0,0,4
7,0,0,0,0,0,0,0,0,0,5
7,0,0,0,0,0,0,0,0,0,3
7,0,0,0,0,0,0,0,0,0,3
7,0,0,0,0,0,0,0,0,0,7
7,0,0,0,0,0,0,0,0,0,7
7,0,0,0,0,0,0,0,0,0,7
7,7,7,7,7,7,7,7,7,7,7
endlayer

layer
7,7,7,7,7,7,7,7,7,7,7
7,0,0,0,0,0,0,0,0,0,7
7,0,0,0,0,0,0,0,0,0,7
7,0,0,0,0,0,0,0,0,0,7
7,0,0,0,0,0,0,0,0,0,7
7,0,0,0,0,0,0,0,0,0,3
7,0,0,0,0,0,0,0,0,0,0
7,0,0,0,0,0,0,0,0,0,0
7,0,0,0,0,0,0,0,0,0,0
7,0,0,0,0,0,0,0,0,0,3
7,0,0,0,0,0,0,0,0,0,3
7,0,0,0,0,0,0,0,0,0,4
7,0,0,0,0,0,0,0,0,0,5
7,0,0,0,0,0,0,0,0,0,3
7,0,0,0,0,0,0,0,0,0,3
7,0,0,0,0,0,0,0,0,0,7
7,0,0,0,0,0,0,0,0,0,7
7,0,0,0,0,0,0,0,0,0,7
7,7,7,7,7,7,7,7,7,7,7
endlayer

layer
8,8,8,8,8,8,8,8,8,8,8
8,0,0,0,0,0,0,0,0,0,8
8,0,0,0,0,0,0,0,0,0,8
8,0,0,0,0,0,0,0,0,0,8
8,0,0,0,0,0,0,0,0,0,8
8,0,0,0,0,0,0,0,0,0,3
8,0,0,0,0,0,0,0,0,0,0
8,0,0,0,0,0,0,0,0,0,0
8,0,0,0,0,0,0,0,0,0,0
8,0,0,0,0,0,0,0,0,0,3
8,0,0,0,0,0,0,0,0,0,3
8,0,0,0,0,0,0,0,0,0,4
8,0,0,0,0,0,0,0,0,0,5
8,0,0,0,0,0,0,0,0,0,3
8,0,0,0,0,0,0,0,0,0,3
8,0,0,0,0,0,0,0,0,0,8
8,0,0,0,0,0,0,0,0,0,8
8,0,0,0,0,0,0,0,0,0,8
8,8,8,8,8,8,8,8,8,8,8
endlayer

layer
7,7,7,7,7,7,7,7,7,7,7
7,0,0,0,0,0,0,0,0,0,7
7,0,0,0,0,0,0,0,0,0,7
7,0,0,0,0,0,0,0,0,0,7
7,0,0,0,0,0,0,0,0,0,7
7,0,0,0,0,0,0,0,0,0,3
7,0,0,0,0,0,0,0,0,0,3
7,0,0,0,0,0,0,0,0,0,3
7,0,0,0,0,0,0,0,0,0,3
7,0,0,0,0,0,0,0,0,0,3
7,0,0,0,0,0,0,0,0,0,3
7,0,0,0,0,0,0,0,0,0,4
7,0,0,0,0,0,0,0,0,0,5
7,0,0,0,0,0,0,0,0,0,3
7,0,0,0,0,0,0,0,0,0,3
7,0,0,0,0,0,0,0,0,0,7
7,0,0,0,0,0,0,0,0,0,7
7,0,0,0,0,0,0,0,0,0,7
7,7,7,7,7,7,7,7,7,7,7
endlayer

layer
1,1,1,1,1,1,1,1,1,1,1
1,9,9,9,9,9,9,9,9,9,1
1,9,9,9,9,9,9,9,9,9,1
1,9,9,9,9,9,9,9,9,9,1
1,9,9,9,9,9,9,9,9,9,1
1,9,9,9,9,10,9,9,9,9,3
1,9,9,9,9,9,9,9,9,9,3
1,9,9,9,9,9,9,9,9,9,3
1,9,9,9,9,9,9,9,9,9,3
1,9,9,9,9,10,9,9,9,9,3
1,9,9,9,9,9,9,9,9,9,3
1,9,9,9,9,9,9,9,9,9,4
1,9,9,9,9,9,9,9,9,9,5
1,9,9,9,9,10,9,9,9,9,3
1,9,9,9,9,9,9,9,9,9,3
1,9,9,9,9,9,9,9,9,9,1
1,9,9,9,9,9,9,9,9,9,1
1,9,9,9,9,9,9,9,9,9,1
1,1,1,1,1,1,1,1,1,1,1
endlayer

layer
1,1,1,1,1,1,1,1,1,1,1
1,1,1,1,1,1,1,1,1,1,1
1,1,1,1,1,1,1,1,1,1,1
1,1,1,1,1,1,1,1,1,1,1
1,1,1,1,1,1,1,1,1,1,1
1,1,1,1,1,2,1,1,1,1,3
1,1,1,1,1,1,1,1,1,1,3
1,1,1,1,1,1,1,1,1,1,3
1,1,1,1,1,1,1,1,1,1,3
1,1,1,1,1,2,1,1,1,1,3
1,1,1,1,1,1,1,1,1,3,3
1,1,1,1,1,1,1,1,1,3,4
1,1,1,1,1,1,1,1,1,3,5
1,1,1,1,1,2,1,1,1,3,3
1,1,1,1,1,1,1,1,1,1,3
1,1,1,1,1,1,1,1,1,1,1
1,1,1,1,1,1,1,1,1,1,1
1,1,1,1,1,1,1,1,1,1,1
1,1,1,1,1,1,1,1,1,1,1
endlayer

