# Gilly's Adobe houses

# template generated by Ruins mod version 14.6 Ingame Parser
# Structure created by Gilly

weight=1
embed_into_distance=4
acceptable_target_blocks=
unacceptable_target_blocks=flowing_water,water,flowing_lava,lava,ice,bedrock,netherrack,soul_sand,Natura:Cloud
dimensions=11,13,18
allowable_overhang=0
max_leveling=7
leveling_buffer=-1
preserve_water=0
preserve_lava=0

rule1=0,100,preserveBlock
rule2=0,100,double_stone_slab-9
rule3=0,100,sandstone-2
rule4=0,100,wooden_door-5
rule5=0,100,wooden_door-4
rule6=0,100,wooden_door-6
rule7=0,100,wooden_door-7
rule8=0,100,wooden_door-8
rule9=0,100,stone_slab-1
rule10=0,100,sandstone_stairs-0
rule11=0,100,sandstone_stairs-2
rule12=0,100,sandstone_stairs-3
rule13=0,100,hay_block-0
rule14=0,100,fence-0
rule15=0,100,wooden_slab-1
rule16=0,100,sandstone_stairs-1

layer
1,1,1,1,1,1,2,2,2,2,2,2,2,2,1,1,1,1
1,1,1,1,1,1,2,1,1,1,1,1,2,2,1,1,1,1
2,2,2,2,2,2,2,1,1,1,1,1,2,1,1,1,1,1
2,1,1,1,1,1,2,1,1,1,1,1,2,1,1,1,2,2
2,1,1,1,1,1,2,1,1,1,1,1,2,2,2,2,2,2
2,1,1,1,1,1,2,1,1,1,1,2,1,1,1,1,1,2
2,1,1,1,1,1,2,2,2,2,2,2,1,1,1,1,1,2
2,1,1,1,1,2,1,1,1,1,1,2,1,1,1,1,1,2
2,2,2,2,2,2,1,1,1,1,1,2,1,1,1,1,1,2
2,1,1,1,1,2,1,1,1,1,1,2,1,1,1,1,1,2
1,1,1,1,1,2,1,1,1,1,1,2,2,2,2,2,2,2
1,1,1,1,2,2,1,1,1,1,1,2,1,1,1,1,1,1
1,1,1,1,2,2,2,2,2,2,2,2,1,1,1,1,1,1
endlayer

layer
1,1,1,1,1,1,2,2,2,2,2,2,2,2,1,1,1,1
1,1,1,1,1,1,2,1,1,1,1,1,2,2,1,1,1,1
2,2,2,2,2,2,2,1,1,1,1,1,2,1,1,1,1,1
2,1,1,1,1,1,2,1,1,1,1,1,2,1,1,1,2,2
2,1,1,1,1,1,2,1,1,1,1,1,2,2,2,2,2,2
2,1,1,1,1,1,2,1,1,1,1,2,1,1,1,1,1,2
2,1,1,1,1,1,2,2,2,2,2,2,1,1,1,1,1,2
2,1,1,1,1,2,1,1,1,1,1,2,1,1,1,1,1,2
2,2,2,2,2,2,1,1,1,1,1,2,1,1,1,1,1,2
2,1,1,1,1,2,1,1,1,1,1,2,1,1,1,1,1,2
1,1,1,1,1,2,1,1,1,1,1,2,2,2,2,2,2,2
1,1,1,1,2,2,1,1,1,1,1,2,1,1,1,1,1,1
1,1,1,1,2,2,2,2,2,2,2,2,1,1,1,1,1,1
endlayer

layer
1,1,1,1,1,1,2,2,2,2,2,2,2,2,1,1,1,1
1,1,1,1,1,1,2,1,1,1,1,1,2,2,1,1,1,1
2,2,2,2,2,2,2,1,1,1,1,1,2,1,1,1,1,1
2,1,1,1,1,1,2,1,1,1,1,1,2,1,1,1,2,2
2,1,1,1,1,1,2,1,1,1,1,1,2,2,2,2,2,2
2,1,1,1,1,1,2,1,1,1,1,2,1,1,1,1,1,2
2,1,1,1,1,1,2,2,2,2,2,2,1,1,1,1,1,2
2,1,1,1,1,2,1,1,1,1,1,2,1,1,1,1,1,2
2,2,2,2,2,2,1,1,1,1,1,2,1,1,1,1,1,2
2,2,1,1,1,2,1,1,1,1,1,2,1,1,1,1,1,2
1,1,1,1,1,2,1,1,1,1,1,2,2,2,2,2,2,2
1,1,1,1,2,2,1,1,1,1,1,2,1,1,1,1,1,1
1,1,1,1,2,2,2,2,2,2,2,2,1,1,1,1,1,1
endlayer

layer
1,1,1,1,1,1,2,2,2,2,2,2,2,2,1,1,1,1
1,1,1,1,1,1,2,1,1,1,1,1,2,2,1,1,1,1
2,2,2,2,2,2,2,1,1,1,1,1,2,2,1,1,1,1
2,1,1,1,1,1,2,1,1,1,1,1,2,2,2,2,2,2
2,1,1,1,1,1,2,1,1,1,1,1,2,2,2,2,2,2
2,1,1,1,1,1,2,1,1,1,1,2,1,1,1,1,1,2
2,1,1,1,1,1,2,2,2,2,2,2,1,1,1,1,1,2
2,1,1,1,1,2,1,1,1,1,1,2,1,1,1,1,1,2
2,2,2,2,2,2,1,1,1,1,1,2,1,1,1,1,1,2
1,2,2,2,2,2,1,1,1,1,1,2,1,1,1,1,1,2
1,1,1,1,2,2,1,1,1,1,1,2,2,2,2,2,2,2
1,1,1,1,2,2,1,1,1,1,1,2,1,1,1,1,1,1
1,1,1,1,2,2,2,2,2,2,2,2,1,1,1,1,1,1
endlayer

layer
1,1,1,1,1,1,3,2,2,3,2,2,3,1,1,1,1,1
1,1,1,1,1,1,2,2,2,2,2,2,2,2,1,1,1,1
3,2,2,3,2,2,2,2,2,2,2,2,2,2,1,1,1,1
2,2,2,2,2,2,2,2,2,2,2,2,2,2,2,2,2,1
2,2,2,2,2,2,2,2,2,2,2,2,2,2,2,2,2,3
3,2,2,2,2,2,2,2,2,2,2,2,2,2,2,2,2,2
2,2,2,2,2,2,2,2,2,2,2,2,2,2,2,2,2,2
2,2,2,2,2,2,2,2,2,2,2,2,2,2,2,2,2,3
3,2,2,2,2,2,2,2,2,2,2,2,2,2,2,2,2,2
1,1,2,2,2,2,2,2,2,2,2,2,2,2,2,2,2,2
1,1,1,1,2,2,2,2,2,2,2,2,2,2,3,2,2,3
1,1,1,1,2,2,2,2,2,2,2,2,1,1,1,1,1,1
1,1,1,1,1,3,2,2,3,2,2,3,1,1,1,1,1,1
endlayer

layer
1,1,1,1,1,1,2,2,2,2,2,2,2,1,1,1,1,1
1,1,1,1,1,1,2,0,0,0,0,0,3,1,1,1,1,1
2,2,2,2,2,2,2,0,0,0,0,0,4,1,1,1,1,1
2,0,0,0,0,0,2,0,0,0,0,0,3,1,1,1,1,1
2,0,0,0,0,0,2,0,0,0,0,0,2,2,3,5,3,2
2,0,0,0,0,0,2,0,0,0,0,2,0,0,0,0,0,2
2,0,0,0,0,0,2,2,2,2,2,2,0,0,0,0,0,2
2,0,0,0,0,2,0,0,0,0,0,2,0,0,0,0,0,2
2,2,3,6,3,2,0,0,0,0,0,2,0,0,0,0,0,2
1,1,1,1,1,3,0,0,0,0,0,2,0,0,0,0,0,2
1,1,1,1,1,7,0,0,0,0,0,2,2,2,2,2,2,2
1,1,1,1,1,3,0,0,0,0,0,2,1,1,1,1,1,1
1,1,1,1,1,2,2,2,2,2,2,2,1,1,1,1,1,1
endlayer

layer
1,1,1,1,1,1,3,2,0,2,0,2,3,1,1,1,1,1
1,1,1,1,1,1,2,0,0,0,0,0,3,1,1,1,1,1
3,2,0,2,0,2,2,0,0,0,0,0,8,1,1,1,1,1
2,0,0,0,0,0,2,0,0,0,0,0,3,1,1,1,1,1
0,0,0,0,0,0,2,0,0,0,0,0,2,2,3,8,3,3
2,0,0,0,0,0,2,0,0,0,0,2,0,0,0,0,0,2
0,0,0,0,0,0,2,2,2,2,2,2,0,0,0,0,0,0
2,0,0,0,0,2,0,0,0,0,0,2,0,0,0,0,0,2
3,2,3,8,3,2,0,0,0,0,0,2,0,0,0,0,0,0
1,1,1,1,1,3,0,0,0,0,0,2,0,0,0,0,0,2
1,1,1,1,1,8,0,0,0,0,0,2,2,0,2,0,2,3
1,1,1,1,1,3,0,0,0,0,0,2,1,1,1,1,1,1
1,1,1,1,1,3,2,0,2,0,2,3,1,1,1,1,1,1
endlayer

layer
1,1,1,1,1,1,2,2,2,2,2,2,2,1,1,1,1,1
1,1,1,1,1,1,2,0,0,0,0,0,2,1,1,1,1,1
2,2,2,2,2,2,2,0,0,0,0,0,3,1,1,1,1,1
2,0,0,0,0,0,2,0,0,0,0,0,2,1,1,1,1,1
2,0,0,0,0,0,2,0,0,0,0,0,2,2,2,3,2,2
2,0,0,0,0,0,2,0,0,0,0,2,0,0,0,0,0,2
2,0,0,0,0,0,2,2,2,2,2,2,0,0,0,0,0,2
2,0,0,0,0,2,0,0,0,0,0,2,0,0,0,0,0,2
2,2,2,3,2,2,0,0,0,0,0,2,0,0,0,0,0,2
1,1,1,1,1,2,0,0,0,0,0,2,0,0,0,0,0,2
1,1,1,1,1,3,0,0,0,0,0,2,2,2,2,2,2,2
1,1,1,1,1,2,0,0,0,0,0,2,1,1,1,1,1,1
1,1,1,1,1,2,2,2,2,2,2,2,1,1,1,1,1,1
endlayer

layer
1,1,1,1,1,1,3,2,2,3,2,2,3,1,1,1,1,1
1,1,1,1,1,1,2,0,0,0,0,0,2,1,1,1,1,1
3,2,2,3,2,2,2,0,0,0,0,0,2,1,1,1,1,1
2,0,0,0,0,0,2,0,0,0,0,0,2,1,1,1,1,1
2,0,0,0,0,0,2,0,0,0,0,0,2,2,2,2,2,3
3,0,0,0,0,0,2,0,0,0,0,2,0,0,0,0,0,2
2,0,0,0,0,0,2,2,2,2,2,2,0,0,0,0,0,2
2,0,0,0,0,2,0,0,0,0,0,2,0,0,0,0,0,3
3,2,2,2,2,2,0,0,0,0,0,2,0,0,0,0,0,2
1,1,1,1,1,2,0,0,0,0,0,2,0,0,0,0,0,2
1,1,1,1,1,2,0,0,0,0,0,2,2,2,3,2,2,3
1,1,1,1,1,2,0,0,0,0,0,2,1,1,1,1,1,1
1,1,1,1,1,3,2,2,3,2,2,3,1,1,1,1,1,1
endlayer

layer
1,1,1,1,1,1,9,10,10,10,10,10,9,1,1,1,1,1
1,1,1,1,1,1,12,2,2,2,2,2,11,1,1,1,1,1
9,3,10,10,10,3,12,2,13,13,13,2,11,1,1,1,1,1
3,0,0,0,0,0,3,2,13,14,13,2,11,1,1,1,1,1
12,0,0,0,0,0,2,2,13,13,13,2,3,10,10,10,3,9
12,0,0,0,0,0,2,2,2,2,2,3,0,0,0,0,0,3
12,0,0,0,0,0,2,2,2,2,2,2,0,0,0,0,0,11
3,0,0,0,0,2,15,15,15,15,15,2,0,0,0,0,0,11
9,3,16,16,16,3,15,15,15,15,15,2,0,0,0,0,0,11
1,1,1,1,1,12,15,15,0,15,15,3,0,0,0,0,0,3
1,1,1,1,1,12,15,15,15,15,15,16,3,16,16,16,3,9
1,1,1,1,1,12,15,15,15,15,15,11,1,1,1,1,1,1
1,1,1,1,1,9,16,16,16,16,16,9,1,1,1,1,1,1
endlayer

layer
1,1,1,1,1,1,1,1,1,1,1,1,1,1,1,1,1,1
1,1,1,1,1,1,1,1,1,1,1,1,1,1,1,1,1,1
1,9,1,1,1,9,1,1,1,1,1,1,1,1,1,1,1,1
9,9,9,9,9,9,9,1,1,1,1,1,1,1,1,1,1,1
1,9,9,9,9,9,1,1,1,1,1,1,9,1,1,1,9,1
1,9,9,0,9,9,1,1,1,1,1,9,9,9,9,9,9,9
1,9,9,9,9,9,1,1,1,1,1,1,9,9,9,9,9,1
9,9,9,9,9,9,1,1,1,1,1,1,9,9,0,9,9,1
1,9,1,1,1,9,1,1,1,1,1,1,9,9,9,9,9,1
1,1,1,1,1,1,1,1,1,1,1,9,9,9,9,9,9,9
1,1,1,1,1,1,1,1,1,1,1,1,9,1,1,1,9,1
1,1,1,1,1,1,1,1,1,1,1,1,1,1,1,1,1,1
1,1,1,1,1,1,1,1,1,1,1,1,1,1,1,1,1,1
endlayer

