# Gilly's Fountain-Tower modern tech level

weight=1
embed_into_distance=1
unacceptable_target_blocks=flowing_water,water,flowing_lava,lava,ice,bedrock,netherrack,soul_sand,Natura:Cloud
dimensions=24,13,13
max_leveling=2
leveling_buffer=0
preserve_water=0
preserve_lava=0
preserve_plants=0

rule1=0,100,stonebrick,stonebrick,stonebrick,stonebrick,stonebrick,stonebrick-2,stonebrick-2
rule2=0,100,stonebrick,stonebrick,stonebrick-1,stonebrick-1,stonebrick-1,stonebrick-1,stonebrick-2
rule3=0,100,stone_slab-5
rule4=0,100,stone_brick_stairs
rule5=0,100,stone_brick_stairs-1
rule6=0,100,stone_brick_stairs-2
rule7=0,100,stone_brick_stairs-3
rule8=0,100,flowing_water
rule9=0,100,stone_brick_stairs-7
rule10=0,100,stone_brick_stairs-6
rule11=0,100,stone_slab-13
rule12=0,100,stained_glass_pane-3
rule13=0,100,fence
rule14=0,100,torch-5


layer
4,4,4,1,1,1,1,1,1,1,4,4,6
7,1,7,1,2,2,2,2,2,1,6,1,6
7,4,1,1,2,2,2,2,2,1,1,4,6
1,1,1,1,2,2,2,2,2,1,1,1,1
1,2,2,2,1,1,1,1,1,2,2,2,1
1,2,2,2,1,1,1,1,1,2,2,2,1
1,2,2,2,1,1,1,1,1,2,2,2,1
1,2,2,2,1,1,1,1,1,2,2,2,1
1,2,2,2,1,1,1,1,1,2,2,2,1
1,1,1,1,2,2,2,2,2,1,1,1,1
7,5,1,1,2,2,2,2,2,1,1,5,6
7,1,7,1,2,2,2,2,2,1,6,1,6
7,5,5,1,1,1,1,1,1,1,5,5,5
endlayer


layer
0,0,0,4,1,6,4,7,1,4,0,0,0
0,0,0,7,8,8,8,8,8,6,0,0,0
0,0,3,1,8,8,8,8,8,1,3,0,0
7,4,1,1,1,8,8,8,1,1,1,4,6
1,8,8,1,1,1,1,1,1,1,8,8,1
5,8,8,8,1,12,12,12,1,8,8,8,5
7,8,8,8,1,12,14,12,1,8,8,8,6
4,8,8,8,1,12,12,12,1,8,8,8,4
1,8,8,1,1,1,1,1,1,1,8,8,1
7,5,1,1,1,8,8,8,1,1,1,5,6
0,0,3,1,8,8,8,8,8,1,3,0,0
0,0,0,7,8,8,8,8,8,6,0,0,0
0,0,0,5,1,6,5,7,1,5,0,0,0
endlayer

layer
0,0,0,0,0,0,0,0,0,0,0,0,0
0,0,0,0,0,0,0,0,0,0,0,0,0
0,0,0,3,0,0,0,0,0,3,0,0,0
0,0,3,1,4,0,0,0,4,1,3,0,0
0,0,0,7,1,3,3,3,1,6,0,0,0
0,0,0,0,11,12,12,12,11,0,0,0,0
0,0,0,0,11,12,13,12,11,0,0,0,0
0,0,0,0,11,12,12,12,11,0,0,0,0
0,0,0,7,1,3,3,3,1,6,0,0,0
0,0,3,1,5,0,0,0,5,1,3,0,0
0,0,0,3,0,0,0,0,0,3,0,0,0
0,0,0,0,0,0,0,0,0,0,0,0,0
0,0,0,0,0,0,0,0,0,0,0,0,0
endlayer

layer
0,0,0,0,0,0,0,0,0,0,0,0,0
0,0,0,0,0,0,0,0,0,0,0,0,0
0,0,0,0,0,0,0,0,0,0,0,0,0
0,0,0,0,0,0,0,0,0,0,0,0,0
0,0,0,0,9,3,3,3,4,0,0,0,0
0,0,0,0,11,12,12,12,11,0,0,0,0
0,0,0,0,11,12,14,12,11,0,0,0,0
0,0,0,0,11,12,12,12,11,0,0,0,0
0,0,0,0,5,3,3,3,10,0,0,0,0
0,0,0,0,0,0,0,0,0,0,0,0,0
0,0,0,0,0,0,0,0,0,0,0,0,0
0,0,0,0,0,0,0,0,0,0,0,0,0
0,0,0,0,0,0,0,0,0,0,0,0,0
endlayer

layer
0,0,0,0,0,0,0,0,0,0,0,0,0
0,0,0,0,0,0,0,0,0,0,0,0,0
0,0,0,0,0,0,0,0,0,0,0,0,0
0,0,0,0,0,0,0,0,0,0,0,0,0
0,0,0,0,9,3,3,3,4,0,0,0,0
0,0,0,0,11,12,12,12,11,0,0,0,0
0,0,0,0,11,12,13,12,11,0,0,0,0
0,0,0,0,11,12,12,12,11,0,0,0,0
0,0,0,0,5,3,3,3,10,0,0,0,0
0,0,0,0,0,0,0,0,0,0,0,0,0
0,0,0,0,0,0,0,0,0,0,0,0,0
0,0,0,0,0,0,0,0,0,0,0,0,0
0,0,0,0,0,0,0,0,0,0,0,0,0
endlayer

layer
0,0,0,0,0,0,0,0,0,0,0,0,0
0,0,0,0,0,0,0,0,0,0,0,0,0
0,0,0,0,0,0,0,0,0,0,0,0,0
0,0,0,0,0,0,0,0,0,0,0,0,0
0,0,0,0,9,3,3,3,4,0,0,0,0
0,0,0,0,11,12,12,12,11,0,0,0,0
0,0,0,0,11,12,14,12,11,0,0,0,0
0,0,0,0,11,12,12,12,11,0,0,0,0
0,0,0,0,5,3,3,3,10,0,0,0,0
0,0,0,0,0,0,0,0,0,0,0,0,0
0,0,0,0,0,0,0,0,0,0,0,0,0
0,0,0,0,0,0,0,0,0,0,0,0,0
0,0,0,0,0,0,0,0,0,0,0,0,0
endlayer

layer
0,0,0,0,0,0,0,0,0,0,0,0,0
0,0,0,0,0,0,0,0,0,0,0,0,0
0,0,0,0,0,0,0,0,0,0,0,0,0
0,0,0,0,0,0,0,0,0,0,0,0,0
0,0,0,0,9,3,3,3,4,0,0,0,0
0,0,0,0,11,12,12,12,11,0,0,0,0
0,0,0,0,11,12,13,12,11,0,0,0,0
0,0,0,0,11,12,12,12,11,0,0,0,0
0,0,0,0,5,3,3,3,10,0,0,0,0
0,0,0,0,0,0,0,0,0,0,0,0,0
0,0,0,0,0,0,0,0,0,0,0,0,0
0,0,0,0,0,0,0,0,0,0,0,0,0
0,0,0,0,0,0,0,0,0,0,0,0,0
endlayer

layer
0,0,0,0,0,0,0,0,0,0,0,0,0
0,0,0,0,0,0,0,0,0,0,0,0,0
0,0,0,0,0,0,0,0,0,0,0,0,0
0,0,0,0,0,0,0,0,0,0,0,0,0
0,0,0,0,9,3,3,3,4,0,0,0,0
0,0,0,0,11,12,12,12,11,0,0,0,0
0,0,0,0,11,12,14,12,11,0,0,0,0
0,0,0,0,11,12,12,12,11,0,0,0,0
0,0,0,0,5,3,3,3,10,0,0,0,0
0,0,0,0,0,0,0,0,0,0,0,0,0
0,0,0,0,0,0,0,0,0,0,0,0,0
0,0,0,0,0,0,0,0,0,0,0,0,0
0,0,0,0,0,0,0,0,0,0,0,0,0
endlayer

layer
0,0,0,0,0,0,0,0,0,0,0,0,0
0,0,0,0,0,0,0,0,0,0,0,0,0
0,0,0,0,0,0,0,0,0,0,0,0,0
0,0,0,0,0,0,0,0,0,0,0,0,0
0,0,0,0,9,3,3,3,4,0,0,0,0
0,0,0,0,11,12,12,12,11,0,0,0,0
0,0,0,0,11,12,13,12,11,0,0,0,0
0,0,0,0,11,12,12,12,11,0,0,0,0
0,0,0,0,5,3,3,3,10,0,0,0,0
0,0,0,0,0,0,0,0,0,0,0,0,0
0,0,0,0,0,0,0,0,0,0,0,0,0
0,0,0,0,0,0,0,0,0,0,0,0,0
0,0,0,0,0,0,0,0,0,0,0,0,0
endlayer

layer
0,0,0,0,0,0,0,0,0,0,0,0,0
0,0,0,0,0,0,0,0,0,0,0,0,0
0,0,0,0,0,0,0,0,0,0,0,0,0
0,0,0,0,0,0,0,0,0,0,0,0,0
0,0,0,0,9,3,3,3,4,0,0,0,0
0,0,0,0,11,12,12,12,11,0,0,0,0
0,0,0,0,11,12,14,12,11,0,0,0,0
0,0,0,0,11,12,12,12,11,0,0,0,0
0,0,0,0,5,3,3,3,10,0,0,0,0
0,0,0,0,0,0,0,0,0,0,0,0,0
0,0,0,0,0,0,0,0,0,0,0,0,0
0,0,0,0,0,0,0,0,0,0,0,0,0
0,0,0,0,0,0,0,0,0,0,0,0,0
endlayer

layer
0,0,0,0,0,0,0,0,0,0,0,0,0
0,0,0,0,0,0,0,0,0,0,0,0,0
0,0,0,0,0,0,0,0,0,0,0,0,0
0,0,0,0,0,0,0,0,0,0,0,0,0
0,0,0,0,9,3,3,3,4,0,0,0,0
0,0,0,0,11,12,12,12,11,0,0,0,0
0,0,0,0,11,12,13,12,11,0,0,0,0
0,0,0,0,11,12,12,12,11,0,0,0,0
0,0,0,0,5,3,3,3,10,0,0,0,0
0,0,0,0,0,0,0,0,0,0,0,0,0
0,0,0,0,0,0,0,0,0,0,0,0,0
0,0,0,0,0,0,0,0,0,0,0,0,0
0,0,0,0,0,0,0,0,0,0,0,0,0
endlayer

layer
0,0,0,0,0,0,0,0,0,0,0,0,0
0,0,0,0,0,0,0,0,0,0,0,0,0
0,0,0,0,0,0,0,0,0,0,0,0,0
0,0,0,0,0,0,0,0,0,0,0,0,0
0,0,0,0,9,3,3,3,4,0,0,0,0
0,0,0,0,11,12,12,12,11,0,0,0,0
0,0,0,0,11,12,14,12,11,0,0,0,0
0,0,0,0,11,12,12,12,11,0,0,0,0
0,0,0,0,5,3,3,3,10,0,0,0,0
0,0,0,0,0,0,0,0,0,0,0,0,0
0,0,0,0,0,0,0,0,0,0,0,0,0
0,0,0,0,0,0,0,0,0,0,0,0,0
0,0,0,0,0,0,0,0,0,0,0,0,0
endlayer

layer
0,0,0,0,0,0,0,0,0,0,0,0,0
0,0,0,0,0,0,0,0,0,0,0,0,0
0,0,0,0,0,0,0,0,0,0,0,0,0
0,0,0,0,0,0,0,0,0,0,0,0,0
0,0,0,0,9,3,3,3,4,0,0,0,0
0,0,0,0,11,12,12,12,11,0,0,0,0
0,0,0,0,11,12,13,12,11,0,0,0,0
0,0,0,0,11,12,12,12,11,0,0,0,0
0,0,0,0,5,3,3,3,10,0,0,0,0
0,0,0,0,0,0,0,0,0,0,0,0,0
0,0,0,0,0,0,0,0,0,0,0,0,0
0,0,0,0,0,0,0,0,0,0,0,0,0
0,0,0,0,0,0,0,0,0,0,0,0,0
endlayer

layer
0,0,0,0,0,0,0,0,0,0,0,0,0
0,0,0,0,0,0,0,0,0,0,0,0,0
0,0,0,0,0,0,0,0,0,0,0,0,0
0,0,0,0,0,0,0,0,0,0,0,0,0
0,0,0,0,9,3,3,3,4,0,0,0,0
0,0,0,0,11,12,12,12,11,0,0,0,0
0,0,0,0,11,12,14,12,11,0,0,0,0
0,0,0,0,11,12,12,12,11,0,0,0,0
0,0,0,0,5,3,3,3,10,0,0,0,0
0,0,0,0,0,0,0,0,0,0,0,0,0
0,0,0,0,0,0,0,0,0,0,0,0,0
0,0,0,0,0,0,0,0,0,0,0,0,0
0,0,0,0,0,0,0,0,0,0,0,0,0
endlayer

layer
0,0,0,0,0,0,0,0,0,0,0,0,0
0,0,0,0,0,0,0,0,0,0,0,0,0
0,0,0,0,0,0,0,0,0,0,0,0,0
0,0,0,0,0,0,0,0,0,0,0,0,0
0,0,0,0,9,3,3,3,4,0,0,0,0
0,0,0,0,11,12,12,12,11,0,0,0,0
0,0,0,0,11,12,13,12,11,0,0,0,0
0,0,0,0,11,12,12,12,11,0,0,0,0
0,0,0,0,5,3,3,3,10,0,0,0,0
0,0,0,0,0,0,0,0,0,0,0,0,0
0,0,0,0,0,0,0,0,0,0,0,0,0
0,0,0,0,0,0,0,0,0,0,0,0,0
0,0,0,0,0,0,0,0,0,0,0,0,0
endlayer

layer
0,0,0,0,0,0,0,0,0,0,0,0,0
0,0,0,0,0,0,0,0,0,0,0,0,0
0,0,0,0,0,0,0,0,0,0,0,0,0
0,0,0,0,0,0,0,0,0,0,0,0,0
0,0,0,0,9,3,3,3,4,0,0,0,0
0,0,0,0,11,12,12,12,11,0,0,0,0
0,0,0,0,11,12,14,12,11,0,0,0,0
0,0,0,0,11,12,12,12,11,0,0,0,0
0,0,0,0,5,3,3,3,10,0,0,0,0
0,0,0,0,0,0,0,0,0,0,0,0,0
0,0,0,0,0,0,0,0,0,0,0,0,0
0,0,0,0,0,0,0,0,0,0,0,0,0
0,0,0,0,0,0,0,0,0,0,0,0,0
endlayer

layer
0,0,0,0,0,0,0,0,0,0,0,0,0
0,0,0,0,0,0,0,0,0,0,0,0,0
0,0,0,0,0,0,0,0,0,0,0,0,0
0,0,0,0,0,0,0,0,0,0,0,0,0
0,0,0,0,9,3,3,3,4,0,0,0,0
0,0,0,0,11,12,12,12,11,0,0,0,0
0,0,0,0,11,12,13,12,11,0,0,0,0
0,0,0,0,11,12,12,12,11,0,0,0,0
0,0,0,0,5,3,3,3,10,0,0,0,0
0,0,0,0,0,0,0,0,0,0,0,0,0
0,0,0,0,0,0,0,0,0,0,0,0,0
0,0,0,0,0,0,0,0,0,0,0,0,0
0,0,0,0,0,0,0,0,0,0,0,0,0
endlayer

layer
0,0,0,0,0,0,0,0,0,0,0,0,0
0,0,0,0,0,0,0,0,0,0,0,0,0
0,0,0,0,0,0,0,0,0,0,0,0,0
0,0,0,0,0,0,0,0,0,0,0,0,0
0,0,0,0,9,3,3,3,4,0,0,0,0
0,0,0,0,11,12,12,12,11,0,0,0,0
0,0,0,0,11,12,14,12,11,0,0,0,0
0,0,0,0,11,12,12,12,11,0,0,0,0
0,0,0,0,5,3,3,3,10,0,0,0,0
0,0,0,0,0,0,0,0,0,0,0,0,0
0,0,0,0,0,0,0,0,0,0,0,0,0
0,0,0,0,0,0,0,0,0,0,0,0,0
0,0,0,0,0,0,0,0,0,0,0,0,0
endlayer

layer
0,0,0,0,0,0,0,0,0,0,0,0,0
0,0,0,0,0,0,0,0,0,0,0,0,0
0,0,0,0,0,0,0,0,0,0,0,0,0
0,0,0,0,0,0,0,0,0,0,0,0,0
0,0,0,0,9,3,3,3,4,0,0,0,0
0,0,0,0,11,12,12,12,11,0,0,0,0
0,0,0,0,11,12,13,12,11,0,0,0,0
0,0,0,0,11,12,12,12,11,0,0,0,0
0,0,0,0,5,3,3,3,10,0,0,0,0
0,0,0,0,0,0,0,0,0,0,0,0,0
0,0,0,0,0,0,0,0,0,0,0,0,0
0,0,0,0,0,0,0,0,0,0,0,0,0
0,0,0,0,0,0,0,0,0,0,0,0,0
endlayer

layer
0,0,0,0,0,0,0,0,0,0,0,0,0
0,0,0,0,0,0,0,0,0,0,0,0,0
0,0,0,0,0,0,0,0,0,0,0,0,0
0,0,0,0,0,0,0,0,0,0,0,0,0
0,0,0,0,9,3,3,3,4,0,0,0,0
0,0,0,0,11,12,12,12,11,0,0,0,0
0,0,0,0,11,12,14,12,11,0,0,0,0
0,0,0,0,11,12,12,12,11,0,0,0,0
0,0,0,0,5,3,3,3,10,0,0,0,0
0,0,0,0,0,0,0,0,0,0,0,0,0
0,0,0,0,0,0,0,0,0,0,0,0,0
0,0,0,0,0,0,0,0,0,0,0,0,0
0,0,0,0,0,0,0,0,0,0,0,0,0
endlayer

layer
0,0,0,0,0,0,0,0,0,0,0,0,0
0,0,0,0,0,0,0,0,0,0,0,0,0
0,0,0,0,0,0,0,0,0,0,0,0,0
0,0,0,0,0,0,0,0,0,0,0,0,0
0,0,0,0,9,3,3,3,4,0,0,0,0
0,0,0,0,11,12,12,12,11,0,0,0,0
0,0,0,0,11,12,13,12,11,0,0,0,0
0,0,0,0,11,12,12,12,11,0,0,0,0
0,0,0,0,5,3,3,3,10,0,0,0,0
0,0,0,0,0,0,0,0,0,0,0,0,0
0,0,0,0,0,0,0,0,0,0,0,0,0
0,0,0,0,0,0,0,0,0,0,0,0,0
0,0,0,0,0,0,0,0,0,0,0,0,0
endlayer

layer
0,0,0,0,0,0,0,0,0,0,0,0,0
0,0,0,0,0,0,0,0,0,0,0,0,0
0,0,0,0,0,0,0,0,0,0,0,0,0
0,0,0,0,0,0,0,0,0,0,0,0,0
0,0,0,0,9,3,3,3,4,0,0,0,0
0,0,0,0,11,12,12,12,11,0,0,0,0
0,0,0,0,11,12,14,12,11,0,0,0,0
0,0,0,0,11,12,12,12,11,0,0,0,0
0,0,0,0,5,3,3,3,10,0,0,0,0
0,0,0,0,0,0,0,0,0,0,0,0,0
0,0,0,0,0,0,0,0,0,0,0,0,0
0,0,0,0,0,0,0,0,0,0,0,0,0
0,0,0,0,0,0,0,0,0,0,0,0,0
endlayer

layer
0,0,0,0,0,0,0,0,0,0,0,0,0
0,0,0,0,0,0,0,0,0,0,0,0,0
0,0,0,0,0,0,0,0,0,0,0,0,0
0,0,0,0,0,0,0,0,0,0,0,0,0
0,0,0,0,9,1,1,1,4,0,0,0,0
0,0,0,0,11,12,12,12,11,0,0,0,0
0,0,0,0,11,12,0,12,11,0,0,0,0
0,0,0,0,11,12,12,12,11,0,0,0,0
0,0,0,0,5,1,1,1,10,0,0,0,0
0,0,0,0,0,0,0,0,0,0,0,0,0
0,0,0,0,0,0,0,0,0,0,0,0,0
0,0,0,0,0,0,0,0,0,0,0,0,0
0,0,0,0,0,0,0,0,0,0,0,0,0
endlayer

layer
0,0,0,0,0,0,0,0,0,0,0,0,0
0,0,0,0,0,0,0,0,0,0,0,0,0
0,0,0,0,0,0,0,0,0,0,0,0,0
0,0,0,0,0,0,0,0,0,0,0,0,0
0,0,0,0,0,0,0,0,0,0,0,0,0
0,0,0,0,0,3,3,3,0,0,0,0,0
0,0,0,0,0,3,0,3,0,0,0,0,0
0,0,0,0,0,3,3,3,0,0,0,0,0
0,0,0,0,0,0,0,0,0,0,0,0,0
0,0,0,0,0,0,0,0,0,0,0,0,0
0,0,0,0,0,0,0,0,0,0,0,0,0
0,0,0,0,0,0,0,0,0,0,0,0,0
0,0,0,0,0,0,0,0,0,0,0,0,0
endlayer

