# Gilly's Skyport access shaft
# template generated by Ruins mod version 14.6 Ingame Parser
# Structure created by Gilly

weight=1
embed_into_distance=45
acceptable_target_blocks=
unacceptable_target_blocks=flowing_water,water,flowing_lava,lava,ice,bedrock,netherrack,soul_sand,Natura:Cloud
dimensions=41,10,9
allowable_overhang=0
max_leveling=4
leveling_buffer=-1
preserve_water=0
preserve_lava=0

rule1=0,100,preserveBlock
rule2=0,100,minecraft:stained_hardened_clay-9
rule3=0,100,minecraft:double_stone_slab-8
rule4=0,100,minecraft:iron_bars-0
rule5=0,100,minecraft:stone_slab-0
rule6=0,100,minecraft:water-0
rule7=0,100,minecraft:ladder-5
rule8=0,100,minecraft:ladder-4
rule9=0,100,minecraft:stained_hardened_clay-4
rule10=0,100,minecraft:glowstone-0

layer
1,2,2,2,2,2,2,1,1
1,2,2,2,2,2,2,1,1
1,2,2,2,2,2,2,1,1
1,2,2,2,2,2,2,2,1
1,2,2,1,1,1,2,2,2
2,2,3,3,1,1,1,1,2
2,3,3,3,1,1,1,1,2
2,3,3,3,1,1,1,1,2
2,2,3,3,1,1,1,1,2
1,2,2,2,2,2,2,2,2
endlayer

layer
1,2,2,2,2,2,2,1,1
1,2,2,4,4,4,2,1,1
1,2,2,4,0,4,2,1,1
1,2,2,4,0,4,2,2,1
1,2,2,0,0,0,2,2,2
2,2,5,5,0,0,0,0,1
2,6,6,5,0,0,0,0,1
2,6,6,5,0,0,0,0,1
2,2,5,5,0,0,0,0,1
1,2,1,1,1,1,1,1,2
endlayer

layer
1,2,2,2,2,2,2,1,1
1,2,2,4,4,4,2,1,1
1,2,2,4,0,4,2,1,1
1,2,2,4,0,4,2,2,1
1,2,2,0,0,0,2,2,2
2,2,0,0,0,0,0,0,1
2,7,0,0,0,0,0,0,1
2,8,0,0,0,0,0,0,1
2,2,0,0,0,0,0,0,1
1,2,1,1,1,1,1,1,2
endlayer

layer
1,2,2,2,2,2,2,1,1
1,2,2,4,4,4,2,1,1
1,2,2,4,0,4,2,1,1
1,2,2,4,0,4,2,2,1
1,2,2,0,0,0,2,2,2
2,2,0,0,0,0,0,0,1
2,7,0,0,0,0,0,0,1
2,8,0,0,0,0,0,0,1
2,2,0,0,0,0,0,0,1
1,2,1,1,1,1,1,1,2
endlayer

layer
1,2,2,2,2,2,2,1,1
1,2,2,4,4,4,2,1,1
1,2,2,4,9,4,2,1,1
1,2,2,4,4,4,2,2,1
1,2,2,0,0,0,2,2,2
2,2,4,0,0,0,0,0,2
2,7,4,0,0,0,0,0,2
2,8,4,0,0,0,0,0,2
2,2,4,0,0,0,0,0,2
1,2,2,2,2,2,2,2,2
endlayer

layer
1,2,2,2,2,2,2,1,1
1,2,2,4,4,4,2,1,1
1,2,2,4,9,4,2,1,1
1,2,2,4,4,4,2,2,1
1,2,2,0,0,0,2,2,2
2,2,0,0,0,0,0,0,1
2,7,4,0,0,0,0,0,1
2,8,4,0,0,0,0,0,1
2,2,0,0,0,0,0,0,1
1,2,1,1,1,1,1,1,2
endlayer

layer
1,2,2,2,2,2,2,1,1
1,2,2,4,4,4,2,1,1
1,2,2,4,9,4,2,1,1
1,2,2,4,4,4,2,2,1
1,2,2,0,0,0,2,2,2
2,2,0,0,0,0,0,0,1
2,7,4,0,0,0,0,0,1
2,8,4,0,0,0,0,0,1
2,2,0,0,0,0,0,0,1
1,2,1,1,1,1,1,1,2
endlayer

layer
1,2,2,2,2,2,2,1,1
1,2,2,4,4,4,2,1,1
1,2,2,4,9,4,2,1,1
1,2,2,4,4,4,2,2,1
1,2,2,0,0,0,2,2,2
2,2,0,0,0,0,0,0,1
2,7,4,0,0,0,0,0,1
2,8,4,0,0,0,0,0,1
2,2,0,0,0,0,0,0,1
1,2,1,1,1,1,1,1,2
endlayer

layer
1,2,2,2,2,2,2,1,1
1,2,2,4,4,4,2,1,1
1,2,2,4,9,4,2,1,1
1,2,2,4,4,4,2,2,1
1,2,2,0,0,0,2,2,2
2,2,0,0,0,0,0,0,1
2,7,4,0,0,0,0,0,1
2,8,4,0,0,0,0,0,1
2,2,0,0,0,0,0,0,1
1,2,1,1,1,1,1,1,2
endlayer

layer
1,2,2,2,2,2,2,1,1
1,2,2,4,4,4,2,1,1
1,2,10,4,9,4,2,1,1
1,2,2,4,4,4,2,2,1
1,2,2,0,0,0,2,2,2
2,2,0,0,0,0,0,0,1
2,7,4,0,0,0,0,0,1
2,8,4,0,0,0,0,0,1
2,2,0,0,0,0,0,0,1
1,2,1,1,1,1,1,1,2
endlayer

layer
2,2,2,2,2,2,2,1,1
2,2,2,4,4,4,2,1,1
2,2,2,4,9,4,2,1,1
2,2,2,4,4,4,2,2,1
2,2,2,0,0,0,2,2,2
2,2,0,0,0,0,0,0,1
2,7,4,0,0,0,0,0,1
2,8,4,0,0,0,0,0,1
2,2,0,0,0,0,0,0,1
2,2,1,1,1,1,1,1,2
endlayer

layer
0,2,2,2,2,2,2,1,1
0,0,0,4,4,4,2,1,1
0,0,0,0,0,4,2,1,1
0,0,0,4,4,4,2,2,1
0,2,2,0,0,0,2,2,2
0,2,0,0,0,0,0,0,1
0,7,4,0,0,0,0,0,1
0,8,4,0,0,0,0,0,1
0,2,0,0,0,0,0,0,1
0,2,1,1,1,1,1,1,2
endlayer

layer
0,2,2,2,2,2,2,1,1
0,0,0,4,4,4,2,1,1
0,0,0,0,0,4,2,1,1
0,0,0,4,4,4,2,2,1
0,2,2,0,0,0,2,2,2
0,2,0,0,0,0,0,0,1
0,7,4,0,0,0,0,0,1
0,8,4,0,0,0,0,0,1
0,2,0,0,0,0,0,0,1
0,2,1,1,1,1,1,1,2
endlayer

layer
0,2,2,2,2,2,2,1,1
0,0,0,4,4,4,2,1,1
0,0,0,0,0,4,2,1,1
0,0,0,4,4,4,2,2,1
0,2,2,0,0,0,2,2,2
0,2,0,0,0,0,0,0,1
0,7,4,0,0,0,0,0,1
0,8,4,0,0,0,0,0,1
0,2,0,0,0,0,0,0,1
0,2,1,1,1,1,1,1,2
endlayer

layer
0,2,2,2,2,2,2,1,1
0,0,2,4,4,4,2,1,1
0,0,2,4,9,4,2,1,1
0,0,2,4,4,4,2,2,1
0,2,2,0,0,0,2,2,2
0,2,4,0,0,0,0,0,2
0,7,4,0,0,0,0,0,2
0,8,4,0,0,0,0,0,2
0,2,4,0,0,0,0,0,2
0,2,2,2,2,2,2,2,2
endlayer

layer
0,2,2,2,2,2,2,1,1
0,2,2,4,4,4,2,1,1
0,2,2,4,9,4,2,1,1
0,2,2,4,4,4,2,2,1
0,2,2,0,0,0,2,2,2
0,2,0,0,0,0,0,0,1
0,7,4,0,0,0,0,0,1
0,8,4,0,0,0,0,0,1
0,2,0,0,0,0,0,0,1
0,2,1,1,1,1,1,1,2
endlayer

layer
3,2,2,2,2,2,2,1,1
3,2,2,4,4,4,2,1,1
3,2,2,4,9,4,2,1,1
3,2,2,4,4,4,2,2,1
3,2,2,0,0,0,2,2,2
3,2,0,0,0,0,0,0,1
3,7,4,0,0,0,0,0,1
3,8,4,0,0,0,0,0,1
3,2,0,0,0,0,0,0,1
3,2,1,1,1,1,1,1,2
endlayer

layer
2,2,2,2,2,2,2,1,1
2,2,2,4,4,4,2,1,1
2,2,10,4,9,4,2,1,1
2,2,2,4,4,4,2,2,1
2,2,2,0,0,0,2,2,2
2,2,0,0,0,0,0,0,1
2,7,4,0,0,0,0,0,1
2,8,4,0,0,0,0,0,1
2,2,0,0,0,0,0,0,1
2,2,1,1,1,1,1,1,2
endlayer

layer
2,2,2,2,2,2,2,1,1
2,2,2,4,4,4,2,1,1
2,2,2,4,9,4,2,1,1
2,2,2,4,4,4,2,2,1
2,2,2,0,0,0,2,2,2
2,2,0,0,0,0,0,0,1
2,7,4,0,0,0,0,0,1
2,8,4,0,0,0,0,0,1
2,2,0,0,0,0,0,0,1
2,2,1,1,1,1,1,1,2
endlayer

layer
0,2,2,2,2,2,2,1,1
0,0,0,4,4,4,2,1,1
0,0,0,0,0,4,2,1,1
0,0,0,4,4,4,2,2,1
0,2,2,0,0,0,2,2,2
0,2,0,0,0,0,0,0,1
0,7,4,0,0,0,0,0,1
0,8,4,0,0,0,0,0,1
0,2,0,0,0,0,0,0,1
0,2,1,1,1,1,1,1,2
endlayer

layer
0,2,2,2,2,2,2,1,1
0,0,0,4,4,4,2,1,1
0,0,0,0,0,4,2,1,1
0,0,0,4,4,4,2,2,1
0,2,2,0,0,0,2,2,2
0,2,0,0,0,0,0,0,1
0,7,4,0,0,0,0,0,1
0,8,4,0,0,0,0,0,1
0,2,0,0,0,0,0,0,1
0,2,1,1,1,1,1,1,2
endlayer

layer
0,2,2,2,2,2,2,1,1
0,0,0,4,4,4,2,1,1
0,0,0,0,0,4,2,1,1
0,0,0,4,4,4,2,2,1
0,2,2,0,0,0,2,2,2
0,2,0,0,0,0,0,0,1
0,7,4,0,0,0,0,0,1
0,8,4,0,0,0,0,0,1
0,2,0,0,0,0,0,0,1
0,2,1,1,1,1,1,1,2
endlayer

layer
0,2,2,2,2,2,2,1,1
0,0,2,4,4,4,2,1,1
0,0,2,4,9,4,2,1,1
0,0,2,4,4,4,2,2,1
0,2,2,0,0,0,2,2,2
0,2,0,0,0,0,0,0,1
0,7,4,0,0,0,0,0,1
0,8,4,0,0,0,0,0,1
0,2,0,0,0,0,0,0,1
0,2,1,1,1,1,1,1,2
endlayer

layer
0,2,2,2,2,2,2,1,1
0,2,2,4,4,4,2,1,1
0,2,2,4,9,4,2,1,1
0,2,2,4,4,4,2,2,1
0,2,2,0,0,0,2,2,2
0,2,0,0,0,0,0,0,1
0,7,4,0,0,0,0,0,1
0,8,4,0,0,0,0,0,1
0,2,0,0,0,0,0,0,1
0,2,1,1,1,1,1,1,2
endlayer

layer
3,2,2,2,2,2,2,1,1
3,2,2,4,4,4,2,1,1
3,2,2,4,9,4,2,1,1
3,2,2,4,4,4,2,2,1
3,2,2,0,0,0,2,2,2
3,2,0,0,0,0,0,0,1
3,7,4,0,0,0,0,0,1
3,8,4,0,0,0,0,0,1
3,2,0,0,0,0,0,0,1
3,2,1,1,1,1,1,1,2
endlayer

layer
2,2,2,2,2,2,2,1,1
2,2,2,4,4,4,2,1,1
2,2,10,4,9,4,2,1,1
2,2,2,4,4,4,2,2,1
2,2,2,0,0,0,2,2,2
2,2,0,0,0,0,0,0,1
2,7,4,0,0,0,0,0,1
2,8,4,0,0,0,0,0,1
2,2,0,0,0,0,0,0,1
2,2,1,1,1,1,1,1,2
endlayer

layer
2,2,2,2,2,2,2,1,1
2,2,2,4,4,4,2,1,1
2,2,2,4,9,4,2,1,1
2,2,2,4,4,4,2,2,1
2,2,2,0,0,0,2,2,2
2,2,4,0,0,0,0,0,2
2,7,4,0,0,0,0,0,2
2,8,4,0,0,0,0,0,2
2,2,4,0,0,0,0,0,2
2,2,2,2,2,2,2,2,2
endlayer

layer
0,2,2,2,2,2,2,1,1
0,0,0,4,4,4,2,1,1
0,0,0,0,0,4,2,1,1
0,0,0,4,4,4,2,2,1
0,2,2,0,0,0,2,2,2
0,2,0,0,0,0,0,0,2
0,7,4,0,0,0,0,0,2
0,8,4,0,0,0,0,0,2
0,2,0,0,0,0,0,0,2
0,2,2,2,2,2,2,2,2
endlayer

layer
0,2,2,2,2,2,2,1,1
0,0,0,4,4,4,2,1,1
0,0,0,0,0,4,2,1,1
0,0,0,4,4,4,2,2,1
0,2,2,0,0,0,2,2,2
0,2,0,0,0,0,0,0,2
0,7,4,0,0,0,0,0,2
0,8,4,0,0,0,0,0,2
0,2,0,0,0,0,0,0,2
0,2,2,2,2,2,2,2,2
endlayer

layer
0,2,2,2,2,2,2,1,1
0,0,0,4,4,4,2,1,1
0,0,0,0,0,4,2,1,1
0,0,0,4,4,4,2,2,1
0,2,2,0,0,0,2,2,2
0,2,0,0,0,0,0,0,2
0,7,4,0,0,0,0,0,2
0,8,4,0,0,0,0,0,2
0,2,0,0,0,0,0,0,2
0,2,2,2,2,2,2,2,2
endlayer

layer
0,2,2,2,2,2,2,1,1
0,0,2,4,4,4,2,1,1
0,0,2,4,9,4,2,1,1
0,0,2,4,4,4,2,2,1
0,2,2,0,0,0,2,2,2
0,2,0,0,0,0,0,0,2
0,7,4,0,0,0,0,0,2
0,8,4,0,0,0,0,0,2
0,2,0,0,0,0,0,0,2
0,2,2,2,2,2,2,2,2
endlayer

layer
0,2,2,2,2,2,2,1,1
0,2,2,4,4,4,2,1,1
0,2,2,4,9,4,2,1,1
0,2,2,4,4,4,2,2,1
0,2,2,0,0,0,2,2,2
0,2,0,0,0,0,0,0,2
0,7,4,0,0,0,0,0,2
0,8,4,0,0,0,0,0,2
0,2,0,0,0,0,0,0,2
0,2,2,2,2,2,2,2,2
endlayer

layer
3,2,2,2,2,2,2,1,1
3,2,2,4,4,4,2,1,1
3,2,2,4,9,4,2,1,1
3,2,2,4,4,4,2,2,1
3,2,2,0,0,0,2,2,2
3,2,0,0,0,0,0,0,2
3,7,4,0,0,0,0,0,2
3,8,4,0,0,0,0,0,2
3,2,0,0,0,0,0,0,2
3,2,2,2,2,2,2,2,2
endlayer

layer
1,2,2,2,2,2,2,1,1
1,2,2,4,4,4,2,1,1
1,2,2,4,9,4,2,1,1
1,2,2,4,4,4,2,2,1
1,2,2,0,0,0,2,2,2
2,2,0,0,0,0,0,0,2
2,7,4,0,0,0,0,0,2
2,8,4,0,0,0,0,0,2
2,2,0,0,0,0,0,0,2
1,2,2,2,2,2,2,2,2
endlayer

layer
1,2,2,2,2,2,2,1,1
1,2,2,4,4,4,2,1,1
1,2,2,4,9,4,2,1,1
1,2,2,4,4,4,2,2,1
1,2,2,0,0,0,2,2,2
2,2,0,0,0,0,0,0,2
2,7,4,0,0,0,0,0,2
2,8,4,0,0,0,0,0,2
2,2,0,0,0,0,0,0,2
1,2,2,2,2,2,2,2,2
endlayer

layer
1,2,2,2,2,2,2,1,1
1,2,2,4,4,4,2,1,1
1,2,2,4,9,4,2,1,1
1,2,2,4,4,4,2,2,1
1,2,2,0,0,0,2,2,2
2,2,0,0,0,0,0,0,2
2,7,4,0,0,0,0,0,2
2,8,4,0,0,0,0,0,2
2,2,0,0,0,0,0,0,2
1,2,2,2,2,2,2,2,2
endlayer

layer
1,2,2,2,2,2,2,1,1
1,2,2,4,4,4,2,1,1
1,2,2,4,9,4,2,1,1
1,2,2,4,4,4,2,2,1
1,2,2,0,0,0,2,2,2
2,2,0,0,0,0,0,0,2
2,7,4,0,0,0,0,0,2
2,8,4,0,0,0,0,0,2
2,2,0,0,0,0,0,0,2
1,2,2,2,2,2,2,2,2
endlayer

layer
1,2,2,2,2,2,2,1,1
1,2,2,4,4,4,2,1,1
1,2,2,4,9,4,2,1,1
1,2,2,4,4,4,2,2,1
1,2,2,0,0,0,2,2,2
2,2,0,0,0,0,0,0,2
2,7,4,0,0,0,0,0,2
2,8,4,0,0,0,0,0,2
2,2,0,0,0,0,0,0,2
1,2,2,2,2,2,2,2,2
endlayer

layer
1,2,2,2,2,2,2,1,1
1,2,2,4,4,4,2,1,1
1,2,2,4,9,4,2,1,1
1,2,2,4,4,4,2,2,1
1,2,2,0,0,0,2,2,2
2,2,4,0,0,0,0,0,2
2,7,4,0,0,0,0,0,2
2,8,4,0,0,0,0,0,2
2,2,4,0,0,0,0,0,2
1,2,2,2,2,2,2,2,2
endlayer

layer
1,2,2,2,2,2,2,1,1
1,2,2,4,4,4,2,1,1
1,2,2,4,9,4,2,1,1
1,2,2,4,4,4,2,2,1
1,2,2,0,0,0,2,2,2
2,2,0,0,0,0,0,0,2
2,7,4,0,0,0,0,0,2
2,8,4,0,0,0,0,0,2
2,2,0,0,0,0,0,0,2
1,2,2,2,2,2,2,2,2
endlayer

layer
1,2,2,2,2,2,2,1,1
1,2,2,4,4,4,2,1,1
1,2,2,4,9,4,2,1,1
1,2,2,4,4,4,2,2,1
1,2,2,0,0,0,2,2,2
2,2,0,0,0,0,0,0,2
2,7,4,0,0,0,0,0,2
2,8,4,0,0,0,0,0,2
2,2,0,0,0,0,0,0,2
1,2,2,2,2,2,2,2,2
endlayer

