# Gilly's Skyport rooms
# template generated by Ruins mod version 14.6 Ingame Parser
# Structure created by Gilly

weight=1
embed_into_distance=36
acceptable_target_blocks=
unacceptable_target_blocks=flowing_water,water,flowing_lava,lava,ice,bedrock,netherrack,soul_sand,Natura:Cloud
dimensions=25,19,11
allowable_overhang=0
max_leveling=3
leveling_buffer=-1
preserve_water=0
preserve_lava=0

rule1=0,100,preserveBlock
rule2=0,100,chisel:stonebricksmooth-12
rule3=0,100,minecraft:glowstone-0
rule4=0,100,chisel:factoryblock-1
rule5=0,100,minecraft:ladder-5
rule6=0,100,minecraft:ladder-4
rule7=0,100,minecraft:stained_hardened_clay-9
rule8=0,100,minecraft:iron_bars-0
rule9=0,100,chisel:factoryblock-6
rule10=0,100,minecraft:stonebrick-0
rule11=0,100,TConstruct:Smeltery-11
rule12=0,100,chisel:limestone-9
rule13=0,100,chisel:dark_oak_planks-9
rule14=0,100,chisel:spruce_planks-15
rule15=0,100,chisel:technical-2
rule16=0,100,chisel:oak_planks-8
rule17=0,100,chisel:technical-6
rule18=0,100,chisel:spruce_planks-8
rule19=0,100,chisel:oak_planks-14
rule20=0,100,chisel:factoryblock-4
rule21=0,100,chisel:birch_planks-9
rule22=0,100,chisel:limestone-15
rule23=0,100,ChestGenHook:mineshaftCorridor:5-2
rule24=0,100,chisel:technical-12
rule25=0,100,chisel:stained_glass_yellow-13
rule26=0,100,ChestGenHook:villageBlacksmith:5-4
rule27=0,100,minecraft:bed-0
rule28=0,100,minecraft:bed-8
rule29=0,100,chisel:birch_planks-8
rule30=0,100,chisel:spruce_planks-9
rule31=0,100,chisel:technical2-2
rule32=0,100,chisel:birch_planks-14
rule33=0,100,chisel:stonebricksmooth-13
rule34=0,100,minecraft:stained_hardened_clay-3
rule35=0,100,minecraft:double_stone_slab-8
rule36=0,100,minecraft:cauldron-0

layer
1,1,1,1,1,1,1,1,1,1,1
1,2,2,2,2,2,2,2,2,2,1
1,2,2,2,2,2,2,2,2,2,1
1,2,2,3,2,2,2,3,2,2,1
1,2,2,2,2,2,2,2,2,2,4
1,2,2,2,2,2,2,2,2,2,4
1,2,2,2,2,2,2,2,2,2,2
1,2,2,3,2,2,2,3,2,2,2
1,2,2,2,2,2,2,2,2,2,2
1,2,2,2,2,2,2,2,2,2,4
1,2,2,2,2,2,2,2,2,2,4
1,2,2,3,2,2,2,3,2,2,5
1,2,2,2,2,2,2,2,2,2,6
1,2,2,2,2,2,2,2,2,2,4
1,2,2,2,2,2,2,2,2,2,4
1,2,2,3,2,2,2,3,2,2,1
1,2,2,2,2,2,2,2,2,2,1
1,2,2,2,2,2,2,2,2,2,1
1,1,1,1,1,1,1,1,1,1,1
endlayer

layer
2,2,2,2,2,2,2,2,2,2,2
2,7,7,7,7,7,7,7,7,7,2
2,7,7,7,7,7,7,7,7,7,2
2,7,7,8,7,7,7,8,7,7,2
2,7,7,7,7,7,7,7,7,7,4
2,7,7,7,7,7,7,7,7,7,4
2,7,7,7,7,7,7,7,7,7,9
2,7,7,8,7,7,7,8,7,7,9
2,7,7,7,7,7,7,7,7,7,9
2,7,7,7,7,7,7,7,7,7,4
2,7,7,7,7,7,7,7,7,9,4
2,7,7,8,7,7,7,8,7,9,5
2,7,7,7,7,7,7,7,7,9,6
2,7,7,7,7,7,7,7,7,9,4
2,7,7,7,7,7,7,7,7,7,4
2,7,7,8,7,7,7,8,7,7,2
2,7,7,7,7,7,7,7,7,7,2
2,7,7,7,7,7,7,7,7,7,2
2,2,2,2,2,2,2,2,2,2,2
endlayer

layer
10,10,10,10,10,10,10,10,10,10,10
10,18,17,16,0,15,14,13,12,11,10
10,18,21,0,0,0,20,19,0,0,10
10,23,0,0,0,0,0,0,0,22,10
10,11,24,0,0,0,0,0,0,0,4
10,25,0,0,0,0,0,0,0,0,4
10,0,0,0,0,0,0,0,0,0,0
10,0,0,0,0,0,0,0,0,0,0
10,0,0,0,0,0,0,0,0,0,0
10,0,0,0,0,0,0,0,0,0,4
10,0,0,0,0,0,0,0,0,0,4
10,0,0,0,0,0,0,0,0,0,5
10,0,0,0,0,0,0,0,0,0,6
10,0,0,0,0,0,0,0,0,0,4
10,16,0,0,0,0,0,0,0,0,4
10,11,0,0,0,0,0,0,0,14,10
10,28,27,0,26,16,0,0,0,11,10
10,22,19,13,20,17,29,0,0,15,10
10,10,10,10,10,10,10,10,10,10,10
endlayer

layer
10,10,10,10,10,10,10,10,10,10,10
10,29,31,0,0,0,0,25,30,0,10
10,0,0,0,0,0,0,0,0,0,10
10,0,0,0,0,0,0,0,0,0,10
10,15,0,0,0,0,0,0,0,0,4
10,0,0,0,0,0,0,0,0,0,4
10,0,0,0,0,0,0,0,0,0,0
10,0,0,0,0,0,0,0,0,0,0
10,0,0,0,0,0,0,0,0,0,0
10,0,0,0,0,0,0,0,0,0,4
10,0,0,0,0,0,0,0,0,0,4
10,0,0,0,0,0,0,0,0,0,5
10,0,0,0,0,0,0,0,0,0,6
10,0,0,0,0,0,0,0,0,0,4
10,32,0,0,0,0,0,0,0,0,4
10,0,0,0,0,0,0,0,0,0,10
10,0,0,0,0,0,0,0,0,25,10
10,0,33,25,12,31,0,0,0,18,10
10,10,10,10,10,10,10,10,10,10,10
endlayer

layer
10,10,10,10,10,10,10,10,10,10,10
10,25,0,0,0,0,0,25,0,0,10
10,0,0,0,0,0,0,0,0,0,10
10,0,0,0,0,0,0,0,0,0,10
10,0,0,0,0,0,0,0,0,0,4
10,0,0,0,0,0,0,0,0,0,4
10,0,0,0,0,0,0,0,0,0,0
10,0,0,0,0,0,0,0,0,0,0
10,0,0,0,0,0,0,0,0,0,0
10,0,0,0,0,0,0,0,0,0,4
10,0,0,0,0,0,0,0,0,0,4
10,0,0,0,0,0,0,0,0,0,5
10,0,0,0,0,0,0,0,0,0,6
10,0,0,0,0,0,0,0,0,0,4
10,0,0,0,0,0,0,0,0,0,4
10,0,0,0,0,0,0,0,0,0,10
10,0,0,0,0,0,0,0,0,0,10
10,0,0,25,0,0,0,0,0,0,10
10,10,10,10,10,10,10,10,10,10,10
endlayer

layer
34,34,34,34,34,34,34,34,34,34,34
34,0,0,0,0,0,0,0,0,0,34
34,0,0,0,0,0,0,0,0,0,34
34,0,0,0,0,0,0,0,0,0,34
34,0,0,0,0,0,0,0,0,0,4
34,0,0,0,0,0,0,0,0,0,4
34,0,0,0,0,0,0,0,0,0,0
34,0,0,0,0,0,0,0,0,0,0
34,0,0,0,0,0,0,0,0,0,0
34,0,0,0,0,0,0,0,0,0,4
34,0,0,0,0,0,0,0,0,0,4
34,0,0,0,0,0,0,0,0,0,5
34,0,0,0,0,0,0,0,0,0,6
34,0,0,0,0,0,0,0,0,0,4
34,0,0,0,0,0,0,0,0,0,4
34,0,0,0,0,0,0,0,0,0,34
34,0,0,0,0,0,0,0,0,0,34
34,0,0,0,0,0,0,0,0,0,34
34,34,34,34,34,34,34,34,34,34,34
endlayer

layer
10,10,10,10,10,10,10,10,10,10,10
10,0,0,0,0,0,0,0,0,0,10
10,0,0,0,0,0,0,0,0,0,10
10,0,0,0,0,0,0,0,0,0,10
10,0,0,0,0,0,0,0,0,0,4
10,0,0,0,0,0,0,0,0,0,4
10,0,0,0,0,0,0,0,0,0,2
10,0,0,0,0,0,0,0,0,0,2
10,0,0,0,0,0,0,0,0,0,2
10,0,0,0,0,0,0,0,0,0,4
10,0,0,0,0,0,0,0,0,0,4
10,0,0,0,0,0,0,0,0,0,5
10,0,0,0,0,0,0,0,0,0,6
10,0,0,0,0,0,0,0,0,0,4
10,0,0,0,0,0,0,0,0,0,4
10,0,0,0,0,0,0,0,0,0,10
10,0,0,0,0,0,0,0,0,0,10
10,0,0,0,0,0,0,0,0,0,10
10,10,10,10,10,10,10,10,10,10,10
endlayer

layer
2,2,2,2,2,2,2,2,2,2,2
2,35,35,35,35,35,35,35,35,35,2
2,35,35,35,35,35,35,35,35,35,2
2,35,35,35,35,35,35,35,35,35,2
2,35,35,35,35,35,35,35,35,35,4
2,35,35,35,35,36,35,35,35,35,4
2,35,35,35,35,35,35,35,35,35,2
2,35,35,35,35,35,35,35,35,35,2
2,35,35,35,35,35,35,35,35,35,2
2,35,35,35,35,36,35,35,35,35,4
2,35,35,35,35,35,35,35,35,35,4
2,35,35,35,35,35,35,35,35,35,5
2,35,35,35,35,35,35,35,35,35,6
2,35,35,35,35,36,35,35,35,35,4
2,35,35,35,35,35,35,35,35,35,4
2,35,35,35,35,35,35,35,35,35,2
2,35,35,35,35,35,35,35,35,35,2
2,35,35,35,35,35,35,35,35,35,2
2,2,2,2,2,2,2,2,2,2,2
endlayer

layer
1,1,1,1,1,1,1,1,1,1,1
1,2,2,2,2,2,2,2,2,2,1
1,2,2,2,2,2,2,2,2,2,1
1,2,2,3,2,2,2,3,2,2,1
1,2,2,2,2,2,2,2,2,2,4
1,2,2,2,2,3,2,2,2,2,4
1,2,2,2,2,2,2,2,2,2,2
1,2,2,3,2,2,2,3,2,2,2
1,2,2,2,2,2,2,2,2,2,2
1,2,2,2,2,3,2,2,2,2,4
1,2,2,2,2,2,2,2,2,2,4
1,2,2,3,2,2,2,3,2,2,5
1,2,2,2,2,2,2,2,2,2,6
1,2,2,2,2,3,2,2,2,2,4
1,2,2,2,2,2,2,2,2,2,4
1,2,2,3,2,2,2,3,2,2,1
1,2,2,2,2,2,2,2,2,2,1
1,2,2,2,2,2,2,2,2,2,1
1,1,1,1,1,1,1,1,1,1,1
endlayer

layer
2,2,2,2,2,2,2,2,2,2,2
2,7,7,7,7,7,7,7,7,7,2
2,7,7,7,7,7,7,7,7,7,2
2,7,7,8,7,7,7,8,7,7,2
2,7,7,7,7,7,7,7,7,7,4
2,7,7,7,7,7,7,7,7,7,4
2,7,7,7,7,7,7,7,7,7,9
2,7,7,8,7,7,7,8,7,7,9
2,7,7,7,7,7,7,7,7,7,9
2,7,7,7,7,7,7,7,7,7,4
2,7,7,7,7,7,7,7,7,9,4
2,7,7,8,7,7,7,8,7,9,5
2,7,7,7,7,7,7,7,7,9,6
2,7,7,7,7,7,7,7,7,9,4
2,7,7,7,7,7,7,7,7,7,4
2,7,7,8,7,7,7,8,7,7,2
2,7,7,7,7,7,7,7,7,7,2
2,7,7,7,7,7,7,7,7,7,2
2,2,2,2,2,2,2,2,2,2,2
endlayer

layer
10,10,10,10,10,10,10,10,10,10,10
10,0,0,0,0,0,0,0,0,0,10
10,0,0,0,0,0,0,0,0,0,10
10,0,0,0,0,0,0,0,0,0,10
10,0,0,0,0,0,0,0,0,0,4
10,0,0,0,0,0,0,0,0,0,4
10,0,0,0,0,0,0,0,0,0,0
10,0,0,0,0,0,0,0,0,0,0
10,0,0,0,0,0,0,0,0,0,0
10,0,0,0,0,0,0,0,0,0,4
10,0,0,0,0,0,0,0,0,0,4
10,0,0,0,0,0,0,0,0,0,5
10,0,0,0,0,0,0,0,0,0,6
10,0,0,0,0,0,0,0,0,0,4
10,0,0,0,0,0,0,0,0,0,4
10,0,0,0,0,0,0,0,0,0,10
10,0,0,0,0,0,0,0,0,0,10
10,0,0,0,0,0,0,0,0,0,10
10,10,10,10,10,10,10,10,10,10,10
endlayer

layer
10,10,10,10,10,10,10,10,10,10,10
10,0,0,0,0,0,0,0,0,0,10
10,0,0,0,0,0,0,0,0,0,10
10,0,0,0,0,0,0,0,0,0,10
10,0,0,0,0,0,0,0,0,0,4
10,0,0,0,0,0,0,0,0,0,4
10,0,0,0,0,0,0,0,0,0,0
10,0,0,0,0,0,0,0,0,0,0
10,0,0,0,0,0,0,0,0,0,0
10,0,0,0,0,0,0,0,0,0,4
10,0,0,0,0,0,0,0,0,0,4
10,0,0,0,0,0,0,0,0,0,5
10,0,0,0,0,0,0,0,0,0,6
10,0,0,0,0,0,0,0,0,0,4
10,0,0,0,0,0,0,0,0,0,4
10,0,0,0,0,0,0,0,0,0,10
10,0,0,0,0,0,0,0,0,0,10
10,0,0,0,0,0,0,0,0,0,10
10,10,10,10,10,10,10,10,10,10,10
endlayer

layer
10,10,10,10,10,10,10,10,10,10,10
10,0,0,0,0,0,0,0,0,0,10
10,0,0,0,0,0,0,0,0,0,10
10,0,0,0,0,0,0,0,0,0,10
10,0,0,0,0,0,0,0,0,0,4
10,0,0,0,0,0,0,0,0,0,4
10,0,0,0,0,0,0,0,0,0,0
10,0,0,0,0,0,0,0,0,0,0
10,0,0,0,0,0,0,0,0,0,0
10,0,0,0,0,0,0,0,0,0,4
10,0,0,0,0,0,0,0,0,0,4
10,0,0,0,0,0,0,0,0,0,5
10,0,0,0,0,0,0,0,0,0,6
10,0,0,0,0,0,0,0,0,0,4
10,0,0,0,0,0,0,0,0,0,4
10,0,0,0,0,0,0,0,0,0,10
10,0,0,0,0,0,0,0,0,0,10
10,0,0,0,0,0,0,0,0,0,10
10,10,10,10,10,10,10,10,10,10,10
endlayer

layer
34,34,34,34,34,34,34,34,34,34,34
34,0,0,0,0,0,0,0,0,0,34
34,0,0,0,0,0,0,0,0,0,34
34,0,0,0,0,0,0,0,0,0,34
34,0,0,0,0,0,0,0,0,0,4
34,0,0,0,0,0,0,0,0,0,4
34,0,0,0,0,0,0,0,0,0,0
34,0,0,0,0,0,0,0,0,0,0
34,0,0,0,0,0,0,0,0,0,0
34,0,0,0,0,0,0,0,0,0,4
34,0,0,0,0,0,0,0,0,0,4
34,0,0,0,0,0,0,0,0,0,5
34,0,0,0,0,0,0,0,0,0,6
34,0,0,0,0,0,0,0,0,0,4
34,0,0,0,0,0,0,0,0,0,4
34,0,0,0,0,0,0,0,0,0,34
34,0,0,0,0,0,0,0,0,0,34
34,0,0,0,0,0,0,0,0,0,34
34,34,34,34,34,34,34,34,34,34,34
endlayer

layer
10,10,10,10,10,10,10,10,10,10,10
10,0,0,0,0,0,0,0,0,0,10
10,0,0,0,0,0,0,0,0,0,10
10,0,0,0,0,0,0,0,0,0,10
10,0,0,0,0,0,0,0,0,0,4
10,0,0,0,0,0,0,0,0,0,4
10,0,0,0,0,0,0,0,0,0,2
10,0,0,0,0,0,0,0,0,0,2
10,0,0,0,0,0,0,0,0,0,2
10,0,0,0,0,0,0,0,0,0,4
10,0,0,0,0,0,0,0,0,0,4
10,0,0,0,0,0,0,0,0,0,5
10,0,0,0,0,0,0,0,0,0,6
10,0,0,0,0,0,0,0,0,0,4
10,0,0,0,0,0,0,0,0,0,4
10,0,0,0,0,0,0,0,0,0,10
10,0,0,0,0,0,0,0,0,0,10
10,0,0,0,0,0,0,0,0,0,10
10,10,10,10,10,10,10,10,10,10,10
endlayer

layer
2,2,2,2,2,2,2,2,2,2,2
2,35,35,35,35,35,35,35,35,35,2
2,35,35,35,35,35,35,35,35,35,2
2,35,35,35,35,35,35,35,35,35,2
2,35,35,35,35,35,35,35,35,35,4
2,35,35,35,35,36,35,35,35,35,4
2,35,35,35,35,35,35,35,35,35,2
2,35,35,35,35,35,35,35,35,35,2
2,35,35,35,35,35,35,35,35,35,2
2,35,35,35,35,36,35,35,35,35,4
2,35,35,35,35,35,35,35,35,35,4
2,35,35,35,35,35,35,35,35,35,5
2,35,35,35,35,35,35,35,35,35,6
2,35,35,35,35,36,35,35,35,35,4
2,35,35,35,35,35,35,35,35,35,4
2,35,35,35,35,35,35,35,35,35,2
2,35,35,35,35,35,35,35,35,35,2
2,35,35,35,35,35,35,35,35,35,2
2,2,2,2,2,2,2,2,2,2,2
endlayer

layer
1,1,1,1,1,1,1,1,1,1,1
1,2,2,2,2,2,2,2,2,2,1
1,2,2,2,2,2,2,2,2,2,1
1,2,2,3,2,2,2,3,2,2,1
1,2,2,2,2,2,2,2,2,2,4
1,2,2,2,2,3,2,2,2,2,4
1,2,2,2,2,2,2,2,2,2,2
1,2,2,3,2,2,2,3,2,2,2
1,2,2,2,2,2,2,2,2,2,2
1,2,2,2,2,3,2,2,2,2,4
1,2,2,2,2,2,2,2,2,2,4
1,2,2,3,2,2,2,3,2,2,5
1,2,2,2,2,2,2,2,2,2,6
1,2,2,2,2,3,2,2,2,2,4
1,2,2,2,2,2,2,2,2,2,4
1,2,2,3,2,2,2,3,2,2,1
1,2,2,2,2,2,2,2,2,2,1
1,2,2,2,2,2,2,2,2,2,1
1,1,1,1,1,1,1,1,1,1,1
endlayer

layer
2,2,2,2,2,2,2,2,2,2,2
2,7,7,7,7,7,7,7,7,7,2
2,7,7,7,7,7,7,7,7,7,2
2,7,7,8,7,7,7,8,7,7,2
2,7,7,7,7,7,7,7,7,7,4
2,7,7,7,7,7,7,7,7,7,4
2,7,7,7,7,7,7,7,7,7,9
2,7,7,8,7,7,7,8,7,7,9
2,7,7,7,7,7,7,7,7,7,9
2,7,7,7,7,7,7,7,7,7,4
2,7,7,7,7,7,7,7,7,9,4
2,7,7,8,7,7,7,8,7,9,5
2,7,7,7,7,7,7,7,7,9,6
2,7,7,7,7,7,7,7,7,9,4
2,7,7,7,7,7,7,7,7,7,4
2,7,7,8,7,7,7,8,7,7,2
2,7,7,7,7,7,7,7,7,7,2
2,7,7,7,7,7,7,7,7,7,2
2,2,2,2,2,2,2,2,2,2,2
endlayer

layer
10,10,10,10,10,10,10,10,10,10,10
10,0,0,0,0,0,0,0,0,0,10
10,0,0,0,0,0,0,0,0,0,10
10,0,0,0,0,0,0,0,0,0,10
10,0,0,0,0,0,0,0,0,0,4
10,0,0,0,0,0,0,0,0,0,4
10,0,0,0,0,0,0,0,0,0,0
10,0,0,0,0,0,0,0,0,0,0
10,0,0,0,0,0,0,0,0,0,0
10,0,0,0,0,0,0,0,0,0,4
10,0,0,0,0,0,0,0,0,0,4
10,0,0,0,0,0,0,0,0,0,5
10,0,0,0,0,0,0,0,0,0,6
10,0,0,0,0,0,0,0,0,0,4
10,0,0,0,0,0,0,0,0,0,4
10,0,0,0,0,0,0,0,0,0,10
10,0,0,0,0,0,0,0,0,0,10
10,0,0,0,0,0,0,0,0,0,10
10,10,10,10,10,10,10,10,10,10,10
endlayer

layer
10,10,10,10,10,10,10,10,10,10,10
10,0,0,0,0,0,0,0,0,0,10
10,0,0,0,0,0,0,0,0,0,10
10,0,0,0,0,0,0,0,0,0,10
10,0,0,0,0,0,0,0,0,0,4
10,0,0,0,0,0,0,0,0,0,4
10,0,0,0,0,0,0,0,0,0,0
10,0,0,0,0,0,0,0,0,0,0
10,0,0,0,0,0,0,0,0,0,0
10,0,0,0,0,0,0,0,0,0,4
10,0,0,0,0,0,0,0,0,0,4
10,0,0,0,0,0,0,0,0,0,5
10,0,0,0,0,0,0,0,0,0,6
10,0,0,0,0,0,0,0,0,0,4
10,0,0,0,0,0,0,0,0,0,4
10,0,0,0,0,0,0,0,0,0,10
10,0,0,0,0,0,0,0,0,0,10
10,0,0,0,0,0,0,0,0,0,10
10,10,10,10,10,10,10,10,10,10,10
endlayer

layer
10,10,10,10,10,10,10,10,10,10,10
10,0,0,0,0,0,0,0,0,0,10
10,0,0,0,0,0,0,0,0,0,10
10,0,0,0,0,0,0,0,0,0,10
10,0,0,0,0,0,0,0,0,0,4
10,0,0,0,0,0,0,0,0,0,4
10,0,0,0,0,0,0,0,0,0,0
10,0,0,0,0,0,0,0,0,0,0
10,0,0,0,0,0,0,0,0,0,0
10,0,0,0,0,0,0,0,0,0,4
10,0,0,0,0,0,0,0,0,0,4
10,0,0,0,0,0,0,0,0,0,5
10,0,0,0,0,0,0,0,0,0,6
10,0,0,0,0,0,0,0,0,0,4
10,0,0,0,0,0,0,0,0,0,4
10,0,0,0,0,0,0,0,0,0,10
10,0,0,0,0,0,0,0,0,0,10
10,0,0,0,0,0,0,0,0,0,10
10,10,10,10,10,10,10,10,10,10,10
endlayer

layer
34,34,34,34,34,34,34,34,34,34,34
34,0,0,0,0,0,0,0,0,0,34
34,0,0,0,0,0,0,0,0,0,34
34,0,0,0,0,0,0,0,0,0,34
34,0,0,0,0,0,0,0,0,0,4
34,0,0,0,0,0,0,0,0,0,4
34,0,0,0,0,0,0,0,0,0,0
34,0,0,0,0,0,0,0,0,0,0
34,0,0,0,0,0,0,0,0,0,0
34,0,0,0,0,0,0,0,0,0,4
34,0,0,0,0,0,0,0,0,0,4
34,0,0,0,0,0,0,0,0,0,5
34,0,0,0,0,0,0,0,0,0,6
34,0,0,0,0,0,0,0,0,0,4
34,0,0,0,0,0,0,0,0,0,4
34,0,0,0,0,0,0,0,0,0,34
34,0,0,0,0,0,0,0,0,0,34
34,0,0,0,0,0,0,0,0,0,34
34,34,34,34,34,34,34,34,34,34,34
endlayer

layer
10,10,10,10,10,10,10,10,10,10,10
10,0,0,0,0,0,0,0,0,0,10
10,0,0,0,0,0,0,0,0,0,10
10,0,0,0,0,0,0,0,0,0,10
10,0,0,0,0,0,0,0,0,0,4
10,0,0,0,0,0,0,0,0,0,4
10,0,0,0,0,0,0,0,0,0,2
10,0,0,0,0,0,0,0,0,0,2
10,0,0,0,0,0,0,0,0,0,2
10,0,0,0,0,0,0,0,0,0,4
10,0,0,0,0,0,0,0,0,0,4
10,0,0,0,0,0,0,0,0,0,5
10,0,0,0,0,0,0,0,0,0,6
10,0,0,0,0,0,0,0,0,0,4
10,0,0,0,0,0,0,0,0,0,4
10,0,0,0,0,0,0,0,0,0,10
10,0,0,0,0,0,0,0,0,0,10
10,0,0,0,0,0,0,0,0,0,10
10,10,10,10,10,10,10,10,10,10,10
endlayer

layer
2,2,2,2,2,2,2,2,2,2,2
2,35,35,35,35,35,35,35,35,35,2
2,35,35,35,35,35,35,35,35,35,2
2,35,35,35,35,35,35,35,35,35,2
2,35,35,35,35,35,35,35,35,35,4
2,35,35,35,35,36,35,35,35,35,4
2,35,35,35,35,35,35,35,35,35,2
2,35,35,35,35,35,35,35,35,35,2
2,35,35,35,35,35,35,35,35,35,2
2,35,35,35,35,36,35,35,35,35,4
2,35,35,35,35,35,35,35,35,35,4
2,35,35,35,35,35,35,35,35,35,5
2,35,35,35,35,35,35,35,35,35,6
2,35,35,35,35,36,35,35,35,35,4
2,35,35,35,35,35,35,35,35,35,4
2,35,35,35,35,35,35,35,35,35,2
2,35,35,35,35,35,35,35,35,35,2
2,35,35,35,35,35,35,35,35,35,2
2,2,2,2,2,2,2,2,2,2,2
endlayer

layer
1,1,1,1,1,1,1,1,1,1,1
1,2,2,2,2,2,2,2,2,2,1
1,2,2,2,2,2,2,2,2,2,1
1,2,2,2,2,2,2,2,2,2,1
1,2,2,2,2,2,2,2,2,2,4
1,2,2,2,2,3,2,2,2,2,4
1,2,2,2,2,2,2,2,2,2,2
1,2,2,2,2,2,2,2,2,2,2
1,2,2,2,2,2,2,2,2,2,2
1,2,2,2,2,3,2,2,2,2,4
1,2,2,2,2,2,2,2,2,2,4
1,2,2,2,2,2,2,2,2,2,5
1,2,2,2,2,2,2,2,2,2,6
1,2,2,2,2,3,2,2,2,2,4
1,2,2,2,2,2,2,2,2,2,4
1,2,2,2,2,2,2,2,2,2,1
1,2,2,2,2,2,2,2,2,2,1
1,2,2,2,2,2,2,2,2,2,1
1,1,1,1,1,1,1,1,1,1,1
endlayer

