# Gilly's Adobe houses

# template generated by Ruins mod version 14.6 Ingame Parser
# Structure created by Gilly

weight=1
embed_into_distance=4
acceptable_target_blocks=
unacceptable_target_blocks=flowing_water,water,flowing_lava,lava,ice,bedrock,netherrack,soul_sand,Natura:Cloud
dimensions=11,21,21
allowable_overhang=0
max_leveling=7
leveling_buffer=-1
preserve_water=0
preserve_lava=0

rule1=0,100,preserveBlock
rule2=0,100,double_stone_slab-9
rule3=0,100,sandstone-2
rule4=0,100,wooden_door-4
rule5=0,100,wooden_door-6
rule6=0,100,wooden_door-7
rule7=0,100,wooden_door-5
rule8=0,100,wooden_door-8
rule9=0,100,stone_slab-1
rule10=0,100,sandstone_stairs-0
rule11=0,100,stone_slab-9
rule12=0,100,sandstone_stairs-2
rule13=0,100,sandstone_stairs-3
rule14=0,100,wooden_slab-1
rule15=0,100,spruce_stairs-3
rule16=0,100,spruce_stairs-0
rule17=0,100,spruce_stairs-2
rule18=0,100,sandstone_stairs-1
rule19=0,100,spruce_stairs-1
rule20=0,100,hay_block-0
rule21=0,100,fence-0

layer
1,1,1,1,1,1,1,2,2,2,2,2,2,2,2,1,1,1,1,1,1
1,2,1,1,1,1,1,2,2,1,1,1,1,1,2,1,1,1,1,1,1
1,2,2,2,2,2,2,2,2,1,1,1,1,1,2,1,1,1,1,1,1
1,1,2,1,1,1,1,1,2,1,1,1,1,1,2,1,1,1,1,1,1
1,1,2,1,1,1,1,1,2,1,1,1,1,1,2,1,1,1,1,1,1
1,1,2,1,1,1,1,1,2,1,1,1,1,1,2,1,1,1,1,1,1
1,1,2,1,1,1,1,1,2,2,2,2,2,2,2,2,2,2,2,2,1
1,1,2,1,1,1,1,1,2,1,1,1,1,2,1,1,1,1,1,2,1
2,2,2,2,2,2,2,2,2,1,1,1,1,2,1,1,1,1,1,2,1
2,1,1,1,1,1,2,1,1,1,1,1,1,2,1,1,1,1,1,2,1
2,1,1,1,1,1,2,1,1,1,1,1,1,2,1,1,1,1,1,2,1
2,1,1,1,1,1,2,1,1,1,1,1,1,2,1,1,1,1,1,2,1
2,1,1,1,1,1,2,1,1,1,1,1,1,2,2,2,2,2,2,2,2
2,1,1,1,1,1,2,1,1,1,1,1,1,1,2,1,1,1,1,1,2
2,2,2,2,2,2,2,2,1,1,1,1,1,1,2,1,1,1,1,1,2
1,2,1,1,1,1,1,2,1,1,1,1,1,1,2,1,1,1,1,1,2
1,2,1,1,1,1,1,2,1,1,1,1,1,1,2,1,1,1,1,1,2
1,2,1,1,1,1,1,2,1,1,1,1,1,1,2,1,1,1,1,1,2
1,2,1,1,1,1,1,2,1,1,1,1,1,2,3,2,2,2,2,2,2
1,2,1,1,1,1,1,2,1,1,1,1,1,2,2,1,1,1,1,1,1
1,2,2,2,2,2,2,2,2,1,1,1,1,1,1,1,1,1,1,1,1
endlayer

layer
1,1,1,1,1,1,1,2,2,2,2,2,2,2,2,1,1,1,1,1,1
1,2,1,1,1,1,1,2,2,1,1,1,1,1,2,1,1,1,1,1,1
1,2,2,2,2,2,2,2,2,1,1,1,1,1,2,1,1,1,1,1,1
1,1,2,1,1,1,1,1,2,1,1,1,1,1,2,1,1,1,1,1,1
1,1,2,1,1,1,1,1,2,1,1,1,1,1,2,1,1,1,1,1,1
1,1,2,1,1,1,1,1,2,1,1,1,1,1,2,1,1,1,1,1,1
1,1,2,1,1,1,1,1,2,2,2,2,2,2,2,2,2,2,2,2,1
1,1,2,1,1,1,1,1,2,1,1,1,1,2,1,1,1,1,1,2,1
2,2,2,2,2,2,2,2,2,1,1,1,1,2,1,1,1,1,1,2,1
2,1,1,1,1,1,2,1,1,1,1,1,1,2,1,1,1,1,1,2,1
2,1,1,1,1,1,2,1,1,1,1,1,1,2,1,1,1,1,1,2,1
2,1,1,1,1,1,2,1,1,1,1,1,1,2,1,1,1,1,1,2,1
2,1,1,1,1,1,2,1,1,1,1,1,1,2,2,2,2,2,2,2,2
2,1,1,1,1,1,2,1,1,1,1,1,1,1,2,1,1,1,1,1,2
2,2,2,2,2,2,2,2,1,1,1,1,1,1,2,1,1,1,1,1,2
1,2,1,1,1,1,1,2,1,1,1,1,1,1,2,1,1,1,1,1,2
1,2,1,1,1,1,1,2,1,1,1,1,1,1,2,1,1,1,1,1,2
1,2,1,1,1,1,1,2,1,1,1,1,1,1,2,1,1,1,1,1,2
1,2,1,1,1,1,1,2,1,1,1,1,1,2,3,2,2,2,2,2,2
1,2,1,1,1,1,1,2,1,1,1,1,1,2,2,1,1,1,1,1,1
1,2,2,2,2,2,2,2,2,1,1,1,1,1,1,1,1,1,1,1,1
endlayer

layer
1,1,1,1,1,1,1,1,2,2,2,2,2,2,2,1,1,1,1,1,1
1,2,2,1,1,1,2,2,2,1,1,1,1,1,2,1,1,1,1,1,1
1,1,2,2,2,2,2,2,2,1,1,1,1,1,2,1,1,1,1,1,1
1,1,2,1,1,1,1,1,2,1,1,1,1,1,2,1,1,1,1,1,1
1,1,2,1,1,1,1,1,2,1,1,1,1,1,2,1,1,1,1,1,1
1,1,2,1,1,1,1,1,2,1,1,1,1,1,2,1,1,1,1,1,1
1,1,2,1,1,1,1,1,2,2,2,2,2,2,2,2,2,2,2,2,1
1,1,2,1,1,1,1,1,2,1,1,1,1,2,1,1,1,1,1,2,1
2,2,2,2,2,2,2,2,2,2,1,1,1,2,1,1,1,1,1,2,1
2,1,1,1,1,1,2,2,2,2,2,1,1,2,1,1,1,1,1,2,1
2,1,1,1,1,1,2,1,1,1,2,2,1,2,1,1,1,1,1,2,1
2,1,1,1,1,1,2,1,1,1,1,1,2,2,1,1,1,1,1,2,1
2,1,1,1,1,1,2,1,1,1,1,1,2,2,2,2,2,2,2,2,2
2,1,1,1,1,1,2,2,2,1,1,1,2,2,2,1,1,1,1,1,2
2,2,2,2,2,2,2,2,2,1,1,1,1,1,2,1,1,1,1,1,2
1,2,1,1,1,1,1,2,2,1,1,1,1,1,2,1,1,1,1,1,2
1,2,1,1,1,1,1,2,1,1,1,1,1,1,2,1,1,1,1,1,2
1,2,1,1,1,1,1,2,1,1,1,1,1,2,2,1,1,1,1,1,2
1,2,1,1,1,1,1,2,1,1,1,1,1,2,2,2,2,2,2,2,2
1,2,1,1,1,1,1,2,2,1,1,1,1,1,1,1,1,1,1,1,1
1,2,2,2,2,2,2,2,2,1,1,1,1,1,1,1,1,1,1,1,1
endlayer

layer
1,1,1,1,1,1,1,1,2,2,2,2,2,2,2,1,1,1,1,1,1
1,1,2,2,2,2,2,1,2,1,1,1,1,1,2,1,1,1,1,1,1
1,1,2,2,2,2,2,2,2,1,1,1,1,1,2,1,1,1,1,1,1
1,1,2,1,1,1,1,1,2,1,1,1,1,1,2,1,1,1,1,1,1
1,1,2,1,1,1,1,1,2,1,1,1,1,1,2,1,1,1,1,1,1
1,1,2,1,1,1,1,1,2,1,1,1,1,1,2,1,1,1,1,1,1
1,1,2,1,1,1,1,1,2,2,2,2,2,2,2,2,2,2,2,2,1
1,1,2,1,1,1,1,1,2,2,2,2,2,2,1,1,1,1,1,2,1
2,2,2,2,2,2,2,2,2,2,2,2,2,2,1,1,1,1,1,2,1
2,1,1,1,1,1,2,2,1,1,1,2,2,2,1,1,1,1,1,2,1
2,1,1,1,1,1,2,2,1,1,1,1,2,2,1,1,1,1,1,2,1
2,1,1,1,1,1,2,2,1,1,1,1,2,2,1,1,1,1,1,2,1
2,1,1,1,1,1,2,2,1,1,1,1,1,2,2,2,2,2,2,2,2
2,1,1,1,1,1,2,2,1,1,1,1,1,2,2,1,1,1,1,1,2
2,2,2,2,2,2,2,2,1,1,1,1,1,2,2,1,1,1,1,1,2
1,2,1,1,1,1,1,2,2,1,1,1,1,2,2,1,1,1,1,1,2
1,2,1,1,1,1,1,2,2,1,1,1,1,2,2,1,1,1,1,1,2
1,2,1,1,1,1,1,2,2,1,1,1,1,2,2,1,1,1,1,1,2
1,2,1,1,1,1,1,2,2,1,1,1,1,1,2,2,2,2,2,2,2
1,2,1,1,1,1,1,2,2,1,1,1,1,1,1,1,1,1,1,1,1
1,2,2,2,2,2,2,2,1,1,1,1,1,1,1,1,1,1,1,1,1
endlayer

layer
1,1,1,1,1,1,1,1,3,2,2,3,2,2,3,1,1,1,1,1,1
1,1,1,2,2,2,1,1,2,2,2,2,2,2,2,1,1,1,1,1,1
1,1,3,2,2,2,2,2,2,2,2,2,2,2,2,1,1,1,1,1,1
1,1,2,2,2,2,2,2,2,2,2,2,2,2,3,1,1,1,1,1,1
1,1,2,2,2,2,2,2,2,2,2,2,2,2,2,1,1,1,1,1,1
1,1,3,2,2,2,2,2,2,2,2,2,2,2,2,1,1,1,1,1,1
1,1,2,2,2,2,2,2,2,2,2,2,2,2,2,2,3,2,2,3,1
1,1,2,2,2,2,2,2,2,2,2,2,2,2,2,2,2,2,2,2,1
3,2,2,2,2,2,2,2,3,1,1,1,2,2,2,2,2,2,2,2,1
2,2,2,2,2,2,2,1,1,1,1,1,2,2,2,2,2,2,2,3,1
2,2,2,2,2,2,2,2,1,1,1,1,2,2,2,2,2,2,2,2,1
3,2,2,2,2,2,2,2,1,1,1,1,1,2,2,2,2,2,2,2,1
2,2,2,2,2,2,2,2,1,1,1,1,1,3,2,2,2,2,2,2,3
2,2,2,2,2,2,2,1,1,1,1,1,1,1,2,2,2,2,2,2,2
3,2,2,2,2,2,2,3,1,1,1,1,1,2,2,2,2,2,2,2,2
1,2,2,2,2,2,2,2,1,1,1,1,1,2,2,2,2,2,2,2,3
1,2,2,2,2,2,2,2,2,1,1,1,1,2,2,2,2,2,2,2,2
1,3,2,2,2,2,2,2,2,1,1,1,1,1,2,2,2,2,2,2,2
1,2,2,2,2,2,2,2,2,1,1,1,1,1,3,2,2,3,2,2,3
1,2,2,2,2,2,2,2,1,1,1,1,1,1,1,1,1,1,1,1,1
1,3,2,2,3,2,2,3,1,1,1,1,1,1,1,1,1,1,1,1,1
endlayer

layer
1,1,1,1,1,1,1,1,2,2,2,2,2,2,2,1,1,1,1,1,1
1,1,1,1,1,1,1,1,2,0,0,0,0,0,2,1,1,1,1,1,1
1,1,2,3,4,3,2,2,2,0,0,0,0,0,2,1,1,1,1,1,1
1,1,2,0,0,0,0,0,2,0,0,0,0,0,2,1,1,1,1,1,1
1,1,2,0,0,0,0,0,2,0,0,0,0,0,2,1,1,1,1,1,1
1,1,2,0,0,0,0,0,2,0,0,0,0,0,2,1,1,1,1,1,1
1,1,2,0,0,0,0,0,2,3,5,3,2,2,2,2,2,2,2,2,1
1,1,2,0,0,0,0,0,2,1,1,1,1,2,0,0,0,0,0,2,1
2,2,2,2,2,2,2,2,2,1,1,1,1,3,0,0,0,0,0,2,1
2,0,0,0,0,0,2,1,1,1,1,1,1,6,0,0,0,0,0,2,1
2,0,0,0,0,0,3,1,1,1,1,1,1,3,0,0,0,0,0,2,1
2,0,0,0,0,0,7,1,1,1,1,1,1,2,0,0,0,0,0,2,1
2,0,0,0,0,0,3,1,1,1,1,1,1,2,2,2,2,2,2,2,2
2,0,0,0,0,0,2,1,1,1,1,1,1,1,2,0,0,0,0,0,2
2,2,2,2,2,2,2,2,1,1,1,1,1,1,3,0,0,0,0,0,2
1,2,0,0,0,0,0,2,1,1,1,1,1,1,6,0,0,0,0,0,2
1,2,0,0,0,0,0,3,1,1,1,1,1,1,3,0,0,0,0,0,2
1,2,0,0,0,0,0,7,1,1,1,1,1,1,2,0,0,0,0,0,2
1,2,0,0,0,0,0,3,1,1,1,1,1,1,2,2,2,2,2,2,2
1,2,0,0,0,0,0,2,1,1,1,1,1,1,1,1,1,1,1,1,1
1,2,2,2,2,2,2,2,1,1,1,1,1,1,1,1,1,1,1,1,1
endlayer

layer
1,1,1,1,1,1,1,1,3,2,0,2,0,2,3,1,1,1,1,1,1
1,1,1,1,1,1,1,1,2,0,0,0,0,0,2,1,1,1,1,1,1
1,1,3,3,8,3,2,2,2,0,0,0,0,0,0,1,1,1,1,1,1
1,1,2,0,0,0,0,0,2,0,0,0,0,0,2,1,1,1,1,1,1
1,1,0,0,0,0,0,0,2,0,0,0,0,0,0,1,1,1,1,1,1
1,1,2,0,0,0,0,0,2,0,0,0,0,0,2,1,1,1,1,1,1
1,1,0,0,0,0,0,0,2,3,8,3,2,2,2,2,2,0,2,3,1
1,1,2,0,0,0,0,0,2,1,1,1,1,2,0,0,0,0,0,2,1
3,2,2,2,2,2,2,2,3,1,1,1,1,3,0,0,0,0,0,0,1
2,0,0,0,0,0,2,1,1,1,1,1,1,8,0,0,0,0,0,2,1
0,0,0,0,0,0,3,1,1,1,1,1,1,3,0,0,0,0,0,0,1
2,0,0,0,0,0,8,1,1,1,1,1,1,2,0,0,0,0,0,2,1
0,0,0,0,0,0,3,1,1,1,1,1,1,3,2,2,2,2,2,2,3
2,0,0,0,0,0,2,1,1,1,1,1,1,1,2,0,0,0,0,0,2
3,2,2,2,2,2,2,3,1,1,1,1,1,1,3,0,0,0,0,0,0
1,2,0,0,0,0,0,2,1,1,1,1,1,1,8,0,0,0,0,0,2
1,0,0,0,0,0,0,3,1,1,1,1,1,1,3,0,0,0,0,0,0
1,2,0,0,0,0,0,8,1,1,1,1,1,1,2,0,0,0,0,0,2
1,0,0,0,0,0,0,3,1,1,1,1,1,1,3,2,0,2,0,2,3
1,2,0,0,0,0,0,2,1,1,1,1,1,1,1,1,1,1,1,1,1
1,3,2,0,2,0,2,3,1,1,1,1,1,1,1,1,1,1,1,1,1
endlayer

layer
1,1,1,1,1,1,1,1,2,2,2,2,2,2,2,1,1,1,1,1,1
1,1,1,1,1,1,1,1,2,0,0,0,0,0,2,1,1,1,1,1,1
1,1,2,2,3,2,2,2,2,0,0,0,0,0,2,1,1,1,1,1,1
1,1,2,0,0,0,0,0,2,0,0,0,0,0,2,1,1,1,1,1,1
1,1,2,0,0,0,0,0,2,0,0,0,0,0,2,1,1,1,1,1,1
1,1,2,0,0,0,0,0,2,0,0,0,0,0,2,1,1,1,1,1,1
1,1,2,0,0,0,0,0,2,2,3,2,2,2,2,2,2,2,2,2,1
1,1,2,0,0,0,0,0,2,1,1,1,1,2,0,0,0,0,0,2,1
2,2,2,2,2,2,2,2,2,1,1,1,1,2,0,0,0,0,0,2,1
2,0,0,0,0,0,2,1,1,1,1,1,1,3,0,0,0,0,0,2,1
2,0,0,0,0,0,2,1,1,1,1,1,1,2,0,0,0,0,0,2,1
2,0,0,0,0,0,3,1,1,1,1,1,1,2,0,0,0,0,0,2,1
2,0,0,0,0,0,2,1,1,1,1,1,1,2,2,2,2,2,2,2,2
2,0,0,0,0,0,2,1,1,1,1,1,1,1,2,0,0,0,0,0,2
2,2,2,2,2,2,2,2,1,1,1,1,1,1,2,0,0,0,0,0,2
1,2,0,0,0,0,0,2,1,1,1,1,1,1,3,0,0,0,0,0,2
1,2,0,0,0,0,0,2,1,1,1,1,1,1,2,0,0,0,0,0,2
1,2,0,0,0,0,0,3,1,1,1,1,1,1,2,0,0,0,0,0,2
1,2,0,0,0,0,0,2,1,1,1,1,1,1,2,2,2,2,2,2,2
1,2,0,0,0,0,0,2,1,1,1,1,1,1,1,1,1,1,1,1,1
1,2,2,2,2,2,2,2,1,1,1,1,1,1,1,1,1,1,1,1,1
endlayer

layer
1,1,1,1,1,1,1,1,3,2,2,3,2,2,3,1,1,1,1,1,1
1,1,1,1,1,1,1,1,2,0,0,0,0,0,2,1,1,1,1,1,1
1,1,3,2,2,2,3,2,2,0,0,0,0,0,2,1,1,1,1,1,1
1,1,2,0,0,0,0,0,2,0,0,0,0,0,3,1,1,1,1,1,1
1,1,2,0,0,0,0,0,2,0,0,0,0,0,2,1,1,1,1,1,1
1,1,3,0,0,0,0,0,2,0,0,0,0,0,2,1,1,1,1,1,1
1,1,2,0,0,0,0,0,2,2,2,2,2,2,2,2,3,2,2,3,1
1,1,2,0,0,0,0,0,2,1,1,1,1,2,0,0,0,0,0,2,1
3,2,2,2,2,2,2,2,3,1,1,1,1,2,0,0,0,0,0,2,1
2,0,0,0,0,0,2,1,1,1,1,1,1,2,0,0,0,0,0,3,1
2,0,0,0,0,0,2,1,1,1,1,1,1,2,0,0,0,0,0,2,1
3,0,0,0,0,0,2,1,1,1,1,1,1,2,0,0,0,0,0,2,1
2,0,0,0,0,0,2,1,1,1,1,1,1,3,2,2,2,2,2,2,3
2,0,0,0,0,0,2,1,1,1,1,1,1,1,2,0,0,0,0,0,2
3,2,2,2,2,2,2,3,1,1,1,1,1,1,2,0,0,0,0,0,2
1,2,0,0,0,0,0,2,1,1,1,1,1,1,2,0,0,0,0,0,3
1,2,0,0,0,0,0,2,1,1,1,1,1,1,2,0,0,0,0,0,2
1,3,0,0,0,0,0,2,1,1,1,1,1,1,2,0,0,0,0,0,2
1,2,0,0,0,0,0,2,1,1,1,1,1,1,3,2,2,3,2,2,3
1,2,0,0,0,0,0,2,1,1,1,1,1,1,1,1,1,1,1,1,1
1,3,2,2,3,2,2,3,1,1,1,1,1,1,1,1,1,1,1,1,1
endlayer

layer
1,1,1,1,1,1,1,1,9,3,10,10,10,3,9,1,1,1,1,1,1
1,1,1,1,1,1,1,1,3,11,11,0,11,11,3,1,1,1,1,1,1
1,1,9,10,10,10,10,10,13,11,0,0,0,11,12,1,1,1,1,1,1
1,1,13,14,14,14,14,14,2,0,0,0,0,0,12,1,1,1,1,1,1
1,1,13,14,14,14,14,14,2,11,0,0,0,11,12,1,1,1,1,1,1
1,1,13,14,14,0,14,14,3,11,11,0,11,11,3,1,1,1,1,1,1
1,1,13,14,14,14,14,14,18,3,18,18,18,3,17,16,16,16,15,9,1
1,1,13,14,14,14,14,14,12,1,1,1,1,19,20,20,20,20,20,19,1
9,3,2,2,2,3,18,18,9,1,1,1,1,15,20,20,20,20,20,17,1
3,11,11,0,11,11,3,1,1,1,1,1,1,15,20,20,21,20,20,17,1
13,11,0,0,0,11,12,1,1,1,1,1,1,15,20,20,20,20,20,17,1
13,0,0,0,0,0,12,1,1,1,1,1,1,16,20,20,20,20,20,16,1
13,11,0,0,0,11,12,1,1,1,1,1,1,9,19,3,2,2,2,3,9
3,11,11,0,11,11,3,1,1,1,1,1,1,1,3,11,11,0,11,11,3
9,3,2,2,2,3,10,9,1,1,1,1,1,1,13,11,0,0,0,11,12
1,13,2,2,2,2,2,12,1,1,1,1,1,1,13,0,0,0,0,0,12
1,13,2,20,20,20,2,12,1,1,1,1,1,1,13,11,0,0,0,11,12
1,13,2,20,21,20,2,12,1,1,1,1,1,1,3,11,11,0,11,11,3
1,13,2,20,20,20,2,12,1,1,1,1,1,1,9,3,18,18,18,3,9
1,13,2,2,2,2,2,12,1,1,1,1,1,1,1,1,1,1,1,1,1
1,9,18,18,18,18,18,9,1,1,1,1,1,1,1,1,1,1,1,1,1
endlayer

layer
1,1,1,1,1,1,1,1,1,1,1,1,1,1,1,1,1,1,1,1,1
1,1,1,1,1,1,1,1,1,9,9,9,9,9,1,1,1,1,1,1,1
1,1,1,1,1,1,1,1,1,9,9,9,9,9,1,1,1,1,1,1,1
1,1,1,1,1,1,1,1,1,9,9,0,9,9,1,1,1,1,1,1,1
1,1,1,1,1,1,1,1,1,9,9,9,9,9,1,1,1,1,1,1,1
1,1,1,1,1,1,1,1,1,9,9,9,9,9,1,1,1,1,1,1,1
1,1,1,1,1,1,1,1,1,1,1,1,1,1,1,1,1,1,1,1,1
1,1,1,1,1,1,1,1,1,1,1,1,1,1,1,1,1,1,1,1,1
1,9,1,1,1,9,1,1,1,1,1,1,1,1,1,1,1,1,1,1,1
9,9,9,9,9,9,9,1,1,1,1,1,1,1,1,1,1,1,1,1,1
1,9,9,9,9,9,1,1,1,1,1,1,1,1,1,1,1,1,1,1,1
1,9,9,0,9,9,1,1,1,1,1,1,1,1,1,1,1,1,1,1,1
1,9,9,9,9,9,1,1,1,1,1,1,1,1,1,1,1,1,1,1,1
9,9,9,9,9,9,9,1,1,1,1,1,1,1,1,9,9,9,9,9,1
1,9,1,1,1,9,1,1,1,1,1,1,1,1,1,9,9,9,9,9,1
1,1,1,1,1,1,1,1,1,1,1,1,1,1,1,9,9,0,9,9,1
1,1,1,1,1,1,1,1,1,1,1,1,1,1,1,9,9,9,9,9,1
1,1,1,1,1,1,1,1,1,1,1,1,1,1,1,9,9,9,9,9,1
1,1,1,1,1,1,1,1,1,1,1,1,1,1,1,1,1,1,1,1,1
1,1,1,1,1,1,1,1,1,1,1,1,1,1,1,1,1,1,1,1,1
1,1,1,1,1,1,1,1,1,1,1,1,1,1,1,1,1,1,1,1,1
endlayer

