# Gilly's underground lab, main floor

# template generated by Ruins mod version 14.6 Ingame Parser
# Structure created by Gilly

weight=1
embed_into_distance=15
acceptable_target_blocks=
unacceptable_target_blocks=flowing_water,water,flowing_lava,lava,ice,bedrock,netherrack,soul_sand,Natura:Cloud
dimensions=9,53,41
allowable_overhang=0
max_leveling=3
leveling_buffer=-1
preserve_water=0
preserve_lava=0
preventRotation=1

rule1=0,100,preserveBlock
rule2=0,100,stonebrick-0
rule3=0,100,glowstone-0
rule4=0,100,cauldron-0
rule5=0,100,stained_hardened_clay-9
rule6=0,100,iron_bars-0
rule7=0,100,stained_glass_pane-3
rule8=0,100,stone_brick_stairs-2
rule9=0,100,stone_brick_stairs-0
rule10=0,100,stone_brick_stairs-3
rule11=0,100,stone_brick_stairs-1
rule12=0,100,stained_hardened_clay-3
rule13=0,100,stone_slab-8
rule14=0,100,stone_brick_stairs-6
rule15=0,100,stone_brick_stairs-4
rule16=0,100,stone_brick_stairs-7
rule17=0,100,stone_brick_stairs-5

layer
1,1,1,1,1,1,1,1,1,1,1,1,2,2,2,2,2,2,2,2,2,2,2,2,2,2,2,2,2,2,2,2,2,1,1,1,1,1,1,1,1
1,1,1,1,1,1,1,1,1,1,1,1,2,0,0,0,0,0,0,0,0,0,0,0,0,0,0,0,0,0,0,0,2,1,1,1,1,1,1,1,1
1,1,1,1,1,1,1,1,1,1,1,1,2,0,3,0,0,0,3,0,0,0,3,0,0,0,3,0,0,0,3,0,2,1,1,1,1,1,1,1,1
1,1,1,1,1,1,1,1,1,1,1,1,2,0,0,0,0,0,0,0,0,0,0,0,0,0,0,0,0,0,0,0,2,1,1,1,1,1,1,1,1
1,1,1,1,1,1,1,1,1,1,1,1,2,0,0,0,1,1,1,1,1,1,1,1,1,1,1,1,1,0,0,0,2,1,1,1,1,1,1,1,1
1,1,1,1,1,1,1,1,1,1,1,1,2,0,0,0,1,1,1,1,1,1,1,1,1,1,1,1,1,0,0,0,2,1,1,1,1,1,1,1,1
1,1,1,1,1,1,1,1,1,1,1,1,2,0,3,0,1,1,1,1,1,1,1,1,1,1,1,1,1,0,3,0,2,1,1,1,1,1,1,1,1
1,1,1,1,1,1,1,1,1,1,1,1,2,0,0,0,1,1,1,1,1,1,1,1,1,1,1,1,1,0,0,0,2,1,1,1,1,1,1,1,1
1,1,1,1,1,1,1,1,1,1,1,1,2,0,0,0,1,1,1,1,1,1,1,1,1,1,1,1,1,0,0,0,2,1,1,1,1,1,1,1,1
1,1,1,1,1,1,1,1,1,1,1,1,2,0,0,0,1,1,1,1,1,1,1,1,1,1,1,1,1,0,0,0,2,1,1,1,1,1,1,1,1
1,1,1,1,1,1,1,1,1,1,1,1,2,0,3,0,1,1,1,1,1,1,1,1,1,1,1,1,1,0,3,0,2,1,1,1,1,1,1,1,1
1,1,1,1,1,1,1,1,1,1,1,1,2,0,0,0,1,1,1,1,1,1,1,1,1,1,1,1,1,0,0,0,2,1,1,1,1,1,1,1,1
1,1,1,1,2,4,2,2,2,2,2,4,2,0,0,0,1,1,1,1,1,1,1,1,1,1,1,1,1,0,2,2,2,2,4,2,2,2,2,4,2
1,1,1,1,4,3,0,0,0,0,0,3,4,0,0,0,1,1,1,1,1,1,1,1,1,1,1,1,1,0,0,0,0,0,3,0,0,0,0,3,4
1,1,1,1,2,0,3,0,0,0,3,0,2,0,3,0,1,1,1,1,1,1,1,1,1,1,1,1,1,0,3,0,0,0,3,0,0,0,3,0,2
1,1,1,1,2,0,0,0,0,0,0,0,2,0,0,0,1,1,1,1,1,1,1,1,1,1,1,1,1,0,0,0,0,0,0,0,0,0,0,0,2
1,1,1,1,2,0,0,0,0,0,0,0,2,2,2,2,1,1,1,1,1,1,1,1,1,1,1,1,1,0,0,0,0,0,0,0,0,0,0,0,2
1,1,1,1,2,0,0,0,0,0,0,0,2,0,0,0,0,0,0,0,0,0,0,0,0,0,0,0,2,0,0,0,0,0,0,0,0,0,0,0,2
1,1,1,1,2,0,3,0,0,0,3,0,2,0,3,0,0,0,3,0,0,0,3,0,0,0,3,0,2,0,3,0,0,0,3,0,0,0,3,3,4
1,1,1,1,4,3,0,0,0,0,0,3,2,0,0,0,0,0,0,0,0,0,0,0,0,0,0,0,2,0,0,0,0,0,0,0,0,0,0,0,2
2,4,2,2,2,2,4,2,2,2,2,4,2,0,0,0,0,0,0,0,0,0,0,0,0,0,0,0,2,0,0,0,0,0,0,0,0,0,0,0,2
4,3,0,0,0,0,3,0,0,0,0,3,2,0,0,0,0,0,0,0,0,0,0,0,0,0,0,0,2,0,0,0,0,0,0,0,0,0,0,0,2
2,0,3,0,0,0,3,0,0,0,3,0,4,3,3,0,0,0,3,0,0,0,3,0,0,0,3,3,4,0,3,0,0,0,3,0,0,0,3,0,2
2,0,0,0,0,0,0,0,0,0,0,0,2,0,0,0,0,0,0,0,0,0,0,0,0,0,0,0,2,0,0,0,0,0,3,0,0,0,0,3,4
2,0,0,0,0,0,0,0,0,0,0,0,2,0,0,0,0,0,0,0,0,0,0,0,0,0,0,0,2,4,2,2,2,2,2,4,2,2,2,4,2
2,0,0,0,0,0,0,0,0,0,0,0,2,0,0,0,0,0,0,0,0,0,0,0,0,0,0,0,2,3,0,0,0,0,0,3,4,1,1,1,1
4,3,3,0,0,0,3,0,0,0,3,3,4,3,3,0,0,0,3,0,0,0,3,0,0,0,3,3,4,0,3,0,0,0,3,0,2,1,1,1,1
2,0,0,0,0,0,0,0,0,0,0,0,2,0,0,0,0,0,0,0,0,0,0,0,0,0,0,0,2,0,0,0,0,0,0,0,2,1,1,1,1
2,0,0,0,0,0,0,0,0,0,0,0,2,0,0,0,0,0,0,0,0,0,0,0,0,0,0,0,2,0,0,0,0,0,0,0,2,1,1,1,1
2,0,0,0,0,0,0,0,0,0,0,0,2,0,0,0,0,0,0,0,0,0,0,0,0,0,0,0,2,0,0,0,0,0,0,0,2,1,1,1,1
2,0,3,0,0,0,3,0,0,0,3,0,2,0,3,0,0,0,3,0,0,0,3,0,0,0,3,0,2,0,3,0,0,0,3,0,2,1,1,1,1
4,3,0,0,0,0,0,0,0,0,0,0,2,0,0,0,0,0,0,0,0,0,0,0,0,0,0,3,4,0,0,0,0,0,0,3,4,1,1,1,1
2,4,2,2,1,1,1,1,1,1,1,1,1,1,1,1,1,1,1,1,1,2,2,2,2,2,4,2,2,2,2,2,2,2,2,4,2,1,1,1,1
2,0,0,0,1,1,1,1,1,1,1,1,1,1,1,1,1,1,1,1,1,0,0,0,0,0,3,0,0,0,0,3,4,1,1,1,1,1,1,1,1
2,0,3,0,1,1,1,1,1,1,1,1,1,1,1,1,1,1,1,1,1,0,3,0,0,0,3,0,0,0,3,0,2,1,1,1,1,1,1,1,1
2,0,0,0,1,1,1,1,1,1,1,1,1,1,1,1,1,1,1,1,1,0,0,0,0,0,0,0,0,0,0,0,2,1,1,1,1,1,1,1,1
2,0,0,0,1,1,1,1,1,1,1,1,1,1,1,1,1,1,1,1,1,0,0,0,0,0,0,0,0,0,0,0,2,1,1,1,1,1,1,1,1
2,0,0,0,1,1,1,1,1,1,1,1,1,1,1,1,1,1,1,1,1,0,0,0,0,0,0,0,0,0,0,0,2,1,1,1,1,1,1,1,1
2,0,3,0,1,1,1,1,1,1,1,1,1,1,1,1,1,1,1,1,1,0,3,0,0,0,3,0,0,0,3,3,4,1,1,1,1,1,1,1,1
2,0,0,0,1,1,1,1,1,1,1,1,1,1,1,1,1,1,1,1,1,0,0,0,0,0,0,0,0,0,0,0,2,1,1,1,1,1,1,1,1
2,0,0,0,1,1,1,1,1,1,1,1,1,1,1,1,1,1,1,1,1,0,0,0,0,0,0,0,0,0,0,0,2,1,1,1,1,1,1,1,1
2,0,0,0,1,1,1,1,1,1,1,1,1,1,1,1,1,1,1,1,1,0,0,0,0,0,0,0,0,0,0,0,2,1,1,1,1,1,1,1,1
2,0,3,0,1,1,1,1,1,1,1,1,1,1,1,1,1,1,1,1,1,0,3,0,0,0,3,0,0,0,3,0,2,1,1,1,1,1,1,1,1
2,0,0,0,1,1,1,1,1,1,1,1,1,1,1,1,1,1,1,1,1,0,0,0,0,0,3,0,0,0,0,3,4,1,1,1,1,1,1,1,1
2,0,0,0,1,1,1,1,1,1,1,1,1,1,1,1,1,1,1,1,1,0,2,2,2,2,4,2,2,2,2,4,2,1,1,1,1,1,1,1,1
2,0,0,0,1,1,1,1,1,1,1,1,1,1,1,1,1,1,1,1,1,0,0,0,2,1,1,1,1,1,1,1,1,1,1,1,1,1,1,1,1
2,0,3,0,1,1,1,1,1,1,1,1,1,1,1,1,1,1,1,1,1,0,3,0,2,1,1,1,1,1,1,1,1,1,1,1,1,1,1,1,1
2,0,0,0,1,1,1,1,1,1,1,1,1,1,1,1,1,1,1,1,1,0,0,0,2,1,1,1,1,1,1,1,1,1,1,1,1,1,1,1,1
2,0,0,0,1,1,1,1,1,1,1,1,1,1,1,1,1,1,1,1,1,0,0,0,2,1,1,1,1,1,1,1,1,1,1,1,1,1,1,1,1
2,0,0,0,0,0,0,0,0,0,0,0,0,0,0,0,0,0,0,0,0,0,0,0,2,1,1,1,1,1,1,1,1,1,1,1,1,1,1,1,1
2,0,3,0,0,0,3,0,0,0,3,0,0,0,3,0,0,0,3,0,0,0,3,0,2,1,1,1,1,1,1,1,1,1,1,1,1,1,1,1,1
2,0,0,0,0,0,0,0,0,0,0,0,0,0,0,0,0,0,0,0,0,0,0,0,2,1,1,1,1,1,1,1,1,1,1,1,1,1,1,1,1
2,2,2,2,2,2,2,2,2,2,2,2,2,2,2,2,2,2,2,2,2,2,2,2,2,1,1,1,1,1,1,1,1,1,1,1,1,1,1,1,1
endlayer

layer
1,1,1,1,1,1,1,1,1,1,1,1,5,5,5,5,5,5,5,5,5,5,5,5,5,5,5,5,5,5,5,5,5,1,1,1,1,1,1,1,1
1,1,1,1,1,1,1,1,1,1,1,1,5,5,5,5,5,5,5,5,5,5,5,5,5,5,5,5,5,5,5,5,5,1,1,1,1,1,1,1,1
1,1,1,1,1,1,1,1,1,1,1,1,5,5,6,5,5,5,6,5,5,5,6,5,5,5,6,5,5,5,6,5,5,1,1,1,1,1,1,1,1
1,1,1,1,1,1,1,1,1,1,1,1,5,5,5,5,5,5,5,5,5,5,5,5,5,5,5,5,5,5,5,5,5,1,1,1,1,1,1,1,1
1,1,1,1,1,1,1,1,1,1,1,1,5,5,5,5,1,1,1,1,1,1,1,1,1,1,1,1,1,5,5,5,5,1,1,1,1,1,1,1,1
1,1,1,1,1,1,1,1,1,1,1,1,5,5,5,5,1,1,1,1,1,1,1,1,1,1,1,1,1,5,5,5,5,1,1,1,1,1,1,1,1
1,1,1,1,1,1,1,1,1,1,1,1,5,5,6,5,1,1,1,1,1,1,1,1,1,1,1,1,1,5,6,5,5,1,1,1,1,1,1,1,1
1,1,1,1,1,1,1,1,1,1,1,1,5,5,5,5,1,1,1,1,1,1,1,1,1,1,1,1,1,5,5,5,5,1,1,1,1,1,1,1,1
1,1,1,1,1,1,1,1,1,1,1,1,5,5,5,5,1,1,1,1,1,1,1,1,1,1,1,1,1,5,5,5,5,1,1,1,1,1,1,1,1
1,1,1,1,1,1,1,1,1,1,1,1,5,5,5,5,1,1,1,1,1,1,1,1,1,1,1,1,1,5,5,5,5,1,1,1,1,1,1,1,1
1,1,1,1,1,1,1,1,1,1,1,1,5,5,6,5,1,1,1,1,1,1,1,1,1,1,1,1,1,5,6,5,5,1,1,1,1,1,1,1,1
1,1,1,1,1,1,1,1,1,1,1,1,5,5,5,5,1,1,1,1,1,1,1,1,1,1,1,1,1,5,5,5,5,1,1,1,1,1,1,1,1
1,1,1,1,7,7,7,7,7,7,7,7,7,5,5,5,1,1,1,1,1,1,1,1,1,1,1,1,1,5,5,5,7,7,7,7,7,7,7,7,7
1,1,1,1,7,9,9,9,9,9,9,9,7,5,5,5,1,1,1,1,1,1,1,1,1,1,1,1,1,5,5,5,9,9,9,9,9,9,9,8,7
1,1,1,1,7,10,6,5,5,5,6,8,7,5,6,5,1,1,1,1,1,1,1,1,1,1,1,1,1,5,6,5,5,5,6,5,5,5,6,8,7
1,1,1,1,7,10,5,5,5,5,5,8,7,5,5,5,1,1,1,1,1,1,1,1,1,1,1,1,1,5,5,5,5,5,5,5,5,5,5,8,7
1,1,1,1,7,10,5,5,5,5,5,8,7,5,5,5,1,1,1,1,1,1,1,1,1,1,1,1,1,5,5,5,5,5,5,5,5,5,5,8,7
1,1,1,1,7,10,5,5,5,5,5,5,5,5,5,5,5,5,5,5,5,5,5,5,5,5,5,5,5,5,5,5,5,5,5,5,5,5,5,8,7
1,1,1,1,7,10,6,5,5,5,6,5,5,5,6,5,5,5,6,5,5,5,6,5,5,5,6,5,5,5,6,5,5,5,6,5,5,5,6,8,7
1,1,1,1,7,10,11,11,11,11,11,11,11,10,5,5,5,5,5,5,5,5,5,5,5,5,5,8,11,10,5,5,5,5,5,5,5,5,5,8,7
7,7,7,7,7,7,7,7,7,7,7,7,7,10,5,5,5,5,5,5,5,5,5,5,5,5,5,8,7,10,5,5,5,5,5,5,5,5,5,8,7
7,9,9,9,9,9,9,9,9,9,9,8,7,10,5,5,5,5,5,5,5,5,5,5,5,5,5,8,7,10,5,5,5,5,5,5,5,5,5,8,7
7,10,6,5,5,5,6,5,5,5,6,8,7,10,6,5,5,5,6,5,5,5,6,5,5,5,6,8,7,10,6,5,5,5,6,5,5,5,6,8,7
7,10,5,5,5,5,5,5,5,5,5,8,7,10,5,5,5,5,5,5,5,5,5,5,5,5,5,8,7,10,11,11,5,11,11,11,11,11,11,8,7
7,10,5,5,5,5,5,5,5,5,5,8,7,10,5,5,5,5,5,5,5,5,5,5,5,5,5,8,7,7,7,10,5,8,7,7,7,7,7,7,7
7,10,5,5,5,5,5,5,5,5,5,8,7,10,5,5,5,5,5,5,5,5,5,5,5,5,5,8,7,9,9,9,5,9,9,9,7,1,1,1,1
7,10,6,5,5,5,6,5,5,5,6,8,7,10,6,5,5,5,6,5,5,5,6,5,5,5,6,8,7,10,6,5,5,5,6,8,7,1,1,1,1
7,10,5,5,5,5,5,5,5,5,5,8,7,10,5,5,5,5,5,5,5,5,5,5,5,5,5,8,7,10,5,5,5,5,5,8,7,1,1,1,1
7,10,5,5,5,5,5,5,5,5,5,9,9,9,5,5,5,5,5,5,5,5,5,5,5,5,5,8,7,10,5,5,5,5,5,8,7,1,1,1,1
7,10,5,5,5,5,5,5,5,5,5,5,5,5,5,5,5,5,5,5,5,5,5,5,5,5,5,8,7,10,5,5,5,5,5,8,7,1,1,1,1
7,10,6,5,5,5,6,5,5,5,6,5,5,5,6,5,5,5,6,5,5,5,6,5,5,5,6,8,7,10,6,5,5,5,6,8,7,1,1,1,1
7,10,5,5,5,5,5,5,5,5,5,5,5,5,5,5,5,5,5,5,5,5,5,5,11,11,11,8,7,10,5,11,11,11,11,8,7,1,1,1,1
7,5,5,5,1,1,1,1,1,1,1,1,1,1,1,1,1,1,1,1,1,5,5,5,8,7,7,7,7,10,5,8,7,7,7,7,7,1,1,1,1
5,5,5,5,1,1,1,1,1,1,1,1,1,1,1,1,1,1,1,1,1,5,5,5,8,9,9,9,9,9,5,8,7,1,1,1,1,1,1,1,1
5,5,6,5,1,1,1,1,1,1,1,1,1,1,1,1,1,1,1,1,1,5,6,5,5,5,6,5,5,5,6,8,7,1,1,1,1,1,1,1,1
5,5,5,5,1,1,1,1,1,1,1,1,1,1,1,1,1,1,1,1,1,5,5,5,5,5,5,5,5,5,5,8,7,1,1,1,1,1,1,1,1
5,5,5,5,1,1,1,1,1,1,1,1,1,1,1,1,1,1,1,1,1,5,5,5,5,5,5,5,5,5,5,8,7,1,1,1,1,1,1,1,1
5,5,5,5,1,1,1,1,1,1,1,1,1,1,1,1,1,1,1,1,1,5,5,5,5,5,5,5,5,5,5,8,7,1,1,1,1,1,1,1,1
5,5,6,5,1,1,1,1,1,1,1,1,1,1,1,1,1,1,1,1,1,5,6,5,5,5,6,5,5,5,6,8,7,1,1,1,1,1,1,1,1
5,5,5,5,1,1,1,1,1,1,1,1,1,1,1,1,1,1,1,1,1,5,5,5,5,5,5,5,5,5,5,8,7,1,1,1,1,1,1,1,1
5,5,5,5,1,1,1,1,1,1,1,1,1,1,1,1,1,1,1,1,1,5,5,5,5,5,5,5,5,5,5,8,7,1,1,1,1,1,1,1,1
5,5,5,5,1,1,1,1,1,1,1,1,1,1,1,1,1,1,1,1,1,5,5,5,5,5,5,5,5,5,5,8,7,1,1,1,1,1,1,1,1
5,5,6,5,1,1,1,1,1,1,1,1,1,1,1,1,1,1,1,1,1,5,6,5,5,5,6,5,5,5,6,8,7,1,1,1,1,1,1,1,1
5,5,5,5,1,1,1,1,1,1,1,1,1,1,1,1,1,1,1,1,1,5,5,5,11,11,11,11,11,11,11,8,7,1,1,1,1,1,1,1,1
5,5,5,5,1,1,1,1,1,1,1,1,1,1,1,1,1,1,1,1,1,5,5,5,7,7,7,7,7,7,7,7,7,1,1,1,1,1,1,1,1
5,5,5,5,1,1,1,1,1,1,1,1,1,1,1,1,1,1,1,1,1,5,5,5,5,1,1,1,1,1,1,1,1,1,1,1,1,1,1,1,1
5,5,6,5,1,1,1,1,1,1,1,1,1,1,1,1,1,1,1,1,1,5,6,5,5,1,1,1,1,1,1,1,1,1,1,1,1,1,1,1,1
5,5,5,5,1,1,1,1,1,1,1,1,1,1,1,1,1,1,1,1,1,5,5,5,5,1,1,1,1,1,1,1,1,1,1,1,1,1,1,1,1
5,5,5,5,1,1,1,1,1,1,1,1,1,1,1,1,1,1,1,1,1,5,5,5,5,1,1,1,1,1,1,1,1,1,1,1,1,1,1,1,1
5,5,5,5,5,5,5,5,5,5,5,5,5,5,5,5,5,5,5,5,5,5,5,5,5,1,1,1,1,1,1,1,1,1,1,1,1,1,1,1,1
5,5,6,5,5,5,6,5,5,5,6,5,5,5,6,5,5,5,6,5,5,5,6,5,5,1,1,1,1,1,1,1,1,1,1,1,1,1,1,1,1
5,5,5,5,5,5,5,5,5,5,5,5,5,5,5,5,5,5,5,5,5,5,5,5,5,1,1,1,1,1,1,1,1,1,1,1,1,1,1,1,1
5,5,5,5,5,5,5,5,5,5,5,5,5,5,5,5,5,5,5,5,5,5,5,5,5,1,1,1,1,1,1,1,1,1,1,1,1,1,1,1,1
endlayer

layer
1,1,1,1,1,1,1,1,1,1,1,1,2,2,2,2,2,2,2,2,2,2,2,2,2,2,2,2,2,2,2,2,2,1,1,1,1,1,1,1,1
1,1,1,1,1,1,1,1,1,1,1,1,2,0,0,0,0,0,0,0,0,0,0,0,0,0,0,0,0,0,0,0,2,1,1,1,1,1,1,1,1
1,1,1,1,1,1,1,1,1,1,1,1,2,0,0,0,0,0,0,0,0,0,0,0,0,0,0,0,0,0,0,0,2,1,1,1,1,1,1,1,1
1,1,1,1,1,1,1,1,1,1,1,1,2,0,0,0,0,0,0,0,0,0,0,0,0,0,0,0,0,0,0,0,2,1,1,1,1,1,1,1,1
1,1,1,1,1,1,1,1,1,1,1,1,2,0,0,0,1,1,1,1,1,1,1,1,1,1,1,1,1,0,0,0,2,1,1,1,1,1,1,1,1
1,1,1,1,1,1,1,1,1,1,1,1,2,0,0,0,1,1,1,1,1,1,1,1,1,1,1,1,1,0,0,0,2,1,1,1,1,1,1,1,1
1,1,1,1,1,1,1,1,1,1,1,1,2,0,0,0,1,1,1,1,1,1,1,1,1,1,1,1,1,0,0,0,2,1,1,1,1,1,1,1,1
1,1,1,1,1,1,1,1,1,1,1,1,2,0,0,0,1,1,1,1,1,1,1,1,1,1,1,1,1,0,0,0,2,1,1,1,1,1,1,1,1
1,1,1,1,1,1,1,1,1,1,1,1,2,0,0,0,1,1,1,1,1,1,1,1,1,1,1,1,1,0,0,0,2,1,1,1,1,1,1,1,1
1,1,1,1,1,1,1,1,1,1,1,1,2,0,0,0,1,1,1,1,1,1,1,1,1,1,1,1,1,0,0,0,2,1,1,1,1,1,1,1,1
1,1,1,1,1,1,1,1,1,1,1,1,2,0,0,0,1,1,1,1,1,1,1,1,1,1,1,1,1,0,0,0,2,1,1,1,1,1,1,1,1
1,1,1,1,1,1,1,1,1,1,1,1,2,0,0,0,1,1,1,1,1,1,1,1,1,1,1,1,1,0,0,0,2,1,1,1,1,1,1,1,1
1,1,1,1,2,2,2,2,2,2,2,2,2,0,0,0,1,1,1,1,1,1,1,1,1,1,1,1,1,0,0,0,2,2,2,2,2,2,2,2,2
1,1,1,1,2,0,0,0,0,0,0,0,2,0,0,0,1,1,1,1,1,1,1,1,1,1,1,1,1,0,0,0,0,0,0,0,0,0,0,0,2
1,1,1,1,2,0,0,0,0,0,0,0,2,0,0,0,1,1,1,1,1,1,1,1,1,1,1,1,1,0,0,0,0,0,0,0,0,0,0,0,2
1,1,1,1,2,0,0,0,0,0,0,0,2,0,0,0,1,1,1,1,1,1,1,1,1,1,1,1,1,0,0,0,0,0,0,0,0,0,0,0,2
1,1,1,1,2,0,0,0,0,0,0,0,2,0,0,0,1,1,1,1,1,1,1,1,1,1,1,1,1,0,0,0,0,0,0,0,0,0,0,0,2
1,1,1,1,2,0,0,0,0,0,0,0,0,0,0,0,0,0,0,0,0,0,0,0,0,0,0,0,0,0,0,0,0,0,0,0,0,0,0,0,2
1,1,1,1,2,0,0,0,0,0,0,0,0,0,0,0,0,0,0,0,0,0,0,0,0,0,0,0,0,0,0,0,0,0,0,0,0,0,0,0,2
1,1,1,1,2,0,0,0,0,0,0,0,0,0,0,0,0,0,0,0,0,0,0,0,0,0,0,0,0,0,0,0,0,0,0,0,0,0,0,0,2
2,2,2,2,2,2,2,2,2,2,2,2,2,0,0,0,0,0,0,0,0,0,0,0,0,0,0,0,2,0,0,0,0,0,0,0,0,0,0,0,2
2,0,0,0,0,0,0,0,0,0,0,0,2,0,0,0,0,0,0,0,0,0,0,0,0,0,0,0,2,0,0,0,0,0,0,0,0,0,0,0,2
2,0,0,0,0,0,0,0,0,0,0,0,2,0,0,0,0,0,0,0,0,0,0,0,0,0,0,0,2,0,0,0,0,0,0,0,0,0,0,0,2
2,0,0,0,0,0,0,0,0,0,0,0,2,0,0,0,0,0,0,0,0,0,0,0,0,0,0,0,2,0,0,0,0,0,0,0,0,0,0,0,2
2,0,0,0,0,0,0,0,0,0,0,0,2,0,0,0,0,0,0,0,0,0,0,0,0,0,0,0,2,2,2,0,0,0,2,2,2,2,2,2,2
2,0,0,0,0,0,0,0,0,0,0,0,2,0,0,0,0,0,0,0,0,0,0,0,0,0,0,0,2,0,0,0,0,0,0,0,2,1,1,1,1
2,0,0,0,0,0,0,0,0,0,0,0,2,0,0,0,0,0,0,0,0,0,0,0,0,0,0,0,2,0,0,0,0,0,0,0,2,1,1,1,1
2,0,0,0,0,0,0,0,0,0,0,0,2,0,0,0,0,0,0,0,0,0,0,0,0,0,0,0,2,0,0,0,0,0,0,0,2,1,1,1,1
2,0,0,0,0,0,0,0,0,0,0,0,0,0,0,0,0,0,0,0,0,0,0,0,0,0,0,0,2,0,0,0,0,0,0,0,2,1,1,1,1
2,0,0,0,0,0,0,0,0,0,0,0,0,0,0,0,0,0,0,0,0,0,0,0,0,0,0,0,2,0,0,0,0,0,0,0,2,1,1,1,1
2,0,0,0,0,0,0,0,0,0,0,0,0,0,0,0,0,0,0,0,0,0,0,0,0,0,0,0,2,0,0,0,0,0,0,0,2,1,1,1,1
2,0,0,0,0,0,0,0,0,0,0,0,0,0,0,0,0,0,0,0,0,0,0,0,0,0,0,0,2,0,0,0,0,0,0,0,2,1,1,1,1
2,0,0,0,1,1,1,1,1,1,1,1,1,1,1,1,1,1,1,1,1,0,0,0,0,2,2,2,2,0,0,0,2,2,2,2,2,1,1,1,1
2,0,0,0,1,1,1,1,1,1,1,1,1,1,1,1,1,1,1,1,1,0,0,0,0,0,0,0,0,0,0,0,2,1,1,1,1,1,1,1,1
2,0,0,0,1,1,1,1,1,1,1,1,1,1,1,1,1,1,1,1,1,0,0,0,0,0,0,0,0,0,0,0,2,1,1,1,1,1,1,1,1
2,0,0,0,1,1,1,1,1,1,1,1,1,1,1,1,1,1,1,1,1,0,0,0,0,0,0,0,0,0,0,0,2,1,1,1,1,1,1,1,1
2,0,0,0,1,1,1,1,1,1,1,1,1,1,1,1,1,1,1,1,1,0,0,0,0,0,0,0,0,0,0,0,2,1,1,1,1,1,1,1,1
2,0,0,0,1,1,1,1,1,1,1,1,1,1,1,1,1,1,1,1,1,0,0,0,0,0,0,0,0,0,0,0,2,1,1,1,1,1,1,1,1
2,0,0,0,1,1,1,1,1,1,1,1,1,1,1,1,1,1,1,1,1,0,0,0,0,0,0,0,0,0,0,0,2,1,1,1,1,1,1,1,1
2,0,0,0,1,1,1,1,1,1,1,1,1,1,1,1,1,1,1,1,1,0,0,0,0,0,0,0,0,0,0,0,2,1,1,1,1,1,1,1,1
2,0,0,0,1,1,1,1,1,1,1,1,1,1,1,1,1,1,1,1,1,0,0,0,0,0,0,0,0,0,0,0,2,1,1,1,1,1,1,1,1
2,0,0,0,1,1,1,1,1,1,1,1,1,1,1,1,1,1,1,1,1,0,0,0,0,0,0,0,0,0,0,0,2,1,1,1,1,1,1,1,1
2,0,0,0,1,1,1,1,1,1,1,1,1,1,1,1,1,1,1,1,1,0,0,0,0,0,0,0,0,0,0,0,2,1,1,1,1,1,1,1,1
2,0,0,0,1,1,1,1,1,1,1,1,1,1,1,1,1,1,1,1,1,0,0,0,0,0,0,0,0,0,0,0,2,1,1,1,1,1,1,1,1
2,0,0,0,1,1,1,1,1,1,1,1,1,1,1,1,1,1,1,1,1,0,0,0,2,2,2,2,2,2,2,2,2,1,1,1,1,1,1,1,1
2,0,0,0,1,1,1,1,1,1,1,1,1,1,1,1,1,1,1,1,1,0,0,0,2,1,1,1,1,1,1,1,1,1,1,1,1,1,1,1,1
2,0,0,0,1,1,1,1,1,1,1,1,1,1,1,1,1,1,1,1,1,0,0,0,2,1,1,1,1,1,1,1,1,1,1,1,1,1,1,1,1
2,0,0,0,1,1,1,1,1,1,1,1,1,1,1,1,1,1,1,1,1,0,0,0,2,1,1,1,1,1,1,1,1,1,1,1,1,1,1,1,1
2,0,0,0,1,1,1,1,1,1,1,1,1,1,1,1,1,1,1,1,1,0,0,0,2,1,1,1,1,1,1,1,1,1,1,1,1,1,1,1,1
2,0,0,0,0,0,0,0,0,0,0,0,0,0,0,0,0,0,0,0,0,0,0,0,2,1,1,1,1,1,1,1,1,1,1,1,1,1,1,1,1
2,0,0,0,0,0,0,0,0,0,0,0,0,0,0,0,0,0,0,0,0,0,0,0,2,1,1,1,1,1,1,1,1,1,1,1,1,1,1,1,1
2,0,0,0,0,0,0,0,0,0,0,0,0,0,0,0,0,0,0,0,0,0,0,0,2,1,1,1,1,1,1,1,1,1,1,1,1,1,1,1,1
2,2,2,2,2,2,2,2,2,2,2,2,2,2,2,2,2,2,2,2,2,2,2,2,2,1,1,1,1,1,1,1,1,1,1,1,1,1,1,1,1
endlayer

layer
1,1,1,1,1,1,1,1,1,1,1,1,2,2,2,2,2,2,2,2,2,2,2,2,2,2,2,2,2,2,2,2,2,1,1,1,1,1,1,1,1
1,1,1,1,1,1,1,1,1,1,1,1,2,0,0,0,0,0,0,0,0,0,0,0,0,0,0,0,0,0,0,0,2,1,1,1,1,1,1,1,1
1,1,1,1,1,1,1,1,1,1,1,1,2,0,0,0,0,0,0,0,0,0,0,0,0,0,0,0,0,0,0,0,2,1,1,1,1,1,1,1,1
1,1,1,1,1,1,1,1,1,1,1,1,2,0,0,0,0,0,0,0,0,0,0,0,0,0,0,0,0,0,0,0,2,1,1,1,1,1,1,1,1
1,1,1,1,1,1,1,1,1,1,1,1,2,0,0,0,1,1,1,1,1,1,1,1,1,1,1,1,1,0,0,0,2,1,1,1,1,1,1,1,1
1,1,1,1,1,1,1,1,1,1,1,1,2,0,0,0,1,1,1,1,1,1,1,1,1,1,1,1,1,0,0,0,2,1,1,1,1,1,1,1,1
1,1,1,1,1,1,1,1,1,1,1,1,2,0,0,0,1,1,1,1,1,1,1,1,1,1,1,1,1,0,0,0,2,1,1,1,1,1,1,1,1
1,1,1,1,1,1,1,1,1,1,1,1,2,0,0,0,1,1,1,1,1,1,1,1,1,1,1,1,1,0,0,0,2,1,1,1,1,1,1,1,1
1,1,1,1,1,1,1,1,1,1,1,1,2,0,0,0,1,1,1,1,1,1,1,1,1,1,1,1,1,0,0,0,2,1,1,1,1,1,1,1,1
1,1,1,1,1,1,1,1,1,1,1,1,2,0,0,0,1,1,1,1,1,1,1,1,1,1,1,1,1,0,0,0,2,1,1,1,1,1,1,1,1
1,1,1,1,1,1,1,1,1,1,1,1,2,0,0,0,1,1,1,1,1,1,1,1,1,1,1,1,1,0,0,0,2,1,1,1,1,1,1,1,1
1,1,1,1,1,1,1,1,1,1,1,1,2,0,0,0,1,1,1,1,1,1,1,1,1,1,1,1,1,0,0,0,2,1,1,1,1,1,1,1,1
1,1,1,1,2,2,2,2,2,2,2,2,2,0,0,0,1,1,1,1,1,1,1,1,1,1,1,1,1,0,0,0,2,2,2,2,2,2,2,2,2
1,1,1,1,2,0,0,0,0,0,0,0,2,0,0,0,1,1,1,1,1,1,1,1,1,1,1,1,1,0,0,0,0,0,0,0,0,0,0,0,2
1,1,1,1,2,0,0,0,0,0,0,0,2,0,0,0,1,1,1,1,1,1,1,1,1,1,1,1,1,0,0,0,0,0,0,0,0,0,0,0,2
1,1,1,1,2,0,0,0,0,0,0,0,2,0,0,0,1,1,1,1,1,1,1,1,1,1,1,1,1,0,0,0,0,0,0,0,0,0,0,0,2
1,1,1,1,2,0,0,0,0,0,0,0,2,0,0,0,1,1,1,1,1,1,1,1,1,1,1,1,1,0,0,0,0,0,0,0,0,0,0,0,2
1,1,1,1,2,0,0,0,0,0,0,0,0,0,0,0,0,0,0,0,0,0,0,0,0,0,0,0,0,0,0,0,0,0,0,0,0,0,0,0,2
1,1,1,1,2,0,0,0,0,0,0,0,0,0,0,0,0,0,0,0,0,0,0,0,0,0,0,0,0,0,0,0,0,0,0,0,0,0,0,0,2
1,1,1,1,2,0,0,0,0,0,0,0,0,0,0,0,0,0,0,0,0,0,0,0,0,0,0,0,0,0,0,0,0,0,0,0,0,0,0,0,2
2,2,2,2,2,2,2,2,2,2,2,2,2,0,0,0,0,0,0,0,0,0,0,0,0,0,0,0,2,0,0,0,0,0,0,0,0,0,0,0,2
2,0,0,0,0,0,0,0,0,0,0,0,2,0,0,0,0,0,0,0,0,0,0,0,0,0,0,0,2,0,0,0,0,0,0,0,0,0,0,0,2
2,0,0,0,0,0,0,0,0,0,0,0,2,0,0,0,0,0,0,0,0,0,0,0,0,0,0,0,2,0,0,0,0,0,0,0,0,0,0,0,2
2,0,0,0,0,0,0,0,0,0,0,0,2,0,0,0,0,0,0,0,0,0,0,0,0,0,0,0,2,0,0,0,0,0,0,0,0,0,0,0,2
2,0,0,0,0,0,0,0,0,0,0,0,2,0,0,0,0,0,0,0,0,0,0,0,0,0,0,0,2,2,2,0,0,0,2,2,2,2,2,2,2
2,0,0,0,0,0,0,0,0,0,0,0,2,0,0,0,0,0,0,0,0,0,0,0,0,0,0,0,2,0,0,0,0,0,0,0,2,1,1,1,1
2,0,0,0,0,0,0,0,0,0,0,0,2,0,0,0,0,0,0,0,0,0,0,0,0,0,0,0,2,0,0,0,0,0,0,0,2,1,1,1,1
2,0,0,0,0,0,0,0,0,0,0,0,2,0,0,0,0,0,0,0,0,0,0,0,0,0,0,0,2,0,0,0,0,0,0,0,2,1,1,1,1
2,0,0,0,0,0,0,0,0,0,0,0,0,0,0,0,0,0,0,0,0,0,0,0,0,0,0,0,2,0,0,0,0,0,0,0,2,1,1,1,1
2,0,0,0,0,0,0,0,0,0,0,0,0,0,0,0,0,0,0,0,0,0,0,0,0,0,0,0,2,0,0,0,0,0,0,0,2,1,1,1,1
2,0,0,0,0,0,0,0,0,0,0,0,0,0,0,0,0,0,0,0,0,0,0,0,0,0,0,0,2,0,0,0,0,0,0,0,2,1,1,1,1
2,0,0,0,0,0,0,0,0,0,0,0,0,0,0,0,0,0,0,0,0,0,0,0,0,0,0,0,2,0,0,0,0,0,0,0,2,1,1,1,1
2,0,0,0,1,1,1,1,1,1,1,1,1,1,1,1,1,1,1,1,1,0,0,0,0,2,2,2,2,0,0,0,2,2,2,2,2,1,1,1,1
2,0,0,0,1,1,1,1,1,1,1,1,1,1,1,1,1,1,1,1,1,0,0,0,0,0,0,0,0,0,0,0,2,1,1,1,1,1,1,1,1
2,0,0,0,1,1,1,1,1,1,1,1,1,1,1,1,1,1,1,1,1,0,0,0,0,0,0,0,0,0,0,0,2,1,1,1,1,1,1,1,1
2,0,0,0,1,1,1,1,1,1,1,1,1,1,1,1,1,1,1,1,1,0,0,0,0,0,0,0,0,0,0,0,2,1,1,1,1,1,1,1,1
2,0,0,0,1,1,1,1,1,1,1,1,1,1,1,1,1,1,1,1,1,0,0,0,0,0,0,0,0,0,0,0,2,1,1,1,1,1,1,1,1
2,0,0,0,1,1,1,1,1,1,1,1,1,1,1,1,1,1,1,1,1,0,0,0,0,0,0,0,0,0,0,0,2,1,1,1,1,1,1,1,1
2,0,0,0,1,1,1,1,1,1,1,1,1,1,1,1,1,1,1,1,1,0,0,0,0,0,0,0,0,0,0,0,2,1,1,1,1,1,1,1,1
2,0,0,0,1,1,1,1,1,1,1,1,1,1,1,1,1,1,1,1,1,0,0,0,0,0,0,0,0,0,0,0,2,1,1,1,1,1,1,1,1
2,0,0,0,1,1,1,1,1,1,1,1,1,1,1,1,1,1,1,1,1,0,0,0,0,0,0,0,0,0,0,0,2,1,1,1,1,1,1,1,1
2,0,0,0,1,1,1,1,1,1,1,1,1,1,1,1,1,1,1,1,1,0,0,0,0,0,0,0,0,0,0,0,2,1,1,1,1,1,1,1,1
2,0,0,0,1,1,1,1,1,1,1,1,1,1,1,1,1,1,1,1,1,0,0,0,0,0,0,0,0,0,0,0,2,1,1,1,1,1,1,1,1
2,0,0,0,1,1,1,1,1,1,1,1,1,1,1,1,1,1,1,1,1,0,0,0,0,0,0,0,0,0,0,0,2,1,1,1,1,1,1,1,1
2,0,0,0,1,1,1,1,1,1,1,1,1,1,1,1,1,1,1,1,1,0,0,0,2,2,2,2,2,2,2,2,2,1,1,1,1,1,1,1,1
2,0,0,0,1,1,1,1,1,1,1,1,1,1,1,1,1,1,1,1,1,0,0,0,2,1,1,1,1,1,1,1,1,1,1,1,1,1,1,1,1
2,0,0,0,1,1,1,1,1,1,1,1,1,1,1,1,1,1,1,1,1,0,0,0,2,1,1,1,1,1,1,1,1,1,1,1,1,1,1,1,1
2,0,0,0,1,1,1,1,1,1,1,1,1,1,1,1,1,1,1,1,1,0,0,0,2,1,1,1,1,1,1,1,1,1,1,1,1,1,1,1,1
2,0,0,0,1,1,1,1,1,1,1,1,1,1,1,1,1,1,1,1,1,0,0,0,2,1,1,1,1,1,1,1,1,1,1,1,1,1,1,1,1
2,0,0,0,0,0,0,0,0,0,0,0,0,0,0,0,0,0,0,0,0,0,0,0,2,1,1,1,1,1,1,1,1,1,1,1,1,1,1,1,1
2,0,0,0,0,0,0,0,0,0,0,0,0,0,0,0,0,0,0,0,0,0,0,0,2,1,1,1,1,1,1,1,1,1,1,1,1,1,1,1,1
2,0,0,0,0,0,0,0,0,0,0,0,0,0,0,0,0,0,0,0,0,0,0,0,2,1,1,1,1,1,1,1,1,1,1,1,1,1,1,1,1
2,2,2,2,2,2,2,2,2,2,2,2,2,2,2,2,2,2,2,2,2,2,2,2,2,1,1,1,1,1,1,1,1,1,1,1,1,1,1,1,1
endlayer

layer
1,1,1,1,1,1,1,1,1,1,1,1,12,12,12,12,12,12,12,12,12,12,12,12,12,12,12,12,12,12,12,12,12,1,1,1,1,1,1,1,1
1,1,1,1,1,1,1,1,1,1,1,1,12,0,0,0,0,0,0,0,0,0,0,0,0,0,0,0,0,0,0,0,12,1,1,1,1,1,1,1,1
1,1,1,1,1,1,1,1,1,1,1,1,12,0,0,0,0,0,0,0,0,0,0,0,0,0,0,0,0,0,0,0,12,1,1,1,1,1,1,1,1
1,1,1,1,1,1,1,1,1,1,1,1,12,0,0,0,0,0,0,0,0,0,0,0,0,0,0,0,0,0,0,0,12,1,1,1,1,1,1,1,1
1,1,1,1,1,1,1,1,1,1,1,1,12,0,0,0,1,1,1,1,1,1,1,1,1,1,1,1,1,0,0,0,12,1,1,1,1,1,1,1,1
1,1,1,1,1,1,1,1,1,1,1,1,12,0,0,0,1,1,1,1,1,1,1,1,1,1,1,1,1,0,0,0,12,1,1,1,1,1,1,1,1
1,1,1,1,1,1,1,1,1,1,1,1,12,0,0,0,1,1,1,1,1,1,1,1,1,1,1,1,1,0,0,0,12,1,1,1,1,1,1,1,1
1,1,1,1,1,1,1,1,1,1,1,1,12,0,0,0,1,1,1,1,1,1,1,1,1,1,1,1,1,0,0,0,12,1,1,1,1,1,1,1,1
1,1,1,1,1,1,1,1,1,1,1,1,12,0,0,0,1,1,1,1,1,1,1,1,1,1,1,1,1,0,0,0,12,1,1,1,1,1,1,1,1
1,1,1,1,1,1,1,1,1,1,1,1,12,0,0,0,1,1,1,1,1,1,1,1,1,1,1,1,1,0,0,0,12,1,1,1,1,1,1,1,1
1,1,1,1,1,1,1,1,1,1,1,1,12,0,0,0,1,1,1,1,1,1,1,1,1,1,1,1,1,0,0,0,12,1,1,1,1,1,1,1,1
1,1,1,1,1,1,1,1,1,1,1,1,12,0,0,0,1,1,1,1,1,1,1,1,1,1,1,1,1,0,0,0,12,1,1,1,1,1,1,1,1
1,1,1,1,12,12,12,12,12,12,12,12,12,0,0,0,1,1,1,1,1,1,1,1,1,1,1,1,1,0,0,0,12,12,12,12,12,12,12,12,12
1,1,1,1,12,0,0,0,0,0,0,0,12,0,0,0,1,1,1,1,1,1,1,1,1,1,1,1,1,0,0,0,0,0,0,0,0,0,0,0,12
1,1,1,1,12,0,0,0,0,0,0,0,12,0,0,0,1,1,1,1,1,1,1,1,1,1,1,1,1,0,0,0,0,0,0,0,0,0,0,0,12
1,1,1,1,12,0,0,0,0,0,0,0,12,0,0,0,1,1,1,1,1,1,1,1,1,1,1,1,1,0,0,0,0,0,0,0,0,0,0,0,12
1,1,1,1,12,0,0,0,0,0,0,0,12,0,0,0,1,1,1,1,1,1,1,1,1,1,1,1,1,0,0,0,0,0,0,0,0,0,0,0,12
1,1,1,1,12,0,0,0,0,0,0,0,0,0,0,0,0,0,0,0,0,0,0,0,0,0,0,0,0,0,0,0,0,0,0,0,0,0,0,0,12
1,1,1,1,12,0,0,0,0,0,0,0,0,0,0,0,0,0,0,0,0,0,0,0,0,0,0,0,0,0,0,0,0,0,0,0,0,0,0,0,12
1,1,1,1,12,0,0,0,0,0,0,0,0,0,0,0,0,0,0,0,0,0,0,0,0,0,0,0,0,0,0,0,0,0,0,0,0,0,0,0,12
12,12,12,12,12,12,12,12,12,12,12,12,12,0,0,0,0,0,0,0,0,0,0,0,0,0,0,0,12,0,0,0,0,0,0,0,0,0,0,0,12
12,0,0,0,0,0,0,0,0,0,0,0,12,0,0,0,0,0,0,0,0,0,0,0,0,0,0,0,12,0,0,0,0,0,0,0,0,0,0,0,12
12,0,0,0,0,0,0,0,0,0,0,0,12,0,0,0,0,0,0,0,0,0,0,0,0,0,0,0,12,0,0,0,0,0,0,0,0,0,0,0,12
12,0,0,0,0,0,0,0,0,0,0,0,12,0,0,0,0,0,0,0,0,0,0,0,0,0,0,0,12,0,0,0,0,0,0,0,0,0,0,0,12
12,0,0,0,0,0,0,0,0,0,0,0,12,0,0,0,0,0,0,0,0,0,0,0,0,0,0,0,12,12,12,0,0,0,12,12,12,12,12,12,12
12,0,0,0,0,0,0,0,0,0,0,0,12,0,0,0,0,0,0,0,0,0,0,0,0,0,0,0,12,0,0,0,0,0,0,0,12,1,1,1,1
12,0,0,0,0,0,0,0,0,0,0,0,12,0,0,0,0,0,0,0,0,0,0,0,0,0,0,0,12,0,0,0,0,0,0,0,12,1,1,1,1
12,0,0,0,0,0,0,0,0,0,0,0,12,0,0,0,0,0,0,0,0,0,0,0,0,0,0,0,12,0,0,0,0,0,0,0,12,1,1,1,1
12,0,0,0,0,0,0,0,0,0,0,0,0,0,0,0,0,0,0,0,0,0,0,0,0,0,0,0,12,0,0,0,0,0,0,0,12,1,1,1,1
12,0,0,0,0,0,0,0,0,0,0,0,0,0,0,0,0,0,0,0,0,0,0,0,0,0,0,0,12,0,0,0,0,0,0,0,12,1,1,1,1
12,0,0,0,0,0,0,0,0,0,0,0,0,0,0,0,0,0,0,0,0,0,0,0,0,0,0,0,12,0,0,0,0,0,0,0,12,1,1,1,1
12,0,0,0,0,0,0,0,0,0,0,0,0,0,0,0,0,0,0,0,0,0,0,0,0,0,0,0,12,0,0,0,0,0,0,0,12,1,1,1,1
12,0,0,0,1,1,1,1,1,1,1,1,1,1,1,1,1,1,1,1,1,0,0,0,0,12,12,12,12,0,0,0,12,12,12,12,12,1,1,1,1
12,0,0,0,1,1,1,1,1,1,1,1,1,1,1,1,1,1,1,1,1,0,0,0,0,0,0,0,0,0,0,0,12,1,1,1,1,1,1,1,1
12,0,0,0,1,1,1,1,1,1,1,1,1,1,1,1,1,1,1,1,1,0,0,0,0,0,0,0,0,0,0,0,12,1,1,1,1,1,1,1,1
12,0,0,0,1,1,1,1,1,1,1,1,1,1,1,1,1,1,1,1,1,0,0,0,0,0,0,0,0,0,0,0,12,1,1,1,1,1,1,1,1
12,0,0,0,1,1,1,1,1,1,1,1,1,1,1,1,1,1,1,1,1,0,0,0,0,0,0,0,0,0,0,0,12,1,1,1,1,1,1,1,1
12,0,0,0,1,1,1,1,1,1,1,1,1,1,1,1,1,1,1,1,1,0,0,0,0,0,0,0,0,0,0,0,12,1,1,1,1,1,1,1,1
12,0,0,0,1,1,1,1,1,1,1,1,1,1,1,1,1,1,1,1,1,0,0,0,0,0,0,0,0,0,0,0,12,1,1,1,1,1,1,1,1
12,0,0,0,1,1,1,1,1,1,1,1,1,1,1,1,1,1,1,1,1,0,0,0,0,0,0,0,0,0,0,0,12,1,1,1,1,1,1,1,1
12,0,0,0,1,1,1,1,1,1,1,1,1,1,1,1,1,1,1,1,1,0,0,0,0,0,0,0,0,0,0,0,12,1,1,1,1,1,1,1,1
12,0,0,0,1,1,1,1,1,1,1,1,1,1,1,1,1,1,1,1,1,0,0,0,0,0,0,0,0,0,0,0,12,1,1,1,1,1,1,1,1
12,0,0,0,1,1,1,1,1,1,1,1,1,1,1,1,1,1,1,1,1,0,0,0,0,0,0,0,0,0,0,0,12,1,1,1,1,1,1,1,1
12,0,0,0,1,1,1,1,1,1,1,1,1,1,1,1,1,1,1,1,1,0,0,0,0,0,0,0,0,0,0,0,12,1,1,1,1,1,1,1,1
12,0,0,0,1,1,1,1,1,1,1,1,1,1,1,1,1,1,1,1,1,0,0,0,12,12,12,12,12,12,12,12,12,1,1,1,1,1,1,1,1
12,0,0,0,1,1,1,1,1,1,1,1,1,1,1,1,1,1,1,1,1,0,0,0,12,1,1,1,1,1,1,1,1,1,1,1,1,1,1,1,1
12,0,0,0,1,1,1,1,1,1,1,1,1,1,1,1,1,1,1,1,1,0,0,0,12,1,1,1,1,1,1,1,1,1,1,1,1,1,1,1,1
12,0,0,0,1,1,1,1,1,1,1,1,1,1,1,1,1,1,1,1,1,0,0,0,12,1,1,1,1,1,1,1,1,1,1,1,1,1,1,1,1
12,0,0,0,1,1,1,1,1,1,1,1,1,1,1,1,1,1,1,1,1,0,0,0,12,1,1,1,1,1,1,1,1,1,1,1,1,1,1,1,1
12,0,0,0,0,0,0,0,0,0,0,0,0,0,0,0,0,0,0,0,0,0,0,0,12,1,1,1,1,1,1,1,1,1,1,1,1,1,1,1,1
12,0,0,0,0,0,0,0,0,0,0,0,0,0,0,0,0,0,0,0,0,0,0,0,12,1,1,1,1,1,1,1,1,1,1,1,1,1,1,1,1
12,0,0,0,0,0,0,0,0,0,0,0,0,0,0,0,0,0,0,0,0,0,0,0,12,1,1,1,1,1,1,1,1,1,1,1,1,1,1,1,1
12,12,12,12,12,12,12,12,12,12,12,12,12,12,12,12,12,12,12,12,12,12,12,12,12,1,1,1,1,1,1,1,1,1,1,1,1,1,1,1,1
endlayer

layer
1,1,1,1,1,1,1,1,1,1,1,1,2,2,2,2,2,2,2,2,2,2,2,2,2,2,2,2,2,2,2,2,2,1,1,1,1,1,1,1,1
1,1,1,1,1,1,1,1,1,1,1,1,2,0,0,0,0,0,0,0,0,0,0,0,0,0,0,0,0,0,0,0,2,1,1,1,1,1,1,1,1
1,1,1,1,1,1,1,1,1,1,1,1,2,0,0,0,0,0,0,0,0,0,0,0,0,0,0,0,0,0,0,0,2,1,1,1,1,1,1,1,1
1,1,1,1,1,1,1,1,1,1,1,1,2,0,0,0,0,0,0,0,0,0,0,0,0,0,0,0,0,0,0,0,2,1,1,1,1,1,1,1,1
1,1,1,1,1,1,1,1,1,1,1,1,2,0,0,0,1,1,1,1,1,1,1,1,1,1,1,1,1,0,0,0,2,1,1,1,1,1,1,1,1
1,1,1,1,1,1,1,1,1,1,1,1,2,0,0,0,1,1,1,1,1,1,1,1,1,1,1,1,1,0,0,0,2,1,1,1,1,1,1,1,1
1,1,1,1,1,1,1,1,1,1,1,1,2,0,0,0,1,1,1,1,1,1,1,1,1,1,1,1,1,0,0,0,2,1,1,1,1,1,1,1,1
1,1,1,1,1,1,1,1,1,1,1,1,2,0,0,0,1,1,1,1,1,1,1,1,1,1,1,1,1,0,0,0,2,1,1,1,1,1,1,1,1
1,1,1,1,1,1,1,1,1,1,1,1,2,0,0,0,1,1,1,1,1,1,1,1,1,1,1,1,1,0,0,0,2,1,1,1,1,1,1,1,1
1,1,1,1,1,1,1,1,1,1,1,1,2,0,0,0,1,1,1,1,1,1,1,1,1,1,1,1,1,0,0,0,2,1,1,1,1,1,1,1,1
1,1,1,1,1,1,1,1,1,1,1,1,2,0,0,0,1,1,1,1,1,1,1,1,1,1,1,1,1,0,0,0,2,1,1,1,1,1,1,1,1
1,1,1,1,1,1,1,1,1,1,1,1,2,0,0,0,1,1,1,1,1,1,1,1,1,1,1,1,1,0,0,0,2,1,1,1,1,1,1,1,1
1,1,1,1,2,2,2,2,2,2,2,2,2,0,0,0,1,1,1,1,1,1,1,1,1,1,1,1,1,0,0,0,2,2,2,2,2,2,2,2,2
1,1,1,1,2,0,0,0,0,0,0,0,2,0,0,0,1,1,1,1,1,1,1,1,1,1,1,1,1,0,0,0,0,0,0,0,0,0,0,0,2
1,1,1,1,2,0,0,0,0,0,0,0,2,0,0,0,1,1,1,1,1,1,1,1,1,1,1,1,1,0,0,0,0,0,0,0,0,0,0,0,2
1,1,1,1,2,0,0,0,0,0,0,0,2,0,0,0,1,1,1,1,1,1,1,1,1,1,1,1,1,0,0,0,0,0,0,0,0,0,0,0,2
1,1,1,1,2,0,0,0,0,0,0,0,2,0,0,0,1,1,1,1,1,1,1,1,1,1,1,1,1,0,0,0,0,0,0,0,0,0,0,0,2
1,1,1,1,2,0,0,0,0,0,0,0,0,0,0,0,0,0,0,0,0,0,0,0,0,0,0,0,0,0,0,0,0,0,0,0,0,0,0,0,2
1,1,1,1,2,0,0,0,0,0,0,0,0,0,0,0,0,0,0,0,0,0,0,0,0,0,0,0,0,0,0,0,0,0,0,0,0,0,0,0,2
1,1,1,1,2,0,0,0,0,0,0,0,0,0,0,0,0,0,0,0,0,0,0,0,0,0,0,0,0,0,0,0,0,0,0,0,0,0,0,0,2
2,2,2,2,2,2,2,2,2,2,2,2,2,0,0,0,0,0,0,0,0,0,0,0,0,0,0,0,2,0,0,0,0,0,0,0,0,0,0,0,2
2,0,0,0,0,0,0,0,0,0,0,0,2,0,0,0,0,0,0,0,0,0,0,0,0,0,0,0,2,0,0,0,0,0,0,0,0,0,0,0,2
2,0,0,0,0,0,0,0,0,0,0,0,2,0,0,0,0,0,0,0,0,0,0,0,0,0,0,0,2,0,0,0,0,0,0,0,0,0,0,0,2
2,0,0,0,0,0,0,0,0,0,0,0,2,0,0,0,0,0,0,0,0,0,0,0,0,0,0,0,2,0,0,0,0,0,0,0,0,0,0,0,2
2,0,0,0,0,0,0,0,0,0,0,0,2,0,0,0,0,0,0,0,0,0,0,0,0,0,0,0,2,2,2,0,0,0,2,2,2,2,2,2,2
2,0,0,0,0,0,0,0,0,0,0,0,2,0,0,0,0,0,0,0,0,0,0,0,0,0,0,0,2,0,0,0,0,0,0,0,2,1,1,1,1
2,0,0,0,0,0,0,0,0,0,0,0,2,0,0,0,0,0,0,0,0,0,0,0,0,0,0,0,2,0,0,0,0,0,0,0,2,1,1,1,1
2,0,0,0,0,0,0,0,0,0,0,0,2,0,0,0,0,0,0,0,0,0,0,0,0,0,0,0,2,0,0,0,0,0,0,0,2,1,1,1,1
2,0,0,0,0,0,0,0,0,0,0,0,0,0,0,0,0,0,0,0,0,0,0,0,0,0,0,0,2,0,0,0,0,0,0,0,2,1,1,1,1
2,0,0,0,0,0,0,0,0,0,0,0,0,0,0,0,0,0,0,0,0,0,0,0,0,0,0,0,2,0,0,0,0,0,0,0,2,1,1,1,1
2,0,0,0,0,0,0,0,0,0,0,0,0,0,0,0,0,0,0,0,0,0,0,0,0,0,0,0,2,0,0,0,0,0,0,0,2,1,1,1,1
2,0,0,0,0,0,0,0,0,0,0,0,0,0,0,0,0,0,0,0,0,0,0,0,0,0,0,0,2,0,0,0,0,0,0,0,2,1,1,1,1
2,0,0,0,1,1,1,1,1,1,1,1,1,1,1,1,1,1,1,1,1,0,0,0,0,2,2,2,2,0,0,0,2,2,2,2,2,1,1,1,1
2,0,0,0,1,1,1,1,1,1,1,1,1,1,1,1,1,1,1,1,1,0,0,0,0,0,0,0,0,0,0,0,2,1,1,1,1,1,1,1,1
2,0,0,0,1,1,1,1,1,1,1,1,1,1,1,1,1,1,1,1,1,0,0,0,0,0,0,0,0,0,0,0,2,1,1,1,1,1,1,1,1
2,0,0,0,1,1,1,1,1,1,1,1,1,1,1,1,1,1,1,1,1,0,0,0,0,0,0,0,0,0,0,0,2,1,1,1,1,1,1,1,1
2,0,0,0,1,1,1,1,1,1,1,1,1,1,1,1,1,1,1,1,1,0,0,0,0,0,0,0,0,0,0,0,2,1,1,1,1,1,1,1,1
2,0,0,0,1,1,1,1,1,1,1,1,1,1,1,1,1,1,1,1,1,0,0,0,0,0,0,0,0,0,0,0,2,1,1,1,1,1,1,1,1
2,0,0,0,1,1,1,1,1,1,1,1,1,1,1,1,1,1,1,1,1,0,0,0,0,0,0,0,0,0,0,0,2,1,1,1,1,1,1,1,1
2,0,0,0,1,1,1,1,1,1,1,1,1,1,1,1,1,1,1,1,1,0,0,0,0,0,0,0,0,0,0,0,2,1,1,1,1,1,1,1,1
2,0,0,0,1,1,1,1,1,1,1,1,1,1,1,1,1,1,1,1,1,0,0,0,0,0,0,0,0,0,0,0,2,1,1,1,1,1,1,1,1
2,0,0,0,1,1,1,1,1,1,1,1,1,1,1,1,1,1,1,1,1,0,0,0,0,0,0,0,0,0,0,0,2,1,1,1,1,1,1,1,1
2,0,0,0,1,1,1,1,1,1,1,1,1,1,1,1,1,1,1,1,1,0,0,0,0,0,0,0,0,0,0,0,2,1,1,1,1,1,1,1,1
2,0,0,0,1,1,1,1,1,1,1,1,1,1,1,1,1,1,1,1,1,0,0,0,0,0,0,0,0,0,0,0,2,1,1,1,1,1,1,1,1
2,0,0,0,1,1,1,1,1,1,1,1,1,1,1,1,1,1,1,1,1,0,0,0,2,2,2,2,2,2,2,2,2,1,1,1,1,1,1,1,1
2,0,0,0,1,1,1,1,1,1,1,1,1,1,1,1,1,1,1,1,1,0,0,0,2,1,1,1,1,1,1,1,1,1,1,1,1,1,1,1,1
2,0,0,0,1,1,1,1,1,1,1,1,1,1,1,1,1,1,1,1,1,0,0,0,2,1,1,1,1,1,1,1,1,1,1,1,1,1,1,1,1
2,0,0,0,1,1,1,1,1,1,1,1,1,1,1,1,1,1,1,1,1,0,0,0,2,1,1,1,1,1,1,1,1,1,1,1,1,1,1,1,1
2,0,0,0,1,1,1,1,1,1,1,1,1,1,1,1,1,1,1,1,1,0,0,0,2,1,1,1,1,1,1,1,1,1,1,1,1,1,1,1,1
2,0,0,0,0,0,0,0,0,0,0,0,0,0,0,0,0,0,0,0,0,0,0,0,2,1,1,1,1,1,1,1,1,1,1,1,1,1,1,1,1
2,0,0,0,0,0,0,0,0,0,0,0,0,0,0,0,0,0,0,0,0,0,0,0,2,1,1,1,1,1,1,1,1,1,1,1,1,1,1,1,1
2,0,0,0,0,0,0,0,0,0,0,0,0,0,0,0,0,0,0,0,0,0,0,0,2,1,1,1,1,1,1,1,1,1,1,1,1,1,1,1,1
2,2,2,2,2,2,2,2,2,2,2,2,2,2,2,2,2,2,2,2,2,2,2,2,2,1,1,1,1,1,1,1,1,1,1,1,1,1,1,1,1
endlayer

layer
1,1,1,1,1,1,1,1,1,1,1,1,2,2,2,2,2,2,2,2,2,2,2,2,2,2,2,2,2,2,2,2,2,1,1,1,1,1,1,1,1
1,1,1,1,1,1,1,1,1,1,1,1,2,13,13,13,13,13,13,13,13,13,13,13,13,13,13,13,13,13,13,13,2,1,1,1,1,1,1,1,1
1,1,1,1,1,1,1,1,1,1,1,1,2,13,4,13,13,13,4,13,13,13,4,13,13,13,4,13,13,13,4,13,2,1,1,1,1,1,1,1,1
1,1,1,1,1,1,1,1,1,1,1,1,2,13,13,13,13,13,13,13,13,13,13,13,13,13,13,13,13,13,13,13,2,1,1,1,1,1,1,1,1
1,1,1,1,1,1,1,1,1,1,1,1,2,13,13,13,1,1,1,1,1,1,1,1,1,1,1,1,1,13,13,13,2,1,1,1,1,1,1,1,1
1,1,1,1,1,1,1,1,1,1,1,1,2,13,13,13,1,1,1,1,1,1,1,1,1,1,1,1,1,13,13,13,2,1,1,1,1,1,1,1,1
1,1,1,1,1,1,1,1,1,1,1,1,2,13,4,13,1,1,1,1,1,1,1,1,1,1,1,1,1,13,4,13,2,1,1,1,1,1,1,1,1
1,1,1,1,1,1,1,1,1,1,1,1,2,13,13,13,1,1,1,1,1,1,1,1,1,1,1,1,1,13,13,13,2,1,1,1,1,1,1,1,1
1,1,1,1,1,1,1,1,1,1,1,1,2,13,13,13,1,1,1,1,1,1,1,1,1,1,1,1,1,13,13,13,2,1,1,1,1,1,1,1,1
1,1,1,1,1,1,1,1,1,1,1,1,2,13,13,13,1,1,1,1,1,1,1,1,1,1,1,1,1,13,13,13,2,1,1,1,1,1,1,1,1
1,1,1,1,1,1,1,1,1,1,1,1,2,13,4,13,1,1,1,1,1,1,1,1,1,1,1,1,1,13,4,13,2,1,1,1,1,1,1,1,1
1,1,1,1,1,1,1,1,1,1,1,1,2,13,13,13,1,1,1,1,1,1,1,1,1,1,1,1,1,13,13,13,2,1,1,1,1,1,1,1,1
1,1,1,1,2,2,2,2,2,2,2,2,2,13,13,13,1,1,1,1,1,1,1,1,1,1,1,1,1,2,2,2,2,2,2,2,2,2,2,2,2
1,1,1,1,2,0,0,0,0,0,0,0,2,13,13,13,1,1,1,1,1,1,1,1,1,1,1,1,1,0,0,0,0,0,0,0,0,0,0,0,2
1,1,1,1,2,0,0,0,0,0,0,0,2,13,4,13,1,1,1,1,1,1,1,1,1,1,1,1,1,0,0,0,0,0,0,0,0,0,0,0,2
1,1,1,1,2,0,0,0,0,0,0,0,2,13,13,13,1,1,1,1,1,1,1,1,1,1,1,1,1,0,0,0,0,0,0,0,0,0,0,0,2
1,1,1,1,2,0,0,0,0,0,0,0,2,2,2,2,1,1,1,1,1,1,1,1,1,1,1,1,1,0,0,0,0,0,0,0,0,0,0,0,2
1,1,1,1,2,0,0,0,0,0,0,0,2,0,0,0,0,0,0,0,0,0,0,0,0,0,0,0,2,0,0,0,0,0,0,0,0,0,0,0,2
1,1,1,1,2,0,0,0,0,0,0,0,2,0,0,0,0,0,0,0,0,0,0,0,0,0,0,0,2,0,0,0,0,0,0,0,0,0,0,0,2
1,1,1,1,2,0,0,0,0,0,0,0,2,0,0,0,0,0,0,0,0,0,0,0,0,0,0,0,2,0,0,0,0,0,0,0,0,0,0,0,2
2,2,2,2,2,2,2,2,2,2,2,2,2,0,0,0,0,0,0,0,0,0,0,0,0,0,0,0,2,0,0,0,0,0,0,0,0,0,0,0,2
2,0,0,0,0,0,0,0,0,0,0,0,2,0,0,0,0,0,0,0,0,0,0,0,0,0,0,0,2,0,0,0,0,0,0,0,0,0,0,0,2
2,0,0,0,0,0,0,0,0,0,0,0,2,0,0,0,0,0,0,0,0,0,0,0,0,0,0,0,2,0,0,0,0,0,0,0,0,0,0,0,2
2,0,0,0,0,0,0,0,0,0,0,0,2,0,0,0,0,0,0,0,0,0,0,0,0,0,0,0,2,0,0,0,0,0,0,0,0,0,0,0,2
2,0,0,0,0,0,0,0,0,0,0,0,2,0,0,0,0,0,0,0,0,0,0,0,0,0,0,0,2,2,2,2,2,2,2,2,2,2,2,2,2
2,0,0,0,0,0,0,0,0,0,0,0,2,0,0,0,0,0,0,0,0,0,0,0,0,0,0,0,2,0,0,0,0,0,0,0,2,1,1,1,1
2,0,0,0,0,0,0,0,0,0,0,0,2,0,0,0,0,0,0,0,0,0,0,0,0,0,0,0,2,0,0,0,0,0,0,0,2,1,1,1,1
2,0,0,0,0,0,0,0,0,0,0,0,2,0,0,0,0,0,0,0,0,0,0,0,0,0,0,0,2,0,0,0,0,0,0,0,2,1,1,1,1
2,0,0,0,0,0,0,0,0,0,0,0,2,0,0,0,0,0,0,0,0,0,0,0,0,0,0,0,2,0,0,0,0,0,0,0,2,1,1,1,1
2,0,0,0,0,0,0,0,0,0,0,0,2,0,0,0,0,0,0,0,0,0,0,0,0,0,0,0,2,0,0,0,0,0,0,0,2,1,1,1,1
2,0,0,0,0,0,0,0,0,0,0,0,2,0,0,0,0,0,0,0,0,0,0,0,0,0,0,0,2,0,0,0,0,0,0,0,2,1,1,1,1
2,0,0,0,0,0,0,0,0,0,0,0,2,0,0,0,0,0,0,0,0,0,0,0,0,0,0,0,2,0,0,0,0,0,0,0,2,1,1,1,1
2,2,2,2,1,1,1,1,1,1,1,1,1,1,1,1,1,1,1,1,1,2,2,2,2,2,2,2,2,2,2,2,2,2,2,2,2,1,1,1,1
2,13,13,13,1,1,1,1,1,1,1,1,1,1,1,1,1,1,1,1,1,0,0,0,0,0,0,0,0,0,0,0,2,1,1,1,1,1,1,1,1
2,13,4,13,1,1,1,1,1,1,1,1,1,1,1,1,1,1,1,1,1,0,0,0,0,0,0,0,0,0,0,0,2,1,1,1,1,1,1,1,1
2,13,13,13,1,1,1,1,1,1,1,1,1,1,1,1,1,1,1,1,1,0,0,0,0,0,0,0,0,0,0,0,2,1,1,1,1,1,1,1,1
2,13,13,13,1,1,1,1,1,1,1,1,1,1,1,1,1,1,1,1,1,0,0,0,0,0,0,0,0,0,0,0,2,1,1,1,1,1,1,1,1
2,13,13,13,1,1,1,1,1,1,1,1,1,1,1,1,1,1,1,1,1,0,0,0,0,0,0,0,0,0,0,0,2,1,1,1,1,1,1,1,1
2,13,4,13,1,1,1,1,1,1,1,1,1,1,1,1,1,1,1,1,1,0,0,0,0,0,0,0,0,0,0,0,2,1,1,1,1,1,1,1,1
2,13,13,13,1,1,1,1,1,1,1,1,1,1,1,1,1,1,1,1,1,0,0,0,0,0,0,0,0,0,0,0,2,1,1,1,1,1,1,1,1
2,13,13,13,1,1,1,1,1,1,1,1,1,1,1,1,1,1,1,1,1,0,0,0,0,0,0,0,0,0,0,0,2,1,1,1,1,1,1,1,1
2,13,13,13,1,1,1,1,1,1,1,1,1,1,1,1,1,1,1,1,1,0,0,0,0,0,0,0,0,0,0,0,2,1,1,1,1,1,1,1,1
2,13,4,13,1,1,1,1,1,1,1,1,1,1,1,1,1,1,1,1,1,0,0,0,0,0,0,0,0,0,0,0,2,1,1,1,1,1,1,1,1
2,13,13,13,1,1,1,1,1,1,1,1,1,1,1,1,1,1,1,1,1,0,0,0,0,0,0,0,0,0,0,0,2,1,1,1,1,1,1,1,1
2,13,13,13,1,1,1,1,1,1,1,1,1,1,1,1,1,1,1,1,1,2,2,2,2,2,2,2,2,2,2,2,2,1,1,1,1,1,1,1,1
2,13,13,13,1,1,1,1,1,1,1,1,1,1,1,1,1,1,1,1,1,13,13,13,2,1,1,1,1,1,1,1,1,1,1,1,1,1,1,1,1
2,13,4,13,1,1,1,1,1,1,1,1,1,1,1,1,1,1,1,1,1,13,4,13,2,1,1,1,1,1,1,1,1,1,1,1,1,1,1,1,1
2,13,13,13,1,1,1,1,1,1,1,1,1,1,1,1,1,1,1,1,1,13,13,13,2,1,1,1,1,1,1,1,1,1,1,1,1,1,1,1,1
2,13,13,13,1,1,1,1,1,1,1,1,1,1,1,1,1,1,1,1,1,13,13,13,2,1,1,1,1,1,1,1,1,1,1,1,1,1,1,1,1
2,13,13,13,13,13,13,13,13,13,13,13,13,13,13,13,13,13,13,13,13,13,13,13,2,1,1,1,1,1,1,1,1,1,1,1,1,1,1,1,1
2,13,4,13,13,13,4,13,13,13,4,13,13,13,4,13,13,13,4,13,13,13,4,13,2,1,1,1,1,1,1,1,1,1,1,1,1,1,1,1,1
2,13,13,13,13,13,13,13,13,13,13,13,13,13,13,13,13,13,13,13,13,13,13,13,2,1,1,1,1,1,1,1,1,1,1,1,1,1,1,1,1
2,2,2,2,2,2,2,2,2,2,2,2,2,2,2,2,2,2,2,2,2,2,2,2,2,1,1,1,1,1,1,1,1,1,1,1,1,1,1,1,1
endlayer

layer
1,1,1,1,1,1,1,1,1,1,1,1,1,1,1,1,1,1,1,1,1,1,1,1,1,1,1,1,1,1,1,1,1,1,1,1,1,1,1,1,1
1,1,1,1,1,1,1,1,1,1,1,1,1,5,5,5,5,5,5,5,5,5,5,5,5,5,5,5,5,5,5,5,1,1,1,1,1,1,1,1,1
1,1,1,1,1,1,1,1,1,1,1,1,1,5,3,5,5,5,3,5,5,5,3,5,5,5,3,5,5,5,3,5,1,1,1,1,1,1,1,1,1
1,1,1,1,1,1,1,1,1,1,1,1,1,5,5,5,5,5,5,5,5,5,5,5,5,5,5,5,5,5,5,5,1,1,1,1,1,1,1,1,1
1,1,1,1,1,1,1,1,1,1,1,1,1,5,5,5,1,1,1,1,1,1,1,1,1,1,1,1,1,5,5,5,1,1,1,1,1,1,1,1,1
1,1,1,1,1,1,1,1,1,1,1,1,1,5,5,5,1,1,1,1,1,1,1,1,1,1,1,1,1,5,5,5,1,1,1,1,1,1,1,1,1
1,1,1,1,1,1,1,1,1,1,1,1,1,5,3,5,1,1,1,1,1,1,1,1,1,1,1,1,1,5,3,5,1,1,1,1,1,1,1,1,1
1,1,1,1,1,1,1,1,1,1,1,1,1,5,5,5,1,1,1,1,1,1,1,1,1,1,1,1,1,5,5,5,1,1,1,1,1,1,1,1,1
1,1,1,1,1,1,1,1,1,1,1,1,1,5,5,5,1,1,1,1,1,1,1,1,1,1,1,1,1,5,5,5,1,1,1,1,1,1,1,1,1
1,1,1,1,1,1,1,1,1,1,1,1,1,5,5,5,1,1,1,1,1,1,1,1,1,1,1,1,1,5,5,5,1,1,1,1,1,1,1,1,1
1,1,1,1,1,1,1,1,1,1,1,1,1,5,3,5,1,1,1,1,1,1,1,1,1,1,1,1,1,5,3,5,1,1,1,1,1,1,1,1,1
1,1,1,1,1,1,1,1,1,1,1,1,1,5,5,5,1,1,1,1,1,1,1,1,1,1,1,1,1,5,5,5,1,1,1,1,1,1,1,1,1
1,1,1,1,7,7,7,7,7,7,7,7,7,2,5,5,1,1,1,1,1,1,1,1,1,1,1,1,1,2,2,2,7,7,7,7,7,7,7,7,7
1,1,1,1,7,15,15,15,15,15,15,15,7,2,5,5,1,1,1,1,1,1,1,1,1,1,1,1,1,13,13,13,14,15,15,15,15,15,15,14,7
1,1,1,1,7,16,13,13,13,13,13,14,7,2,3,5,1,1,1,1,1,1,1,1,1,1,1,1,1,13,13,13,13,13,13,13,13,13,13,14,7
1,1,1,1,7,16,13,13,13,13,13,14,7,2,5,5,1,1,1,1,1,1,1,1,1,1,1,1,1,13,13,13,13,13,13,13,13,13,13,14,7
1,1,1,1,7,16,13,13,4,13,13,14,7,2,2,2,1,1,1,1,1,1,1,1,1,1,1,1,1,13,13,13,4,13,13,13,4,13,13,14,7
1,1,1,1,7,16,13,13,13,13,13,14,7,16,13,13,13,13,13,13,13,13,13,13,13,13,13,14,7,17,13,13,13,13,13,13,13,13,13,14,7
1,1,1,1,7,16,13,13,13,13,13,14,7,16,13,13,13,13,13,13,13,13,13,13,13,13,13,14,7,16,13,13,13,13,13,13,13,13,13,14,7
1,1,1,1,7,16,17,17,17,17,17,17,7,16,13,13,13,13,13,13,13,13,13,13,13,13,13,14,7,16,13,13,13,13,13,13,13,13,13,14,7
7,7,7,7,7,7,7,7,7,7,7,7,7,16,13,13,4,13,13,13,4,13,13,13,4,13,13,14,7,16,13,13,4,13,13,13,4,13,13,14,7
7,15,15,15,15,15,15,15,15,15,15,14,7,16,13,13,13,13,13,13,13,13,13,13,13,13,13,14,7,16,13,13,13,13,13,13,13,13,13,14,7
7,16,13,13,13,13,13,13,13,13,13,14,7,16,13,13,13,13,13,13,13,13,13,13,13,13,13,14,7,16,13,13,13,13,13,13,13,13,13,14,7
7,16,13,13,13,13,13,13,13,13,13,14,7,16,13,13,13,13,13,13,13,13,13,13,13,13,13,14,7,16,17,17,17,17,17,17,17,17,17,14,7
7,16,13,13,4,13,13,13,4,13,13,14,7,16,13,13,4,13,13,13,4,13,13,13,4,13,13,14,7,7,7,7,7,7,7,7,7,7,7,7,7
7,16,13,13,13,13,13,13,13,13,13,14,7,16,13,13,13,13,13,13,13,13,13,13,13,13,13,14,7,15,15,15,15,15,15,15,7,1,1,1,1
7,16,13,13,13,13,13,13,13,13,13,14,7,16,13,13,13,13,13,13,13,13,13,13,13,13,13,14,7,16,13,13,13,13,13,14,7,1,1,1,1
7,16,13,13,13,13,13,13,13,13,13,14,7,16,13,13,13,13,13,13,13,13,13,13,13,13,13,14,7,16,13,13,13,13,13,14,7,1,1,1,1
7,16,13,13,4,13,13,13,4,13,13,14,7,16,13,13,4,13,13,13,4,13,13,13,4,13,13,14,7,16,13,13,4,13,13,14,7,1,1,1,1
7,16,13,13,13,13,13,13,13,13,13,14,7,16,13,13,13,13,13,13,13,13,13,13,13,13,13,14,7,16,13,13,13,13,13,14,7,1,1,1,1
7,16,13,13,13,13,13,13,13,13,13,14,7,16,13,13,13,13,13,13,13,13,13,13,13,13,13,14,7,16,13,13,13,13,13,14,7,1,1,1,1
7,16,13,13,13,13,13,13,13,13,13,14,7,16,13,13,13,13,13,13,13,14,17,17,17,17,17,17,7,16,17,17,17,17,17,17,7,1,1,1,1
7,2,2,2,1,1,1,1,1,1,1,1,1,1,1,1,1,1,1,1,1,7,7,7,7,7,7,7,7,7,7,7,7,7,7,7,7,1,1,1,1
1,5,5,5,1,1,1,1,1,1,1,1,1,1,1,1,1,1,1,1,1,15,15,15,15,15,15,15,15,15,15,14,7,1,1,1,1,1,1,1,1
1,5,3,5,1,1,1,1,1,1,1,1,1,1,1,1,1,1,1,1,1,13,13,13,13,13,13,13,13,13,13,14,7,1,1,1,1,1,1,1,1
1,5,5,5,1,1,1,1,1,1,1,1,1,1,1,1,1,1,1,1,1,13,13,13,13,13,13,13,13,13,13,14,7,1,1,1,1,1,1,1,1
1,5,5,5,1,1,1,1,1,1,1,1,1,1,1,1,1,1,1,1,1,13,13,13,4,13,13,13,4,13,13,14,7,1,1,1,1,1,1,1,1
1,5,5,5,1,1,1,1,1,1,1,1,1,1,1,1,1,1,1,1,1,13,13,13,13,13,13,13,13,13,13,14,7,1,1,1,1,1,1,1,1
1,5,3,5,1,1,1,1,1,1,1,1,1,1,1,1,1,1,1,1,1,13,13,13,13,13,13,13,13,13,13,14,7,1,1,1,1,1,1,1,1
1,5,5,5,1,1,1,1,1,1,1,1,1,1,1,1,1,1,1,1,1,13,13,13,13,13,13,13,13,13,13,14,7,1,1,1,1,1,1,1,1
1,5,5,5,1,1,1,1,1,1,1,1,1,1,1,1,1,1,1,1,1,13,13,13,4,13,13,13,4,13,13,14,7,1,1,1,1,1,1,1,1
1,5,5,5,1,1,1,1,1,1,1,1,1,1,1,1,1,1,1,1,1,13,13,13,13,13,13,13,13,13,13,14,7,1,1,1,1,1,1,1,1
1,5,3,5,1,1,1,1,1,1,1,1,1,1,1,1,1,1,1,1,1,13,13,13,13,13,13,13,13,13,13,14,7,1,1,1,1,1,1,1,1
1,5,5,5,1,1,1,1,1,1,1,1,1,1,1,1,1,1,1,1,1,13,13,13,14,17,17,17,17,17,17,14,7,1,1,1,1,1,1,1,1
1,5,5,5,1,1,1,1,1,1,1,1,1,1,1,1,1,1,1,1,1,2,2,2,7,7,7,7,7,7,7,7,7,1,1,1,1,1,1,1,1
1,5,5,5,1,1,1,1,1,1,1,1,1,1,1,1,1,1,1,1,1,5,5,5,1,1,1,1,1,1,1,1,1,1,1,1,1,1,1,1,1
1,5,3,5,1,1,1,1,1,1,1,1,1,1,1,1,1,1,1,1,1,5,3,5,1,1,1,1,1,1,1,1,1,1,1,1,1,1,1,1,1
1,5,5,5,1,1,1,1,1,1,1,1,1,1,1,1,1,1,1,1,1,5,5,5,1,1,1,1,1,1,1,1,1,1,1,1,1,1,1,1,1
1,5,5,5,1,1,1,1,1,1,1,1,1,1,1,1,1,1,1,1,1,5,5,5,1,1,1,1,1,1,1,1,1,1,1,1,1,1,1,1,1
1,5,5,5,5,5,5,5,5,5,5,5,5,5,5,5,5,5,5,5,5,5,5,5,1,1,1,1,1,1,1,1,1,1,1,1,1,1,1,1,1
1,5,3,5,5,5,3,5,5,5,3,5,5,5,3,5,5,5,3,5,5,5,3,5,1,1,1,1,1,1,1,1,1,1,1,1,1,1,1,1,1
1,5,5,5,5,5,5,5,5,5,5,5,5,5,5,5,5,5,5,5,5,5,5,5,1,1,1,1,1,1,1,1,1,1,1,1,1,1,1,1,1
1,1,1,1,1,1,1,1,1,1,1,1,1,1,1,1,1,1,1,1,1,1,1,1,1,1,1,1,1,1,1,1,1,1,1,1,1,1,1,1,1
endlayer

layer
1,1,1,1,1,1,1,1,1,1,1,1,1,1,1,1,1,1,1,1,1,1,1,1,1,1,1,1,1,1,1,1,1,1,1,1,1,1,1,1,1
1,1,1,1,1,1,1,1,1,1,1,1,1,1,1,1,1,1,1,1,1,1,1,1,1,1,1,1,1,1,1,1,1,1,1,1,1,1,1,1,1
1,1,1,1,1,1,1,1,1,1,1,1,1,1,1,1,1,1,1,1,1,1,1,1,1,1,1,1,1,1,1,1,1,1,1,1,1,1,1,1,1
1,1,1,1,1,1,1,1,1,1,1,1,1,1,1,1,1,1,1,1,1,1,1,1,1,1,1,1,1,1,1,1,1,1,1,1,1,1,1,1,1
1,1,1,1,1,1,1,1,1,1,1,1,1,1,1,1,1,1,1,1,1,1,1,1,1,1,1,1,1,1,1,1,1,1,1,1,1,1,1,1,1
1,1,1,1,1,1,1,1,1,1,1,1,1,1,1,1,1,1,1,1,1,1,1,1,1,1,1,1,1,1,1,1,1,1,1,1,1,1,1,1,1
1,1,1,1,1,1,1,1,1,1,1,1,1,1,1,1,1,1,1,1,1,1,1,1,1,1,1,1,1,1,1,1,1,1,1,1,1,1,1,1,1
1,1,1,1,1,1,1,1,1,1,1,1,1,1,1,1,1,1,1,1,1,1,1,1,1,1,1,1,1,1,1,1,1,1,1,1,1,1,1,1,1
1,1,1,1,1,1,1,1,1,1,1,1,1,1,1,1,1,1,1,1,1,1,1,1,1,1,1,1,1,1,1,1,1,1,1,1,1,1,1,1,1
1,1,1,1,1,1,1,1,1,1,1,1,1,1,1,1,1,1,1,1,1,1,1,1,1,1,1,1,1,1,1,1,1,1,1,1,1,1,1,1,1
1,1,1,1,1,1,1,1,1,1,1,1,1,1,1,1,1,1,1,1,1,1,1,1,1,1,1,1,1,1,1,1,1,1,1,1,1,1,1,1,1
1,1,1,1,1,1,1,1,1,1,1,1,1,1,1,1,1,1,1,1,1,1,1,1,1,1,1,1,1,1,1,1,1,1,1,1,1,1,1,1,1
1,1,1,1,2,4,2,2,2,2,2,4,2,1,1,1,1,1,1,1,1,1,1,1,1,1,1,1,1,2,2,2,2,2,4,2,2,2,2,4,2
1,1,1,1,4,3,0,0,0,0,0,3,4,1,1,1,1,1,1,1,1,1,1,1,1,1,1,1,1,0,0,0,0,0,3,0,0,0,0,3,4
1,1,1,1,2,0,0,0,0,0,0,0,2,1,1,1,1,1,1,1,1,1,1,1,1,1,1,1,1,0,0,0,0,0,0,0,0,0,0,0,2
1,1,1,1,2,0,0,0,0,0,0,0,2,1,1,1,1,1,1,1,1,1,1,1,1,1,1,1,1,0,0,0,0,0,0,0,0,0,0,0,2
1,1,1,1,2,0,0,0,3,0,0,0,2,2,2,0,1,1,1,1,1,1,1,1,1,1,1,1,1,0,0,0,3,0,0,0,3,0,0,0,2
1,1,1,1,2,0,0,0,0,0,0,0,2,0,0,0,0,0,0,0,0,0,0,0,0,0,0,0,2,0,0,0,0,0,0,0,0,0,0,0,2
1,1,1,1,2,0,0,0,0,0,0,0,2,0,0,0,0,0,0,0,0,0,0,0,0,0,0,0,4,3,0,0,0,0,0,0,0,0,0,3,4
1,1,1,1,4,3,0,0,0,0,0,3,4,0,0,0,0,0,0,0,0,0,0,0,0,0,0,0,2,0,0,0,0,0,0,0,0,0,0,0,2
2,4,2,2,2,2,4,2,2,2,2,4,2,0,0,0,3,0,0,0,3,0,0,0,3,0,0,0,2,0,0,0,3,0,0,0,3,0,0,0,2
4,3,0,0,0,0,3,0,0,0,0,0,2,0,0,0,0,0,0,0,0,0,0,0,0,0,0,0,2,0,0,0,0,0,0,0,0,0,0,0,2
2,0,0,0,0,0,0,0,0,0,0,0,4,3,0,0,0,0,0,0,0,0,0,0,0,0,0,3,4,0,0,0,0,0,0,0,0,0,0,0,2
2,0,0,0,0,0,0,0,0,0,0,0,2,0,0,0,0,0,0,0,0,0,0,0,0,0,0,0,2,0,0,0,0,0,3,0,0,0,0,3,4
2,0,0,0,3,0,0,0,3,0,0,0,2,0,0,0,3,0,0,0,3,0,0,0,3,0,0,0,2,4,2,2,2,2,4,2,2,2,2,4,2
2,0,0,0,0,0,0,0,0,0,0,0,2,0,0,0,0,0,0,0,0,0,0,0,0,0,0,0,4,3,0,0,0,0,0,3,4,1,1,1,1
4,3,0,0,0,0,0,0,0,0,0,0,4,3,0,0,0,0,0,0,0,0,0,0,0,0,0,3,2,0,0,0,0,0,0,0,2,1,1,1,1
2,0,0,0,0,0,0,0,0,0,0,0,2,0,0,0,0,0,0,0,0,0,0,0,0,0,0,0,2,0,0,0,0,0,0,0,2,1,1,1,1
2,0,0,0,3,0,0,0,3,0,0,0,2,0,0,0,3,0,0,0,3,0,0,0,3,0,0,0,2,0,0,0,3,0,0,0,2,1,1,1,1
2,0,0,0,0,0,0,0,0,0,0,0,2,0,0,0,0,0,0,0,0,0,0,0,0,0,0,0,2,0,0,0,0,0,0,0,2,1,1,1,1
2,0,0,0,0,0,0,0,0,0,0,0,4,3,0,0,0,0,0,0,0,0,0,0,0,0,0,0,2,0,0,0,0,0,0,0,2,1,1,1,1
4,3,0,0,0,0,0,0,0,0,0,0,2,0,0,0,0,0,0,0,0,0,3,0,0,0,0,3,4,3,0,0,0,0,0,3,4,1,1,1,1
2,2,2,2,1,1,1,1,1,1,1,1,1,1,1,1,1,1,1,1,1,2,4,2,2,2,4,2,2,4,2,2,2,2,2,4,2,1,1,1,1
1,1,1,1,1,1,1,1,1,1,1,1,1,1,1,1,1,1,1,1,1,0,0,0,0,0,3,0,0,0,0,3,4,1,1,1,1,1,1,1,1
1,1,1,1,1,1,1,1,1,1,1,1,1,1,1,1,1,1,1,1,1,0,0,0,0,0,0,0,0,0,0,0,2,1,1,1,1,1,1,1,1
1,1,1,1,1,1,1,1,1,1,1,1,1,1,1,1,1,1,1,1,1,0,0,0,0,0,0,0,0,0,0,0,2,1,1,1,1,1,1,1,1
1,1,1,1,1,1,1,1,1,1,1,1,1,1,1,1,1,1,1,1,1,0,0,0,3,0,0,0,3,0,0,0,2,1,1,1,1,1,1,1,1
1,1,1,1,1,1,1,1,1,1,1,1,1,1,1,1,1,1,1,1,1,0,0,0,0,0,0,0,0,0,0,0,2,1,1,1,1,1,1,1,1
1,1,1,1,1,1,1,1,1,1,1,1,1,1,1,1,1,1,1,1,1,0,0,0,0,0,0,0,0,0,0,3,4,1,1,1,1,1,1,1,1
1,1,1,1,1,1,1,1,1,1,1,1,1,1,1,1,1,1,1,1,1,0,0,0,0,0,0,0,0,0,0,0,2,1,1,1,1,1,1,1,1
1,1,1,1,1,1,1,1,1,1,1,1,1,1,1,1,1,1,1,1,1,0,0,0,3,0,0,0,3,0,0,0,2,1,1,1,1,1,1,1,1
1,1,1,1,1,1,1,1,1,1,1,1,1,1,1,1,1,1,1,1,1,0,0,0,0,0,0,0,0,0,0,0,2,1,1,1,1,1,1,1,1
1,1,1,1,1,1,1,1,1,1,1,1,1,1,1,1,1,1,1,1,1,0,0,0,0,0,0,0,0,0,0,0,2,1,1,1,1,1,1,1,1
1,1,1,1,1,1,1,1,1,1,1,1,1,1,1,1,1,1,1,1,1,0,0,0,0,0,3,0,0,0,0,3,4,1,1,1,1,1,1,1,1
1,1,1,1,1,1,1,1,1,1,1,1,1,1,1,1,1,1,1,1,1,2,2,2,2,2,4,2,2,2,2,4,2,1,1,1,1,1,1,1,1
1,1,1,1,1,1,1,1,1,1,1,1,1,1,1,1,1,1,1,1,1,1,1,1,1,1,1,1,1,1,1,1,1,1,1,1,1,1,1,1,1
1,1,1,1,1,1,1,1,1,1,1,1,1,1,1,1,1,1,1,1,1,1,1,1,1,1,1,1,1,1,1,1,1,1,1,1,1,1,1,1,1
1,1,1,1,1,1,1,1,1,1,1,1,1,1,1,1,1,1,1,1,1,1,1,1,1,1,1,1,1,1,1,1,1,1,1,1,1,1,1,1,1
1,1,1,1,1,1,1,1,1,1,1,1,1,1,1,1,1,1,1,1,1,1,1,1,1,1,1,1,1,1,1,1,1,1,1,1,1,1,1,1,1
1,1,1,1,1,1,1,1,1,1,1,1,1,1,1,1,1,1,1,1,1,1,1,1,1,1,1,1,1,1,1,1,1,1,1,1,1,1,1,1,1
1,1,1,1,1,1,1,1,1,1,1,1,1,1,1,1,1,1,1,1,1,1,1,1,1,1,1,1,1,1,1,1,1,1,1,1,1,1,1,1,1
1,1,1,1,1,1,1,1,1,1,1,1,1,1,1,1,1,1,1,1,1,1,1,1,1,1,1,1,1,1,1,1,1,1,1,1,1,1,1,1,1
1,1,1,1,1,1,1,1,1,1,1,1,1,1,1,1,1,1,1,1,1,1,1,1,1,1,1,1,1,1,1,1,1,1,1,1,1,1,1,1,1
endlayer

