# Gilly's Brickyard

weight=1
embed_into_distance=3
unacceptable_target_blocks=flowing_water,water,flowing_lava,lava,ice,bedrock,netherrack,soul_sand,Natura:Cloud
dimensions=13,11,15
cut_in_buffer=0
max_leveling=3
leveling_buffer=-1
preserve_water=0
preserve_lava=0
preserve_plants=0

rule1=0,100,preserveBlock
rule2=0,100,stonebrick,stonebrick,stonebrick,stonebrick,stonebrick,stonebrick,stonebrick-2
rule3=0,100,brick_block
rule4=0,100,log
rule5=0,100,planks
rule6=0,100,planks-1
rule7=0,100,planks-5
rule8=0,100,iron_bars
rule9=0,100,wooden_slab-5


rule10=0,100,wooden_door-2
rule11=0,100,wooden_door-8
rule12=0,100,torch-5
rule13=0,100,furnace-2
rule14=0,100,cobblestone_wall
rule15=0,100,cauldron
rule16=0,100,fence
rule17=0,100,nether_brick_fence

layer
1,1,1,1,2,2,1,1,1,1,1,1,2,2,1
1,2,2,2,2,2,2,2,2,2,2,2,2,2,1
1,2,1,1,1,1,1,1,1,1,1,1,1,2,1
1,14,1,1,1,1,1,1,1,1,1,1,1,14,1
1,2,1,1,1,1,1,1,1,1,1,1,1,2,1
1,2,1,1,1,1,1,1,1,1,1,1,1,14,1
1,2,1,1,1,1,1,1,1,1,1,1,1,2,2
1,14,1,1,1,1,1,1,2,2,2,2,2,2,2
1,2,1,1,1,1,1,1,2,1,1,1,1,1,2
1,2,2,2,2,14,2,2,2,1,1,1,1,1,2
1,1,1,1,1,1,1,2,2,2,2,2,2,2,2
endlayer

layer
1,1,1,1,1,2,2,1,1,1,1,2,2,1,1
1,2,2,2,2,2,2,2,2,2,2,2,2,2,1
1,2,1,1,1,1,1,1,1,1,1,1,1,2,1
1,14,1,1,1,1,1,1,1,1,1,1,1,14,1
1,2,1,1,1,1,1,1,1,1,1,1,1,2,1
1,2,1,1,1,1,1,1,1,1,1,1,1,14,1
1,2,1,1,1,1,1,1,1,1,1,1,1,2,1
1,14,1,1,1,1,1,1,2,2,2,2,2,2,2
1,2,1,1,1,1,1,1,2,1,1,1,1,1,2
1,2,2,2,2,14,2,2,2,1,1,1,1,1,2
1,1,1,1,1,1,1,1,2,2,2,2,2,2,2
endlayer

layer
1,1,1,1,1,1,2,2,1,1,2,2,1,1,1
1,2,2,2,2,2,2,2,2,2,2,2,2,2,1
1,2,1,1,1,1,1,1,1,1,1,1,1,2,1
1,14,1,1,1,1,1,1,1,1,1,1,1,14,1
1,2,1,1,1,1,1,1,1,1,1,1,1,2,1
1,2,1,1,1,1,1,1,1,1,1,1,1,14,1
1,2,1,1,1,1,1,1,1,1,1,1,1,2,1
1,14,1,1,1,1,1,1,2,2,2,2,2,2,1
1,2,1,1,1,1,1,1,2,2,2,2,2,2,2
1,2,2,2,2,14,2,2,2,2,2,2,2,2,2
1,1,1,1,1,1,1,1,1,2,2,2,2,2,2
endlayer

layer
1,1,1,1,1,1,1,2,2,2,2,1,1,1,1
1,2,2,2,2,2,2,2,2,2,2,2,2,2,1
1,2,2,2,2,2,2,2,2,2,2,2,2,2,1
1,2,2,2,2,2,2,2,2,2,2,2,2,2,1
1,2,2,2,2,2,2,2,2,2,2,2,2,2,1
1,2,2,2,2,2,2,2,2,2,2,2,2,2,1
1,2,2,2,2,2,2,2,2,2,2,2,2,2,1
1,2,2,2,2,2,2,2,2,2,2,2,2,2,1
1,2,2,2,2,2,2,2,2,2,2,2,2,2,1
1,2,2,2,2,2,2,2,2,2,2,2,2,2,1
1,1,1,1,1,1,1,1,1,1,1,1,1,1,1
endlayer

layer
0,0,0,0,0,0,0,0,0,0,0,0,0,0,0
1,4,3,4,3,3,3,3,10,10,3,4,3,4,0
1,3,0,0,0,0,0,0,0,0,0,0,0,3,0
1,3,0,0,0,0,0,0,0,0,0,0,0,3,0
1,3,0,0,0,0,0,0,0,0,12,0,0,3,0
1,4,15,0,12,0,0,0,0,0,0,0,0,3,0
1,3,0,0,0,0,0,0,0,0,0,0,0,3,0
1,3,0,0,0,0,0,0,4,3,10,10,3,4,0
1,3,0,0,0,0,0,0,3,0,0,0,0,0,0
1,4,3,4,3,3,3,3,4,0,0,0,0,0,0
0,0,0,0,0,0,0,0,0,0,0,0,0,0,0
endlayer

layer
0,0,0,0,0,0,0,0,0,0,0,0,0,0,0
1,4,5,4,5,0,0,5,11,11,5,4,5,4,0
1,5,0,0,0,0,0,0,0,0,0,0,0,5,0
1,0,0,0,0,0,0,0,0,0,0,0,0,0,0
1,5,0,0,0,0,0,0,0,0,0,0,0,0,0
1,4,13,0,0,0,0,0,0,0,0,0,0,0,0
1,5,0,0,0,0,0,0,0,0,0,0,0,5,0
1,0,0,0,0,0,0,0,4,5,11,11,5,4,0
1,5,0,0,0,0,0,0,5,0,0,0,0,0,0
1,4,5,4,5,5,5,5,4,0,0,0,0,0,0
0,0,0,0,0,0,0,0,0,0,0,0,0,0,0
endlayer

layer
0,0,0,0,0,0,0,0,0,0,0,0,0,0,0
1,4,5,4,5,8,8,5,16,16,5,4,5,4,0
1,5,0,0,0,0,0,0,0,0,0,0,0,5,0
1,8,0,0,0,0,0,0,0,0,0,0,0,8,0
1,5,0,0,0,0,0,0,0,0,0,0,0,8,0
1,4,14,0,0,0,0,0,0,0,0,0,0,8,0
1,5,0,0,0,0,0,0,0,0,0,0,0,5,0
1,8,0,0,0,0,0,0,4,5,16,16,5,4,0
1,5,0,0,0,0,0,0,5,0,0,0,0,0,0
1,4,5,4,5,8,8,5,4,0,0,0,0,0,0
0,0,0,0,0,0,0,0,0,0,0,0,0,0,0
endlayer

layer
0,0,0,0,0,0,0,0,0,0,0,0,0,0,0
1,4,5,4,5,5,5,5,5,5,5,4,5,4,0
1,5,0,0,0,0,0,0,0,0,0,0,0,5,0
1,5,0,0,0,0,0,0,0,0,0,0,0,5,0
1,5,0,0,0,0,0,0,0,0,0,0,0,5,0
1,4,14,0,0,0,0,0,0,0,0,0,0,5,0
1,5,0,0,0,0,0,0,0,0,0,0,0,5,0
1,5,0,0,0,0,0,0,4,5,5,5,5,4,0
1,5,0,0,0,0,0,0,5,0,0,0,0,0,0
1,4,5,4,5,5,5,5,4,0,0,0,0,0,0
0,0,0,0,0,0,0,0,0,0,0,0,0,0,0
endlayer

layer
9,9,9,9,9,9,9,9,9,9,9,9,9,9,9
9,7,7,7,7,7,7,7,7,7,7,7,7,7,9
9,7,6,6,6,6,6,6,6,6,6,6,6,7,9
9,7,6,6,6,6,6,6,6,6,6,6,6,7,9
9,7,6,6,6,6,6,6,6,6,6,6,6,7,9
9,7,6,6,6,6,6,6,6,6,6,6,6,7,9
9,7,6,6,6,6,6,6,6,6,6,6,6,7,9
9,7,6,6,6,6,6,6,7,7,7,7,7,7,9
9,7,6,6,6,6,6,6,7,9,9,9,9,9,9
9,7,7,7,7,7,7,7,7,9,0,0,0,0,0
9,9,9,9,9,9,9,9,9,9,0,0,0,0,0
endlayer

layer
0,0,0,0,0,0,0,0,0,0,0,0,0,0,0
0,17,17,17,17,17,17,17,17,17,17,17,17,17,0
0,17,9,9,9,9,9,9,9,9,9,9,9,17,0
0,17,9,9,9,9,9,9,9,9,9,9,9,17,0
0,17,9,9,9,9,9,9,9,9,9,9,9,17,0
0,17,14,9,9,9,9,9,9,9,9,9,9,17,0
0,17,9,9,9,9,9,9,9,9,9,9,9,17,0
0,17,9,9,9,9,9,9,17,17,17,17,17,17,0
0,17,9,9,9,9,9,9,17,0,0,0,0,0,0
0,17,17,17,17,17,17,17,17,0,0,0,0,0,0
0,0,0,0,0,0,0,0,0,0,0,0,0,0,0
endlayer

layer
0,0,0,0,0,0,0,0,0,0,0,0,0,0,0
0,0,0,0,0,0,0,0,0,0,0,0,0,0,0
0,0,0,0,0,0,0,0,0,0,0,0,0,0,0
0,0,0,0,0,0,0,0,0,0,0,0,0,0,0
0,0,0,0,0,0,0,0,0,0,0,0,0,0,0
0,0,14,0,0,0,0,0,0,0,0,0,0,0,0
0,0,0,0,0,0,0,0,0,0,0,0,0,0,0
0,0,0,0,0,0,0,0,0,0,0,0,0,0,0
0,0,0,0,0,0,0,0,0,0,0,0,0,0,0
0,0,0,0,0,0,0,0,0,0,0,0,0,0,0
0,0,0,0,0,0,0,0,0,0,0,0,0,0,0
endlayer

layer
0,0,0,0,0,0,0,0,0,0,0,0,0,0,0
0,0,0,0,0,0,0,0,0,0,0,0,0,0,0
0,0,0,0,0,0,0,0,0,0,0,0,0,0,0
0,0,0,0,0,0,0,0,0,0,0,0,0,0,0
0,0,0,0,0,0,0,0,0,0,0,0,0,0,0
0,0,14,0,0,0,0,0,0,0,0,0,0,0,0
0,0,0,0,0,0,0,0,0,0,0,0,0,0,0
0,0,0,0,0,0,0,0,0,0,0,0,0,0,0
0,0,0,0,0,0,0,0,0,0,0,0,0,0,0
0,0,0,0,0,0,0,0,0,0,0,0,0,0,0
0,0,0,0,0,0,0,0,0,0,0,0,0,0,0
endlayer

layer
0,0,0,0,0,0,0,0,0,0,0,0,0,0,0
0,0,0,0,0,0,0,0,0,0,0,0,0,0,0
0,0,0,0,0,0,0,0,0,0,0,0,0,0,0
0,0,0,0,0,0,0,0,0,0,0,0,0,0,0
0,0,0,0,0,0,0,0,0,0,0,0,0,0,0
0,0,14,0,0,0,0,0,0,0,0,0,0,0,0
0,0,0,0,0,0,0,0,0,0,0,0,0,0,0
0,0,0,0,0,0,0,0,0,0,0,0,0,0,0
0,0,0,0,0,0,0,0,0,0,0,0,0,0,0
0,0,0,0,0,0,0,0,0,0,0,0,0,0,0
0,0,0,0,0,0,0,0,0,0,0,0,0,0,0
endlayer

