# Gilly's Skyport landing
# template generated by Ruins mod version 14.6 Ingame Parser
# Structure created by Gilly

weight=1
embed_into_distance=4
acceptable_target_blocks=
unacceptable_target_blocks=flowing_water,water,flowing_lava,lava,ice,bedrock,netherrack,soul_sand,Natura:Cloud
dimensions=24,18,23
allowable_overhang=0
max_leveling=4
leveling_buffer=-1
preserve_water=0
preserve_lava=0

rule1=0,100,preserveBlock
rule2=0,100,minecraft:stained_hardened_clay-9
rule3=0,100,minecraft:iron_bars-0
rule4=0,100,minecraft:stained_hardened_clay-4
rule5=0,100,minecraft:glowstone-0
rule6=0,100,minecraft:ladder-5
rule7=0,100,minecraft:ladder-4
rule8=0,100,minecraft:stained_glass_pane-3
rule9=0,100,minecraft:stone_brick_stairs-2
rule10=0,100,minecraft:stonebrick-0
rule11=0,100,minecraft:stone_slab-5
rule12=0,100,minecraft:stone_slab-13
rule13=0,100,minecraft:stained_hardened_clay-3
rule14=0,100,minecraft:double_stone_slab-8

layer
1,1,1,1,1,1,1,1,1,1,1,1,1,1,1,1,1,1,1,1,1,1,1
1,1,1,1,1,1,1,1,1,1,1,1,1,1,2,1,1,1,1,1,1,1,1
1,1,1,1,1,1,1,1,2,2,2,2,2,2,2,2,1,1,1,1,1,1,1
1,1,1,1,1,1,1,1,2,2,2,2,2,2,2,2,1,1,1,1,1,1,1
2,2,2,2,2,2,2,2,2,2,3,3,3,2,2,2,2,1,1,1,1,1,1
2,2,2,2,2,2,2,2,2,2,3,4,3,2,2,2,2,1,1,1,1,1,1
2,2,2,2,2,2,2,2,2,2,3,3,3,2,2,2,2,2,1,1,1,1,1
2,2,2,2,2,2,2,2,2,2,0,0,0,2,2,2,2,2,1,1,1,1,1
2,2,2,2,2,2,2,2,2,0,0,0,0,0,2,2,2,2,1,1,1,1,1
2,2,2,2,2,2,2,2,6,3,0,0,0,0,2,5,2,2,1,1,1,1,1
2,2,2,2,2,2,2,2,7,3,0,0,0,0,2,2,2,1,1,1,1,1,1
2,2,2,2,2,2,2,2,2,0,0,0,0,0,2,2,2,1,1,1,1,1,1
2,2,2,2,2,2,2,2,2,2,2,2,2,2,2,2,1,1,1,1,1,1,1
2,2,2,2,2,2,2,2,2,2,1,1,1,1,1,2,1,1,1,1,1,1,1
2,2,2,2,2,2,2,2,2,2,1,1,1,1,1,1,1,1,1,1,1,1,1
2,2,2,2,2,2,2,2,2,2,1,1,1,1,1,1,1,1,1,1,1,1,1
1,1,1,1,1,1,1,1,1,1,1,1,1,1,1,1,1,1,1,1,1,1,1
1,1,1,1,1,1,1,1,1,1,1,1,1,1,1,1,1,1,1,1,1,1,1
endlayer

layer
1,1,1,1,1,1,1,1,1,1,1,1,1,1,2,1,1,1,1,1,1,1,1
1,1,1,1,1,1,1,1,1,2,2,2,2,2,2,2,1,1,1,1,1,1,1
1,1,1,1,1,1,1,1,2,2,2,2,2,2,2,2,1,1,1,1,1,1,1
1,1,1,1,1,1,1,2,2,2,2,2,2,2,2,2,2,1,1,1,1,1,1
1,1,1,1,1,1,1,2,2,2,3,3,3,2,2,2,2,1,1,1,1,1,1
1,2,2,2,2,2,2,2,2,2,3,0,3,2,2,2,2,2,1,1,1,1,1
1,9,8,2,2,2,2,2,2,2,3,3,3,2,2,2,2,2,1,1,1,1,1
1,9,8,5,2,2,2,2,2,2,0,0,0,2,2,2,2,2,1,1,1,1,1
1,9,8,2,2,2,2,2,2,0,0,0,0,0,10,8,2,2,1,1,1,1,1
1,9,8,2,2,2,2,2,6,3,0,0,0,0,10,8,2,2,1,1,1,1,1
1,9,8,2,2,2,2,2,7,3,0,0,0,0,10,8,2,2,1,1,1,1,1
1,9,8,2,2,2,2,2,2,0,0,0,0,0,10,8,2,1,1,1,1,1,1
1,9,8,5,2,2,2,2,2,2,2,2,2,2,2,2,2,1,1,1,1,1,1
1,9,8,2,2,2,2,2,2,2,2,2,2,2,2,2,1,1,1,1,1,1,1
1,2,2,2,2,2,2,2,2,1,1,1,1,1,1,1,1,1,1,1,1,1,1
1,1,1,1,1,1,1,1,1,1,1,1,1,1,1,1,1,1,1,1,1,1,1
1,1,1,1,1,1,1,1,1,1,1,1,1,1,1,1,1,1,1,1,1,1,1
1,1,1,1,1,1,1,1,1,1,1,1,1,1,1,1,1,1,1,1,1,1,1
endlayer

layer
1,1,1,1,1,1,1,1,1,1,1,1,1,1,2,1,1,1,1,1,1,1,1
1,1,1,1,1,1,1,1,1,1,1,1,1,1,2,2,1,1,1,1,1,1,1
1,1,1,1,1,1,1,1,2,3,3,3,3,3,2,2,2,1,1,1,1,1,1
1,1,1,1,1,1,1,1,3,2,2,2,2,2,2,2,2,1,1,1,1,1,1
1,1,1,1,1,1,1,1,3,2,3,3,3,2,2,2,2,2,1,1,1,1,1
1,1,1,1,1,1,1,1,3,2,3,0,3,2,2,2,2,2,1,1,1,1,1
1,1,11,2,2,2,2,2,2,2,3,3,3,2,2,2,2,2,1,1,1,1,1
1,1,11,9,8,2,2,2,2,2,0,0,0,2,2,2,2,2,1,1,1,1,1
1,1,11,9,8,5,2,2,2,0,0,0,0,0,12,8,2,2,2,1,1,1,1
1,1,11,9,8,2,2,2,6,3,0,0,0,0,12,8,2,2,1,1,1,1,1
1,1,11,9,8,2,2,2,7,3,0,0,0,0,12,8,2,2,1,1,1,1,1
1,1,11,9,8,5,2,2,2,0,0,0,0,0,12,8,2,2,1,1,1,1,1
1,1,11,9,8,2,2,2,2,2,2,2,2,2,2,2,2,1,1,1,1,1,1
1,1,11,2,2,2,2,2,2,1,1,1,1,1,1,2,1,1,1,1,1,1,1
1,1,1,1,1,1,1,1,1,1,1,1,1,1,1,1,1,1,1,1,1,1,1
1,1,1,1,1,1,1,1,1,1,1,1,1,1,1,1,1,1,1,1,1,1,1
1,1,1,1,1,1,1,1,1,1,1,1,1,1,1,1,1,1,1,1,1,1,1
1,1,1,1,1,1,1,1,1,1,1,1,1,1,1,1,1,1,1,1,1,1,1
endlayer

layer
1,1,1,1,1,1,1,1,1,1,1,1,1,1,2,1,1,1,1,1,1,1,1
1,1,1,1,1,1,1,1,1,2,2,2,2,2,2,2,1,1,1,1,1,1,1
1,1,1,1,1,1,1,1,2,2,2,2,2,2,2,2,2,1,1,1,1,1,1
1,1,1,1,1,1,1,2,2,2,2,2,2,2,2,2,2,1,1,1,1,1,1
1,1,1,1,1,1,1,2,2,2,3,3,3,2,2,2,2,2,1,1,1,1,1
1,1,1,1,1,1,1,2,2,2,3,4,3,2,2,2,2,2,1,1,1,1,1
1,1,1,1,1,1,1,2,2,2,3,3,3,2,2,2,2,2,2,1,1,1,1
1,1,1,1,11,2,2,2,2,2,0,0,0,2,2,2,2,2,1,1,1,1,1
1,1,1,1,11,9,8,5,2,0,0,0,0,0,12,8,2,2,2,1,1,1,1
1,1,1,1,11,9,8,2,6,3,0,0,0,0,12,8,2,2,1,1,1,1,1
1,1,1,1,11,9,8,2,7,3,0,0,0,0,12,8,2,2,2,1,1,1,1
1,1,1,1,11,9,8,5,2,0,0,0,0,0,12,8,2,2,1,1,1,1,1
1,1,1,1,11,2,2,2,2,2,2,2,2,2,2,2,2,1,1,1,1,1,1
1,1,1,1,1,1,1,1,2,2,2,2,2,2,2,2,1,1,1,1,1,1,1
1,1,1,1,1,1,1,1,1,1,1,1,1,1,1,1,1,1,1,1,1,1,1
1,1,1,1,1,1,1,1,1,1,1,1,1,1,1,1,1,1,1,1,1,1,1
1,1,1,1,1,1,1,1,1,1,1,1,1,1,1,1,1,1,1,1,1,1,1
1,1,1,1,1,1,1,1,1,1,1,1,1,1,1,1,1,1,1,1,1,1,1
endlayer

layer
1,1,1,1,1,1,1,1,1,1,1,1,1,1,2,1,1,1,1,1,1,1,1
1,1,1,1,1,1,1,1,1,1,1,1,1,1,2,2,1,1,1,1,1,1,1
1,1,1,1,1,1,1,1,2,3,3,3,3,3,2,2,2,1,1,1,1,1,1
1,1,1,1,1,1,1,1,3,2,2,2,2,2,2,2,2,1,1,1,1,1,1
1,1,1,1,1,1,1,1,3,2,3,3,3,2,2,2,2,2,1,1,1,1,1
1,1,1,1,1,1,1,1,3,2,3,4,3,2,2,2,2,2,1,1,1,1,1
1,1,1,1,1,1,1,1,3,2,3,3,3,2,2,2,2,2,2,1,1,1,1
1,1,1,1,1,1,2,2,2,2,0,0,0,2,2,2,2,2,1,1,1,1,1
1,1,1,1,1,1,11,2,2,0,0,0,0,0,12,8,2,2,2,1,1,1,1
1,1,1,1,1,1,11,2,6,3,0,0,0,0,12,8,2,2,1,1,1,1,1
1,1,1,1,1,1,11,2,7,3,0,0,0,0,12,8,2,2,2,1,1,1,1
1,1,1,1,1,1,11,2,2,0,0,0,0,0,12,8,2,2,1,1,1,1,1
1,1,1,1,1,1,2,2,2,2,2,2,2,2,2,2,2,1,1,1,1,1,1
1,1,1,1,1,1,1,1,2,1,1,1,1,1,1,2,1,1,1,1,1,1,1
1,1,1,1,1,1,1,1,1,1,1,1,1,1,1,1,1,1,1,1,1,1,1
1,1,1,1,1,1,1,1,1,1,1,1,1,1,1,1,1,1,1,1,1,1,1
1,1,1,1,1,1,1,1,1,1,1,1,1,1,1,1,1,1,1,1,1,1,1
1,1,1,1,1,1,1,1,1,1,1,1,1,1,1,1,1,1,1,1,1,1,1
endlayer

layer
1,1,1,1,1,1,1,1,1,1,1,1,1,1,2,1,1,1,1,1,1,1,1
1,1,1,1,1,1,1,1,1,2,2,2,2,2,2,2,1,1,1,1,1,1,1
1,1,1,1,1,1,1,1,2,2,2,2,2,2,2,2,2,1,1,1,1,1,1
1,1,1,1,1,1,1,2,2,2,2,2,2,2,2,2,2,1,1,1,1,1,1
1,1,1,1,1,1,1,2,2,2,3,3,3,2,2,2,2,2,1,1,1,1,1
1,1,1,1,1,1,1,2,2,2,3,0,3,2,2,2,2,2,1,1,1,1,1
1,1,1,1,1,1,1,2,2,2,3,3,3,2,2,2,2,2,2,1,1,1,1
1,1,1,1,1,1,2,2,2,2,0,0,0,2,2,2,2,2,1,1,1,1,1
1,1,1,1,1,1,1,1,2,0,0,0,0,0,12,8,2,2,2,1,1,1,1
1,1,1,1,1,1,1,1,6,3,0,0,0,0,12,8,2,2,1,1,1,1,1
1,1,1,1,1,1,1,1,7,3,0,0,0,0,12,8,2,2,2,1,1,1,1
1,1,1,1,1,1,1,1,2,0,0,0,0,0,12,8,2,2,1,1,1,1,1
1,1,1,1,1,1,2,2,2,2,2,2,2,2,2,2,2,1,1,1,1,1,1
1,1,1,1,1,1,1,1,2,2,2,2,2,2,2,2,1,1,1,1,1,1,1
1,1,1,1,1,1,1,1,1,1,1,1,1,1,1,1,1,1,1,1,1,1,1
1,1,1,1,1,1,1,1,1,1,1,1,1,1,1,1,1,1,1,1,1,1,1
1,1,1,1,1,1,1,1,1,1,1,1,1,1,1,1,1,1,1,1,1,1,1
1,1,1,1,1,1,1,1,1,1,1,1,1,1,1,1,1,1,1,1,1,1,1
endlayer

layer
1,1,1,1,1,1,1,1,1,1,1,1,1,1,2,1,1,1,1,1,1,1,1
1,1,1,1,1,1,1,1,1,1,1,1,1,1,2,2,1,1,1,1,1,1,1
1,1,1,1,1,1,1,1,2,3,3,3,3,3,2,2,2,1,1,1,1,1,1
1,1,1,1,1,1,1,1,3,2,2,2,2,2,2,2,2,1,1,1,1,1,1
1,1,1,1,1,1,1,1,3,2,3,3,3,2,2,2,2,2,1,1,1,1,1
1,1,1,0,0,1,1,1,3,2,3,0,3,2,2,2,2,2,1,1,1,1,1
1,1,0,0,0,0,1,1,3,2,3,3,3,2,2,2,2,2,2,1,1,1,1
1,1,0,0,0,0,2,2,2,2,0,0,0,2,2,2,2,2,2,1,1,1,1
1,1,0,0,0,0,0,0,2,0,0,0,0,0,12,8,2,2,2,1,1,1,1
1,1,0,0,0,0,0,0,6,3,0,0,0,0,12,8,2,2,2,1,1,1,1
1,1,0,0,0,0,0,0,7,3,0,0,0,0,12,8,2,2,2,1,1,1,1
1,1,0,0,0,0,0,0,2,0,0,0,0,0,12,8,2,2,1,1,1,1,1
1,1,1,0,0,0,2,2,2,2,2,2,2,2,2,2,2,1,1,1,1,1,1
1,1,1,1,1,1,1,1,2,1,1,1,1,1,1,2,1,1,1,1,1,1,1
1,1,1,1,1,1,1,1,1,1,1,1,1,1,1,1,1,1,1,1,1,1,1
1,1,1,1,1,1,1,1,1,1,1,1,1,1,1,1,1,1,1,1,1,1,1
1,1,1,1,1,1,1,1,1,1,1,1,1,1,1,1,1,1,1,1,1,1,1
1,1,1,1,1,1,1,1,1,1,1,1,1,1,1,1,1,1,1,1,1,1,1
endlayer

layer
1,1,1,1,1,1,1,1,1,1,1,1,1,1,2,2,1,1,1,1,1,1,1
1,1,1,1,1,1,1,1,1,2,2,2,2,2,2,2,2,1,1,1,1,1,1
1,1,1,0,0,0,0,1,2,2,2,2,2,2,2,2,2,2,0,1,1,1,1
1,1,0,0,0,0,0,2,2,2,2,2,2,2,2,2,2,2,0,0,1,1,1
1,1,0,0,0,0,0,2,2,2,3,3,3,2,2,2,2,2,2,0,0,1,1
1,0,0,0,0,0,0,2,2,2,3,4,3,2,2,2,2,2,2,0,0,1,1
1,0,0,0,0,0,0,2,2,2,3,3,3,2,2,2,2,2,2,0,0,0,1
0,0,0,0,0,0,2,2,2,2,0,0,0,2,2,2,2,2,2,0,0,0,1
0,0,0,0,0,0,0,0,2,0,0,0,0,0,10,2,2,2,2,0,0,0,0
0,0,0,0,0,0,0,0,6,3,0,0,0,0,10,5,2,2,2,0,0,0,0
0,0,0,0,0,0,0,0,7,3,0,0,0,0,10,2,2,2,2,0,0,0,0
1,0,0,0,0,0,0,0,2,0,0,0,0,0,10,2,2,2,2,0,0,0,1
1,0,0,0,0,0,2,2,2,2,2,2,2,2,2,2,2,0,0,0,0,0,1
1,1,0,0,0,0,0,0,2,2,2,2,2,2,2,2,0,0,0,0,0,1,1
1,1,0,0,0,0,0,0,0,0,0,0,0,0,0,0,0,0,0,0,0,1,1
1,1,1,0,0,0,0,0,0,0,0,0,0,0,0,0,0,0,0,0,1,1,1
1,1,1,1,1,0,0,0,0,0,0,0,0,0,0,0,0,0,1,1,1,1,1
1,1,1,1,1,1,1,1,0,0,0,0,0,0,0,0,1,1,1,1,1,1,1
endlayer

layer
1,1,1,1,0,0,0,0,0,0,0,0,0,0,2,0,0,0,1,1,1,1,1
1,1,0,0,0,0,0,0,0,0,0,0,0,0,2,2,0,0,0,0,1,1,1
1,0,0,0,0,0,0,0,2,2,2,2,2,2,2,2,2,0,0,0,0,1,1
1,0,0,0,0,0,0,0,2,2,2,2,2,2,2,2,2,2,0,0,0,0,1
0,0,0,0,0,0,0,0,2,2,3,3,3,2,2,2,2,2,0,0,0,0,1
0,0,0,0,0,0,0,0,2,2,3,4,3,2,2,2,2,2,2,0,0,0,0
0,0,0,0,0,0,0,0,2,2,3,3,3,2,2,2,2,2,2,0,0,0,0
0,0,0,0,0,0,2,2,2,2,0,0,0,2,2,2,2,2,2,0,0,0,0
0,0,0,0,0,0,0,0,2,0,0,0,0,0,0,11,2,2,2,0,0,0,0
0,0,0,0,0,0,0,0,6,3,0,0,0,0,0,11,2,2,2,0,0,0,0
0,0,0,0,0,0,0,0,7,3,0,0,0,0,0,11,2,2,2,0,0,0,0
0,0,0,0,0,0,0,0,2,0,0,0,0,0,0,11,2,2,2,0,0,0,0
0,0,0,0,0,0,2,2,2,2,2,2,2,2,2,2,2,0,0,0,0,0,0
0,0,0,0,0,0,0,0,2,0,0,0,0,0,0,2,0,0,0,0,0,0,0
1,0,0,0,0,0,0,0,0,0,0,0,0,0,0,0,0,0,0,0,0,0,1
1,0,0,0,0,0,0,0,0,0,0,0,0,0,0,0,0,0,0,0,0,0,1
1,1,0,0,0,0,0,0,0,0,0,0,0,0,0,0,0,0,0,0,0,1,1
1,1,1,1,0,0,0,0,0,0,0,0,0,0,0,0,0,0,0,1,1,1,1
endlayer

layer
1,1,0,0,0,0,0,0,0,0,0,0,0,0,2,0,0,0,0,0,0,1,1
1,0,0,0,0,0,0,0,0,0,0,0,0,0,2,2,0,0,0,0,0,0,1
0,0,0,0,0,0,0,0,0,0,0,0,0,0,0,2,2,0,0,0,0,0,0
0,0,0,0,0,0,0,0,0,0,0,0,0,0,0,2,2,0,0,0,0,0,0
0,0,0,0,0,0,0,0,0,0,0,0,0,0,0,0,2,2,0,0,0,0,0
0,0,0,0,0,0,0,0,0,0,0,0,0,0,0,0,2,2,0,0,0,0,0
0,0,0,0,0,0,0,0,0,3,3,3,3,3,3,3,2,2,2,0,0,0,0
0,0,0,0,0,0,2,2,0,3,0,0,0,0,0,0,0,0,0,0,0,0,0
0,0,0,0,0,0,0,0,2,3,0,0,0,0,0,0,0,0,0,0,0,0,0
0,0,0,0,0,0,0,0,6,3,0,0,0,0,0,0,0,0,0,0,0,0,0
0,0,0,0,0,0,0,0,7,3,0,0,0,0,0,0,0,0,0,0,0,0,0
0,0,0,0,0,0,0,0,2,3,0,0,0,0,0,0,2,2,2,0,0,0,0
0,0,0,0,0,0,2,2,2,2,3,3,3,3,3,2,2,0,0,0,0,0,0
0,0,0,0,0,0,0,0,2,0,0,0,0,0,0,2,0,0,0,0,0,0,0
0,0,0,0,0,0,0,0,0,0,0,0,0,0,0,0,0,0,0,0,0,0,0
0,0,0,0,0,0,0,0,0,0,0,0,0,0,0,0,0,0,0,0,0,0,0
1,0,0,0,0,0,0,0,0,0,0,0,0,0,0,0,0,0,0,0,0,0,1
1,1,0,0,0,0,0,0,0,0,0,0,0,0,0,0,0,0,0,0,0,1,1
endlayer

layer
1,0,0,0,0,0,0,0,0,0,0,0,0,0,0,0,0,0,0,0,0,0,1
0,0,0,0,0,0,0,0,0,0,0,0,0,0,0,0,0,0,0,0,0,0,0
0,0,0,0,0,0,0,0,0,0,0,0,0,0,0,2,2,0,0,0,0,0,0
0,0,0,0,0,0,0,0,0,0,0,0,0,0,0,2,2,0,0,0,0,0,0
0,0,0,0,0,0,0,0,0,0,0,0,0,0,0,0,2,2,0,0,0,0,0
0,0,0,0,0,0,0,0,0,0,0,0,0,0,0,0,2,2,0,0,0,0,0
0,0,0,0,0,0,0,0,0,0,0,0,0,0,0,0,2,2,2,0,0,0,0
0,0,0,0,0,0,2,2,0,0,0,0,0,0,0,0,0,0,0,0,0,0,0
0,0,0,0,0,0,0,0,2,0,0,0,0,0,0,0,0,0,0,0,0,0,0
0,0,0,0,0,0,0,0,6,3,0,0,0,0,0,0,0,0,0,0,0,0,0
0,0,0,0,0,0,0,0,7,3,0,0,0,0,0,0,0,0,0,0,0,0,0
0,0,0,0,0,0,0,0,2,0,0,0,0,0,0,0,2,2,2,0,0,0,0
0,0,0,0,0,0,2,2,2,2,0,0,0,0,0,2,2,0,0,0,0,0,0
0,0,0,0,0,0,0,0,2,0,0,0,0,0,0,2,0,0,0,0,0,0,0
0,0,0,0,0,0,0,0,0,0,0,0,0,0,0,0,0,0,0,0,0,0,0
0,0,0,0,0,0,0,0,0,0,0,0,0,0,0,0,0,0,0,0,0,0,0
0,0,0,0,0,0,0,0,0,0,0,0,0,0,0,0,0,0,0,0,0,0,0
1,0,0,0,0,0,0,0,0,0,0,0,0,0,0,0,0,0,0,0,0,0,1
endlayer

layer
0,0,0,0,0,0,0,0,0,0,0,0,0,0,0,0,0,0,0,0,0,0,0
0,0,0,0,0,0,0,0,0,0,0,0,0,0,0,0,0,0,0,0,0,0,0
0,0,0,0,0,0,0,0,0,0,0,0,0,0,0,0,0,0,0,0,0,0,0
0,0,0,0,0,0,0,0,0,0,0,0,0,0,0,0,0,0,0,0,0,0,0
0,0,0,0,0,0,0,0,0,0,0,0,0,0,0,0,2,2,0,0,0,0,0
0,0,0,0,0,0,0,0,0,0,0,0,0,0,0,0,2,2,0,0,0,0,0
0,0,0,0,0,0,0,0,0,0,0,0,0,0,0,0,2,2,2,0,0,0,0
0,0,0,0,0,0,2,2,0,0,0,0,0,0,0,0,0,0,0,0,0,0,0
0,0,0,0,0,0,0,0,2,0,0,0,0,0,0,0,0,0,0,0,0,0,0
0,0,0,0,0,0,0,0,6,3,0,0,0,0,0,0,0,0,0,0,0,0,0
0,0,0,0,0,0,0,0,7,3,0,0,0,0,0,0,0,0,0,0,0,0,0
0,0,0,0,0,0,0,0,2,0,0,0,0,0,0,0,2,2,2,0,0,0,0
0,0,0,0,0,0,2,2,2,2,0,0,0,0,0,2,2,0,0,0,0,0,0
0,0,0,0,0,0,0,0,2,0,0,0,0,0,0,2,0,0,0,0,0,0,0
0,0,0,0,0,0,0,0,0,0,0,0,0,0,0,0,0,0,0,0,0,0,0
0,0,0,0,0,0,0,0,0,0,0,0,0,0,0,0,0,0,0,0,0,0,0
0,0,0,0,0,0,0,0,0,0,0,0,0,0,0,0,0,0,0,0,0,0,0
0,0,0,0,0,0,0,0,0,0,0,0,0,0,0,0,0,0,0,0,0,0,0
endlayer

layer
0,0,0,0,0,0,0,0,0,0,0,0,0,0,0,0,0,0,0,0,0,0,0
0,0,0,0,0,0,0,0,0,0,0,0,0,0,0,0,0,0,0,0,0,0,0
0,0,0,0,0,0,0,0,0,0,0,0,0,0,0,0,0,0,0,0,0,0,0
0,0,0,0,0,0,0,0,0,0,0,0,0,0,0,0,0,0,0,0,0,0,0
0,0,0,0,0,0,0,0,0,0,0,0,0,0,0,0,0,0,0,0,0,0,0
0,0,0,0,0,0,0,0,0,0,0,0,0,0,0,0,2,2,0,0,0,0,0
0,0,0,0,0,0,0,0,0,0,0,0,0,0,0,0,2,2,2,0,0,0,0
0,0,0,0,0,0,2,2,0,0,0,0,0,0,0,0,0,2,0,0,0,0,0
0,0,0,0,0,0,0,2,2,0,0,0,0,0,0,0,0,2,0,0,0,0,0
0,0,0,0,0,0,0,2,6,3,0,0,0,0,0,0,0,2,0,0,0,0,0
0,0,0,0,0,0,0,2,7,3,0,0,0,0,0,0,0,2,0,0,0,0,0
0,0,0,0,0,0,0,2,2,0,0,0,0,0,0,0,2,2,2,0,0,0,0
0,0,0,0,0,0,2,2,2,2,0,0,0,0,0,2,2,0,0,0,0,0,0
0,0,0,0,0,0,0,0,2,2,2,2,2,2,2,2,0,0,0,0,0,0,0
0,0,0,0,0,0,0,0,0,0,0,0,0,0,0,0,0,0,0,0,0,0,0
0,0,0,0,0,0,0,0,0,0,0,0,0,0,0,0,0,0,0,0,0,0,0
0,0,0,0,0,0,0,0,0,0,0,0,0,0,0,0,0,0,0,0,0,0,0
0,0,0,0,0,0,0,0,0,0,0,0,0,0,0,0,0,0,0,0,0,0,0
endlayer

layer
0,0,0,0,0,0,0,0,0,0,0,0,0,0,0,0,0,0,0,0,0,0,0
0,0,0,0,0,0,0,0,0,0,0,0,0,0,0,0,0,0,0,0,0,0,0
0,0,0,0,0,0,0,0,0,0,0,0,0,0,0,0,0,0,0,0,0,0,0
0,0,0,0,0,0,0,0,0,0,0,0,0,0,0,0,0,0,0,0,0,0,0
0,0,0,0,0,0,0,0,0,0,0,0,0,0,0,0,0,0,0,0,0,0,0
0,0,0,0,0,0,0,0,0,0,0,0,0,0,0,0,2,2,0,0,0,0,0
0,0,0,0,0,0,0,0,0,0,0,0,0,0,0,0,2,2,2,0,0,0,0
0,0,0,0,0,0,2,2,0,0,0,0,0,0,0,0,0,0,0,0,0,0,0
0,0,0,0,0,0,0,0,2,0,0,0,0,0,0,0,0,0,0,0,0,0,0
0,0,0,0,0,0,0,0,6,3,0,0,0,0,0,0,0,0,0,0,0,0,0
0,0,0,0,0,0,0,0,7,3,0,0,0,0,0,0,0,0,0,0,0,0,0
0,0,0,0,0,0,0,0,2,0,0,0,0,0,0,0,2,2,2,0,0,0,0
0,0,0,0,0,0,2,2,2,2,0,0,0,0,0,2,2,2,0,0,0,0,0
0,0,0,0,0,0,0,0,2,0,0,0,0,0,0,2,0,0,0,0,0,0,0
0,0,0,0,0,0,0,0,0,0,0,0,0,0,0,0,0,0,0,0,0,0,0
0,0,0,0,0,0,0,0,0,0,0,0,0,0,0,0,0,0,0,0,0,0,0
0,0,0,0,0,0,0,0,0,0,0,0,0,0,0,0,0,0,0,0,0,0,0
0,0,0,0,0,0,0,0,0,0,0,0,0,0,0,0,0,0,0,0,0,0,0
endlayer

layer
0,0,0,0,0,0,0,0,0,0,0,0,0,0,0,0,0,0,0,0,0,0,0
0,0,0,0,0,0,0,0,0,0,0,0,0,0,0,0,0,0,0,0,0,0,0
0,0,0,0,0,0,0,0,0,0,0,0,0,0,0,0,0,0,0,0,0,0,0
0,0,0,0,0,0,0,0,0,0,0,0,0,0,0,0,0,0,0,0,0,0,0
0,0,0,0,0,0,0,0,0,0,0,0,0,0,0,0,0,0,0,0,0,0,0
0,0,0,0,0,0,0,0,0,0,0,0,0,0,0,0,2,2,0,0,0,0,0
0,0,0,0,0,0,0,0,0,0,0,0,0,0,0,0,2,2,2,0,0,0,0
0,0,0,0,0,0,2,2,0,0,0,0,0,0,0,0,0,2,0,0,0,0,0
0,0,0,0,0,0,0,2,2,0,0,0,0,0,0,0,0,2,0,0,0,0,0
0,0,0,0,0,0,0,2,6,3,0,0,0,0,0,0,0,2,0,0,0,0,0
0,0,0,0,0,0,0,2,7,3,0,0,0,0,0,0,0,2,0,0,0,0,0
0,0,0,0,0,0,0,2,2,0,0,0,0,0,0,0,2,2,2,0,0,0,0
0,0,0,0,0,0,2,2,2,2,0,0,0,0,0,2,2,2,0,0,0,0,0
0,0,0,0,0,0,0,0,2,2,2,2,2,2,2,2,2,0,0,0,0,0,0
0,0,0,0,0,0,0,0,0,0,0,0,0,0,0,0,0,0,0,0,0,0,0
0,0,0,0,0,0,0,0,0,0,0,0,0,0,0,0,0,0,0,0,0,0,0
0,0,0,0,0,0,0,0,0,0,0,0,0,0,0,0,0,0,0,0,0,0,0
0,0,0,0,0,0,0,0,0,0,0,0,0,0,0,0,0,0,0,0,0,0,0
endlayer

layer
0,0,0,0,0,0,0,0,0,0,0,0,0,0,0,0,0,0,0,0,0,0,0
0,0,0,0,0,0,0,0,0,0,0,0,0,0,0,0,0,0,0,0,0,0,0
0,0,0,0,0,0,0,0,0,0,0,0,0,0,0,0,0,0,0,0,0,0,0
0,0,0,0,0,0,0,0,0,0,0,0,0,0,0,0,0,0,0,0,0,0,0
0,0,0,0,0,0,0,0,0,0,0,0,0,0,0,0,0,0,0,0,0,0,0
0,0,0,0,0,0,0,0,0,0,0,0,0,0,0,0,2,2,0,0,0,0,0
0,0,0,0,0,0,0,0,0,0,0,0,0,0,0,0,2,2,2,2,0,0,0
0,0,0,0,0,2,2,2,0,0,0,0,0,0,0,0,0,0,0,0,0,0,0
0,0,0,0,0,0,0,0,2,0,0,0,0,0,0,0,0,0,0,0,0,0,0
0,0,0,0,0,0,0,0,6,3,0,0,0,0,0,0,0,0,0,0,0,0,0
0,0,0,0,0,0,0,0,7,3,0,0,0,0,0,0,0,0,0,0,0,0,0
0,0,0,0,0,0,0,0,2,0,0,0,0,0,0,0,2,2,2,2,0,0,0
0,0,0,0,0,2,2,2,2,2,0,0,0,0,0,2,2,2,0,0,0,0,0
0,0,0,0,0,0,0,0,2,0,0,0,0,0,0,2,2,0,0,0,0,0,0
0,0,0,0,0,0,0,0,2,0,0,0,0,0,0,0,2,0,0,0,0,0,0
0,0,0,0,0,0,0,0,0,0,0,0,0,0,0,0,0,0,0,0,0,0,0
0,0,0,0,0,0,0,0,0,0,0,0,0,0,0,0,0,0,0,0,0,0,0
0,0,0,0,0,0,0,0,0,0,0,0,0,0,0,0,0,0,0,0,0,0,0
endlayer

layer
0,0,0,0,0,0,0,0,0,0,0,0,0,0,0,0,0,0,0,0,0,0,0
0,0,0,0,0,0,0,0,0,0,0,0,0,0,0,0,0,0,0,0,0,0,0
0,0,0,0,0,0,0,0,0,0,0,0,0,0,0,0,0,0,0,0,0,0,0
0,0,0,0,0,0,0,0,0,0,0,0,0,0,0,0,0,0,0,0,0,0,0
0,0,0,0,0,0,0,0,0,0,0,0,0,0,0,0,0,0,0,0,0,0,0
0,0,0,0,0,0,0,0,0,0,0,0,0,0,0,0,2,2,0,0,0,0,0
0,0,0,0,0,0,0,0,0,0,0,0,0,0,0,0,2,2,2,2,2,0,0
0,0,0,2,2,2,2,2,0,0,0,0,0,0,0,0,0,2,2,2,0,0,0
0,0,0,0,2,2,2,2,2,0,0,0,0,0,0,0,0,2,2,2,0,0,0
0,0,0,0,2,2,2,2,6,3,0,0,0,0,0,0,0,2,2,2,0,0,0
0,0,0,0,2,2,2,2,7,3,0,0,0,0,0,0,0,2,2,2,0,0,0
0,0,0,0,2,2,2,2,2,0,0,0,0,0,0,0,2,2,2,2,2,0,0
0,0,0,2,2,2,2,2,2,2,0,0,0,0,0,2,2,2,2,2,2,0,0
0,0,0,0,2,2,2,2,2,2,2,2,2,2,2,2,2,2,2,2,0,0,0
0,0,0,0,2,0,0,0,2,0,0,0,2,0,0,0,2,2,2,0,0,0,0
0,0,0,0,2,0,0,0,2,0,0,0,2,0,0,0,2,2,0,0,0,0,0
0,0,0,0,0,0,0,0,0,0,0,0,0,0,0,0,0,0,0,0,0,0,0
0,0,0,0,0,0,0,0,0,0,0,0,0,0,0,0,0,0,0,0,0,0,0
endlayer

layer
0,0,0,0,0,0,0,0,0,0,0,0,0,0,0,0,0,0,0,0,0,0,0
0,0,0,0,0,0,0,0,0,0,0,0,0,0,0,0,0,0,0,0,0,0,0
0,0,0,0,0,0,0,0,0,0,0,0,0,0,0,0,0,0,0,0,0,0,0
0,0,0,0,0,0,0,0,0,0,0,0,0,0,0,0,0,0,0,0,0,0,0
0,0,0,0,0,0,0,0,0,0,0,0,0,0,0,0,0,0,0,0,0,0,0
0,0,0,0,0,0,0,0,0,0,0,0,0,0,0,0,2,2,2,0,0,0,0
0,0,2,2,2,2,2,0,0,0,0,0,0,0,0,0,2,2,2,2,2,2,0
0,2,2,2,5,2,2,2,0,0,0,0,0,0,0,0,2,2,2,2,2,2,0
0,2,2,2,2,2,2,2,2,0,0,0,0,0,0,0,2,2,2,2,2,2,0
0,2,2,2,2,2,2,2,6,3,0,0,0,0,0,0,2,2,2,5,2,2,0
0,2,2,2,2,2,2,2,7,3,0,0,0,0,0,0,2,2,2,2,2,2,0
0,2,2,2,5,2,2,2,2,0,0,0,0,0,0,0,2,2,2,2,2,2,0
0,2,2,2,2,2,2,2,2,2,0,0,0,0,0,2,2,2,2,2,2,2,0
0,2,2,2,2,2,2,2,2,2,0,0,0,0,0,2,2,2,2,5,2,2,0
0,2,2,2,2,2,2,2,2,2,2,2,2,2,2,2,2,2,2,2,2,2,0
0,2,2,2,5,2,2,2,5,2,2,2,5,2,2,2,5,2,2,2,2,0,0
0,0,2,2,2,2,2,2,2,2,2,2,2,2,2,2,2,2,2,2,0,0,0
0,0,0,0,0,0,0,0,0,0,0,0,0,0,0,0,0,0,0,0,0,0,0
endlayer

layer
0,0,0,0,0,0,0,0,0,0,0,0,0,0,0,0,0,0,0,0,0,0,0
0,0,0,0,0,0,0,0,0,0,0,0,0,0,0,0,0,0,0,0,0,0,0
0,0,0,0,0,0,0,0,0,0,0,0,0,0,0,0,0,0,0,0,0,0,0
0,0,0,0,0,0,0,0,0,0,0,0,0,0,0,0,0,0,0,0,0,0,0
0,0,0,0,0,0,0,0,0,0,0,0,0,0,0,0,0,0,0,0,0,0,0
0,0,13,13,13,13,13,0,0,0,0,0,0,0,0,2,13,13,13,13,13,13,0
0,13,14,14,14,14,14,13,0,0,0,0,0,0,0,2,2,14,14,14,14,14,13
13,14,14,14,3,14,14,14,13,0,0,0,0,0,0,2,2,14,14,14,14,14,13
13,14,14,14,14,14,14,14,2,0,0,0,0,0,0,2,2,14,14,14,14,14,13
13,14,14,14,14,14,14,14,6,3,0,0,0,0,0,2,2,14,14,3,14,14,13
13,14,14,14,14,14,14,14,7,3,0,0,0,0,0,2,2,14,14,14,14,14,13
13,14,14,14,3,14,14,14,2,0,0,0,0,0,0,2,2,14,14,14,14,14,13
13,14,14,14,14,14,14,14,2,2,0,0,0,0,0,2,14,14,14,14,14,14,13
13,14,14,14,14,14,14,14,14,2,2,2,2,2,2,14,14,14,14,3,14,14,13
13,14,14,14,14,14,14,14,14,14,14,14,14,14,14,14,14,14,14,14,14,14,13
13,14,14,14,3,14,14,14,3,14,14,14,3,14,14,14,3,14,14,14,14,13,0
0,13,14,14,14,14,14,14,14,14,14,14,14,14,14,14,14,14,14,14,13,0,0
0,0,13,13,13,13,13,13,13,13,13,13,13,13,13,13,13,13,13,13,0,0,0
endlayer

layer
0,0,0,0,0,0,0,0,0,0,0,0,0,0,0,0,0,0,0,0,0,0,0
0,0,0,0,0,0,0,0,0,0,0,0,0,0,0,0,0,0,0,0,0,0,0
0,0,0,0,0,0,0,0,0,0,0,0,0,0,0,0,0,0,0,0,0,0,0
0,0,0,0,0,0,0,0,0,0,0,0,0,0,0,0,0,0,0,0,0,0,0
0,0,0,0,0,0,0,0,0,0,0,0,0,0,0,0,0,0,0,0,0,0,0
0,0,2,2,2,2,2,0,0,0,0,0,0,0,0,2,2,2,2,2,2,2,0
0,2,0,0,0,0,0,2,0,0,0,0,0,0,0,2,2,0,0,0,0,0,2
2,0,0,0,0,0,0,0,2,0,0,0,0,0,0,0,2,0,0,0,0,0,2
2,0,0,0,0,0,0,0,2,0,0,0,0,0,0,0,2,0,0,0,0,0,2
2,0,0,0,0,0,0,0,6,3,0,0,0,0,0,0,2,0,0,0,0,0,2
2,0,0,0,0,0,0,0,7,3,0,0,0,0,0,0,2,0,0,0,0,0,2
2,0,0,0,0,0,0,0,2,0,0,0,0,0,0,0,2,0,0,0,0,0,2
2,0,0,0,0,0,0,0,2,2,2,2,2,2,2,2,2,0,0,0,0,0,2
2,0,0,0,0,0,0,0,0,2,2,2,2,2,2,2,0,0,0,0,0,0,2
2,0,0,0,0,0,0,0,0,0,0,0,0,0,0,0,0,0,0,0,0,0,2
2,0,0,0,0,0,0,0,0,0,0,0,0,0,0,0,0,0,0,0,0,2,0
0,2,0,0,0,0,0,0,0,0,0,0,0,0,0,0,0,0,0,0,2,0,0
0,0,2,2,2,2,2,2,2,2,2,2,2,2,2,2,2,2,2,2,0,0,0
endlayer

layer
0,0,0,0,0,0,0,0,0,0,0,0,0,0,0,0,0,0,0,0,0,0,0
0,0,0,0,0,0,0,0,0,0,0,0,0,0,0,0,0,0,0,0,0,0,0
0,0,0,0,0,0,0,0,0,0,0,0,0,0,0,0,0,0,0,0,0,0,0
0,0,0,0,0,0,0,0,0,0,0,0,0,0,0,0,0,0,0,0,0,0,0
0,0,0,0,0,0,0,0,0,0,0,0,0,0,0,0,0,0,0,0,0,0,0
0,0,0,0,0,0,0,0,0,0,0,0,0,0,0,2,2,0,0,0,0,0,0
0,0,0,0,0,0,0,0,0,0,0,0,0,0,0,2,2,0,0,0,0,0,0
0,0,0,0,0,0,0,0,2,0,0,0,0,0,0,2,2,0,0,0,0,0,0
0,0,0,0,0,0,0,0,2,0,0,0,0,0,0,2,2,0,0,0,0,0,0
0,0,0,0,0,0,0,0,0,3,0,0,0,0,0,2,2,0,0,0,0,0,0
0,0,0,0,0,0,0,0,0,3,0,0,0,0,0,2,2,0,0,0,0,0,0
0,0,0,0,0,0,0,0,2,0,0,0,0,0,0,2,2,0,0,0,0,0,0
0,0,0,0,0,0,0,0,2,2,0,0,0,0,0,2,2,0,0,0,0,0,0
0,0,0,0,0,0,0,0,0,2,2,2,2,2,2,2,0,0,0,0,0,0,0
0,0,0,0,0,0,0,0,0,0,0,0,0,0,0,0,0,0,0,0,0,0,0
0,0,0,0,0,0,0,0,0,0,0,0,0,0,0,0,0,0,0,0,0,0,0
0,0,0,0,0,0,0,0,0,0,0,0,0,0,0,0,0,0,0,0,0,0,0
0,0,0,0,0,0,0,0,0,0,0,0,0,0,0,0,0,0,0,0,0,0,0
endlayer

layer
0,0,0,0,0,0,0,0,0,0,0,0,0,0,0,0,0,0,0,0,0,0,0
0,0,0,0,0,0,0,0,0,0,0,0,0,0,0,0,0,0,0,0,0,0,0
0,0,0,0,0,0,0,0,0,0,0,0,0,0,0,0,0,0,0,0,0,0,0
0,0,0,0,0,0,0,0,0,0,0,0,0,0,0,0,0,0,0,0,0,0,0
0,0,0,0,0,0,0,0,0,0,0,0,0,0,0,0,0,0,0,0,0,0,0
0,0,0,0,0,0,0,0,0,0,0,0,0,0,0,2,2,0,0,0,0,0,0
0,0,0,0,0,0,0,0,0,0,0,0,0,0,0,2,2,0,0,0,0,0,0
0,0,0,0,0,0,0,0,2,0,0,0,0,0,0,0,2,0,0,0,0,0,0
0,0,0,0,0,0,0,0,2,3,0,0,0,0,0,0,2,0,0,0,0,0,0
0,0,0,0,0,0,0,0,0,3,0,0,0,0,0,0,2,0,0,0,0,0,0
0,0,0,0,0,0,0,0,0,3,0,0,0,0,0,0,2,0,0,0,0,0,0
0,0,0,0,0,0,0,0,2,3,0,0,0,0,0,0,2,0,0,0,0,0,0
0,0,0,0,0,0,0,0,2,2,2,2,2,2,2,2,2,0,0,0,0,0,0
0,0,0,0,0,0,0,0,0,2,2,2,2,2,2,2,0,0,0,0,0,0,0
0,0,0,0,0,0,0,0,0,0,0,0,0,0,0,0,0,0,0,0,0,0,0
0,0,0,0,0,0,0,0,0,0,0,0,0,0,0,0,0,0,0,0,0,0,0
0,0,0,0,0,0,0,0,0,0,0,0,0,0,0,0,0,0,0,0,0,0,0
0,0,0,0,0,0,0,0,0,0,0,0,0,0,0,0,0,0,0,0,0,0,0
endlayer

layer
0,0,0,0,0,0,0,0,0,0,0,0,0,0,0,0,0,0,0,0,0,0,0
0,0,0,0,0,0,0,0,0,0,0,0,0,0,0,0,0,0,0,0,0,0,0
0,0,0,0,0,0,0,0,0,0,0,0,0,0,0,0,0,0,0,0,0,0,0
0,0,0,0,0,0,0,0,0,0,0,0,0,0,0,0,0,0,0,0,0,0,0
0,0,0,0,0,0,0,0,0,0,0,0,0,0,0,0,0,0,0,0,0,0,0
0,0,0,0,0,0,0,0,0,0,0,0,0,0,0,2,2,0,0,0,0,0,0
0,0,0,0,0,0,0,0,0,0,0,0,0,0,0,2,2,0,0,0,0,0,0
0,0,0,0,0,0,0,0,2,0,0,0,0,0,0,2,2,0,0,0,0,0,0
0,0,0,0,0,0,0,0,2,0,0,0,0,0,0,2,2,0,0,0,0,0,0
0,0,0,0,0,0,0,0,0,0,0,0,0,0,0,2,2,0,0,0,0,0,0
0,0,0,0,0,0,0,0,0,0,0,0,0,0,0,2,2,0,0,0,0,0,0
0,0,0,0,0,0,0,0,2,0,0,0,0,0,0,2,2,0,0,0,0,0,0
0,0,0,0,0,0,0,0,2,2,0,0,0,0,0,2,2,0,0,0,0,0,0
0,0,0,0,0,0,0,0,0,2,2,2,2,2,2,2,0,0,0,0,0,0,0
0,0,0,0,0,0,0,0,0,0,0,0,0,0,0,0,0,0,0,0,0,0,0
0,0,0,0,0,0,0,0,0,0,0,0,0,0,0,0,0,0,0,0,0,0,0
0,0,0,0,0,0,0,0,0,0,0,0,0,0,0,0,0,0,0,0,0,0,0
0,0,0,0,0,0,0,0,0,0,0,0,0,0,0,0,0,0,0,0,0,0,0
endlayer

layer
0,0,0,0,0,0,0,0,0,0,0,0,0,0,0,0,0,0,0,0,0,0,0
0,0,0,0,0,0,0,0,0,0,0,0,0,0,0,0,0,0,0,0,0,0,0
0,0,0,0,0,0,0,0,0,0,0,0,0,0,0,0,0,0,0,0,0,0,0
0,0,0,0,0,0,0,0,0,0,0,0,0,0,0,0,0,0,0,0,0,0,0
0,0,0,0,0,0,0,0,0,0,0,0,0,0,0,0,0,0,0,0,0,0,0
0,0,0,0,0,0,0,0,0,0,0,0,0,0,0,2,2,0,0,0,0,0,0
0,0,0,0,0,0,0,0,0,0,0,0,0,0,0,2,2,0,0,0,0,0,0
0,0,0,0,0,0,0,0,2,0,0,0,0,0,0,0,2,0,0,0,0,0,0
0,0,0,0,0,0,0,0,2,0,0,0,0,0,0,0,2,0,0,0,0,0,0
0,0,0,0,0,0,0,0,2,0,0,0,0,0,0,0,2,0,0,0,0,0,0
0,0,0,0,0,0,0,0,2,0,0,0,0,0,0,0,2,0,0,0,0,0,0
0,0,0,0,0,0,0,0,2,0,0,0,0,0,0,0,2,0,0,0,0,0,0
0,0,0,0,0,0,0,0,2,2,0,0,0,0,0,2,2,0,0,0,0,0,0
0,0,0,0,0,0,0,0,0,2,2,2,2,2,2,2,0,0,0,0,0,0,0
0,0,0,0,0,0,0,0,0,0,0,0,0,0,0,0,0,0,0,0,0,0,0
0,0,0,0,0,0,0,0,0,0,0,0,0,0,0,0,0,0,0,0,0,0,0
0,0,0,0,0,0,0,0,0,0,0,0,0,0,0,0,0,0,0,0,0,0,0
0,0,0,0,0,0,0,0,0,0,0,0,0,0,0,0,0,0,0,0,0,0,0
endlayer

