# Gilly's underground Hangar

# template generated by Ruins mod version 14.6 Ingame Parser
# Structure created by Gilly

weight=1
embed_into_distance=21
acceptable_target_blocks=
unacceptable_target_blocks=flowing_water,water,flowing_lava,lava,ice,bedrock,netherrack,soul_sand,Natura:Cloud
dimensions=13,39,43
allowable_overhang=0
max_leveling=3
leveling_buffer=-1
preserve_water=0
preserve_lava=0

rule1=0,100,preserveBlock
rule2=0,100,glowstone-0
rule3=0,100,cauldron-0
rule4=0,100,stone_slab-8
rule5=0,100,stained_hardened_clay-9
rule6=0,100,stone_slab-13
rule7=0,100,stone_slab-5
rule8=0,100,iron_bars-0
rule9=0,100,stone_slab-0
rule10=0,100,stained_glass_pane-3
rule11=0,100,stone_brick_stairs-4
rule12=0,100,stone_brick_stairs-0
rule13=0,100,stone_brick_stairs-3
rule14=0,100,stone_brick_stairs-2
rule15=0,100,double_stone_slab-0
rule16=0,100,stone_brick_stairs-1
rule17=0,100,ladder-4
rule18=0,100,stained_hardened_clay-4
rule19=0,100,stained_hardened_clay-15
rule20=0,100,ladder-5
rule21=0,100,stained_hardened_clay-5
rule22=0,100,stained_hardened_clay-8
rule23=0,100,stained_hardened_clay-14
rule24=0,100,stained_hardened_clay-6
rule25=0,100,stone_brick_stairs-5

layer
1,1,1,1,1,1,1,1,1,1,1,1,1,1,1,1,1,1,1,1,1,1,1,1,1,1,1,1,1,1,1,1,1,1,1,1,1,1,1,1,1,1,1
1,1,1,1,1,1,1,1,1,1,1,1,1,1,1,1,1,1,1,1,1,1,1,1,1,1,1,1,1,1,1,1,1,1,1,1,1,1,1,1,1,1,1
1,1,1,1,2,0,0,0,2,1,1,1,1,1,2,0,0,0,2,1,1,1,1,1,2,0,0,0,2,1,1,1,1,1,2,0,0,0,2,1,1,1,1
1,1,1,1,0,0,0,0,0,1,1,1,1,1,0,0,0,0,0,1,1,1,1,1,0,0,0,0,0,1,1,1,1,1,0,0,0,0,0,1,1,1,1
1,1,1,1,0,0,0,0,0,1,1,1,1,1,0,0,0,0,0,1,1,1,1,1,0,0,0,0,0,1,1,1,1,1,0,0,0,0,0,1,1,1,1
1,1,1,1,2,0,0,0,2,1,1,1,1,1,2,0,0,0,2,1,1,1,1,1,2,0,0,0,2,1,1,1,1,1,2,0,0,0,2,1,1,1,1
1,1,1,1,3,0,0,0,3,1,1,1,1,1,3,0,0,0,3,1,1,1,1,1,3,0,0,0,3,1,1,1,1,1,3,4,4,4,3,1,1,1,1
1,1,1,1,4,4,4,4,4,1,1,1,1,1,4,4,4,4,4,1,1,1,1,1,4,4,4,4,4,1,1,1,1,1,4,4,4,4,4,1,1,1,1
1,1,1,1,4,4,4,4,4,1,1,1,1,1,4,4,4,4,4,1,1,1,1,1,4,4,4,4,4,1,1,1,1,1,4,4,4,4,4,1,1,1,1
1,1,1,1,4,4,4,4,4,1,1,1,1,1,4,4,4,4,4,1,1,1,1,1,4,4,4,4,4,1,1,1,1,1,4,4,4,4,4,1,1,1,1
1,1,1,1,3,4,4,4,3,1,5,5,5,1,3,4,4,4,3,1,1,1,1,1,3,4,4,4,3,1,5,5,5,1,3,4,4,4,3,1,1,1,1
1,1,1,1,2,0,0,0,2,1,5,6,5,1,2,0,0,0,2,1,1,1,1,1,2,0,0,0,2,1,5,6,5,1,2,0,0,0,2,1,1,1,1
1,1,1,5,3,5,5,5,3,5,5,6,5,5,3,5,5,5,3,5,1,1,1,5,3,5,5,5,3,5,5,6,5,5,3,5,5,5,3,5,1,1,1
1,1,1,1,1,5,5,5,5,5,5,6,5,5,5,5,5,5,5,5,5,5,5,5,5,5,5,5,5,5,5,6,5,5,5,5,5,5,5,5,5,5,5
1,1,1,1,1,5,7,7,7,7,7,7,7,7,7,7,7,7,7,7,7,7,7,7,7,7,7,7,7,7,7,7,7,7,7,7,7,7,7,7,7,5,0
1,1,1,1,1,5,7,5,5,5,5,5,5,5,5,5,5,5,5,5,5,5,5,5,5,5,5,5,5,5,5,5,5,5,5,5,5,5,5,5,5,5,5
1,1,1,1,1,5,7,5,1,1,1,1,1,1,1,1,1,1,1,1,1,1,1,1,1,1,1,1,1,1,1,1,1,1,1,1,1,1,1,1,1,1,1
5,5,5,5,5,5,7,5,5,5,5,5,5,1,1,1,1,1,1,1,1,1,1,1,1,1,1,1,1,1,1,1,1,1,1,1,1,1,1,1,1,1,1
0,0,0,0,0,6,7,6,0,0,0,0,0,1,1,1,5,5,5,5,5,5,5,5,5,5,5,5,5,5,5,5,5,5,5,5,5,1,1,1,1,1,1
5,5,5,5,5,5,7,5,5,5,5,5,5,1,1,5,5,0,0,0,0,0,0,0,0,0,0,0,0,0,0,0,0,0,0,0,5,5,1,1,1,1,1
1,1,1,1,1,5,7,5,1,1,1,1,1,1,5,5,0,0,0,0,0,0,0,0,0,0,0,0,0,0,0,0,0,0,0,0,0,5,5,1,1,1,1
1,1,1,1,1,5,7,5,1,1,1,1,1,1,5,0,0,0,0,0,0,0,0,0,0,0,0,0,0,0,0,0,0,0,0,0,0,0,5,1,1,1,1
1,1,1,1,1,5,7,5,1,1,1,1,1,1,5,0,0,0,0,0,0,0,0,0,0,0,0,0,0,0,0,0,0,0,0,0,0,0,5,1,1,1,1
1,1,1,1,1,5,7,5,1,1,1,1,1,1,5,0,0,0,0,0,0,0,0,0,0,0,0,0,0,0,0,0,0,0,0,0,0,0,5,1,1,1,1
1,1,1,1,1,5,7,5,1,1,1,1,1,1,5,0,0,0,0,0,0,0,0,0,0,0,0,0,0,0,0,0,0,0,0,0,0,0,5,1,1,1,1
5,5,5,5,5,5,7,5,5,5,5,5,5,5,5,0,0,0,0,0,0,0,0,0,0,0,0,0,0,0,0,0,0,0,0,0,0,0,5,1,1,1,1
0,0,0,0,0,6,7,7,7,7,7,7,7,8,0,0,0,0,0,0,5,0,0,0,0,0,0,0,0,0,0,0,5,0,0,0,0,0,5,1,1,1,1
5,5,5,5,5,5,7,5,5,5,5,5,5,5,5,0,0,0,0,0,0,0,0,0,0,0,0,0,0,0,0,0,0,0,0,0,0,0,5,1,1,1,1
1,1,1,1,1,5,7,5,1,1,1,1,1,1,5,0,0,0,0,0,0,0,0,0,0,0,0,0,0,0,0,0,0,0,0,0,0,0,5,1,1,1,1
1,1,1,1,1,5,7,5,1,1,1,1,1,1,5,0,0,0,0,0,0,0,0,0,0,0,0,0,0,0,0,0,0,0,0,0,0,0,5,1,1,1,1
1,1,1,1,1,5,7,5,1,1,1,1,1,1,5,0,0,0,0,0,0,0,0,0,0,0,0,0,0,0,0,0,0,0,0,0,0,0,5,1,1,1,1
1,1,1,1,1,5,7,5,1,1,1,1,1,1,5,0,0,0,0,0,0,0,0,0,0,0,0,0,0,0,0,0,0,0,0,0,0,0,5,1,1,1,1
1,1,1,1,1,5,7,5,1,1,1,1,1,1,5,5,0,0,0,0,0,0,0,0,0,0,0,0,0,0,0,0,0,0,0,0,0,5,5,1,1,1,1
5,5,5,5,5,5,7,5,5,5,5,5,5,1,1,5,5,0,0,0,0,0,0,0,0,0,0,0,0,0,0,0,0,0,0,0,5,5,1,1,1,1,1
0,0,0,0,0,6,7,6,0,0,0,0,0,1,1,1,5,5,5,5,5,5,5,5,5,5,5,5,5,5,5,5,5,5,5,5,5,1,1,1,1,1,1
5,5,5,5,5,5,7,5,5,5,5,5,5,1,1,1,1,1,1,1,1,1,1,1,1,1,1,1,1,1,1,1,1,1,1,1,1,1,1,1,1,1,1
1,1,1,1,1,5,7,5,1,1,1,1,1,1,1,1,1,1,1,1,1,1,1,1,1,1,1,1,1,1,1,1,1,1,1,1,1,1,1,1,1,1,1
1,1,1,1,1,5,6,5,1,1,1,1,1,1,1,1,1,1,1,1,1,1,1,1,1,1,1,1,1,1,1,1,1,1,1,1,1,1,1,1,1,1,1
1,1,1,1,1,5,0,5,1,1,1,1,1,1,1,1,1,1,1,1,1,1,1,1,1,1,1,1,1,1,1,1,1,1,1,1,1,1,1,1,1,1,1
endlayer

layer
1,1,5,5,5,5,5,5,5,5,5,1,5,5,5,5,5,5,5,5,5,1,5,5,5,5,5,5,5,5,5,1,5,5,5,5,5,5,5,5,5,1,1
1,1,5,5,5,5,5,5,5,5,5,1,5,5,5,5,5,5,5,5,5,1,5,5,5,5,5,5,5,5,5,1,5,5,5,5,5,5,5,5,5,1,1
1,1,5,5,3,9,9,9,3,5,5,1,5,5,3,9,9,9,3,5,5,1,5,5,3,9,9,9,3,5,5,1,5,5,3,9,9,9,3,5,5,1,1
1,1,5,5,9,9,9,9,9,5,5,1,5,5,9,9,9,9,9,5,5,1,5,5,9,9,9,9,9,5,5,1,5,5,9,9,9,9,9,5,5,1,1
1,1,5,5,9,9,9,9,9,5,5,1,5,5,9,9,9,9,9,5,5,1,5,5,9,9,9,9,9,5,5,1,5,5,9,9,9,9,9,5,5,1,1
1,1,5,5,9,9,9,9,9,5,5,1,5,5,9,9,9,9,9,5,5,1,5,5,9,9,9,9,9,5,5,1,5,5,9,9,9,9,9,5,5,1,1
1,1,5,5,0,9,9,9,0,5,5,1,5,5,0,9,9,9,0,5,5,1,5,5,0,9,9,9,0,5,5,1,5,5,0,9,9,9,0,5,5,1,1
1,1,5,5,0,0,0,0,0,5,5,1,5,5,0,0,0,0,0,5,5,1,5,5,0,0,0,0,0,5,5,1,5,5,0,0,0,0,0,5,5,1,1
1,1,5,5,0,0,0,0,0,5,5,1,5,5,0,0,0,0,0,5,5,1,5,5,0,0,0,0,0,5,5,1,5,5,0,0,0,0,0,5,5,1,1
1,1,5,5,0,0,0,0,0,5,5,1,5,5,0,0,0,0,0,5,5,1,5,5,0,0,0,0,0,5,5,1,5,5,0,0,0,0,0,5,5,1,1
1,1,5,5,0,0,0,0,0,5,5,5,5,5,0,0,0,0,0,5,5,1,5,5,0,0,0,0,0,5,5,5,5,5,0,0,0,0,0,5,5,1,1
1,1,5,5,5,5,5,5,5,5,5,0,5,5,5,5,5,5,5,5,5,1,5,5,5,5,5,5,5,5,5,0,5,5,5,5,5,5,5,5,5,1,1
1,1,5,10,10,10,10,10,10,10,5,0,5,10,10,10,10,10,10,10,5,1,5,10,10,10,10,10,10,10,5,0,5,10,10,10,10,10,10,10,5,1,1
1,1,1,5,5,5,5,5,5,5,5,0,5,5,5,5,5,5,5,5,5,5,5,5,5,5,5,5,5,5,5,0,5,5,5,5,5,5,5,5,5,5,5
1,1,1,1,1,5,0,0,0,0,0,0,0,0,0,0,0,0,0,0,0,0,0,0,0,0,0,0,0,0,0,0,0,0,0,0,0,0,0,0,0,8,0
1,1,1,1,1,5,0,5,5,5,5,5,5,5,5,5,5,5,5,5,5,5,5,5,5,5,5,5,5,5,5,5,5,5,5,5,5,5,5,5,5,5,5
1,1,1,1,1,5,0,5,1,1,1,1,1,1,1,1,1,1,1,1,1,1,1,1,1,1,1,1,1,1,1,1,1,1,1,1,1,1,1,1,1,1,1
1,1,1,5,5,5,0,5,5,5,1,1,1,1,1,1,1,1,1,1,1,1,1,1,1,1,1,1,1,1,1,1,1,1,1,1,1,1,1,1,1,1,1
5,5,5,0,0,8,0,8,0,0,5,5,5,1,1,1,5,5,5,5,5,5,5,5,5,5,5,5,5,5,5,5,5,5,5,5,5,1,1,1,1,1,1
1,1,1,5,5,5,0,5,5,5,1,1,1,1,1,5,5,0,0,0,0,0,0,0,0,0,0,0,0,0,0,0,0,0,0,0,5,5,1,1,1,1,1
1,1,1,1,1,5,0,5,1,1,1,1,1,1,5,5,0,0,0,0,0,2,0,0,0,0,2,0,0,0,0,2,0,0,0,0,0,5,5,1,1,1,1
1,1,1,1,1,5,0,5,1,1,1,1,1,1,5,0,0,0,0,0,0,0,0,0,0,0,0,0,0,0,0,0,0,0,0,0,0,0,5,1,1,1,1
1,1,1,1,1,5,0,5,1,1,1,1,1,1,5,0,0,0,0,0,0,0,0,0,0,0,0,0,0,0,0,0,0,0,0,0,0,0,5,1,1,1,1
1,1,1,1,1,5,0,5,1,1,1,1,1,1,5,0,0,0,0,0,0,0,0,0,0,0,0,0,0,0,0,0,0,0,0,0,0,0,5,1,1,1,1
1,1,1,1,1,5,0,5,1,1,1,1,1,1,5,0,2,0,0,0,0,2,0,0,0,0,2,0,0,0,0,2,0,0,0,0,2,0,5,1,1,1,1
1,1,1,5,5,5,0,5,5,5,5,5,5,5,5,0,0,0,0,5,5,5,0,0,0,0,0,0,0,0,0,5,5,5,0,0,0,0,5,1,1,1,1
5,5,5,0,0,8,0,0,0,0,0,0,0,8,6,0,0,0,0,0,5,0,0,0,0,0,0,0,0,0,0,0,5,0,0,0,0,0,5,1,1,1,1
1,1,1,5,5,5,0,5,5,5,5,5,5,5,5,0,0,0,0,5,5,5,0,0,0,0,0,0,0,0,0,5,5,5,0,0,0,0,5,1,1,1,1
1,1,1,1,1,5,0,5,1,1,1,1,1,1,5,0,2,0,0,0,0,2,0,0,0,0,2,0,0,0,0,2,0,0,0,0,2,0,5,1,1,1,1
1,1,1,1,1,5,0,5,1,1,1,1,1,1,5,0,0,0,0,0,0,0,0,0,0,0,0,0,0,0,0,0,0,0,0,0,0,0,5,1,1,1,1
1,1,1,1,1,5,0,5,1,1,1,1,1,1,5,0,0,0,0,0,0,0,0,0,0,0,0,0,0,0,0,0,0,0,0,0,0,0,5,1,1,1,1
1,1,1,1,1,5,0,5,1,1,1,1,1,1,5,0,0,0,0,0,0,0,0,0,0,0,0,0,0,0,0,0,0,0,0,0,0,0,5,1,1,1,1
1,1,1,1,1,5,0,5,1,1,1,1,1,1,5,5,0,0,0,0,0,2,0,0,0,0,2,0,0,0,0,2,0,0,0,0,0,5,5,1,1,1,1
1,1,1,5,5,5,0,5,5,5,1,1,1,1,1,5,5,0,0,0,0,0,0,0,0,0,0,0,0,0,0,0,0,0,0,0,5,5,1,1,1,1,1
5,5,5,0,0,8,0,8,0,0,5,5,5,1,1,1,5,5,5,5,5,5,5,5,5,5,5,5,5,5,5,5,5,5,5,5,5,1,1,1,1,1,1
1,1,1,5,5,5,0,5,5,5,1,1,1,1,1,1,1,1,1,1,1,1,1,1,1,1,1,1,1,1,1,1,1,1,1,1,1,1,1,1,1,1,1
1,1,1,1,1,5,0,5,1,1,1,1,1,1,1,1,1,1,1,1,1,1,1,1,1,1,1,1,1,1,1,1,1,1,1,1,1,1,1,1,1,1,1
1,1,1,1,1,5,8,5,1,1,1,1,1,1,1,1,1,1,1,1,1,1,1,1,1,1,1,1,1,1,1,1,1,1,1,1,1,1,1,1,1,1,1
1,1,1,1,1,5,0,5,1,1,1,1,1,1,1,1,1,1,1,1,1,1,1,1,1,1,1,1,1,1,1,1,1,1,1,1,1,1,1,1,1,1,1
endlayer

layer
1,1,5,5,5,5,5,5,5,5,5,1,5,5,5,5,5,5,5,5,5,1,5,5,5,5,5,5,5,5,5,1,5,5,5,5,5,5,5,5,5,1,1
1,1,5,0,0,0,0,0,0,0,5,1,5,0,0,0,0,0,0,0,5,1,5,0,0,0,0,0,0,0,5,1,5,0,0,0,0,0,0,0,5,1,1
1,1,5,0,0,0,0,0,0,0,5,1,5,0,0,0,0,0,0,0,5,1,5,0,0,0,0,0,0,0,5,1,5,0,0,0,0,0,0,0,5,1,1
1,1,5,0,0,0,0,0,0,0,5,1,5,0,0,0,0,0,0,0,5,1,5,0,0,0,0,0,0,0,5,1,5,0,0,0,0,0,0,0,5,1,1
1,1,5,0,0,0,0,0,0,0,5,1,5,0,0,0,0,0,0,0,5,1,5,0,0,0,0,0,0,0,5,1,5,0,0,0,0,0,0,0,5,1,1
1,1,5,0,0,0,0,0,0,0,5,1,5,0,0,0,0,0,0,0,5,1,5,0,0,0,0,0,0,0,5,1,5,0,0,0,0,0,0,0,5,1,1
1,1,5,0,0,0,0,0,0,0,5,1,5,0,0,0,0,0,0,0,5,1,5,0,0,0,0,0,0,0,5,1,5,0,0,0,0,0,0,0,5,1,1
1,1,5,0,0,0,0,0,0,0,5,1,5,0,0,0,0,0,0,0,5,1,5,0,0,0,0,0,0,0,5,1,5,0,0,0,0,0,0,0,5,1,1
1,1,5,0,0,0,0,0,0,0,5,1,5,0,0,0,0,0,0,0,5,1,5,0,0,0,0,0,0,0,5,1,5,0,0,0,0,0,0,0,5,1,1
1,1,5,0,0,0,0,0,0,0,5,1,5,0,0,0,0,0,0,0,5,1,5,0,0,0,0,0,0,0,5,1,5,0,0,0,0,0,0,0,5,1,1
1,1,5,0,0,0,0,0,0,0,5,5,5,0,0,0,0,0,0,0,5,1,5,0,0,0,0,0,0,0,5,5,5,0,0,0,0,0,0,0,5,1,1
1,1,5,0,0,0,0,0,0,0,8,0,8,0,0,0,0,0,0,0,5,1,5,0,0,0,0,0,0,0,8,0,8,0,0,0,0,0,0,0,5,1,1
1,1,5,11,11,11,11,11,11,11,5,0,5,11,11,11,11,11,11,11,5,1,5,11,11,11,11,11,11,11,5,0,5,11,11,11,11,11,11,11,5,1,1
1,1,1,5,5,5,5,5,5,5,5,0,5,5,5,5,5,5,5,5,5,5,5,5,5,5,5,5,5,5,5,0,5,5,5,5,5,5,5,5,5,5,5
1,1,1,1,1,5,0,0,0,0,0,0,0,0,0,0,0,0,0,0,0,0,0,0,0,0,0,0,0,0,0,0,0,0,0,0,0,0,0,0,0,5,5
1,1,1,1,1,5,0,5,5,5,5,5,8,5,5,5,8,5,5,5,8,5,5,5,8,5,5,5,8,5,5,5,8,5,5,5,8,5,5,5,8,5,5
1,1,1,1,2,5,0,5,2,1,1,1,2,1,1,1,2,1,1,1,2,1,1,1,2,1,1,1,2,1,1,1,2,1,1,1,2,1,1,1,2,1,1
1,1,1,5,0,5,0,5,0,5,1,1,1,1,1,1,3,5,5,5,3,5,5,5,3,5,5,5,3,5,5,5,3,5,5,5,3,1,1,1,1,1,1
1,1,1,5,0,5,0,5,0,5,1,1,1,1,1,5,10,10,10,10,10,10,10,10,10,10,10,10,10,10,10,10,10,10,10,10,10,5,1,1,1,1,1
1,1,1,5,0,5,0,5,0,5,1,1,1,1,5,10,10,13,12,12,12,12,12,12,12,12,12,12,12,12,12,12,12,12,12,12,10,10,5,1,1,1,1
1,1,1,1,2,5,0,5,2,1,1,1,2,3,10,10,12,12,5,5,5,3,5,5,5,5,3,5,5,5,5,3,5,5,5,14,12,10,10,3,2,1,1
1,1,1,1,1,5,0,5,1,1,1,1,1,5,10,12,13,5,15,5,15,5,15,15,15,15,5,15,15,15,15,5,15,5,15,5,14,12,10,5,1,1,1
1,1,1,1,1,5,0,5,1,1,1,1,1,5,10,13,5,15,15,5,15,5,15,15,15,15,5,15,15,15,15,5,15,5,15,15,5,14,10,5,1,1,1
1,1,1,1,1,5,0,5,1,1,1,1,1,5,10,13,5,15,15,5,15,5,15,15,15,15,5,15,15,15,15,5,15,5,15,15,5,14,10,5,1,1,1
1,1,1,1,2,5,0,5,2,1,1,1,2,3,10,13,3,5,5,5,5,3,5,5,5,5,3,5,5,5,5,3,5,5,5,5,3,14,10,3,2,1,1
1,1,1,5,0,5,0,5,8,5,5,5,8,5,10,13,5,15,15,5,15,5,15,15,15,15,5,15,15,15,15,5,15,5,15,15,5,14,10,5,1,1,1
1,1,1,5,0,5,0,0,0,0,0,0,0,5,10,13,5,15,15,5,15,5,15,15,15,15,5,15,15,15,15,5,15,5,15,15,5,14,10,5,1,1,1
1,1,1,5,0,5,0,5,8,5,5,5,8,5,10,13,5,15,15,5,15,5,15,15,15,15,5,15,15,15,15,5,15,5,15,15,5,14,10,5,1,1,1
1,1,1,1,2,5,0,5,2,1,1,1,2,3,10,13,3,5,5,5,5,3,5,5,5,5,3,5,5,5,5,3,5,5,5,5,3,14,10,3,2,1,1
1,1,1,1,1,5,0,5,1,1,1,1,1,5,10,13,5,15,15,5,15,5,15,15,15,15,5,15,15,15,15,5,15,5,15,15,5,14,10,5,1,1,1
1,1,1,1,1,5,0,5,1,1,1,1,1,5,10,13,5,15,15,5,15,5,15,15,15,15,5,15,15,15,15,5,15,5,15,15,5,14,10,5,1,1,1
1,1,1,1,1,5,0,5,1,1,1,1,1,5,10,16,13,5,15,5,15,5,15,15,15,15,5,15,15,15,15,5,15,5,15,5,16,14,10,5,1,1,1
1,1,1,1,2,5,0,5,2,1,1,1,2,3,10,10,16,13,5,5,5,3,5,5,5,5,3,5,5,5,5,3,5,5,5,16,14,10,10,3,2,1,1
1,1,1,5,0,5,0,5,0,5,1,1,1,1,5,10,10,16,16,16,16,16,16,16,16,16,16,16,16,16,16,16,16,16,16,14,10,10,5,1,1,1,1
1,1,1,5,0,5,0,5,0,5,1,1,1,1,1,5,10,10,10,10,10,10,10,10,10,10,10,10,10,10,10,10,10,10,10,10,10,5,1,1,1,1,1
1,1,1,5,0,5,0,5,0,5,1,1,1,1,1,1,3,5,5,5,3,5,5,5,3,5,5,5,3,5,5,5,3,5,5,5,3,1,1,1,1,1,1
1,1,1,1,2,5,0,5,2,1,1,1,2,1,1,1,2,1,1,1,2,1,1,1,2,1,1,1,2,1,1,1,2,1,1,1,2,1,1,1,2,1,1
1,1,1,1,1,5,5,5,1,1,1,1,1,1,1,1,1,1,1,1,1,1,1,1,1,1,1,1,1,1,1,1,1,1,1,1,1,1,1,1,1,1,1
1,1,1,1,1,5,0,5,1,1,1,1,1,1,1,1,1,1,1,1,1,1,1,1,1,1,1,1,1,1,1,1,1,1,1,1,1,1,1,1,1,1,1
endlayer

layer
1,1,5,5,5,5,5,5,5,5,5,1,5,5,5,5,5,5,5,5,5,1,5,5,5,5,5,5,5,5,5,1,5,5,5,5,5,5,5,5,5,1,1
1,1,5,0,0,0,0,0,0,0,5,1,5,0,0,0,0,0,0,0,5,1,5,0,0,0,0,0,0,0,5,1,5,0,0,0,0,0,0,0,5,1,1
1,1,5,0,0,0,0,0,0,0,5,1,5,0,0,0,0,0,0,0,5,1,5,0,0,0,0,0,0,0,5,1,5,0,0,0,0,0,0,0,5,1,1
1,1,5,0,0,0,0,0,0,0,5,1,5,0,0,0,0,0,0,0,5,1,5,0,0,0,0,0,0,0,5,1,5,0,0,0,0,0,0,0,5,1,1
1,1,5,0,0,0,0,0,0,0,5,1,5,0,0,0,0,0,0,0,5,1,5,0,0,0,0,0,0,0,5,1,5,0,0,0,0,0,0,0,5,1,1
1,1,5,0,0,0,0,0,0,0,5,1,5,0,0,0,0,0,0,0,5,1,5,0,0,0,0,0,0,0,5,1,5,0,0,0,0,0,0,0,5,1,1
1,1,5,0,0,0,0,0,0,0,5,1,5,0,0,0,0,0,0,0,5,1,5,0,0,0,0,0,0,0,5,1,5,0,0,0,0,0,0,0,5,1,1
1,1,5,0,0,0,0,0,0,0,5,1,5,0,0,0,0,0,0,0,5,1,5,0,0,0,0,0,0,0,5,1,5,0,0,0,0,0,0,0,5,1,1
1,1,5,0,0,0,0,0,0,0,5,1,5,0,0,0,0,0,0,0,5,1,5,0,0,0,0,0,0,0,5,1,5,0,0,0,0,0,0,0,5,1,1
1,1,5,0,0,0,0,0,0,0,5,1,5,0,0,0,0,0,0,0,5,1,5,0,0,0,0,0,0,0,5,1,5,0,0,0,0,0,0,0,5,1,1
1,1,5,0,0,0,0,0,0,0,5,5,5,0,0,0,0,0,0,0,5,1,5,0,0,0,0,0,0,0,5,5,5,0,0,0,0,0,0,0,5,1,1
1,1,5,17,0,0,0,0,0,0,8,0,8,0,0,0,0,0,0,17,5,1,5,17,0,0,0,0,0,0,8,0,8,0,0,0,0,0,0,17,5,1,1
5,5,5,18,19,18,19,18,19,18,5,0,5,18,19,18,19,18,19,18,5,5,5,18,19,18,19,18,19,18,5,0,5,18,19,18,19,18,19,18,5,5,5
5,5,5,18,19,18,19,18,19,18,5,5,5,18,19,18,19,18,19,18,5,5,5,18,19,18,19,18,19,18,5,5,5,18,19,18,19,18,19,18,5,5,5
5,5,5,5,5,5,5,5,5,5,5,5,5,5,5,5,5,5,5,5,5,5,5,5,5,5,5,5,5,5,5,5,5,5,5,5,5,5,5,5,5,5,5
5,5,5,5,5,5,5,5,5,5,5,5,5,5,5,5,5,5,5,5,5,5,5,5,5,5,5,5,5,5,5,5,5,5,5,5,5,5,5,5,5,5,5
5,5,5,5,8,5,5,5,8,5,5,5,8,5,5,5,8,5,5,5,8,5,5,5,8,5,5,5,8,5,5,5,8,5,5,5,8,5,5,5,8,5,5
5,5,5,5,5,5,5,5,5,5,5,5,5,5,5,5,5,5,5,5,5,5,5,5,5,5,5,5,5,5,5,5,5,5,5,5,5,5,5,5,5,5,5
5,5,5,5,5,5,5,5,5,5,5,5,5,5,5,5,5,18,19,18,19,18,19,18,19,18,19,18,19,18,19,18,19,18,19,18,5,5,5,5,5,5,5
5,5,5,5,5,5,5,5,5,5,5,5,5,5,5,5,19,0,0,0,0,0,0,0,0,0,0,0,0,0,0,0,0,0,0,0,19,5,5,5,5,5,5
5,5,5,5,8,5,5,5,8,5,5,5,8,5,5,18,0,0,0,0,0,0,0,0,0,0,0,0,0,0,0,0,0,0,0,0,0,18,5,5,8,5,5
5,5,5,5,5,5,5,5,5,5,5,5,5,5,19,0,0,0,0,0,0,0,0,0,0,0,0,0,0,0,0,0,0,0,0,0,0,0,19,5,5,5,5
5,5,5,5,5,5,5,5,5,5,5,5,5,5,18,0,0,0,0,0,0,0,0,0,0,0,0,0,0,0,0,0,0,0,0,0,0,0,18,5,5,5,5
5,5,5,5,5,5,5,5,5,5,5,5,5,5,19,0,0,0,0,0,0,0,0,0,0,0,0,0,0,0,0,0,0,0,0,0,0,0,19,5,5,5,5
5,5,5,5,8,5,5,5,8,5,5,5,8,5,18,0,0,0,0,0,0,0,0,0,0,0,0,0,0,0,0,0,0,0,0,0,0,0,18,5,8,5,5
5,5,5,5,5,5,5,5,5,5,5,5,5,5,19,0,0,0,0,0,0,0,0,0,0,0,0,0,0,0,0,0,0,0,0,0,0,0,19,5,5,5,5
5,5,5,5,5,5,5,5,5,5,5,5,5,5,18,0,0,0,0,0,0,0,0,0,0,0,0,0,0,0,0,0,0,0,0,0,0,0,18,5,5,5,5
5,5,5,5,5,5,5,5,5,5,5,5,5,5,19,0,0,0,0,0,0,0,0,0,0,0,0,0,0,0,0,0,0,0,0,0,0,0,19,5,5,5,5
5,5,5,5,8,5,5,5,8,5,5,5,8,5,18,0,0,0,0,0,0,0,0,0,0,0,0,0,0,0,0,0,0,0,0,0,0,0,18,5,8,5,5
5,5,5,5,5,5,5,5,5,5,5,5,5,5,19,0,0,0,0,0,0,0,0,0,0,0,0,0,0,0,0,0,0,0,0,0,0,0,19,5,5,5,5
20,5,5,5,5,5,5,5,5,5,5,5,5,5,18,0,0,0,0,0,0,0,0,0,0,0,0,0,0,0,0,0,0,0,0,0,0,0,18,5,5,5,5
17,5,5,5,5,5,5,5,5,5,5,5,5,5,19,0,0,0,0,0,0,0,0,0,0,0,0,0,0,0,0,0,0,0,0,0,0,0,19,5,5,5,5
5,5,5,5,8,5,5,5,8,5,5,5,8,5,5,18,0,0,0,0,0,0,0,0,0,0,0,0,0,0,0,0,0,0,0,0,0,18,5,5,8,5,5
5,5,5,5,5,5,5,5,5,5,5,5,5,5,5,5,19,0,0,0,0,0,0,0,0,0,0,0,0,0,0,0,0,0,0,0,19,5,5,5,5,5,5
5,5,5,5,5,5,5,5,5,5,5,5,5,5,5,5,5,18,19,18,19,18,19,18,19,18,19,18,19,18,19,18,19,18,19,18,5,5,5,5,5,5,5
5,5,5,5,5,5,5,5,5,5,5,5,5,5,5,5,5,5,5,5,5,5,5,5,5,5,5,5,5,5,5,5,5,5,5,5,5,5,5,5,5,5,5
5,5,5,5,8,5,5,5,8,5,5,5,8,5,5,5,8,5,5,5,8,5,5,5,8,5,5,5,8,5,5,5,8,5,5,5,8,5,5,5,8,5,5
5,5,5,5,5,5,5,5,5,5,5,5,5,5,5,5,5,5,5,5,5,5,5,5,5,5,5,5,5,5,5,5,5,5,5,5,5,5,5,5,5,5,5
5,5,5,5,5,5,5,5,5,5,5,5,5,5,5,5,5,5,5,5,5,5,5,5,5,5,5,5,5,5,5,5,5,5,5,5,5,5,5,5,5,5,5
endlayer

layer
1,1,5,5,5,5,5,5,5,5,5,1,5,5,5,5,5,5,5,5,5,1,5,5,5,5,5,5,5,5,5,1,5,5,5,5,5,5,5,5,5,1,1
1,1,5,0,0,0,0,0,0,0,5,1,5,0,0,0,0,0,0,0,5,1,5,0,0,0,0,0,0,0,5,1,5,0,0,0,0,0,0,0,5,1,1
1,1,16,0,0,0,0,0,0,0,16,1,16,0,0,0,0,0,0,0,16,1,16,0,0,0,0,0,0,0,16,1,16,0,0,0,0,0,0,0,16,1,1
1,1,14,0,0,0,0,0,0,0,13,1,14,0,0,0,0,0,0,0,13,1,14,0,0,0,0,0,0,0,13,1,14,0,0,0,0,0,0,0,13,1,1
1,1,14,0,0,0,0,0,0,0,13,1,14,0,0,0,0,0,0,0,13,1,14,0,0,0,0,0,0,0,13,1,14,0,0,0,0,0,0,0,13,1,1
1,1,14,0,0,0,0,0,0,0,13,1,14,0,0,0,0,0,0,0,13,1,14,0,0,0,0,0,0,0,13,1,14,0,0,0,0,0,0,0,13,1,1
1,1,14,0,0,0,0,0,0,0,13,1,14,0,0,0,0,0,0,0,13,1,14,0,0,0,0,0,0,0,13,1,14,0,0,0,0,0,0,0,13,1,1
1,1,14,0,0,0,0,0,0,0,13,1,14,0,0,0,0,0,0,0,13,1,14,0,0,0,0,0,0,0,13,1,14,0,0,0,0,0,0,0,13,1,1
1,1,14,0,0,0,0,0,0,0,13,1,14,0,0,0,0,0,0,0,13,1,14,0,0,0,0,0,0,0,13,1,14,0,0,0,0,0,0,0,13,1,1
1,1,14,0,0,0,0,0,0,0,13,1,14,0,0,0,0,0,0,0,13,1,14,0,0,0,0,0,0,0,13,1,14,0,0,0,0,0,0,0,13,1,1
1,1,14,0,0,0,0,0,0,0,13,5,14,0,0,0,0,0,0,0,13,1,14,0,0,0,0,0,0,0,13,5,14,0,0,0,0,0,0,0,13,1,1
1,1,14,0,0,0,0,0,0,0,13,5,14,0,0,0,0,0,0,0,13,1,14,0,0,0,0,0,0,0,13,5,14,0,0,0,0,0,0,0,13,1,1
5,5,16,0,0,0,0,0,0,0,16,5,16,0,0,0,0,0,0,0,16,5,16,0,0,0,0,0,0,0,16,5,16,0,0,0,0,0,0,0,16,5,5
5,0,0,0,0,0,0,0,0,0,0,0,0,0,0,0,0,0,0,0,0,0,0,0,0,0,0,0,0,0,0,0,0,0,0,0,0,0,0,0,0,0,5
5,0,0,0,0,0,0,0,0,0,0,0,0,0,0,0,0,0,0,0,0,0,0,0,0,0,0,0,0,0,0,0,0,0,0,0,0,0,0,0,0,0,5
5,0,0,0,0,0,0,0,0,0,0,0,0,0,0,0,0,0,0,0,0,0,0,0,0,0,0,0,0,0,0,0,0,0,0,0,0,0,0,0,0,0,5
5,0,0,0,0,0,0,0,0,0,0,0,0,0,0,0,0,0,0,0,0,0,0,0,0,0,0,0,0,0,0,0,0,0,0,0,0,0,0,0,0,0,5
5,0,0,0,0,0,0,0,0,0,0,0,0,0,0,0,0,0,0,0,0,0,0,0,0,0,0,0,0,0,0,0,0,0,0,0,0,0,0,0,0,0,5
5,0,0,0,0,0,0,0,0,0,0,0,0,0,0,0,0,0,0,0,0,0,0,0,0,0,0,0,0,0,0,0,0,0,0,0,0,0,0,0,0,0,5
5,0,0,0,0,0,0,0,0,0,0,0,0,0,0,0,0,0,0,0,0,0,0,0,0,0,0,0,0,0,0,0,0,0,0,0,0,0,0,0,0,0,5
5,0,0,0,0,0,0,0,0,0,0,0,0,0,0,0,0,0,0,0,0,0,0,0,0,0,0,0,0,0,0,0,0,0,0,0,0,0,0,0,0,0,5
5,0,0,0,0,0,0,0,0,0,0,0,0,0,0,0,0,0,0,0,0,0,0,0,0,0,0,0,0,0,0,0,0,0,0,0,0,0,0,0,0,0,5
5,0,0,0,0,0,0,0,0,0,0,0,0,0,0,0,0,0,0,0,0,0,0,0,0,0,0,0,0,0,0,0,0,0,0,0,0,0,0,0,0,0,5
5,0,0,0,0,0,0,0,0,0,0,0,0,0,0,0,0,0,0,0,0,0,0,0,0,0,0,0,0,0,0,0,0,0,0,0,0,0,0,0,0,0,5
5,0,0,0,0,0,0,0,0,0,0,0,0,0,0,0,0,0,0,0,0,0,0,0,0,0,0,0,0,0,0,0,0,0,0,0,0,0,0,0,0,0,5
0,0,0,0,0,0,0,0,0,0,0,0,0,0,0,0,0,0,0,0,0,0,0,0,0,0,0,0,0,0,0,0,0,0,0,0,0,0,0,0,0,0,5
0,0,0,0,0,0,0,0,0,0,0,0,0,0,0,0,0,0,0,0,0,0,0,0,0,0,0,0,0,0,0,0,0,0,0,0,0,0,0,0,0,0,5
0,0,0,0,0,0,0,0,0,0,0,0,0,0,0,0,0,0,0,0,0,0,0,0,0,0,0,0,0,0,0,0,0,0,0,0,0,0,0,0,0,0,5
5,0,0,0,0,0,0,0,0,0,0,0,0,0,0,0,0,0,0,0,0,0,0,0,0,0,0,0,0,0,0,0,0,0,0,0,0,0,0,0,0,0,5
5,0,0,0,0,0,0,0,0,0,0,0,0,0,0,0,0,0,0,0,0,0,0,0,0,0,0,0,0,0,0,0,0,0,0,0,0,0,0,0,0,0,5
20,0,0,0,0,0,0,0,0,0,0,0,0,0,0,0,0,0,0,0,0,0,0,0,0,0,0,0,0,0,0,0,0,0,0,0,0,0,0,0,0,0,5
17,0,0,0,0,0,0,0,0,0,0,0,0,0,0,0,0,0,0,0,0,0,0,0,0,0,0,0,0,0,0,0,0,0,0,0,0,0,0,0,0,0,5
5,0,0,0,0,0,0,0,0,0,0,0,0,0,0,0,0,0,0,0,0,0,0,0,0,0,0,0,0,0,0,0,0,0,0,0,0,0,0,0,0,0,5
5,0,0,0,0,0,0,0,0,0,0,0,0,0,0,0,0,0,0,0,0,0,0,0,0,0,0,0,0,0,0,0,0,0,0,0,0,0,0,0,0,0,5
5,0,0,0,0,0,0,0,0,0,0,0,0,0,0,0,0,0,0,0,0,0,0,0,0,0,0,0,0,0,0,0,0,0,0,0,0,0,0,0,0,0,5
5,0,0,0,0,0,0,0,0,0,0,0,0,0,0,0,0,0,0,0,0,0,0,0,0,0,0,0,0,0,0,0,0,0,0,0,0,0,0,0,0,0,5
5,0,0,0,0,0,0,0,0,0,0,0,0,0,0,0,0,0,0,0,0,0,0,0,0,0,0,0,0,0,0,0,0,0,0,0,0,0,0,0,0,0,5
5,5,0,0,0,0,0,0,0,0,0,5,0,0,0,0,0,0,0,0,0,5,0,0,0,0,0,0,0,0,0,5,0,0,0,0,0,0,0,0,0,5,5
5,5,5,5,5,5,5,5,5,5,5,5,5,5,5,5,5,5,5,5,5,5,5,5,5,5,5,5,5,5,5,5,5,5,5,5,5,5,5,5,5,5,5
endlayer

layer
1,1,5,5,5,5,5,5,5,5,5,1,5,5,5,5,5,5,5,5,5,1,5,5,5,5,5,5,5,5,5,1,5,5,5,5,5,5,5,5,5,1,1
1,1,5,0,0,0,0,0,0,0,5,1,5,0,0,0,0,0,0,0,5,1,5,0,0,0,0,0,0,0,5,1,5,0,0,0,0,0,0,0,5,1,1
1,1,5,0,0,0,0,0,0,0,5,1,5,0,0,0,0,0,0,0,5,1,5,0,0,0,0,0,0,0,5,1,5,0,0,0,0,0,0,0,5,1,1
1,1,5,0,0,0,0,0,0,0,5,1,5,0,0,0,0,0,0,0,5,1,5,0,0,0,0,0,0,0,5,1,5,0,0,0,0,0,0,0,5,1,1
1,1,5,0,0,0,0,0,0,0,5,1,5,0,0,0,0,0,0,0,5,1,5,0,0,0,0,0,0,0,5,1,5,0,0,0,0,0,0,0,5,1,1
1,1,5,0,0,0,0,0,0,0,5,1,5,0,0,0,0,0,0,0,5,1,5,0,0,0,0,0,0,0,5,1,5,0,0,0,0,0,0,0,5,1,1
1,1,5,0,0,0,0,0,0,0,5,1,5,0,0,0,0,0,0,0,5,1,5,0,0,0,0,0,0,0,5,1,5,0,0,0,0,0,0,0,5,1,1
1,1,5,0,0,0,0,0,0,0,5,1,5,0,0,0,0,0,0,0,5,1,5,0,0,0,0,0,0,0,5,1,5,0,0,0,0,0,0,0,5,1,1
1,1,5,0,0,0,0,0,0,0,5,1,5,0,0,0,0,0,0,0,5,1,5,0,0,0,0,0,0,0,5,1,5,0,0,0,0,0,0,0,5,1,1
1,1,5,0,0,0,0,0,0,0,5,1,5,0,0,0,0,0,0,0,5,1,5,0,0,0,0,0,0,0,5,1,5,0,0,0,0,0,0,0,5,1,1
1,1,5,0,0,0,0,0,0,0,5,1,5,0,0,0,0,0,0,0,5,1,5,0,0,0,0,0,0,0,5,1,5,0,0,0,0,0,0,0,5,1,1
1,1,5,0,0,0,0,0,0,0,5,1,5,0,0,0,0,0,0,0,5,1,5,0,0,0,0,0,0,0,5,1,5,0,0,0,0,0,0,0,5,1,1
5,5,5,0,0,0,0,0,0,0,5,5,5,0,0,0,0,0,0,0,5,5,5,0,0,0,0,0,0,0,5,5,5,0,0,0,0,0,0,0,5,5,5
5,0,0,0,0,0,0,0,0,0,0,0,0,0,0,0,0,0,0,0,0,0,0,0,0,0,0,0,0,0,0,0,0,0,0,0,0,0,0,0,0,0,5
21,0,0,0,0,0,0,0,0,0,0,0,0,0,0,0,0,0,0,0,0,0,0,0,0,0,0,0,0,0,0,0,0,0,0,0,0,0,0,0,0,0,21
5,0,0,0,0,0,0,0,0,0,0,0,0,0,0,0,0,0,0,0,0,0,0,0,0,0,0,0,0,0,0,0,0,0,0,0,0,0,0,0,0,0,5
5,0,0,0,0,0,0,0,0,0,0,0,0,0,0,0,0,0,0,0,0,0,0,0,0,0,0,0,0,0,0,0,0,0,0,0,0,0,0,0,0,0,5
5,0,0,0,0,0,0,0,0,0,0,0,0,0,0,0,0,0,0,0,0,0,0,0,0,0,0,0,0,0,0,0,0,0,0,0,0,0,0,0,0,0,5
5,0,0,0,0,0,0,0,0,0,0,0,0,0,0,0,0,0,0,0,0,0,0,0,0,0,0,0,0,0,0,0,0,0,0,0,0,0,0,0,0,0,5
5,0,0,0,0,0,0,0,0,0,0,0,0,0,0,0,0,0,0,0,0,0,0,0,0,0,0,0,0,0,0,0,0,0,0,0,0,0,0,0,0,0,5
5,0,0,0,0,0,0,0,0,0,0,0,0,0,0,0,0,0,0,0,0,0,0,0,0,0,0,0,0,0,0,0,0,0,0,0,0,0,0,0,0,0,5
5,0,0,0,0,0,0,0,0,0,0,0,0,0,0,0,0,0,0,0,0,0,0,0,0,0,0,0,0,0,0,0,0,0,0,0,0,0,0,0,0,0,5
5,0,0,0,0,0,0,0,0,0,0,0,0,0,0,0,0,0,0,0,0,0,0,0,0,0,0,0,0,0,0,0,0,0,0,0,0,0,0,0,0,0,5
5,0,0,0,0,0,0,0,0,0,0,0,0,0,0,0,0,0,0,0,0,0,0,0,0,0,0,0,0,0,0,0,0,0,0,0,0,0,0,0,0,0,5
5,0,0,0,0,0,0,0,0,0,0,0,0,0,0,0,0,0,0,0,0,0,0,0,0,0,0,0,0,0,0,0,0,0,0,0,0,0,0,0,0,0,5
0,0,0,0,0,0,0,0,0,0,0,0,0,0,0,0,0,0,0,0,0,0,0,0,0,0,0,0,0,0,0,0,0,0,0,0,0,0,0,0,0,0,5
0,0,0,0,0,0,0,0,0,0,0,0,0,0,0,0,0,0,0,0,0,0,0,0,0,0,0,0,0,0,0,0,0,0,0,0,0,0,0,0,0,0,5
0,0,0,0,0,0,0,0,0,0,0,0,0,0,0,0,0,0,0,0,0,0,0,0,0,0,0,0,0,0,0,0,0,0,0,0,0,0,0,0,0,0,5
5,0,0,0,0,0,0,0,0,0,0,0,0,0,0,0,0,0,0,0,0,0,0,0,0,0,0,0,0,0,0,0,0,0,0,0,0,0,0,0,0,0,5
5,0,0,0,0,0,0,0,0,0,0,0,0,0,0,0,0,0,0,0,0,0,0,0,0,0,0,0,0,0,0,0,0,0,0,0,0,0,0,0,0,0,5
20,0,0,0,0,0,0,0,0,0,0,0,0,0,0,0,0,0,0,0,0,0,0,0,0,0,0,0,0,0,0,0,0,0,0,0,0,0,0,0,0,0,5
17,0,0,0,0,0,0,0,0,0,0,0,0,0,0,0,0,0,0,0,0,0,0,0,0,0,0,0,0,0,0,0,0,0,0,0,0,0,0,0,0,0,5
5,0,0,0,0,0,0,0,0,0,0,0,0,0,0,0,0,0,0,0,0,0,0,0,0,0,0,0,0,0,0,0,0,0,0,0,0,0,0,0,0,0,5
5,0,0,0,0,0,0,0,0,0,0,0,0,0,0,0,0,0,0,0,0,0,0,0,0,0,0,0,0,0,0,0,0,0,0,0,0,0,0,0,0,0,5
5,0,0,0,0,0,0,0,0,0,0,0,0,0,0,0,0,0,0,0,0,0,0,0,0,0,0,0,0,0,0,0,0,0,0,0,0,0,0,0,0,0,5
21,0,0,0,0,0,0,0,0,0,0,0,0,0,0,0,0,0,0,0,0,0,0,0,0,0,0,0,0,0,0,0,0,0,0,0,0,0,0,0,0,0,21
5,0,0,0,0,0,0,0,0,0,0,0,0,0,0,0,0,0,0,0,0,0,0,0,0,0,0,0,0,0,0,0,0,0,0,0,0,0,0,0,0,0,5
5,5,0,0,0,0,0,0,0,0,0,5,0,0,0,0,0,0,0,0,0,5,0,0,0,0,0,0,0,0,0,5,0,0,0,0,0,0,0,0,0,5,5
5,5,5,21,5,5,5,5,5,5,5,5,5,5,5,5,5,5,5,5,5,5,5,5,5,5,5,5,5,5,5,5,5,5,5,5,5,5,5,21,5,5,5
endlayer

layer
1,1,5,5,5,5,5,5,5,5,5,1,5,5,5,5,5,5,5,5,5,1,5,5,5,5,5,5,5,5,5,1,5,5,5,5,5,5,5,5,5,1,1
1,1,5,0,0,0,0,0,0,0,5,1,5,0,0,0,0,0,0,0,5,1,5,0,0,0,0,0,0,0,5,1,5,0,0,0,0,0,0,0,5,1,1
1,1,5,0,0,0,0,0,0,0,5,1,5,0,0,0,0,0,0,0,5,1,5,0,0,0,0,0,0,0,5,1,5,0,0,0,0,0,0,0,5,1,1
1,1,5,0,0,0,0,0,0,0,5,1,5,0,0,0,0,0,0,0,5,1,5,0,0,0,0,0,0,0,5,1,5,0,0,0,0,0,0,0,5,1,1
1,1,5,0,0,0,0,0,0,0,5,1,5,0,0,0,0,0,0,0,5,1,5,0,0,0,0,0,0,0,5,1,5,0,0,0,0,0,0,0,5,1,1
1,1,5,0,0,0,0,0,0,0,5,1,5,0,0,0,0,0,0,0,5,1,5,0,0,0,0,0,0,0,5,1,5,0,0,0,0,0,0,0,5,1,1
1,1,5,0,0,0,0,0,0,0,5,1,5,0,0,0,0,0,0,0,5,1,5,0,0,0,0,0,0,0,5,1,5,0,0,0,0,0,0,0,5,1,1
1,1,5,0,0,0,0,0,0,0,5,1,5,0,0,0,0,0,0,0,5,1,5,0,0,0,0,0,0,0,5,1,5,0,0,0,0,0,0,0,5,1,1
1,1,5,0,0,0,0,0,0,0,5,1,5,0,0,0,0,0,0,0,5,1,5,0,0,0,0,0,0,0,5,1,5,0,0,0,0,0,0,0,5,1,1
1,1,5,0,0,0,0,0,0,0,5,1,5,0,0,0,0,0,0,0,5,1,5,0,0,0,0,0,0,0,5,1,5,0,0,0,0,0,0,0,5,1,1
1,1,5,0,0,0,0,0,0,0,5,1,5,0,0,0,0,0,0,0,5,1,5,0,0,0,0,0,0,0,5,1,5,0,0,0,0,0,0,0,5,1,1
1,1,5,0,0,0,0,0,0,0,5,1,5,0,0,0,0,0,0,0,5,1,5,0,0,0,0,0,0,0,5,1,5,0,0,0,0,0,0,0,5,1,1
5,5,24,0,0,0,0,0,0,0,24,5,22,0,0,0,0,0,0,0,22,5,23,0,0,0,0,0,0,0,23,5,22,0,0,0,0,0,0,0,22,5,5
5,0,0,0,0,0,0,0,0,0,0,0,0,0,0,0,0,0,0,0,0,0,0,0,0,0,0,0,0,0,0,0,0,0,0,0,0,0,0,0,0,0,5
21,0,0,0,0,0,0,0,0,0,0,0,0,0,0,0,0,0,0,0,0,0,0,0,0,0,0,0,0,0,0,0,0,0,0,0,0,0,0,0,0,0,21
5,0,0,0,0,0,0,0,0,0,0,0,0,0,0,0,0,0,0,0,0,0,0,0,0,0,0,0,0,0,0,0,0,0,0,0,0,0,0,0,0,0,5
5,0,0,0,0,0,0,0,0,0,0,0,0,0,0,0,0,0,0,0,0,0,0,0,0,0,0,0,0,0,0,0,0,0,0,0,0,0,0,0,0,0,5
5,0,0,0,0,0,0,0,0,0,0,0,0,0,0,0,0,0,0,0,0,0,0,0,0,0,0,0,0,0,0,0,0,0,0,0,0,0,0,0,0,0,5
5,0,0,0,0,0,0,0,0,0,0,0,0,0,0,0,0,0,0,0,0,0,0,0,0,0,0,0,0,0,0,0,0,0,0,0,0,0,0,0,0,0,5
5,0,0,0,0,0,0,0,0,0,0,0,0,0,0,0,0,0,0,0,0,0,0,0,0,0,0,0,0,0,0,0,0,0,0,0,0,0,0,0,0,0,5
5,0,0,0,0,0,0,0,0,0,0,0,0,0,0,0,0,0,0,0,0,0,0,0,0,0,0,0,0,0,0,0,0,0,0,0,0,0,0,0,0,0,5
5,0,0,0,0,0,0,0,0,0,0,0,0,0,0,0,0,0,0,0,0,0,0,0,0,0,0,0,0,0,0,0,0,0,0,0,0,0,0,0,0,0,5
5,0,0,0,0,0,0,0,0,0,0,0,0,0,0,0,0,0,0,0,0,0,0,0,0,0,0,0,0,0,0,0,0,0,0,0,0,0,0,0,0,0,5
5,0,0,0,0,0,0,0,0,0,0,0,0,0,0,0,0,0,0,0,0,0,0,0,0,0,0,0,0,0,0,0,0,0,0,0,0,0,0,0,0,0,5
5,0,0,0,0,0,0,0,0,0,0,0,0,0,0,0,0,0,0,0,0,0,0,0,0,0,0,0,0,0,0,0,0,0,0,0,0,0,0,0,0,0,5
0,0,0,0,0,0,0,0,0,0,0,0,0,0,0,0,0,0,0,0,0,0,0,0,0,0,0,0,0,0,0,0,0,0,0,0,0,0,0,0,0,0,5
0,0,0,0,0,0,0,0,0,0,0,0,0,0,0,0,0,0,0,0,0,0,0,0,0,0,0,0,0,0,0,0,0,0,0,0,0,0,0,0,0,0,5
0,0,0,0,0,0,0,0,0,0,0,0,0,0,0,0,0,0,0,0,0,0,0,0,0,0,0,0,0,0,0,0,0,0,0,0,0,0,0,0,0,0,5
5,0,0,0,0,0,0,0,0,0,0,0,0,0,0,0,0,0,0,0,0,0,0,0,0,0,0,0,0,0,0,0,0,0,0,0,0,0,0,0,0,0,5
5,0,0,0,0,0,0,0,0,0,0,0,0,0,0,0,0,0,0,0,0,0,0,0,0,0,0,0,0,0,0,0,0,0,0,0,0,0,0,0,0,0,5
20,0,0,0,0,0,0,0,0,0,0,0,0,0,0,0,0,0,0,0,0,0,0,0,0,0,0,0,0,0,0,0,0,0,0,0,0,0,0,0,0,0,5
17,0,0,0,0,0,0,0,0,0,0,0,0,0,0,0,0,0,0,0,0,0,0,0,0,0,0,0,0,0,0,0,0,0,0,0,0,0,0,0,0,0,5
5,0,0,0,0,0,0,0,0,0,0,0,0,0,0,0,0,0,0,0,0,0,0,0,0,0,0,0,0,0,0,0,0,0,0,0,0,0,0,0,0,0,5
5,0,0,0,0,0,0,0,0,0,0,0,0,0,0,0,0,0,0,0,0,0,0,0,0,0,0,0,0,0,0,0,0,0,0,0,0,0,0,0,0,0,5
5,0,0,0,0,0,0,0,0,0,0,0,0,0,0,0,0,0,0,0,0,0,0,0,0,0,0,0,0,0,0,0,0,0,0,0,0,0,0,0,0,0,5
21,0,0,0,0,0,0,0,0,0,0,0,0,0,0,0,0,0,0,0,0,0,0,0,0,0,0,0,0,0,0,0,0,0,0,0,0,0,0,0,0,0,21
5,0,0,0,0,0,0,0,0,0,0,0,0,0,0,0,0,0,0,0,0,0,0,0,0,0,0,0,0,0,0,0,0,0,0,0,0,0,0,0,0,0,5
5,5,0,0,0,0,0,0,0,0,0,5,0,0,0,0,0,0,0,0,0,5,0,0,0,0,0,0,0,0,0,5,0,0,0,0,0,0,0,0,0,5,5
5,5,5,21,5,5,5,5,5,5,5,5,5,5,5,5,5,5,5,5,5,5,5,5,5,5,5,5,5,5,5,5,5,5,5,5,5,5,5,21,5,5,5
endlayer

layer
1,1,5,24,24,24,24,24,24,24,5,1,5,22,22,22,22,22,22,22,5,1,5,23,23,23,23,23,23,23,5,1,5,22,22,22,22,22,22,22,5,1,1
1,1,24,0,0,0,0,0,0,0,24,1,22,0,0,0,0,0,0,0,22,1,23,0,0,0,0,0,0,0,23,1,22,0,0,0,0,0,0,0,22,1,1
1,1,24,0,0,0,0,0,0,0,24,1,22,0,0,0,0,0,0,0,22,1,23,0,0,0,0,0,0,0,23,1,22,0,0,0,0,0,0,0,22,1,1
1,1,24,0,0,0,0,0,0,0,24,1,22,0,0,0,0,0,0,0,22,1,23,0,0,0,0,0,0,0,23,1,22,0,0,0,0,0,0,0,22,1,1
1,1,24,0,0,0,0,0,0,0,24,1,22,0,0,0,0,0,0,0,22,1,23,0,0,0,0,0,0,0,23,1,22,0,0,0,0,0,0,0,22,1,1
1,1,24,0,0,0,0,0,0,0,24,1,22,0,0,0,0,0,0,0,22,1,23,0,0,0,0,0,0,0,23,1,22,0,0,0,0,0,0,0,22,1,1
1,1,24,0,0,0,0,0,0,0,24,1,22,0,0,0,0,0,0,0,22,1,23,0,0,0,0,0,0,0,23,1,22,0,0,0,0,0,0,0,22,1,1
1,1,24,0,0,0,0,0,0,0,24,1,22,0,0,0,0,0,0,0,22,1,23,0,0,0,0,0,0,0,23,1,22,0,0,0,0,0,0,0,22,1,1
1,1,24,0,0,0,0,0,0,0,24,1,22,0,0,0,0,0,0,0,22,1,23,0,0,0,0,0,0,0,23,1,22,0,0,0,0,0,0,0,22,1,1
1,1,24,0,0,0,0,0,0,0,24,1,22,0,0,0,0,0,0,0,22,1,23,0,0,0,0,0,0,0,23,1,22,0,0,0,0,0,0,0,22,1,1
1,1,24,0,0,0,0,0,0,0,24,1,22,0,0,0,0,0,0,0,22,1,23,0,0,0,0,0,0,0,23,1,22,0,0,0,0,0,0,0,22,1,1
1,1,24,0,0,0,0,0,0,0,24,1,22,0,0,0,0,0,0,0,22,1,23,0,0,0,0,0,0,0,23,1,22,0,0,0,0,0,0,0,22,1,1
5,5,24,0,0,0,0,0,0,0,24,5,22,0,0,0,0,0,0,0,22,5,23,0,0,0,0,0,0,0,23,5,22,0,0,0,0,0,0,0,22,5,5
5,0,0,0,0,0,0,0,0,0,0,0,0,0,0,0,0,0,0,0,0,0,0,0,0,0,0,0,0,0,0,0,0,0,0,0,0,0,0,0,0,0,5
21,0,0,0,0,0,0,0,0,0,0,0,0,0,0,0,0,0,0,0,0,0,0,0,0,0,0,0,0,0,0,0,0,0,0,0,0,0,0,0,0,0,21
21,0,0,0,0,0,0,0,0,0,0,0,0,0,0,0,0,0,0,0,0,0,0,0,0,0,0,0,0,0,0,0,0,0,0,0,0,0,0,0,0,0,21
21,0,0,0,0,0,0,0,0,0,0,0,0,0,0,0,0,0,0,0,0,0,0,0,0,0,0,0,0,0,0,0,0,0,0,0,0,0,0,0,0,0,21
21,0,0,0,0,0,0,0,0,0,0,0,0,0,0,0,0,0,0,0,0,0,0,0,0,0,0,0,0,0,0,0,0,0,0,0,0,0,0,0,0,0,21
21,0,0,0,0,0,0,0,0,0,0,0,0,0,0,0,0,0,0,0,0,0,0,0,0,0,0,0,0,0,0,0,0,0,0,0,0,0,0,0,0,0,21
21,0,0,0,0,0,0,0,0,0,0,0,0,0,0,0,0,0,0,0,0,0,0,0,0,0,0,0,0,0,0,0,0,0,0,0,0,0,0,0,0,0,21
21,0,0,0,0,0,0,0,0,0,0,0,0,0,0,0,0,0,0,0,0,0,0,0,0,0,0,0,0,0,0,0,0,0,0,0,0,0,0,0,0,0,21
21,0,0,0,0,0,0,0,0,0,0,0,0,0,0,0,0,0,0,0,0,0,0,0,0,0,0,0,0,0,0,0,0,0,0,0,0,0,0,0,0,0,21
21,0,0,0,0,0,0,0,0,0,0,0,0,0,0,0,0,0,0,0,0,0,0,0,0,0,0,0,0,0,0,0,0,0,0,0,0,0,0,0,0,0,21
21,0,0,0,0,0,0,0,0,0,0,0,0,0,0,0,0,0,0,0,0,0,0,0,0,0,0,0,0,0,0,0,0,0,0,0,0,0,0,0,0,0,21
21,0,0,0,0,0,0,0,0,0,0,0,0,0,0,0,0,0,0,0,0,0,0,0,0,0,0,0,0,0,0,0,0,0,0,0,0,0,0,0,0,0,21
21,0,0,0,0,0,0,0,0,0,0,0,0,0,0,0,0,0,0,0,0,0,0,0,0,0,0,0,0,0,0,0,0,0,0,0,0,0,0,0,0,0,21
21,0,0,0,0,0,0,0,0,0,0,0,0,0,0,0,0,0,0,0,0,0,0,0,0,0,0,0,0,0,0,0,0,0,0,0,0,0,0,0,0,0,21
21,0,0,0,0,0,0,0,0,0,0,0,0,0,0,0,0,0,0,0,0,0,0,0,0,0,0,0,0,0,0,0,0,0,0,0,0,0,0,0,0,0,21
21,0,0,0,0,0,0,0,0,0,0,0,0,0,0,0,0,0,0,0,0,0,0,0,0,0,0,0,0,0,0,0,0,0,0,0,0,0,0,0,0,0,21
21,0,0,0,0,0,0,0,0,0,0,0,0,0,0,0,0,0,0,0,0,0,0,0,0,0,0,0,0,0,0,0,0,0,0,0,0,0,0,0,0,0,21
20,0,0,0,0,0,0,0,0,0,0,0,0,0,0,0,0,0,0,0,0,0,0,0,0,0,0,0,0,0,0,0,0,0,0,0,0,0,0,0,0,0,21
17,0,0,0,0,0,0,0,0,0,0,0,0,0,0,0,0,0,0,0,0,0,0,0,0,0,0,0,0,0,0,0,0,0,0,0,0,0,0,0,0,0,21
21,0,0,0,0,0,0,0,0,0,0,0,0,0,0,0,0,0,0,0,0,0,0,0,0,0,0,0,0,0,0,0,0,0,0,0,0,0,0,0,0,0,21
21,0,0,0,0,0,0,0,0,0,0,0,0,0,0,0,0,0,0,0,0,0,0,0,0,0,0,0,0,0,0,0,0,0,0,0,0,0,0,0,0,0,21
21,0,0,0,0,0,0,0,0,0,0,0,0,0,0,0,0,0,0,0,0,0,0,0,0,0,0,0,0,0,0,0,0,0,0,0,0,0,0,0,0,0,21
21,0,0,0,0,0,0,0,0,0,0,0,0,0,0,0,0,0,0,0,0,0,0,0,0,0,0,0,0,0,0,0,0,0,0,0,0,0,0,0,0,0,21
5,0,0,0,0,0,0,0,0,0,0,0,0,0,0,0,0,0,0,0,0,0,0,0,0,0,0,0,0,0,0,0,0,0,0,0,0,0,0,0,0,0,5
5,5,0,0,0,0,0,0,0,0,0,21,0,0,0,0,0,0,0,0,0,21,0,0,0,0,0,0,0,0,0,21,0,0,0,0,0,0,0,0,0,5,5
5,5,5,21,21,21,21,21,21,21,21,5,21,21,21,21,21,21,21,21,21,5,21,21,21,21,21,21,21,21,21,5,21,21,21,21,21,21,21,21,5,5,5
endlayer

layer
1,1,5,5,5,5,5,5,5,5,5,1,5,5,5,5,5,5,5,5,5,1,5,5,5,5,5,5,5,5,5,1,5,5,5,5,5,5,5,5,5,1,1
1,1,5,0,0,0,0,0,0,0,5,1,5,0,0,0,0,0,0,0,5,1,5,0,0,0,0,0,0,0,5,1,5,0,0,0,0,0,0,0,5,1,1
1,1,5,0,0,0,0,0,0,0,5,1,5,0,0,0,0,0,0,0,5,1,5,0,0,0,0,0,0,0,5,1,5,0,0,0,0,0,0,0,5,1,1
1,1,5,0,0,0,0,0,0,0,5,1,5,0,0,0,0,0,0,0,5,1,5,0,0,0,0,0,0,0,5,1,5,0,0,0,0,0,0,0,5,1,1
1,1,5,0,0,0,0,0,0,0,5,1,5,0,0,0,0,0,0,0,5,1,5,0,0,0,0,0,0,0,5,1,5,0,0,0,0,0,0,0,5,1,1
1,1,5,0,0,0,0,0,0,0,5,1,5,0,0,0,0,0,0,0,5,1,5,0,0,0,0,0,0,0,5,1,5,0,0,0,0,0,0,0,5,1,1
1,1,5,0,0,0,0,0,0,0,5,1,5,0,0,0,0,0,0,0,5,1,5,0,0,0,0,0,0,0,5,1,5,0,0,0,0,0,0,0,5,1,1
1,1,5,0,0,0,0,0,0,0,5,1,5,0,0,0,0,0,0,0,5,1,5,0,0,0,0,0,0,0,5,1,5,0,0,0,0,0,0,0,5,1,1
1,1,5,0,0,0,0,0,0,0,5,1,5,0,0,0,0,0,0,0,5,1,5,0,0,0,0,0,0,0,5,1,5,0,0,0,0,0,0,0,5,1,1
1,1,5,0,0,0,0,0,0,0,5,1,5,0,0,0,0,0,0,0,5,1,5,0,0,0,0,0,0,0,5,1,5,0,0,0,0,0,0,0,5,1,1
1,1,5,0,0,0,0,0,0,0,5,1,5,0,0,0,0,0,0,0,5,1,5,0,0,0,0,0,0,0,5,1,5,0,0,0,0,0,0,0,5,1,1
1,1,5,0,0,0,0,0,0,0,5,1,5,0,0,0,0,0,0,0,5,1,5,0,0,0,0,0,0,0,5,1,5,0,0,0,0,0,0,0,5,1,1
5,5,5,0,0,0,0,0,0,0,5,5,5,0,0,0,0,0,0,0,5,5,5,0,0,0,0,0,0,0,5,5,5,0,0,0,0,0,0,0,5,5,5
5,0,0,0,0,0,0,0,0,0,0,0,0,0,0,0,0,0,0,0,0,0,0,0,0,0,0,0,0,0,0,0,0,0,0,0,0,0,0,0,0,0,5
5,0,0,0,0,0,0,0,0,0,0,0,0,0,0,0,0,0,0,0,0,0,0,0,0,0,0,0,0,0,0,0,0,0,0,0,0,0,0,0,0,0,5
5,0,0,0,0,0,0,0,0,0,0,0,0,0,0,0,0,0,0,0,0,0,0,0,0,0,0,0,0,0,0,0,0,0,0,0,0,0,0,0,0,0,5
5,0,0,0,0,0,0,0,0,0,0,0,0,0,0,0,0,0,0,0,0,0,0,0,0,0,0,0,0,0,0,0,0,0,0,0,0,0,0,0,0,0,5
5,0,0,0,0,0,0,0,0,0,0,0,0,0,0,0,0,0,0,0,0,0,0,0,0,0,0,0,0,0,0,0,0,0,0,0,0,0,0,0,0,0,5
5,0,0,0,0,0,0,0,0,0,0,0,0,0,0,0,0,0,0,0,0,0,0,0,0,0,0,0,0,0,0,0,0,0,0,0,0,0,0,0,0,0,5
5,0,0,0,0,0,0,0,0,0,0,0,0,0,0,0,0,0,0,0,0,0,0,0,0,0,0,0,0,0,0,0,0,0,0,0,0,0,0,0,0,0,5
5,0,0,0,0,0,0,0,0,0,0,0,0,0,0,0,0,0,0,0,0,0,0,0,0,0,0,0,0,0,0,0,0,0,0,0,0,0,0,0,0,0,5
5,0,0,0,0,0,0,0,0,0,0,0,0,0,0,0,0,0,0,0,0,0,0,0,0,0,0,0,0,0,0,0,0,0,0,0,0,0,0,0,0,0,5
5,0,0,0,0,0,0,0,0,0,0,0,0,0,0,0,0,0,0,0,0,0,0,0,0,0,0,0,0,0,0,0,0,0,0,0,0,0,0,0,0,0,5
5,0,0,0,0,0,0,0,0,0,0,0,0,0,0,0,0,0,0,0,0,0,0,0,0,0,0,0,0,0,0,0,0,0,0,0,0,0,0,0,0,0,5
5,0,0,0,0,0,0,0,0,0,0,0,0,0,0,0,0,0,0,0,0,0,0,0,0,0,0,0,0,0,0,0,0,0,0,0,0,0,0,0,0,0,5
5,0,0,0,0,0,0,0,0,0,0,0,0,0,0,0,0,0,0,0,0,0,0,0,0,0,0,0,0,0,0,0,0,0,0,0,0,0,0,0,0,0,5
5,0,0,0,0,0,0,0,0,0,0,0,0,0,0,0,0,0,0,0,0,0,0,0,0,0,0,0,0,0,0,0,0,0,0,0,0,0,0,0,0,0,5
5,0,0,0,0,0,0,0,0,0,0,0,0,0,0,0,0,0,0,0,0,0,0,0,0,0,0,0,0,0,0,0,0,0,0,0,0,0,0,0,0,0,5
5,0,0,0,0,0,0,0,0,0,0,0,0,0,0,0,0,0,0,0,0,0,0,0,0,0,0,0,0,0,0,0,0,0,0,0,0,0,0,0,0,0,5
5,0,0,0,0,0,0,0,0,0,0,0,0,0,0,0,0,0,0,0,0,0,0,0,0,0,0,0,0,0,0,0,0,0,0,0,0,0,0,0,0,0,5
20,0,0,0,0,0,0,0,0,0,0,0,0,0,0,0,0,0,0,0,0,0,0,0,0,0,0,0,0,0,0,0,0,0,0,0,0,0,0,0,0,0,5
17,0,0,0,0,0,0,0,0,0,0,0,0,0,0,0,0,0,0,0,0,0,0,0,0,0,0,0,0,0,0,0,0,0,0,0,0,0,0,0,0,0,5
5,0,0,0,0,0,0,0,0,0,0,0,0,0,0,0,0,0,0,0,0,0,0,0,0,0,0,0,0,0,0,0,0,0,0,0,0,0,0,0,0,0,5
5,0,0,0,0,0,0,0,0,0,0,0,0,0,0,0,0,0,0,0,0,0,0,0,0,0,0,0,0,0,0,0,0,0,0,0,0,0,0,0,0,0,5
5,0,0,0,0,0,0,0,0,0,0,0,0,0,0,0,0,0,0,0,0,0,0,0,0,0,0,0,0,0,0,0,0,0,0,0,0,0,0,0,0,0,5
5,0,0,0,0,0,0,0,0,0,0,0,0,0,0,0,0,0,0,0,0,0,0,0,0,0,0,0,0,0,0,0,0,0,0,0,0,0,0,0,0,0,5
5,0,0,0,0,0,0,0,0,0,0,0,0,0,0,0,0,0,0,0,0,0,0,0,0,0,0,0,0,0,0,0,0,0,0,0,0,0,0,0,0,0,5
5,5,0,0,0,0,0,0,0,0,0,5,0,0,0,0,0,0,0,0,0,5,0,0,0,0,0,0,0,0,0,5,0,0,0,0,0,0,0,0,0,5,5
5,5,5,5,5,5,5,5,5,5,5,5,5,5,5,5,5,5,5,5,5,5,5,5,5,5,5,5,5,5,5,5,5,5,5,5,5,5,5,5,5,5,5
endlayer

layer
1,1,5,5,5,5,5,5,5,5,5,1,5,5,5,5,5,5,5,5,5,1,5,5,5,5,5,5,5,5,5,1,5,5,5,5,5,5,5,5,5,1,1
1,1,5,5,5,5,5,5,5,5,5,1,5,5,5,5,5,5,5,5,5,1,5,5,5,5,5,5,5,5,5,1,5,5,5,5,5,5,5,5,5,1,1
1,1,5,5,5,5,5,5,5,5,5,1,5,5,5,5,5,5,5,5,5,1,5,5,5,5,5,5,5,5,5,1,5,5,5,5,5,5,5,5,5,1,1
1,1,5,5,5,5,5,5,5,5,5,1,5,5,5,5,5,5,5,5,5,1,5,5,5,5,5,5,5,5,5,1,5,5,5,5,5,5,5,5,5,1,1
1,1,5,5,5,5,5,5,5,5,5,1,5,5,5,5,5,5,5,5,5,1,5,5,5,5,5,5,5,5,5,1,5,5,5,5,5,5,5,5,5,1,1
1,1,5,5,5,5,5,5,5,5,5,1,5,5,5,5,5,5,5,5,5,1,5,5,5,5,5,5,5,5,5,1,5,5,5,5,5,5,5,5,5,1,1
1,1,5,5,3,5,5,5,3,5,5,1,5,5,3,5,5,5,3,5,5,1,5,5,3,5,5,5,3,5,5,1,5,5,3,5,5,5,3,5,5,1,1
1,1,5,5,5,5,5,5,5,5,5,1,5,5,5,5,5,5,5,5,5,1,5,5,5,5,5,5,5,5,5,1,5,5,5,5,5,5,5,5,5,1,1
1,1,5,5,5,5,5,5,5,5,5,1,5,5,5,5,5,5,5,5,5,1,5,5,5,5,5,5,5,5,5,1,5,5,5,5,5,5,5,5,5,1,1
1,1,5,5,5,5,5,5,5,5,5,1,5,5,5,5,5,5,5,5,5,1,5,5,5,5,5,5,5,5,5,1,5,5,5,5,5,5,5,5,5,1,1
1,1,5,5,3,5,5,5,3,5,5,1,5,5,3,5,5,5,3,5,5,1,5,5,3,5,5,5,3,5,5,1,5,5,3,5,5,5,3,5,5,1,1
1,1,5,5,5,5,5,5,5,5,5,1,5,5,5,5,5,5,5,5,5,1,5,5,5,5,5,5,5,5,5,1,5,5,5,5,5,5,5,5,5,1,1
5,5,5,25,25,25,25,25,25,25,5,5,5,25,25,25,25,25,25,25,5,5,5,25,25,25,25,25,25,25,5,5,5,25,25,25,25,25,25,25,5,5,5
5,5,0,0,0,0,0,0,0,0,0,0,0,0,0,0,0,0,0,0,0,0,0,0,0,0,0,0,0,0,0,0,0,0,0,0,0,0,0,0,0,0,5
5,5,0,0,0,0,0,0,0,0,0,0,0,0,0,0,0,0,0,0,0,0,0,0,0,0,0,0,0,0,0,0,0,0,0,0,0,0,0,0,0,0,5
5,5,0,0,0,0,0,0,0,0,0,0,0,0,0,0,0,0,0,0,0,0,0,0,0,0,0,0,0,0,0,0,0,0,0,0,0,0,0,0,0,0,5
5,5,0,0,0,0,0,0,0,0,0,0,0,0,0,0,0,0,0,0,0,0,0,0,0,0,0,0,0,0,0,0,0,0,0,0,0,0,0,0,0,0,5
5,5,0,0,0,0,0,0,0,0,0,0,0,0,0,0,0,0,0,0,0,0,0,0,0,0,0,0,0,0,0,0,0,0,0,0,0,0,0,0,0,0,5
5,5,0,0,0,0,0,0,0,0,0,0,0,0,0,0,0,0,0,0,0,0,0,0,0,0,0,0,0,0,0,0,0,0,0,0,0,0,0,0,0,0,5
5,5,0,0,0,0,0,0,0,0,0,0,0,0,0,0,0,0,0,0,0,0,0,0,0,0,0,0,0,0,0,0,0,0,0,0,0,0,0,0,0,0,5
5,5,0,0,0,0,0,0,0,0,0,0,0,0,0,0,0,0,0,0,0,0,0,0,0,0,0,0,0,0,0,0,0,0,0,0,0,0,0,0,0,0,5
5,5,0,0,0,0,0,0,0,0,0,0,0,0,0,0,0,0,0,0,0,0,0,0,0,0,0,0,0,0,0,0,0,0,0,0,0,0,0,0,0,0,5
5,5,0,0,0,0,0,0,0,0,0,0,0,0,0,0,0,0,0,0,0,0,0,0,0,0,0,0,0,0,0,0,0,0,0,0,0,0,0,0,0,0,5
5,5,0,0,0,0,0,0,0,0,0,0,0,0,0,0,0,0,0,0,0,0,0,0,0,0,0,0,0,0,0,0,0,0,0,0,0,0,0,0,0,0,5
5,5,0,0,0,0,0,0,0,0,0,0,0,0,0,0,0,0,0,0,0,0,0,0,0,0,0,0,0,0,0,0,0,0,0,0,0,0,0,0,0,0,5
5,5,0,0,0,0,0,0,0,0,0,0,0,0,0,0,0,0,0,0,0,0,0,0,0,0,0,0,0,0,0,0,0,0,0,0,0,0,0,0,0,0,5
5,5,0,0,0,0,0,0,0,0,0,0,0,0,0,0,0,0,0,0,0,0,0,0,0,0,0,0,0,0,0,0,0,0,0,0,0,0,0,0,0,0,5
5,5,0,0,0,0,0,0,0,0,0,0,0,0,0,0,0,0,0,0,0,0,0,0,0,0,0,0,0,0,0,0,0,0,0,0,0,0,0,0,0,0,5
5,5,0,0,0,0,0,0,0,0,0,0,0,0,0,0,0,0,0,0,0,0,0,0,0,0,0,0,0,0,0,0,0,0,0,0,0,0,0,0,0,0,5
5,5,0,0,0,0,0,0,0,0,0,0,0,0,0,0,0,0,0,0,0,0,0,0,0,0,0,0,0,0,0,0,0,0,0,0,0,0,0,0,0,0,5
20,5,0,0,0,0,0,0,0,0,0,0,0,0,0,0,0,0,0,0,0,0,0,0,0,0,0,0,0,0,0,0,0,0,0,0,0,0,0,0,0,0,5
17,5,0,0,0,0,0,0,0,0,0,0,0,0,0,0,0,0,0,0,0,0,0,0,0,0,0,0,0,0,0,0,0,0,0,0,0,0,0,0,0,0,5
5,5,0,0,0,0,0,0,0,0,0,0,0,0,0,0,0,0,0,0,0,0,0,0,0,0,0,0,0,0,0,0,0,0,0,0,0,0,0,0,0,0,5
5,5,0,0,0,0,0,0,0,0,0,0,0,0,0,0,0,0,0,0,0,0,0,0,0,0,0,0,0,0,0,0,0,0,0,0,0,0,0,0,0,0,5
5,5,0,0,0,0,0,0,0,0,0,0,0,0,0,0,0,0,0,0,0,0,0,0,0,0,0,0,0,0,0,0,0,0,0,0,0,0,0,0,0,0,5
5,5,0,0,0,0,0,0,0,0,0,0,0,0,0,0,0,0,0,0,0,0,0,0,0,0,0,0,0,0,0,0,0,0,0,0,0,0,0,0,0,0,5
5,5,0,0,0,0,0,0,0,0,0,5,0,0,0,0,0,0,0,0,0,5,0,0,0,0,0,0,0,0,0,5,0,0,0,0,0,0,0,0,0,5,5
5,5,0,0,0,0,0,0,0,0,0,5,0,0,0,0,0,0,0,0,0,5,0,0,0,0,0,0,0,0,0,5,0,0,0,0,0,0,0,0,0,5,5
5,5,5,5,5,5,5,5,5,5,5,5,5,5,5,5,5,5,5,5,5,5,5,5,5,5,5,5,5,5,5,5,5,5,5,5,5,5,5,5,5,5,5
endlayer

layer
1,1,5,5,5,5,5,5,5,5,5,1,5,5,5,5,5,5,5,5,5,1,5,5,5,5,5,5,5,5,5,1,5,5,5,5,5,5,5,5,5,1,1
1,1,5,5,5,5,5,5,5,5,5,1,5,5,5,5,5,5,5,5,5,1,5,5,5,5,5,5,5,5,5,1,5,5,5,5,5,5,5,5,5,1,1
1,1,5,5,5,5,5,5,5,5,5,1,5,5,5,5,5,5,5,5,5,1,5,5,5,5,5,5,5,5,5,1,5,5,5,5,5,5,5,5,5,1,1
1,1,5,5,5,5,5,5,5,5,5,1,5,5,5,5,5,5,5,5,5,1,5,5,5,5,5,5,5,5,5,1,5,5,5,5,5,5,5,5,5,1,1
1,1,5,5,5,5,5,5,5,5,5,1,5,5,5,5,5,5,5,5,5,1,5,5,5,5,5,5,5,5,5,1,5,5,5,5,5,5,5,5,5,1,1
1,1,5,5,5,5,5,5,5,5,5,1,5,5,5,5,5,5,5,5,5,1,5,5,5,5,5,5,5,5,5,1,5,5,5,5,5,5,5,5,5,1,1
1,1,5,5,2,5,5,5,2,5,5,1,5,5,2,5,5,5,2,5,5,1,5,5,2,5,5,5,2,5,5,1,5,5,2,5,5,5,2,5,5,1,1
1,1,5,5,5,5,5,5,5,5,5,1,5,5,5,5,5,5,5,5,5,1,5,5,5,5,5,5,5,5,5,1,5,5,5,5,5,5,5,5,5,1,1
1,1,5,5,5,5,5,5,5,5,5,1,5,5,5,5,5,5,5,5,5,1,5,5,5,5,5,5,5,5,5,1,5,5,5,5,5,5,5,5,5,1,1
1,1,5,5,5,5,5,5,5,5,5,1,5,5,5,5,5,5,5,5,5,1,5,5,5,5,5,5,5,5,5,1,5,5,5,5,5,5,5,5,5,1,1
1,1,5,5,2,5,5,5,2,5,5,1,5,5,2,5,5,5,2,5,5,1,5,5,2,5,5,5,2,5,5,1,5,5,2,5,5,5,2,5,5,1,1
1,1,5,5,5,5,5,5,5,5,5,1,5,5,5,5,5,5,5,5,5,1,5,5,5,5,5,5,5,5,5,1,5,5,5,5,5,5,5,5,5,1,1
5,5,5,5,5,5,5,5,5,5,5,5,5,5,5,5,5,5,5,5,5,5,5,5,5,5,5,5,5,5,5,5,5,5,5,5,5,5,5,5,5,5,5
5,5,0,0,0,0,0,0,0,0,0,5,0,0,0,0,0,0,0,0,0,0,0,0,0,0,0,0,0,0,0,0,0,0,0,0,0,0,0,0,0,5,5
5,5,0,0,0,0,0,0,0,0,0,5,0,0,0,0,0,0,0,0,0,0,0,0,0,0,0,0,0,0,0,0,0,0,0,0,0,0,0,0,0,5,5
5,5,0,0,0,0,0,0,0,0,0,5,0,0,0,0,0,0,0,0,0,0,0,0,0,0,0,0,0,0,0,0,0,0,0,0,0,0,0,0,0,5,5
5,5,0,0,0,0,0,0,0,0,0,5,0,0,0,0,0,0,0,0,0,0,0,0,0,0,0,0,0,0,0,0,0,0,0,0,0,0,0,0,0,5,5
5,5,0,0,0,0,0,0,0,0,0,5,0,0,0,0,0,0,0,0,0,0,0,0,0,0,0,0,0,0,0,0,0,0,0,0,0,0,0,0,0,5,5
5,5,0,0,0,0,0,0,0,0,0,5,0,0,0,0,0,0,0,0,0,0,0,0,0,0,0,0,0,0,0,0,0,0,0,0,0,0,0,0,0,5,5
5,5,0,0,0,0,0,0,0,0,0,5,0,0,0,0,0,0,0,0,0,0,0,0,0,0,0,0,0,0,0,0,0,0,0,0,0,0,0,0,0,5,5
5,5,0,0,0,0,0,0,0,0,0,5,0,0,0,0,0,0,0,0,0,0,0,0,0,0,0,0,0,0,0,0,0,0,0,0,0,0,0,0,0,5,5
5,5,0,0,0,0,0,0,0,0,0,5,0,0,0,0,0,0,0,0,0,0,0,0,0,0,0,0,0,0,0,0,0,0,0,0,0,0,0,0,0,5,5
5,5,0,0,0,0,0,0,0,0,0,5,0,0,0,0,0,0,0,0,0,0,0,0,0,0,0,0,0,0,0,0,0,0,0,0,0,0,0,0,0,5,5
5,5,0,0,0,0,0,0,0,0,0,5,0,0,0,0,0,0,0,0,0,0,0,0,0,0,0,0,0,0,0,0,0,0,0,0,0,0,0,0,0,5,5
5,5,0,0,0,0,0,0,0,0,0,5,0,0,0,0,0,0,0,0,0,0,0,0,0,0,0,0,0,0,0,0,0,0,0,0,0,0,0,0,0,5,5
5,5,0,0,0,0,0,0,0,0,0,5,0,0,0,0,0,0,0,0,0,0,0,0,0,0,0,0,0,0,0,0,0,0,0,0,0,0,0,0,0,5,5
5,5,0,0,0,0,0,0,0,0,0,5,0,0,0,0,0,0,0,0,0,0,0,0,0,0,0,0,0,0,0,0,0,0,0,0,0,0,0,0,0,5,5
5,5,0,0,0,0,0,0,0,0,0,5,0,0,0,0,0,0,0,0,0,0,0,0,0,0,0,0,0,0,0,0,0,0,0,0,0,0,0,0,0,5,5
5,5,0,0,0,0,0,0,0,0,0,5,0,0,0,0,0,0,0,0,0,0,0,0,0,0,0,0,0,0,0,0,0,0,0,0,0,0,0,0,0,5,5
5,5,0,0,0,0,0,0,0,0,0,5,0,0,0,0,0,0,0,0,0,0,0,0,0,0,0,0,0,0,0,0,0,0,0,0,0,0,0,0,0,5,5
20,5,0,0,0,0,0,0,0,0,0,5,0,0,0,0,0,0,0,0,0,0,0,0,0,0,0,0,0,0,0,0,0,0,0,0,0,0,0,0,0,5,5
17,5,0,0,0,0,0,0,0,0,0,5,0,0,0,0,0,0,0,0,0,0,0,0,0,0,0,0,0,0,0,0,0,0,0,0,0,0,0,0,0,5,5
5,5,0,0,0,0,0,0,0,0,0,5,0,0,0,0,0,0,0,0,0,0,0,0,0,0,0,0,0,0,0,0,0,0,0,0,0,0,0,0,0,5,5
5,5,0,0,0,0,0,0,0,0,0,5,0,0,0,0,0,0,0,0,0,0,0,0,0,0,0,0,0,0,0,0,0,0,0,0,0,0,0,0,0,5,5
5,5,0,0,0,0,0,0,0,0,0,5,0,0,0,0,0,0,0,0,0,0,0,0,0,0,0,0,0,0,0,0,0,0,0,0,0,0,0,0,0,5,5
5,5,0,0,0,0,0,0,0,0,0,5,0,0,0,0,0,0,0,0,0,5,0,0,0,0,0,0,0,0,0,5,0,0,0,0,0,0,0,0,0,5,5
5,5,0,0,0,0,0,0,0,0,0,5,0,0,0,0,0,0,0,0,0,5,0,0,0,0,0,0,0,0,0,5,0,0,0,0,0,0,0,0,0,5,5
5,5,0,0,0,0,0,0,0,0,0,5,0,0,0,0,0,0,0,0,0,5,0,0,0,0,0,0,0,0,0,5,0,0,0,0,0,0,0,0,0,5,5
5,5,5,5,5,5,5,5,5,5,5,5,5,5,5,5,5,5,5,5,5,5,5,5,5,5,5,5,5,5,5,5,5,5,5,5,5,5,5,5,5,5,5
endlayer

layer
1,1,1,1,1,1,1,1,1,1,1,1,1,1,1,1,1,1,1,1,1,1,1,1,1,1,1,1,1,1,1,1,1,1,1,1,1,1,1,1,1,1,1
1,1,1,1,1,1,1,1,1,1,1,1,1,1,1,1,1,1,1,1,1,1,1,1,1,1,1,1,1,1,1,1,1,1,1,1,1,1,1,1,1,1,1
1,1,1,1,1,1,1,1,1,1,1,1,1,1,1,1,1,1,1,1,1,1,1,1,1,1,1,1,1,1,1,1,1,1,1,1,1,1,1,1,1,1,1
1,1,1,1,1,1,1,1,1,1,1,1,1,1,1,1,1,1,1,1,1,1,1,1,1,1,1,1,1,1,1,1,1,1,1,1,1,1,1,1,1,1,1
1,1,1,1,1,1,1,1,1,1,1,1,1,1,1,1,1,1,1,1,1,1,1,1,1,1,1,1,1,1,1,1,1,1,1,1,1,1,1,1,1,1,1
1,1,1,1,1,1,1,1,1,1,1,1,1,1,1,1,1,1,1,1,1,1,1,1,1,1,1,1,1,1,1,1,1,1,1,1,1,1,1,1,1,1,1
1,1,1,1,1,1,1,1,1,1,1,1,1,1,1,1,1,1,1,1,1,1,1,1,1,1,1,1,1,1,1,1,1,1,1,1,1,1,1,1,1,1,1
1,1,1,1,1,1,1,1,1,1,1,1,1,1,1,1,1,1,1,1,1,1,1,1,1,1,1,1,1,1,1,1,1,1,1,1,1,1,1,1,1,1,1
1,1,1,1,1,1,1,1,1,1,1,1,1,1,1,1,1,1,1,1,1,1,1,1,1,1,1,1,1,1,1,1,1,1,1,1,1,1,1,1,1,1,1
1,1,1,1,1,1,1,1,1,1,1,1,1,1,1,1,1,1,1,1,1,1,1,1,1,1,1,1,1,1,1,1,1,1,1,1,1,1,1,1,1,1,1
1,1,1,1,1,1,1,1,1,1,1,1,1,1,1,1,1,1,1,1,1,1,1,1,1,1,1,1,1,1,1,1,1,1,1,1,1,1,1,1,1,1,1
1,1,1,1,1,1,1,1,1,1,1,1,1,1,1,1,1,1,1,1,1,1,1,1,1,1,1,1,1,1,1,1,1,1,1,1,1,1,1,1,1,1,1
1,5,5,5,5,5,5,5,5,5,5,5,5,5,5,5,5,5,5,5,5,5,5,5,5,5,5,5,5,5,5,5,5,5,5,5,5,5,5,5,5,5,1
1,5,5,5,5,5,5,5,5,5,5,5,5,5,5,5,5,5,5,5,5,5,5,5,5,5,5,5,5,5,5,5,5,5,5,5,5,5,5,5,5,5,1
1,5,5,5,5,5,5,5,5,5,5,5,5,5,5,5,5,5,5,5,5,5,5,5,5,5,5,5,5,5,5,5,5,5,5,5,5,5,5,5,5,5,1
1,5,5,5,5,5,3,5,5,5,5,5,5,5,5,5,5,5,5,5,5,5,3,5,5,5,5,5,5,5,3,5,5,5,5,5,5,5,5,5,5,5,1
1,5,5,5,5,5,5,5,5,5,5,5,5,5,5,5,5,5,5,5,5,5,5,5,5,5,5,5,5,5,5,5,5,5,5,5,5,5,5,5,5,5,1
1,5,5,5,5,5,5,5,5,5,5,5,5,3,5,5,5,5,5,5,5,5,5,5,5,5,5,5,5,5,5,5,5,5,5,5,5,5,5,3,5,5,1
1,5,5,5,5,5,5,5,5,5,5,5,5,5,5,5,14,16,16,16,16,16,16,16,16,16,16,16,16,16,16,16,16,16,16,16,16,5,5,5,5,5,1
1,5,5,5,5,5,5,5,5,5,5,5,5,5,5,14,16,0,0,0,0,0,0,0,0,0,0,0,0,0,0,0,0,0,0,0,13,16,5,5,5,5,1
1,5,5,5,5,5,5,5,5,5,5,5,5,5,16,14,0,0,0,0,0,0,0,0,0,0,0,0,0,0,0,0,0,0,0,0,0,13,16,5,5,5,1
1,5,5,5,5,5,5,5,5,5,5,5,5,5,14,0,0,0,0,0,0,0,0,0,0,0,0,0,0,0,0,0,0,0,0,0,0,0,13,5,5,5,1
1,5,5,5,5,5,3,5,5,5,5,5,5,5,14,0,0,0,0,0,0,0,0,0,0,0,0,0,0,0,0,0,0,0,0,0,0,0,13,5,5,5,1
1,5,5,5,5,5,5,5,5,5,5,5,5,5,14,0,0,0,0,0,0,0,0,0,0,0,0,0,0,0,0,0,0,0,0,0,0,0,13,5,5,5,1
1,5,5,5,5,5,5,5,5,5,5,5,5,5,14,0,0,0,0,0,0,0,0,0,0,0,0,0,0,0,0,0,0,0,0,0,0,0,13,5,5,5,1
1,5,5,5,5,5,5,5,5,5,5,5,5,5,14,0,0,0,0,0,0,0,0,0,0,0,0,0,0,0,0,0,0,0,0,0,0,0,13,5,5,5,1
1,5,3,5,5,5,5,5,5,5,5,2,3,5,14,0,0,0,0,0,0,0,0,0,0,0,0,0,0,0,0,0,0,0,0,0,0,0,13,5,3,2,1
1,5,5,5,5,5,5,5,5,5,5,5,5,5,14,0,0,0,0,0,0,0,0,0,0,0,0,0,0,0,0,0,0,0,0,0,0,0,13,5,5,5,1
1,5,5,5,5,5,5,5,5,5,5,5,5,5,14,0,0,0,0,0,0,0,0,0,0,0,0,0,0,0,0,0,0,0,0,0,0,0,13,5,5,5,1
1,5,5,5,5,5,3,5,5,5,5,5,5,5,14,0,0,0,0,0,0,0,0,0,0,0,0,0,0,0,0,0,0,0,0,0,0,0,13,5,5,5,1
1,5,5,5,5,5,5,5,5,5,5,5,5,5,14,0,0,0,0,0,0,0,0,0,0,0,0,0,0,0,0,0,0,0,0,0,0,0,13,5,5,5,1
1,5,5,5,5,5,5,5,5,5,5,5,5,5,14,0,0,0,0,0,0,0,0,0,0,0,0,0,0,0,0,0,0,0,0,0,0,0,13,5,5,5,1
1,5,5,5,5,5,5,5,5,5,5,5,5,5,14,12,0,0,0,0,0,0,0,0,0,0,0,0,0,0,0,0,0,0,0,0,0,13,12,5,5,5,1
1,5,5,5,5,5,5,5,5,5,5,5,5,5,5,14,12,0,0,0,0,0,0,0,0,0,0,0,0,0,0,0,0,0,0,0,13,12,5,5,5,5,1
1,5,5,5,5,5,5,5,5,5,5,5,5,5,5,5,14,12,12,12,12,12,12,12,12,12,12,12,12,12,12,12,12,12,12,12,12,5,5,5,5,5,1
1,5,5,5,5,5,5,5,5,5,5,5,5,3,5,5,5,5,5,5,5,5,5,5,5,5,5,5,5,5,5,5,5,5,5,5,5,5,5,3,5,5,1
1,5,5,5,5,5,3,5,5,5,5,5,5,5,5,5,5,5,5,5,5,5,5,5,5,5,5,5,5,5,5,5,5,5,5,5,5,5,5,5,5,5,1
1,5,5,5,5,5,5,5,5,5,5,5,5,5,5,5,5,5,5,5,5,5,3,5,5,5,5,5,5,5,3,5,5,5,5,5,5,5,5,5,5,5,1
1,5,5,5,5,5,5,5,5,5,5,5,5,5,5,5,5,5,5,5,5,5,5,5,5,5,5,5,5,5,5,5,5,5,5,5,5,5,5,5,5,5,1
endlayer

layer
1,1,1,1,1,1,1,1,1,1,1,1,1,1,1,1,1,1,1,1,1,1,1,1,1,1,1,1,1,1,1,1,1,1,1,1,1,1,1,1,1,1,1
1,1,1,1,1,1,1,1,1,1,1,1,1,1,1,1,1,1,1,1,1,1,1,1,1,1,1,1,1,1,1,1,1,1,1,1,1,1,1,1,1,1,1
1,1,1,1,1,1,1,1,1,1,1,1,1,1,1,1,1,1,1,1,1,1,1,1,1,1,1,1,1,1,1,1,1,1,1,1,1,1,1,1,1,1,1
1,1,1,1,1,1,1,1,1,1,1,1,1,1,1,1,1,1,1,1,1,1,1,1,1,1,1,1,1,1,1,1,1,1,1,1,1,1,1,1,1,1,1
1,1,1,1,1,1,1,1,1,1,1,1,1,1,1,1,1,1,1,1,1,1,1,1,1,1,1,1,1,1,1,1,1,1,1,1,1,1,1,1,1,1,1
1,1,1,1,1,1,1,1,1,1,1,1,1,1,1,1,1,1,1,1,1,1,1,1,1,1,1,1,1,1,1,1,1,1,1,1,1,1,1,1,1,1,1
1,1,1,1,1,1,1,1,1,1,1,1,1,1,1,1,1,1,1,1,1,1,1,1,1,1,1,1,1,1,1,1,1,1,1,1,1,1,1,1,1,1,1
1,1,1,1,1,1,1,1,1,1,1,1,1,1,1,1,1,1,1,1,1,1,1,1,1,1,1,1,1,1,1,1,1,1,1,1,1,1,1,1,1,1,1
1,1,1,1,1,1,1,1,1,1,1,1,1,1,1,1,1,1,1,1,1,1,1,1,1,1,1,1,1,1,1,1,1,1,1,1,1,1,1,1,1,1,1
1,1,1,1,1,1,1,1,1,1,1,1,1,1,1,1,1,1,1,1,1,1,1,1,1,1,1,1,1,1,1,1,1,1,1,1,1,1,1,1,1,1,1
1,1,1,1,1,1,1,1,1,1,1,1,1,1,1,1,1,1,1,1,1,1,1,1,1,1,1,1,1,1,1,1,1,1,1,1,1,1,1,1,1,1,1
1,1,1,1,1,1,1,1,1,1,1,1,1,1,1,1,1,1,1,1,1,1,1,1,1,1,1,1,1,1,1,1,1,1,1,1,1,1,1,1,1,1,1
1,1,5,5,5,5,5,5,5,5,5,5,5,5,5,5,5,5,5,5,5,5,5,5,5,5,5,5,5,5,5,5,5,5,5,5,5,5,5,5,5,1,1
1,1,5,5,5,5,5,5,5,5,5,5,5,5,5,5,5,5,5,5,5,5,5,5,5,5,5,5,5,5,5,5,5,5,5,5,5,5,5,5,5,1,1
1,1,5,5,5,5,5,5,5,5,5,5,5,5,5,5,5,5,5,5,5,5,5,5,5,5,5,5,5,5,5,5,5,5,5,5,5,5,5,5,5,1,1
1,1,5,5,5,5,2,5,5,5,5,5,5,5,5,5,5,5,5,5,5,5,2,5,5,5,5,5,5,5,2,5,5,5,5,5,5,5,5,5,5,1,1
1,1,5,5,5,5,5,5,5,5,5,5,5,5,5,5,5,5,5,5,5,5,5,5,5,5,5,5,5,5,5,5,5,5,5,5,5,5,5,5,5,1,1
1,1,5,5,5,5,5,5,5,5,5,5,5,2,5,5,10,10,10,10,10,10,10,10,10,10,10,10,10,10,10,10,10,10,10,10,10,5,5,2,5,1,1
1,1,5,5,5,5,5,5,5,5,5,5,5,5,5,10,10,4,4,4,4,4,4,4,4,4,4,4,4,4,4,4,4,4,4,4,10,10,5,5,5,1,1
1,1,5,5,5,5,5,5,5,5,5,5,5,5,10,10,4,0,0,0,0,0,0,0,0,0,0,0,0,0,0,0,0,0,0,0,4,10,10,5,5,1,1
1,1,5,5,5,5,5,5,5,5,5,5,5,10,10,4,0,0,0,0,0,0,0,0,0,0,0,0,0,0,0,0,0,0,0,0,0,4,10,10,5,1,1
1,1,5,5,5,5,5,5,5,5,5,5,5,10,4,0,0,0,0,0,0,0,0,0,0,0,0,0,0,0,0,0,0,0,0,0,0,0,4,10,5,1,1
1,1,5,5,5,5,2,5,5,5,5,5,5,10,4,0,0,0,0,0,0,0,0,0,0,0,0,0,0,0,0,0,0,0,0,0,0,0,4,10,5,1,1
1,1,5,5,5,5,5,5,5,5,5,5,5,10,4,0,0,0,0,0,0,0,0,0,0,0,0,0,0,0,0,0,0,0,0,0,0,0,4,10,5,1,1
1,1,5,5,5,5,5,5,5,5,5,5,5,10,4,0,0,0,0,0,0,0,0,0,0,0,0,0,0,0,0,0,0,0,0,0,0,0,4,10,5,1,1
1,1,5,5,5,5,5,5,5,5,5,5,5,10,4,0,0,0,0,0,0,0,0,0,0,0,0,0,0,0,0,0,0,0,0,0,0,0,4,10,5,1,1
1,1,2,5,5,5,5,5,5,5,5,5,5,10,4,0,0,0,0,0,0,0,0,0,0,0,0,0,0,0,0,0,0,0,0,0,0,0,4,10,5,1,1
1,1,5,5,5,5,5,5,5,5,5,5,5,10,4,0,0,0,0,0,0,0,0,0,0,0,0,0,0,0,0,0,0,0,0,0,0,0,4,10,5,1,1
1,1,5,5,5,5,5,5,5,5,5,5,5,10,4,0,0,0,0,0,0,0,0,0,0,0,0,0,0,0,0,0,0,0,0,0,0,0,4,10,5,1,1
1,1,5,5,5,5,2,5,5,5,5,5,5,10,4,0,0,0,0,0,0,0,0,0,0,0,0,0,0,0,0,0,0,0,0,0,0,0,4,10,5,1,1
1,1,5,5,5,5,5,5,5,5,5,5,5,10,4,0,0,0,0,0,0,0,0,0,0,0,0,0,0,0,0,0,0,0,0,0,0,0,4,10,5,1,1
1,1,5,5,5,5,5,5,5,5,5,5,5,10,4,0,0,0,0,0,0,0,0,0,0,0,0,0,0,0,0,0,0,0,0,0,0,0,4,10,5,1,1
1,1,5,5,5,5,5,5,5,5,5,5,5,10,10,4,0,0,0,0,0,0,0,0,0,0,0,0,0,0,0,0,0,0,0,0,0,4,10,10,5,1,1
1,1,5,5,5,5,5,5,5,5,5,5,5,5,10,10,4,0,0,0,0,0,0,0,0,0,0,0,0,0,0,0,0,0,0,0,4,10,10,5,5,1,1
1,1,5,5,5,5,5,5,5,5,5,5,5,5,5,10,10,4,4,4,4,4,4,4,4,4,4,4,4,4,4,4,4,4,4,4,10,10,5,5,5,1,1
1,1,5,5,5,5,5,5,5,5,5,5,5,2,5,5,10,10,10,10,10,10,10,10,10,10,10,10,10,10,10,10,10,10,10,10,10,5,5,2,5,1,1
1,1,5,5,5,5,2,5,5,5,5,5,5,5,5,5,5,5,5,5,5,5,5,5,5,5,5,5,5,5,5,5,5,5,5,5,5,5,5,5,5,1,1
1,1,5,5,5,5,5,5,5,5,5,5,5,5,5,5,5,5,5,5,5,5,2,5,5,5,5,5,5,5,2,5,5,5,5,5,5,5,5,5,5,1,1
1,1,5,5,5,5,5,5,5,5,5,5,5,5,5,5,5,5,5,5,5,5,5,5,5,5,5,5,5,5,5,5,5,5,5,5,5,5,5,5,5,1,1
endlayer

