# Gilly's underground Hangar access port

# template generated by Ruins mod version 14.6 Ingame Parser
# Structure created by Gilly

weight=1
embed_into_distance=24
acceptable_target_blocks=
unacceptable_target_blocks=flowing_water,water,flowing_lava,lava,ice,bedrock,netherrack,soul_sand,Natura:Cloud
dimensions=28,11,7
allowable_overhang=0
max_leveling=3
leveling_buffer=-1
preserve_water=0
preserve_lava=0

rule1=0,100,preserveBlock
rule2=0,100,stained_hardened_clay-9
rule3=0,100,stonebrick-0
rule4=0,100,stone_slab-5
rule5=0,100,water-0
rule6=0,100,ladder-5
rule7=0,100,ladder-4
rule8=0,100,glowstone-0
rule9=0,100,iron_bars-0
rule10=0,100,stained_hardened_clay-5
rule11=0,100,stone_brick_stairs-7
rule12=0,100,stone_brick_stairs-6
rule13=0,100,stone_brick_stairs-3
rule14=0,100,stone_brick_stairs-2

layer
1,2,2,2,2,2,1
1,2,1,1,1,2,1
1,2,1,1,1,2,1
1,2,1,1,1,2,1
1,2,2,2,2,2,1
1,2,3,3,3,2,1
1,2,3,3,3,2,1
1,2,3,3,3,2,1
1,2,3,3,3,2,1
1,2,3,3,3,2,1
1,2,2,2,2,2,1
endlayer

layer
1,2,1,1,1,2,1
1,1,1,1,1,1,1
1,1,1,1,1,1,1
1,1,1,1,1,1,1
1,2,2,2,2,1,1
1,1,0,4,4,2,1
1,1,0,4,5,5,2
1,1,0,4,5,5,2
1,1,0,4,4,2,1
1,1,0,0,0,1,1
1,2,1,1,1,2,1
endlayer

layer
1,2,1,1,1,2,1
1,1,2,2,2,1,1
1,1,2,2,2,1,1
1,1,2,2,2,1,1
1,2,2,2,2,1,1
1,1,0,0,0,2,1
1,1,0,0,0,6,2
1,1,0,0,0,7,2
1,1,0,0,0,2,1
1,1,0,0,0,1,1
1,2,1,1,1,2,1
endlayer

layer
1,2,1,1,1,2,1
1,1,2,2,2,1,1
1,1,2,8,2,1,1
1,1,2,2,2,1,1
1,2,2,2,2,1,1
1,1,0,0,0,2,1
1,1,0,0,0,6,2
1,1,0,0,0,7,2
1,1,0,0,0,2,1
1,1,0,0,0,1,1
1,2,1,1,1,2,1
endlayer

layer
1,2,2,2,2,2,2
1,2,2,2,2,2,2
1,2,2,9,2,2,2
1,2,2,2,2,2,2
1,2,2,2,2,2,2
1,2,0,0,9,2,2
1,2,0,0,9,6,2
1,2,0,0,9,7,2
1,2,0,0,9,2,2
1,2,0,0,0,2,2
1,2,2,2,2,2,2
endlayer

layer
1,2,2,2,2,2,0
1,2,9,9,9,0,0
1,2,9,0,0,0,0
1,2,9,9,9,0,0
1,2,2,2,2,2,0
1,1,0,0,0,2,0
1,1,0,0,9,6,0
1,1,0,0,9,7,0
1,1,0,0,0,2,0
1,1,0,0,0,2,0
1,2,1,1,1,2,0
endlayer

layer
1,2,2,2,2,2,0
1,2,9,9,9,0,0
1,2,9,0,0,0,0
1,2,9,9,9,0,0
1,2,2,2,2,2,0
1,1,0,0,0,2,0
1,1,0,0,9,6,0
1,1,0,0,9,7,0
1,1,0,0,0,2,0
1,1,0,0,0,2,0
1,2,1,1,1,2,0
endlayer

layer
1,2,2,2,2,2,0
1,2,9,9,9,0,0
1,2,9,0,0,0,0
1,2,9,9,9,0,0
1,2,2,2,2,2,0
1,1,0,0,0,2,0
1,1,0,0,9,6,0
1,1,0,0,9,7,0
1,1,0,0,0,2,0
1,1,0,0,0,2,0
1,2,1,1,1,2,0
endlayer

layer
1,2,2,2,2,10,0
1,2,9,9,9,10,0
1,2,9,2,9,10,0
1,2,9,9,9,10,0
1,2,2,2,2,10,0
1,1,0,0,0,10,0
1,1,0,0,9,6,0
1,1,0,0,9,7,0
1,1,0,0,0,10,0
1,1,0,0,0,10,0
1,2,1,1,1,10,0
endlayer

layer
1,2,2,2,2,2,0
1,2,9,9,9,2,0
1,2,9,2,9,2,0
1,2,9,9,9,2,0
1,2,2,2,2,2,0
1,1,0,0,0,2,0
1,1,0,0,9,6,0
1,1,0,0,9,7,0
1,1,0,0,0,2,0
1,1,0,0,0,2,0
1,2,1,1,1,2,0
endlayer

layer
1,2,2,2,2,2,2
1,2,9,9,9,2,2
1,2,9,2,9,2,2
1,2,9,9,9,2,2
1,2,2,2,2,2,2
1,1,0,0,9,2,2
1,1,0,0,9,6,2
1,1,0,0,9,7,2
1,1,0,0,9,2,2
1,1,0,0,0,2,2
1,2,1,1,1,2,2
endlayer

layer
1,2,2,2,2,2,2
1,2,9,9,9,2,2
1,2,9,2,9,2,2
1,2,9,9,9,2,2
1,2,2,2,2,2,2
1,2,0,0,0,2,2
1,2,0,0,9,6,2
1,2,0,0,9,7,2
1,2,0,0,0,2,2
1,2,0,0,0,2,2
1,2,2,2,2,2,2
endlayer

layer
1,2,2,2,2,2,2
1,2,9,9,9,2,2
1,2,9,2,9,2,2
1,2,9,9,9,2,2
1,2,2,2,2,2,2
1,2,0,0,0,2,2
1,2,0,0,9,6,2
1,2,0,0,9,7,2
1,2,0,0,0,2,2
1,2,0,0,0,2,2
1,2,2,2,2,2,2
endlayer

layer
1,2,2,2,2,2,2
1,2,9,9,9,2,2
1,2,9,2,9,2,2
1,2,9,9,9,2,2
1,2,2,2,2,2,2
1,2,0,0,0,2,2
1,2,0,0,9,6,2
1,2,0,0,9,7,2
1,2,0,0,0,2,2
1,2,0,0,0,2,2
1,2,2,2,2,2,2
endlayer

layer
1,2,2,2,2,2,2
1,2,9,9,9,2,2
1,2,9,2,9,2,2
1,2,9,9,9,2,2
1,2,2,2,2,2,2
1,2,0,0,0,2,2
1,2,0,0,9,6,2
1,2,0,0,9,7,2
1,2,0,0,0,2,2
1,2,0,0,0,2,2
1,2,2,2,2,2,2
endlayer

layer
1,2,2,2,2,2,2
1,2,9,9,9,2,2
1,2,9,2,9,2,2
1,2,9,9,9,2,2
1,2,2,2,2,2,2
1,2,0,0,0,2,2
1,2,0,0,9,6,2
1,2,0,0,9,7,2
1,2,0,0,0,2,2
1,2,0,0,0,2,2
1,2,2,2,2,2,2
endlayer

layer
1,2,2,2,2,2,1
1,2,9,9,9,2,2
1,2,9,2,9,2,2
1,2,9,9,9,2,2
1,2,2,2,2,2,2
1,2,0,0,0,2,2
1,2,0,0,9,6,2
1,2,0,0,9,7,2
1,2,0,0,0,2,2
1,2,0,0,0,2,2
1,2,2,2,2,2,2
endlayer

layer
1,2,2,2,2,2,1
1,2,9,9,9,2,1
1,2,9,2,9,2,2
1,2,9,9,9,2,2
1,2,2,2,2,2,2
1,2,0,0,0,2,2
1,2,0,0,9,6,2
1,2,0,0,9,7,2
1,2,0,0,0,2,2
1,2,0,0,0,2,2
1,2,2,2,2,2,2
endlayer

layer
1,2,2,2,2,2,1
1,2,9,9,9,2,1
11,2,9,2,9,2,1
1,2,9,9,9,2,2
11,2,2,2,2,2,2
1,2,0,0,0,2,2
11,2,0,0,9,6,2
1,2,0,0,9,7,2
11,2,0,0,0,2,2
1,2,0,0,0,2,2
1,2,2,2,2,2,2
endlayer

layer
1,2,2,2,2,2,1
1,2,9,9,9,2,1
3,2,9,2,9,2,1
1,2,9,9,9,2,1
3,2,2,2,2,2,2
1,2,0,0,0,2,2
3,2,0,0,9,6,2
1,2,0,0,9,7,2
3,2,0,0,0,2,2
1,2,0,0,0,2,2
1,2,2,2,2,2,1
endlayer

layer
1,2,2,2,2,2,1
1,2,9,9,9,2,1
3,2,9,2,9,2,1
1,2,9,9,9,2,1
3,2,2,2,2,2,1
1,2,0,0,0,2,2
3,2,0,0,9,6,2
1,2,0,0,9,7,2
3,2,0,0,0,2,2
1,2,0,0,0,2,1
1,2,2,2,2,2,1
endlayer

layer
1,2,2,2,2,2,1
1,2,9,9,9,2,1
3,2,9,2,9,2,1
1,2,9,9,9,2,1
3,2,2,2,2,2,1
1,2,0,0,0,2,1
3,2,0,0,9,6,2
1,2,0,0,9,7,2
3,2,0,0,0,2,1
1,2,0,0,0,2,1
1,2,2,2,2,2,1
endlayer

layer
1,2,2,2,2,2,1
1,2,9,9,9,2,1
3,2,9,2,9,2,12
1,2,9,9,9,2,1
3,2,2,2,2,2,1
1,2,0,0,0,2,1
3,2,0,0,9,6,1
1,2,0,0,9,7,1
3,2,0,0,0,2,1
1,2,0,0,0,2,1
1,2,2,2,2,2,1
endlayer

layer
1,2,2,2,2,2,1
1,2,9,9,9,2,1
3,2,9,2,9,2,3
1,2,9,9,9,2,1
3,2,2,2,2,2,1
1,2,0,0,0,2,1
3,2,0,0,9,6,1
1,2,0,0,9,7,1
3,2,0,0,0,2,1
1,2,0,0,0,2,1
1,2,2,2,2,2,1
endlayer

layer
1,2,2,2,2,2,1
1,2,9,9,9,2,1
3,2,9,2,9,2,3
1,2,9,9,9,2,1
3,2,2,2,2,2,12
1,2,0,0,0,2,1
3,2,0,0,9,6,1
1,2,0,0,9,7,1
3,2,0,0,0,2,1
1,2,0,0,0,2,12
1,2,2,2,2,2,1
endlayer

layer
1,2,2,2,2,2,1
1,2,9,9,9,2,1
3,2,9,2,9,2,3
1,2,9,9,9,2,1
3,2,2,2,2,2,3
1,0,0,0,0,2,1
3,2,0,0,9,6,1
1,0,0,0,9,7,1
3,2,0,0,0,2,1
1,0,0,0,0,2,3
1,2,2,2,2,2,1
endlayer

layer
1,2,2,2,2,2,1
1,2,9,9,9,2,1
3,2,9,2,9,2,3
1,2,9,9,9,2,1
3,2,2,2,2,2,3
1,2,0,0,9,2,1
3,3,0,0,9,6,1
1,2,0,0,9,7,1
3,3,0,0,9,2,1
1,2,0,0,0,2,3
1,2,2,2,2,2,1
endlayer

layer
1,1,0,0,0,1,1
1,0,0,0,0,0,1
3,14,0,0,0,13,3
1,0,0,0,0,0,1
3,14,0,0,0,13,3
1,0,0,0,0,0,1
3,14,0,0,0,0,1
1,0,0,0,0,0,1
3,14,0,0,0,0,1
1,0,0,0,0,3,3
1,1,0,0,0,1,1
endlayer

