# Converted from schematic
# THIS TEMPLATE USES DEFAULTS!  Please edit for corrections.
# If you need help, consult template_rules.txt

weight=1
embed_into_distance=1
acceptable_target_blocks=1,2,3,12,13,79
dimensions=12,22,20
allowable_overhang=0
max_cut_in=2
cut_in_buffer=0
max_leveling=2
leveling_buffer=1
preserve_water=0
preserve_lava=0
preserve_plants=0


rule1=0,100,2
rule2=0,100,80
rule3=0,100,3
rule4=0,100,9
rule5=0,100,79
rule6=0,100,60-7
rule7=0,100,89
rule8=0,100,35-1
rule9=0,100,87
rule10=0,100,78
rule11=0,100,50-2
rule12=0,100,50-3
rule13=0,100,50-4
rule14=0,100,59-7
rule15=0,100,44
rule16=0,100,51-15
rule17=0,100,61-5
rule18=0,100,50-1
rule19=0,100,50-5


layer
1,1,1,1,1,1,1,2,2,2,2,2,2,1,1,1,1,1,1,1
1,1,1,1,1,2,2,2,2,2,2,2,2,2,2,1,1,1,1,1
1,1,1,3,2,2,2,2,2,2,2,2,2,2,2,2,3,1,1,1
1,1,3,2,2,2,2,2,2,2,2,2,2,2,2,2,2,3,1,1
1,1,2,2,2,2,2,2,2,2,2,2,2,2,2,2,2,2,1,1
1,2,2,2,2,2,2,2,2,2,2,2,2,2,6,6,6,4,2,1
1,2,2,2,2,2,2,2,2,2,2,2,2,2,2,2,6,5,2,1
2,2,2,2,2,2,2,2,2,2,2,2,2,2,2,6,2,5,2,2
2,2,2,2,8,2,2,2,2,2,2,2,2,2,6,2,2,5,2,2
2,2,2,8,8,2,2,2,2,7,7,2,2,2,3,6,6,5,2,2
2,2,2,8,8,2,2,2,2,7,7,2,2,2,6,6,6,5,2,2
2,2,2,8,8,2,2,2,2,2,2,2,2,2,6,3,6,4,2,2
2,2,2,2,2,2,2,2,2,2,2,2,2,2,6,0,6,4,2,2
1,2,2,2,2,2,2,2,2,2,2,2,2,2,0,6,6,4,2,2
1,2,2,9,9,2,2,2,2,2,2,2,2,2,2,6,6,4,2,2
1,1,2,2,2,2,2,2,2,2,2,2,2,0,2,0,2,2,2,2
1,1,3,2,2,2,2,2,2,2,2,2,2,2,2,2,2,2,2,1
1,1,1,3,2,2,2,2,2,2,2,2,2,2,2,2,2,2,2,2
1,1,1,1,1,2,2,2,2,2,2,2,2,2,2,2,2,2,2,2
1,1,1,1,1,1,1,2,2,2,2,2,2,2,2,2,2,2,2,2
1,1,1,1,1,1,1,1,2,2,2,2,1,1,2,2,2,2,2,2
1,1,1,1,1,1,1,1,2,2,2,2,1,1,1,1,1,1,1,1
endlayer

layer
10,10,10,10,10,10,10,2,2,5,5,2,2,10,10,10,10,10,10,10
10,10,10,10,10,2,2,2,2,10,10,2,2,2,2,10,10,10,10,10
10,10,10,2,2,2,2,2,0,10,10,2,2,2,2,2,2,10,10,10
10,10,2,2,2,2,2,2,10,10,10,10,2,2,2,2,2,2,10,10
10,10,2,2,2,2,2,2,10,10,10,10,2,2,0,0,0,2,10,10
10,2,0,17,0,0,2,2,10,10,10,10,2,2,14,14,14,0,2,10
10,2,10,10,10,10,2,2,10,10,10,10,2,2,0,0,14,0,2,10
2,2,10,10,0,0,0,0,0,0,0,10,2,2,0,14,0,0,2,2
2,2,10,0,0,0,2,2,0,0,0,0,2,2,14,0,0,0,2,2
5,10,10,0,0,0,10,0,0,0,0,0,0,10,0,14,0,0,10,5
5,10,10,0,0,0,0,0,0,0,0,0,0,10,14,14,14,0,10,5
2,2,10,0,0,0,2,10,0,0,0,0,10,0,14,0,14,0,2,2
2,2,10,10,10,10,2,10,10,0,0,10,10,2,14,0,14,0,11,2
10,2,15,15,15,0,2,2,10,10,10,10,2,0,0,14,14,12,2,0
10,2,15,16,16,15,2,2,2,10,10,2,2,0,0,14,14,0,2,0
10,10,2,2,2,2,2,2,2,10,10,2,0,0,0,0,2,13,0,0
10,10,2,2,2,2,2,2,2,10,10,2,2,0,2,2,0,0,0,10
10,10,10,2,2,2,2,2,2,10,10,2,2,2,0,0,0,0,0,0
10,10,10,10,10,0,2,2,2,10,10,2,2,2,0,0,0,0,0,0
10,10,10,10,10,10,10,2,2,10,10,2,2,0,0,0,0,0,0,0
10,10,10,10,10,10,10,10,2,10,10,2,10,10,0,0,0,0,0,0
10,10,10,10,10,10,10,10,2,10,10,2,10,10,10,10,10,10,10,10
endlayer

layer
0,0,0,0,0,0,0,2,2,5,5,2,2,0,0,0,0,0,0,0
0,0,0,0,0,2,2,2,2,0,0,2,2,2,2,0,0,0,0,0
0,0,0,2,2,2,2,0,0,0,0,2,0,2,2,2,2,0,0,0
0,0,2,2,2,2,2,0,0,0,0,0,0,2,2,7,2,2,0,0
0,0,2,2,2,2,2,0,0,0,0,0,0,2,0,0,0,2,0,0
0,2,0,0,0,0,2,0,0,0,0,0,0,2,0,0,0,0,2,0
0,2,0,0,0,0,2,0,0,0,0,0,0,2,0,0,0,0,2,0
2,2,0,0,0,0,0,0,0,0,0,0,0,2,0,0,0,0,2,2
2,2,0,0,0,0,0,0,0,0,0,0,0,2,0,0,0,0,2,2
5,0,0,0,0,0,0,0,0,0,0,0,0,0,0,0,0,0,0,5
5,0,0,0,0,0,0,0,0,0,0,0,0,0,0,0,0,0,0,5
2,2,0,0,0,0,0,0,0,0,0,0,0,0,0,0,0,0,2,2
2,2,0,0,0,0,2,0,0,0,0,0,0,0,0,0,0,0,0,2
0,2,0,0,0,0,2,0,0,0,0,0,2,0,0,0,0,0,0,0
0,2,0,0,0,0,2,2,2,0,0,2,0,0,0,0,11,0,0,0
0,0,2,2,2,2,2,2,2,0,0,2,2,0,0,0,2,0,0,0
0,0,2,2,2,2,2,2,2,0,0,2,0,0,2,2,0,0,0,0
0,0,0,2,2,0,0,2,2,0,0,2,0,0,0,0,0,0,0,0
0,0,0,0,0,0,0,2,2,0,0,2,2,0,0,0,0,0,0,0
0,0,0,0,0,0,0,0,2,0,0,2,2,0,0,0,0,0,0,0
0,0,0,0,0,0,0,0,2,0,0,2,0,0,0,0,0,0,0,0
0,0,0,0,0,0,0,0,2,0,0,2,0,0,0,0,0,0,0,0
endlayer

layer
0,0,0,0,0,0,0,2,2,2,2,2,2,0,0,0,0,0,0,0
0,0,0,0,0,2,2,2,2,2,2,2,2,2,2,0,0,0,0,0
0,0,0,10,2,2,2,0,2,2,2,2,0,2,2,2,10,0,0,0
0,0,10,2,2,2,2,0,0,0,0,0,0,2,2,7,2,10,0,0
0,0,2,2,2,2,2,0,0,0,0,0,0,2,0,0,0,2,0,0
0,2,0,0,18,0,2,0,0,0,0,0,0,2,0,0,0,0,2,0
0,2,0,0,0,0,0,0,0,0,0,0,0,2,0,0,0,0,2,0
2,2,0,0,0,0,0,0,0,0,0,0,0,2,0,0,0,0,2,2
2,2,0,0,0,0,0,0,0,0,0,0,0,2,0,0,0,0,0,2
2,2,0,0,0,0,0,0,0,0,0,0,0,0,0,0,0,0,0,2
2,2,0,0,0,0,0,0,0,0,0,0,0,0,0,0,0,0,0,2
2,2,0,0,0,0,0,0,0,0,0,0,0,0,0,0,0,0,0,2
2,2,0,0,0,0,0,0,0,0,0,0,0,0,0,0,0,0,0,2
0,2,0,0,0,0,0,0,0,0,0,0,0,0,0,0,0,0,0,0
0,2,0,0,0,0,2,0,2,2,2,0,0,0,0,0,0,0,0,0
0,0,2,2,2,2,0,0,2,2,2,0,0,0,0,0,0,0,0,0
0,0,10,2,2,2,0,2,2,2,2,2,0,0,2,0,0,0,0,0
0,0,0,10,2,0,0,0,2,2,2,2,0,0,0,0,0,0,0,0
0,0,0,0,0,0,0,0,2,2,2,2,0,0,0,0,0,0,0,0
0,0,0,0,0,0,0,0,0,2,2,2,0,0,0,0,0,0,0,0
0,0,0,0,0,0,0,0,0,2,2,2,0,0,0,0,0,0,0,0
0,0,0,0,0,0,0,0,0,2,2,2,0,0,0,0,0,0,0,0
endlayer

layer
0,0,0,0,0,0,0,10,2,2,2,2,10,0,0,0,0,0,0,0
0,0,0,0,0,2,2,2,2,2,2,2,2,2,2,0,0,0,0,0
0,0,0,0,2,2,2,0,19,2,2,19,0,2,2,2,0,0,0,0
0,0,0,2,2,2,2,0,0,0,0,0,0,2,2,2,2,0,0,0
0,0,2,2,2,0,2,0,0,0,0,0,0,2,0,0,0,2,0,0
0,2,2,0,0,0,0,0,0,0,0,0,0,2,0,0,0,0,2,0
0,2,0,0,0,0,0,0,0,0,0,0,0,2,0,0,0,0,2,0
10,2,0,0,0,0,0,0,0,0,0,0,0,0,0,0,0,0,0,10
2,2,0,0,0,0,0,0,0,0,0,0,0,0,0,0,0,0,0,0
2,2,0,0,0,0,0,0,0,0,0,0,0,0,0,0,0,0,0,0
2,2,0,0,0,0,0,0,0,0,0,0,0,0,0,0,0,0,0,0
2,2,0,0,0,0,0,0,0,0,0,0,0,0,0,0,0,0,0,0
10,2,2,2,0,0,0,0,0,0,0,0,0,0,0,0,0,0,0,10
0,2,2,2,2,0,0,0,0,2,2,2,0,0,0,0,0,0,0,0
0,2,2,2,2,2,0,0,2,2,2,0,0,0,0,0,0,0,0,0
0,0,2,2,2,2,0,0,2,2,2,2,0,0,0,0,0,0,0,0
0,0,0,2,2,0,0,0,0,2,2,0,0,0,0,0,0,0,0,0
0,0,0,0,0,0,0,0,0,2,2,0,0,0,0,0,0,0,0,0
0,0,0,0,0,0,0,0,2,2,2,2,0,0,0,0,0,0,0,0
0,0,0,0,0,0,0,0,0,2,2,2,0,0,0,0,0,0,0,0
0,0,0,0,0,0,0,0,0,10,10,10,0,0,0,0,0,0,0,0
0,0,0,0,0,0,0,0,0,0,0,0,0,0,0,0,0,0,0,0
endlayer

layer
0,0,0,0,0,0,0,0,10,10,10,10,0,0,0,0,0,0,0,0
0,0,0,0,0,10,2,2,2,2,2,2,2,2,10,0,0,0,0,0
0,0,0,0,2,2,2,2,2,2,2,2,2,2,2,2,0,0,0,0
0,0,0,2,2,2,2,2,2,2,2,2,2,2,2,2,2,0,0,0
0,0,2,2,2,2,2,2,2,2,2,2,2,2,2,2,2,2,0,0
0,10,0,0,0,0,0,0,0,2,2,2,2,2,2,2,2,2,10,0
0,0,0,0,0,0,0,0,0,0,2,2,2,2,2,0,0,0,0,0
0,2,0,0,0,0,0,0,0,0,2,2,2,0,0,0,0,0,0,0
10,2,0,0,0,0,0,0,0,0,0,2,2,0,0,0,0,0,0,0
10,0,0,0,0,0,0,0,0,0,0,2,0,0,0,0,0,0,0,0
10,0,0,0,0,0,0,0,0,0,0,2,0,0,0,0,0,0,0,0
10,2,0,0,0,0,0,0,0,0,0,0,2,0,0,0,0,0,0,0
0,2,2,0,0,0,0,0,0,0,0,2,2,0,0,0,0,0,0,0
0,2,2,0,2,0,0,0,0,0,0,2,0,0,0,0,0,0,0,0
0,10,2,2,2,0,0,0,0,0,2,2,0,0,0,0,0,0,0,0
0,0,2,2,2,0,0,0,0,0,0,0,0,0,0,0,0,0,0,0
0,0,0,2,0,0,0,0,0,0,0,0,0,0,0,0,0,0,0,0
0,0,0,0,0,0,0,0,0,0,2,0,0,0,0,0,0,0,0,0
0,0,0,0,0,0,0,0,0,0,2,2,0,0,0,0,0,0,0,0
0,0,0,0,0,0,0,0,0,10,10,10,0,0,0,0,0,0,0,0
0,0,0,0,0,0,0,0,0,0,0,0,0,0,0,0,0,0,0,0
0,0,0,0,0,0,0,0,0,0,0,0,0,0,0,0,0,0,0,0
endlayer

layer
0,0,0,0,0,0,0,0,0,0,0,0,0,0,0,0,0,0,0,0
0,0,0,0,0,0,10,2,2,2,2,2,2,10,0,0,0,0,0,0
0,0,0,0,10,2,2,2,2,2,2,2,2,2,2,10,0,0,0,0
0,0,0,10,2,2,2,2,2,2,2,2,2,2,2,2,10,0,0,0
0,0,10,0,2,0,0,0,2,2,2,2,2,2,2,2,2,10,0,0
0,0,0,0,0,0,0,0,0,0,2,2,2,2,0,2,2,2,0,0
0,0,0,0,0,0,0,0,0,0,0,2,2,0,0,0,0,0,0,0
0,0,0,0,0,0,0,0,0,0,2,2,0,0,0,0,0,0,0,0
0,0,0,0,0,0,0,0,0,0,0,0,0,0,0,0,0,0,0,0
0,2,0,0,0,0,0,0,0,0,0,0,0,0,0,0,0,0,0,0
0,0,0,0,0,0,0,0,0,0,0,2,0,0,0,0,0,0,0,0
0,0,0,0,0,0,0,0,0,0,0,0,0,0,0,0,0,0,0,0
0,2,0,0,0,0,0,0,0,0,0,0,2,0,0,0,0,0,0,0
0,10,0,0,0,0,0,0,0,0,0,2,2,0,0,0,0,0,0,0
0,0,2,2,0,0,0,0,0,0,0,2,0,0,0,0,0,0,0,0
0,0,10,2,0,0,0,0,0,0,0,0,0,0,0,0,0,0,0,0
0,0,0,0,0,0,0,0,0,0,0,0,0,0,0,0,0,0,0,0
0,0,0,0,0,0,0,0,0,0,0,0,0,0,0,0,0,0,0,0
0,0,0,0,0,0,0,0,0,0,0,2,0,0,0,0,0,0,0,0
0,0,0,0,0,0,0,0,0,0,0,0,0,0,0,0,0,0,0,0
0,0,0,0,0,0,0,0,0,0,0,0,0,0,0,0,0,0,0,0
0,0,0,0,0,0,0,0,0,0,0,0,0,0,0,0,0,0,0,0
endlayer

layer
0,0,0,0,0,0,0,0,0,0,0,0,0,0,0,0,0,0,0,0
0,0,0,0,0,0,0,10,10,10,10,10,10,0,0,0,0,0,0,0
0,0,0,0,0,10,2,2,2,2,2,2,2,2,10,0,0,0,0,0
0,0,0,0,10,2,2,2,2,2,2,2,2,2,2,10,0,0,0,0
0,0,0,0,0,2,2,2,2,2,2,2,2,2,2,2,10,0,0,0
0,0,0,0,0,0,0,0,0,2,2,2,2,2,2,0,0,10,0,0
0,0,0,0,0,0,0,0,0,2,2,2,2,0,0,0,0,0,0,0
0,0,0,0,0,0,0,0,0,0,0,2,0,0,0,0,0,0,0,0
0,0,0,0,0,0,0,0,0,0,0,0,0,0,0,0,0,0,0,0
0,0,0,0,0,0,0,0,0,0,0,0,0,0,0,0,0,0,0,0
0,0,0,0,0,0,0,0,0,0,0,0,0,0,0,0,0,0,0,0
0,0,0,0,0,0,0,0,0,0,0,0,0,0,0,0,0,0,0,0
0,10,0,0,0,0,0,0,0,0,0,2,2,0,0,0,0,0,0,0
0,0,0,0,0,0,0,0,0,0,0,0,2,0,0,0,0,0,0,0
0,0,10,2,0,0,0,0,0,0,0,2,0,0,0,0,0,0,0,0
0,0,0,0,0,0,0,0,0,0,0,0,0,0,0,0,0,0,0,0
0,0,0,0,0,0,0,0,0,0,0,0,0,0,0,0,0,0,0,0
0,0,0,0,0,0,0,0,0,0,0,0,0,0,0,0,0,0,0,0
0,0,0,0,0,0,0,0,0,0,0,10,0,0,0,0,0,0,0,0
0,0,0,0,0,0,0,0,0,0,0,0,0,0,0,0,0,0,0,0
0,0,0,0,0,0,0,0,0,0,0,0,0,0,0,0,0,0,0,0
0,0,0,0,0,0,0,0,0,0,0,0,0,0,0,0,0,0,0,0
endlayer

layer
0,0,0,0,0,0,0,0,0,0,0,0,0,0,0,0,0,0,0,0
0,0,0,0,0,0,0,0,0,0,0,0,0,0,0,0,0,0,0,0
0,0,0,0,0,0,10,10,10,2,2,10,10,10,0,0,0,0,0,0
0,0,0,0,0,10,2,2,2,2,2,2,2,2,10,0,0,0,0,0
0,0,0,0,0,2,0,2,2,2,2,2,2,2,2,10,0,0,0,0
0,0,0,0,0,0,0,0,0,2,2,2,2,2,2,2,0,0,0,0
0,0,0,0,0,0,0,0,0,0,2,2,2,0,0,0,0,0,0,0
0,0,0,0,0,0,0,0,0,0,0,0,2,0,0,0,0,0,0,0
0,0,0,0,0,0,0,0,0,0,0,0,2,0,0,0,0,0,0,0
0,0,0,0,0,0,0,0,0,0,0,0,0,0,0,0,0,0,0,0
0,0,0,0,0,0,0,0,0,0,0,0,0,0,0,0,0,0,0,0
0,0,0,0,0,0,0,0,0,0,0,0,2,0,0,0,0,0,0,0
0,0,0,0,0,0,0,0,0,0,0,0,2,0,0,0,0,0,0,0
0,0,0,0,0,0,0,0,0,0,0,0,2,2,2,0,0,0,0,0
0,0,0,0,0,0,0,0,0,0,0,2,0,0,0,0,0,0,0,0
0,0,0,0,0,0,0,0,0,0,0,0,0,0,0,0,0,0,0,0
0,0,0,0,0,0,0,0,0,0,0,0,0,0,0,0,0,0,0,0
0,0,0,0,0,0,0,0,0,0,0,0,0,0,0,0,0,0,0,0
0,0,0,0,0,0,0,0,0,0,0,0,0,0,0,0,0,0,0,0
0,0,0,0,0,0,0,0,0,0,0,0,0,0,0,0,0,0,0,0
0,0,0,0,0,0,0,0,0,0,0,0,0,0,0,0,0,0,0,0
0,0,0,0,0,0,0,0,0,0,0,0,0,0,0,0,0,0,0,0
endlayer

layer
0,0,0,0,0,0,0,0,0,0,0,0,0,0,0,0,0,0,0,0
0,0,0,0,0,0,0,0,0,0,0,0,0,0,0,0,0,0,0,0
0,0,0,0,0,0,0,0,0,10,10,0,0,0,0,0,0,0,0,0
0,0,0,0,0,0,10,10,10,2,2,10,10,10,0,0,0,0,0,0
0,0,0,0,0,10,2,2,2,2,2,2,2,2,10,0,0,0,0,0
0,0,0,0,0,0,0,0,0,2,2,2,2,2,0,0,0,0,0,0
0,0,0,0,0,0,0,0,0,0,0,2,2,0,0,0,0,0,0,0
0,0,0,0,0,0,0,0,0,0,0,0,2,0,0,0,0,0,0,0
0,0,0,0,0,0,0,0,0,0,0,0,0,0,0,0,0,0,0,0
0,0,0,0,0,0,0,0,0,0,0,0,0,0,0,0,0,0,0,0
0,0,0,0,0,0,0,0,0,0,0,0,2,0,0,0,0,0,0,0
0,0,0,0,0,0,0,0,0,0,0,0,2,0,0,0,0,0,0,0
0,0,0,0,0,0,0,0,0,0,0,0,2,2,0,0,0,0,0,0
0,0,0,0,0,0,0,0,0,0,0,0,2,2,2,2,0,0,0,0
0,0,0,0,0,0,0,0,0,0,0,2,2,2,0,0,0,0,0,0
0,0,0,0,0,0,0,0,0,0,0,0,2,2,0,0,0,0,0,0
0,0,0,0,0,0,0,0,0,0,0,0,0,0,0,0,0,0,0,0
0,0,0,0,0,0,0,0,0,0,0,0,0,0,0,0,0,0,0,0
0,0,0,0,0,0,0,0,0,0,0,0,0,0,0,0,0,0,0,0
0,0,0,0,0,0,0,0,0,0,0,0,0,0,0,0,0,0,0,0
0,0,0,0,0,0,0,0,0,0,0,0,0,0,0,0,0,0,0,0
0,0,0,0,0,0,0,0,0,0,0,0,0,0,0,0,0,0,0,0
endlayer

layer
0,0,0,0,0,0,0,0,0,0,0,0,0,0,0,0,0,0,0,0
0,0,0,0,0,0,0,0,0,0,0,0,0,0,0,0,0,0,0,0
0,0,0,0,0,0,0,0,0,0,0,0,0,0,0,0,0,0,0,0
0,0,0,0,0,0,0,0,0,10,10,0,0,0,0,0,0,0,0,0
0,0,0,0,0,0,10,10,10,10,10,10,10,10,0,0,0,0,0,0
0,0,0,0,0,0,0,2,0,2,2,2,2,10,0,0,0,0,0,0
0,0,0,0,0,0,0,0,0,0,0,2,2,2,0,0,0,0,0,0
0,0,0,0,0,0,0,0,0,0,0,0,0,2,0,0,0,0,0,0
0,0,0,0,0,0,0,0,0,0,0,0,0,2,0,0,0,0,0,0
0,0,0,0,0,0,0,0,0,0,0,0,0,0,0,0,0,0,0,0
0,0,0,0,0,0,0,0,0,0,0,0,2,2,0,0,0,0,0,0
0,0,0,0,0,0,0,0,0,0,0,0,0,2,0,0,0,0,0,0
0,0,0,0,0,0,0,0,0,0,0,0,0,2,0,0,0,0,0,0
0,0,0,0,0,0,0,0,0,0,0,0,0,2,10,10,0,0,0,0
0,0,0,0,0,0,0,0,0,0,0,0,2,10,0,0,0,0,0,0
0,0,0,0,0,0,0,0,0,0,0,0,10,10,0,0,0,0,0,0
0,0,0,0,0,0,0,0,0,0,0,0,0,0,0,0,0,0,0,0
0,0,0,0,0,0,0,0,0,0,0,0,0,0,0,0,0,0,0,0
0,0,0,0,0,0,0,0,0,0,0,0,0,0,0,0,0,0,0,0
0,0,0,0,0,0,0,0,0,0,0,0,0,0,0,0,0,0,0,0
0,0,0,0,0,0,0,0,0,0,0,0,0,0,0,0,0,0,0,0
0,0,0,0,0,0,0,0,0,0,0,0,0,0,0,0,0,0,0,0
endlayer

layer
0,0,0,0,0,0,0,0,0,0,0,0,0,0,0,0,0,0,0,0
0,0,0,0,0,0,0,0,0,0,0,0,0,0,0,0,0,0,0,0
0,0,0,0,0,0,0,0,0,0,0,0,0,0,0,0,0,0,0,0
0,0,0,0,0,0,0,0,0,0,0,0,0,0,0,0,0,0,0,0
0,0,0,0,0,0,0,0,0,0,0,0,0,0,0,0,0,0,0,0
0,0,0,0,0,0,0,10,0,10,10,10,10,0,0,0,0,0,0,0
0,0,0,0,0,0,0,0,0,0,0,10,10,10,0,0,0,0,0,0
0,0,0,0,0,0,0,0,0,0,0,0,0,10,0,0,0,0,0,0
0,0,0,0,0,0,0,0,0,0,0,0,0,10,0,0,0,0,0,0
0,0,0,0,0,0,0,0,0,0,0,0,0,0,0,0,0,0,0,0
0,0,0,0,0,0,0,0,0,0,0,0,0,0,0,0,0,0,0,0
0,0,0,0,0,0,0,0,0,0,0,0,0,10,0,0,0,0,0,0
0,0,0,0,0,0,0,0,0,0,0,0,0,10,0,0,0,0,0,0
0,0,0,0,0,0,0,0,0,0,0,0,0,10,0,0,0,0,0,0
0,0,0,0,0,0,0,0,0,0,0,0,10,0,0,0,0,0,0,0
0,0,0,0,0,0,0,0,0,0,0,0,0,0,0,0,0,0,0,0
0,0,0,0,0,0,0,0,0,0,0,0,0,0,0,0,0,0,0,0
0,0,0,0,0,0,0,0,0,0,0,0,0,0,0,0,0,0,0,0
0,0,0,0,0,0,0,0,0,0,0,0,0,0,0,0,0,0,0,0
0,0,0,0,0,0,0,0,0,0,0,0,0,0,0,0,0,0,0,0
0,0,0,0,0,0,0,0,0,0,0,0,0,0,0,0,0,0,0,0
0,0,0,0,0,0,0,0,0,0,0,0,0,0,0,0,0,0,0,0
endlayer

