# Converted from schematic
# THIS TEMPLATE USES DEFAULTS!  Please edit for corrections.
# If you need help, consult template_rules.txt

weight=1
embed_into_distance=1
acceptable_target_blocks=1,2,3,12,13
dimensions=24,9,9
allowable_overhang=0
max_cut_in=24
cut_in_buffer=0
max_leveling=0
leveling_buffer=0
preserve_water=0
preserve_lava=0
preserve_plants=0


rule1=0,100,2
rule2=0,100,3
rule3=0,100,109-2
rule4=0,100,109
rule5=0,100,98-1
rule6=0,100,109-1
rule7=0,100,5
rule8=0,100,17
rule9=0,100,109-3
rule10=0,100,4
rule11=0,100,58
rule12=0,100,64-2
rule13=0,100,65-4
rule14=0,100,54-4
rule15=0,100,98
rule16=0,100,50-4
rule17=0,100,102
rule18=0,100,50-2
rule19=0,100,50-1
rule20=0,100,64-8
rule21=0,100,50-3
rule22=0,100,98-3
rule23=0,100,67-2
rule24=0,100,67
rule25=0,100,67-1
rule26=0,100,67-3
rule27=0,100,109-6
rule28=0,100,67-6
rule29=0,100,109-4
rule30=0,100,109-5
rule31=0,100,67-4
rule32=0,100,67-5
rule33=0,100,109-7
rule34=0,100,67-7
rule35=0,100,96-8
rule36=0,100,47
rule37=0,100,61-5
rule38=0,100,26-9
rule39=0,100,26-1
rule40=0,100,126
rule41=0,100,53-2
rule42=0,100,53-1
rule43=0,100,53
rule44=0,100,53-3
rule45=0,100,89
rule46=0,100,44


layer
1,1,1,1,1,1,1,1,1
1,1,1,1,1,1,1,1,1
1,1,2,2,2,2,2,1,1
1,1,2,2,2,2,2,1,1
1,1,2,2,2,2,2,1,1
1,1,2,2,2,2,2,1,1
1,1,2,2,2,2,2,1,1
1,1,1,1,1,1,1,1,1
1,1,1,1,1,1,1,1,1
endlayer

layer
0,0,0,0,0,0,0,0,0
0,9,4,0,4,0,4,3,0
0,9,5,5,5,5,5,3,0
0,0,5,7,7,7,5,0,0
0,0,5,7,8,7,5,0,0
0,0,5,7,7,7,5,0,0
0,9,5,5,5,5,5,3,0
0,6,6,0,0,0,6,3,0
0,0,0,0,0,0,0,0,0
endlayer

layer
0,0,0,0,0,0,0,0,0
0,0,0,0,0,0,0,0,0
0,0,5,10,12,10,5,0,0
0,0,10,0,0,0,10,0,0
0,0,10,0,13,0,10,0,0
0,0,10,14,7,11,10,0,0
0,0,15,10,10,10,5,0,0
0,0,0,0,0,0,0,0,0
0,0,0,0,0,0,0,0,0
endlayer

layer
0,0,0,0,0,0,0,0,0
0,0,0,18,0,18,0,0,0
0,0,15,10,20,10,15,0,0
0,21,10,0,0,0,10,16,0
0,0,17,0,13,0,17,0,0
0,21,10,0,7,0,10,16,0
0,0,15,10,10,10,5,0,0
0,0,0,19,0,19,0,0,0
0,0,0,0,0,0,0,0,0
endlayer

layer
0,0,0,0,0,0,0,0,0
0,0,0,0,0,0,0,0,0
0,0,15,10,10,10,15,0,0
0,0,10,0,19,0,10,0,0
0,0,17,0,13,0,17,0,0
0,0,10,18,7,18,10,0,0
0,0,15,10,10,10,15,0,0
0,0,0,0,0,0,0,0,0
0,0,0,0,0,0,0,0,0
endlayer

layer
0,0,0,0,0,0,0,0,0
0,0,0,0,0,0,0,0,0
0,0,15,15,22,15,15,0,0
0,0,15,0,0,0,15,0,0
0,0,15,0,13,0,15,0,0
0,0,15,0,7,0,15,0,0
0,0,15,15,15,15,15,0,0
0,0,0,0,0,0,0,0,0
0,0,0,0,0,0,0,0,0
endlayer

layer
0,0,0,0,0,0,0,0,0
0,0,0,0,0,0,0,0,0
0,0,4,24,24,24,3,0,0
0,0,26,10,10,10,23,0,0
0,0,26,10,13,10,23,0,0
0,0,26,10,10,10,23,0,0
0,0,9,25,25,25,6,0,0
0,0,0,0,0,0,0,0,0
0,0,0,0,0,0,0,0,0
endlayer

layer
0,0,0,0,0,0,0,0,0
0,0,0,0,0,0,0,0,0
0,0,0,0,0,0,0,0,0
0,0,0,15,10,15,0,0,0
0,0,0,10,13,10,0,0,0
0,0,0,15,10,15,0,0,0
0,0,0,0,0,0,0,0,0
0,0,0,0,0,0,0,0,0
0,0,0,0,0,0,0,0,0
endlayer

layer
0,0,0,0,0,0,0,0,0
0,0,0,0,0,0,0,0,0
0,0,0,0,0,0,0,0,0
0,0,0,15,10,15,0,0,0
0,0,0,17,13,17,0,0,0
0,0,0,15,10,15,0,0,0
0,0,0,0,0,0,0,0,0
0,0,0,0,0,0,0,0,0
0,0,0,0,0,0,0,0,0
endlayer

layer
0,0,0,0,0,0,0,0,0
0,0,0,0,0,0,0,0,0
0,0,0,0,0,0,0,0,0
0,0,0,15,10,15,0,0,0
0,0,0,17,13,17,0,0,0
0,0,0,15,10,15,0,0,0
0,0,0,0,0,0,0,0,0
0,0,0,0,0,0,0,0,0
0,0,0,0,0,0,0,0,0
endlayer

layer
0,0,0,0,0,0,0,0,0
0,0,0,0,0,0,0,0,0
0,0,0,0,0,0,0,0,0
0,0,0,15,17,15,0,0,0
0,0,0,10,13,10,0,0,0
0,0,0,15,10,15,0,0,0
0,0,0,0,0,0,0,0,0
0,0,0,0,0,0,0,0,0
0,0,0,0,0,0,0,0,0
endlayer

layer
0,0,0,0,0,0,0,0,0
0,0,0,0,0,0,0,0,0
0,0,0,0,0,0,0,0,0
0,0,0,15,17,15,0,0,0
0,0,0,10,13,10,0,0,0
0,0,0,15,10,15,0,0,0
0,0,0,0,0,0,0,0,0
0,0,0,0,0,0,0,0,0
0,0,0,0,0,0,0,0,0
endlayer

layer
0,0,0,0,0,0,0,0,0
0,0,0,0,0,0,0,0,0
0,0,0,0,0,0,0,0,0
0,0,0,15,10,15,0,0,0
0,0,0,17,13,17,0,0,0
0,0,0,15,10,15,0,0,0
0,0,0,0,0,0,0,0,0
0,0,0,0,0,0,0,0,0
0,0,0,0,0,0,0,0,0
endlayer

layer
0,0,0,0,0,0,0,0,0
0,0,0,0,0,0,0,0,0
0,0,0,0,0,0,0,0,0
0,0,0,15,10,15,0,0,0
0,0,0,17,13,17,0,0,0
0,0,0,15,10,15,0,0,0
0,0,0,0,0,0,0,0,0
0,0,0,0,0,0,0,0,0
0,0,0,0,0,0,0,0,0
endlayer

layer
0,0,0,0,0,0,0,0,0
0,0,0,0,0,0,0,0,0
0,0,0,0,0,0,0,0,0
0,0,0,15,10,15,0,0,0
0,0,0,10,13,10,0,0,0
0,0,0,15,10,15,0,0,0
0,0,0,0,0,0,0,0,0
0,0,0,0,0,0,0,0,0
0,0,0,0,0,0,0,0,0
endlayer

layer
0,0,15,0,0,0,15,0,0
0,0,0,0,0,0,0,0,0
15,0,29,29,31,29,27,0,15
0,0,33,15,10,15,27,0,0
0,0,34,10,13,10,28,0,0
0,0,33,15,10,15,27,0,0
15,0,30,30,32,30,27,0,15
0,0,0,0,0,0,0,0,0
0,0,15,0,0,0,15,0,0
endlayer

layer
0,0,15,0,0,0,15,0,0
0,0,10,31,31,31,10,15,0
15,10,10,7,7,7,10,10,15
0,34,7,7,7,7,7,28,0
0,34,7,7,35,7,7,28,0
0,34,7,7,7,7,7,28,0
15,10,10,7,7,7,10,10,15
0,0,10,32,32,32,10,0,0
0,0,15,0,0,0,15,0,0
endlayer

layer
0,0,15,0,0,0,15,0,0
0,15,10,15,15,15,10,15,0
15,10,36,11,6,37,36,10,15
0,15,38,0,0,0,9,15,0
0,15,39,0,0,0,9,15,0
0,15,40,0,0,0,9,15,0
15,10,36,14,4,14,36,10,15
0,15,10,15,15,15,10,15,0
0,0,15,0,0,0,15,0,0
endlayer

layer
0,0,0,0,0,0,0,0,0
0,15,10,17,17,17,10,15,0
0,10,36,0,0,0,36,10,0
0,17,0,0,0,0,0,17,0
0,17,0,0,0,0,0,17,0
0,17,0,0,0,0,0,17,0
0,10,36,0,0,0,36,10,0
0,15,10,17,17,17,10,15,0
0,0,0,0,0,0,0,0,0
endlayer

layer
0,0,0,0,0,0,0,0,0
0,15,10,17,17,17,10,15,0
0,10,36,0,0,0,36,10,0
0,17,0,0,0,0,0,17,0
0,17,0,0,0,0,0,17,0
0,17,0,0,0,0,0,17,0
0,10,36,0,0,0,36,10,0
0,15,10,17,17,17,10,15,0
0,0,0,0,0,0,0,0,0
endlayer

layer
0,0,15,15,15,15,15,0,0
0,15,10,10,10,10,10,15,0
15,10,7,0,0,0,7,10,15
15,10,0,0,0,0,0,10,15
15,10,0,0,0,0,0,10,15
15,10,0,0,0,0,0,10,15
15,10,7,0,0,0,7,10,15
0,15,10,10,10,10,10,15,0
0,0,15,15,15,15,15,0,0
endlayer

layer
0,0,15,0,15,0,15,0,0
0,43,43,43,43,43,43,41,0
15,44,7,7,7,7,7,41,15
0,44,7,0,0,0,7,41,0
15,44,7,0,0,0,7,41,15
0,44,7,0,0,0,7,41,0
15,44,7,7,7,7,7,41,15
0,44,42,42,42,42,42,42,0
0,0,15,0,15,0,15,0,0
endlayer

layer
0,0,15,0,0,0,15,0,0
0,0,0,0,0,0,0,0,0
15,0,44,43,43,43,43,0,15
0,0,44,7,7,7,41,0,0
0,0,44,7,45,7,41,0,0
0,0,44,7,7,7,41,0,0
15,0,42,42,42,42,41,0,15
0,0,0,0,0,0,0,0,0
0,0,15,0,0,0,15,0,0
endlayer

layer
0,0,46,0,0,0,46,0,0
0,0,0,0,0,0,0,0,0
46,0,0,0,0,0,0,0,46
0,0,0,43,43,43,0,0,0
0,0,0,44,7,41,0,0,0
0,0,0,42,42,41,0,0,0
46,0,0,0,0,0,0,0,46
0,0,0,0,0,0,0,0,0
0,0,46,0,0,0,46,0,0
endlayer

